Workbook

Sheet BTR Quoting Rents
B2: COMMERCIAL HOLDINGS
B4: Property | C4: Marketing Name | D4: Commercial Asset Manager | E4: Asset Manager | F4: Development Manager | G4: Location | H4: Region | I4: Unit No. | J4: Qube Reference | K4: Qube Unit ref | L4: Qube Unit Description | M4: Salesforce uniit id | N4: Completion Date (PC) | O4: Status | P4: Units | Q4: Leases | R4: Floor Area | S4: Tenant | T4: U/O | U4: Months Vacant | V4: Service Charge | W4: EPC Rating | X4: Lease Start | Y4: Rent Commencement | Z4: RF Expiry | AA4: RF - Time Value | AB4: RF - [£]Value | AC4: Rent Review Date | AD4: Break Date | AE4: Lease Expiration Date | AF4: Capital Contribution £ | AG4: Headline Rent £PA | AH4: Headline Rent £/sqft | AI4: NER [£] | AJ4: Grown Underwritten Rent | AK4: Cap. Con - Time Value | AL4: Total TI - Time Value | AM4: Total TI - [£] Value | AN4: Lease Length | AO4: Unexpired Term | AP4: Time to Rent Review | AQ4: Lease Length - Break | AR4: Time to Break | AS4: CBRE ERV £pa | AT4: CBRE ERV £psf | AU4: Current QR £pa | AV4: Current QR £psf
A5: Clippers Quay1 Zegera Way | B5: Clippers Quay | C5: Clippers Quay | D5: Stewart Blackford | E5: Vicki Turnbull | G5: Manchester | H5: Regions | I5: 1 Zegera Way | J5: 222577002 | K5: 222577002 | L5: Clippers - Unit 1 Zerega Way M50 | M5: a1G4J0000025xoHUAQ | N5: 21/12/2018 | O5: Operational | P5: 1 | Q5: 1 | R5: 1249 | S5: Teta Ltd | U5: - | V5: exclusive | X5: 45449 | Y5: 45571 | Z5: - | AA5: 4.0109545 | AB5: -6684.9242 | AC5: 47275 | AD5: 46544 | AE5: 49101 | AG5: 20000 | AH5: 16.01281 | AI5: 17770.213 | AK5: 0 | AL5: 4.0109545 | AM5: 6684.9242 | AN5: 9.9988446 | AO5: 9.2897261 | AP5: 4.2903038 | AQ5: 2.9980106 | AR5: 2.2888921 | AS5: 20000 | AT5: 16.01281
A6: Clippers Quay2 Zegera Way | B6: Clippers Quay | C6: Clippers Quay | D6: Stewart Blackford | E6: Vicki Turnbull | G6: Manchester | H6: Regions | I6: 2 Zegera Way | J6: 222577003 | K6: 222577003 | L6: Clippers - Unit 2 Zerega Way M50 | M6: a1G4J0000025xMrUAI | N6: 43142 | O6: Operational | P6: 1 | Q6: 1 | R6: 1461 | S6: OB1 Bars Ltd. | U6: - | V6: exclusive | X6: 43817 | Y6: 43879 | Z6: - | AA6: 2.0383539 | AB6: -3736.9822 | AC6: 45644 | AD6: 44913 | AE6: 47469 | AG6: 22000 | AH6: 15.058179 | AI6: 20754.65 | AK6: 0 | AL6: 2.0383539 | AM6: 3736.9822 | AN6: 9.9988446 | AO6: 4.8214582 | AP6: - | AQ6: 3.0007485 | AR6: - | AS6: 21900 | AT6: 14.989733
A7: Clippers QuayUnit 4 & 5 Waterman Walk | B7: Clippers Quay | C7: Clippers Quay | D7: Stewart Blackford | E7: Vicki Turnbull | G7: Manchester | H7: Regions | I7: Unit 4 & 5 Waterman Walk | J7: 222577001 | K7: 222577001 | L7: Clippers - Unit 4-5 Waterman Walk | M7: a1G4J0000025xf4UAA | N7: 43318 | O7: Operational | P7: 2 | Q7: 1 | R7: 3832 | S7: Co-Operative Group Food Ltd. | U7: - | V7: exclusive | X7: 43616 | Y7: 43799 | Z7: - | AA7: 6.0164318 | AB7: -31242.282 | AC7: 45443 | AD7: 47268 | AE7: 49094 | AG7: 62313.91 | AH7: 16.261459 | AI7: 59189.321 | AK7: 0 | AL7: 6.0164318 | AM7: 31242.282 | AN7: 14.998267 | AO7: 9.2705607 | AP7: - | AQ7: 9.9988446 | AR7: 4.2711384 | AS7: 54800 | AT7: 14.300626
A8: Clippers Quay2 & 3 Waterman Walk | B8: Clippers Quay | C8: Clippers Quay | D8: Stewart Blackford | E8: Vicki Turnbull | G8: Manchester | H8: Regions | I8: 2 & 3 Waterman Walk | J8: 222577005 | K8: 222577005 | L8: Clippers - Unit 2 Waterman Walk (GPLC Office) | M8: a1G4J0000025x0gUAA | N8: 43142 | O8: Operational | P8: 2 | Q8: 1 | R8: 2388 | S8: Grainger Plc | U8: - | V8: exclusive | X8: 44124 | Y8: - | Z8: - | AA8: - | AB8: - | AE8: 45949 | AH8: 0 | AI8: 0 | AK8: - | AL8: - | AM8: - | AN8: 4.9966844 | AO8: 0.65983613 | AP8: - | AQ8: - | AR8: - | AS8: 41800 | AT8: 17.504188
J9: 222577004 | K9: 222577004 | L9: Clippers - Unit 3 Waterman Walk (GPLC Office) | M9: a1G4J0000025xvyUAA
A10: Clippers Quay1 Waterman Walk | B10: Clippers Quay | C10: Clippers Quay | D10: Stewart Blackford | E10: Vicki Turnbull | G10: Manchester | H10: Regions | I10: 1 Waterman Walk | J10: 222577006 | K10: 222577006 | L10: Clippers - Unit 1 Waterman Walk | M10: a1G4J0000025xRhUAI | N10: 43142 | O10: Operational | P10: 1 | Q10: 1 | R10: 1435 | S10: Cult Group Ltd | U10: - | V10: exclusive | X10: 43472 | Y10: 43776 | Z10: - | AA10: 9.9945096 | AB10: -19072.856 | AC10: 47125 | AD10: 45298 | AE10: 48950 | AG10: 22900 | AH10: 15.958188 | AI10: 19084.988 | AK10: 0 | AL10: 9.9945096 | AM10: 19072.856 | AN10: 14.998267 | AO10: 8.8763018 | AP10: 3.8796174 | AQ10: 4.9994223 | AR10: - | AS10: 20000 | AT10: 13.937282
A11: Hawkins & George1 | B11: Hawkins & George | C11: Hawkins & George | D11: Becky Day | E11: Vicki Turnbull | G11: Bristol | H11: Regions | I11: 1 | J11: 222625001 | K11: 222625001 | L11: Unit 1, Hawkins Lane Building, East Tucker St | M11: a1G4J0000025wsUUAQ | N11: 21/05/2019 | O11: Operational | P11: 1 | Q11: 1 | R11: 1635 | S11: Vacant | U11: 68 | W11: B | Z11: - | AA11: 0 | AB11: 0 | AH11: 0 | AI11: 0 | AK11: - | AL11: - | AM11: - | AN11: 0 | AO11: - | AP11: - | AQ11: 0 | AR11: - | AS11: 38050 | AT11: 23.272171 | AU11: 40875 | AV11: 25
A12: Hawkins & George2 | B12: Hawkins & George | C12: Hawkins & George | D12: Becky Day | E12: Vicki Turnbull | G12: Bristol | H12: Regions | I12: 2 | J12: 222625002 | K12: 222625002 | L12: Unit 2, Hawkins Lane Building, East Tucker St | M12: a1G4J0000025y18UAA | N12: 21/05/2019 | O12: Operational | P12: 1 | Q12: 1 | R12: 439 | S12: The Ruby Hue Ltd | U12: - | W12: C | X12: 44867 | Y12: 44987 | Z12: - | AA12: 3.9452012 | AB12: -3608.2152 | AC12: 46693 | AD12: 46693 | AE12: 48520 | AG12: 10975 | AH12: 25 | AI12: 10253.274 | AK12: 0 | AL12: 3.9452012 | AM12: 3608.2152 | AN12: 10.001583 | AO12: 7.6990008 | AP12: 2.6968406 | AQ12: 4.9994223 | AR12: 2.6968406 | AS12: 10975 | AT12: 25
A13: Hawkins & George3 | B13: Hawkins & George | C13: Hawkins & George | D13: Becky Day | E13: Vicki Turnbull | G13: Bristol | H13: Regions | I13: 3 | J13: 222625003 | K13: 222625003 | L13: Unit 3, Hawkins Lane Building, East Tucker St | M13: a1G4J0000025xJHUAY | N13: 21/05/2019 | O13: Operational | P13: 1 | Q13: 1 | R13: 1470 | S13: Vacant | U13: 68 | W13: B | Z13: - | AA13: 0 | AB13: 0 | AH13: 0 | AI13: 0 | AK13: - | AL13: - | AM13: - | AN13: 0 | AO13: - | AP13: - | AQ13: 0 | AR13: - | AS13: 28500 | AT13: 19.387755 | AU13: 36750 | AV13: 25
A14: Redcliffe Quarter1.1 | B14: Redcliffe Quarter | C14: Glasshouse Square | D14: Bradley Wallace | E14: Sarah Norstrom | G14: Bristol | H14: Regions | I14: 1.1 | J14: 222707001 | K14: 222707001 | L14: Unit 1.1 Redcliffe Quarter, Bristol. BS1 6WL | M14: a1G8d0000005cWREAY | N14: 13/07/2022 | O14: Operational | P14: 1 | Q14: 1 | R14: 1452 | S14: Vacant | U14: 31 | Z14: - | AA14: 0 | AB14: 0 | AH14: 0 | AI14: 0 | AK14: - | AL14: - | AM14: - | AN14: 0 | AO14: - | AP14: - | AQ14: 0 | AR14: - | AS14: 33733 | AT14: 23.232094 | AU14: 36300 | AV14: 25
A15: Redcliffe Quarter1.2 | B15: Redcliffe Quarter | C15: Glasshouse Square | D15: Bradley Wallace | E15: Sarah Norstrom | G15: Bristol | H15: Regions | I15: 1.2 | J15: 222707002 | K15: 222707002 | L15: Unit 1.2 Redcliffe Quarter, Bristol. BS1 6WL | M15: a1G8d0000005cWWEAY | N15: 13/07/2022 | O15: Operational | P15: 1 | Q15: 1 | R15: 1024 | S15: J Turok t/a Doubleshot barbers | U15: - | X15: 45541 | Y15: 45722 | Z15: 0 | AA15: 5.9506784 | AB15: -10572.372 | AC15: 47183 | AD15: 47183 | AE15: 47278 | AF15: 0 | AG15: 21320 | AH15: 20.820312 | AI15: 18968.309 | AK15: 0 | AL15: 5.9506784 | AM15: 10572.372 | AN15: 4.7557484 | AO15: 4.2985175 | AP15: 4.0384162 | AQ15: 4.495647 | AR15: 4.0384162 | AS15: 21853 | AT15: 21.34082
A16: Redcliffe Quarter1.3 | B16: Redcliffe Quarter | C16: Glasshouse Square | D16: Bradley Wallace | E16: Sarah Norstrom | G16: Bristol | H16: Regions | I16: 1.3 | J16: 222707003 | K16: 222707003 | L16: Unit 1.3 Redcliffe Quarter, Bristol. BS1 6WL | M16: a1G8d0000005cWbEAI | N16: 13/07/2022 | O16: Operational | P16: 1 | Q16: 1 | R16: 1066 | S16: UKGolfbox Bristol Ltd | U16: - | X16: 45596 | Y16: 45787 | Z16: 2 | AA16: 6.2794452 | AB16: -11459.987 | AE16: 47432 | AF16: 0 | AG16: 21900 | AH16: 20.54409 | AI16: 19620.223 | AK16: 0 | AL16: 6.2794452 | AM16: 11459.987 | AN16: 5.0268014 | AO16: 4.7201556 | AP16: - | AQ16: - | AR16: - | AS16: 26650 | AT16: 25
A17: Redcliffe Quarter2.1 | B17: Redcliffe Quarter | C17: Glasshouse Square | D17: Bradley Wallace | E17: Sarah Norstrom | G17: Bristol | H17: Regions | I17: 2.1 | J17: 222707004 | K17: 222707004 | L17: Unit 2.1 Redcliffe Quarter, Bristol. BS1 6WL | M17: a1G8d0000005cWgEAI | N17: 13/07/2022 | O17: Operational | P17: 1 | Q17: 1 | R17: 4539 | S17: Under Offer | T17: ASDA | U17: 31 | Z17: - | AA17: 0 | AB17: 0 | AH17: 0 | AI17: 0 | AK17: - | AL17: - | AM17: - | AN17: 0 | AO17: - | AP17: - | AQ17: 0 | AR17: - | AS17: 99858 | AT17: 22 | AU17: 104397 | AV17: 23
A18: Redcliffe Quarter2.2 (Unit 5) | B18: Redcliffe Quarter | C18: Glasshouse Square | D18: Bradley Wallace | E18: Sarah Norstrom | G18: Bristol | H18: Regions | I18: 2.2 (Unit 5) | K18: #N/A | L18: Not on Qube yet | M18: Not on SF yet | N18: est. 01/09/2025 | O18: Under Construction | P18: 1 | Q18: 1 | R18: 2393 | S18: Winvic Construction | U18: - | Z18: - | AA18: 0 | AB18: 0 | AH18: 0 | AT18: 0 | AU18: 59825 | AV18: 25 | AW18: this is on the market as the tenant will be vacating in a few months
A19: Redcliffe Quarter2.3 (unit 6) | B19: Redcliffe Quarter | C19: Glasshouse Square | D19: Bradley Wallace | E19: Sarah Norstrom | G19: Bristol | H19: Regions | I19: 2.3 (unit 6) | K19: #N/A | L19: Not on Qube yet | M19: Not on SF yet | N19: est. 01/09/2025 | O19: Under Construction | P19: 1 | Q19: 1 | R19: 2754 | S19: Winvic Construction | U19: - | Z19: - | AA19: 0 | AB19: 0 | AH19: 0 | AT19: 0 | AU19: 68850 | AV19: 25 | AW19: this is on the market as the tenant will be vacating in a few months
A20: Glasshouse1 | B20: Glasshouse | C20: Glasshouse | D20: Bradley Wallace | E20: Sarah Norstrom | F20: Maria Sabat | G20: Bristol | H20: Regions | I20: 1 | K20: #N/A | L20: Not on Qube yet | M20: Not on SF yet | N20: est 08/08/2025 | O20: Under Construction | P20: 1 | Q20: 1 | R20: 2667.2944 | S20: Vacant | Z20: - | AA20: 0 | AB20: 0 | AG20: 0 | AH20: 0 | AI20: 0 | AK20: - | AL20: - | AM20: - | AN20: 0 | AO20: - | AP20: - | AQ20: 0 | AR20: - | AS20: #N/A | AT20: #N/A
A21: Glasshouse2 | B21: Glasshouse | C21: Glasshouse | D21: Bradley Wallace | E21: Sarah Norstrom | F21: Maria Sabat | G21: Bristol | H21: Regions | I21: 2 | K21: #N/A | L21: Not on Qube yet | M21: Not on SF yet | N21: est 08/08/2025 | O21: Under Construction | P21: 1 | Q21: 1 | R21: 3119.3782 | S21: Vacant | Z21: - | AA21: 0 | AB21: 0 | AG21: 0 | AH21: 0 | AI21: 0 | AK21: - | AL21: - | AM21: - | AN21: 0 | AO21: - | AP21: - | AQ21: 0 | AR21: - | AS21: #N/A | AT21: #N/A
A22: Glasshouse3 | B22: Glasshouse | C22: Glasshouse | D22: Bradley Wallace | E22: Sarah Norstrom | F22: Maria Sabat | G22: Bristol | H22: Regions | I22: 3 | K22: #N/A | L22: Not on Qube yet | M22: Not on SF yet | N22: est 08/08/2025 | O22: Under Construction | P22: 1 | Q22: 1 | R22: 1791.113 | S22: Vacant | Z22: - | AA22: 0 | AB22: 0 | AG22: 0 | AH22: 0 | AI22: 0 | AK22: - | AL22: - | AM22: - | AN22: 0 | AO22: - | AP22: - | AQ22: 0 | AR22: - | AS22: #N/A | AT22: #N/A
A23: Glasshouse4 | B23: Glasshouse | C23: Glasshouse | D23: Bradley Wallace | E23: Sarah Norstrom | F23: Maria Sabat | G23: Bristol | H23: Regions | I23: 4 | K23: #N/A | L23: Not on Qube yet | M23: Not on SF yet | N23: est 14/04/2025 (Dev think 26/05/2025) | O23: Under Construction | P23: 1 | Q23: 1 | R23: 992.43158 | S23: Vacant | Z23: - | AA23: 0 | AB23: 0 | AG23: 0 | AH23: 0 | AI23: 0 | AK23: - | AL23: - | AM23: - | AN23: 0 | AO23: - | AP23: - | AQ23: 0 | AR23: - | AS23: #N/A | AT23: #N/A
A24: Brook Place1/2 | B24: Brook Place | C24: Brook Place | D24: Stewart Blackford | E24: Vicki Turnbull | G24: Sheffield | H24: Regions | I24: 1/2 | J24: 222632001 | K24: 222632001 | L24: Unit 1 Brook Place 110 Napier Street S11 8BR | M24: a1G4J0000025y3lUAA | N24: 30/09/2019 | O24: Operational | P24: 2 | Q24: 1 | R24: 3721 | S24: R1SE Brook Place Ltd | U24: - | V24: Inclusive | W24: B | X24: 44326 | Y24: 44691 | Z24: - | AA24: 11.999987 | AB24: -32360.965 | AC24: 46152 | AD24: 46152 | AE24: 47977 | AG24: 32361 | AH24: 8.6968557 | AI24: 25888.059 | AK24: 0 | AL24: 11.999987 | AM24: 32360.965 | AN24: 9.9961067 | AO24: 6.2123161 | AP24: 1.2156317 | AQ24: 4.9994223 | AR24: 1.2156317 | AS24: 31600 | AT24: 8.4923408
J25: 222632002 | K25: 222632002 | L25: Unit 2, Brook Place, 112 Napier Street, S11 8 | M25: a1G4J0000025x8FUAQ
A26: Brook Place3 | B26: Brook Place | C26: Brook Place | D26: Stewart Blackford | E26: Vicki Turnbull | G26: Sheffield | H26: Regions | I26: 3 | J26: 222632003 | K26: 222632003 | L26: Unit 3, Brook Place, 114 Napier Street, S11 8 | M26: a1G4J0000025yBfUAI | N26: 30/09/2019 | O26: Operational | P26: 1 | Q26: 1 | R26: 1981 | S26: Smile 2 Impress | U26: - | V26: Inclusive | W26: B | X26: 44729 | Y26: 45002 | Z26: - | AA26: 8.9753326 | AB26: -19359.045 | AC26: 46555 | AD26: 46555 | AE26: 48381 | AG26: 25883 | AH26: 13.065623 | AI26: 22010.744 | AK26: 0 | AL26: 8.9753326 | AM26: 19359.045 | AN26: 9.9988446 | AO26: 7.3184314 | AP26: 2.3190091 | AQ26: 4.9994223 | AR26: 2.3190091 | AS26: 24800 | AT26: 12.51893
A27: Solstice Apartments1/2 | B27: Solstice Apartments | C27: Solstice Apartments | D27: Stewart Blackford | E27: Vicki Turnbull | G27: Milton Keynes | H27: Regions | I27: 1/2 | J27: 222641001 | K27: 222641001 | L27: 809, Silbury Boulevard, Milton Keynes, MK9 | M27: a1G4J0000025y5HUAQ | N27: 43954 | O27: Operational | P27: 2 | Q27: 1 | R27: 4498 | S27: Spectrum Associates (MK) Ltd | U27: - | V27: exclusive | W27: B | X27: 44448 | Y27: 44751 | Z27: - | AA27: 9.9616329 | AB27: -62542.452 | AC27: 46274 | AD27: 48100 | AE27: 49835 | AF27: -45000 | AG27: 75340 | AH27: 16.749667 | AI27: 64584.512 | AK27: 7.1675073 | AL27: 17.12914 | AM27: 107542.45 | AN27: 14.749117 | AO27: 11.299351 | AP27: 1.5496566 | AQ27: 9.9988446 | AR27: 6.5490789 | AS27: 75340 | AT27: 16.749667
J28: 222641002 | K28: 222641002 | L28: 811, Silbury Boulevard, Milton Keynes, MK9 | M28: a1G4J0000025y35UAA
A29: Millet Place1 | B29: Millet Place | C29: Millet Place | D29: Bradley Wallace | E29: Harriet Shaw & Sarah Norstrom | G29: London | H29: London | I29: 1 | J29: 900005001 | K29: 900005001 | L29: Unit 1, 1 Millet Place, London E16 2YJ | M29: a1G4J00000260JEUAY | N29: 43924 | O29: Operational | P29: 1 | Q29: 1 | R29: 2250 | S29: Vacant | U29: 58 | W29: B | Z29: - | AA29: 0 | AB29: 0 | AH29: 0 | AI29: 0 | AK29: - | AL29: - | AM29: - | AN29: 0 | AO29: - | AP29: - | AQ29: 0 | AR29: - | AS29: 51731.25 | AT29: 22.991667 | AU29: 52000 | AV29: 23.111111
A30: Millet Place2 | B30: Millet Place | C30: Millet Place | D30: Bradley Wallace | E30: Harriet Shaw & Sarah Norstrom | G30: London | H30: London | I30: 2 | J30: 900005002 | K30: 900005002 | L30: Unit 2, 5 Millet Place, London E16 2YJ | M30: a1G4J000002605CUAQ | N30: 43924 | O30: Operational | P30: 1 | Q30: 1 | R30: 3451 | S30: Under Offer | T30: Tesco | U30: 58 | W30: A | Z30: - | AA30: 0 | AB30: 0 | AH30: 0 | AI30: 0 | AK30: - | AL30: - | AM30: - | AN30: 0 | AO30: - | AP30: - | AQ30: 0 | AR30: - | AS30: 60000 | AT30: 17.386265 | AU30: 80000 | AV30: 23.181686
A31: Millet Place3 | B31: Millet Place | C31: Millet Place | D31: Bradley Wallace | E31: Harriet Shaw & Sarah Norstrom | G31: London | H31: London | I31: 3 | J31: 900005003 | K31: 900005003 | L31: Unit 3,7 Millet Place, London E16 2YJ | M31: a1G4J000002607zUAA | N31: 43924 | O31: Operational | P31: 1 | Q31: 1 | R31: 904 | S31: Vacant | U31: 58 | W31: B | Z31: - | AA31: 0 | AB31: 0 | AH31: 0 | AI31: 0 | AK31: - | AL31: - | AM31: - | AN31: 0 | AO31: - | AP31: - | AQ31: 0 | AR31: - | AS31: 20340 | AT31: 22.5 | AU31: 26000 | AV31: 28.761062
A32: Millet Place4 | B32: Millet Place | C32: Millet Place | D32: Bradley Wallace | E32: Harriet Shaw & Sarah Norstrom | G32: London | H32: London | I32: 4 | J32: 900005004 | K32: 900005004 | L32: Unit 4, 9 Millet Place, London E16 2YJ | M32: a1G4J00000260MYUAY | N32: 43924 | O32: Operational | P32: 1 | Q32: 1 | R32: 1132 | S32: Under Offer | T32: Subway | U32: 58 | W32: A | Z32: - | AA32: 0 | AB32: 0 | AH32: 0 | AI32: 0 | AK32: - | AL32: - | AM32: - | AN32: 0 | AO32: - | AP32: - | AQ32: 0 | AR32: - | AS32: 24055 | AT32: 21.25 | AU32: 30000 | AV32: 26.501767
A33: The FilamentsPodium A/B - Unit 1 | B33: The Filaments | C33: The Filaments | D33: Bradley Wallace | E33: Vicki Turnbull | G33: Manchester | H33: Regions | I33: Podium A/B - Unit 1 | J33: 222653001 | K33: 222653001 | L33: Unit 1 Halogen House, 217 Chapel St, Salford | M33: a1G8d0000004Me4EAE | N33: 19/02/2021 | O33: Operational | P33: 1 | Q33: 1 | R33: 1069 | S33: Vacant | T33: Fiori Ltd | U33: 48 | W33: C | Z33: - | AA33: 0 | AB33: 0 | AH33: 0 | AI33: 0 | AK33: - | AL33: - | AM33: - | AN33: 0 | AO33: - | AP33: - | AQ33: 0 | AR33: - | AS33: 24000 | AT33: 22.450889 | AU33: 25000 | AV33: 23.386342
A34: The FilamentsPodium A/B - Unit 2 | B34: The Filaments | C34: The Filaments | D34: Stewart Blackford | E34: Vicki Turnbull | G34: Manchester | H34: Regions | I34: Podium A/B - Unit 2 | J34: 222653002 | K34: 222653002 | L34: Unit 2, Halogen House, 217 Chapel St, Salford | M34: a1G8d0000004Me9EAE | N34: 19/02/2021 | O34: Operational | P34: 1 | Q34: 1 | R34: 828 | S34: K&K Hospitality | U34: - | W34: D | X34: 44642 | Y34: 44733 | Z34: - | AA34: 2.9917775 | AB34: -4986.2959 | AC34: 46468 | AD34: 46468 | AE34: 47198 | AG34: 20000 | AH34: 24.154589 | AI34: 19002.626 | AK34: 0 | AL34: 2.9917775 | AM34: 4986.2959 | AN34: 6.9980961 | AO34: 4.0794848 | AP34: 2.080811 | AQ34: 4.9994223 | AR34: 2.080811 | AS34: 20000 | AT34: 24.154589
A35: The FilamentsPodium A/B - Unit 3 | B35: The Filaments | C35: The Filaments | D35: Stewart Blackford | E35: Vicki Turnbull | G35: Manchester | H35: Regions | I35: Podium A/B - Unit 3 | J35: 222653003 | K35: 222653003 | L35: Unit 3, Halogen House, 217 Chapel St, Salford | M35: a1G8d0000004MeEEAU | N35: 19/02/2021 | O35: Operational | P35: 1 | Q35: 1 | R35: 426 | S35: Inner West Coffee | U35: - | W35: D | X35: 44470 | Y35: 44547 | Z35: - | AA35: 2.5315041 | AB35: -2729.8052 | AC35: 45566 | AE35: 46295 | AG35: 12940 | AH35: 30.375587 | AI35: 12393.677 | AK35: 0 | AL35: 2.5315041 | AM35: 2729.8052 | AN35: 4.9966844 | AO35: 1.6071527 | AP35: - | AQ35: - | AR35: - | AS35: 12800 | AT35: 30.046948
A36: The FilamentsPodium C - Unit 4 | B36: The Filaments | C36: The Filaments | D36: Stewart Blackford | E36: Vicki Turnbull | G36: Manchester | H36: Regions | I36: Podium C - Unit 4 | J36: 222653004 | K36: 222653004 | L36: Unit 4, Neon House, 207 Chapel St, Salford, M | M36: a1G8d0000004MeJEAU | N36: 14/03/2021 | O36: Operational | P36: 1 | Q36: 1 | R36: 1231 | S36: Shoalter Automation (UK) | U36: - | W36: D | X36: 44992 | Y36: 45358 | Z36: - | AA36: 12.032864 | AB36: -25569.835 | AC36: 46819 | AD36: 47184 | AE36: 48645 | AF36: - | AG36: 25500 | AH36: 20.714866 | AI36: 25500 | AK36: - | AL36: - | AM36: - | AN36: 10.001583 | AO36: 8.0412395 | AP36: 3.0418172 | AQ36: 6.0014971 | AR36: 4.0411541 | AS36: 25500 | AT36: 20.714866
A37: The FilamentsPodium C - Unit 5 | B37: The Filaments | C37: The Filaments | D37: Stewart Blackford | E37: Vicki Turnbull | G37: Manchester | H37: Regions | I37: Podium C - Unit 5 | J37: 222653005 | K37: 222653005 | L37: Unit 5, Neon House, 207 Chapel St, Salford, M | M37: a1G8d0000004MeOEAU | N37: 14/03/2021 | O37: Operational | P37: 1 | Q37: 1 | R37: 1332 | S37: Rush242 Ltd | U37: - | W37: D | X37: 45064 | Y37: 45248 | Z37: - | AA37: 6.0493084 | AB37: -14745.189 | AC37: 46905 | AD37: 46905 | AE37: 48716 | AF37: -15000 | AG37: 29250 | AH37: 21.959459 | AI37: 23348.752 | AK37: 6.1538462 | AL37: 12.203155 | AM37: 29745.189 | AN37: 9.9988446 | AO37: 8.235631 | AP37: 3.2772774 | AQ37: 5.0404909 | AR37: 3.2772774 | AS37: 29250 | AT37: 21.959459
A38: The FilamentsPodium C - Unit 6 | B38: The Filaments | C38: The Filaments | D38: Stewart Blackford | E38: Vicki Turnbull | G38: Manchester | H38: Regions | I38: Podium C - Unit 6 | J38: 222653006 | K38: 222653006 | L38: Unit 6, Neon House, 207 Chapel St, Salford, M | M38: a1G8d0000004MeTEAU | N38: 14/03/2021 | O38: Operational | P38: 1 | Q38: 1 | R38: 2940 | S38: BLS International Services | U38: - | W38: D | X38: 45156 | Y38: 45340 | Z38: - | AA38: 6.0493084 | AB38: -22684.907 | AC38: 46983 | AD38: 46252 | AE38: 48808 | AG38: 45000 | AH38: 15.306122 | AI38: 37440.251 | AK38: 0 | AL38: 6.0493084 | AM38: 22684.907 | AN38: 9.9988446 | AO38: 8.4875187 | AP38: 3.4908343 | AQ38: 3.0007485 | AR38: 1.4894226 | AS38: 45000 | AT38: 15.306122
A39: Apex Gardens1 | B39: Apex Gardens | C39: Apex Gardens | D39: Bradley Wallace | E39: Harriet Shaw & Alexa Byrne | G39: London | H39: London | I39: 1 | J39: 222646001 | K39: 222646001 | L39: Unit 1, Aster Apartments. | M39: a1G8d0000004RxMEAU | N39: 21/06/2021 | O39: Operational | P39: 1 | Q39: 1 | R39: 1780 | S39: Under Offer | T39: Ellies Nursery | U39: 43 | Z39: - | AA39: 0 | AB39: 0 | AH39: 0 | AI39: 0 | AK39: - | AL39: - | AM39: - | AN39: 0 | AO39: - | AP39: - | AQ39: 0 | AR39: - | AS39: 44500 | AT39: 25 | AU39: 45000 | AV39: 25.280899
A40: Apex Gardens2 | B40: Apex Gardens | C40: Apex Gardens | D40: Stewart Blackford | E40: Harriet Shaw & Alexa Byrne | G40: London | H40: London | I40: 2 | J40: 222644002 | K40: 222644002 | L40: Unit 2, Juniper House | M40: a1G8d0000004RwxEAE | N40: 21/06/2021 | O40: Operational | P40: 6 | Q40: 1 | R40: 7704 | S40: Pure Gym | U40: - | X40: 45191 | Y40: 45285 | Z40: - | AA40: 3.0904076 | AB40: -50219.123 | AD40: 25/09/2033 | AE40: 50672 | AF40: -100000 | AG40: 195000 | AH40: 25.311526 | AI40: 179992.79 | AK40: 6.1538462 | AL40: 9.2442537 | AM40: 150219.12 | AN40: 15.006481 | AO40: 13.590982 | AP40: - | AQ40: 10.009796 | AR40: 8.5942972 | AS40: #N/A | AT40: #N/A
I41: 3 | J41: 222644003 | K41: 222644003 | L41: Unit 3, Juniper House | M41: a1G8d0000004Rx2EAE
I42: 4 | J42: 222644004 | K42: 222644004 | L42: Unit 4, Juniper House | M42: a1G8d0000004Rx7EAE
...

Sheet PRS Quoting rents
B1: Address | D1: Qube ref | E1: Qube description | F1: Salesforce id | G1: Quoting rent | H1: QR £psf | J1: Lessee / Assignee | K1: Description | L1: Use Class | N1: Term | O1: Start | P1: Expiry | Q1: Rent Review | R1: Earliest Break Date / Landlord & Tenants Enforcement | S1: Excluded from '54 Act | T1: Service Charge | U1: Insurance | V1: Rent Deposit | W1: Current Rent (p.a.) | X1: CBRE September 2024 ERV | AB1: Measured Floor Areas | AC1: NIA | AD1: ITZA (sq. ft.) | AH1: £/Sqft | AI1: Remarks / Action
A2: 1 | B2: Ospringe House | C2: Ospringe House, SE1 8TP | D2: 317670001 | E2: Ospringe House Grnd Flr office Wooton St SE1 | F2: a1G4J0000025yKMUAY | G2: 25000 | H2: 26.096033 | I2: 1 | J2: VACANT | K2: Office | L2: B1 | M2: 1 | AB2: 958 | AC2: Keys held with Rebecca Crow / Maria Dev | AI2: Refresh quote requested
A3: 1 | B3: 16 & 18 | C3: Wilcox Rd, SW8 2UX | D3: 317652009 | E3: 16/18 Wilcox Road London SW8 2UX | F3: a1G4J000002632zUAA | G3: 35000 | H3: 37.768426 | I3: 1 | J3: Colin Gallagher 27/11/24 -lease forfieted | K3: Ground floor shop and yard | L3: A1 | M3: 1 | N3: 10 years | O3: 21/11/2022 | P3: 20/11/2032 | Q3: 21/11/2027 | R3: 21/11/2027 | S3: Yes | T3: Exclusive | U3: Exclusive | V3: £1743.91 (Holding £1644.08) | W3: 27000 | X3: 23000 | AB3: 926.7 | AC3: 906 | AD3: 493 | AH3: 29.135643 | AI3: 27/11/24 russell cooke forfieted lease, houston lawrence estimated rent between £30-£35k, passing rent £28k need to inspect. 13/01 agent opinion awaited, exploring refresh of unit. Pedro owns 32/34 viewed wk comm 2nd feb. viewing with estate agent scheduled 06/02. Collin gallagher is offering to pay arrears off. QR £35k
A4: 1 | B4: G01 | C4: ABILITY PLAZA, 298-316 KINGSLAND RD, 1A ARBUTUS ST, E8 4DT | D4: 418576001 | E4: Unit 1 Ability Plaza, London, E8 | F4: a1G4J0000025zy0UAA | G4: 22770 | H4: 22.5 | J4: VACANT | K4: Ground floor | L4: B1 with ancillary A2 | O4: 45398 | W4: 0 | X4: 22300 | Z4: 0 | AA4: 1012 | AB4: 1012 | AD4: BKR | AE4: D82 | AF4: 44898 | AH4: 0 | AI4: lease discalimed 08/10/24 on market Strettons / Ellis Brown at "22.50 psf | AJ4: Ellis Brown | AK4: Rightmove
A5: 1 | B5: G02 (SEE ABOVE) | C5: ABILITY PLAZA, 298-316 KINGSLAND RD, 1A ARBUTUS ST, E8 4DT | D5: 418576002 | E5: Unit 2 Ability Plaza, London, E8 | F5: a1G4J000002600AUAQ | G5: 22522.5 | H5: 22.5 | J5: VACANT | K5: Ground floor | L5: B1 | N5: At Will | O5: 45177 | P5: monthly | R5: Tenancy at will | W5: 0 | X5: 59800 | Z5: 5405 | AA5: 1001 | AB5: 1001 | AD5: BKR | AE5: D78 | AF5: 44988 | AH5: 59.74026 | AI5: as above | AJ5: Strettons | AK5: Rightmove Zoopla
A6: 1 | B6: G03 | C6: ABILITY PLAZA, 298-316 KINGSLAND RD, 1A ARBUTUS ST, E8 4DT | D6: 418576003 | E6: Unit 3 Ability Plaza, London, E8 | F6: a1G4J0000025zx3UAA | G6: 19350 | H6: 22.5 | J6: VACANT | K6: Ground & Mezzanine floor | L6: B1 | R6: Tenancy at will | W6: 0 | X6: 0 | Z6: 0 | AA6: 860 | AB6: 1001 | AD6: BKR | AE6: C69 | AF6: 44988 | AH6: 0 | AI6: as above
A7: 1 | B7: G04 | C7: ABILITY PLAZA, 298-316 KINGSLAND RD, 1A ARBUTUS ST, E8 4DT | D7: 418576004 | E7: Unit 4 Ability Plaza, London, E8 | F7: a1G4J0000025zuGUAQ | G7: 19327.5 | H7: 22.5 | J7: VACANT | K7: Ground floor | L7: B1 | R7: Tenancy at will | W7: 0 | X7: 0 | Z7: 0 | AA7: 859 | AD7: None | AE7: C70 | AF7: 44898 | AH7: 0 | AI7: as above
A8: 1 | B8: G05 | C8: ABILITY PLAZA, 298-316 KINGSLAND RD, 1A ARBUTUS ST, E8 4DT | D8: 418576005 | E8: Unit 5 Ability Plaza, London, E8 | F8: a1G4J0000025zM4UAI | G8: 26000 | H8: 25.641026 | I8: 25.641026 | J8: VACANT | K8: Ground floor | L8: B1 | N8: At Will | O8: 25/05/2023 | P8: Monthly | Q8: N/A | R8: Tenancy at will | S8: Yes | T8: N/A | U8: Landlord | V8: N/A | W8: 33420 | X8: 25400 | Z8: 3342 | AA8: 1014 | AD8: BKR | AE8: D97 | AF8: 44898 | AG8: 1 space | AH8: 32.95858 | AI8: keys back 16th jan, agents have inspected, office revival instruted to clear unit and get marketing (chased for update 10/02/25)
A9: 1 | B9: Unit GA1 (222) | C9: ABILITY VIEW, 218/222 KINGSLAND RD, E2 | D9: 418577012 | E9: Unit GA1, 222 Kingsland Road, E2 8AX | F9: a1G4J0000025zr9UAA | G9: 37000 | H9: 35.852713 | J9: RWD Since 2001 Ltd | K9: Ground & Lower ground floors | L9: B1 | N9: 5 years | O9: 44104 | P9: 45929 | Q9: 45199 | R9: N/A | S9: Yes | T9: Exclusive | U9: Exclusive | V9: 9900 | W9: 37000 | X9: 30700 | Z9: 9900 | AA9: 1662 | AD9: BKR | AE9: E116 | AF9: 46144 | AH9: 22.262335 | AI9: 28/01 Initial approach to tenant on their intentions at lease expiry
A10: 1 | B10: Unit GA2 (Unit 2 - 222) | C10: ABILITY VIEW, 218/222 KINGSLAND RD, E2 | D10: 418577013 | E10: Unit GA2 Ability view, 222 Kingsland Road | F10: a1G4J0000025zj4UAA | G10: 29000 | H10: 28.100775 | J10: Skyway Charity | K10: Ground & Lower ground floors | L10: B1 | N10: 10 Years | O10: 42095 | P10: 45747 | Q10: N/A | R10: N/A | S10: Yes | T10: Inclusive | U10: Exclusive - 3.2% | V10: 2625 | W10: 29000 | X10: 25800 | Z10: 0 | AA10: 1032 | AD10: None | AE10: D82 | AF10: 44212 | AH10: 28.100775 | AI10: tenant has advised they will not be renewing 31/03/25. Awaitng marketing report from Strettons & Ellis Brown, chased 10/02/25
A11: 1 | B11: Unit 3 | C11: ABILITY TOWERS, EC1V 5AE | D11: 418576003 | E11: Unit 3 Ability Plaza, London, E8 | F11: a1G4J0000025zx3UAA | G11: 77220 | H11: 22.5 | J11: VACANT | K11: GF | L11: Office B1 | W11: 0 | X11: 89200 | Y11: 76050 | Z11: 0 | AA11: 3432 | AE11: C65 | AF11: 44478 | AH11: 25.990676 | AI11: QR dropped to £22.50 psf. agents have advised full flexible use class to include e and f1 - to reach out to planner | AJ11: as above | AK11: as above
A12: 1 | B12: Unit 22 & 23 | C12: SPRINGFIELD HOUSE LOFTS, TYSSEN ST, E8 2LY | D12: 418578022 | E12: Unit 22 & 23 Springfield Hse,Tyssen St | F12: a1G4J000002605ZUAQ | G12: 41775 | H12: 25 | J12: VACANT | K12: Ground floor | L12: B1 | W12: 0 | X12: 45000 | Y12: 41775 | Z12: 0 | AA12: 1671 | AE12: B47 | AI12: on market with Strettons & Belcor, qr reduced to £47,500. 09/07 rent reduced to £25 psf. whats the latest on planning app? no interest at present | AJ12: Belcor | AK12: Zoopla rightmove

Sheet All Qube commercial units
A1: 1. Vacant Units
A2: Qube Unit Reference | B2: sheet | C2: DS sheet | D2: SF unit id | E2: Portfolio | F2: Old Reference | G2: Qube and Salesforce Description | H2: Type | I2: Status | J2: Tenure | K2: ERV | L2: ERV As At | M2: On Commercial quoting Rent sheet | N2: Description | O2: Total | P2: Missing from SF | Q2: On SF | R2: On Comm Team sheet | S2: Not on Comm Team sheet
A3: 222625001 | B3: 222625001 | C3: =VLOOKUP(A3,'DS Tenanted units'!A:A,1,FALSE) -> #N/A | D3: a1G4J0000025wsUUAQ | E3: GRML | F3: 373713 | G3: Unit 1, Hawkins Lane Building, East Tucker St | H3: Commercial | I3: For Let | J3: Vac-C | K3: 38050 | L3: 45565 | M3: Yes | N3: Vacant Units | O3: 138 | P3: 71 | Q3: =O3-P3 -> 67 | R3: 40 | S3: =O3-R3 -> 98
A4: 222625003 | B4: 222625003 | C4: =VLOOKUP(A4,'DS Tenanted units'!A:A,1,FALSE) -> #N/A | D4: a1G4J0000025xJHUAY | E4: GRML | F4: 373715 | G4: Unit 3, Hawkins Lane Building, East Tucker St | H4: Commercial | I4: For Let | J4: Vac-C | K4: 28500 | L4: 45565 | M4: Yes | N4: Tenanted units-CommLease | O4: 161 | P4: 11 | Q4: =O4-P4 -> 150 | R4: 36 | S4: =O4-R4 -> 125
A5: 222646001 | B5: 222646001 | C5: =VLOOKUP(A5,'DS Tenanted units'!A:A,1,FALSE) -> #N/A | D5: a1G8d0000004RxMEAU | E5: GRML | F5: 10095637138 | G5: Unit 1, Aster Apartments. | H5: Commercial | I5: For Let | J5: Vac-C | K5: 44500 | L5: 45565 | M5: Yes | N5: Tenanted units-Comm LIC | O5: 294 | P5: 0 | Q5: =O5-P5 -> 294 | R5: 0 | S5: =O5-R5 -> 294
A6: 222653001 | B6: 222653001 | C6: =VLOOKUP(A6,'DS Tenanted units'!A:A,1,FALSE) -> #N/A | D6: a1G8d0000004Me4EAE | E6: GRIP | G6: Unit 1 Halogen House, 217 Chapel St, Salford | H6: COMMERCIAL | I6: For Let | J6: Vac-C | K6: 24000 | L6: 45565 | M6: Yes | N6: Tenanted Units-Queries e.g Wayleaves | O6: 43 | P6: 3 | Q6: =O6-P6 -> 40 | R6: 0 | S6: =O6-R6 -> 43
A7: 222680001 | B7: 222680001 | C7: =VLOOKUP(A7,'DS Tenanted units'!A:A,1,FALSE) -> #N/A | D7: a1G8d0000004Gl5EAE | E7: GRML | F7: 4510747827 | G7: Unit 1, The Forge, Newcastle, NE1 3AA | H7: COMMERCIAL | I7: For Let | J7: Vac-C | K7: 29010 | L7: 45565 | M7: Yes | N7: Tenanted Units-Comm-Let | O7: 107 | P7: 1 | Q7: =O7-P7 -> 106 | R7: 0 | S7: =O7-R7 -> 107
A8: 222690003 | B8: 222690003 | C8: =VLOOKUP(A8,'DS Tenanted units'!A:A,1,FALSE) -> #N/A | D8: a1G8d0000004bzrEAA | E8: GRML | G8: Gilders Yard - B.02, 12 Great Hampton St | H8: COMMERCIAL | I8: For Let | J8: Vac-C | K8: 25768 | L8: 45565 | M8: Yes | O8: =SUM(O3:O7) -> 743 | P8: =SUM(P3:P7) -> 86 | Q8: =SUM(Q3:Q7) -> 657 | R8: =SUM(R3:R7) -> 76 | S8: =SUM(S3:S7) -> 667
A9: 222698001 | B9: 222698001 | C9: =VLOOKUP(A9,'DS Tenanted units'!A:A,1,FALSE) -> #N/A | D9: a1G8d0000004qhAEAQ | E9: GRML | F9: 10095672408 | G9: Unit A Bamboo House, Weavers Yard, Newbury | H9: COMMERCIAL | I9: For Let | J9: Vac-C | K9: 49818 | L9: 45565 | M9: Yes
A10: 222698002 | B10: 222698002 | C10: =VLOOKUP(A10,'DS Tenanted units'!A:A,1,FALSE) -> #N/A | D10: a1G8d0000004qhKEAQ | E10: GRML | G10: Unit A Garter House, Weavers Yard, Newbury | H10: COMMERCIAL | I10: For Let | J10: Vac-C | K10: 26130 | L10: 45565 | M10: Yes
A11: 222698003 | B11: 222698003 | C11: =VLOOKUP(A11,'DS Tenanted units'!A:A,1,FALSE) -> #N/A | D11: a1G8d0000004qhUEAQ | E11: GRML | G11: Unit B Garter House, Weavers Yard, Newbury | H11: COMMERCIAL | I11: For Let | J11: Vac-C | K11: 41970 | L11: 45565 | M11: Yes
A12: 222698004 | B12: 222698004 | C12: =VLOOKUP(A12,'DS Tenanted units'!A:A,1,FALSE) -> #N/A | D12: a1G8d0000004qheEAA | E12: GRML | F12: 10095672457 | G12: Unit A Purl House, Weavers Yard, Newbury | H12: COMMERCIAL | I12: For Let | J12: Vac-C | K12: 24390 | L12: 45565 | M12: Yes
A13: 222698005 | B13: 222698005 | C13: =VLOOKUP(A13,'DS Tenanted units'!A:A,1,FALSE) -> #N/A | D13: a1G8d0000004qZvEAI | E13: GRML | G13: Unit A Linen Place, Weavers Yard, Newbury | H13: COMMERCIAL | I13: For Let | J13: Vac-C | K13: 29260 | L13: 45565 | M13: Yes
A14: 222698006 | B14: 222698006 | C14: =VLOOKUP(A14,'DS Tenanted units'!A:A,1,FALSE) -> #N/A | D14: a1G8d0000004qeREAQ | E14: GRML | G14: Unit A Farrow House, Weavers Yard, Newbury | H14: COMMERCIAL | I14: For Let | J14: Vac-C | K14: 10010 | L14: 45565 | M14: Yes
A15: 222698007 | B15: 222698007 | C15: =VLOOKUP(A15,'DS Tenanted units'!A:A,1,FALSE) -> #N/A | D15: a1G8d0000004qhoEAA | E15: GRML | G15: 5 Station Approach, Weavers Yard, Newbury | H15: COMMERCIAL | I15: For Let | J15: Vac-C | K15: 9928 | L15: 45565 | M15: Yes
A16: 222698008 | B16: 222698008 | C16: =VLOOKUP(A16,'DS Tenanted units'!A:A,1,FALSE) -> #N/A | D16: a1G8d0000004qf5EAA | E16: GRML | G16: 4 Station Approach, Weavers Yard, Newbury | H16: COMMERCIAL | I16: For Let | J16: Vac-C | K16: 12274 | L16: 45565 | M16: Yes
A17: 222698009 | B17: 222698009 | C17: =VLOOKUP(A17,'DS Tenanted units'!A:A,1,FALSE) -> #N/A | D17: a1G8d0000004qi3EAA | E17: GRML | G17: 3 Station Approach, Weavers Yard, Newbury | H17: COMMERCIAL | I17: For Let | J17: Vac-C | K17: 12000 | L17: 45565 | M17: Yes
A18: 222707001 | B18: 222707001 | C18: =VLOOKUP(A18,'DS Tenanted units'!A:A,1,FALSE) -> #N/A | D18: a1G8d0000005cWREAY | E18: GRML | G18: Unit 1.1 Redcliffe Quarter, Bristol. BS1 6WL | H18: COMMERCIAL | I18: For Let | J18: Vac-C | K18: 33733 | L18: 45565 | M18: Yes
A19: 222707004 | B19: 222707004 | C19: =VLOOKUP(A19,'DS Tenanted units'!A:A,1,FALSE) -> #N/A | D19: a1G8d0000005cWgEAI | E19: GRML | F19: 365551 | G19: Unit 2.1 Redcliffe Quarter, Bristol. BS1 6WL | H19: COMMERCIAL | I19: For Let | J19: Vac-C | K19: 99858 | L19: 45565 | M19: Yes
A20: 222711002 | B20: 222711002 | C20: =VLOOKUP(A20,'DS Tenanted units'!A:A,1,FALSE) -> #N/A | D20: a1G8d0000005r5fEAA | E20: GRML | G20: Commercial unit 2 Enigma Square | H20: COMMERCIAL | I20: For Let | J20: Vac-C | K20: 26573 | L20: 45565 | M20: Yes
A21: 222711003 | B21: 222711003 | C21: =VLOOKUP(A21,'DS Tenanted units'!A:A,1,FALSE) -> #N/A | D21: a1G8d0000005r5kEAA | E21: GRML | G21: Commercial unit 3 Enigma Square | H21: COMMERCIAL | I21: For Let | J21: Vac-C | K21: 26573 | L21: 45565 | M21: Yes
A22: 222736001 | B22: 222736001 | C22: =VLOOKUP(A22,'DS Tenanted units'!A:A,1,FALSE) -> #N/A | D22: a1G8d000002PHNdEAO | E22: GRML | G22: Copperworks, 5 Capital Quarter, Cardiff | H22: COMMERCIAL | I22: For Let | J22: Vac-C | K22: 35000 | L22: 45565 | M22: Yes
A23: 222746001 | B23: 222746001 | C23: =VLOOKUP(A23,'DS Tenanted units'!A:A,1,FALSE) -> #N/A | D23: a1G8d000002QBVNEA4 | E23: GRML | G23: Commercial unit 1, 18 Silvertown way, London | H23: COMMERCIAL | I23: For Let | J23: Vac-C | K23: 61533 | L23: 45565 | M23: Yes
A24: 222746002 | B24: 222746002 | C24: =VLOOKUP(A24,'DS Tenanted units'!A:A,1,FALSE) -> #N/A | D24: a1G8d000002QBVSEA4 | E24: GRML | G24: Commercial unit 2, 18 Silvertown way, London | H24: COMMERCIAL | I24: For Let | J24: Vac-C | K24: 45020 | L24: 45565 | M24: Yes
A25: 222746003 | B25: 222746003 | C25: =VLOOKUP(A25,'DS Tenanted units'!A:A,1,FALSE) -> #N/A | D25: a1G8d000002QBVXEA4 | E25: GRML | G25: Commercial unit 3, 18 Silvertown way, London | H25: COMMERCIAL | I25: For Let | J25: Vac-C | K25: 31050 | L25: 45565 | M25: Yes
A26: 222746004 | B26: 222746004 | C26: =VLOOKUP(A26,'DS Tenanted units'!A:A,1,FALSE) -> #N/A | D26: a1G8d000002QBVcEAO | E26: GRML | G26: Commercial unit 4, 18 Silvertown way, London | H26: COMMERCIAL | I26: For Let | J26: Vac-C | K26: 61533 | L26: 45565 | M26: Yes
A27: 222746005 | B27: 222746005 | C27: =VLOOKUP(A27,'DS Tenanted units'!A:A,1,FALSE) -> #N/A | D27: a1G8d000002QBVhEAO | E27: GRML | G27: Commercial unit 5, 18 Silvertown way, London | H27: COMMERCIAL | I27: For Let | J27: Vac-C | K27: 103650 | L27: 45565 | M27: Yes
A28: 222757001 | B28: 222757001 | C28: =VLOOKUP(A28,'DS Tenanted units'!A:A,1,FALSE) -> #N/A | D28: a1GNz0000000v37MAA | E28: GRML | F28: 10095947501 | G28: 86 Upper Allen Street, Sheffield | H28: COMMERCIAL | I28: For Let | J28: Vac-C | K28: 9384 | L28: 45565 | M28: Yes
A29: 222761001 | B29: 222761001 | C29: =VLOOKUP(A29,'DS Tenanted units'!A:A,1,FALSE) -> #N/A | D29: a1GNz0000000zgDMAQ | E29: GRML | G29: Commercial unit, 21 Queens Road | H29: COMMERCIAL | I29: For Let | J29: Vac-C | K29: 22500 | L29: 45565 | M29: Yes
A30: 222795001 | B30: 222795001 | C30: =VLOOKUP(A30,'DS Tenanted units'!A:A,1,FALSE) -> #N/A | D30: a1GNz000001HUHFMA4 | E30: GRML | G30: Commercial Unit, 98 Moor Street Queensway | H30: COMMERCIAL | I30: For Let | J30: Vac-C | K30: 33700 | L30: 45565 | M30: Yes
A31: 222808001 | B31: #N/A | C31: =VLOOKUP(A31,'DS Tenanted units'!A:A,1,FALSE) -> #N/A | D31: a1GNz0000054K5KMAU | E31: GRML | F31: 10095640582 | G31: Commerical Approach, 6 Ferry Lane, Tottenham | H31: Commercial | I31: For Let | J31: Vac-C | K31: 17400 | L31: 45565 | M31: Yes
A32: 222813001 | B32: 222813001 | C32: =VLOOKUP(A32,'DS Tenanted units'!A:A,1,FALSE) -> #N/A | D32: a1GNz000006cEcoMAE | E32: GRML | G32: The Kimmeridge Retail Unit 1 | H32: COMMERCIAL | I32: For Let | J32: Vac-C | K32: 80500 | L32: 45645 | M32: Yes
A33: 222813002 | B33: 222813002 | C33: =VLOOKUP(A33,'DS Tenanted units'!A:A,1,FALSE) -> #N/A | D33: a1GNz000006cG0HMAU | E33: GRML | G33: The Kimmeridge Retail Unit 2 | H33: COMMERCIAL | I33: For Let | J33: Vac-C | K33: 33960 | L33: 45645 | M33: Yes
A34: 222813003 | B34: 222813003 | C34: =VLOOKUP(A34,'DS Tenanted units'!A:A,1,FALSE) -> #N/A | D34: a1GNz000006c7eYMAQ | E34: GRML | G34: The Kimmeridge Retail Unit 3 | H34: COMMERCIAL | I34: For Let | J34: Vac-C | K34: 33960 | L34: 45645 | M34: Yes
A35: 222813004 | B35: 222813004 | C35: =VLOOKUP(A35,'DS Tenanted units'!A:A,1,FALSE) -> #N/A | D35: a1GNz000006cG8LMAU | E35: GRML | G35: The Kimmeridge Retail Unit 4 | H35: COMMERCIAL | I35: For Let | J35: Vac-C | K35: 32430 | L35: 45645 | M35: Yes
A36: 222813005 | B36: 222813005 | C36: =VLOOKUP(A36,'DS Tenanted units'!A:A,1,FALSE) -> #N/A | D36: a1GNz000006cENWMA2 | E36: GRML | G36: The Kimmeridge Retail Unit 5 | H36: COMMERCIAL | I36: For Let | J36: Vac-C | K36: 62400 | L36: 45645 | M36: Yes
A37: 222813006 | B37: 222813006 | C37: =VLOOKUP(A37,'DS Tenanted units'!A:A,1,FALSE) -> #N/A | D37: a1GNz000006cGGPMA2 | E37: GRML | G37: The Kimmeridge Retail Unit 6 | H37: COMMERCIAL | I37: For Let | J37: Vac-C | K37: 39180 | L37: 45645 | M37: Yes
A38: 222813007 | B38: 222813007 | C38: =VLOOKUP(A38,'DS Tenanted units'!A:A,1,FALSE) -> #N/A | D38: a1GNz000006cGMrMAM | E38: GRML | G38: The Kimmeridge Retail Unit 7 | H38: COMMERCIAL | I38: For Let | J38: Vac-C | K38: 29880 | L38: 45645 | M38: Yes
A39: 900005001 | B39: 900005001 | C39: =VLOOKUP(A39,'DS Tenanted units'!A:A,1,FALSE) -> #N/A | D39: a1G4J00000260JEUAY | E39: Vesta | F39: 10094370345 | G39: Unit 1, 1 Millet Place, London E16 2YJ | H39: Commercial | I39: For Let | J39: Vac-C | K39: 51731 | L39: 45565 | M39: Yes
A40: 900005002 | B40: 900005002 | C40: =VLOOKUP(A40,'DS Tenanted units'!A:A,1,FALSE) -> #N/A | D40: a1G4J000002605CUAQ | E40: Vesta | F40: 10094370347 | G40: Unit 2, 5 Millet Place, London E16 2YJ | H40: Commercial | I40: For Let | J40: Vac-C | K40: 60000 | L40: 45565 | M40: Yes
...

Sheet DS Tenanted units
A1: Grainger plc
A2: Commercial Units and tenancies 11/02/25
J4: Terms of Lease | Q4: Rent Review | T4: Break Clause
A5: Unit | B5: Unit Description | C5: Type | D5: Tenure | E5: Status | F5: Tenant (parent) | G5: Unit Exists in Salesforce | H5: Salesforce Opportunity | I5: Qube v SF comment | J5: Lease Start Dtae | K5: Lease End date | L5: Lease term-years | M5: Lease term-months | N5: Lease term-days | O5: Vacant due date | P5: Date vacant | Q5: Next rent review | R5: Rent review frequency | S5: Rent Review Required Notiice | T5: Break clause date | U5: landlord breaks | V5: tenant breaks | W5: Years to next break clause | X5: required notice | Y5: months notice-break clause
C6: Field name | J6: leasedate[5] | K6: leasedate[6] | L6: leaseterm[1] | M6: leaseterm[2] | N6: leaseterm[3] | O6: leasedate[4] | P6: leasedate[2] | Q6: leasedate[1] | R6: gap 1[1] | T6: leasedate[8] | U6: whobreaks[1] | V6: whobreaks[2] | W6: gap [6] | X6: notice [4] | Y6: notice [6]
C7: Comment | O7: This field can be ignored-data does not seem to be accurate | P7: This field can be ignored-data does not seem to be accurate
A8: 109866001 | B8: 40/42 Kensington Park Rd G/F & Basement | C8: Commercial | D8: CommLease | E8: Tenanted | F8: Trustees re Sir John Morden | G8: 40/42 Kensington Park Rd G/F & Basement | H8: GREP-CoA Trustees re Sir John Morden - 40/42 Kensington Park Rd G/F & Basement | I8: Dummy Opportunity exists in Salesforce | J8: 40505 | K8: 131815 | L8: 250 | M8: 0 | N8: 0 | O8: n/a | P8: n/a | Q8: n/a | R8: 0 | S8: 0 | T8: =VLOOKUP(A8,#REF!,9,FALSE) -> #REF! | U8: No | V8: No | W8: 0 | X8: 6 | Y8: 0
A9: 109918015 | B9: Berewood - Woodside House Orchard | C9: Commercial | D9: CommLease | E9: Tenanted | F9: Lynda Joy Harding | G9: #N/A | H9: #N/A | I9: Opportunity does not exist in Salesforce | J9: 45426 | K9: 47251 | L9: 5 | M9: 0 | N9: 0 | O9: n/a | P9: n/a | Q9: 46204 | R9: 0 | S9: 0 | T9: =VLOOKUP(A9,#REF!,9,FALSE) -> #REF! | U9: Yes | V9: Yes | W9: 0 | X9: 6 | Y9: 0
A10: 109918017 | B10: Berewood - Berewood Allotment | C10: Commercial | D10: CommLease | E10: Tenanted | F10: Havant Borough Council. | G10: #N/A | H10: #N/A | I10: Opportunity does not exist in Salesforce | J10: 38467 | K10: n/a | L10: 0 | M10: 0 | N10: 0 | O10: n/a | P10: n/a | Q10: n/a | R10: 0 | S10: 0 | T10: =VLOOKUP(A10,#REF!,9,FALSE) -> #REF! | U10: No | V10: No | W10: 0 | X10: 0 | Y10: 0
A11: 109956007 | B11: Telephone Mast 7 Kennel Fm Dummer | C11: Commercial | D11: CommLease | E11: Tenanted | F11: Vodafone Limited. | G11: #N/A | H11: #N/A | I11: Opportunity does not exist in Salesforce | J11: 37728 | K11: 45032 | L11: 20 | M11: 0 | N11: 0 | O11: n/a | P11: n/a | Q11: n/a | R11: 0 | S11: 0 | T11: =VLOOKUP(A11,#REF!,9,FALSE) -> #REF! | U11: No | V11: No | W11: 0 | X11: 0 | Y11: 0
A12: 109961004 | B12: Woodcroft Farm Petersfield Fields Waterloovil | C12: Land | D12: CommLease | E12: Tenanted | F12: Jennifer Ann Manson | G12: Woodcroft Farm Petersfield Fields Waterloovil | H12: GREP-CoA Jennifer Ann Manson - Woodcroft Farm Petersfield Fields Waterloovil | I12: Dummy Opportunity exists in Salesforce | J12: 44859 | K12: 45589 | L12: 2 | M12: 0 | N12: 0 | O12: n/a | P12: n/a | Q12: n/a | R12: 0 | S12: 0 | T12: =VLOOKUP(A12,#REF!,9,FALSE) -> #REF! | U12: No | V12: No | W12: 0 | X12: 0 | Y12: 0
A13: 109961005 | B13: Woodcroft Farm Eastland Gate Fields Waterloov | C13: Land | D13: CommLease | E13: Tenanted | F13: Jennifer A Manson & Caroline J Eastwood | G13: Woodcroft Farm Eastland Gate Fields Waterloov | H13: REP-CoA Jennifer A Manson & Caroline J Eastwood - Woodcroft Farm Eastland Gate Fields Waterloov | I13: Dummy Opportunity exists in Salesforce | J13: 42669 | K13: 46320 | L13: 10 | M13: 0 | N13: 0 | O13: n/a | P13: n/a | Q13: 44495 | R13: 0 | S13: 3 | T13: =VLOOKUP(A13,#REF!,9,FALSE) -> #REF! | U13: Yes | V13: No | W13: 0 | X13: 0 | Y13: 3
A14: 112179001 | B14: Kesgrave - Dev Site | C14: Commercial | D14: CommLease | E14: Tenanted | F14: William Kerr(Farms)Limited. | G14: #N/A | H14: #N/A | I14: Opportunity does not exist in Salesforce | J14: 43739 | K14: 44834 | L14: 3 | M14: 0 | N14: 0 | O14: n/a | P14: n/a | Q14: n/a | R14: 0 | S14: 0 | T14: =VLOOKUP(A14,#REF!,9,FALSE) -> #REF! | U14: No | V14: No | W14: 0 | X14: 0 | Y14: 0
A15: 112179002 | B15: Bell Lane, Kesgrave,Ipswich. Right of Way | C15: Commercial | D15: CommLease | E15: Tenanted | F15: Ipswich Speedway Limited. | G15: #N/A | H15: #N/A | I15: Opportunity does not exist in Salesforce | J15: 42370 | K15: 43100 | L15: 2 | M15: 0 | N15: 0 | O15: n/a | P15: n/a | Q15: n/a | R15: 0 | S15: 0 | T15: =VLOOKUP(A15,#REF!,9,FALSE) -> #REF! | U15: No | V15: No | W15: 0 | X15: 0 | Y15: 0
A16: 113352001 | B16: Unit A, The Old Generator House, Foxall, Ipsw | C16: Commercial | D16: CommLease | E16: Tenanted | F16: Suffolk Aviation Heritage Group. | G16: Unit A, The Old Generator House, Foxall, Ipsw | H16: GREP-CoA Suffolk Aviation Heritage Group - Unit A, The Old Generator House, Foxall, Ipsw | I16: Dummy Opportunity exists in Salesforce | J16: 44697 | K16: 53827 | L16: 25 | M16: 0 | N16: 0 | O16: n/a | P16: n/a | Q16: 46522 | R16: 0 | S16: 12 | T16: =VLOOKUP(A16,#REF!,9,FALSE) -> #REF! | U16: Yes | V16: No | W16: 0 | X16: 6 | Y16: 6
A17: 113352002 | B17: Land @Foxall Martlesham. Telecomm Mast | C17: Land | D17: CommLease | E17: Tenanted | F17: Buz Broadband Limited. | G17: Land @Foxall Martlesham. Telecomm Mast | H17: GREP-CoA Buz Broadband Limited. - Land @Foxall Martlesham. Telecomm Mast | I17: Dummy Opportunity exists in Salesforce | J17: 42324 | K17: 45976 | L17: 10 | M17: 0 | N17: 0 | O17: n/a | P17: n/a | Q17: 43420 | R17: 3 | S17: 6 | T17: =VLOOKUP(A17,#REF!,9,FALSE) -> #REF! | U17: No | V17: No | W17: 0 | X17: 0 | Y17: 0
A18: 122489021 | B18: Aldershot CM0065 McGrigor Barracks Hosp | C18: Commercial | D18: CommLease | E18: Tenanted | F18: Carry Gently Limited. | G18: Aldershot CM0065 McGrigor Barracks Hosp | H18: GREP-CoA Carry Gently Limited. - Aldershot CM0065 McGrigor Barracks Hosp | I18: Dummy Opportunity exists in Salesforce | J18: 45383 | K18: 46477 | L18: 3 | M18: 0 | N18: 0 | O18: n/a | P18: n/a | Q18: n/a | R18: 0 | S18: 3 | T18: =VLOOKUP(A18,#REF!,9,FALSE) -> #REF! | U18: Yes | V18: No | W18: 0 | X18: 0 | Y18: 6
A19: 122489022 | B19: Aldershot TS0031 Resettlement Centre. | C19: Commercial | D19: CommLease | E19: Tenanted | F19: Gold Valley Lake House Limited | G19: Aldershot TS0031 Resettlement Centre. | H19: GREP-CoA Gold Valley Lake House Limited - Aldershot TS0031 Resettlement Centre. | I19: Dummy Opportunity exists in Salesforce | J19: 45292 | K19: 46022 | L19: 2 | M19: 0 | N19: 0 | O19: n/a | P19: n/a | Q19: n/a | R19: 0 | S19: 3 | T19: =VLOOKUP(A19,#REF!,9,FALSE) -> #REF! | U19: Yes | V19: Yes | W19: 0 | X19: 0 | Y19: 6
A20: 122489023 | B20: Aldershot TS0108 Resettlement Centre | C20: Commercial | D20: CommLease | E20: Tenanted | F20: Mixed Freight Services Limited. | G20: #N/A | H20: #N/A | I20: Opportunity does not exist in Salesforce | J20: 42430 | K20: n/a | L20: 0 | M20: 0 | N20: 0 | O20: n/a | P20: n/a | Q20: n/a | R20: 0 | S20: 0 | T20: =VLOOKUP(A20,#REF!,9,FALSE) -> #REF! | U20: No | V20: No | W20: 0 | X20: 0 | Y20: 0
A21: 122489024 | B21: Aldershot TS0106 Resettlement Centre | C21: Commercial | D21: CommLease | E21: Tenanted | F21: Charters of Aldershot. | G21: #N/A | H21: #N/A | I21: Opportunity does not exist in Salesforce | J21: 45292 | K21: 46387 | L21: 3 | M21: 0 | N21: 0 | O21: n/a | P21: n/a | Q21: n/a | R21: 0 | S21: 0 | T21: =VLOOKUP(A21,#REF!,9,FALSE) -> #REF! | U21: No | V21: No | W21: 0 | X21: 6 | Y21: 0
A22: 122489025 | B22: Aldershot RV0032 Resettlement Centre/ Galwey | C22: Commercial | D22: CommLease | E22: Tenanted | F22: Yeomans Limited | G22: Aldershot RV0032 Resettlement Centre/ Galwey | H22: GREP-CoA Yeomans Limited - Aldershot RV0032 Resettlement Centre/ Galwey | I22: Dummy Opportunity exists in Salesforce | J22: 45658 | K22: 46477 | L22: 2 | M22: 3 | N22: 0 | O22: n/a | P22: n/a | Q22: n/a | R22: 0 | S22: 0 | T22: =VLOOKUP(A22,#REF!,9,FALSE) -> #REF! | U22: Yes | V22: Yes | W22: 0 | X22: 6 | Y22: 0
A23: 122489028 | B23: Aldershot RV0035 RAVC Building 8’ | C23: Commercial | D23: CommLease | E23: Tenanted | F23: Millgrove Construction Ltd | G23: #N/A | H23: #N/A | I23: Opportunity does not exist in Salesforce | J23: 44743 | K23: 45838 | L23: 3 | M23: 0 | N23: 0 | O23: n/a | P23: n/a | Q23: 45658 | R23: 0 | S23: 0 | T23: =VLOOKUP(A23,#REF!,9,FALSE) -> #REF! | U23: Yes | V23: Yes | W23: 0 | X23: 6 | Y23: 0
A24: 122489032 | B24: Storage and Hardstanding at Fitzwygram House | C24: Commercial | D24: CommLease | E24: Tenanted | F24: Paul Winch | G24: Storage and Hardstanding at Fitzwygram House | H24: REP-CoA Paul Winch - Storage and Hardstanding at Fitzwygram House | I24: Dummy Opportunity exists in Salesforce | J24: 44927 | K24: 45657 | L24: 2 | M24: 0 | N24: 0 | O24: n/a | P24: n/a | Q24: n/a | R24: 0 | S24: 0 | T24: =VLOOKUP(A24,#REF!,9,FALSE) -> #REF! | U24: Yes | V24: Yes | W24: 0 | X24: 6 | Y24: 0
A25: 122494014 | B25: Aldershot BG0091 BROWNING Drill Shed 19A | C25: Commercial | D25: CommLease | E25: Tenanted | F25: Woodend Removals. | G25: Aldershot BG0091 BROWNING Drill Shed 19A | H25: GREP-CoA Woodend Removals. - Aldershot BG0091 BROWNING Drill Shed 19A | I25: Dummy Opportunity exists in Salesforce | J25: 45292 | K25: 46022 | L25: 2 | M25: 0 | N25: 0 | O25: n/a | P25: n/a | Q25: n/a | R25: 0 | S25: 0 | T25: =VLOOKUP(A25,#REF!,9,FALSE) -> #REF! | U25: Yes | V25: Yes | W25: 0 | X25: 6 | Y25: 0
A26: 122494018 | B26: Aldershot BGA092 BROWNING 14 DOORS. | C26: Commercial | D26: CommLease | E26: Tenanted | F26: Express Transport (UK) Ltd | G26: Aldershot BGA092 BROWNING 14 DOORS UTILITIES. | H26: GREP-CoA Express Transport (UK) Ltd. - Aldershot BGA092 BROWNING 14 DOORS UTILITIES. | I26: Dummy Opportunity exists in Salesforce | J26: 45292 | K26: 46112 | L26: 2 | M26: 3 | N26: 0 | O26: n/a | P26: n/a | Q26: 45658 | R26: 0 | S26: 0 | T26: =VLOOKUP(A26,#REF!,9,FALSE) -> #REF! | U26: Yes | V26: Yes | W26: 0 | X26: 6 | Y26: 6
A27: 122494019 | B27: Aldershot BGD092.11 quartermasters stores | C27: Commercial | D27: CommLease | E27: Tenanted | F27: Trustees of Farnborogh Foodbank | G27: Aldershot BGD092.11 quartermasters stores | H27: GREP-CoA Trustees of Farnborough Foodbank. - Aldershot BGD092.11 quartermasters stores | I27: Dummy Opportunity exists in Salesforce | J27: 44442 | K27: 45291 | L27: 2 | M27: 3 | N27: 29 | O27: n/a | P27: n/a | Q27: n/a | R27: 0 | S27: 0 | T27: =VLOOKUP(A27,#REF!,9,FALSE) -> #REF! | U27: Yes | V27: No | W27: 0 | X27: 6 | Y27: 3
A28: 122494021 | B28: Aldershot BG0088/BG0080 Browning Mess/ac | C28: Commercial | D28: CommLease | E28: Tenanted | F28: Civil Nuclear Police Authority. | G28: #N/A | H28: #N/A | I28: Opportunity does not exist in Salesforce | J28: 45292 | K28: 46112 | L28: 2 | M28: 3 | N28: 0 | O28: n/a | P28: n/a | Q28: n/a | R28: 0 | S28: 0 | T28: =VLOOKUP(A28,#REF!,9,FALSE) -> #REF! | U28: Yes | V28: Yes | W28: 0 | X28: 0 | Y28: 3
A29: 122494022 | B29: Aldershot 2 Grass Open spaceBrowning barracks | C29: Commercial | D29: CommLease | E29: Tenanted | F29: Civil Nuclear Police Authority. | G29: #N/A | H29: #N/A | I29: Opportunity does not exist in Salesforce | J29: 43831 | K29: 45291 | L29: 4 | M29: 0 | N29: 0 | O29: n/a | P29: n/a | Q29: n/a | R29: 0 | S29: 0 | T29: =VLOOKUP(A29,#REF!,9,FALSE) -> #REF! | U29: No | V29: No | W29: 0 | X29: 0 | Y29: 0
A30: 122494025 | B30: Aldershot BG0090 MT Workshop Browning Brks. | C30: Commercial | D30: CommLease | E30: Tenanted | F30: De Angelo Brothers UK Limited. | G30: #N/A | H30: #N/A | I30: Opportunity does not exist in Salesforce | J30: 44927 | K30: 46022 | L30: 3 | M30: 0 | N30: 0 | O30: n/a | P30: n/a | Q30: n/a | R30: 0 | S30: 0 | T30: =VLOOKUP(A30,#REF!,9,FALSE) -> #REF! | U30: No | V30: No | W30: 0 | X30: 0 | Y30: 0
A31: 122494026 | B31: Aldershot BG0094R Portacabin Browning Brks | C31: Commercial | D31: CommLease | E31: Tenanted | F31: APCymru Limited. | G31: #N/A | H31: #N/A | I31: Opportunity does not exist in Salesforce | J31: 45149 | K31: 45879 | L31: 2 | M31: 0 | N31: 0 | O31: n/a | P31: n/a | Q31: n/a | R31: 0 | S31: 0 | T31: =VLOOKUP(A31,#REF!,9,FALSE) -> #REF! | U31: Yes | V31: Yes | W31: 0 | X31: 6 | Y31: 3
A32: 122494027 | B32: Aldershot BGD092 L quartermasters stores | C32: Commercial | D32: CommLease | E32: Tenanted | F32: David Noyes | G32: Aldershot BGD092 L quartermasters stores | I32: Opportunity does not exist in Salesforce | J32: 45658 | K32: 46112 | L32: 1 | M32: 3 | N32: 0 | O32: n/a | P32: n/a | Q32: n/a | R32: 0 | S32: 0 | T32: =VLOOKUP(A32,#REF!,9,FALSE) -> #REF! | U32: Yes | V32: Yes | W32: 0 | X32: 6 | Y32: 0
A33: 122494028 | B33: Aldershot BGD092 R quartermasters stores | C33: Commercial | D33: CommLease | E33: Tenanted | F33: Annek Services Ltd | G33: #N/A | H33: #N/A | I33: Opportunity does not exist in Salesforce | J33: 45177 | K33: 46082 | L33: 2 | M33: 5 | N33: 22 | O33: n/a | P33: n/a | Q33: 45908 | R33: 0 | S33: 0 | T33: =VLOOKUP(A33,#REF!,9,FALSE) -> #REF! | U33: Yes | V33: Yes | W33: 0 | X33: 6 | Y33: 0
A34: 122494029 | B34: Aldershot BGD092.17 quartermasters stores | C34: Commercial | D34: CommLease | E34: Tenanted | F34: The Source Young Peoples Charity. | G34: Aldershot BGD092.17 quartermasters stores | H34: GREP-CoA The Source Young Peoples Charity. - Aldershot BGD092.17 quartermasters stores | I34: Dummy Opportunity exists in Salesforce | J34: 42200 | K34: n/a | L34: 0 | M34: 0 | N34: 0 | O34: n/a | P34: n/a | Q34: n/a | R34: 0 | S34: 0 | T34: =VLOOKUP(A34,#REF!,9,FALSE) -> #REF! | U34: No | V34: No | W34: 0 | X34: 0 | Y34: 0
A35: 122494036 | B35: Aldershot BGD092 BROWNING quartermasters stor | C35: Commercial | D35: CommLease | E35: Tenanted | F35: Logical Fulfilment Limited. | G35: #N/A | H35: #N/A | I35: Opportunity does not exist in Salesforce | J35: 45292 | K35: 46112 | L35: 2 | M35: 3 | N35: 0 | O35: n/a | P35: n/a | Q35: n/a | R35: 0 | S35: 0 | T35: =VLOOKUP(A35,#REF!,9,FALSE) -> #REF! | U35: Yes | V35: No | W35: 0 | X35: 6 | Y35: 3
A36: 122494041 | B36: Aldershot BGA092 BROWNING 14 DOORS UTILITIES. | C36: Commercial | D36: CommLease | E36: Tenanted | F36: Express Limited | G36: Aldershot BGA092 BROWNING 14 DOORS UTILITIES. | H36: GREP-CoA Express Transport (UK) Ltd. - Aldershot BGA092 BROWNING 14 DOORS UTILITIES. | I36: Dummy Opportunity exists in Salesforce | J36: 43261 | K36: 44721 | L36: 4 | M36: 0 | N36: 0 | O36: n/a | P36: n/a | Q36: n/a | R36: 0 | S36: 0 | T36: =VLOOKUP(A36,#REF!,9,FALSE) -> #REF! | U36: No | V36: No | W36: 0 | X36: 0 | Y36: 0
A37: 122494044 | B37: Aldershot BG0090 MT Workshop Browning Brks. | C37: Commercial | D37: CommLease | E37: Tenanted | F37: Bywell productions ltd. | G37: #N/A | H37: #N/A | I37: Opportunity does not exist in Salesforce | J37: 45292 | K37: 46112 | L37: 2 | M37: 3 | N37: 0 | O37: n/a | P37: n/a | Q37: 45658 | R37: 0 | S37: 0 | T37: =VLOOKUP(A37,#REF!,9,FALSE) -> #REF! | U37: Yes | V37: No | W37: 0 | X37: 3 | Y37: 0
A38: 122495021 | B38: East Car Park at Mandora House. | C38: Commercial | D38: CommLease | E38: Tenanted | F38: Rhino Recovery Ltd | G38: East Car Park at Mandora House. | H38: GREP-CoA Rhino Recovery Ltd - East Car Park at Mandora House. | I38: Dummy Opportunity exists in Salesforce | J38: 45658 | K38: 46022 | L38: 1 | M38: 0 | N38: 0 | O38: n/a | P38: n/a | Q38: n/a | R38: 0 | S38: 0 | T38: =VLOOKUP(A38,#REF!,9,FALSE) -> #REF! | U38: Yes | V38: Yes | W38: 0 | X38: 1 | Y38: 0
A39: 122495023 | B39: Aldershot Mandora Part of West Car Park 1 | C39: Commercial | D39: CommLease | E39: Tenanted | F39: We Buy Any Car Limited | G39: Aldershot Mandora Part of West Car Park 1 | H39: GREP-CoA We Buy Any Car Limited - Aldershot Mandora Part of West Car Park 1 | I39: Dummy Opportunity exists in Salesforce | J39: 45139 | K39: 45657 | L39: 1 | M39: 5 | N39: 0 | O39: n/a | P39: n/a | Q39: n/a | R39: 0 | S39: 0 | T39: =VLOOKUP(A39,#REF!,9,FALSE) -> #REF! | U39: Yes | V39: Yes | W39: 0 | X39: 0 | Y39: 0
A40: 122495025 | B40: Aldershot BL0187 BULLER Block A Offcrs Mess | C40: Commercial | D40: CommLease | E40: Tenanted | F40: Civil Nuclear Police Authority. | G40: #N/A | H40: #N/A | I40: Opportunity does not exist in Salesforce | J40: 45292 | K40: 45930 | L40: 1 | M40: 9 | N40: 0 | O40: n/a | P40: n/a | Q40: n/a | R40: 0 | S40: 0 | T40: =VLOOKUP(A40,#REF!,9,FALSE) -> #REF! | U40: Yes | V40: Yes | W40: 0 | X40: 0 | Y40: 3
A41: 122495033 | B41: Aldershot Buller Barracks PrdGrnd1/hardstndng | C41: Commercial | D41: CommLic | E41: Tenanted | F41: Tercel Medical Group Limited. | G41: #N/A | H41: #N/A | I41: Opportunity does not exist in Salesforce | J41: 45658 | K41: 46022 | L41: 1 | M41: 0 | N41: 0 | O41: n/a | P41: n/a | Q41: n/a | R41: 0 | S41: 0 | T41: =VLOOKUP(A41,#REF!,9,FALSE) -> #REF! | U41: Yes | V41: Yes | W41: 0 | X41: 3 | Y41: 0
...
