Workbook

Sheet Tenancies Per Unit
A1: Unit id | B1: Unit Name | C1: Tenancy id | D1: Start Date | E1: End Date | F1: PMS Reference | G1: Status | H1: Tenancy Status | I1: Tenancy Version | J1: Last Modified Date | K1: Tenancy Frequency | L1: Tenancy Count | M1: Group
A2: a1G4J0000025tqLUAQ | B2: =VLOOKUP(C2, Mappings!F:G, 2, FALSE) -> 6, Fernside Court, Holders Hill Road, Hendon, | C2: 800Pv00000GEoKCIA1 | D2: =VLOOKUP(C2, Mappings!K:L, 2, FALSE) -> 43707 | E2: =VLOOKUP(C2, Mappings!N:O, 2, FALSE) -> 106894 | F2: =VLOOKUP(C2, Mappings!A:B, 2, FALSE) -> 103734021004 | G2: Activated | H2: Current | I2: Current | J2: 2025-04-29T14:11:59.000+0000 | K2: Duplicate | L2: 3 | M2: {=MATCH(A2, _xlfn.UNIQUE(_xlfn._xlws.FILTER(A:A, A:A<>"")), 0)} -> 2
A3: a1G4J0000025tqLUAQ | B3: =VLOOKUP(C3, Mappings!F:G, 2, FALSE) -> 6, Fernside Court, Holders Hill Road, Hendon, | C3: 800Pv00000Fsyg6IAB | D3: =VLOOKUP(C3, Mappings!K:L, 2, FALSE) -> 45778 | E3: =VLOOKUP(C3, Mappings!N:O, 2, FALSE) -> 46507 | F3: =VLOOKUP(C3, Mappings!A:B, 2, FALSE) -> pmsuatsmoke | G3: Draft | H3: Ended | I3: Old | J3: 2025-04-29T13:10:06.000+0000 | K3: Duplicate | L3: 3 | M3: {=MATCH(A3, _xlfn.UNIQUE(_xlfn._xlws.FILTER(A:A, A:A<>"")), 0)} -> 2
A4: a1G4J0000025tqLUAQ | B4: =VLOOKUP(C4, Mappings!F:G, 2, FALSE) -> 6, Fernside Court, Holders Hill Road, Hendon, | C4: 800Pv00000G4jS4IAJ | D4: =VLOOKUP(C4, Mappings!K:L, 2, FALSE) -> 45778 | E4: =VLOOKUP(C4, Mappings!N:O, 2, FALSE) -> 46507 | F4: =VLOOKUP(C4, Mappings!A:B, 2, FALSE) -> sdfghu565432 | G4: Draft | H4: Ended | I4: Old | J4: 2025-04-15T12:23:46.000+0000 | K4: Duplicate | L4: 3 | M4: {=MATCH(A4, _xlfn.UNIQUE(_xlfn._xlws.FILTER(A:A, A:A<>"")), 0)} -> 2
A5: a1G4J0000025tVtUAI | B5: =VLOOKUP(C5, Mappings!F:G, 2, FALSE) -> 75, Victoria Court, Southport, Merseyside | C5: 800Pv00000G4x0LIAR | F5: =VLOOKUP(C5, Mappings!A:B, 2, FALSE) -> 103336078001 | G5: Activated | H5: Current | I5: Current | J5: 2025-04-29T14:14:04.000+0000 | K5: Duplicate | L5: 2 | M5: {=MATCH(A5, _xlfn.UNIQUE(_xlfn._xlws.FILTER(A:A, A:A<>"")), 0)} -> 3
A6: a1G4J0000025tVtUAI | B6: =VLOOKUP(C6, Mappings!F:G, 2, FALSE) -> 75, Victoria Court, Southport, Merseyside | C6: 800Pv00000GEodVIAT | D6: =VLOOKUP(C6, Mappings!K:L, 2, FALSE) -> 28665 | F6: =VLOOKUP(C6, Mappings!A:B, 2, FALSE) -> 103336078002 | G6: Draft | H6: Ended | I6: Old | J6: 2025-04-22T18:41:28.000+0000 | K6: Duplicate | L6: 2 | M6: {=MATCH(A6, _xlfn.UNIQUE(_xlfn._xlws.FILTER(A:A, A:A<>"")), 0)} -> 3
A7: a1G4J0000025u8DUAQ | B7: =VLOOKUP(C7, Mappings!F:G, 2, FALSE) -> 86, Clementina Road, Leyton, London | C7: 800Pv00000GF0HIIA1 | D7: =VLOOKUP(C7, Mappings!K:L, 2, FALSE) -> 30857 | E7: =VLOOKUP(C7, Mappings!N:O, 2, FALSE) -> 76511 | F7: =VLOOKUP(C7, Mappings!A:B, 2, FALSE) -> 104566001003 | G7: Activated | H7: Current | I7: Current | J7: 2025-04-29T14:14:10.000+0000 | K7: Duplicate | L7: 2 | M7: {=MATCH(A7, _xlfn.UNIQUE(_xlfn._xlws.FILTER(A:A, A:A<>"")), 0)} -> 4
A8: a1G4J0000025u8DUAQ | B8: =VLOOKUP(C8, Mappings!F:G, 2, FALSE) -> 86, Clementina Road, Leyton, London | C8: 800Pv00000G4x0MIAR | D8: =VLOOKUP(C8, Mappings!K:L, 2, FALSE) -> 45280 | F8: =VLOOKUP(C8, Mappings!A:B, 2, FALSE) -> 104566001002 | G8: Draft | H8: Ended | I8: Old | J8: 2025-04-15T14:27:12.000+0000 | K8: Duplicate | L8: 2 | M8: {=MATCH(A8, _xlfn.UNIQUE(_xlfn._xlws.FILTER(A:A, A:A<>"")), 0)} -> 4
A9: a1G4J0000025uErUAI | B9: =VLOOKUP(C9, Mappings!F:G, 2, FALSE) -> 12, Chelsea Close, Hampton Hill, Middlesex | C9: 800Pv00000GOv7DIAT | D9: =VLOOKUP(C9, Mappings!K:L, 2, FALSE) -> 40351 | E9: =VLOOKUP(C9, Mappings!N:O, 2, FALSE) -> 86005 | F9: =VLOOKUP(C9, Mappings!A:B, 2, FALSE) -> 104350004005 | G9: Activated | H9: Current | I9: Current | J9: 2025-04-29T14:14:11.000+0000 | K9: Duplicate | L9: 2 | M9: {=MATCH(A9, _xlfn.UNIQUE(_xlfn._xlws.FILTER(A:A, A:A<>"")), 0)} -> 5
A10: a1G4J0000025uErUAI | B10: =VLOOKUP(C10, Mappings!F:G, 2, FALSE) -> 12, Chelsea Close, Hampton Hill, Middlesex | C10: 800Pv00000G4x0OIAR | D10: =VLOOKUP(C10, Mappings!K:L, 2, FALSE) -> 45345 | F10: =VLOOKUP(C10, Mappings!A:B, 2, FALSE) -> 104350004004 | G10: Draft | H10: Ended | I10: Old | J10: 2025-04-22T18:41:28.000+0000 | K10: Duplicate | L10: 2 | M10: {=MATCH(A10, _xlfn.UNIQUE(_xlfn._xlws.FILTER(A:A, A:A<>"")), 0)} -> 5
A11: a1G4J0000025wRDUAY | B11: =VLOOKUP(C11, Mappings!F:G, 2, FALSE) -> 140a, Tanfield Avenue, Neasden, London | C11: 800Pv00000GF0JNIA1 | D11: =VLOOKUP(C11, Mappings!K:L, 2, FALSE) -> 36067 | E11: =VLOOKUP(C11, Mappings!N:O, 2, FALSE) -> 72226 | F11: =VLOOKUP(C11, Mappings!A:B, 2, FALSE) -> 114947002002 | G11: Activated | H11: Current | I11: Current | J11: 2025-04-29T14:11:59.000+0000 | K11: Duplicate | L11: 4 | M11: {=MATCH(A11, _xlfn.UNIQUE(_xlfn._xlws.FILTER(A:A, A:A<>"")), 0)} -> 6
A12: a1G4J0000025wRDUAY | B12: =VLOOKUP(C12, Mappings!F:G, 2, FALSE) -> 140a, Tanfield Avenue, Neasden, London | C12: 800Pv00000G4iMLIAZ | D12: =VLOOKUP(C12, Mappings!K:L, 2, FALSE) -> 45778 | E12: =VLOOKUP(C12, Mappings!N:O, 2, FALSE) -> 46507 | F12: =VLOOKUP(C12, Mappings!A:B, 2, FALSE) -> pms128999 | G12: Draft | H12: Ended | I12: Old | J12: 2025-04-15T12:10:00.000+0000 | K12: Duplicate | L12: 4 | M12: {=MATCH(A12, _xlfn.UNIQUE(_xlfn._xlws.FILTER(A:A, A:A<>"")), 0)} -> 6
A13: a1G4J0000025wRDUAY | B13: =VLOOKUP(C13, Mappings!F:G, 2, FALSE) -> 140a, Tanfield Avenue, Neasden, London | C13: 800Pv00000G4sLcIAJ | D13: =VLOOKUP(C13, Mappings!K:L, 2, FALSE) -> 45778 | E13: =VLOOKUP(C13, Mappings!N:O, 2, FALSE) -> 46507 | F13: =VLOOKUP(C13, Mappings!A:B, 2, FALSE) -> 566576ujhgbv | G13: Draft | H13: Ended | I13: Old | J13: 2025-04-15T12:32:41.000+0000 | K13: Duplicate | L13: 4 | M13: {=MATCH(A13, _xlfn.UNIQUE(_xlfn._xlws.FILTER(A:A, A:A<>"")), 0)} -> 6
A14: a1G4J0000025wRDUAY | B14: =VLOOKUP(C14, Mappings!F:G, 2, FALSE) -> 140a, Tanfield Avenue, Neasden, London | C14: 800Pv00000G4zJqIAJ | D14: =VLOOKUP(C14, Mappings!K:L, 2, FALSE) -> 45778 | E14: =VLOOKUP(C14, Mappings!N:O, 2, FALSE) -> 46507 | F14: =VLOOKUP(C14, Mappings!A:B, 2, FALSE) -> 245364uyjhngbfdgwr | G14: Draft | H14: Ended | I14: Old | J14: 2025-04-15T12:43:09.000+0000 | K14: Duplicate | L14: 4 | M14: {=MATCH(A14, _xlfn.UNIQUE(_xlfn._xlws.FILTER(A:A, A:A<>"")), 0)} -> 6
A15: a1G4J0000025wy1UAA | B15: =VLOOKUP(C15, Mappings!F:G, 2, FALSE) -> 1 Woodward House, Waterlooville, PO7 3BP | C15: 800Pv00000GF1rZIAT | D15: =VLOOKUP(C15, Mappings!K:L, 2, FALSE) -> 45715 | E15: =VLOOKUP(C15, Mappings!N:O, 2, FALSE) -> 48635 | F15: =VLOOKUP(C15, Mappings!A:B, 2, FALSE) -> 222584001005 | G15: Activated | H15: Current | I15: Current | J15: 2025-04-29T14:14:41.000+0000 | K15: Duplicate | L15: 2 | M15: {=MATCH(A15, _xlfn.UNIQUE(_xlfn._xlws.FILTER(A:A, A:A<>"")), 0)} -> 7
A16: a1G4J0000025wy1UAA | B16: =VLOOKUP(C16, Mappings!F:G, 2, FALSE) -> 1 Woodward House, Waterlooville, PO7 3BP | C16: 800Pv00000G4x0YIAR | D16: =VLOOKUP(C16, Mappings!K:L, 2, FALSE) -> 45426 | F16: =VLOOKUP(C16, Mappings!A:B, 2, FALSE) -> 222584001004 | G16: Draft | H16: Ended | I16: Old | J16: 2025-04-15T14:27:12.000+0000 | K16: Duplicate | L16: 2 | M16: {=MATCH(A16, _xlfn.UNIQUE(_xlfn._xlws.FILTER(A:A, A:A<>"")), 0)} -> 7
A17: a1G4J0000025x0wUAA | B17: =VLOOKUP(C17, Mappings!F:G, 2, FALSE) -> Apt 107, Abbeville Apts, 37 London Rd, Barkin | C17: 800Pv00000GF1rdIAD | D17: =VLOOKUP(C17, Mappings!K:L, 2, FALSE) -> 45471 | E17: =VLOOKUP(C17, Mappings!N:O, 2, FALSE) -> 46200 | F17: =VLOOKUP(C17, Mappings!A:B, 2, FALSE) -> 122486009005 | G17: Activated | H17: Current | I17: Current | J17: 2025-04-29T14:11:58.000+0000 | K17: Duplicate | L17: 2 | M17: {=MATCH(A17, _xlfn.UNIQUE(_xlfn._xlws.FILTER(A:A, A:A<>"")), 0)} -> 8
A18: a1G4J0000025x0wUAA | B18: =VLOOKUP(C18, Mappings!F:G, 2, FALSE) -> Apt 107, Abbeville Apts, 37 London Rd, Barkin | C18: 800Pv00000G4x0aIAB | D18: =VLOOKUP(C18, Mappings!K:L, 2, FALSE) -> 45471 | E18: =VLOOKUP(C18, Mappings!N:O, 2, FALSE) -> 46200 | F18: =VLOOKUP(C18, Mappings!A:B, 2, FALSE) -> 122486009004 | G18: Draft | H18: Ended | I18: Old | J18: 2025-04-15T14:26:16.000+0000 | K18: Duplicate | L18: 2 | M18: {=MATCH(A18, _xlfn.UNIQUE(_xlfn._xlws.FILTER(A:A, A:A<>"")), 0)} -> 8
A19: a1G4J0000025x1GUAQ | B19: =VLOOKUP(C19, Mappings!F:G, 2, FALSE) -> Apt 302, Abbeville Apts, 37 London Rd, Barkin | C19: 800Pv00000FzkYUIAZ | D19: =VLOOKUP(C19, Mappings!K:L, 2, FALSE) -> 45240 | E19: =VLOOKUP(C19, Mappings!N:O, 2, FALSE) -> 45605 | F19: =VLOOKUP(C19, Mappings!A:B, 2, FALSE) -> 122486038005 | G19: Activated | H19: Current | I19: Current | J19: 2025-04-29T14:11:58.000+0000 | K19: Duplicate | L19: 2 | M19: {=MATCH(A19, _xlfn.UNIQUE(_xlfn._xlws.FILTER(A:A, A:A<>"")), 0)} -> 9
A20: a1G4J0000025x1GUAQ | B20: =VLOOKUP(C20, Mappings!F:G, 2, FALSE) -> Apt 302, Abbeville Apts, 37 London Rd, Barkin | C20: 800Pv00000GEtDzIAL | D20: =VLOOKUP(C20, Mappings!K:L, 2, FALSE) -> 45240 | E20: =VLOOKUP(C20, Mappings!N:O, 2, FALSE) -> 45605 | F20: =VLOOKUP(C20, Mappings!A:B, 2, FALSE) -> 122486038003 | G20: Draft | H20: Ended | I20: Old | J20: 2025-04-29T13:16:29.000+0000 | K20: Duplicate | L20: 2 | M20: {=MATCH(A20, _xlfn.UNIQUE(_xlfn._xlws.FILTER(A:A, A:A<>"")), 0)} -> 9
A21: a1G4J0000025x6gUAA | B21: =VLOOKUP(C21, Mappings!F:G, 2, FALSE) -> Flat 24, Cooke Place, Block E, Salford, M5 | C21: 800Pv00000G4x0eIAB | D21: =VLOOKUP(C21, Mappings!K:L, 2, FALSE) -> 45728 | E21: =VLOOKUP(C21, Mappings!N:O, 2, FALSE) -> 46095 | F21: =VLOOKUP(C21, Mappings!A:B, 2, FALSE) -> 122601026006 | G21: Activated | H21: Current | I21: Current | J21: 2025-04-29T14:11:58.000+0000 | K21: Duplicate | L21: 2 | M21: {=MATCH(A21, _xlfn.UNIQUE(_xlfn._xlws.FILTER(A:A, A:A<>"")), 0)} -> 10
A22: a1G4J0000025x6gUAA | B22: =VLOOKUP(C22, Mappings!F:G, 2, FALSE) -> Flat 24, Cooke Place, Block E, Salford, M5 | C22: 800Pv00000FHJTrIAP | D22: =VLOOKUP(C22, Mappings!K:L, 2, FALSE) -> 45731 | F22: =VLOOKUP(C22, Mappings!A:B, 2, FALSE) -> 122601026007 | G22: Draft | H22: Ended | I22: Old | J22: 2025-04-09T13:31:35.000+0000 | K22: Duplicate | L22: 2 | M22: {=MATCH(A22, _xlfn.UNIQUE(_xlfn._xlws.FILTER(A:A, A:A<>"")), 0)} -> 10
A23: a1G4J0000025xe1UAA | B23: =VLOOKUP(C23, Mappings!F:G, 2, FALSE) -> 5 Dorrell Apt, Darbyshire Rd, Aldershot, Hant | C23: 800Pv00000GEm71IAD | D23: =VLOOKUP(C23, Mappings!K:L, 2, FALSE) -> 45454 | E23: =VLOOKUP(C23, Mappings!N:O, 2, FALSE) -> 45818 | F23: =VLOOKUP(C23, Mappings!A:B, 2, FALSE) -> 222606005003 | G23: Activated | H23: Current | I23: Current | J23: 2025-04-29T14:12:13.000+0000 | K23: Duplicate | L23: 2 | M23: {=MATCH(A23, _xlfn.UNIQUE(_xlfn._xlws.FILTER(A:A, A:A<>"")), 0)} -> 11
A24: a1G4J0000025xe1UAA | B24: =VLOOKUP(C24, Mappings!F:G, 2, FALSE) -> 5 Dorrell Apt, Darbyshire Rd, Aldershot, Hant | C24: 800Pv00000G4x0nIAB | D24: =VLOOKUP(C24, Mappings!K:L, 2, FALSE) -> 45454 | E24: =VLOOKUP(C24, Mappings!N:O, 2, FALSE) -> 45819 | F24: =VLOOKUP(C24, Mappings!A:B, 2, FALSE) -> 222606005002 | G24: Draft | H24: Ended | I24: Old | J24: 2025-04-15T14:26:17.000+0000 | K24: Duplicate | L24: 2 | M24: {=MATCH(A24, _xlfn.UNIQUE(_xlfn._xlws.FILTER(A:A, A:A<>"")), 0)} -> 11
A25: a1G4J0000025xFhUAI | B25: =VLOOKUP(C25, Mappings!F:G, 2, FALSE) -> 22 Nevinson Way, Waterlooville, Hampshire | C25: 800Pv00000GEqyAIAT | D25: =VLOOKUP(C25, Mappings!K:L, 2, FALSE) -> 43882 | E25: =VLOOKUP(C25, Mappings!N:O, 2, FALSE) -> 46073 | F25: =VLOOKUP(C25, Mappings!A:B, 2, FALSE) -> 127166001004 | G25: Activated | H25: Current | I25: Current | J25: 2025-04-29T14:14:42.000+0000 | K25: Duplicate | L25: 2 | M25: {=MATCH(A25, _xlfn.UNIQUE(_xlfn._xlws.FILTER(A:A, A:A<>"")), 0)} -> 12
A26: a1G4J0000025xFhUAI | B26: =VLOOKUP(C26, Mappings!F:G, 2, FALSE) -> 22 Nevinson Way, Waterlooville, Hampshire | C26: 800Pv00000G4ok1IAB | D26: =VLOOKUP(C26, Mappings!K:L, 2, FALSE) -> 43882 | F26: =VLOOKUP(C26, Mappings!A:B, 2, FALSE) -> 127166001001 | G26: Draft | H26: Ended | I26: Old | J26: 2025-04-29T13:12:57.000+0000 | K26: Duplicate | L26: 2 | M26: {=MATCH(A26, _xlfn.UNIQUE(_xlfn._xlws.FILTER(A:A, A:A<>"")), 0)} -> 12
A27: a1G4J0000025xFwUAI | B27: =VLOOKUP(C27, Mappings!F:G, 2, FALSE) -> GR-Apt 117, Kings Dock Mill, Liverpool, L1 | C27: 800Pv00000G4ok4IAB | D27: =VLOOKUP(C27, Mappings!K:L, 2, FALSE) -> 39420 | E27: =VLOOKUP(C27, Mappings!N:O, 2, FALSE) -> 94203 | F27: =VLOOKUP(C27, Mappings!A:B, 2, FALSE) -> 127057116002 | G27: Activated | H27: Current | I27: Current | J27: 2025-04-29T14:14:42.000+0000 | K27: Duplicate | L27: 2 | M27: {=MATCH(A27, _xlfn.UNIQUE(_xlfn._xlws.FILTER(A:A, A:A<>"")), 0)} -> 13
A28: a1G4J0000025xFwUAI | B28: =VLOOKUP(C28, Mappings!F:G, 2, FALSE) -> GR-Apt 117, Kings Dock Mill, Liverpool, L1 | C28: 800Pv00000GEqyGIAT | F28: =VLOOKUP(C28, Mappings!A:B, 2, FALSE) -> 127057116001 | G28: Draft | H28: Ended | I28: Old | J28: 2025-04-29T13:16:12.000+0000 | K28: Duplicate | L28: 2 | M28: {=MATCH(A28, _xlfn.UNIQUE(_xlfn._xlws.FILTER(A:A, A:A<>"")), 0)} -> 13
A29: a1G4J0000025xFXUAY | B29: =VLOOKUP(C29, Mappings!F:G, 2, FALSE) -> Bay 13, Kings Dock Mill, Liverpool, L1 | C29: 800Pv00000GEzs2IAD | D29: =VLOOKUP(C29, Mappings!K:L, 2, FALSE) -> 45392 | E29: =VLOOKUP(C29, Mappings!N:O, 2, FALSE) -> 45756 | F29: =VLOOKUP(C29, Mappings!A:B, 2, FALSE) -> 127057205007 | G29: Activated | H29: Current | I29: Current | J29: 2025-04-29T14:11:58.000+0000 | K29: Duplicate | L29: 2 | M29: {=MATCH(A29, _xlfn.UNIQUE(_xlfn._xlws.FILTER(A:A, A:A<>"")), 0)} -> 14
A30: a1G4J0000025xFXUAY | B30: =VLOOKUP(C30, Mappings!F:G, 2, FALSE) -> Bay 13, Kings Dock Mill, Liverpool, L1 | C30: 800Pv00000G51aIIAR | D30: =VLOOKUP(C30, Mappings!K:L, 2, FALSE) -> 45392 | E30: =VLOOKUP(C30, Mappings!N:O, 2, FALSE) -> 45756 | F30: =VLOOKUP(C30, Mappings!A:B, 2, FALSE) -> 127057205008 | G30: Draft | H30: Ended | I30: Old | J30: 2025-04-29T13:12:39.000+0000 | K30: Duplicate | L30: 2 | M30: {=MATCH(A30, _xlfn.UNIQUE(_xlfn._xlws.FILTER(A:A, A:A<>"")), 0)} -> 14
A31: a1G4J0000025xheUAA | B31: =VLOOKUP(C31, Mappings!F:G, 2, FALSE) -> Car Park Bay 47, Carey Lane | C31: 800Pv00000GEvlwIAD | D31: =VLOOKUP(C31, Mappings!K:L, 2, FALSE) -> 44646 | E31: =VLOOKUP(C31, Mappings!N:O, 2, FALSE) -> 45010 | F31: =VLOOKUP(C31, Mappings!A:B, 2, FALSE) -> 222531002002 | G31: Activated | H31: Current | I31: Current | J31: 2025-04-29T14:14:45.000+0000 | K31: Duplicate | L31: 2 | M31: {=MATCH(A31, _xlfn.UNIQUE(_xlfn._xlws.FILTER(A:A, A:A<>"")), 0)} -> 15
A32: a1G4J0000025xheUAA | B32: =VLOOKUP(C32, Mappings!F:G, 2, FALSE) -> Car Park Bay 47, Carey Lane | C32: 800Pv00000G54GRIAZ | D32: =VLOOKUP(C32, Mappings!K:L, 2, FALSE) -> 44646 | F32: =VLOOKUP(C32, Mappings!A:B, 2, FALSE) -> 222531002001 | G32: Draft | H32: Ended | I32: Old | J32: 2025-04-29T13:13:32.000+0000 | K32: Duplicate | L32: 2 | M32: {=MATCH(A32, _xlfn.UNIQUE(_xlfn._xlws.FILTER(A:A, A:A<>"")), 0)} -> 15
A33: a1G4J0000025xI9UAI | B33: =VLOOKUP(C33, Mappings!F:G, 2, FALSE) -> 305 Tayleur Apt , Waterman Wlk, Salford M50 | C33: 800Pv00000G4x0hIAB | D33: =VLOOKUP(C33, Mappings!K:L, 2, FALSE) -> 45365 | E33: =VLOOKUP(C33, Mappings!N:O, 2, FALSE) -> 45729 | F33: =VLOOKUP(C33, Mappings!A:B, 2, FALSE) -> 222580017003 | G33: Activated | H33: Current | I33: Current | J33: 2025-04-29T14:12:12.000+0000 | K33: Duplicate | L33: 2 | M33: {=MATCH(A33, _xlfn.UNIQUE(_xlfn._xlws.FILTER(A:A, A:A<>"")), 0)} -> 16
A34: a1G4J0000025xI9UAI | B34: =VLOOKUP(C34, Mappings!F:G, 2, FALSE) -> 305 Tayleur Apt , Waterman Wlk, Salford M50 | C34: 800Pv00000GF1ruIAD | D34: =VLOOKUP(C34, Mappings!K:L, 2, FALSE) -> 45365 | E34: =VLOOKUP(C34, Mappings!N:O, 2, FALSE) -> 45729 | F34: =VLOOKUP(C34, Mappings!A:B, 2, FALSE) -> 222580017004 | G34: Draft | H34: Ended | I34: Old | J34: 2025-04-29T13:30:16.000+0000 | K34: Duplicate | L34: 2 | M34: {=MATCH(A34, _xlfn.UNIQUE(_xlfn._xlws.FILTER(A:A, A:A<>"")), 0)} -> 16
A35: a1G4J0000025xnnUAA | B35: =VLOOKUP(C35, Mappings!F:G, 2, FALSE) -> 611 Syren Apt , Ottinger Close, Salford M50 | C35: 800Pv00000GEm7EIAT | D35: =VLOOKUP(C35, Mappings!K:L, 2, FALSE) -> 45481 | E35: =VLOOKUP(C35, Mappings!N:O, 2, FALSE) -> 45845 | F35: =VLOOKUP(C35, Mappings!A:B, 2, FALSE) -> 222581076004 | G35: Activated | H35: Current | I35: Current | J35: 2025-04-29T14:12:12.000+0000 | K35: Duplicate | L35: 2 | M35: {=MATCH(A35, _xlfn.UNIQUE(_xlfn._xlws.FILTER(A:A, A:A<>"")), 0)} -> 17
A36: a1G4J0000025xnnUAA | B36: =VLOOKUP(C36, Mappings!F:G, 2, FALSE) -> 611 Syren Apt , Ottinger Close, Salford M50 | C36: 800Pv00000G4x0uIAB | D36: =VLOOKUP(C36, Mappings!K:L, 2, FALSE) -> 45481 | E36: =VLOOKUP(C36, Mappings!N:O, 2, FALSE) -> 45845 | F36: =VLOOKUP(C36, Mappings!A:B, 2, FALSE) -> 222581076003 | G36: Draft | H36: Ended | I36: Old | J36: 2025-04-15T14:26:26.000+0000 | K36: Duplicate | L36: 2 | M36: {=MATCH(A36, _xlfn.UNIQUE(_xlfn._xlws.FILTER(A:A, A:A<>"")), 0)} -> 17
A37: a1G4J0000025xoHUAQ | B37: =VLOOKUP(C37, Mappings!F:G, 2, FALSE) -> Clippers - Unit 1 Zerega Way M50 | C37: 800Pv00000GOrhwIAD | D37: =VLOOKUP(C37, Mappings!K:L, 2, FALSE) -> 45449 | E37: =VLOOKUP(C37, Mappings!N:O, 2, FALSE) -> 49100 | F37: =VLOOKUP(C37, Mappings!A:B, 2, FALSE) -> 222577002002 | G37: Activated | H37: Current | I37: Current | J37: 2025-04-29T14:14:45.000+0000 | K37: Duplicate | L37: 2 | M37: {=MATCH(A37, _xlfn.UNIQUE(_xlfn._xlws.FILTER(A:A, A:A<>"")), 0)} -> 18
A38: a1G4J0000025xoHUAQ | B38: =VLOOKUP(C38, Mappings!F:G, 2, FALSE) -> Clippers - Unit 1 Zerega Way M50 | C38: 800Pv00000G54GmIAJ | D38: =VLOOKUP(C38, Mappings!K:L, 2, FALSE) -> 45838 | E38: =VLOOKUP(C38, Mappings!N:O, 2, FALSE) -> 53142 | F38: =VLOOKUP(C38, Mappings!A:B, 2, FALSE) -> 222577002001 | G38: Draft | H38: Ended | I38: Old | J38: 2025-04-29T13:13:32.000+0000 | K38: Duplicate | L38: 2 | M38: {=MATCH(A38, _xlfn.UNIQUE(_xlfn._xlws.FILTER(A:A, A:A<>"")), 0)} -> 18
A39: a1G4J0000025xpjUAA | B39: =VLOOKUP(C39, Mappings!F:G, 2, FALSE) -> 44, New Islington, 43 Chippenham Road, M4 6BY | C39: 800Pv00000G4x0vIAB | D39: =VLOOKUP(C39, Mappings!K:L, 2, FALSE) -> 45464 | E39: =VLOOKUP(C39, Mappings!N:O, 2, FALSE) -> 45828 | F39: =VLOOKUP(C39, Mappings!A:B, 2, FALSE) -> 222521044005 | G39: Activated | H39: Current | I39: Current | J39: 2025-04-29T14:15:13.000+0000 | K39: Duplicate | L39: 2 | M39: {=MATCH(A39, _xlfn.UNIQUE(_xlfn._xlws.FILTER(A:A, A:A<>"")), 0)} -> 19
A40: a1G4J0000025xpjUAA | B40: =VLOOKUP(C40, Mappings!F:G, 2, FALSE) -> 44, New Islington, 43 Chippenham Road, M4 6BY | C40: 800Pv00000GEm7FIAT | D40: =VLOOKUP(C40, Mappings!K:L, 2, FALSE) -> 45464 | E40: =VLOOKUP(C40, Mappings!N:O, 2, FALSE) -> 45828 | F40: =VLOOKUP(C40, Mappings!A:B, 2, FALSE) -> 222521044006 | G40: Draft | H40: Ended | I40: Old | J40: 2025-04-29T13:14:43.000+0000 | K40: Duplicate | L40: 2 | M40: {=MATCH(A40, _xlfn.UNIQUE(_xlfn._xlws.FILTER(A:A, A:A<>"")), 0)} -> 19
...

Sheet Pivot
A3: Row Labels | B3: Count of Tenancy id
A4: a1G4J0000025tqLUAQ | B4: 3
A5: 800Pv00000Fsyg6IAB | B5: 1
A6: Old | B6: 1
A7: 800Pv00000G4jS4IAJ | B7: 1
A8: Old | B8: 1
A9: 800Pv00000GEoKCIA1 | B9: 1
A10: Current | B10: 1
A11: a1G4J0000025tVtUAI | B11: 2
A12: 800Pv00000G4x0LIAR | B12: 1
A13: Current | B13: 1
A14: 800Pv00000GEodVIAT | B14: 1
A15: Old | B15: 1
... A405: Grand Total | B405: 161

Sheet Unmapped Tenancies
A1: Tenancy id | B1: Unit id | C1: Status | D1: Tenancy Status | F1: Last Modified Date | G1: Tenancy Frequency | H1: Tenancy Count
A2: 800Pv00000GEodVIAT | B2: a1G4J0000025tVtUAI | C2: Draft | D2: Ended | E2: =IF(I2=_xlfn.MAXIFS(I:I, B:B, B2), "Current", "Old") -> Old | F2: 2025-04-22T18:41:28.000+0000 | G2: =IF(COUNTIF(B:B, B2) > 1, "Duplicate", "Unique") -> Duplicate | H2: =COUNTIF(B:B, B2) -> 2 | I2: =--SUBSTITUTE(LEFT(F2,19),"T"," ") -> 45769.779
A3: 800Pv00000G4x0LIAR | B3: a1G4J0000025tVtUAI | C3: Activated | D3: Current | E3: =IF(I3=_xlfn.MAXIFS(I:I, B:B, B3), "Current", "Old") -> Current | F3: 2025-04-29T14:14:04.000+0000 | G3: =IF(COUNTIF(B:B, B3) > 1, "Duplicate", "Unique") -> Duplicate | H3: =COUNTIF(B:B, B3) -> 2 | I3: =--SUBSTITUTE(LEFT(F3,19),"T"," ") -> 45776.593
A4: 800Pv00000G4vusIAB | B4: a1G4J0000025tVuUAI | C4: Activated | D4: Current | F4: 2025-04-29T14:14:04.000+0000 | G4: =IF(COUNTIF(B:B, B4) > 1, "Duplicate", "Unique") -> Unique
A5: 800Pv00000FzmItIAJ | B5: a1G4J0000025tVvUAI | C5: Activated | D5: Current | F5: 2025-04-29T14:14:04.000+0000 | G5: =IF(COUNTIF(B:B, B5) > 1, "Duplicate", "Unique") -> Unique
A6: 800Pv00000GEoeEIAT | B6: a1G4J0000025tVwUAI | C6: Activated | D6: Current | F6: 2025-04-29T14:14:04.000+0000 | G6: =IF(COUNTIF(B:B, B6) > 1, "Duplicate", "Unique") -> Unique
A7: 800Pv00000GEoeFIAT | B7: a1G4J0000025tVxUAI | C7: Activated | D7: Current | F7: 2025-04-29T14:14:04.000+0000 | G7: =IF(COUNTIF(B:B, B7) > 1, "Duplicate", "Unique") -> Unique
A8: 800Pv00000G53g5IAB | B8: a1G4J0000025tW0UAI | C8: Activated | D8: Current | F8: 2025-04-29T14:14:04.000+0000 | G8: =IF(COUNTIF(B:B, B8) > 1, "Duplicate", "Unique") -> Unique
A9: 800Pv00000GEoeGIAT | B9: a1G4J0000025tW1UAI | C9: Activated | D9: Current | F9: 2025-04-29T14:14:04.000+0000 | G9: =IF(COUNTIF(B:B, B9) > 1, "Duplicate", "Unique") -> Unique
A10: 800Pv00000GEoeHIAT | B10: a1G4J0000025tW2UAI | C10: Activated | D10: Current | F10: 2025-04-29T14:14:04.000+0000 | G10: =IF(COUNTIF(B:B, B10) > 1, "Duplicate", "Unique") -> Unique
A11: 800Pv00000GEoeIIAT | B11: a1G4J0000025tW5UAI | C11: Activated | D11: Current | F11: 2025-04-29T14:18:20.000+0000 | G11: =IF(COUNTIF(B:B, B11) > 1, "Duplicate", "Unique") -> Unique
A12: 800Pv00000FzmIxIAJ | B12: a1G4J0000025tW6UAI | C12: Activated | D12: Current | F12: 2025-04-29T14:14:04.000+0000 | G12: =IF(COUNTIF(B:B, B12) > 1, "Duplicate", "Unique") -> Unique
A13: 800Pv00000GEoeJIAT | B13: a1G4J0000025tW7UAI | C13: Activated | D13: Current | F13: 2025-04-29T14:14:04.000+0000 | G13: =IF(COUNTIF(B:B, B13) > 1, "Duplicate", "Unique") -> Unique
A14: 800Pv00000FzmIzIAJ | B14: a1G4J0000025tW9UAI | C14: Activated | D14: Current | F14: 2025-04-29T14:14:04.000+0000 | G14: =IF(COUNTIF(B:B, B14) > 1, "Duplicate", "Unique") -> Unique
A15: 800Pv00000GEoeKIAT | B15: a1G4J0000025tWAUAY | C15: Activated | D15: Current | F15: 2025-04-29T14:14:04.000+0000 | G15: =IF(COUNTIF(B:B, B15) > 1, "Duplicate", "Unique") -> Unique
... A524: 800Pv00000GEoKBIA1 | B524: a1G4J0000025tqKUAQ | C524: Activated | D524: Current | F524: 2025-04-29T14:14:08.000+0000 | G524: =IF(COUNTIF(B:B, B524) > 1, "Duplicate", "Unique") -> Unique
A525: 800Pv00000Fsyg6IAB | B525: a1G4J0000025tqLUAQ | C525: Draft | D525: Ended | E525: =IF(I525=_xlfn.MAXIFS(I:I, B:B, B525), "Current", "Old") -> Old | F525: 2025-04-29T13:10:06.000+0000 | G525: =IF(COUNTIF(B:B, B525) > 1, "Duplicate", "Unique") -> Duplicate | H525: =COUNTIF(B:B, B525) -> 3 | I525: =--SUBSTITUTE(LEFT(F525,19),"T"," ") -> 45776.549
A526: 800Pv00000GEoKCIA1 | B526: a1G4J0000025tqLUAQ | C526: Activated | D526: Current | E526: =IF(I526=_xlfn.MAXIFS(I:I, B:B, B526), "Current", "Old") -> Current | F526: 2025-04-29T14:11:59.000+0000 | G526: =IF(COUNTIF(B:B, B526) > 1, "Duplicate", "Unique") -> Duplicate | H526: =COUNTIF(B:B, B526) -> 3 | I526: =--SUBSTITUTE(LEFT(F526,19),"T"," ") -> 45776.592
A527: 800Pv00000G4jS4IAJ | B527: a1G4J0000025tqLUAQ | C527: Draft | D527: Ended | E527: =IF(I527=_xlfn.MAXIFS(I:I, B:B, B527), "Current", "Old") -> Old | F527: 2025-04-15T12:23:46.000+0000 | G527: =IF(COUNTIF(B:B, B527) > 1, "Duplicate", "Unique") -> Duplicate | H527: =COUNTIF(B:B, B527) -> 3 | I527: =--SUBSTITUTE(LEFT(F527,19),"T"," ") -> 45762.517
A528: 800Pv00000GEoKDIA1 | B528: a1G4J0000025tqNUAQ | C528: Activated | D528: Current | F528: 2025-04-29T14:14:08.000+0000 | G528: =IF(COUNTIF(B:B, B528) > 1, "Duplicate", "Unique") -> Unique
A529: 800Pv00000GEoKEIA1 | B529: a1G4J0000025tqOUAQ | C529: Activated | D529: Current | F529: 2025-04-29T14:14:08.000+0000 | G529: =IF(COUNTIF(B:B, B529) > 1, "Duplicate", "Unique") -> Unique
A530: 800Pv00000G55atIAB | B530: a1G4J0000025tqPUAQ | C530: Activated | D530: Current | F530: 2025-04-29T14:14:08.000+0000 | G530: =IF(COUNTIF(B:B, B530) > 1, "Duplicate", "Unique") -> Unique
A531: 800Pv00000GEoKGIA1 | B531: a1G4J0000025tqQUAQ | C531: Activated | D531: Current | F531: 2025-04-29T14:14:08.000+0000 | G531: =IF(COUNTIF(B:B, B531) > 1, "Duplicate", "Unique") -> Unique
A532: 800Pv00000G55D5IAJ | B532: a1G4J0000025tqUUAQ | C532: Activated | D532: Current | F532: 2025-04-29T14:14:08.000+0000 | G532: =IF(COUNTIF(B:B, B532) > 1, "Duplicate", "Unique") -> Unique
A533: 800Pv00000G55auIAB | B533: a1G4J0000025tqZUAQ | C533: Activated | D533: Current | F533: 2025-04-29T14:14:08.000+0000 | G533: =IF(COUNTIF(B:B, B533) > 1, "Duplicate", "Unique") -> Unique
A534: 800Pv00000GEoKHIA1 | B534: a1G4J0000025tqaUAA | C534: Activated | D534: Current | F534: 2025-04-29T14:14:08.000+0000 | G534: =IF(COUNTIF(B:B, B534) > 1, "Duplicate", "Unique") -> Unique
A535: 800Pv00000FzrUQIAZ | B535: a1G4J0000025tqbUAA | C535: Activated | D535: Current | F535: 2025-04-29T14:14:08.000+0000 | G535: =IF(COUNTIF(B:B, B535) > 1, "Duplicate", "Unique") -> Unique
A536: 800Pv00000GEoKIIA1 | B536: a1G4J0000025tqeUAA | C536: Activated | D536: Current | F536: 2025-04-29T14:18:20.000+0000 | G536: =IF(COUNTIF(B:B, B536) > 1, "Duplicate", "Unique") -> Unique
A537: 800Pv00000GEoKJIA1 | B537: a1G4J0000025tqgUAA | C537: Activated | D537: Current | F537: 2025-04-29T14:14:08.000+0000 | G537: =IF(COUNTIF(B:B, B537) > 1, "Duplicate", "Unique") -> Unique
A538: 800Pv00000GEoKKIA1 | B538: a1G4J0000025tqhUAA | C538: Activated | D538: Current | F538: 2025-04-29T14:14:08.000+0000 | G538: =IF(COUNTIF(B:B, B538) > 1, "Duplicate", "Unique") -> Unique
A539: 800Pv00000GEoKLIA1 | B539: a1G4J0000025tqkUAA | C539: Activated | D539: Current | F539: 2025-04-29T14:14:08.000+0000 | G539: =IF(COUNTIF(B:B, B539) > 1, "Duplicate", "Unique") -> Unique
... A1062: 800Pv00000GF02KIAT | B1062: a1G4J0000025u8CUAQ | C1062: Activated | D1062: Current | F1062: 2025-04-29T14:14:10.000+0000 | G1062: =IF(COUNTIF(B:B, B1062) > 1, "Duplicate", "Unique") -> Unique
A1063: 800Pv00000G4x0MIAR | B1063: a1G4J0000025u8DUAQ | C1063: Draft | D1063: Ended | E1063: =IF(I1063=_xlfn.MAXIFS(I:I, B:B, B1063), "Current", "Old") -> Old | F1063: 2025-04-15T14:27:12.000+0000 | G1063: =IF(COUNTIF(B:B, B1063) > 1, "Duplicate", "Unique") -> Duplicate | H1063: =COUNTIF(B:B, B1063) -> 2 | I1063: =--SUBSTITUTE(LEFT(F1063,19),"T"," ") -> 45762.602
A1064: 800Pv00000GF0HIIA1 | B1064: a1G4J0000025u8DUAQ | C1064: Activated | D1064: Current | E1064: =IF(I1064=_xlfn.MAXIFS(I:I, B:B, B1064), "Current", "Old") -> Current | F1064: 2025-04-29T14:14:10.000+0000 | G1064: =IF(COUNTIF(B:B, B1064) > 1, "Duplicate", "Unique") -> Duplicate | H1064: =COUNTIF(B:B, B1064) -> 2 | I1064: =--SUBSTITUTE(LEFT(F1064,19),"T"," ") -> 45776.593
A1065: 800Pv00000GF02LIAT | B1065: a1G4J0000025u8EUAQ | C1065: Activated | D1065: Current | F1065: 2025-04-29T14:14:10.000+0000 | G1065: =IF(COUNTIF(B:B, B1065) > 1, "Duplicate", "Unique") -> Unique
A1066: 800Pv00000G55PTIAZ | B1066: a1G4J0000025u8FUAQ | C1066: Activated | D1066: Current | F1066: 2025-04-29T14:14:10.000+0000 | G1066: =IF(COUNTIF(B:B, B1066) > 1, "Duplicate", "Unique") -> Unique
A1067: 800Pv00000FzrYPIAZ | B1067: a1G4J0000025u8LUAQ | C1067: Activated | D1067: Current | F1067: 2025-04-29T14:14:10.000+0000 | G1067: =IF(COUNTIF(B:B, B1067) > 1, "Duplicate", "Unique") -> Unique
A1068: 800Pv00000GF02MIAT | B1068: a1G4J0000025u8MUAQ | C1068: Activated | D1068: Current | F1068: 2025-04-29T14:14:10.000+0000 | G1068: =IF(COUNTIF(B:B, B1068) > 1, "Duplicate", "Unique") -> Unique
A1069: 800Pv00000GF02NIAT | B1069: a1G4J0000025u8NUAQ | C1069: Activated | D1069: Current | F1069: 2025-04-29T14:14:10.000+0000 | G1069: =IF(COUNTIF(B:B, B1069) > 1, "Duplicate", "Unique") -> Unique
A1070: 800Pv00000GF0HJIA1 | B1070: a1G4J0000025u8OUAQ | C1070: Activated | D1070: Current | F1070: 2025-04-29T14:14:10.000+0000 | G1070: =IF(COUNTIF(B:B, B1070) > 1, "Duplicate", "Unique") -> Unique
...

Sheet Mappings
A1: Id | B1: PMS_Reference__c | C1: Test | F1: Id | G1: Unit__r.Name | I1: Id | K1: Id | L1: StartDate | N1: Id | O1: Tenancy_End_Date__c | Q1: Unit Name | R1: Start Date | S1: End Date
A2: 800Pv00000FHJTrIAP | B2: 122601026007 | C2: 800Pv00000FHJTrIAP | D2: =VLOOKUP(C2, Mappings!A:B, 2, FALSE) -> 122601026007 | F2: 800Pv00000FHJTrIAP | G2: Flat 24, Cooke Place, Block E, Salford, M5 | I2: 800Pv00000FHJTrIAP | K2: 800Pv00000FHJTrIAP | L2: 45731 | N2: 800Pv00000FHJTrIAP | Q2: =VLOOKUP(F2, Mappings!F:G, 2, FALSE) -> Flat 24, Cooke Place, Block E, Salford, M5 | R2: =VLOOKUP(K2, Mappings!K:L, 2, FALSE) -> 45731 | S2: =VLOOKUP(N2, Mappings!N:O, 2, FALSE) -> 0
A3: 800Pv00000Fsyg6IAB | B3: pmsuatsmoke | C3: 800Pv00000Fsyg6IAB | D3: =VLOOKUP(C3, Mappings!A:B, 2, FALSE) -> pmsuatsmoke | F3: 800Pv00000Fsyg6IAB | G3: 6, Fernside Court, Holders Hill Road, Hendon, | I3: 800Pv00000Fsyg6IAB | K3: 800Pv00000Fsyg6IAB | L3: 45778 | N3: 800Pv00000Fsyg6IAB | O3: 46507 | R3: =VLOOKUP(K3, Mappings!K:L, 2, FALSE) -> 45778 | S3: =VLOOKUP(N3, Mappings!N:O, 2, FALSE) -> 46507
A4: 800Pv00000FzYkEIAV | B4: 127690001001 | C4: 800Pv00000FzYkEIAV | D4: =VLOOKUP(C4, Mappings!A:B, 2, FALSE) -> 127690001001 | F4: 800Pv00000FzYkEIAV | G4: GR-Brookfield Cottage, Liverpool, L17 | I4: 800Pv00000FzYkEIAV | K4: 800Pv00000FzYkEIAV | L4: 45317 | N4: 800Pv00000FzYkEIAV | R4: =VLOOKUP(K4, Mappings!K:L, 2, FALSE) -> 45317
A5: 800Pv00000FzkYUIAZ | B5: 122486038005 | C5: 800Pv00000FzkYUIAZ | D5: =VLOOKUP(C5, Mappings!A:B, 2, FALSE) -> 122486038005 | F5: 800Pv00000FzkYUIAZ | G5: Apt 302, Abbeville Apts, 37 London Rd, Barkin | I5: 800Pv00000FzkYUIAZ | K5: 800Pv00000FzkYUIAZ | L5: 45240 | N5: 800Pv00000FzkYUIAZ | O5: 45605 | R5: =VLOOKUP(K5, Mappings!K:L, 2, FALSE) -> 45240
A6: 800Pv00000FzoWSIAZ | B6: 317463001002 | C6: 800Pv00000FzoWSIAZ | D6: =VLOOKUP(C6, Mappings!A:B, 2, FALSE) -> 317463001002 | F6: 800Pv00000FzoWSIAZ | G6: Flat 1, Middleton Hse, Causton St, SW1P 4AS | I6: 800Pv00000FzoWSIAZ | K6: 800Pv00000FzoWSIAZ | L6: 38718 | N6: 800Pv00000FzoWSIAZ | O6: 84372 | R6: =VLOOKUP(K6, Mappings!K:L, 2, FALSE) -> 38718
A7: 800Pv00000Fzpt9IAB | B7: 222583094004 | C7: 800Pv00000Fzpt9IAB | D7: =VLOOKUP(C7, Mappings!A:B, 2, FALSE) -> 222583094004 | F7: 800Pv00000Fzpt9IAB | G7: Parking C2 Tayleur Apt, Salford M50 | I7: 800Pv00000Fzpt9IAB | K7: 800Pv00000Fzpt9IAB | L7: 45348 | N7: 800Pv00000Fzpt9IAB | O7: 45560 | R7: =VLOOKUP(K7, Mappings!K:L, 2, FALSE) -> 45348
A8: 800Pv00000FzptBIAR | B8: 222580003004 | F8: 800Pv00000FzptBIAR | G8: 103 Tayleur Apt , Waterman Wlk, Salford M50 | I8: 800Pv00000FzptBIAR | K8: 800Pv00000FzptBIAR | L8: 45014 | N8: 800Pv00000FzptBIAR | O8: 45744 | R8: =VLOOKUP(K8, Mappings!K:L, 2, FALSE) -> 45014
A9: 800Pv00000G4iMLIAZ | B9: pms128999 | F9: 800Pv00000G4iMLIAZ | G9: 140a, Tanfield Avenue, Neasden, London | I9: 800Pv00000G4iMLIAZ | K9: 800Pv00000G4iMLIAZ | L9: 45778 | N9: 800Pv00000G4iMLIAZ | O9: 46507 | R9: =VLOOKUP(K9, Mappings!K:L, 2, FALSE) -> 45778
A10: 800Pv00000G4jS4IAJ | B10: sdfghu565432 | F10: 800Pv00000G4jS4IAJ | G10: 6, Fernside Court, Holders Hill Road, Hendon, | I10: 800Pv00000G4jS4IAJ | K10: 800Pv00000G4jS4IAJ | L10: 45778 | N10: 800Pv00000G4jS4IAJ | O10: 46507 | R10: =VLOOKUP(K10, Mappings!K:L, 2, FALSE) -> 45778
A11: 800Pv00000G4ok1IAB | B11: 127166001001 | F11: 800Pv00000G4ok1IAB | G11: 22 Nevinson Way, Waterlooville, Hampshire | I11: 800Pv00000G4ok1IAB | K11: 800Pv00000G4ok1IAB | L11: 43882 | N11: 800Pv00000G4ok1IAB | R11: =VLOOKUP(K11, Mappings!K:L, 2, FALSE) -> 43882
A12: 800Pv00000G4ok4IAB | B12: 127057116002 | F12: 800Pv00000G4ok4IAB | G12: GR-Apt 117, Kings Dock Mill, Liverpool, L1 | I12: 800Pv00000G4ok4IAB | K12: 800Pv00000G4ok4IAB | L12: 39420 | N12: 800Pv00000G4ok4IAB | O12: 94203 | R12: =VLOOKUP(K12, Mappings!K:L, 2, FALSE) -> 39420
A13: 800Pv00000G4orjIAB | B13: 222521059004 | F13: 800Pv00000G4orjIAB | G13: 59, New Islington, 43 Chippenham Road, M4 6BY | I13: 800Pv00000G4orjIAB | K13: 800Pv00000G4orjIAB | L13: 45481 | N13: 800Pv00000G4orjIAB | O13: 45845 | R13: =VLOOKUP(K13, Mappings!K:L, 2, FALSE) -> 45481
A14: 800Pv00000G4os9IAB | B14: 222659075002 | F14: 800Pv00000G4os9IAB | G14: 75 Gatehouse Apts, 86 East St, Southampton | I14: 800Pv00000G4os9IAB | K14: 800Pv00000G4os9IAB | L14: 45471 | N14: 800Pv00000G4os9IAB | O14: 45835 | R14: =VLOOKUP(K14, Mappings!K:L, 2, FALSE) -> 45471
A15: 800Pv00000G4osYIAR | B15: 222579004002 | F15: 800Pv00000G4osYIAR | G15: 104 Torrens Apt, Waterman Wlk, Salford M50 | I15: 800Pv00000G4osYIAR | K15: 800Pv00000G4osYIAR | L15: 45481 | N15: 800Pv00000G4osYIAR | O15: 45845 | R15: =VLOOKUP(K15, Mappings!K:L, 2, FALSE) -> 45481
A16: 800Pv00000G4r6MIAR | B16: 222653003001 | F16: 800Pv00000G4r6MIAR | G16: Unit 3, Halogen House, 217 Chapel St, Salford | I16: 800Pv00000G4r6MIAR | K16: 800Pv00000G4r6MIAR | L16: 45301 | N16: 800Pv00000G4r6MIAR | R16: =VLOOKUP(K16, Mappings!K:L, 2, FALSE) -> 45301
A17: 800Pv00000G4r6VIAR | B17: 222683106001 | F17: 800Pv00000G4r6VIAR | G17: 507 Pin Yard, 11 Sweet Street, Leeds | I17: 800Pv00000G4r6VIAR | K17: 800Pv00000G4r6VIAR | L17: 45465 | N17: 800Pv00000G4r6VIAR | O17: 46194 | R17: =VLOOKUP(K17, Mappings!K:L, 2, FALSE) -> 45465
A18: 800Pv00000G4r73IAB | B18: 222708129001 | F18: 800Pv00000G4r73IAB | G18: 439 Enigma Square, 414 North Row, MK9 2GF | I18: 800Pv00000G4r73IAB | K18: 800Pv00000G4r73IAB | L18: 45481 | N18: 800Pv00000G4r73IAB | O18: 45664 | R18: =VLOOKUP(K18, Mappings!K:L, 2, FALSE) -> 45481
A19: 800Pv00000G4r78IAB | B19: 222708207001 | F19: 800Pv00000G4r78IAB | G19: 639 Enigma Square, 414 North Row, MK9 2GF | I19: 800Pv00000G4r78IAB | K19: 800Pv00000G4r78IAB | L19: 45348 | N19: 800Pv00000G4r78IAB | O19: 45713 | R19: =VLOOKUP(K19, Mappings!K:L, 2, FALSE) -> 45348
A20: 800Pv00000G4r7SIAR | B20: 222741019001 | F20: 800Pv00000G4r7SIAR | G20: 117 Assay Apartments, Station View, Guildford | I20: 800Pv00000G4r7SIAR | K20: 800Pv00000G4r7SIAR | L20: 45488 | N20: 800Pv00000G4r7SIAR | O20: 45852 | R20: =VLOOKUP(K20, Mappings!K:L, 2, FALSE) -> 45488
A21: 800Pv00000G4r7hIAB | B21: 222744075001 | F21: 800Pv00000G4r7hIAB | G21: 75 Nautilus Apts, 2 Norah Smyth Rd, London | I21: 800Pv00000G4r7hIAB | K21: 800Pv00000G4r7hIAB | L21: 45436 | N21: 800Pv00000G4r7hIAB | O21: 45800 | R21: =VLOOKUP(K21, Mappings!K:L, 2, FALSE) -> 45436
A22: 800Pv00000G4rZTIAZ | B22: 222659069002 | F22: 800Pv00000G4rZTIAZ | G22: 69 Gatehouse Apts, 86 East St, Southampton | I22: 800Pv00000G4rZTIAZ | K22: 800Pv00000G4rZTIAZ | L22: 45094 | N22: 800Pv00000G4rZTIAZ | O22: 45459 | R22: =VLOOKUP(K22, Mappings!K:L, 2, FALSE) -> 45094
A23: 800Pv00000G4sJzIAJ | B23: 222630020004 | F23: 800Pv00000G4sJzIAJ | G23: 120, Brook Place Apts, Sheffield, S11 8BR | I23: 800Pv00000G4sJzIAJ | K23: 800Pv00000G4sJzIAJ | L23: 45464 | N23: 800Pv00000G4sJzIAJ | O23: 45828 | R23: =VLOOKUP(K23, Mappings!K:L, 2, FALSE) -> 45464
A24: 800Pv00000G4sLcIAJ | B24: 566576ujhgbv | F24: 800Pv00000G4sLcIAJ | G24: 140a, Tanfield Avenue, Neasden, London | I24: 800Pv00000G4sLcIAJ | K24: 800Pv00000G4sLcIAJ | L24: 45778 | N24: 800Pv00000G4sLcIAJ | O24: 46507 | R24: =VLOOKUP(K24, Mappings!K:L, 2, FALSE) -> 45778
A25: 800Pv00000G4to2IAB | B25: 222488066008 | F25: 800Pv00000G4to2IAB | G25: 67, 124 The Rock, Bury, BL9 | I25: 800Pv00000G4to2IAB | K25: 800Pv00000G4to2IAB | L25: 45493 | N25: 800Pv00000G4to2IAB | O25: 45857 | R25: =VLOOKUP(K25, Mappings!K:L, 2, FALSE) -> 45493
A26: 800Pv00000G4to5IAB | B26: 217371015006 | F26: 800Pv00000G4to5IAB | G26: Apt 32, Kings Dock Mill, Liverpool, L1 | I26: 800Pv00000G4to5IAB | K26: 800Pv00000G4to5IAB | L26: 45485 | N26: 800Pv00000G4to5IAB | O26: 45849 | R26: =VLOOKUP(K26, Mappings!K:L, 2, FALSE) -> 45485
A27: 800Pv00000G4to9IAB | B27: 222648149003 | F27: 800Pv00000G4to9IAB | G27: 1406, Neon House, 207 Chapel St, Salford, M3 | I27: 800Pv00000G4to9IAB | K27: 800Pv00000G4to9IAB | L27: 45502 | N27: 800Pv00000G4to9IAB | O27: 45866 | R27: =VLOOKUP(K27, Mappings!K:L, 2, FALSE) -> 45502
A28: 800Pv00000G4toCIAR | B28: 222522002003 | F28: 800Pv00000G4toCIAR | G28: 2, Ancoats, 2 Butler Street, M4 6BZ | I28: 800Pv00000G4toCIAR | K28: 800Pv00000G4toCIAR | L28: 45464 | N28: 800Pv00000G4toCIAR | O28: 45828 | R28: =VLOOKUP(K28, Mappings!K:L, 2, FALSE) -> 45464
A29: 800Pv00000G4toNIAR | B29: 222580046003 | F29: 800Pv00000G4toNIAR | G29: 508 Tayleur Apt , Waterman Wlk, Salford M50 | I29: 800Pv00000G4toNIAR | K29: 800Pv00000G4toNIAR | L29: 45475 | N29: 800Pv00000G4toNIAR | O29: 45839 | R29: =VLOOKUP(K29, Mappings!K:L, 2, FALSE) -> 45475
A30: 800Pv00000G4toaIAB | B30: 222652088003 | F30: 800Pv00000G4toaIAB | G30: Car Parking 4 - Level 1 Neon | I30: 800Pv00000G4toaIAB | K30: 800Pv00000G4toaIAB | L30: 45289 | N30: 800Pv00000G4toaIAB | O30: 45654 | R30: =VLOOKUP(K30, Mappings!K:L, 2, FALSE) -> 45289
A31: 800Pv00000G4tooIAB | B31: 222648032003 | F31: 800Pv00000G4tooIAB | G31: 413, Neon House, 207 Chapel St, Salford, M3 5 | I31: 800Pv00000G4tooIAB | K31: 800Pv00000G4tooIAB | L31: 45476 | N31: 800Pv00000G4tooIAB | O31: 45840 | R31: =VLOOKUP(K31, Mappings!K:L, 2, FALSE) -> 45476
A32: 800Pv00000G4tovIAB | B32: 222631002007 | F32: 800Pv00000G4tovIAB | G32: Parking 02 Brook Place Apts, Sheffield, S11 | I32: 800Pv00000G4tovIAB | K32: 800Pv00000G4tovIAB | L32: 45474 | N32: 800Pv00000G4tovIAB | O32: 45838 | R32: =VLOOKUP(K32, Mappings!K:L, 2, FALSE) -> 45474
A33: 800Pv00000G4toyIAB | B33: 222578131007 | F33: 800Pv00000G4toyIAB | G33: 907 Ambassador Apt, Waterman Wlk, Salford M50 | I33: 800Pv00000G4toyIAB | K33: 800Pv00000G4toyIAB | L33: 45492 | N33: 800Pv00000G4toyIAB | O33: 45856 | R33: =VLOOKUP(K33, Mappings!K:L, 2, FALSE) -> 45492
A34: 800Pv00000G4tp2IAB | B34: 222578062007 | F34: 800Pv00000G4tp2IAB | G34: 414 Ambassador Apt, Waterman Wlk, Salford M50 | I34: 800Pv00000G4tp2IAB | K34: 800Pv00000G4tp2IAB | L34: 45469 | N34: 800Pv00000G4tp2IAB | O34: 45833 | R34: =VLOOKUP(K34, Mappings!K:L, 2, FALSE) -> 45469
A35: 800Pv00000G4tpDIAR | B35: 418537036001 | F35: 800Pv00000G4tpDIAR | G35: Car Space 8, St Annes Ct, Howard Place, BN1 | I35: 800Pv00000G4tpDIAR | K35: 800Pv00000G4tpDIAR | L35: 45413 | N35: 800Pv00000G4tpDIAR | O35: 45777 | R35: =VLOOKUP(K35, Mappings!K:L, 2, FALSE) -> 45413
A36: 800Pv00000G4tpFIAR | B36: 222630007004 | F36: 800Pv00000G4tpFIAR | G36: 107, Brook Place Apts, Sheffield, S11 8BR | I36: 800Pv00000G4tpFIAR | K36: 800Pv00000G4tpFIAR | L36: 45489 | N36: 800Pv00000G4tpFIAR | O36: 45853 | R36: =VLOOKUP(K36, Mappings!K:L, 2, FALSE) -> 45489
A37: 800Pv00000G4x0LIAR | B37: 103336078001 | F37: 800Pv00000G4x0LIAR | G37: 75, Victoria Court, Southport, Merseyside | I37: 800Pv00000G4x0LIAR | K37: 800Pv00000G4x0LIAR | N37: 800Pv00000G4x0LIAR | R37: =VLOOKUP(K37, Mappings!K:L, 2, FALSE) -> 0
A38: 800Pv00000G4x0MIAR | B38: 104566001002 | F38: 800Pv00000G4x0MIAR | G38: 86, Clementina Road, Leyton, London | I38: 800Pv00000G4x0MIAR | K38: 800Pv00000G4x0MIAR | L38: 45280 | N38: 800Pv00000G4x0MIAR
A39: 800Pv00000G4x0OIAR | B39: 104350004004 | F39: 800Pv00000G4x0OIAR | G39: 12, Chelsea Close, Hampton Hill, Middlesex | I39: 800Pv00000G4x0OIAR | K39: 800Pv00000G4x0OIAR | L39: 45345 | N39: 800Pv00000G4x0OIAR
A40: 800Pv00000G4x0YIAR | B40: 222584001004 | F40: 800Pv00000G4x0YIAR | G40: 1 Woodward House, Waterlooville, PO7 3BP | I40: 800Pv00000G4x0YIAR | K40: 800Pv00000G4x0YIAR | L40: 45426 | N40: 800Pv00000G4x0YIAR
...
