Workbook

Sheet 4. Live Offers
B2: SCHEDULE OF OFFERS - DEAL PIPELINE
B4: User Guide: All Blue Cells are to be inputted manually; all other cells entail automatic formulae
B5: To avoid duplication or confusion, update the relevant row to reflect the latest offer from the prospective tenant
B6: Only live offers should be kept on the schedule - should an offer covert into a lease signing, it can be subsequently removed or transferred to a historic record sheet | AB6: =AD19/12*3 -> 15107.4
B7: Straight-line headline rent fixed until break or lease expiry, in absence of stepped rental profile
B9: SUBJECT PROPERTY - SUMMARY | J9: INTERNAL PROCESS CHECKS | P9: TENANT INFORMATION | W9: LIVE LEASE / OFFER SUMMARY | AI9: APPRAISAL SUMMARY / INPUTS | AX9: LEGAL COMPLETION PATHWAY | BD9: UNSUCCESSFUL OFFERS | BH9: Latest
B10: Property | C10: Location | E10: Unit No. | F10: Qube Ref. | G10: Floor Area | H10: IV Gain ± | J10: AM | K10: IC | L10: Legals | M10: Lease Plan | N10: Arcadis | P10: HoTs Date | Q10: Tenant Entity | S10: Agent | T10: Guarantor | U10: Use | W10: Lease Length | X10: Break Clause | Y10: Rent Review | Z10: 1954 Act | AA10: Estate Charge | AB10: Deposit [£] | AC10: Marketing Rent | AD10: Headline Rent | AE10: Headline Rent (£/sqft) | AF10: CBRE ERV [£] | AG10: ERV ± | AI10: Deal Timings | AJ10: Rent Free | AK10: Cap. Con. [£] | AL10: RF Value [£] | AM10: Cap. Con. [Mths] | AN10: Total TIs [Mths] | AO10: TIs Value [£] | AP10: TIs £PSF | AQ10: N.E.R. [£] | AR10: Yield [%] | AS10: CBRE IV | AT10: YP. Perp Def | AU10: GPLC IV | AV10: CBRE ± | AX10: Instruction | AY10: Completion | AZ10: Legal Contact | BA10: Duration | BB10: Estimated Completion | BD10: Proposed Tenant | BE10: Fall Through Date | BF10: Reason | BH10: Updated comments
B11: Millet Place | C11: =INDEX('[1]2. Asset Dashboard'!E:E,MATCH('4. Live Offers'!B11,'[1]2. Asset Dashboard'!C:C,0)) -> London | E11: 4 | F11: {=IF(INDEX('[1]3. Unit-Level Index'!H:H,MATCH(CONCATENATE('4. Live Offers'!B11," ",'4. Live Offers'!E11),CONCATENATE('[1]3. Unit-Level Index'!B:B," ",'[1]3. Unit-Level Index'!G:G),0))="","-",(INDEX('[1]3. Unit-Level Index'!H:H,MATCH(CONCATENATE('4. Live Offers'!B11," ",'4. Live Offers'!E11),CONCATENATE('[1]3. Unit-Level Index'!B:B," ",'[1]3. Unit-Level Index'!G:G),0))))} -> 900005004 | G11: {=INDEX('[1]3. Unit-Level Index'!M:M,MATCH(CONCATENATE('4. Live Offers'!B11,"",'4. Live Offers'!E11),CONCATENATE('[1]3. Unit-Level Index'!B:B,"",'[1]3. Unit-Level Index'!G:G),0))} -> 1132 | H11: =AV11 -> 0.20583461 | J11: Yes | K11: Yes | L11: Yes | M11: Yes | N11: Yes | P11: 45110 | Q11: Nectar Subs Limited (Subway) | S11: BGP | T11: - | U11: Grab and Go | W11: 15 | X11: 10 | Y11: 5 | Z11: Inside | AB11: =AD11/12*6 -> 12000 | AD11: 24000 | AE11: =IFERROR(AD11/G11,0) -> 21.201413 | AF11: {=INDEX('[1]Mar-24'!N:N,MATCH(CONCATENATE('4. Live Offers'!B11,"",'4. Live Offers'!E11),CONCATENATE('[1]Mar-24'!B:B,"",'[1]Mar-24'!C:C),0))} -> 24055 | AG11: =IFERROR((AD11-AF11)/AF11,"-") -> -0.0022864269 | AI11: 3 | AJ11: 19 | AK11: -11985 | AL11: =(-(AD11/12)*AJ11) -> -38000 | AM11: =IFERROR((-AK11)/(AD11/12),"-") -> 5.9925 | AN11: =IFERROR(AM11+AJ11,"-") -> 24.9925 | AO11: =AL11+AK11 -> -49985 | AP11: =IFERROR(-AO11/G11,"-") -> 44.15636 | AQ11: =IFERROR((IF(X11<W11,((AD11*X11+AO11)/X11),(AD11*W11+AO11)/W11)),"-") -> 19001.5 | AR11: {=INDEX('[1]Mar-24'!S:S,MATCH(CONCATENATE('4. Live Offers'!B11,"",'4. Live Offers'!E11),CONCATENATE('[1]Mar-24'!B:B,"",'[1]Mar-24'!C:C),0))} -> 0.075 | AS11: {=INDEX('[1]Mar-24'!R:R,MATCH(CONCATENATE('4. Live Offers'!B11,"",'4. Live Offers'!E11),CONCATENATE('[1]Mar-24'!B:B,"",'[1]Mar-24'!C:C),0))} -> 206341.58 | AT11: =IFERROR((1+AR11)^-(AI11/12)*(1/AR11),"-") -> 13.094431 | AU11: =IFERROR(AQ11*AT11,"-") -> 248813.82 | AV11: =IFERROR(((AT11*AQ11)-AS11)/AS11,"-") -> 0.20583461 | AX11: 45172 | AZ11: Sonal Kang | BA11: =IFERROR(DATEDIF(AX11,AY11,"m"),"In Progress") -> In Progress | BB11: 45580 | BH11: 25/10 - completion set for 03/01/2025
B12: Millet Place | C12: =INDEX('[1]2. Asset Dashboard'!E:E,MATCH('4. Live Offers'!B12,'[1]2. Asset Dashboard'!C:C,0)) -> London | E12: 2 | F12: {=IF(INDEX('[1]3. Unit-Level Index'!H:H,MATCH(CONCATENATE('4. Live Offers'!B12," ",'4. Live Offers'!E12),CONCATENATE('[1]3. Unit-Level Index'!B:B," ",'[1]3. Unit-Level Index'!G:G),0))="","-",(INDEX('[1]3. Unit-Level Index'!H:H,MATCH(CONCATENATE('4. Live Offers'!B12," ",'4. Live Offers'!E12),CONCATENATE('[1]3. Unit-Level Index'!B:B," ",'[1]3. Unit-Level Index'!G:G),0))))} -> 900005002 | G12: {=INDEX('[1]3. Unit-Level Index'!M:M,MATCH(CONCATENATE('4. Live Offers'!B12,"",'4. Live Offers'!E12),CONCATENATE('[1]3. Unit-Level Index'!B:B,"",'[1]3. Unit-Level Index'!G:G),0))} -> 3451 | H12: =AV12 -> 1.5600273 | J12: Yes | K12: Yes | L12: Yes | M12: Yes | N12: Yes | P12: 44562 | Q12: Tesco | S12: BGP | U12: Supermarket | W12: 15 | X12: 10 | Y12: 5 | Z12: Inside | AD12: 100000 | AE12: =IFERROR(AD12/G12,0) -> 28.977108 | AF12: {=INDEX('[1]Mar-24'!N:N,MATCH(CONCATENATE('4. Live Offers'!B12,"",'4. Live Offers'!E12),CONCATENATE('[1]Mar-24'!B:B,"",'[1]Mar-24'!C:C),0))} -> 60000 | AG12: =IFERROR((AD12-AF12)/AF12,"-") -> 0.66666667 | AI12: 2 | AJ12: 12 | AK12: -350000 | AL12: =(-(AD12/12)*AJ12) -> -100000 | AM12: =IFERROR((-AK12)/(AD12/12),"-") -> 42 | AN12: =IFERROR(AM12+AJ12,"-") -> 54 | AO12: =AL12+AK12 -> -450000 | AP12: =IFERROR(-AO12/G12,"-") -> 130.39699 | AQ12: =IFERROR((IF(X12<W12,((AD12*X12+AO12)/X12),(AD12*W12+AO12)/W12)),"-") -> 55000 | AR12: {=INDEX('[1]Mar-24'!S:S,MATCH(CONCATENATE('4. Live Offers'!B12,"",'4. Live Offers'!E12),CONCATENATE('[1]Mar-24'!B:B,"",'[1]Mar-24'!C:C),0))} -> 0.075 | AS12: {=INDEX('[1]Mar-24'!R:R,MATCH(CONCATENATE('4. Live Offers'!B12,"",'4. Live Offers'!E12),CONCATENATE('[1]Mar-24'!B:B,"",'[1]Mar-24'!C:C),0))} -> 283023.23 | AT12: =IFERROR((1+AR12)^-(AI12/12)*(1/AR12),"-") -> 13.173585 | AU12: =IFERROR(AQ12*AT12,"-") -> 724547.2 | AV12: =IFERROR(((AT12*AQ12)-AS12)/AS12,"-") -> 1.5600273 | AX12: 44480 | AZ12: Lydia Armstrong | BA12: =IFERROR(DATEDIF(AX12,AY12,"m"),"In Progress") -> In Progress | BB12: 45658 | BH12: 25/10 - AFL Date set for exchange wk comm 4th nov
B13: Exchange Square | C13: =INDEX('[1]2. Asset Dashboard'!E:E,MATCH('4. Live Offers'!B13,'[1]2. Asset Dashboard'!C:C,0)) -> Birmingham | E13: 1 | F13: {=IF(INDEX('[1]3. Unit-Level Index'!H:H,MATCH(CONCATENATE('4. Live Offers'!B13," ",'4. Live Offers'!E13),CONCATENATE('[1]3. Unit-Level Index'!B:B," ",'[1]3. Unit-Level Index'!G:G),0))="","-",(INDEX('[1]3. Unit-Level Index'!H:H,MATCH(CONCATENATE('4. Live Offers'!B13," ",'4. Live Offers'!E13),CONCATENATE('[1]3. Unit-Level Index'!B:B," ",'[1]3. Unit-Level Index'!G:G),0))))} -> 222795001 | G13: {=INDEX('[1]3. Unit-Level Index'!M:M,MATCH(CONCATENATE('4. Live Offers'!B13,"",'4. Live Offers'!E13),CONCATENATE('[1]3. Unit-Level Index'!B:B,"",'[1]3. Unit-Level Index'!G:G),0))} -> 2104 | H13: =AV13 -> 0.35925641 | J13: Yes | K13: Yes | L13: Yes | M13: Yes | N13: Yes | P13: 45364 | Q13: Hariharan Baskar (t/a Londis) | S13: Siddall Jones | T13: - | U13: Supermarket | W13: 15 | X13: 15 | Y13: 5 | Z13: Outside | AA13: 1.84 | AB13: =AD13/12*4 -> 13000 | AC13: 39000 | AD13: 39000 | AE13: =IFERROR(AD13/G13,0) -> 18.536122 | AF13: {=INDEX('[1]Mar-24'!N:N,MATCH(CONCATENATE('4. Live Offers'!B13,"",'4. Live Offers'!E13),CONCATENATE('[1]Mar-24'!B:B,"",'[1]Mar-24'!C:C),0))} -> 33700 | AG13: =IFERROR((AD13-AF13)/AF13,"-") -> 0.15727003 | AI13: 6 | AJ13: 12 | AK13: 0 | AL13: =(-(AD13/12)*AJ13) -> -39000 | AM13: =IFERROR((-AK13)/(AD13/12),"-") -> 0 | AN13: =IFERROR(AM13+AJ13,"-") -> 12 | AO13: =AL13+AK13 -> -39000 | AP13: =IFERROR(-AO13/G13,"-") -> 18.536122 | AQ13: =IFERROR((IF(X13<W13,((AD13*X13+AO13)/X13),(AD13*W13+AO13)/W13)),"-") -> 36400 | AR13: {=INDEX('[1]Mar-24'!S:S,MATCH(CONCATENATE('4. Live Offers'!B13,"",'4. Live Offers'!E13),CONCATENATE('[1]Mar-24'!B:B,"",'[1]Mar-24'!C:C),0))} -> 0.09 | AS13: {=INDEX('[1]Mar-24'!R:R,MATCH(CONCATENATE('4. Live Offers'!B13,"",'4. Live Offers'!E13),CONCATENATE('[1]Mar-24'!B:B,"",'[1]Mar-24'!C:C),0))} -> 284999.59 | AT13: =IFERROR((1+AR13)^-(AI13/12)*(1/AR13),"-") -> 10.642514 | AU13: =IFERROR(AQ13*AT13,"-") -> 387387.52 | AV13: =IFERROR(((AT13*AQ13)-AS13)/AS13,"-") -> 0.35925641 | AX13: 45411 | AZ13: Liz Evans | BA13: =IFERROR(DATEDIF(AX13,AY13,"m"),"In Progress") -> In Progress | BB13: 45627 | BH13: 25/10 - update requested from WBD
B14: Queens Road | C14: =INDEX('[1]2. Asset Dashboard'!E:E,MATCH('4. Live Offers'!B14,'[1]2. Asset Dashboard'!C:C,0)) -> Nottingham | E14: 1 | F14: {=IF(INDEX('[1]3. Unit-Level Index'!H:H,MATCH(CONCATENATE('4. Live Offers'!B14," ",'4. Live Offers'!E14),CONCATENATE('[1]3. Unit-Level Index'!B:B," ",'[1]3. Unit-Level Index'!G:G),0))="","-",(INDEX('[1]3. Unit-Level Index'!H:H,MATCH(CONCATENATE('4. Live Offers'!B14," ",'4. Live Offers'!E14),CONCATENATE('[1]3. Unit-Level Index'!B:B," ",'[1]3. Unit-Level Index'!G:G),0))))} -> 222761001 | G14: {=INDEX('[1]3. Unit-Level Index'!M:M,MATCH(CONCATENATE('4. Live Offers'!B14,"",'4. Live Offers'!E14),CONCATENATE('[1]3. Unit-Level Index'!B:B,"",'[1]3. Unit-Level Index'!G:G),0))} -> 1800 | H14: =AV14 -> 0.22341676 | J14: Yes | K14: Yes | L14: Yes | M14: Yes | N14: Yes | P14: 45224 | Q14: Parker Hampton Food Group Ltd | S14: FHP | T14: - | U14: Supermarket | W14: 15 | X14: 10 | Y14: 5 | AB14: 11200 | AD14: 22400 | AE14: =IFERROR(AD14/G14,0) -> 12.444444 | AF14: {=INDEX('[1]Mar-24'!N:N,MATCH(CONCATENATE('4. Live Offers'!B14,"",'4. Live Offers'!E14),CONCATENATE('[1]Mar-24'!B:B,"",'[1]Mar-24'!C:C),0))} -> 22500 | AG14: =IFERROR((AD14-AF14)/AF14,"-") -> -0.0044444444 | AI14: 3 | AJ14: 9 | AK14: 0 | AL14: =(-(AD14/12)*AJ14) -> -16800 | AM14: =IFERROR((-AK14)/(AD14/12),"-") -> 0 | AN14: =IFERROR(AM14+AJ14,"-") -> 9 | AO14: =AL14+AK14 -> -16800 | AP14: =IFERROR(-AO14/G14,"-") -> 9.3333333 | AQ14: =IFERROR((IF(X14<W14,((AD14*X14+AO14)/X14),(AD14*W14+AO14)/W14)),"-") -> 20720 | AR14: {=INDEX('[1]Mar-24'!S:S,MATCH(CONCATENATE('4. Live Offers'!B14,"",'4. Live Offers'!E14),CONCATENATE('[1]Mar-24'!B:B,"",'[1]Mar-24'!C:C),0))} -> 0.11 | AS14: {=INDEX('[1]Mar-24'!R:R,MATCH(CONCATENATE('4. Live Offers'!B14,"",'4. Live Offers'!E14),CONCATENATE('[1]Mar-24'!B:B,"",'[1]Mar-24'!C:C),0))} -> 150000.22 | AT14: =IFERROR((1+AR14)^-(AI14/12)*(1/AR14),"-") -> 8.8567945 | AU14: =IFERROR(AQ14*AT14,"-") -> 183512.78 | AV14: =IFERROR(((AT14*AQ14)-AS14)/AS14,"-") -> 0.22341676 | AX14: 45265 | AY14: 45631 | AZ14: Lydia Armstrong | BA14: =IFERROR(DATEDIF(AX14,AY14,"m"),"In Progress") -> 12 | BB14: 45658
B15: Redcliffe Quarter | C15: =INDEX('[1]2. Asset Dashboard'!E:E,MATCH('4. Live Offers'!B15,'[1]2. Asset Dashboard'!C:C,0)) -> Bristol | E15: 2.1 | F15: {=IF(INDEX('[1]3. Unit-Level Index'!H:H,MATCH(CONCATENATE('4. Live Offers'!B15," ",'4. Live Offers'!E15),CONCATENATE('[1]3. Unit-Level Index'!B:B," ",'[1]3. Unit-Level Index'!G:G),0))="","-",(INDEX('[1]3. Unit-Level Index'!H:H,MATCH(CONCATENATE('4. Live Offers'!B15," ",'4. Live Offers'!E15),CONCATENATE('[1]3. Unit-Level Index'!B:B," ",'[1]3. Unit-Level Index'!G:G),0))))} -> 222707004 | G15: {=INDEX('[1]3. Unit-Level Index'!M:M,MATCH(CONCATENATE('4. Live Offers'!B15,"",'4. Live Offers'!E15),CONCATENATE('[1]3. Unit-Level Index'!B:B,"",'[1]3. Unit-Level Index'!G:G),0))} -> 4539 | H15: =AV15 -> -0.094199011 | J15: Yes | K15: Yes | L15: Yes | M15: Yes | N15: Yes | P15: 45258 | Q15: ASDA Stores Limited | S15: Alder King | T15: - | U15: Supermarket | W15: 15 | X15: 10 | Y15: 5 | Z15: Inside | AA15: TBC | AB15: 0 | AC15: 113475 | AD15: 96226.8 | AE15: =IFERROR(AD15/G15,0) -> 21.2 | AF15: {=INDEX('[1]Mar-24'!N:N,MATCH(CONCATENATE('4. Live Offers'!B15,"",'4. Live Offers'!E15),CONCATENATE('[1]Mar-24'!B:B,"",'[1]Mar-24'!C:C),0))} -> 99858 | AG15: =IFERROR((AD15-AF15)/AF15,"-") -> -0.036363636 | AI15: 3 | AJ15: 18 | AK15: -200000 | AL15: =(-(AD15/12)*AJ15) -> -144340.2 | AM15: =IFERROR((-AK15)/(AD15/12),"-") -> 24.941077 | AN15: =IFERROR(AM15+AJ15,"-") -> 42.941077 | AO15: =AL15+AK15 -> -344340.2 | AP15: =IFERROR(-AO15/G15,"-") -> 75.862569 | AQ15: =IFERROR((IF(X15<W15,((AD15*X15+AO15)/X15),(AD15*W15+AO15)/W15)),"-") -> 61792.78 | AR15: 0.075 | AS15: {=INDEX('[1]Mar-24'!R:R,MATCH(CONCATENATE('4. Live Offers'!B15,"",'4. Live Offers'!E15),CONCATENATE('[1]Mar-24'!B:B,"",'[1]Mar-24'!C:C),0))} -> 893288.13 | AT15: =IFERROR((1+AR15)^-(AI15/12)*(1/AR15),"-") -> 13.094431 | AU15: =IFERROR(AQ15*AT15,"-") -> 809141.27 | AV15: =IFERROR(((AT15*AQ15)-AS15)/AS15,"-") -> -0.094199011 | AX15: 45266 | AZ15: Liz Evans | BA15: =IFERROR(DATEDIF(AX15,AY15,"m"),"In Progress") -> In Progress | BB15: 45627 | BH15: 25/10 - Alder King speaking with Asda on contents insurance and Latent defects
B16: Weavers Yard | C16: =INDEX('[1]2. Asset Dashboard'!E:E,MATCH('4. Live Offers'!B16,'[1]2. Asset Dashboard'!C:C,0)) -> Newbury | E16: Block H - Unit 9 (3 Station Approach) | F16: {=IF(INDEX('[1]3. Unit-Level Index'!H:H,MATCH(CONCATENATE('4. Live Offers'!B16," ",'4. Live Offers'!E16),CONCATENATE('[1]3. Unit-Level Index'!B:B," ",'[1]3. Unit-Level Index'!G:G),0))="","-",(INDEX('[1]3. Unit-Level Index'!H:H,MATCH(CONCATENATE('4. Live Offers'!B16," ",'4. Live Offers'!E16),CONCATENATE('[1]3. Unit-Level Index'!B:B," ",'[1]3. Unit-Level Index'!G:G),0))))} -> 222698009 | G16: {=INDEX('[1]3. Unit-Level Index'!M:M,MATCH(CONCATENATE('4. Live Offers'!B16,"",'4. Live Offers'!E16),CONCATENATE('[1]3. Unit-Level Index'!B:B,"",'[1]3. Unit-Level Index'!G:G),0))} -> 616 | H16: =AV16 -> 0.00095778946 | J16: Yes | K16: Yes | L16: Yes | M16: Yes | N16: Yes | P16: 45237 | Q16: A&I Locals Ltd | S16: Quintons | T16: - | U16: Convenience Store | W16: 10 | X16: 10 | Y16: 5 | AA16: 1 | AB16: 6000 | AC16: =25*G16 -> 15400 | AD16: 12000 | AE16: =IFERROR(AD16/G16,0) -> 19.480519 | AF16: {=INDEX('[1]Mar-24'!N:N,MATCH(CONCATENATE('4. Live Offers'!B16,"",'4. Live Offers'!E16),CONCATENATE('[1]Mar-24'!B:B,"",'[1]Mar-24'!C:C),0))} -> 12000 | AG16: =IFERROR((AD16-AF16)/AF16,"-") -> 0 | AI16: 4 | AJ16: 3 | AK16: -10000 | AL16: =(-(AD16/12)*AJ16) -> -3000 | AM16: =IFERROR((-AK16)/(AD16/12),"-") -> 10 | AN16: =IFERROR(AM16+AJ16,"-") -> 13 | AO16: =AL16+AK16 -> -13000 | AP16: =IFERROR(-AO16/G16,"-") -> 21.103896 | AQ16: =IFERROR((IF(X16<W16,((AD16*X16+AO16)/X16),(AD16*W16+AO16)/W16)),"-") -> 10700 | AR16: {=INDEX('[1]Mar-24'!S:S,MATCH(CONCATENATE('4. Live Offers'!B16,"",'4. Live Offers'!E16),CONCATENATE('[1]Mar-24'!B:B,"",'[1]Mar-24'!C:C),0))} -> 0.09 | AS16: {=INDEX('[1]Mar-24'!R:R,MATCH(CONCATENATE('4. Live Offers'!B16,"",'4. Live Offers'!E16),CONCATENATE('[1]Mar-24'!B:B,"",'[1]Mar-24'!C:C),0))} -> 115411.74 | AT16: =IFERROR((1+AR16)^-(AI16/12)*(1/AR16),"-") -> 10.796475 | AU16: =IFERROR(AQ16*AT16,"-") -> 115522.28 | AV16: =IFERROR(((AT16*AQ16)-AS16)/AS16,"-") -> 0.00095778946 | AX16: 45266 | AZ16: Lydia Armstrong | BA16: =IFERROR(DATEDIF(AX16,AY16,"m"),"In Progress") -> In Progress | BB16: 45505 | BH16: 18/10 - to remarket property
B17: Hawkins & George | C17: =INDEX('[1]2. Asset Dashboard'!E:E,MATCH('4. Live Offers'!B17,'[1]2. Asset Dashboard'!C:C,0)) -> Bristol | E17: 1 | F17: {=IF(INDEX('[1]3. Unit-Level Index'!H:H,MATCH(CONCATENATE('4. Live Offers'!B17," ",'4. Live Offers'!E17),CONCATENATE('[1]3. Unit-Level Index'!B:B," ",'[1]3. Unit-Level Index'!G:G),0))="","-",(INDEX('[1]3. Unit-Level Index'!H:H,MATCH(CONCATENATE('4. Live Offers'!B17," ",'4. Live Offers'!E17),CONCATENATE('[1]3. Unit-Level Index'!B:B," ",'[1]3. Unit-Level Index'!G:G),0))))} -> 222625001 | G17: {=INDEX('[1]3. Unit-Level Index'!M:M,MATCH(CONCATENATE('4. Live Offers'!B17,"",'4. Live Offers'!E17),CONCATENATE('[1]3. Unit-Level Index'!B:B,"",'[1]3. Unit-Level Index'!G:G),0))} -> 1635 | H17: =AV17 -> 0.030349884 | J17: Yes | K17: Yes | L17: Yes | M17: Yes | N17: Planned | P17: 45267 | Q17: Industrial Bar Project Ltd (t/a The Boiler Room) | S17: Alder King | T17: - | U17: F&B Operator | W17: 20 | X17: 7 | Y17: 5 | Z17: Outside | AA17: 0.6 | AB17: =AD17/12*6 -> 19025 | AC17: =25*G17 -> 40875 | AD17: 38050 | AE17: =IFERROR(AD17/G17,0) -> 23.272171 | AF17: {=INDEX('[1]Mar-24'!N:N,MATCH(CONCATENATE('4. Live Offers'!B17,"",'4. Live Offers'!E17),CONCATENATE('[1]Mar-24'!B:B,"",'[1]Mar-24'!C:C),0))} -> 36249 | AG17: =IFERROR((AD17-AF17)/AF17,"-") -> 0.049684129 | AI17: 4 | AJ17: 12 | AK17: =-35000*1/3 -> -11666.667 | AL17: =(-(AD17/12)*AJ17) -> -38050 | AM17: =IFERROR((-AK17)/(AD17/12),"-") -> 3.6793693 | AN17: =IFERROR(AM17+AJ17,"-") -> 15.679369 | AO17: =AL17+AK17 -> -49716.667 | AP17: =IFERROR(-AO17/G17,"-") -> 30.407747 | AQ17: =IFERROR((IF(X17<W17,((AD17*X17+AO17)/X17),(AD17*W17+AO17)/W17)),"-") -> 30947.619 | AR17: {=INDEX('[1]Mar-24'!S:S,MATCH(CONCATENATE('4. Live Offers'!B17,"",'4. Live Offers'!E17),CONCATENATE('[1]Mar-24'!B:B,"",'[1]Mar-24'!C:C),0))} -> 0.09 | AS17: {=INDEX('[1]Mar-24'!R:R,MATCH(CONCATENATE('4. Live Offers'!B17,"",'4. Live Offers'!E17),CONCATENATE('[1]Mar-24'!B:B,"",'[1]Mar-24'!C:C),0))} -> 324283.24 | AT17: =IFERROR((1+AR17)^-(AI17/12)*(1/AR17),"-") -> 10.796475 | AU17: =IFERROR(AQ17*AT17,"-") -> 334125.2 | AV17: =IFERROR(((AT17*AQ17)-AS17)/AS17,"-") -> 0.030349884 | AX17: 45385 | AZ17: Lydia Armstrong | BA17: =IFERROR(DATEDIF(AX17,AY17,"m"),"In Progress") -> In Progress | BB17: 45717 | BH17: 25/10 - lease plan with freeholder for review
B18: West Way Square | C18: =INDEX('[1]2. Asset Dashboard'!E:E,MATCH('4. Live Offers'!B18,'[1]2. Asset Dashboard'!C:C,0)) -> Oxford | E18: 1 | F18: {=IF(INDEX('[1]3. Unit-Level Index'!H:H,MATCH(CONCATENATE('4. Live Offers'!B18," ",'4. Live Offers'!E18),CONCATENATE('[1]3. Unit-Level Index'!B:B," ",'[1]3. Unit-Level Index'!G:G),0))="","-",(INDEX('[1]3. Unit-Level Index'!H:H,MATCH(CONCATENATE('4. Live Offers'!B18," ",'4. Live Offers'!E18),CONCATENATE('[1]3. Unit-Level Index'!B:B," ",'[1]3. Unit-Level Index'!G:G),0))))} -> - | G18: {=INDEX('[1]3. Unit-Level Index'!M:M,MATCH(CONCATENATE('4. Live Offers'!B18,"",'4. Live Offers'!E18),CONCATENATE('[1]3. Unit-Level Index'!B:B,"",'[1]3. Unit-Level Index'!G:G),0))} -> 2332.5 | H18: =AV18 -> 0.27529011 | J18: No | P18: TBC | Q18: KFC | S18: JPH Real Estate | T18: - | U18: Takeaway | W18: 20 | X18: 10 | Y18: 5 | AD18: 80500 | AE18: =IFERROR(AD18/G18,0) -> 34.512326 | AF18: {=INDEX('[1]Mar-24'!N:N,MATCH(CONCATENATE('4. Live Offers'!B18,"",'4. Live Offers'!E18),CONCATENATE('[1]Mar-24'!B:B,"",'[1]Mar-24'!C:C),0))} -> 80500 | AG18: =IFERROR((AD18-AF18)/AF18,"-") -> 0 | AJ18: 6 | AL18: =(-(AD18/12)*AJ18) -> -40250 | AM18: =IFERROR((-AK18)/(AD18/12),"-") -> 0 | AN18: =IFERROR(AM18+AJ18,"-") -> 6 | AO18: =AL18+AK18 -> -40250 | AP18: =IFERROR(-AO18/G18,"-") -> 17.256163 | AQ18: =IFERROR((IF(X18<W18,((AD18*X18+AO18)/X18),(AD18*W18+AO18)/W18)),"-") -> 76475 | AR18: {=INDEX('[1]Mar-24'!S:S,MATCH(CONCATENATE('4. Live Offers'!B18,"",'4. Live Offers'!E18),CONCATENATE('[1]Mar-24'!B:B,"",'[1]Mar-24'!C:C),0))} -> 0.085 | AS18: {=INDEX('[1]Mar-24'!R:R,MATCH(CONCATENATE('4. Live Offers'!B18,"",'4. Live Offers'!E18),CONCATENATE('[1]Mar-24'!B:B,"",'[1]Mar-24'!C:C),0))} -> 705491.15 | AT18: =IFERROR((1+AR18)^-(AI18/12)*(1/AR18),"-") -> 11.764706 | AU18: =IFERROR(AQ18*AT18,"-") -> 899705.88 | AV18: =IFERROR(((AT18*AQ18)-AS18)/AS18,"-") -> 0.27529011 | BA18: =IFERROR(DATEDIF(AX18,AY18,"m"),"In Progress") -> 0 | BH18: Early stage appraisal.
B19: Block D2 Hallsville Q | C19: =INDEX('[1]2. Asset Dashboard'!E:E,MATCH('4. Live Offers'!B19,'[1]2. Asset Dashboard'!C:C,0)) -> London | E19: Unit 4 | F19: {=IF(INDEX('[1]3. Unit-Level Index'!H:H,MATCH(CONCATENATE('4. Live Offers'!B19," ",'4. Live Offers'!E19),CONCATENATE('[1]3. Unit-Level Index'!B:B," ",'[1]3. Unit-Level Index'!G:G),0))="","-",(INDEX('[1]3. Unit-Level Index'!H:H,MATCH(CONCATENATE('4. Live Offers'!B19," ",'4. Live Offers'!E19),CONCATENATE('[1]3. Unit-Level Index'!B:B," ",'[1]3. Unit-Level Index'!G:G),0))))} -> 222746004 | G19: {=INDEX('[1]3. Unit-Level Index'!M:M,MATCH(CONCATENATE('4. Live Offers'!B19,"",'4. Live Offers'!E19),CONCATENATE('[1]3. Unit-Level Index'!B:B,"",'[1]3. Unit-Level Index'!G:G),0))} -> 2772 | H19: =AV19 -> -0.112517 | J19: Yes | K19: Yes | L19: Yes | M19: Yes | P19: TBC | Q19: Norman H Barnett | S19: CF Commercial | T19: - | U19: Law Firm | W19: 25 | X19: 10 | Y19: 5 | Z19: Outside | AA19: 3.35 | AB19: 15107 | AC19: =25*G19 -> 69300 | AD19: 60429.6 | AE19: =IFERROR(AD19/G19,0) -> 21.8 | AF19: {=INDEX('[1]Mar-24'!N:N,MATCH(CONCATENATE('4. Live Offers'!B19,"",'4. Live Offers'!E19),CONCATENATE('[1]Mar-24'!B:B,"",'[1]Mar-24'!C:C),0))} -> 68900 | AG19: =IFERROR((AD19-AF19)/AF19,"-") -> -0.12293759 | AI19: 6 | AJ19: 12 | AK19: -25000 | AL19: =(-(AD19/12)*AJ19) -> -60429.6 | AM19: =IFERROR((-AK19)/(AD19/12),"-") -> 4.9644545 | AN19: =IFERROR(AM19+AJ19,"-") -> 16.964455 | AO19: =AL19+AK19 -> -85429.6 | AP19: =IFERROR(-AO19/G19,"-") -> 30.818759 | AQ19: =IFERROR((IF(X19<W19,((AD19*X19+AO19)/X19),(AD19*W19+AO19)/W19)),"-") -> 51886.64 | AR19: {=INDEX('[1]Mar-24'!S:S,MATCH(CONCATENATE('4. Live Offers'!B19,"",'4. Live Offers'!E19),CONCATENATE('[1]Mar-24'!B:B,"",'[1]Mar-24'!C:C),0))} -> 0.075 | AS19: {=INDEX('[1]Mar-24'!R:R,MATCH(CONCATENATE('4. Live Offers'!B19,"",'4. Live Offers'!E19),CONCATENATE('[1]Mar-24'!B:B,"",'[1]Mar-24'!C:C),0))} -> 751847.93 | AT19: =IFERROR((1+AR19)^-(AI19/12)*(1/AR19),"-") -> 12.859809 | AU19: =IFERROR(AQ19*AT19,"-") -> 667252.26 | AV19: =IFERROR(((AT19*AQ19)-AS19)/AS19,"-") -> -0.112517 | AX19: 45520 | BA19: =IFERROR(DATEDIF(AX19,AY19,"m"),"In Progress") -> In Progress | BB19: 45658 | BH19: 25/10 - awaiting techincal information for LtA - have threatended to pause legals
B20: Weavers Yard | C20: =INDEX('[1]2. Asset Dashboard'!E:E,MATCH('4. Live Offers'!B20,'[1]2. Asset Dashboard'!C:C,0)) -> Newbury | E20: Block B - Unit 3 (Unit B) | F20: {=IF(INDEX('[1]3. Unit-Level Index'!H:H,MATCH(CONCATENATE('4. Live Offers'!B20," ",'4. Live Offers'!E20),CONCATENATE('[1]3. Unit-Level Index'!B:B," ",'[1]3. Unit-Level Index'!G:G),0))="","-",(INDEX('[1]3. Unit-Level Index'!H:H,MATCH(CONCATENATE('4. Live Offers'!B20," ",'4. Live Offers'!E20),CONCATENATE('[1]3. Unit-Level Index'!B:B," ",'[1]3. Unit-Level Index'!G:G),0))))} -> 222698003 | G20: {=INDEX('[1]3. Unit-Level Index'!M:M,MATCH(CONCATENATE('4. Live Offers'!B20,"",'4. Live Offers'!E20),CONCATENATE('[1]3. Unit-Level Index'!B:B,"",'[1]3. Unit-Level Index'!G:G),0))} -> 1399 | H20: =AV20 -> -0.27838193 | J20: Yes | K20: Yes | L20: Yes | P20: TBC | Q20: Q Gelato Limited | S20: Quintons | T20: - | U20: Ice Cream Parlour | W20: 15 | X20: 5 | Y20: 5 | Z20: Outside | AA20: TBC | AB20: =AD20/12*3 -> 7500 | AC20: 30000 | AD20: 30000 | AE20: =IFERROR(AD20/G20,0) -> 21.443888 | AF20: {=INDEX('[1]Mar-24'!N:N,MATCH(CONCATENATE('4. Live Offers'!B20,"",'4. Live Offers'!E20),CONCATENATE('[1]Mar-24'!B:B,"",'[1]Mar-24'!C:C),0))} -> 41970 | AG20: =IFERROR((AD20-AF20)/AF20,"-") -> -0.28520372 | AI20: 6 | AJ20: 6 | AK20: -15000 | AL20: =(-(AD20/12)*AJ20) -> -15000 | AM20: =IFERROR((-AK20)/(AD20/12),"-") -> 6 | AN20: =IFERROR(AM20+AJ20,"-") -> 12 | AO20: =AL20+AK20 -> -30000 | AP20: =IFERROR(-AO20/G20,"-") -> 21.443888 | AQ20: =IFERROR((IF(X20<W20,((AD20*X20+AO20)/X20),(AD20*W20+AO20)/W20)),"-") -> 24000 | AR20: {=INDEX('[1]Mar-24'!S:S,MATCH(CONCATENATE('4. Live Offers'!B20,"",'4. Live Offers'!E20),CONCATENATE('[1]Mar-24'!B:B,"",'[1]Mar-24'!C:C),0))} -> 0.09 | AS20: {=INDEX('[1]Mar-24'!R:R,MATCH(CONCATENATE('4. Live Offers'!B20,"",'4. Live Offers'!E20),CONCATENATE('[1]Mar-24'!B:B,"",'[1]Mar-24'!C:C),0))} -> 353955.02 | AT20: =IFERROR((1+AR20)^-(AI20/12)*(1/AR20),"-") -> 10.642514 | AU20: =IFERROR(AQ20*AT20,"-") -> 255420.34 | AV20: =IFERROR(((AT20*AQ20)-AS20)/AS20,"-") -> -0.27838193 | AX20: 45583 | AZ20: Signe (Russell Cooke) | BA20: =IFERROR(DATEDIF(AX20,AY20,"m"),"In Progress") -> In Progress | BB20: 45690 | BH20: 25/10 - legals instructed
B21: Millet Place | C21: =INDEX('[1]2. Asset Dashboard'!E:E,MATCH('4. Live Offers'!B21,'[1]2. Asset Dashboard'!C:C,0)) -> London | E21: 1 | F21: {=IF(INDEX('[1]3. Unit-Level Index'!H:H,MATCH(CONCATENATE('4. Live Offers'!B21," ",'4. Live Offers'!E21),CONCATENATE('[1]3. Unit-Level Index'!B:B," ",'[1]3. Unit-Level Index'!G:G),0))="","-",(INDEX('[1]3. Unit-Level Index'!H:H,MATCH(CONCATENATE('4. Live Offers'!B21," ",'4. Live Offers'!E21),CONCATENATE('[1]3. Unit-Level Index'!B:B," ",'[1]3. Unit-Level Index'!G:G),0))))} -> 900005001 | G21: {=INDEX('[1]3. Unit-Level Index'!M:M,MATCH(CONCATENATE('4. Live Offers'!B21,"",'4. Live Offers'!E21),CONCATENATE('[1]3. Unit-Level Index'!B:B,"",'[1]3. Unit-Level Index'!G:G),0))} -> 2250 | H21: =AV21 -> 0.47584568 | J21: Yes | K21: Yes | L21: Yes | M21: Yes | N21: Yes | P21: 45464 | Q21: Bright Start Nursery | S21: BGP | T21: Personal Guarantee | U21: Nursery | W21: 25 | X21: 10 | Y21: 5 | Z21: Outside | AB21: 26000 | AD21: 52000 | AE21: =IFERROR(AD21/G21,0) -> 23.111111 | AF21: {=INDEX('[1]Mar-24'!N:N,MATCH(CONCATENATE('4. Live Offers'!B21,"",'4. Live Offers'!E21),CONCATENATE('[1]Mar-24'!B:B,"",'[1]Mar-24'!C:C),0))} -> 51731.25 | AG21: =IFERROR((AD21-AF21)/AF21,"-") -> 0.005195119 | AI21: 3 | AJ21: 6 | AK21: 0 | AL21: =(-(AD21/12)*AJ21) -> -26000 | AM21: =IFERROR((-AK21)/(AD21/12),"-") -> 0 | AN21: =IFERROR(AM21+AJ21,"-") -> 6 | AO21: =AL21+AK21 -> -26000 | AP21: =IFERROR(-AO21/G21,"-") -> 11.555556 | AQ21: =IFERROR((IF(X21<W21,((AD21*X21+AO21)/X21),(AD21*W21+AO21)/W21)),"-") -> 49400 | AR21: {=INDEX('[1]Mar-24'!S:S,MATCH(CONCATENATE('4. Live Offers'!B21,"",'4. Live Offers'!E21),CONCATENATE('[1]Mar-24'!B:B,"",'[1]Mar-24'!C:C),0))} -> 0.075 | AS21: {=INDEX('[1]Mar-24'!R:R,MATCH(CONCATENATE('4. Live Offers'!B21,"",'4. Live Offers'!E21),CONCATENATE('[1]Mar-24'!B:B,"",'[1]Mar-24'!C:C),0))} -> 438301.16 | AT21: =IFERROR((1+AR21)^-(AI21/12)*(1/AR21),"-") -> 13.094431 | AU21: =IFERROR(AQ21*AT21,"-") -> 646864.88 | AV21: =IFERROR(((AT21*AQ21)-AS21)/AS21,"-") -> 0.47584568 | AX21: 45464 | BA21: =IFERROR(DATEDIF(AX21,AY21,"m"),"In Progress") -> In Progress | BB21: 45689 | BD21: Tamba Day Nursery | BE21: April-24 | BF21: Required additional cap con | BH21: 25/10 - signage app approved and going to planning, agent to provide update on timeline
B22: Millet Place | C22: =INDEX('[1]2. Asset Dashboard'!E:E,MATCH('4. Live Offers'!B22,'[1]2. Asset Dashboard'!C:C,0)) -> London | E22: 3 | F22: {=IF(INDEX('[1]3. Unit-Level Index'!H:H,MATCH(CONCATENATE('4. Live Offers'!B22," ",'4. Live Offers'!E22),CONCATENATE('[1]3. Unit-Level Index'!B:B," ",'[1]3. Unit-Level Index'!G:G),0))="","-",(INDEX('[1]3. Unit-Level Index'!H:H,MATCH(CONCATENATE('4. Live Offers'!B22," ",'4. Live Offers'!E22),CONCATENATE('[1]3. Unit-Level Index'!B:B," ",'[1]3. Unit-Level Index'!G:G),0))))} -> 900005003 | G22: {=INDEX('[1]3. Unit-Level Index'!M:M,MATCH(CONCATENATE('4. Live Offers'!B22,"",'4. Live Offers'!E22),CONCATENATE('[1]3. Unit-Level Index'!B:B,"",'[1]3. Unit-Level Index'!G:G),0))} -> 904 | H22: =AV22 -> 0.87677831 | J22: Yes | K22: Yes | L22: Yes | M22: Yes | N22: Yes | P22: 45464 | Q22: Bright Start Nursery | S22: BGP | T22: Personal Guarantee | U22: Nursery | W22: 25 | X22: 10 | Y22: 5 | Z22: Outside | AB22: 13000 | AD22: 26000 | AE22: =IFERROR(AD22/G22,0) -> 28.761062 | AF22: {=INDEX('[1]Mar-24'!N:N,MATCH(CONCATENATE('4. Live Offers'!B22,"",'4. Live Offers'!E22),CONCATENATE('[1]Mar-24'!B:B,"",'[1]Mar-24'!C:C),0))} -> 20340 | AG22: =IFERROR((AD22-AF22)/AF22,"-") -> 0.27826942 | AI22: 3 | AJ22: 6 | AK22: 0 | AL22: =(-(AD22/12)*AJ22) -> -13000 | AM22: =IFERROR((-AK22)/(AD22/12),"-") -> 0 | AN22: =IFERROR(AM22+AJ22,"-") -> 6 | AO22: =AL22+AK22 -> -13000 | AP22: =IFERROR(-AO22/G22,"-") -> 14.380531 | AQ22: =IFERROR((IF(X22<W22,((AD22*X22+AO22)/X22),(AD22*W22+AO22)/W22)),"-") -> 24700 | AR22: {=INDEX('[1]Mar-24'!S:S,MATCH(CONCATENATE('4. Live Offers'!B22,"",'4. Live Offers'!E22),CONCATENATE('[1]Mar-24'!B:B,"",'[1]Mar-24'!C:C),0))} -> 0.075 | AS22: {=INDEX('[1]Mar-24'!R:R,MATCH(CONCATENATE('4. Live Offers'!B22,"",'4. Live Offers'!E22),CONCATENATE('[1]Mar-24'!B:B,"",'[1]Mar-24'!C:C),0))} -> 172333.85 | AT22: =IFERROR((1+AR22)^-(AI22/12)*(1/AR22),"-") -> 13.094431 | AU22: =IFERROR(AQ22*AT22,"-") -> 323432.44 | AV22: =IFERROR(((AT22*AQ22)-AS22)/AS22,"-") -> 0.87677831 | AX22: 45464 | BA22: =IFERROR(DATEDIF(AX22,AY22,"m"),"In Progress") -> In Progress | BB22: 45689 | BD22: Tamba Day Nursery | BE22: April-24 | BF22: Required additional cap con | BH22: as above
B23: The Forge | C23: =INDEX('[1]2. Asset Dashboard'!E:E,MATCH('4. Live Offers'!B23,'[1]2. Asset Dashboard'!C:C,0)) -> Newcastle | E23: 1 | F23: {=IF(INDEX('[1]3. Unit-Level Index'!H:H,MATCH(CONCATENATE('4. Live Offers'!B23," ",'4. Live Offers'!E23),CONCATENATE('[1]3. Unit-Level Index'!B:B," ",'[1]3. Unit-Level Index'!G:G),0))="","-",(INDEX('[1]3. Unit-Level Index'!H:H,MATCH(CONCATENATE('4. Live Offers'!B23," ",'4. Live Offers'!E23),CONCATENATE('[1]3. Unit-Level Index'!B:B," ",'[1]3. Unit-Level Index'!G:G),0))))} -> 222675001 | G23: {=INDEX('[1]3. Unit-Level Index'!M:M,MATCH(CONCATENATE('4. Live Offers'!B23,"",'4. Live Offers'!E23),CONCATENATE('[1]3. Unit-Level Index'!B:B,"",'[1]3. Unit-Level Index'!G:G),0))} -> 2901 | H23: =AV23 -> -0.077646834 | J23: Yes | K23: Yes | L23: Yes | N23: Yes | P23: 45457 | Q23: Sanco Pizza Limted | S23: Bradley Hall | T23: Personal Guarantee | U23: Restaurant | W23: 10 | X23: 10 | Y23: 5 | Z23: Outside | AA23: 0 | AB23: =AD23/12*6 -> 14500 | AC23: 29950 | AD23: 29000 | AE23: =IFERROR(AD23/G23,0) -> 9.9965529 | AF23: {=INDEX('[1]Mar-24'!N:N,MATCH(CONCATENATE('4. Live Offers'!B23,"",'4. Live Offers'!E23),CONCATENATE('[1]Mar-24'!B:B,"",'[1]Mar-24'!C:C),0))} -> 29010 | AG23: =IFERROR((AD23-AF23)/AF23,"-") -> -0.00034470872 | AI23: 6 | AJ23: 8 | AK23: -80000 | AL23: =(-(AD23/12)*AJ23) -> -19333.333 | AM23: =IFERROR((-AK23)/(AD23/12),"-") -> 33.103448 | AN23: =IFERROR(AM23+AJ23,"-") -> 41.103448 | AO23: =AL23+AK23 -> -99333.333 | AP23: =IFERROR(-AO23/G23,"-") -> 34.241066 | AQ23: =IFERROR((IF(X23<W23,((AD23*X23+AO23)/X23),(AD23*W23+AO23)/W23)),"-") -> 19066.667 | AR23: 0.09 | AS23: {=INDEX('[1]Mar-24'!R:R,MATCH(CONCATENATE('4. Live Offers'!B23,"",'4. Live Offers'!E23),CONCATENATE('[1]Mar-24'!B:B,"",'[1]Mar-24'!C:C),0))} -> 219999.54 | AT23: =IFERROR((1+AR23)^-(AI23/12)*(1/AR23),"-") -> 10.642514 | AU23: =IFERROR(AQ23*AT23,"-") -> 202917.27 | AV23: =IFERROR(((AT23*AQ23)-AS23)/AS23,"-") -> -0.077646834 | BA23: In Progress | BB23: 45627 | BH23: 25/10 - renegotiating terms - have chased up 25/10
B24: Redcliffe Quarter | C24: =INDEX('[1]2. Asset Dashboard'!E:E,MATCH('4. Live Offers'!B24,'[1]2. Asset Dashboard'!C:C,0)) -> Bristol | E24: 1.1 | F24: {=IF(INDEX('[1]3. Unit-Level Index'!H:H,MATCH(CONCATENATE('4. Live Offers'!B24," ",'4. Live Offers'!E24),CONCATENATE('[1]3. Unit-Level Index'!B:B," ",'[1]3. Unit-Level Index'!G:G),0))="","-",(INDEX('[1]3. Unit-Level Index'!H:H,MATCH(CONCATENATE('4. Live Offers'!B24," ",'4. Live Offers'!E24),CONCATENATE('[1]3. Unit-Level Index'!B:B," ",'[1]3. Unit-Level Index'!G:G),0))))} -> 222707001 | G24: {=INDEX('[1]3. Unit-Level Index'!M:M,MATCH(CONCATENATE('4. Live Offers'!B24,"",'4. Live Offers'!E24),CONCATENATE('[1]3. Unit-Level Index'!B:B,"",'[1]3. Unit-Level Index'!G:G),0))} -> 1452 | H24: =AV24 -> 0.15072902 | J24: Yes | K24: Yes | L24: Yes | P24: 45552 | Q24: Wendy Zhang | S24: Alder King | T24: - | U24: Therapy clinic | W24: 15 | X24: 15 | Y24: 5 | Z24: Outside | AA24: TBC | AB24: 8000 | AD24: 33733 | AE24: =IFERROR(AD24/G24,0) -> 23.232094 | AF24: {=INDEX('[1]Mar-24'!N:N,MATCH(CONCATENATE('4. Live Offers'!B24,"",'4. Live Offers'!E24),CONCATENATE('[1]Mar-24'!B:B,"",'[1]Mar-24'!C:C),0))} -> 36300 | AG24: =IFERROR((AD24-AF24)/AF24,"-") -> -0.070716253 | AI24: 3 | AJ24: 6 | AK24: 0 | AL24: =(-(AD24/12)*AJ24) -> -16866.5 | AM24: =IFERROR((-AK24)/(AD24/12),"-") -> 0 | AN24: =IFERROR(AM24+AJ24,"-") -> 6 | AO24: =AL24+AK24 -> -16866.5 | AP24: =IFERROR(-AO24/G24,"-") -> 11.616047 | AQ24: =IFERROR((IF(X24<W24,((AD24*X24+AO24)/X24),(AD24*W24+AO24)/W24)),"-") -> 32608.567 | AR24: {=INDEX('[1]Mar-24'!S:S,MATCH(CONCATENATE('4. Live Offers'!B24,"",'4. Live Offers'!E24),CONCATENATE('[1]Mar-24'!B:B,"",'[1]Mar-24'!C:C),0))} -> 0.0825 | AS24: {=INDEX('[1]Mar-24'!R:R,MATCH(CONCATENATE('4. Live Offers'!B24,"",'4. Live Offers'!E24),CONCATENATE('[1]Mar-24'!B:B,"",'[1]Mar-24'!C:C),0))} -> 336742.33 | AT24: =IFERROR((1+AR24)^-(AI24/12)*(1/AR24),"-") -> 11.883355 | AU24: =IFERROR(AQ24*AT24,"-") -> 387499.18 | AV24: =IFERROR(((AT24*AQ24)-AS24)/AS24,"-") -> 0.15072902 | AX24: 45576 | BA24: In Progress | BB24: 45689 | BH24: 25/10 - MPAN being created with monarch
B25: Enigma Square | C25: =INDEX('[1]2. Asset Dashboard'!E:E,MATCH('4. Live Offers'!B25,'[1]2. Asset Dashboard'!C:C,0)) -> Milton Keynes | E25: 1 | F25: {=IF(INDEX('[1]3. Unit-Level Index'!H:H,MATCH(CONCATENATE('4. Live Offers'!B25," ",'4. Live Offers'!E25),CONCATENATE('[1]3. Unit-Level Index'!B:B," ",'[1]3. Unit-Level Index'!G:G),0))="","-",(INDEX('[1]3. Unit-Level Index'!H:H,MATCH(CONCATENATE('4. Live Offers'!B25," ",'4. Live Offers'!E25),CONCATENATE('[1]3. Unit-Level Index'!B:B," ",'[1]3. Unit-Level Index'!G:G),0))))} -> 222711001 | G25: {=INDEX('[1]3. Unit-Level Index'!M:M,MATCH(CONCATENATE('4. Live Offers'!B25,"",'4. Live Offers'!E25),CONCATENATE('[1]3. Unit-Level Index'!B:B,"",'[1]3. Unit-Level Index'!G:G),0))} -> 5489 | H25: =AV25 -> 0.51200648 | J25: Yes | K25: Yes | L25: Yes | M25: Yes | N25: Yes | P25: 45489 | Q25: Krishna Asian Food Market Limited | S25: Louch Shacklock | U25: Supermarket | W25: 15 | X25: 15 | Y25: 5 | Z25: Outside | AA25: TBC | AB25: 60379 | AD25: 137225 | AE25: =IFERROR(AD25/G25,0) -> 25 | AF25: {=INDEX('[1]Mar-24'!N:N,MATCH(CONCATENATE('4. Live Offers'!B25,"",'4. Live Offers'!E25),CONCATENATE('[1]Mar-24'!B:B,"",'[1]Mar-24'!C:C),0))} -> 109780 | AG25: =IFERROR((AD25-AF25)/AF25,"-") -> 0.25 | AI25: 2 | AJ25: 17 | AK25: 0 | AL25: =(-(AD25/12)*AJ25) -> -194402.08 | AM25: =IFERROR((-AK25)/(AD25/12),"-") -> 0 | AN25: =IFERROR(AM25+AJ25,"-") -> 17 | AO25: =AL25+AK25 -> -194402.08 | AP25: =IFERROR(-AO25/G25,"-") -> 35.416667 | AQ25: =IFERROR((IF(X25<W25,((AD25*X25+AO25)/X25),(AD25*W25+AO25)/W25)),"-") -> 124264.86 | AR25: 0.085 | AS25: {=INDEX('[1]Mar-24'!R:R,MATCH(CONCATENATE('4. Live Offers'!B25,"",'4. Live Offers'!E25),CONCATENATE('[1]Mar-24'!B:B,"",'[1]Mar-24'!C:C),0))} -> 953829.62 | AT25: =IFERROR((1+AR25)^-(AI25/12)*(1/AR25),"-") -> 11.605828 | AU25: =IFERROR(AQ25*AT25,"-") -> 1442196.6 | AV25: =IFERROR(((AT25*AQ25)-AS25)/AS25,"-") -> 0.51200648 | AX25: 45488 | BA25: =IFERROR(DATEDIF(AX25,AY25,"m"),"In Progress") -> In Progress | BB25: 45689 | BH25: 25/10 - awaiting response from tenants sols - structural mezzanine being reviewed by Arcadis
B26: Hale Wharf 2 | C26: =INDEX('[1]2. Asset Dashboard'!E:E,MATCH('4. Live Offers'!B26,'[1]2. Asset Dashboard'!C:C,0)) -> London | E26: 1 | F26: {=IF(INDEX('[1]3. Unit-Level Index'!H:H,MATCH(CONCATENATE('4. Live Offers'!B26," ",'4. Live Offers'!E26),CONCATENATE('[1]3. Unit-Level Index'!B:B," ",'[1]3. Unit-Level Index'!G:G),0))="","-",(INDEX('[1]3. Unit-Level Index'!H:H,MATCH(CONCATENATE('4. Live Offers'!B26," ",'4. Live Offers'!E26),CONCATENATE('[1]3. Unit-Level Index'!B:B," ",'[1]3. Unit-Level Index'!G:G),0))))} -> - | G26: {=INDEX('[1]3. Unit-Level Index'!M:M,MATCH(CONCATENATE('4. Live Offers'!B26,"",'4. Live Offers'!E26),CONCATENATE('[1]3. Unit-Level Index'!B:B,"",'[1]3. Unit-Level Index'!G:G),0))} -> 1159 | H26: =AV26 -> 0.28039401 | J26: Yes | Q26: NewCo | S26: Strettons | U26: Café Bistro | W26: 15 | X26: 15 | Y26: 5 | Z26: Outside | AA26: TBC | AB26: 14500 | AC26: 29000 | AD26: 29000 | AE26: =IFERROR(AD26/G26,0) -> 25.02157 | AF26: {=INDEX('[1]Mar-24'!N:N,MATCH(CONCATENATE('4. Live Offers'!B26,"",'4. Live Offers'!E26),CONCATENATE('[1]Mar-24'!B:B,"",'[1]Mar-24'!C:C),0))} -> 26078 | AG26: =IFERROR((AD26-AF26)/AF26,"-") -> 0.11204847 | AI26: 3 | AJ26: 8 | AK26: 0 | AL26: =(-(AD26/12)*AJ26) -> -19333.333 | AM26: =IFERROR((-AK26)/(AD26/12),"-") -> 0 | AN26: =IFERROR(AM26+AJ26,"-") -> 8 | AO26: =AL26+AK26 -> -19333.333 | AP26: =IFERROR(-AO26/G26,"-") -> 16.681047 | AQ26: =IFERROR((IF(X26<W26,((AD26*X26+AO26)/X26),(AD26*W26+AO26)/W26)),"-") -> 27711.111 | AR26: {=INDEX('[1]Mar-24'!S:S,MATCH(CONCATENATE('4. Live Offers'!B26,"",'4. Live Offers'!E26),CONCATENATE('[1]Mar-24'!B:B,"",'[1]Mar-24'!C:C),0))} -> 0.0775 | AS26: {=INDEX('[1]Mar-24'!R:R,MATCH(CONCATENATE('4. Live Offers'!B26,"",'4. Live Offers'!E26),CONCATENATE('[1]Mar-24'!B:B,"",'[1]Mar-24'!C:C),0))} -> 274097 | AT26: =IFERROR((1+AR26)^-(AI26/12)*(1/AR26),"-") -> 12.664673 | AU26: =IFERROR(AQ26*AT26,"-") -> 350952.16 | AV26: =IFERROR(((AT26*AQ26)-AS26)/AS26,"-") -> 0.28039401
B27: Gilders Yard | C27: =INDEX('[1]2. Asset Dashboard'!E:E,MATCH('4. Live Offers'!B27,'[1]2. Asset Dashboard'!C:C,0)) -> Birmingham | E27: B02 | F27: {=IF(INDEX('[1]3. Unit-Level Index'!H:H,MATCH(CONCATENATE('4. Live Offers'!B27," ",'4. Live Offers'!E27),CONCATENATE('[1]3. Unit-Level Index'!B:B," ",'[1]3. Unit-Level Index'!G:G),0))="","-",(INDEX('[1]3. Unit-Level Index'!H:H,MATCH(CONCATENATE('4. Live Offers'!B27," ",'4. Live Offers'!E27),CONCATENATE('[1]3. Unit-Level Index'!B:B," ",'[1]3. Unit-Level Index'!G:G),0))))} -> 222690003 | G27: {=INDEX('[1]3. Unit-Level Index'!M:M,MATCH(CONCATENATE('4. Live Offers'!B27,"",'4. Live Offers'!E27),CONCATENATE('[1]3. Unit-Level Index'!B:B,"",'[1]3. Unit-Level Index'!G:G),0))} -> 1747 | H27: =AV27 -> 0.099904136 | J27: Yes | K27: Yes | L27: Yes | N27: Yes | P27: 45527 | Q27: Hepstone Ltd | S27: Siddall Jones | U27: Wellness Club | W27: 5 | X27: 3 | Y27: 3 | Z27: Outside | AA27: TBC | AB27: 13750 | AC27: 27500 | AD27: 27500 | AE27: =IFERROR(AD27/G27,0) -> 15.741271 | AF27: {=INDEX('[1]Mar-24'!N:N,MATCH(CONCATENATE('4. Live Offers'!B27,"",'4. Live Offers'!E27),CONCATENATE('[1]Mar-24'!B:B,"",'[1]Mar-24'!C:C),0))} -> 25768.25 | AG27: =IFERROR((AD27-AF27)/AF27,"-") -> 0.067204797 | AI27: 3 | AJ27: 6 | AK27: 0 | AL27: =(-(AD27/12)*AJ27) -> -13750 | AM27: =IFERROR((-AK27)/(AD27/12),"-") -> 0 | AN27: =IFERROR(AM27+AJ27,"-") -> 6 | AO27: =AL27+AK27 -> -13750 | AP27: =IFERROR(-AO27/G27,"-") -> 7.8706354 | AQ27: =IFERROR((IF(X27<W27,((AD27*X27+AO27)/X27),(AD27*W27+AO27)/W27)),"-") -> 22916.667 | AR27: {=INDEX('[1]Mar-24'!S:S,MATCH(CONCATENATE('4. Live Offers'!B27,"",'4. Live Offers'!E27),CONCATENATE('[1]Mar-24'!B:B,"",'[1]Mar-24'!C:C),0))} -> 0.1 | AS27: {=INDEX('[1]Mar-24'!R:R,MATCH(CONCATENATE('4. Live Offers'!B27,"",'4. Live Offers'!E27),CONCATENATE('[1]Mar-24'!B:B,"",'[1]Mar-24'!C:C),0))} -> 203445.67 | AT27: =IFERROR((1+AR27)^-(AI27/12)*(1/AR27),"-") -> 9.7645409 | AU27: =IFERROR(AQ27*AT27,"-") -> 223770.73 | AV27: =IFERROR(((AT27*AQ27)-AS27)/AS27,"-") -> 0.099904136 | AX27: 45506 | AZ27: Signe (Russell Cooke) | BA27: =IFERROR(DATEDIF(AX27,AY27,"m"),"In Progress") -> In Progress | BB27: 45590 | BH27: 25/10 - update requested from sol, exchange expected iminintely
B28: Weavers Yard | C28: =INDEX('[1]2. Asset Dashboard'!E:E,MATCH('4. Live Offers'!B28,'[1]2. Asset Dashboard'!C:C,0)) -> Newbury | E28: Block H - Unit 8 (4 Station Approach) | F28: {=IF(INDEX('[1]3. Unit-Level Index'!H:H,MATCH(CONCATENATE('4. Live Offers'!B28," ",'4. Live Offers'!E28),CONCATENATE('[1]3. Unit-Level Index'!B:B," ",'[1]3. Unit-Level Index'!G:G),0))="","-",(INDEX('[1]3. Unit-Level Index'!H:H,MATCH(CONCATENATE('4. Live Offers'!B28," ",'4. Live Offers'!E28),CONCATENATE('[1]3. Unit-Level Index'!B:B," ",'[1]3. Unit-Level Index'!G:G),0))))} -> 222698008 | G28: {=INDEX('[1]3. Unit-Level Index'!M:M,MATCH(CONCATENATE('4. Live Offers'!B28,"",'4. Live Offers'!E28),CONCATENATE('[1]3. Unit-Level Index'!B:B,"",'[1]3. Unit-Level Index'!G:G),0))} -> 646 | H28: =AV28 -> 0.1354317 | J28: Yes | K28: Yes | L28: Yes | P28: - | Q28: Parasol Coffee Ltd | S28: Quintons | T28: - | U28: Café | W28: 10 | X28: 5 | Y28: 5 | Z28: outside | AA28: TBC | AB28: 7750 | AC28: 16150 | AD28: 15342.5 | AE28: =IFERROR(AD28/G28,0) -> 23.75 | AF28: {=INDEX('[1]Mar-24'!N:N,MATCH(CONCATENATE('4. Live Offers'!B28,"",'4. Live Offers'!E28),CONCATENATE('[1]Mar-24'!B:B,"",'[1]Mar-24'!C:C),0))} -> 12274 | AG28: =IFERROR((AD28-AF28)/AF28,"-") -> 0.25 | AI28: 3 | AJ28: 6 | AK28: -15000 | AL28: =(-(AD28/12)*AJ28) -> -7671.25 | AM28: =IFERROR((-AK28)/(AD28/12),"-") -> 11.732117 | AN28: =IFERROR(AM28+AJ28,"-") -> 17.732117 | AO28: =AL28+AK28 -> -22671.25 | AP28: =IFERROR(-AO28/G28,"-") -> 35.094814 | AQ28: =IFERROR((IF(X28<W28,((AD28*X28+AO28)/X28),(AD28*W28+AO28)/W28)),"-") -> 10808.25 | AR28: {=INDEX('[1]Mar-24'!S:S,MATCH(CONCATENATE('4. Live Offers'!B28,"",'4. Live Offers'!E28),CONCATENATE('[1]Mar-24'!B:B,"",'[1]Mar-24'!C:C),0))} -> 0.09 | AS28: {=INDEX('[1]Mar-24'!R:R,MATCH(CONCATENATE('4. Live Offers'!B28,"",'4. Live Offers'!E28),CONCATENATE('[1]Mar-24'!B:B,"",'[1]Mar-24'!C:C),0))} -> 103513.08 | AT28: =IFERROR((1+AR28)^-(AI28/12)*(1/AR28),"-") -> 10.874289 | AU28: =IFERROR(AQ28*AT28,"-") -> 117532.03 | AV28: =IFERROR(((AT28*AQ28)-AS28)/AS28,"-") -> 0.1354317 | AX28: 45520 | AZ28: Signe (Russell Cooke) | BA28: =IFERROR(DATEDIF(AX28,AY28,"m"),"In Progress") -> In Progress | BB28: 45748 | BH28: 25/10 afl for access june, then september for trading, to cover legal fees for afl
B29: Hawkins & George | C29: =INDEX('[1]2. Asset Dashboard'!E:E,MATCH('4. Live Offers'!B29,'[1]2. Asset Dashboard'!C:C,0)) -> Bristol | E29: 3 | F29: {=IF(INDEX('[1]3. Unit-Level Index'!H:H,MATCH(CONCATENATE('4. Live Offers'!B29," ",'4. Live Offers'!E29),CONCATENATE('[1]3. Unit-Level Index'!B:B," ",'[1]3. Unit-Level Index'!G:G),0))="","-",(INDEX('[1]3. Unit-Level Index'!H:H,MATCH(CONCATENATE('4. Live Offers'!B29," ",'4. Live Offers'!E29),CONCATENATE('[1]3. Unit-Level Index'!B:B," ",'[1]3. Unit-Level Index'!G:G),0))))} -> 222625003 | G29: {=INDEX('[1]3. Unit-Level Index'!M:M,MATCH(CONCATENATE('4. Live Offers'!B29,"",'4. Live Offers'!E29),CONCATENATE('[1]3. Unit-Level Index'!B:B,"",'[1]3. Unit-Level Index'!G:G),0))} -> 1470 | H29: =AV29 -> 0.055251913 | J29: Yes | K29: Yes | L29: Yes | P29: Awaited | Q29: (New Co) Sky Kong Kong Kitchen | S29: Flueretts | U29: Cafe | W29: 10 | X29: 10 | Y29: 5 | Z29: Outside | AA29: TBC | AB29: 14250 | AC29: 30000 | AD29: 28500 | AE29: =IFERROR(AD29/G29,0) -> 19.387755 | AF29: {=INDEX('[1]Mar-24'!N:N,MATCH(CONCATENATE('4. Live Offers'!B29,"",'4. Live Offers'!E29),CONCATENATE('[1]Mar-24'!B:B,"",'[1]Mar-24'!C:C),0))} -> 30000 | AG29: =IFERROR((AD29-AF29)/AF29,"-") -> -0.05 | AI29: 3 | AJ29: 9 | AK29: -12000 | AL29: =(-(AD29/12)*AJ29) -> -21375 | AM29: =IFERROR((-AK29)/(AD29/12),"-") -> 5.0526316 | AN29: =IFERROR(AM29+AJ29,"-") -> 14.052632 | AO29: =AL29+AK29 -> -33375 | AP29: =IFERROR(-AO29/G29,"-") -> 22.704082 | AQ29: =IFERROR((IF(X29<W29,((AD29*X29+AO29)/X29),(AD29*W29+AO29)/W29)),"-") -> 25162.5 | AR29: {=INDEX('[1]Mar-24'!S:S,MATCH(CONCATENATE('4. Live Offers'!B29,"",'4. Live Offers'!E29),CONCATENATE('[1]Mar-24'!B:B,"",'[1]Mar-24'!C:C),0))} -> 0.09 | AS29: {=INDEX('[1]Mar-24'!R:R,MATCH(CONCATENATE('4. Live Offers'!B29,"",'4. Live Offers'!E29),CONCATENATE('[1]Mar-24'!B:B,"",'[1]Mar-24'!C:C),0))} -> 259297.61 | AT29: =IFERROR((1+AR29)^-(AI29/12)*(1/AR29),"-") -> 10.874289 | AU29: =IFERROR(AQ29*AT29,"-") -> 273624.29 | AV29: =IFERROR(((AT29*AQ29)-AS29)/AS29,"-") -> 0.055251913 | AX29: 45520 | AZ29: WBD (TBC) | BA29: In Progress | BB29: 45717 | BH29: 25/10 - Lease to complete by 31/10/24
B30: The Tilt Works | C30: =INDEX('[1]2. Asset Dashboard'!E:E,MATCH('4. Live Offers'!B30,'[1]2. Asset Dashboard'!C:C,0)) -> Sheffield | E30: 1 | F30: {=IF(INDEX('[1]3. Unit-Level Index'!H:H,MATCH(CONCATENATE('4. Live Offers'!B30," ",'4. Live Offers'!E30),CONCATENATE('[1]3. Unit-Level Index'!B:B," ",'[1]3. Unit-Level Index'!G:G),0))="","-",(INDEX('[1]3. Unit-Level Index'!H:H,MATCH(CONCATENATE('4. Live Offers'!B30," ",'4. Live Offers'!E30),CONCATENATE('[1]3. Unit-Level Index'!B:B," ",'[1]3. Unit-Level Index'!G:G),0))))} -> 222757001 | G30: {=INDEX('[1]3. Unit-Level Index'!M:M,MATCH(CONCATENATE('4. Live Offers'!B30,"",'4. Live Offers'!E30),CONCATENATE('[1]3. Unit-Level Index'!B:B,"",'[1]3. Unit-Level Index'!G:G),0))} -> 613 | H30: =AV30 -> 0.62190458 | J30: Yes | K30: Yes | L30: Yes | Q30: New Co Star Convenience | S30: Knight Frank | U30: Convenience store | W30: 5 | X30: 3 | Y30: 3 | Z30: Outside | AA30: TBC | AB30: 6000 | AD30: 12000 | AE30: =IFERROR(AD30/G30,0) -> 19.575856 | AF30: {=INDEX('[1]Mar-24'!N:N,MATCH(CONCATENATE('4. Live Offers'!B30,"",'4. Live Offers'!E30),CONCATENATE('[1]Mar-24'!B:B,"",'[1]Mar-24'!C:C),0))} -> 9384 | AG30: =IFERROR((AD30-AF30)/AF30,"-") -> 0.27877238 | AI30: 3 | AJ30: 3 | AK30: 0 | AL30: =(-(AD30/12)*AJ30) -> -3000 | AM30: =IFERROR((-AK30)/(AD30/12),"-") -> 0 | AN30: =IFERROR(AM30+AJ30,"-") -> 3 | AO30: =AL30+AK30 -> -3000 | AP30: =IFERROR(-AO30/G30,"-") -> 4.8939641 | AQ30: =IFERROR((IF(X30<W30,((AD30*X30+AO30)/X30),(AD30*W30+AO30)/W30)),"-") -> 11000 | AR30: {=INDEX('[1]Mar-24'!S:S,MATCH(CONCATENATE('4. Live Offers'!B30,"",'4. Live Offers'!E30),CONCATENATE('[1]Mar-24'!B:B,"",'[1]Mar-24'!C:C),0))} -> 0.105 | AS30: {=INDEX('[1]Mar-24'!R:R,MATCH(CONCATENATE('4. Live Offers'!B30,"",'4. Live Offers'!E30),CONCATENATE('[1]Mar-24'!B:B,"",'[1]Mar-24'!C:C),0))} -> 62999.56 | AT30: =IFERROR((1+AR30)^-(AI30/12)*(1/AR30),"-") -> 9.289025 | AU30: =IFERROR(AQ30*AT30,"-") -> 102179.27 | AV30: =IFERROR(((AT30*AQ30)-AS30)/AS30,"-") -> 0.62190458 | AX30: 45568 | BA30: In Progress | BB30: 45748 | BH30: 25/10 - to return cpse replies
B31: The Filaments | C31: =INDEX('[1]2. Asset Dashboard'!E:E,MATCH('4. Live Offers'!B31,'[1]2. Asset Dashboard'!C:C,0)) -> Manchester | E31: Podium A/B - Unit 1 | G31: {=INDEX('[1]3. Unit-Level Index'!M:M,MATCH(CONCATENATE('4. Live Offers'!B31,"",'4. Live Offers'!E31),CONCATENATE('[1]3. Unit-Level Index'!B:B,"",'[1]3. Unit-Level Index'!G:G),0))} -> 1069 | H31: =AV31 -> 0.15137492 | J31: Yes | K31: Yes | L31: Yes | Q31: Fiori Café | S31: LTL Property Consultants | U31: Cafe | W31: 10 | X31: 10 | Y31: 5 | Z31: outside | AB31: 6250 | AD31: 25000 | AE31: =IFERROR(AD31/G31,0) -> 23.386342 | AF31: {=INDEX('[1]Mar-24'!N:N,MATCH(CONCATENATE('4. Live Offers'!B31,"",'4. Live Offers'!E31),CONCATENATE('[1]Mar-24'!B:B,"",'[1]Mar-24'!C:C),0))} -> 25000 | AG31: =IFERROR((AD31-AF31)/AF31,"-") -> 0 | AI31: 3 | AJ31: 9 | AK31: 0 | AL31: =(-(AD31/12)*AJ31) -> -18750 | AM31: =IFERROR((-AK31)/(AD31/12),"-") -> 0 | AN31: =IFERROR(AM31+AJ31,"-") -> 9 | AO31: =AL31+AK31 -> -18750 | AP31: =IFERROR(-AO31/G31,"-") -> 17.539757 | AQ31: =IFERROR((IF(X31<W31,((AD31*X31+AO31)/X31),(AD31*W31+AO31)/W31)),"-") -> 23125 | AR31: {=INDEX('[1]Mar-24'!S:S,MATCH(CONCATENATE('4. Live Offers'!B31,"",'4. Live Offers'!E31),CONCATENATE('[1]Mar-24'!B:B,"",'[1]Mar-24'!C:C),0))} -> 0.09 | AS31: {=INDEX('[1]Mar-24'!R:R,MATCH(CONCATENATE('4. Live Offers'!B31,"",'4. Live Offers'!E31),CONCATENATE('[1]Mar-24'!B:B,"",'[1]Mar-24'!C:C),0))} -> 218406.64 | AT31: =IFERROR((1+AR31)^-(AI31/12)*(1/AR31),"-") -> 10.874289 | AU31: =IFERROR(AQ31*AT31,"-") -> 251467.93 | AV31: =IFERROR(((AT31*AQ31)-AS31)/AS31,"-") -> 0.15137492 | BH31: 25/10 - tenants solicitor details awaited, chasing regularly, have asked other agent to reach out to other offeror
B32: Block D2 Hallsville Q | C32: =INDEX('[1]2. Asset Dashboard'!E:E,MATCH('4. Live Offers'!B32,'[1]2. Asset Dashboard'!C:C,0)) -> London | G32: {=INDEX('[1]3. Unit-Level Index'!M:M,MATCH(CONCATENATE('4. Live Offers'!B32,"",'4. Live Offers'!E32),CONCATENATE('[1]3. Unit-Level Index'!B:B,"",'[1]3. Unit-Level Index'!G:G),0))} -> #N/A | H32: =AV32 -> - | J32: No | Q32: Kiki and MiuMiu Ltd | S32: Lunson Mitchenall | U32: Supermarket | W32: 15 | X32: 5 | Y32: 5 | Z32: Outside | AB32: 25000 | AD32: 100000 | AE32: =IFERROR(AD32/G32,0) -> 0 | AF32: {=INDEX('[1]Mar-24'!N:N,MATCH(CONCATENATE('4. Live Offers'!B32,"",'4. Live Offers'!E32),CONCATENATE('[1]Mar-24'!B:B,"",'[1]Mar-24'!C:C),0))} -> #N/A | AG32: =IFERROR((AD32-AF32)/AF32,"-") -> - | AI32: 3 | AJ32: 18 | AK32: 0 | AL32: =(-(AD32/12)*AJ32) -> -150000 | AM32: =IFERROR((-AK32)/(AD32/12),"-") -> 0 | AN32: =IFERROR(AM32+AJ32,"-") -> 18 | AO32: =AL32+AK32 -> -150000 | AP32: =IFERROR(-AO32/G32,"-") -> - | AQ32: =IFERROR((IF(X32<W32,((AD32*X32+AO32)/X32),(AD32*W32+AO32)/W32)),"-") -> 70000 | AR32: {=INDEX('[1]Mar-24'!S:S,MATCH(CONCATENATE('4. Live Offers'!B32,"",'4. Live Offers'!E32),CONCATENATE('[1]Mar-24'!B:B,"",'[1]Mar-24'!C:C),0))} -> #N/A | AS32: {=INDEX('[1]Mar-24'!R:R,MATCH(CONCATENATE('4. Live Offers'!B32,"",'4. Live Offers'!E32),CONCATENATE('[1]Mar-24'!B:B,"",'[1]Mar-24'!C:C),0))} -> #N/A | AT32: =IFERROR((1+AR32)^-(AI32/12)*(1/AR32),"-") -> - | AU32: =IFERROR(AQ32*AT32,"-") -> - | AV32: =IFERROR(((AT32*AQ32)-AS32)/AS32,"-") -> - | BH32: 25/10 - chased agents for update
B33: Enigma Square | C33: =INDEX('[1]2. Asset Dashboard'!E:E,MATCH('4. Live Offers'!B33,'[1]2. Asset Dashboard'!C:C,0)) -> Milton Keynes | E33: 2 | G33: {=INDEX('[1]3. Unit-Level Index'!M:M,MATCH(CONCATENATE('4. Live Offers'!B33,"",'4. Live Offers'!E33),CONCATENATE('[1]3. Unit-Level Index'!B:B,"",'[1]3. Unit-Level Index'!G:G),0))} -> 1241 | H33: =AV33 -> 0.33325002 | J33: Yes | K33: Yes | P33: 45554 | Q33: New Co | S33: Louch Shacklock | U33: Dentist | W33: 15 | X33: 15 | Y33: 5 | Z33: Outside | AB33: 15500 | AD33: 31000 | AE33: =IFERROR(AD33/G33,0) -> 24.979855 | AF33: {=INDEX('[1]Mar-24'!N:N,MATCH(CONCATENATE('4. Live Offers'!B33,"",'4. Live Offers'!E33),CONCATENATE('[1]Mar-24'!B:B,"",'[1]Mar-24'!C:C),0))} -> 27922.5 | AG33: =IFERROR((AD33-AF33)/AF33,"-") -> 0.11021578 | AI33: 3 | AJ33: 17 | AK33: 0 | AL33: =(-(AD33/12)*AJ33) -> -43916.667 | AM33: =IFERROR((-AK33)/(AD33/12),"-") -> 0 | AN33: =IFERROR(AM33+AJ33,"-") -> 17 | AO33: =AL33+AK33 -> -43916.667 | AP33: =IFERROR(-AO33/G33,"-") -> 35.388128 | AQ33: =IFERROR((IF(X33<W33,((AD33*X33+AO33)/X33),(AD33*W33+AO33)/W33)),"-") -> 28072.222 | AR33: {=INDEX('[1]Mar-24'!S:S,MATCH(CONCATENATE('4. Live Offers'!B33,"",'4. Live Offers'!E33),CONCATENATE('[1]Mar-24'!B:B,"",'[1]Mar-24'!C:C),0))} -> 0.09 | AS33: {=INDEX('[1]Mar-24'!R:R,MATCH(CONCATENATE('4. Live Offers'!B33,"",'4. Live Offers'!E33),CONCATENATE('[1]Mar-24'!B:B,"",'[1]Mar-24'!C:C),0))} -> 228963.4 | AT33: =IFERROR((1+AR33)^-(AI33/12)*(1/AR33),"-") -> 10.874289 | AU33: =IFERROR(AQ33*AT33,"-") -> 305265.45 | AV33: =IFERROR(((AT33*AQ33)-AS33)/AS33,"-") -> 0.33325002 | BH33: 25/10 - hots awaited to instruct legals
B34: Redcliffe Quarter | C34: =INDEX('[1]2. Asset Dashboard'!E:E,MATCH('4. Live Offers'!B34,'[1]2. Asset Dashboard'!C:C,0)) -> Bristol | E34: 1.3 | G34: {=INDEX('[1]3. Unit-Level Index'!M:M,MATCH(CONCATENATE('4. Live Offers'!B34,"",'4. Live Offers'!E34),CONCATENATE('[1]3. Unit-Level Index'!B:B,"",'[1]3. Unit-Level Index'!G:G),0))} -> 1066 | H34: =AV34 -> -0.05259124 | J34: Yes | K34: Yes | L34: Yes | M34: Yes | N34: Yes | Q34: New Co (Indoor Golf Simulation) | S34: Alder King | U34: Leisure | W34: 5 | X34: 5 | Y34: 5 | Z34: Outside | AB34: 10950 | AC34: 26650 | AD34: 21900 | AE34: =IFERROR(AD34/G34,0) -> 20.54409 | AF34: {=INDEX('[1]Mar-24'!N:N,MATCH(CONCATENATE('4. Live Offers'!B34,"",'4. Live Offers'!E34),CONCATENATE('[1]Mar-24'!B:B,"",'[1]Mar-24'!C:C),0))} -> 26650 | AG34: =IFERROR((AD34-AF34)/AF34,"-") -> -0.1782364 | AI34: 3 | AJ34: 6 | AK34: 0 | AL34: =(-(AD34/12)*AJ34) -> -10950 | AM34: =IFERROR((-AK34)/(AD34/12),"-") -> 0 | AN34: =IFERROR(AM34+AJ34,"-") -> 6 | AO34: =AL34+AK34 -> -10950 | AP34: =IFERROR(-AO34/G34,"-") -> 10.272045 | AQ34: =IFERROR((IF(X34<W34,((AD34*X34+AO34)/X34),(AD34*W34+AO34)/W34)),"-") -> 19710 | AR34: {=INDEX('[1]Mar-24'!S:S,MATCH(CONCATENATE('4. Live Offers'!B34,"",'4. Live Offers'!E34),CONCATENATE('[1]Mar-24'!B:B,"",'[1]Mar-24'!C:C),0))} -> 0.0825 | AS34: {=INDEX('[1]Mar-24'!R:R,MATCH(CONCATENATE('4. Live Offers'!B34,"",'4. Live Offers'!E34),CONCATENATE('[1]Mar-24'!B:B,"",'[1]Mar-24'!C:C),0))} -> 247222.68 | AT34: =IFERROR((1+AR34)^-(AI34/12)*(1/AR34),"-") -> 11.883355 | AU34: =IFERROR(AQ34*AT34,"-") -> 234220.93 | AV34: =IFERROR(((AT34*AQ34)-AS34)/AS34,"-") -> -0.05259124 | AX34: 45573 | BA34: In Progress | BB34: 45719 | BH34: 25/10 - legals progressing, exchange expected before 31/10
B35: Apex Gardens | C35: =INDEX('[1]2. Asset Dashboard'!E:E,MATCH('4. Live Offers'!B35,'[1]2. Asset Dashboard'!C:C,0)) -> London | E35: 1 | G35: {=INDEX('[1]3. Unit-Level Index'!M:M,MATCH(CONCATENATE('4. Live Offers'!B35,"",'4. Live Offers'!E35),CONCATENATE('[1]3. Unit-Level Index'!B:B,"",'[1]3. Unit-Level Index'!G:G),0))} -> 1780 | H35: =AV35 -> -0.12778794 | J35: Yes | K35: Yes | L35: Yes | Q35: NewCo | S35: Strettons | T35: Vision Tek East Coast Ltd | U35: Nursery | W35: 15 | X35: 5 | Y35: 5 | Z35: Outside | AB35: 10000 | AC35: 45000 | AD35: 40000 | AE35: =IFERROR(AD35/G35,0) -> 22.47191 | AF35: {=INDEX('[1]Mar-24'!N:N,MATCH(CONCATENATE('4. Live Offers'!B35,"",'4. Live Offers'!E35),CONCATENATE('[1]Mar-24'!B:B,"",'[1]Mar-24'!C:C),0))} -> 44500 | AG35: =IFERROR((AD35-AF35)/AF35,"-") -> -0.1011236 | AI35: 3 | AJ35: 12 | AK35: 0 | AL35: =(-(AD35/12)*AJ35) -> -40000 | AM35: =IFERROR((-AK35)/(AD35/12),"-") -> 0 | AN35: =IFERROR(AM35+AJ35,"-") -> 12 | AO35: =AL35+AK35 -> -40000 | AP35: =IFERROR(-AO35/G35,"-") -> 22.47191 | AQ35: =IFERROR((IF(X35<W35,((AD35*X35+AO35)/X35),(AD35*W35+AO35)/W35)),"-") -> 32000 | AR35: {=INDEX('[1]Mar-24'!S:S,MATCH(CONCATENATE('4. Live Offers'!B35,"",'4. Live Offers'!E35),CONCATENATE('[1]Mar-24'!B:B,"",'[1]Mar-24'!C:C),0))} -> 0.075 | AS35: {=INDEX('[1]Mar-24'!R:R,MATCH(CONCATENATE('4. Live Offers'!B35,"",'4. Live Offers'!E35),CONCATENATE('[1]Mar-24'!B:B,"",'[1]Mar-24'!C:C),0))} -> 480412.73 | AT35: =IFERROR((1+AR35)^-(AI35/12)*(1/AR35),"-") -> 13.094431 | AU35: =IFERROR(AQ35*AT35,"-") -> 419021.78 | AV35: =IFERROR(((AT35*AQ35)-AS35)/AS35,"-") -> -0.12778794 | AX35: 45581 | BA35: In Progress | BB35: 45717 | BH35: 25/10 - legals instructed
B36: Weavers Yard | C36: =INDEX('[1]2. Asset Dashboard'!E:E,MATCH('4. Live Offers'!B36,'[1]2. Asset Dashboard'!C:C,0)) -> Newbury | E36: Block A - Unit 1 (Unit A Bamboo House) | G36: {=INDEX('[1]3. Unit-Level Index'!M:M,MATCH(CONCATENATE('4. Live Offers'!B36,"",'4. Live Offers'!E36),CONCATENATE('[1]3. Unit-Level Index'!B:B,"",'[1]3. Unit-Level Index'!G:G),0))} -> 2166 | H36: =AV36 -> -0.21130681 | J36: Yes | K36: Yes | Q36: NewCo | S36: Quintons | U36: Bar | W36: 10 | X36: 10 | Y36: 5 | Z36: Outside | AB36: 11250 | AC36: 48000 | AD36: 43950 | AE36: =IFERROR(AD36/G36,0) -> 20.290859 | AF36: {=INDEX('[1]Mar-24'!N:N,MATCH(CONCATENATE('4. Live Offers'!B36,"",'4. Live Offers'!E36),CONCATENATE('[1]Mar-24'!B:B,"",'[1]Mar-24'!C:C),0))} -> 49818 | AG36: =IFERROR((AD36-AF36)/AF36,"-") -> -0.11778875 | AI36: 4 | AJ36: 0 | AK36: -90000 | AL36: =(-(AD36/12)*AJ36) -> 0 | AM36: =IFERROR((-AK36)/(AD36/12),"-") -> 24.573379 | AN36: =IFERROR(AM36+AJ36,"-") -> 24.573379 | AO36: =AL36+AK36 -> -90000 | AP36: =IFERROR(-AO36/G36,"-") -> 41.551247 | AQ36: =IFERROR((IF(X36<W36,((AD36*X36+AO36)/X36),(AD36*W36+AO36)/W36)),"-") -> 34950 | AR36: {=INDEX('[1]Mar-24'!S:S,MATCH(CONCATENATE('4. Live Offers'!B36,"",'4. Live Offers'!E36),CONCATENATE('[1]Mar-24'!B:B,"",'[1]Mar-24'!C:C),0))} -> 0.085 | AS36: {=INDEX('[1]Mar-24'!R:R,MATCH(CONCATENATE('4. Live Offers'!B36,"",'4. Live Offers'!E36),CONCATENATE('[1]Mar-24'!B:B,"",'[1]Mar-24'!C:C),0))} -> 507353.02 | AT36: =IFERROR((1+AR36)^-(AI36/12)*(1/AR36),"-") -> 11.449095 | AU36: =IFERROR(AQ36*AT36,"-") -> 400145.87 | AV36: =IFERROR(((AT36*AQ36)-AS36)/AS36,"-") -> -0.21130681 | BH36: 25/10 - ic approved, hots awaited
B37: Hale Wharf 2 | C37: =INDEX('[1]2. Asset Dashboard'!E:E,MATCH('4. Live Offers'!B37,'[1]2. Asset Dashboard'!C:C,0)) -> London | E37: 2 | G37: {=INDEX('[1]3. Unit-Level Index'!M:M,MATCH(CONCATENATE('4. Live Offers'!B37,"",'4. Live Offers'!E37),CONCATENATE('[1]3. Unit-Level Index'!B:B,"",'[1]3. Unit-Level Index'!G:G),0))} -> 763 | H37: =AV37 -> 0.077962533 | J37: Yes | Q37: Grades Group Ltd | S37: Strettons | U37: Barber | W37: 10 | X37: 10 | Y37: 5 | Z37: Outside | AB37: 9500 | AC37: 19000 | AD37: 19000 | AE37: =IFERROR(AD37/G37,0) -> 24.901704 | AF37: {=INDEX('[1]Mar-24'!N:N,MATCH(CONCATENATE('4. Live Offers'!B37,"",'4. Live Offers'!E37),CONCATENATE('[1]Mar-24'!B:B,"",'[1]Mar-24'!C:C),0))} -> 19075 | AG37: =IFERROR((AD37-AF37)/AF37,"-") -> -0.003931848 | AI37: 3 | AJ37: 12 | AK37: 0 | AL37: =(-(AD37/12)*AJ37) -> -19000 | AM37: =IFERROR((-AK37)/(AD37/12),"-") -> 0 | AN37: =IFERROR(AM37+AJ37,"-") -> 12 | AO37: =AL37+AK37 -> -19000 | AP37: =IFERROR(-AO37/G37,"-") -> 24.901704 | AQ37: =IFERROR((IF(X37<W37,((AD37*X37+AO37)/X37),(AD37*W37+AO37)/W37)),"-") -> 17100 | AR37: {=INDEX('[1]Mar-24'!S:S,MATCH(CONCATENATE('4. Live Offers'!B37,"",'4. Live Offers'!E37),CONCATENATE('[1]Mar-24'!B:B,"",'[1]Mar-24'!C:C),0))} -> 0.0775 | AS37: {=INDEX('[1]Mar-24'!R:R,MATCH(CONCATENATE('4. Live Offers'!B37,"",'4. Live Offers'!E37),CONCATENATE('[1]Mar-24'!B:B,"",'[1]Mar-24'!C:C),0))} -> 200903 | AT37: =IFERROR((1+AR37)^-(AI37/12)*(1/AR37),"-") -> 12.664673 | AU37: =IFERROR(AQ37*AT37,"-") -> 216565.91 | AV37: =IFERROR(((AT37*AQ37)-AS37)/AS37,"-") -> 0.077962533 | BH37: 11/10 - on hold until outcome of change of use to amenity is decided
B38: Block D2 Hallsville Q | C38: =INDEX('[1]2. Asset Dashboard'!E:E,MATCH('4. Live Offers'!B38,'[1]2. Asset Dashboard'!C:C,0)) -> London | E38: Workspace | G38: {=INDEX('[1]3. Unit-Level Index'!M:M,MATCH(CONCATENATE('4. Live Offers'!B38,"",'4. Live Offers'!E38),CONCATENATE('[1]3. Unit-Level Index'!B:B,"",'[1]3. Unit-Level Index'!G:G),0))} -> 4146 | H38: =AV38 -> -0.033028544 | S38: CF Commercial | W38: 20 | X38: 10 | Y38: 5 | Z38: outside | AB38: 77887 | AD38: 103850 | AE38: =IFERROR(AD38/G38,0) -> 25.048239 | AF38: {=INDEX('[1]Mar-24'!N:N,MATCH(CONCATENATE('4. Live Offers'!B38,"",'4. Live Offers'!E38),CONCATENATE('[1]Mar-24'!B:B,"",'[1]Mar-24'!C:C),0))} -> 103100 | AG38: =IFERROR((AD38-AF38)/AF38,"-") -> 0.0072744908 | AI38: 3 | AJ38: 24 | AL38: =(-(AD38/12)*AJ38) -> -207700 | AM38: =IFERROR((-AK38)/(AD38/12),"-") -> 0 | AN38: =IFERROR(AM38+AJ38,"-") -> 24 | AO38: =AL38+AK38 -> -207700 | AP38: =IFERROR(-AO38/G38,"-") -> 50.096479 | AQ38: =IFERROR((IF(X38<W38,((AD38*X38+AO38)/X38),(AD38*W38+AO38)/W38)),"-") -> 83080 | AR38: {=INDEX('[1]Mar-24'!S:S,MATCH(CONCATENATE('4. Live Offers'!B38,"",'4. Live Offers'!E38),CONCATENATE('[1]Mar-24'!B:B,"",'[1]Mar-24'!C:C),0))} -> 0.075 | AS38: {=INDEX('[1]Mar-24'!R:R,MATCH(CONCATENATE('4. Live Offers'!B38,"",'4. Live Offers'!E38),CONCATENATE('[1]Mar-24'!B:B,"",'[1]Mar-24'!C:C),0))} -> 1125043.9 | AT38: =IFERROR((1+AR38)^-(AI38/12)*(1/AR38),"-") -> 13.094431 | AU38: =IFERROR(AQ38*AT38,"-") -> 1087885.3 | AV38: =IFERROR(((AT38*AQ38)-AS38)/AS38,"-") -> -0.033028544
B39: Block D1 Hallsville Q | C39: =INDEX('[1]2. Asset Dashboard'!E:E,MATCH('4. Live Offers'!B39,'[1]2. Asset Dashboard'!C:C,0)) -> London | E39: Unit 2 | G39: {=INDEX('[1]3. Unit-Level Index'!M:M,MATCH(CONCATENATE('4. Live Offers'!B39,"",'4. Live Offers'!E39),CONCATENATE('[1]3. Unit-Level Index'!B:B,"",'[1]3. Unit-Level Index'!G:G),0))} -> 1247 | H39: =AV39 -> 0.095949112 | Q39: Holland & Barrett | S39: Lunson Mitchenall | U39: Retail | W39: 6 | X39: 6 | Z39: inside | AD39: 35000 | AE39: =IFERROR(AD39/G39,0) -> 28.067362 | AF39: {=INDEX('[1]Mar-24'!N:N,MATCH(CONCATENATE('4. Live Offers'!B39,"",'4. Live Offers'!E39),CONCATENATE('[1]Mar-24'!B:B,"",'[1]Mar-24'!C:C),0))} -> 31175 | AG39: =IFERROR((AD39-AF39)/AF39,"-") -> 0.12269447 | AI39: 7 | AJ39: 12 | AK39: 0 | AL39: =(-(AD39/12)*AJ39) -> -35000 | AM39: =IFERROR((-AK39)/(AD39/12),"-") -> 0 | AN39: =IFERROR(AM39+AJ39,"-") -> 12 | AO39: =AL39+AK39 -> -35000 | AP39: =IFERROR(-AO39/G39,"-") -> 28.067362 | AQ39: =IFERROR((IF(X39<W39,((AD39*X39+AO39)/X39),(AD39*W39+AO39)/W39)),"-") -> 29166.667 | AR39: {=INDEX('[1]Mar-24'!S:S,MATCH(CONCATENATE('4. Live Offers'!B39,"",'4. Live Offers'!E39),CONCATENATE('[1]Mar-24'!B:B,"",'[1]Mar-24'!C:C),0))} -> 0.075 | AS39: {=INDEX('[1]Mar-24'!R:R,MATCH(CONCATENATE('4. Live Offers'!B39,"",'4. Live Offers'!E39),CONCATENATE('[1]Mar-24'!B:B,"",'[1]Mar-24'!C:C),0))} -> 340183.73 | AT39: =IFERROR((1+AR39)^-(AI39/12)*(1/AR39),"-") -> 12.782539 | AU39: =IFERROR(AQ39*AT39,"-") -> 372824.06 | AV39: =IFERROR(((AT39*AQ39)-AS39)/AS39,"-") -> 0.095949112
