Workbook

Sheet Survey responses Data extension
A1: id | B1: Feedback | C1: Happy to be contacted | D1: Preferred contact details | E1: Email | F1: Survey sent time | G1: Like best about home | H1: Home Storage | I1: Furnishing Quality | J1: Design and layout comments | K1: Recommend living in a Grainger home | L1: One thing we could do to improve | M1: Month 3 Recommend Score comments | N1: Recommend Grainger home | O1: M3 Contact consent | P1: One thing to improve
A2: 335121209 | C2: Yes | E2: ornela.doku@gmail.com | F2: 1/1/2023 3:03:50 AM | H2: Just enough | I2: It‚Äôs pretty good
A3: 336557361 | C3: Yes | E3: guy.lewis4@btinternet.com | F3: 1/1/2023 3:05:34 AM | G3: It's ideal for my needs. | H3: Just enough | I3: It‚Äôs ok | J3: Nothing really, the layouts fine.
A4: 434491725 | C4: No | E4: roberttaryn@gmail.com | F4: 1/1/2024 3:01:25 AM | G4: Well maintained, resident services team is very helpful | I4: It‚Äôs ok | J4: Apartment is very well located, resident services team are friendly and responsive, many amenities and services making it a very convenient place to live. | K4: 10 | L4: Nothing to note
A5: 266770073 | C5: Yes | E5: okezieemekaik@gmail.com | F5: 1/1/2024 3:03:10 AM | G5: Cost effective | I5: The quality is high | J5: This is because I always get quick responses to my requests | K5: 1 | L5: Avoid mould in the windows
A6: 438157905 | C6: No | E6: vsena2019@outlook.com | F6: 1/1/2024 3:03:10 AM | G6: Very good materials, the position and the fact it has the key furniture (such as a sofa, table and appliances). | I6: It‚Äôs pretty good | J6: The flat is pristine and of high quality. No problem at all with plumbing and appliances. The reception team is very nice and proactive and it is a pleasure to deal with them. | K6: 10 | L6: Upload the appliances' manuals to the app.
A7: 444268080 | C7: Yes | E7: saoud.ali2@gmail.com | F7: 1/1/2024 3:03:11 AM | G7: Staff members | I7: It‚Äôs pretty good | J7: 9 out of 10 _x000D_ Great staff members | K7: 9 | L7: Maybe _x000D_ Swimming Pool in the building
A8: 447957566 | C8: Yes | E8: gurshinsidhu2609@gmail.com | F8: 1/10/2024 3:01:12 AM | G8: Focus on resident well-being, welcoming and inclusive environment, sense of community, location and convenience | I8: It‚Äôs ok | J8: Grainger is known for their commitment to resident well-being, offering a variety of programs and services to support physical, mental, and emotional health. | K8: 10 | L8: Everything is wonderful.
A9: 412558798 | C9: No | E9: jennyellen@live.co.uk | F9: 1/10/2024 3:01:12 AM | G9: Design of the apartment, spaciousness | I9: It‚Äôs pretty good | J9: Very happy here | K9: 10 | L9: N/A
A10: 449016273 | C10: No | E10: krishnajap@gmail.com | F10: 1/10/2024 3:01:12 AM | G10: Interiors are pleasing to the eye, all appliances are top notch and the bed has been changed before i arrived | I10: It‚Äôs pretty good | J10: Im pretty happy about the team, they very helpful and take initiatives to make all of us comfortable | K10: 7 | L10: Bedroom bed is not proportionate to the small room
A11: 447735429 | C11: Yes | E11: marcsantm98@gmail.com | F11: 1/10/2024 3:01:12 AM | G11: it‚Äôs located in a nice area, very quiet, home itself is spacious and cozy | I11: The quality is high | J11: The entire process from viewing the place, contacting them, moving in was so smooth and stress free | K11: 10 | L11: getting notifications when packages get delivered
A12: 440945794 | C12: Yes | E12: katiehargadon@outlook.com | F12: 1/10/2024 3:02:15 AM | G12: Good quality furniture and finishes, lovely staff team | I12: It‚Äôs pretty good | J12: Good living environment and decent price for location | K12: 10 | L12: Car parking! Having to pay for ncp whilst on wait
A13: 323014711 | C13: Yes | E13: harrynettleton1@gmail.com | F13: 1/11/2023 3:05:32 AM | G13: The bathroom | H13: Just enough | I13: It‚Äôs not great | J13: Kitchen units shouldn‚Äôt be white, higher quality carpets for sure. Sofa is a little small.
A14: 341526721 | C14: Yes | E14: damla.koyuncu.dk@gmail.com | F14: 1/11/2023 3:05:32 AM | H14: The perfect amount | I14: It‚Äôs ok | J14: Bedside lamp, providing basic kitchen appliances (kettle/microwave).
A15: 336558003 | C15: Yes | E15: jessica-lawton@hotmail.co.uk | F15: 1/11/2023 3:05:32 AM | G15: Spacious bedroom_x000D_ Balcony _x000D_ Modern and neutral decor _x000D_ Extras in the building e.g. sky lounge, gym, parcel room etc. | H15: Would like more | I15: It‚Äôs pretty good | J15: Just the storage could be better
A16: 264201920 | C16: Yes | E16: alandcoleman@aol.com | F16: 1/11/2023 3:05:32 AM | G16: Easy access to town | H16: Would like more | J16: The meters for electricity readings should be moved so that we can actually take a reading without having to demolish a wall to read it
A17: 334293048 | C17: Yes | E17: alexpurvis95@gmail.com | F17: 1/11/2024 3:02:11 AM | G17: Proximity to centre | H17: Would like more | I17: It‚Äôs pretty good | J17: Good flat, simple layout, appliances work, staff are friendly and helpful, location is good | K17: 10 | L17: Clear out the water from the UG carpark
A18: 442959822 | C18: Yes | E18: neilkkw@hotmail.com | F18: 1/11/2024 3:02:11 AM | G18: location is very well. near the station! | I18: It‚Äôs pretty good | J18: all respond are very quick | K18: 10 | L18: indicator and garbage collection
A19: 442960033 | C19: Yes | E19: kikipinga@msn.com | F19: 1/11/2024 3:02:11 AM | G19: I like the monthly or special session events such as breakfast morning, christmas party, halloween competition. These events give me a great opportunity to knowing our neighbours and built up my sense of belonging. | I19: It‚Äôs pretty good | J19: The Grainger Team consistently provides prompt responses to all my inquiries. Even if they can't immediately resolve my issues, they promptly inform me of when they can be fixed. | K19: 8 | L19: a free and regular window cleaning service
A20: 434278401 | C20: No | E20: kachun1220@gmail.com | F20: 1/11/2024 3:02:11 AM | G20: Near more shop and market | I20: It‚Äôs pretty good | K20: 8
A21: 442010571 | C21: Yes | E21: letsgochingu@gmail.com | F21: 1/11/2024 3:02:11 AM | G21: good service | I21: It‚Äôs pretty good | J21: the building is quite nice | K21: 8 | L21: helping residents to set up utility bills
A22: 439636585 | C22: No | E22: hardikagrawal18@gmail.com | F22: 1/11/2024 3:02:11 AM | G22: Management is quite professional and helpful. | I22: It‚Äôs pretty good | J22: Due to a couple of negatives like thin walls and bin room being outside and a little messy | K22: 8 | L22: Walls are too thin, so less noise other rooms help
A23: 343712490 | C23: Yes | E23: angsumanbhanjdeo@gmail.com | F23: 1/12/2023 3:03:35 AM | G23: I have been impressed with the decor, planning and maintenance. The attention to detail in the design and layout of the space is evident and adds to the overall aesthetic appeal. The spaces are well-maintained and clean, with everything in order. | H23: Would like more | I23: The quality is high | J23: Storage Space - The wardrobe space can be increased, current space doesn't suffice. There is space opposite to the current wardrobe which can be easily utilised to add some additional space for storage of clothes
A24: 264932505 | C24: Yes | E24: soumya.jena.nayak@gmail.com | F24: 1/12/2023 3:03:35 AM | G24: The Flat was spacious and apartment safety rules were good. All the staffs very friendly and supportive and ready to answer all the queries. | H24: The perfect amount | I24: It‚Äôs pretty good | J24: Yes they can work on the lighting part as it was not enough for study and work purpose.
A25: 340652457 | C25: No | E25: aimable.mardel@gmail.com | F25: 1/12/2023 3:05:41 AM | G25: High ceilings, lots of natural light and a modern finish. | H25: Would like more | I25: It‚Äôs pretty good | J25: Better usage of space. For example, the beds could have storage in them and the sofas could be sofa beds.
A26: 436448244 | C26: Yes | E26: churu.takudzwa.peter@icloud.com | F26: 1/12/2024 3:02:02 AM | G26: The free gym membership and Conceirge team are always helpful | I26: It‚Äôs ok | J26: I scored an 8 as there is not too much negative things to say. I haven‚Äôt had many issues and the few ones I had were managed quickly | K26: 8 | L26: I think L shaped sofas would be a better option
A27: 447036611 | C27: Yes | E27: abhilasha_kakkar@hotmail.co.uk | F27: 1/12/2024 3:02:02 AM | G27: The spacious-ness of the flat; the events and freebies offered; the reception team are always very friendly and courteous to requests/issues | I27: It‚Äôs ok | J27: Although most of the experience has been good, the flat had obvious signs of wear and tear and felt 'lived in' when I moved in, despite it being professionally cleaned by Grainger beforehand. Also, the parking spaces are far too limited! | K27: 8 | L27: quicker/better maintenance & more parking.
A28: 340877429 | C28: No | E28: rawan.t@windowslive.com | F28: 1/13/2023 3:05:31 AM | G28: The lounge area is amazing_x000D_ I wish though it can be booked not the kitchen alone | H28: Would like more | I28: It‚Äôs pretty good
A29: 263523402 | C29: Yes | E29: v.marike@gmail.com | F29: 1/13/2023 3:05:31 AM | G29: Rental agreement and renewal_x000D_ Central App to log repairs_x000D_ Open plan space in living areas | H29: Just enough | J29: Have separate washing/dryer machine. The combined one reduces capacity and results in a very useless dryer.
A30: 443850810 | C30: Yes | E30: yeungderek@hotmail.com | F30: 1/14/2024 3:01:00 AM | G30: The onsite staff are attentive and a joy to see/speak to every day. | I30: It‚Äôs ok | J30: Purely driven by the helpfulness of staff along with the modern look and feel of the apartments. | K30: 10 | L30: Self service parcel collection
A31: 447734744 | C31: No | E31: ummul_ashraf96@ymail.com | F31: 1/14/2024 3:03:12 AM | G31: The security, communal area and friendly staff | I31: The quality is high | J31: Very comfortable, approachable staff and excellent location. | K31: 10 | L31: Efficient delivery of parcels
A32: 447036361 | C32: Yes | E32: lyslys52013@gmail.com | F32: 1/14/2024 3:03:12 AM | G32: I really like the river view, and the facilities are excellent. I also enjoy the gym. | I32: It‚Äôs ok | K32: 8 | L32: Please open both elevators for use.
A33: 210057862 | C33: Yes | E33: vidubov@yahoo.com | F33: 1/15/2023 3:04:44 AM | G33: Fed up with construction works for the last 1,5 years. Its not acceptable, very noisy and we don‚Äôt know when it will stop. Communal area should be finished by Christmas but still not done. | H33: Would like more | I33: It‚Äôs ok | J33: Would need a new boiler as I've got old one and it needs to be re-set almost daily.
A34: 447271698 | C34: Yes | E34: shinice_98@hotmail.com | F34: 1/16/2024 3:02:02 AM | G34: Great staff | I34: It‚Äôs pretty good | J34: Great property management | K34: 10 | L34: More community events
A35: 440511048 | C35: No | E35: danielconn15@gmail.com | F35: 1/16/2024 3:02:03 AM | G35: Lovely and spacious + balcony | I35: The quality is high | J35: nothing really - still early days. | K35: 8 | L35: better contractors for emergency situations
A36: 452198630 | C36: Yes | E36: mehrnoosh.tavassoli@gmail.com | F36: 1/16/2024 3:02:03 AM | G36: Its perfect management and my unique window view | I36: It‚Äôs pretty good | J36: Due to I believe your building is the best one in this level all around Derby. | K36: 10 | L36: Fixing anything in the house that needs.
A37: 340657894 | C37: Yes | E37: bhekithembafortune@yahoo.com | F37: 1/17/2023 3:05:34 AM | G37: The Team on-site! | H37: Would like more | I37: It‚Äôs ok | J37: Nothing
A38: 450107440 | C38: Yes | E38: ningzhi.wang97@gmail.com | F38: 1/17/2024 3:01:39 AM | G38: Staff are welcoming and helpful._x000D_ Common space is well decorated and maintained. | I38: It‚Äôs not great | J38: The overall experience is good and common space is great for parties. | K38: 9 | L38: Try to get the elevator fixed faster.
A39: 345693207 | C39: Yes | E39: gamalkuw20@icloud.com | F39: 1/18/2023 3:05:37 AM | H39: The perfect amount | I39: It‚Äôs ok
A40: 210064790 | C40: Yes | E40: drewcon45@gmail.com | F40: 1/18/2023 3:05:37 AM | G40: I‚Äôve been here a while and it‚Äôs cool. The location is excellent as are the buildings in general and the facilities. The RST are first class and it‚Äôs a real hassle free living experience. | H40: Would like more | I40: It‚Äôs ok | J40: Maybe more durable flooring but that‚Äôs just a nice to have. The building is as advertised and the fixtures and fitting quality on the whole are pretty solid.
...

Sheet Touchpoint - Full Response - 3 
A1: Contact ID 18 Digit | B1: 18 digit OPP ID | C1: First Name | D1: Last Name | E1: Title | F1: Tenancy End Date | G1: Tenancy Start Date | H1: Role | I1: Email | J1: Phone | K1: Unit Address _Subject_ | L1: Active | M1: Tenancy Type | N1: Primary Offer Estate | O1: Move-In Date | P1: Agreed Unit | Q1: Property Type | R1: Unit Status | S1: Fund | T1: Estate | U1: Portfolio | V1: Unit Manager: Full Name | W1: Property Manager: Full Name | X1: Asset Manager: Full Name | Y1: Property Manager Assistant: Full Name | Z1: Future Vacant Date | AA1: Building Name | AB1: Plot No | AC1: Opportunity Name | AD1: id | AE1: Feedback | AF1: Happy to be contacted | AG1: Preferred contact details | AH1: Like best about home | AI1: Home Storage | AJ1: Furnishing Quality | AK1: Design and layout comments | AL1: Survey sent time | AM1: Month 3 Recommend Score comments | AN1: Recommend living in a Grainger home | AO1: One thing we could do to improve | AP1: M3 Contact consent | AR1: Count id
A2: 003Nz00000JSncNIAT | B2: 006Nz00000FAHDRIA5 | C2: Wing Shiu | D2: Lo | F2: 45901 | G2: 45537 | H2: Tenant | I2: chlws01@alumni.ust.hk | J2: 07901619214 | K2: FLAT 127, Gatehouse Apartments,86 East Street, Southampton, SO14 3HP | L2: TRUE | M2: New | O2: 45537 | P2: <a href="a1G4J0000025xJE" target="_blank">127 Gatehouse Apts, 86 East St, Southampton</a> | Q2: Apartment | R2: Tenanted | T2: Gatehouse Apartments | U2: BTR-London & SE | V2: Alice Shaw | X2: Harriet Shaw | Y2: Hayley Fry | Z2: 45915 | AA2: Gatehouse Apts, 86 East St, Southampton | AB2: 25 Gatehouse Apts, 86 East St, Southampton | AC2: GREP-CoA Hoi Yan Yu & Wing Shiu Lo - 127 Gatehouse Apts, 86 East St, Southampton | AD2: 540162006 | AH2: Great | AJ2: It‚Äôs pretty good | AL2: 45627.126 | AM2: Nice staff, prompt response on service enquiry | AN2: 10 | AO2: Lift service maintenance | AR2: =COUNTIF(AD:AD,AD2) -> 1
A3: 003Nz00000JLDycIAH | B3: 006Nz00000FAHDRIA5 | C3: Hoi Yan | D3: Yu | F3: 45901 | G3: 45537 | H3: Lead Tenant | I3: junelowbb825@gmail.com | J3: 07901619214 | K3: FLAT 127, Gatehouse Apartments,86 East Street, Southampton, SO14 3HP | L3: TRUE | M3: New | O3: 45537 | P3: <a href="a1G4J0000025xJE" target="_blank">127 Gatehouse Apts, 86 East St, Southampton</a> | Q3: Apartment | R3: Tenanted | T3: Gatehouse Apartments | U3: BTR-London & SE | V3: Alice Shaw | X3: Harriet Shaw | Y3: Hayley Fry | Z3: 45915 | AA3: Gatehouse Apts, 86 East St, Southampton | AB3: 25 Gatehouse Apts, 86 East St, Southampton | AC3: GREP-CoA Hoi Yan Yu & Wing Shiu Lo - 127 Gatehouse Apts, 86 East St, Southampton | AD3: 539721296 | AH3: The view is excellent. I enjoy the sea view._x000D_ The service team is also great with helpful and friendly staff. | AJ3: It‚Äôs pretty good | AL3: 45627.126 | AM3: great service team, no extra pet charges | AN3: 10 | AO3: lift maintenance service | AR3: =COUNTIF(AD:AD,AD3) -> 1
A4: 003Nz00000JKmAQIA1 | B4: 006Nz00000F6dJ1IAJ | C4: Renato Jose | D4: Valerio | F4: 45905 | G4: 45541 | H4: Tenant | I4: renato3.1projectos@gmail.com | J4: 07902578105 | K4: Apartment 89 Kings Dock Mill,32 Tabley Street, Liverpool, L1 8DX | L4: TRUE | M4: New | O4: 45541 | P4: <a href="a1G4J0000025yHK" target="_blank">Apt 89, Kings Dock Mill, Liverpool, L1</a> | Q4: Apartment | R4: Tenanted | T4: Kings Dock Mill | U4: PRS-Regions | V4: Luke Pollard | X4: Vicki Turnbull | Y4: Matthew Grayton | Z4: 45534 | AA4: Kings Dock Mill, Liverpool, L1 | AB4: Apt 89, Kings Dock Mill, Liverpool, L1 | AC4: GREP-CoA Debora Marques Ferreira Cunha, Renato Jose Valerio - Apt 89, Kings Dock Mill, Liverpool, L1 | AD4: 539720258 | AH4: Location | AJ4: It‚Äôs ok | AL4: 45631.126 | AM4: Na | AN4: 9 | AO4: Na | AR4: =COUNTIF(AD:AD,AD4) -> 1
A5: 003Nz00000IF65zIAD | B5: 006Nz00000EOc0yIAD | C5: Alghalia | D5: Marafie | F5: 45901 | G5: 45537 | H5: Lead Tenant | I5: ghaliamarafie@gmail.com | J5: 0096566604978 | K5: Apartment 108, Millwrights Place,Temple Back, Bristol, BS1 6ZS | L5: TRUE | M5: New | O5: 45537 | P5: <a href="a1GNz0000019Hx7" target="_blank">108 Millwrights Place, Temple Back, Bristol</a> | Q5: Apartment | R5: Tenanted | T5: Millwrights Place | U5: BTR-Regions | X5: Sarah Norstrom | Z5: 45901 | AA5: Millwrights Place - Apartments | AB5: 108 Millwrights Place, Temple Back, Bristol | AC5: GREP-CoA Alghalia Marafie, Amal Hani & Salem Marafie - 108 Millwrights Place, Temple Back, Bristol | AD5: 535380882 | AH5: Nice and safe | AJ5: The quality is high | AL5: 45627.126 | AM5: It‚Äôs a really nice apartment, I like the staff too | AN5: 10 | AO5: Fixing the back elevator | AR5: =COUNTIF(AD:AD,AD5) -> 1
A6: 003Nz00000ICcNJIA1 | B6: 006Nz00000DejtVIAR | C6: Chido | D6: shahwe | F6: 45874 | G6: 45510 | H6: Tenant | I6: chido8shahwe@gmail.com | J6: 07736592694 | K6: Apartment 56, Gilders Yard,14 Great Hampton Street, Birmingham, B18 6ER | L6: TRUE | M6: New | O6: 45510 | P6: <a href="a1G8d0000004c7l" target="_blank">56, Gilders Yard, 14 Great Hampton St, Birm</a> | Q6: Apartment | R6: Tenanted | T6: Gilders Yard | U6: BTR-Regions | V6: Lewis Morris | X6: Vicki Turnbull | Y6: Neil Persad | Z6: 45874 | AA6: Gilders Yard - Apartments A-C | AB6: 56, Gilders Yard, 14 Great Hampton St, Birm | AC6: GREP-CoA Susannah Mbenga & Chido Shahwe - 56, Gilders Yard, 14 Great Hampton St, Birm | AD6: 535163160 | AH6: Clean space | AJ6: It‚Äôs not great | AL6: 45600.126 | AR6: =COUNTIF(AD:AD,AD6) -> 1
A7: 003Nz00000H9fQLIAZ | B7: 006Nz00000D4TK7IAN | C7: Ramaswamy Swaminatha | D7: Manikandan | F7: 45847 | G7: 45483 | H7: Tenant | I7: rsmanikandan@yahoo.com | J7: 07536524526 | K7: 7,Highfield Avenue, Newbury, RG14 5DS | L7: TRUE | M7: New | O7: 45483 | P7: <a href="a1G8d000002OmUX" target="_blank">7 Highfield Avenue, Newbury</a> | Q7: House | R7: Tenanted | T7: Weavers Yard | U7: BTR-London & SE | V7: Kimberley Pope | X7: Harriet Shaw | Y7: Daniel Hind | Z7: 45847 | AA7: 7 Highfield Avenue | AB7: 7 Highfield Avenue, Newbury | AC7: GREP-CoA Anithadevi Manikandan & Ramaswamy Swaminatha Manikandan - 7 Highfield Avenue, Newbury | AD7: 531158779 | AH7: Teams availability and friendly support | AJ7: It‚Äôs pretty good | AL7: 45573.084 | AR7: =COUNTIF(AD:AD,AD7) -> 1
A8: 003Nz00000GYWAjIAP | B8: 006Nz00000DBAarIAH | C8: Keri | D8: Castillo | F8: 45884 | G8: 45520 | H8: Lead Tenant | I8: kerilouisee@hotmail.co.uk | J8: 07763920820 | K8: 30,Houghton Avenue, Hampshire, PO7 3AA | L8: TRUE | M8: New | O8: 45520 | P8: <a href="a1G4J0000025xkt" target="_blank">30 Houghton Avenue, Waterlooville, PO7 3AA</a> | Q8: House | R8: Tenanted | T8: Berewood PRS | U8: BTR-London & SE | V8: Megan Fleming | X8: Harriet Shaw | Y8: Megan Fleming | Z8: 45511 | AA8: 30 Houghton Avenue, Waterlooville, PO7 3AA | AB8: 30 Houghton Avenue, Waterlooville, PO7 3AA | AC8: GREP-CoA Keri Castillo - 30 Houghton Avenue, Waterlooville, PO7 3AA | AD8: 528400757 | AH8: I like the natural, clean look of the property | AL8: 45610.126 | AM8: garden sizes are small | AN8: 7 | AO8: Check the sizes of the bathrooms - too big | AR8: =COUNTIF(AD:AD,AD8) -> 1
A9: 003Nz00000G5WPRIA3 | B9: 006Nz00000Cp0wmIAB | C9: Sandra Jayne | D9: Trippier | F9: 47292 | G9: 45467 | H9: Lead Tenant | I9: sandrajt47@hotmail.com | J9: 07543795144 | K9: 106,Plant Farm Crescent, Winchester, PO7 3DB | L9: TRUE | M9: New | O9: 45467 | P9: <a href="a1G4J000004PtLo" target="_blank">106 Plant Farm Cres, Waterlooville, PO7 3DB</a> | R9: Tenanted | T9: GT - Berewood | U9: Grainger Trust | V9: Shelby Overington | X9: Georgia Kirby-Watt | AA9: 98-108 Plant Farm Cres, Waterlooville, PO73DB | AB9: 106 Plant Farm Cres, Waterlooville, PO7 3DB | AC9: GREP-CoA Sandra Jayne Trippier - 106 Plant Farm Cres, Waterlooville, PO7 3DB | AD9: 526572176 | AH9: It is very clean inside and nicely decorated | AJ9: It‚Äôs pretty good | AL9: 45557.085 | AR9: =COUNTIF(AD:AD,AD9) -> 1
A10: 003Nz00000FZb49IAD | B10: 006Nz00000C5sDpIAJ | C10: Riya | D10: Rajan Shayla | F10: 45870 | G10: 45506 | H10: Tenant | I10: riyarajanshalya@gmail.com | J10: 07401084330 | K10: Apartment 506 Torrens Apartments,Waterman Walk, Salford, M50 3AS | L10: TRUE | M10: New | O10: 45506 | P10: <a href="a1G4J0000025z4I" target="_blank">506 Torrens Apt, Waterman Wlk, Salford M50</a> | Q10: Apartment | R10: Tenanted | T10: Clippers Quay | U10: BTR-Regions | V10: Helen Bowers | X10: Vicki Turnbull | Y10: Helen Bowers | Z10: 45870 | AA10: Clippers - Torrens Apartments | AB10: 506 Torrens Apt, Waterman Wlk, Salford M50 | AC10: GREP-CoA Fernanda Breame and Riya Rajan Shayla - 506 Torrens Apt, Waterman Wlk, Salford M50 | AD10: 524649833 | AH10: The view from my window | AJ10: It‚Äôs ok | AL10: 45596.126 | AR10: =COUNTIF(AD:AD,AD10) -> 1
A11: 003Nz00000FG1PJIA1 | B11: 006Nz00000CDIJZIA5 | C11: William | D11: Teoh | F11: 45863 | G11: 45499 | H11: Lead Tenant | I11: williamtzs@gmail.com | J11: 07594136149 | K11: 108 Assay Apartments,Station View, Guildford, GU1 4BQ | L11: TRUE | M11: New | O11: 45499 | P11: <a href="a1G8d000002Q2Z7" target="_blank">108 Assay Apartments, Station View, Guildford</a> | Q11: Apartment | R11: Tenanted | T11: The Mint | U11: BTR-London & SE | V11: Kimberley Pope | X11: Harriet Shaw | Z11: 45498 | AA11: The Mint - Assay Apartments. | AB11: 108 Assay Apartments, Station View, Guildford | AC11: GREP-CoA William Teoh and Heather Fitzpatrick - 108 Assay Apartments, Station View, Guildford | AD11: 523138734 | AH11: A mordern design, all facilities like washing machine, dishwasher, bathroom and cooker are provided in working and clean condition & overall very comfortable layout. The reception team are very friendly and helpful with things as well. | AJ11: It‚Äôs ok | AL11: 45589.084 | AR11: =COUNTIF(AD:AD,AD11) -> 1
A12: 003Nz00000ER1PnIAL | B12: 006Nz00000BaNB4IAN | C12: Angela | D12: Robinson | F12: 45856 | G12: 45492 | H12: Lead Tenant | I12: angelarobinson63@yahoo.com | J12: 07368228039 | K12: Apartment 24,15 St. Johns Gardens, Bury, BL9 0QW | L12: TRUE | M12: New | O12: 45492 | P12: <a href="a1G4J0000025xsh" target="_blank">24, 15 St. Johns Gardens, Bury, BL9</a> | Q12: Apartment | R12: Tenanted | T12: The Rock | U12: PRS-Regions | V12: David Hancock | X12: Vicki Turnbull | Y12: Lorraine Cree | Z12: 45813 | AA12: St. Johns Gardens, 5, Bury, Lancs, BL9 | AB12: 46, 5 St. Johns Gardens, Bury, BL9 | AC12: GREP-CoA Angela Robinson - 24, 15 St. Johns Gardens, Bury, BL9 | AD12: 519742842 | AH12: I love the size and layout. It‚Äôs perfect for me and my son. | AL12: 45582.084 | AR12: =COUNTIF(AD:AD,AD12) -> 1
A13: 003Nz00000EMW63IAH | B13: 006Nz00000BWsLZIA1 | C13: Sean | D13: Pillay | F13: 45818 | G13: 45454 | H13: Lead Tenant | I13: sean.pillay88@gmail.com | J13: 7426868860 | K13: 201 Brook Place,10 Summerfield Street, Sheffield, S11 8BR | L13: TRUE | M13: New | O13: 45454 | P13: <a href="a1G4J0000025zIZ" target="_blank">201, Brook Place Apts, Sheffield, S11 8BR</a> | Q13: Apartment | R13: Tenanted | T13: Brook Place | U13: BTR-Regions | V13: Emma Cramer-Mitchell | X13: Vicki Turnbull | Y13: Leanne Hargreaves | Z13: 46212 | AA13: Brook Place Apts, 10 Summerfield Street, Shef | AB13: 430, Brook Place Apts, Sheffield, S11 8BS | AC13: GREP-CoA Sean Pillay, Dominika Matuszkiewicz - 201, Brook Place Apts, Sheffield, S11 8BR | AD13: 519499748 | AF13: Yes | AH13: It is very quiet and the space is very peaceful - plus comes with a gym! Can't even start to elaborate how practical that is. | AJ13: The quality is high | AK13: My experience has been really wonderful and the reception team is so nice and gets all our problems sorted promptly. Haven't lived in such a nice place before. | AL13: 45544.085 | AR13: =COUNTIF(AD:AD,AD13) -> 1
A14: 003Nz00000EknwyIAB | B14: 006Nz00000BpLNfIAN | C14: Peter | D14: Little | F14: 45870 | G14: 45506 | H14: Lead Tenant | I14: peterjameslittle41@hotmail.com | J14: 07594444586 | K14: Apartment 209 The Condor,1 Springwell Square, Derby, DE1 1FB | L14: TRUE | M14: New | O14: 45506 | P14: <a href="a1G8d000002QBYq" target="_blank">209 The Condor, 1 Springwell Sq</a> | Q14: Apartment | R14: Tenanted | T14: The Condor | U14: BTR-Regions | V14: Jessica Coates | X14: Vicki Turnbull | Y14: Leanne Hargreaves | Z14: 45870 | AA14: The Condor - Apartments | AB14: 209 The Condor, 1 Springwell Sq | AC14: GREP-CoA Peter Little - 209 The Condor, 1 Springwell Sq | AD14: 521196636 | AH14: I like the fact that the property is so central to Derby shops etc. | AJ14: It‚Äôs pretty good | AL14: 45596.126 | AR14: =COUNTIF(AD:AD,AD14) -> 1
A15: 003Nz00000EJKXdIAP | B15: 006Nz00000BUahIIAT | C15: Caleb | D15: Ogwu | F15: 45850 | G15: 45486 | H15: Lead Tenant | I15: calebogwu7@gmail.com | J15: 07482363828 | K15: Flat 707, Pin Yard,11 Sweet Street, Leeds, LS11 9FB | L15: TRUE | M15: New | O15: 45486 | P15: <a href="a1G8d0000004Xcn" target="_blank">707 Pin Yard, 11 Sweet Street, Leeds</a> | Q15: Apartment | R15: On the Market Available to View | T15: The Headline | U15: BTR-Regions | V15: George Diamantopoulos | X15: Vicki Turnbull | Y15: Leanne Hargreaves | Z15: 45666 | AA15: The Headline Apts, Wellington Park Way, Leeds | AB15: 104, The Headline, Wellington Park Way, Leeds | AC15: GREP-CoA Mr Caleb Ogwu & Miss Anuoluwapo Ikotun - 707 Pin Yard, 11 Sweet Street, Leeds | AD15: 519273414 | AJ15: It‚Äôs pretty good | AL15: 45576.084 | AR15: =COUNTIF(AD:AD,AD15) -> 1
A16: 003Nz00000E38LxIAJ | B16: 006Nz00000BJg6rIAD | C16: Erik Youngtaek | D16: Yu | F16: 45817 | G16: 45453 | H16: Lead Tenant | I16: youngtaek.yu@hotmail.co.uk | J16: 07450208063 | K16: Flat 33, Nautilus Apartments,2 Norah Smyth Road, London, E16 1FE | L16: TRUE | M16: New | O16: 45453 | P16: <a href="a1G8d000002QBMz" target="_blank">33 Nautilus Apts, 2 Norah Smyth Rd, London</a> | Q16: Apartment | R16: Tenanted | T16: Nautilus Apartments | U16: BTR-London & SE | V16: Fatma Azakli | X16: Harriet Shaw | Y16: Fatma Azakli | Z16: 45813 | AA16: Nautilus - Apartments | AB16: 122 Nautilus Apts, 1 Jam Lane, London | AC16: GREP-CoA Erik Youngtaek Yu & Jarim Koo - 33 Nautilus Apts, 2 Norah Smyth Rd, London | AD16: 518048632 | AL16: 45543.084 | AR16: =COUNTIF(AD:AD,AD16) -> 1
A17: 003Nz00000E35mHIAR | B17: 006Nz00000BJcEXIA1 | C17: Valentina | D17: Rumyantseva | F17: 45864 | G17: 45500 | H17: Lead Tenant | I17: vale.obsgyn@gmail.com | J17: 07774085392 | K17: Apartment 617, The Barnum,23 Queens Road, Nottingham, NG2 3FP | L17: TRUE | M17: New | O17: 45500 | P17: <a href="a1GNz00000016GI" target="_blank">617 The Barnum, 23 Queens Road, Nottingham</a> | Q17: Apartment | R17: Tenanted | T17: The Barnum | U17: BTR-Regions | V17: Natasha Burns | X17: Vicki Turnbull | Y17: Leanne Hargreaves | Z17: 45822 | AA17: The Barnum - Apartments | AB17: 631 The Barnum, 23 Queens Road, Nottingham | AC17: GREP-CoA Valentina Rumyantseva - 617 The Barnum, 23 Queens Road, Nottingham | AD17: 518048414 | AH17: Super comfy, the best place I ever lived | AJ17: The quality is high | AL17: 45590.084 | AR17: =COUNTIF(AD:AD,AD17) -> 1
A18: 003Nz00000E1RB0IAN | B18: 006Nz00000BM0mDIAT | C18: Desiree | D18: Brito | F18: 45838 | G18: 45474 | H18: Tenant | I18: estaesjkde@gmail.com | J18: 07587693558 | K18: Flat 520, Pin Yard,11 Sweet Street, Leeds, LS11 9FB | L18: TRUE | M18: New | O18: 45474 | P18: <a href="a1G8d0000004Xit" target="_blank">520 Pin Yard, 11 Sweet Street, Leeds</a> | Q18: Apartment | R18: Tenanted | T18: Pin Yard | U18: BTR-Regions | V18: Ruth Friend | X18: Vicki Turnbull | Y18: Ruth Friend | Z18: 45838 | AA18: Pin Yard - Apartments | AB18: 520 Pin Yard, 11 Sweet Street, Leeds | AC18: GREP-CoA Omolade Osinaike, Desiree Brito - 520 Pin Yard, 11 Sweet Street, Leeds | AD18: 518043880 | AH18: It‚Äôs a good size for 2 people but kitchen could have more storage space, wish the ceiling lights had the option to choose to turn on or off a certain number of them , not all of them as it is now. The yelowish color of the floors corridors is awful. | AJ18: It‚Äôs pretty good | AL18: 45564.085 | AR18: =COUNTIF(AD:AD,AD18) -> 1
A19: 003Nz00000Dze7WIAR | B19: 006Nz00000Al1SjIAJ | C19: Trina | D19: Persyn | F19: 45805 | G19: 45441 | H19: Tenant | I19: trinapersyn@outlook.com | J19: 07562618895 | K19: Apartment 206, Neon House,207 Chapel Street, Salford, M3 5PF | L19: TRUE | M19: New | O19: 45441 | P19: <a href="a1G4J0000025yF6" target="_blank">206, Neon House, 207 Chapel St, Salford, M3 5</a> | Q19: Apartment | R19: Tenanted | T19: The Filaments | U19: BTR-Regions | V19: Samantha Lancaster | X19: Vicki Turnbull | Y19: Samantha Lancaster | Z19: 45805 | AA19: The Filaments, 207 Chapel St, Salford, M3 5PF | AB19: 206, Neon House, 207 Chapel St, Salford, M3 5 | AC19: GREP-CoA Jaspreet Kaur Ghuman, Chloe Self and Trina Persyn - 206, Neon House, 207 Chapel St, Salford, M3 5 | AD19: 517820092 | AF19: Yes | AH19: The sense of community and amenities | AJ19: The quality is high | AK19: Really enjoy living here | AL19: 45531.084 | AR19: =COUNTIF(AD:AD,AD19) -> 1
A20: 003Nz00000DwS7hIAF | B20: 006Nz00000BEbFvIAL | C20: Alicia | D20: Platts | F20: 45800 | G20: 45436 | H20: Tenant | I20: allie.platts98@gmail.com | J20: 07563089559 | K20: Apartment 615 Torrens Apartments,Waterman Walk, Salford, M50 3AT | L20: TRUE | M20: New | O20: 45436 | P20: <a href="a1G4J0000025zDd" target="_blank">615 Torrens Apt, Waterman Wlk, Salford M50</a> | Q20: Apartment | R20: Tenanted | T20: Clippers Quay | U20: BTR-Regions | V20: Helen Bowers | X20: Vicki Turnbull | Y20: Helen Bowers | Z20: 45800 | AA20: Clippers - Torrens Apartments | AB20: 615 Torrens Apt, Waterman Wlk, Salford M50 | AC20: GREP-CoA Max Goodwin and Alicia Platts - 615 Torrens Apt, Waterman Wlk, Salford M50 | AD20: 517585939 | AF20: Yes | AH20: Everything is such good quality - not only my apartment but also the reception and communal areas, the staff, and the extra offerings. | AJ20: It‚Äôs pretty good | AK20: Everything about our experience living here has been considered, from extra help with moving into how easy it is to submit a maintenance request. | AL20: 45526.085 | AR20: =COUNTIF(AD:AD,AD20) -> 1
A21: 003Nz00000DvxTlIAJ | B21: 006Nz00000BEh24IAD | C21: Samuel | D21: Perry | F21: 45836 | G21: 45472 | H21: Lead Tenant | I21: samperrycoach@gmail.com | J21: 07960306865 | K21: Apartment 506, The Copper Works,5 Capital Quarter,, Cardiff, CF10 4DT | L21: TRUE | M21: New | O21: 45472 | P21: <a href="a1GNz0000000bil" target="_blank">506, 5 Capital Quarter, Tyndall St., Cardiff</a> | Q21: Apartment | R21: Tenanted | T21: The Copper Works | U21: BTR-Regions | V21: Karen Meek | X21: Sarah Norstrom | Z21: 45820 | AA21: The Copper Works - Apartments | AB21: 210, 5 Capital Quarter, Tyndall St., Cardiff | AC21: GREP-CoA Samuel Perry - 506, 5 Capital Quarter, Tyndall St., Cardiff | AD21: 517584226 | AH21: The communal spaces | AJ21: It‚Äôs ok | AL21: 45562.085 | AR21: =COUNTIF(AD:AD,AD21) -> 1
A22: 003Nz00000DIUxuIAH | B22: 006Nz00000Alz2IIAR | C22: Pui Fun | D22: Cheng | F22: 45601 | G22: 45418 | H22: Tenant | I22: pandabb123abc@gmail.com | J22: 07407374811 | K22: Apartment 504 Syren Apartments,Ottinger Close, Salford, M50 3AP | L22: TRUE | M22: New | O22: 45418 | P22: <a href="a1G4J0000025xyC" target="_blank">504 Syren Apt , Ottinger Close, Salford M50</a> | Q22: Apartment | R22: Tenanted | T22: Clippers Quay | U22: BTR-Regions | V22: Helen Bowers | X22: Vicki Turnbull | Y22: Helen Bowers | Z22: 45601 | AA22: Clippers - Syren Apartments | AB22: 504 Syren Apt , Ottinger Close, Salford M50 | AC22: GREP-CoA M Cheng, P F Cheng, P C Cheng & P H Cheng - 504 Syren Apt , Ottinger Close, Salford M50 | AD22: 514679292 | AF22: Yes | AH22: dinning room and gym room | AJ22: The quality is high | AK22: up to now quite good | AL22: 45508.085 | AR22: =COUNTIF(AD:AD,AD22) -> 1
A23: 003Nz00000DgR5yIAF | B23: 006Nz00000B3fDCIAZ | C23: Lai Ming | D23: Kong | F23: 45840 | G23: 45476 | H23: Lead Tenant | I23: klming1026@hotmail.com | J23: 07881122025 | K23: Apartment 806 Ambassador Apartments,Waterman Walk, Salford, M50 3AW | L23: TRUE | M23: New | O23: 45476 | P23: <a href="a1G4J0000025ykt" target="_blank">806 Ambassador Apt, Waterman Wlk, Salford M50</a> | Q23: Apartment | R23: Tenanted | T23: Clippers Quay | U23: BTR-Regions | V23: Helen Bowers | X23: Vicki Turnbull | Y23: Helen Bowers | Z23: 45500 | AA23: Clippers - Ambassador Apartments | AB23: 806 Ambassador Apt, Waterman Wlk, Salford M50 | AC23: GREP-CoA Lai Ming Kong & Yun Lau Tang - 806 Ambassador Apt, Waterman Wlk, Salford M50 | AD23: 516376794 | AH23: Nice environment and Service | AJ23: It‚Äôs ok | AL23: 45566.084 | AR23: =COUNTIF(AD:AD,AD23) -> 1
A24: 003Nz00000Dgh98IAB | B24: 006Nz00000B2Qg1IAF | C24: Grace | D24: Mead | F24: 45806 | G24: 45442 | H24: Lead Tenant | I24: mead.grace@hotmail.com | J24: 07887811322 | K24: 1707, Silver Yard,297 Moor Street Queensway, Birmingham, B4 6GJ | L24: TRUE | M24: New | O24: 45442 | P24: <a href="a1GNz000001HRhZ" target="_blank">1707 The Silver Yard, 100 Moor St Queensway</a> | Q24: Apartment | R24: Tenanted | T24: The Silver Yard | U24: BTR-Regions | X24: Sarah Norstrom | Y24: Emma Billingham | AA24: The Silver Yard - Apartments | AB24: 1707 The Silver Yard, 100 Moor St Queensway | AC24: GREP-CoA Daniel Clark and Grace Mead - 1707 The Silver Yard, 100 Moor St Queensway | AD24: 516378915 | AF24: Yes | AH24: Very clean, modern, staff is very friendly and helpful | AJ24: It‚Äôs pretty good | AK24: Well looked after, facilities are good and staff is great- also feels very secure and safe with security 24/7 and having to fob into everywhere | AL24: 45532.085 | AR24: =COUNTIF(AD:AD,AD24) -> 1
A25: 003Nz00000DFqQFIA1 | B25: 006Nz00000AWd28IAD | C25: Lydia Anne | D25: Tibbet | F25: 45807 | G25: 45444 | H25: Tenant | I25: lydia.tibbet@gmail.com | J25: 07360158053 | K25: Apartment 401, The Copper Works,5 Capital Quarter,, Cardiff, CF10 4DS | L25: TRUE | M25: New | O25: 45444 | P25: <a href="a1GNz0000000cZx" target="_blank">401, 5 Capital Quarter, Tyndall St., Cardiff</a> | Q25: Apartment | R25: Tenanted | T25: The Copper Works | U25: BTR-Regions | V25: Karen Meek | X25: Sarah Norstrom | AA25: The Copper Works - Apartments | AB25: 401, 5 Capital Quarter, Tyndall St., Cardiff | AC25: GREP-CoA Jessica Debono and Lydia Anne Tibbet - 401, 5 Capital Quarter, Tyndall St., Cardiff | AD25: 514457897 | AF25: Yes | AH25: I like the necessities, I like the gym and communal areas specifically. Concierge also great. | AJ25: It‚Äôs ok | AK25: As above ref parking. The fact parking is an extra ¬£150 a month when that mirrors NCP charges is really ridiculous. That has been a real difficulty. Plus 6 months with no outdoor space and furniture when that was promised upon arrival. | AL25: 45534.085 | AR25: =COUNTIF(AD:AD,AD25) -> 1
A26: 003Nz00000DBqNBIA1 | B26: 006Nz00000AikkXIAR | C26: Amy | D26: Clift | F26: 46196 | G26: 45467 | H26: Lead Tenant | I26: amyclift.ac@gmail.com | J26: 07469243953 | K26: Apartment 417, Ingot Place,84 Upper Allen Street, Sheffield, S3 7NY | L26: TRUE | M26: New | O26: 45467 | P26: <a href="a1GNz0000000yH7" target="_blank">417, 84 Upper Allen St, Sheffield</a> | Q26: Apartment | R26: Tenanted | T26: Brook Place | U26: BTR-Regions | V26: Emma Cramer-Mitchell | X26: Vicki Turnbull | Y26: Leanne Hargreaves | Z26: 45808 | AA26: Brook Place Apts, 10 Summerfield Street, Shef | AB26: 218, Brook Place Apts, Sheffield, S11 8BR | AC26: GREP-CoA Amy Clift & Alexander Shaw - 417, 84 Upper Allen St, Sheffield | AD26: 514225006 | AH26: The actual flat | AJ26: It‚Äôs pretty good | AL26: 45557.085 | AR26: =COUNTIF(AD:AD,AD26) -> 1
A27: 003Nz00000DbNPbIAN | B27: 006Nz00000AzhjrIAB | C27: Louise | D27: Henderson | F27: 45793 | G27: 45429 | H27: Lead Tenant | I27: lhjhenderson@gmail.com | J27: 07885685804 | K27: Apartment 915 Torrens Apartments,Waterman Walk, Salford, M50 3AT | L27: TRUE | M27: New | O27: 45429 | P27: <a href="a1G4J0000025ys9" target="_blank">915 Torrens Apt, Waterman Wlk, Salford M50</a> | Q27: Apartment | R27: Tenanted | T27: Clippers Quay | U27: BTR-Regions | V27: Helen Bowers | X27: Vicki Turnbull | Y27: Helen Bowers | Z27: 45793 | AA27: Clippers - Torrens Apartments | AB27: 915 Torrens Apt, Waterman Wlk, Salford M50 | AC27: GREP-CoA Louise Henderson - 915 Torrens Apt, Waterman Wlk, Salford M50 | AD27: 516137169 | AF27: Yes | AH27: The security and friendly staff | AJ27: It‚Äôs pretty good | AK27: Nice safe building and a good location. The building is well cared for the staff are very friendly. Car parking is expensive considering the high rent. And I can‚Äôt get my bath water hot. | AL27: 45519.085 | AR27: =COUNTIF(AD:AD,AD27) -> 1
A28: 003Nz00000DbID6IAN | B28: 006Nz00000Azhs0IAB | C28: Ahmed Mohamed Elmagh | D28: Elgendy | F28: 45838 | G28: 45474 | H28: Lead Tenant | I28: a.elgendy78@gmail.com | J28: 36300123565 | K28: Flat 328 , Enigma Square,414 North Row, Milton Keynes, MK9 2GF | L28: TRUE | M28: New | O28: 45474 | P28: <a href="a1G8d0000005rSf" target="_blank">328 Enigma Square, 414 North Row, MK9 2GF</a> | Q28: Apartment | R28: Tenanted | T28: Solstice Apartments | U28: BTR-Regions | V28: Tina Viragh | X28: Sarah Norstrom | Y28: Kaycee Cooper | Z28: 45535 | AA28: Solstice Apts, 801 Silbury Boulevard, MK9 | AB28: 325, Solstice Apts, Silbury Boulevard | AC28: GREP-CoA Ahmed Elgendy, Hager Amer - 328 Enigma Square, 414 North Row, MK9 2GF | AD28: 516140415 | AH28: Best thing is the amazing team | AL28: 45564.085 | AR28: =COUNTIF(AD:AD,AD28) -> 1
A29: 003Nz00000CX9buIAD | B29: 006Nz00000AIgcXIAT | C29: YIU WAI | D29: FUNG | F29: 45796 | G29: 45432 | H29: Tenant | I29: andyfungjewelry@gmail.com | J29: 07867083456 | K29: Apartment 409 Ambassador Apartments,Waterman Walk, Salford, M50 3AU | L29: TRUE | M29: New | O29: 45432 | P29: <a href="a1G4J0000025yu2" target="_blank">409 Ambassador Apt, Waterman Wlk, Salford M50</a> | Q29: Apartment | R29: Tenanted | T29: Clippers Quay | U29: BTR-Regions | V29: Helen Bowers | X29: Vicki Turnbull | Y29: Helen Bowers | Z29: 45425 | AA29: Clippers - Ambassador Apartments | AB29: 409 Ambassador Apt, Waterman Wlk, Salford M50 | AC29: GREP-CoA Pui Ki Ho & Yiu Wai Fung - 409 Ambassador Apt, Waterman Wlk, Salford M50 | AD29: 511267792 | AF29: Yes | AH29: The resident service team | AJ29: It‚Äôs ok | AK29: Because of great resident service team | AL29: 45522.085 | AR29: =COUNTIF(AD:AD,AD29) -> 1
A30: 003Nz00000CX72DIAT | B30: 006Nz00000AIWQMIA5 | C30: Charlotte | D30: Noerregaard-Ettle | F30: 45777 | G30: 45413 | H30: Lead Tenant | I30: charlotte@wordenskjold.dk | J30: '+44 7974 396908 | K30: Flat 51, Hawkins Lane Building,East Tucker Street, Bristol, BS1 6WQ | L30: TRUE | M30: New | O30: 45413 | P30: <a href="a1G4J0000025yl8" target="_blank">FLAT 51, Hawkins Ln, Finzels Reach, Bristol,</a> | Q30: Apartment | R30: Tenanted | T30: Hawkins & George | U30: BTR-Regions | V30: Sarah Regan | X30: Vicki Turnbull | Y30: Craig Parkinson | Z30: 45777 | AA30: HG-Hawkins Ln, Finzels Reach, Bristol, BS1 | AB30: FLAT 51, Hawkins Ln, Finzels Reach, Bristol, | AC30: GREP-CoA Charlotte & Andrew Noerregaard-Ettle - FLAT 51, Hawkins Ln, Finzels Reach, Bristol, | AD30: 511267593 | AF30: Yes | AH30: Amenities-fitness, rooftop, mail and package service. Support from the reception when needed | AJ30: It‚Äôs ok | AK30: Very noisy apartment- pub on the left side and glass container on the right side. Plus Parking availability. | AL30: 45503.085 | AR30: =COUNTIF(AD:AD,AD30) -> 1
A31: 003Nz00000CuluzIAB | B31: 006Nz00000AVB7uIAH | C31: Koon Hong | D31: Kwok | F31: 45777 | G31: 45413 | H31: Tenant | I31: kukukux3@gmail.com | J31: 07752064317 | K31: Flat 604 , Enigma Square,414 North Row, Milton Keynes, MK9 2FU | L31: TRUE | M31: New | O31: 45413 | P31: <a href="a1G8d0000005rDF" target="_blank">604 Enigma Square, 414 North Row, MK9 2FU</a> | Q31: Apartment | R31: Reserved | T31: Enigma Square | U31: BTR-Regions | V31: Tina Viragh | X31: Sarah Norstrom | Y31: Grace Fiske | Z31: 45841 | AA31: Enigma Square - Apartments | AB31: 320 Enigma Square, 414 North Row, MK9 2GE | AC31: GREP-CoA Suet Ying Chow, Koon Hong Kwok - 604 Enigma Square, 414 North Row, MK9 2FU | AD31: 512999361 | AF31: No | AH31: Good management | AJ31: It‚Äôs pretty good | AK31: location is good and staff is nice. | AL31: 45503.085 | AR31: =COUNTIF(AD:AD,AD31) -> 1
A32: 003Nz00000CUIIRIA5 | B32: 006Nz00000AGSPDIA5 | C32: Matthew | D32: Kizintas | F32: 45817 | G32: 45453 | H32: Tenant | I32: mattkizintas@gmail.com | J32: 07799480709 | K32: Apartment 45, Millwrights Place,Temple Back, Bristol, BS1 6ZS | L32: TRUE | M32: New | O32: 45453 | P32: <a href="a1GNz0000019GzR" target="_blank">45 Millwrights Place, Temple Back, Bristol</a> | Q32: Apartment | R32: Tenanted | T32: Millwrights Place | U32: BTR-Regions | X32: Sarah Norstrom | AA32: Millwrights Place - Apartments | AB32: 45 Millwrights Place, Temple Back, Bristol | AC32: GREP-CoA Carin Madeleine Selenius & Matthew Kizintas - 45 Millwrights Place, Temple Back, Bristol | AD32: 511042214 | AF32: Yes | AH32: The home Is in a good location | AJ32: It‚Äôs ok | AK32: Numerous issues when we moved into the flat with which we did not feel particularly well Supported by the building manager. | AL32: 45543.084 | AR32: =COUNTIF(AD:AD,AD32) -> 1
A33: 003Nz00000CUGYNIA5 | B33: 006Nz00000AGu3hIAD | C33: Leung Lai Ping | D33: Gloria | F33: 45770 | G33: 45406 | H33: Lead Tenant | I33: glorialeung318@gmail.com | J33: 85269398910 | K33: 805 Brook Place,10 Summerfield Street, Sheffield, S11 8DA | L33: TRUE | M33: New | O33: 45406 | P33: <a href="a1G4J0000025zMK" target="_blank">805, Brook Place Apts, Sheffield, S11 8DA</a> | Q33: Apartment | R33: Tenanted | T33: Brook Place | U33: BTR-Regions | V33: Emma Cramer-Mitchell | X33: Vicki Turnbull | Y33: Leanne Hargreaves | Z33: 45770 | AA33: Brook Place Apts, 10 Summerfield Street, Shef | AB33: 805, Brook Place Apts, Sheffield, S11 8DA | AC33: GREP-CoA Leung Lai Ping Gloria - 805, Brook Place Apts, Sheffield, S11 8DA | AD33: 511042358 | AF33: No | AH33: Grainger is great in terms of the apartment itself and staff quality. Property is quite new. And it's located near city centre. Staff is nice and helpful | AJ33: It‚Äôs pretty good | AK33: everything seems perfect but there is always room for improvement | AL33: 45496.085 | AR33: =COUNTIF(AD:AD,AD33) -> 1
A34: 003Nz00000CSZDdIAP | B34: 006Nz00000AFtxiIAD | C34: Abdulmohsen | D34: Alkhanbashi | E34: PHD | F34: 45817 | G34: 45453 | H34: Lead Tenant | I34: amohsen.alkanbashi@gmail.com | J34: 07555971045 | K34: Apartment 67, Millwrights Place,Temple Back, Bristol, BS1 6ZS | L34: TRUE | M34: New | O34: 45453 | P34: <a href="a1GNz0000019HHB" target="_blank">67 Millwrights Place, Temple Back, Bristol</a> | Q34: Apartment | R34: Tenanted | T34: Millwrights Place | U34: BTR-Regions | X34: Sarah Norstrom | Z34: 45817 | AA34: Millwrights Place - Apartments | AB34: 67 Millwrights Place, Temple Back, Bristol | AC34: GREP-CoA Abdulmohsen Alkhanbashi - 67 Millwrights Place, Temple Back, Bristol | AD34: 511035015 | AF34: Yes | AH34: Apartment is spacious, great amenities, brilliant staff, and perfect location. | AJ34: It‚Äôs pretty good | AK34: I love the place. I am already recommending it to people. | AL34: 45543.084 | AR34: =COUNTIF(AD:AD,AD34) -> 1
A35: 003Nz00000CSNyuIAH | B35: 006Nz00000A1zQHIAZ | C35: Delia | D35: Kong | F35: 45817 | G35: 45450 | H35: Tenant | I35: moonlightwave216@gmail.com | J35: 07917957437 | K35: Flat 134, Nautilus Apartments,1 Jam Lane, London, E16 1GT | L35: TRUE | M35: New | O35: 45450 | P35: <a href="a1G8d000002QBMW" target="_blank">134 Nautilus Apts, 1 Jam Lane, London</a> | Q35: Apartment | R35: Tenanted | T35: Argo Apartments | U35: BTR-London & SE | V35: Raihana Parveen | X35: Harriet Shaw | Y35: Holly Boggis | Z35: 45828 | AA35: Argo Apartments | AB35: 76 Argo Apts, 4 Silvertown Way,London,E16 1YD | AC35: GREP-CoA Scott Tham, Delia Kong - 134 Nautilus Apts, 1 Jam Lane, London | AD35: 511034863 | AF35: Yes | AH35: Appreciate the efficient use of space and generally good quality furnitures. | AJ35: It‚Äôs pretty good | AK35: I would recommend the apartment. However, the whole process prior to getting the keys was not smooth, such as inaccurate information shared during the letting process and issues with the contract took weeks to resolve. | AL35: 45540.084 | AR35: =COUNTIF(AD:AD,AD35) -> 1
A36: 003Nz00000CriNPIAZ | B36: 006Nz00000AW4ikIAD | C36: Chloe | D36: Brown | F36: 45779 | G36: 45414 | H36: Lead Tenant | I36: chloebrownuk@outlook.com | J36: 07568386061 | K36: 117 Brook Place,10 Summerfield Street, Sheffield, S11 8BR | L36: TRUE | M36: New | O36: 45414 | P36: <a href="a1G4J0000025zJm" target="_blank">117, Brook Place Apts, Sheffield, S11 8BR</a> | Q36: Apartment | R36: Tenanted | T36: Brook Place | U36: BTR-Regions | V36: Emma Cramer-Mitchell | X36: Vicki Turnbull | Y36: Leanne Hargreaves | Z36: 45778 | AA36: Brook Place Apts, 10 Summerfield Street, Shef | AB36: 117, Brook Place Apts, Sheffield, S11 8BR | AC36: GREP-CoA Chloe Brown - 117, Brook Place Apts, Sheffield, S11 8BR | AD36: 512747822 | AF36: Yes | AH36: It allows pets | AJ36: It‚Äôs not great | AK36: It‚Äôs a little pricey and the parking is limited | AL36: 45504.085 | AR36: =COUNTIF(AD:AD,AD36) -> 1
A37: 003Nz00000CRDjpIAH | B37: 006Nz00000AEYQfIAP | C37: John Steven | D37: Lee | F37: 46558 | G37: 45464 | H37: Lead Tenant | I37: johnstevenlee08@gmail.com | J37: 07360340696 | K37: 508, Silver Yard,100 Moor Street Queensway, Birmingham, B4 6GF | L37: TRUE | M37: New | O37: 45464 | P37: <a href="a1GNz000001HPCj" target="_blank">508 The Silver Yard, 100 Moor St Queensway</a> | Q37: Apartment | R37: Tenanted | T37: The Silver Yard | U37: BTR-Regions | X37: Sarah Norstrom | Y37: Emma Billingham | Z37: 46558 | AA37: The Silver Yard - Apartments | AB37: 508 The Silver Yard, 100 Moor St Queensway | AC37: GREP-CoA John Steven Lee - 508 The Silver Yard, 100 Moor St Queensway | AD37: 510808855 | AH37: location | AJ37: It‚Äôs ok | AL37: 45554.085 | AR37: =COUNTIF(AD:AD,AD37) -> 1
A38: 003Nz00000CrCs9IAF | B38: 006Nz00000AVnOUIA1 | C38: Ruth | D38: Howells | F38: 45596 | G38: 45413 | H38: Lead Tenant | I38: ruthkhowells@gmail.com | J38: '+44 7736 468158 | K38: 234 Brook Place,10 Summerfield Street, Sheffield, S11 8BR | L38: TRUE | M38: New | O38: 45413 | P38: <a href="a1G4J0000025zJo" target="_blank">234, Brook Place Apts, Sheffield, S11 8BR</a> | Q38: Apartment | R38: Tenanted | T38: Brook Place | U38: BTR-Regions | V38: Emma Cramer-Mitchell | X38: Vicki Turnbull | Y38: Leanne Hargreaves | Z38: 45626 | AA38: Brook Place Apts, 10 Summerfield Street, Shef | AB38: 234, Brook Place Apts, Sheffield, S11 8BR | AC38: GREP-CoA Ruth Howells, Robert Howells - 234, Brook Place Apts, Sheffield, S11 8BR | AD38: 512744837 | AF38: Yes | AH38: Pet friendly, flexible rental period, safe and quiet and good amenities | AJ38: It‚Äôs pretty good | AK38: It is early days but so far we are happy. We really like the flat and it suits our family well. | AL38: 45503.085 | AR38: =COUNTIF(AD:AD,AD38) -> 1
A39: 003Nz00000CoKshIAF | B39: 006Nz00000AVB7uIAH | C39: Suet Ying | D39: Chow | F39: 45777 | G39: 45413 | H39: Lead Tenant | I39: louisechow621@gmail.com | J39: 07752064317 | K39: Flat 604 , Enigma Square,414 North Row, Milton Keynes, MK9 2FU | L39: TRUE | M39: New | O39: 45413 | P39: <a href="a1G8d0000005rDF" target="_blank">604 Enigma Square, 414 North Row, MK9 2FU</a> | Q39: Apartment | R39: Reserved | T39: Enigma Square | U39: BTR-Regions | V39: Tina Viragh | X39: Sarah Norstrom | Y39: Grace Fiske | Z39: 45841 | AA39: Enigma Square - Apartments | AB39: 320 Enigma Square, 414 North Row, MK9 2GE | AC39: GREP-CoA Suet Ying Chow, Koon Hong Kwok - 604 Enigma Square, 414 North Row, MK9 2FU | AD39: 512720968 | AF39: Yes | AH39: Staff is nice and helpful esp. Michelle, Janki. | AJ39: It‚Äôs pretty good | AK39: Building quality is good, can keep the home very warm. | AL39: 45503.085 | AR39: =COUNTIF(AD:AD,AD39) -> 1
A40: 003Nz00000CIhxGIAT | B40: 006Nz00000A8kb1IAB | C40: Carol | D40: George | F40: 45781 | G40: 45416 | H40: Lead Tenant | I40: ohcarolinah@yahoo.com | J40: 07765740226 | K40: Apartment 625, The Barnum,23 Queens Road, Nottingham, NG2 3FJ | L40: TRUE | M40: New | O40: 45416 | P40: <a href="a1GNz000000163O" target="_blank">625 The Barnum, 23 Queens Road, Nottingham</a> | Q40: Apartment | R40: Tenanted | T40: The Barnum | U40: BTR-Regions | V40: Natasha Burns | X40: Vicki Turnbull | Y40: Leanne Hargreaves | Z40: 45780 | AA40: The Barnum - Apartments | AB40: 625 The Barnum, 23 Queens Road, Nottingham | AC40: GREP-CoA Carol George - 625 The Barnum, 23 Queens Road, Nottingham | AD40: 510045017 | AF40: Yes | AH40: Lounges, amenities and onsite team especially Natasha and Amy. | AJ40: It‚Äôs ok | AK40: I love my home but just fix the issues I raised above. | AL40: 45506.085 | AR40: =COUNTIF(AD:AD,AD40) -> 1
...

Sheet Mnth 3 TP survey records in SF
A1: Id | B1: Name | C1: Contact_ID_Mapped__c | D1: Opportunity_ID_Mapped__c | E1: RecordType.Name | F1: CreatedDate | G1: CreatedBy.Name | H1: Opportunity_Name__c | I1: LastModifiedBy.Name | J1: LastModifiedDate | K1: Unit_Address__c | L1: Opportunity_ID_Mapped__r.Name | M1: Opportunity_ID_Mapped__r.Primary_Offer__r.Unit__c | N1: Opportunity_ID_Mapped__r.Primary_Offer__r.Unit__r.Name | O1: Opportunity_ID_Mapped__r.Primary_Offer__r.Unit__r.Display_Address__c | P1: Unit check | Q1: Count of same name | R1: count of same opp name | S1: Count of same opp id
A2: a1kNz000004e0v3IAA | B2: 539720258 | C2: 003Nz00000JKmAQIA1 | D2: 006Nz00000F6dJ1IAJ | E2: Month 3: How can we make things better (Specification) Survey | F2: 2024-12-05T23:30:17.000+0000 | G2: marketing cloud connector | H2: GREP-CoA Debora Marques Ferreira Cunha, Renato Jose Valerio - Apt 89, Kings Dock Mill, Liverpool, L1 | I2: marketing cloud connector | J2: 2024-12-05T23:30:17.000+0000 | K2: <a href="a1G4J0000025yHK" target="_blank">Apt 89, Kings Dock Mill, Liverpool, L1</a> | L2: GREP-CoA Debora Marques Ferreira Cunha, Renato Jose Valerio - Apt 89, Kings Dock Mill, Liverpool, L1 | M2: a1G4J0000025yHKUAY | N2: Apt 89, Kings Dock Mill, Liverpool, L1 | O2: Kings Dock Mill, Liverpool Liverpool L1 | P2: =N2=K2 -> FALSE | Q2: =COUNTIF($B$2:$B$1196,B2) -> 1 | R2: =COUNTIF($H$2:$H$1196,H2) -> 1 | S2: =COUNTIF($D$2:$D$1196,D2) -> 1
A3: a1kNz000004c4edIAA | B3: 535380882 | C3: 003Nz00000IF65zIAD | D3: 006Nz00000EOc0yIAD | E3: Month 3: How can we make things better (Specification) Survey | F3: 2024-12-01T23:30:47.000+0000 | G3: marketing cloud connector | H3: GREP-CoA Alghalia Marafie, Amal Hani & Salem Marafie - 108 Millwrights Place, Temple Back, Bristol | I3: marketing cloud connector | J3: 2024-12-01T23:30:47.000+0000 | K3: <a href="a1GNz0000019Hx7" target="_blank">108 Millwrights Place, Temple Back, Bristol</a> | L3: GREP-CoA Alghalia Marafie, Amal Hani & Salem Marafie - 108 Millwrights Place, Temple Back, Bristol | M3: a1GNz0000019Hx7MAE | N3: 108 Millwrights Place, Temple Back, Bristol | O3: Millwrights Place, Bristol Bristol BS1 | P3: =N3=K3 -> FALSE | Q3: =COUNTIF($B$2:$B$1196,B3) -> 1 | R3: =COUNTIF($H$2:$H$1196,H3) -> 1 | S3: =COUNTIF($D$2:$D$1196,D3) -> 1
A4: a1kNz000004c4ecIAA | B4: 540162006 | C4: 003Nz00000JSncNIAT | D4: 006Nz00000FAHDRIA5 | E4: Month 3: How can we make things better (Specification) Survey | F4: 2024-12-01T23:30:47.000+0000 | G4: marketing cloud connector | H4: GREP-CoA Hoi Yan Yu & Wing Shiu Lo - 127 Gatehouse Apts, 86 East St, Southampton | I4: marketing cloud connector | J4: 2024-12-01T23:30:47.000+0000 | K4: <a href="a1G4J0000025xJE" target="_blank">127 Gatehouse Apts, 86 East St, Southampton</a> | L4: GREP-CoA Hoi Yan Yu & Wing Shiu Lo - 127 Gatehouse Apts, 86 East St, Southampton | M4: a1G4J0000025xJEUAY | N4: 127 Gatehouse Apts, 86 East St, Southampton | O4: Gatehouse Apartments, Southampton Southampton SO14 | P4: =N4=K4 -> FALSE | Q4: =COUNTIF($B$2:$B$1196,B4) -> 1 | R4: =COUNTIF($H$2:$H$1196,H4) -> 2 | S4: =COUNTIF($D$2:$D$1196,D4) -> 2
A5: a1kNz000004c4ebIAA | B5: 539721296 | C5: 003Nz00000JLDycIAH | D5: 006Nz00000FAHDRIA5 | E5: Month 3: How can we make things better (Specification) Survey | F5: 2024-12-01T23:30:47.000+0000 | G5: marketing cloud connector | H5: GREP-CoA Hoi Yan Yu & Wing Shiu Lo - 127 Gatehouse Apts, 86 East St, Southampton | I5: marketing cloud connector | J5: 2024-12-01T23:30:47.000+0000 | K5: <a href="a1G4J0000025xJE" target="_blank">127 Gatehouse Apts, 86 East St, Southampton</a> | L5: GREP-CoA Hoi Yan Yu & Wing Shiu Lo - 127 Gatehouse Apts, 86 East St, Southampton | M5: a1G4J0000025xJEUAY | N5: 127 Gatehouse Apts, 86 East St, Southampton | O5: Gatehouse Apartments, Southampton Southampton SO14 | P5: =N5=K5 -> FALSE | Q5: =COUNTIF($B$2:$B$1196,B5) -> 1 | R5: =COUNTIF($H$2:$H$1196,H5) -> 2 | S5: =COUNTIF($D$2:$D$1196,D5) -> 2
A6: a1kNz000004aMXZIA2 | B6: 471138769 | C6: 003Nz000004AhxRIAS | D6: 006Nz00000EItagIAD | E6: Month 3: How can we make things better (Specification) Survey | F6: 2024-11-27T23:30:11.000+0000 | G6: marketing cloud connector | H6: GREP-CoA Dev Bhuta, Palak Bhatt - 426 Enigma Square, 414 North Row, MK9 2GE | I6: Saji Gunasekaran | J6: 2024-11-27T23:32:52.000+0000 | K6: 426 Enigma Square, 414 North Row, MK9 2GE | L6: GREP-CoA Dev Bhuta, Palak Bhatt - 426 Enigma Square, 414 North Row, MK9 2GE | M6: a1G8d0000005rSQEAY | N6: 426 Enigma Square, 414 North Row, MK9 2GE | O6: Enigma Square, Milton Keynes Milton Keynes MK9 | P6: =N6=K6 -> TRUE | Q6: =COUNTIF($B$2:$B$1196,B6) -> 2 | R6: =COUNTIF($H$2:$H$1196,H6) -> 1 | S6: =COUNTIF($D$2:$D$1196,D6) -> 1
A7: a1kNz000004ZwgZIAS | B7: 527014030 | C7: 003Nz00000GDOUmIAP | D7: 006Nz00000DABdrIAH | E7: Month 3: How can we make things better (Specification) Survey | F7: 2024-11-25T23:30:25.000+0000 | G7: Saji Gunasekaran | I7: Saji Gunasekaran | J7: 2024-11-27T14:48:48.000+0000 | K7: 1002, Lamp House, 215 Chapel St, Salford, M3 | L7: GREP-CoA Mahmoudreza Oshagh & Banafsheh Shahzamanian Sichani - 1002, Lamp House, 215 Chapel St, Salford, M3 | M7: a1G4J0000025yS9UAI | N7: 1002, Lamp House, 215 Chapel St, Salford, M3 | O7: The Filaments, Salford Salford M3 | P7: =N7=K7 -> TRUE | Q7: =COUNTIF($B$2:$B$1196,B7) -> 1 | R7: =COUNTIF($H$2:$H$1196,H7) -> 0 | S7: =COUNTIF($D$2:$D$1196,D7) -> 1
A8: a1kNz000004ZwgYIAS | B8: 523136143 | C8: 003Nz00000FFGNDIA5 | D8: 006Nz00000CCr6UIAT | E8: Month 3: How can we make things better (Specification) Survey | F8: 2024-11-17T23:30:25.000+0000 | G8: Saji Gunasekaran | I8: Saji Gunasekaran | J8: 2024-11-27T14:47:55.000+0000 | K8: 82 Gatehouse Apts, 86 East St, Southampton | L8: GREP-CoA Puspinder Singh and Kritika Gambhir - 82 Gatehouse Apts, 86 East St, Southampton | M8: a1G4J0000025yQJUAY | N8: 82 Gatehouse Apts, 86 East St, Southampton | O8: Gatehouse Apartments, Southampton Southampton SO14 | P8: =N8=K8 -> TRUE | Q8: =COUNTIF($B$2:$B$1196,B8) -> 1 | R8: =COUNTIF($H$2:$H$1196,H8) -> 0 | S8: =COUNTIF($D$2:$D$1196,D8) -> 1
A9: a1kNz000004ZwgXIAS | B9: 524354677 | C9: 003Nz00000FV3FWIA1 | D9: 006Nz00000COf1XIAT | E9: Month 3: How can we make things better (Specification) Survey | F9: 2024-11-15T23:30:25.000+0000 | G9: Saji Gunasekaran | I9: Saji Gunasekaran | J9: 2024-11-27T14:47:03.000+0000 | K9: 608 The Silver Yard, 100 Moor St Queensway | L9: GREP-CoA Jiashu Wang and Yi Zheng - 608 The Silver Yard, 100 Moor St Queensway | M9: a1GNz000001HPPdMAO | N9: 608 The Silver Yard, 100 Moor St Queensway | O9: The Silver Yard, Birmingham Birmingham B4 | P9: =N9=K9 -> TRUE | Q9: =COUNTIF($B$2:$B$1196,B9) -> 1 | R9: =COUNTIF($H$2:$H$1196,H9) -> 0 | S9: =COUNTIF($D$2:$D$1196,D9) -> 1
A10: a1kNz000004ZwgWIAS | B10: 526344635 | C10: 003Nz00000G13E0IAJ | D10: 006Nz00000ClhLxIAJ | E10: Month 3: How can we make things better (Specification) Survey | F10: 2024-11-15T23:30:25.000+0000 | G10: Saji Gunasekaran | I10: Saji Gunasekaran | J10: 2024-11-27T14:45:57.000+0000 | K10: 506 Assay Apartments, Station View, Guildford | L10: GREP-CoA Emre Tarasil and Gulsah Tarasli - 506 Assay Apartments, Station View, Guildford | M10: a1G8d000002Q2T8EAK | N10: 506 Assay Apartments, Station View, Guildford | O10: The Mint, Guildford Guildford GU1 | P10: =N10=K10 -> TRUE | Q10: =COUNTIF($B$2:$B$1196,B10) -> 1 | R10: =COUNTIF($H$2:$H$1196,H10) -> 0 | S10: =COUNTIF($D$2:$D$1196,D10) -> 1
A11: a1kNz000004SYE9IAO | B11: 528400757 | C11: 003Nz00000GYWAjIAP | D11: 006Nz00000DBAarIAH | E11: Month 3: How can we make things better (Specification) Survey | F11: 2024-11-14T23:30:29.000+0000 | G11: marketing cloud connector | H11: GREP-CoA Keri Castillo - 30 Houghton Avenue, Waterlooville, PO7 3AA | I11: Saji Gunasekaran | J11: 2024-11-25T00:42:05.000+0000 | K11: 30 Houghton Avenue, Waterlooville, PO7 3AA | L11: GREP-CoA Keri Castillo - 30 Houghton Avenue, Waterlooville, PO7 3AA | M11: a1G4J0000025xktUAA | N11: 30 Houghton Avenue, Waterlooville, PO7 3AA | O11: The Grainger Collection at Berewood Hampshire PO7 | P11: =N11=K11 -> TRUE | Q11: =COUNTIF($B$2:$B$1196,B11) -> 2 | R11: =COUNTIF($H$2:$H$1196,H11) -> 1 | S11: =COUNTIF($D$2:$D$1196,D11) -> 2
A12: a1kNz000004ZwgVIAS | B12: 528400757 | C12: 003Nz00000GYWAjIAP | D12: 006Nz00000DBAarIAH | E12: Month 3: How can we make things better (Specification) Survey | F12: 2024-11-14T23:30:25.000+0000 | G12: Saji Gunasekaran | I12: Saji Gunasekaran | J12: 2024-11-27T14:45:01.000+0000 | K12: 30 Houghton Avenue, Waterlooville, PO7 3AA | L12: GREP-CoA Keri Castillo - 30 Houghton Avenue, Waterlooville, PO7 3AA | M12: a1G4J0000025xktUAA | N12: 30 Houghton Avenue, Waterlooville, PO7 3AA | O12: The Grainger Collection at Berewood Hampshire PO7 | P12: =N12=K12 -> TRUE | Q12: =COUNTIF($B$2:$B$1196,B12) -> 2 | R12: =COUNTIF($H$2:$H$1196,H12) -> 0 | S12: =COUNTIF($D$2:$D$1196,D12) -> 2
A13: a1kNz000004ZwgUIAS | B13: 531161716 | C13: 003Nz00000HARQ9IAP | D13: 006Nz00000DcigTIAR | E13: Month 3: How can we make things better (Specification) Survey | F13: 2024-11-12T23:30:25.000+0000 | G13: Saji Gunasekaran | I13: Saji Gunasekaran | J13: 2024-11-27T14:44:10.000+0000 | K13: Apt 111, Kings Dock Mill, Liverpool, L1 | L13: GREP-CoA Lauren Gibson and Sean Farrell - Apt 111, Kings Dock Mill, Liverpool, L1 | M13: a1G4J0000025yK9UAI | N13: Apt 111, Kings Dock Mill, Liverpool, L1 | O13: Kings Dock Mill, Liverpool Liverpool L1 | P13: =N13=K13 -> TRUE | Q13: =COUNTIF($B$2:$B$1196,B13) -> 1 | R13: =COUNTIF($H$2:$H$1196,H13) -> 0 | S13: =COUNTIF($D$2:$D$1196,D13) -> 1
A14: a1kNz000004ZwgTIAS | B14: 523133171 | C14: 003Nz00000FDzD7IAL | D14: 006Nz00000EUZYGIA5 | E14: Month 3: How can we make things better (Specification) Survey | F14: 2024-11-12T23:30:25.000+0000 | G14: Saji Gunasekaran | I14: Saji Gunasekaran | J14: 2024-11-27T14:42:26.000+0000 | K14: 1102 The Silver Yard, 100 Moor St Queensway | L14: GREP-CoA Sumita Datta - 1102 The Silver Yard, 100 Moor St Queensway | M14: a1GNz000001HQITMA4 | N14: 1102 The Silver Yard, 100 Moor St Queensway | O14: The Silver Yard, Birmingham Birmingham B4 | P14: =N14=K14 -> TRUE | Q14: =COUNTIF($B$2:$B$1196,B14) -> 1 | R14: =COUNTIF($H$2:$H$1196,H14) -> 0 | S14: =COUNTIF($D$2:$D$1196,D14) -> 1
