Workbook
Name aspectpremium: '2. GRI Pricing Inputs'!$C$53:$E$55
Name balcony: '2. GRI Pricing Inputs'!$C$67:$E$69
Name baseprice: '2. GRI Pricing Inputs'!$C$15:$F$17
Name bathpremium: '2. GRI Pricing Inputs'!$C$21:$E$24
Name floorpremium: '2. GRI Pricing Inputs'!$C$45:$E$47
Name other: '2. GRI Pricing Inputs'!$O$32:$P$47
Name phasedrelease: '2. GRI Pricing Inputs'!$I$54
Name sizepremium: '2. GRI Pricing Inputs'!$C$28:$E$31

Sheet Cover
C3: BTR PRICING WORKBOOK
K5: ACQ | L5: CFT | M5: ONB | N5: AM | O5: LET
C6: Project: | E6: Enigma Square | J6: Project Team | L6: [Name] | M6: [Name] | N6: [Name] | O6: [Name]
C7: Pricing Date: | E7: 45502 | J7: Reviewer | L7: [Name] | M7: [Name] | N7: [Name] | O7: [Name]
C9: INSTRUCTIONS
C11: Key: | E11: Light blue = input | G11: White = calculation
C13: Tab | D13: Process
C14: 1. Accomodation tab | D14: 1 | E14: Input accomodation to be constructed, as per the Development agreement, in columns D-F (request final DA from the acquistions manager)
D15: 2 | E15: Update Qube for Qube location data (fund/portfolio/estate) as per BTR example provided (check with asset manager if unsure)
D16: 3 | E16: Create Grainger schedule as required in the format provided (Col L-AA)
D17: 4 | E17: Input Grainger required accomodation attributes (Col S-AA)
C19: 2. GRI Pricing inputs | D19: 5 | E19: Input premium values and growth inputs (Number 1-15)
D20: 6 | E20: Describe methodology for each inputs
C22: 3. GRI Pricing | D22: 7 | E22: Review and sense check pricing framework unit by unit
D23: 8 | E23: Add any manual adjustment and provide rationale for adjustments
D24: 9 | E24: Review and sense check overall and average pricing
C26: 4. CBRE ERV's | D26: 10 | E26: CFT to provide i) approved underwritten rents ii) market ERV per the latest CBRE valuation
D27: 11 | E27: Communication expected launch date to CFT in order to grow benchmarks to same point in time.
D28: 12 | E28: All rents must be compared at the same point in time, on a like for like basis.
D29: 13 | E29: If appraising the current market rent today, we must grow both the underwriting and CBRE from their respective points in time to today.
D30: 14 | E30: Grainger underwrite rental growth for each project and CBRE assume rental growth in their valuation (check growth % for each specific project).
C32: 5. Dashboard | D32: 15 | E32: Review dashboard, ensure current pricing are in line as expected of the current view of the market
D33: 16 | E33: Aim to launch at and outperform the higher of i) ‘grown underwritten ERV’ and ii) ‘CBRE Est. Forecast' ERV
D34: 17 | E34: Append the table within leasing and marketing report
C36: 6. IC Appendix | D36: 18 | E36: Append the full master schedule within leasing and marketing report.
C38: 7. Archive Pricing | D38: 19 | E38: To allow tracking of previously approved prices for each unit.

Sheet 1. Accomodation
H3: 1. ACCOMODATION SCHEDULE | Y3: ='4. Valuation'!$D$6 -> 45536
H5: Project | I5: =Cover!E6 -> Enigma Square
H7: Qube Location Data | L7: Grainger Accomodation
H8: Qube Field | I8: Inputs | J8: Example | L8: Bedroom | M8: No. of Homes | N8: Av. Size (sqft) | O8: Notes
H9: Fund | I9: BTR-London & SE | L9: Studio | M9: =IFERROR(COUNTIF($P$21:$P$622,$L9),"-") -> 13 | N9: =IFERROR(AVERAGEIF($P$21:$P$622,$L9,$O$21:$O$622),"-") -> 389.98462 | O9: [XXX]
H10: Portfolio | I10: Enigma Square | L10: 1 Bed | M10: =IFERROR(COUNTIF($P$21:$P$622,$L10),"-") -> 182 | N10: =IFERROR(AVERAGEIF($P$21:$P$622,$L10,$O$21:$O$622),"-") -> 504.70418 | O10: [XXX]
H11: Estate | I11: Enigma Square Apartments | J11: XXXX - Apartments | L11: 2 Bed | M11: =IFERROR(COUNTIF($P$21:$P$622,$L11),"-") -> 54 | N11: =IFERROR(AVERAGEIF($P$21:$P$622,$L11,$O$21:$O$622),"-") -> 734.66111 | O11: [XXX]
J12: XXXX - XXX Apts | L12: 3 bed | M12: =IFERROR(COUNTIF($P$21:$P$622,$L12),"-") -> 12 | N12: =IFERROR(AVERAGEIF($P$21:$P$622,$L12,$O$21:$O$622),"-") -> 1007.4292
J13: XXXX - Amenity | M13: =IFERROR(COUNTIF($P$21:$P$622,$L13),"-") -> 0 | N13: =IFERROR(AVERAGEIF($P$21:$P$622,$L13,$O$21:$O$622),"-") -> -
J14: XXXX - Commercial | M14: =IFERROR(COUNTIF($P$21:$P$622,$L14),"-") -> 0 | N14: =IFERROR(AVERAGEIF($P$21:$P$622,$L14,$O$21:$O$622),"-") -> -
L15: Total | M15: =SUM(M9:M13) -> 261 | N15: =IFERROR(SUM(O21:O620)/M15,0) -> 569.68126
J16: XXXX - Car Parking | L16: Car Park | M16: 178
D19: DA ACCOMODATION | H19: Qube Property Location Inputs | L19: GRAINGER ACCOMODATION
C20: Plot Number | D20: Home type | E20: Size (sq.ft) | F20: Bedroom | H20: Fund | I20: Portfolio | J20: Estate | L20: Block Name | M20: =D20 -> Home type | N20: Door Number | O20: =E20 -> Size (sq.ft) | P20: ='2. GRI Pricing Inputs'!C15 -> Bedroom | Q20: ='2. GRI Pricing Inputs'!C22 -> Bath | R20: ='2. GRI Pricing Inputs'!C45 -> Floor | S20: ='2. GRI Pricing Inputs'!C53 -> Aspect | T20: ='2. GRI Pricing Inputs'!C60 -> Storage | U20: ='2. GRI Pricing Inputs'!C67 -> Balcony | V20: ='2. GRI Pricing Inputs'!C83 -> Additional Toilet | W20: ='2. GRI Pricing Inputs'!C90 -> Larger Master Bedroom | X20: ='2. GRI Pricing Inputs'!C98 -> 0 | Y20: ='2. GRI Pricing Inputs'!C105 -> 0
D21: [Select] | H21: =$I$9 -> BTR-London & SE | I21: =$I$10 -> Enigma Square | J21: Enigma Square Apartments | L21: C | M21: Apartment | N21: 101 | O21: 517.1 | P21: 1 Bed | Q21: 1 | R21: 1 | S21: North Row below Treeline | U21: Small Terrace Balcony | V21: [Select] | X21: [Select] | Y21: [Select]
D22: [Select] | H22: =$I$9 -> BTR-London & SE | I22: =$I$10 -> Enigma Square | J22: Enigma Square Apartments | L22: C | M22: Apartment | N22: 102 | O22: 385.46 | P22: Studio | Q22: 1 | R22: 1 | S22: Nursery and mixed other buildings | U22: None | V22: [Select] | X22: [Select] | Y22: [Select]
D23: [Select] | H23: =$I$9 -> BTR-London & SE | I23: =$I$10 -> Enigma Square | J23: Enigma Square Apartments | L23: C | M23: Apartment | N23: 103 | O23: 394.17 | P23: Studio | Q23: 1 | R23: 1 | S23: Nursery and mixed other buildings | U23: None | V23: [Select] | X23: [Select] | Y23: [Select]
D24: [Select] | H24: =$I$9 -> BTR-London & SE | I24: =$I$10 -> Enigma Square | J24: Enigma Square Apartments | L24: C | M24: Apartment | N24: 104 | O24: 521.51 | P24: 1 Bed | Q24: 1 | R24: 1 | S24: North Row below Treeline | U24: Small Terrace Balcony | V24: [Select] | X24: [Select] | Y24: [Select]
D25: [Select] | H25: =$I$9 -> BTR-London & SE | I25: =$I$10 -> Enigma Square | J25: Enigma Square Apartments | L25: C | M25: Apartment | N25: 105 | O25: 532.49 | P25: 1 Bed | Q25: 1 | R25: 1 | S25: North Row below Treeline | U25: Small Terrace Balcony | V25: [Select] | X25: [Select] | Y25: [Select]
D26: [Select] | H26: =$I$9 -> BTR-London & SE | I26: =$I$10 -> Enigma Square | J26: Enigma Square Apartments | L26: C | M26: Apartment | N26: 106 | O26: 728.18 | P26: 2 Bed | Q26: 2 | R26: 1 | S26: Carpark and other block | U26: Long Terrace Balcony | V26: [Select] | X26: [Select] | Y26: [Select]
D27: [Select] | H27: =$I$9 -> BTR-London & SE | I27: =$I$10 -> Enigma Square | J27: Enigma Square Apartments | L27: C | M27: Apartment | N27: 107 | O27: 489.44 | P27: 1 Bed | Q27: 1 | R27: 1 | S27: Nursery and mixed other buildings | U27: None | V27: [Select] | X27: [Select] | Y27: [Select]
D28: [Select] | H28: =$I$9 -> BTR-London & SE | I28: =$I$10 -> Enigma Square | J28: Enigma Square Apartments | L28: C | M28: Apartment | N28: 108 | O28: 509.56 | P28: 1 Bed | Q28: 1 | R28: 1 | S28: Carpark and other block | U28: Small Terrace Balcony | V28: [Select] | X28: [Select] | Y28: [Select]
D29: [Select] | H29: =$I$9 -> BTR-London & SE | I29: =$I$10 -> Enigma Square | J29: Enigma Square Apartments | L29: C | M29: Apartment | N29: 109 | O29: 506.87 | P29: 1 Bed | Q29: 1 | R29: 1 | S29: Nursery and mixed other buildings | U29: None | V29: [Select] | X29: [Select] | Y29: [Select]
D30: [Select] | H30: =$I$9 -> BTR-London & SE | I30: =$I$10 -> Enigma Square | J30: Enigma Square Apartments | L30: C | M30: Apartment | N30: 110 | O30: 509.56 | P30: 1 Bed | Q30: 1 | R30: 1 | S30: Carpark and other block | U30: Small Terrace Balcony | V30: [Select] | X30: [Select] | Y30: [Select]
D31: [Select] | H31: =$I$9 -> BTR-London & SE | I31: =$I$10 -> Enigma Square | J31: Enigma Square Apartments | L31: C | M31: Apartment | N31: 111 | O31: 747.02 | P31: 2 Bed | Q31: 2 | R31: 1 | S31: Carpark and other block | U31: None | V31: [Select] | X31: [Select] | Y31: [Select]
D32: [Select] | H32: =$I$9 -> BTR-London & SE | I32: =$I$10 -> Enigma Square | J32: Enigma Square Apartments | L32: C | M32: Apartment | N32: 112 | O32: 506.76 | P32: 1 Bed | Q32: 1 | R32: 1 | S32: Carpark and other block | U32: Small Terrace Balcony | V32: [Select] | X32: [Select] | Y32: [Select]
... D36: [Select] | H36: =$I$9 -> BTR-London & SE | I36: =$I$10 -> Enigma Square | J36: Enigma Square Apartments | L36: C | M36: Apartment | N36: 204 | O36: 521.51 | P36: 1 Bed | Q36: 1 | R36: 2 | S36: North Row below Treeline | U36: Cantilever Balcony | V36: [Select] | X36: [Select] | Y36: [Select]
D37: [Select] | H37: =$I$9 -> BTR-London & SE | I37: =$I$10 -> Enigma Square | J37: Enigma Square Apartments | L37: C | M37: Apartment | N37: 205 | O37: 762.95 | P37: 2 Bed | Q37: 2 | R37: 2 | S37: North Row below Treeline | T37: One storage | U37: Enclosed Cantiliever | V37: [Select] | X37: [Select] | Y37: [Select]
D38: [Select] | H38: =$I$9 -> BTR-London & SE | I38: =$I$10 -> Enigma Square | J38: Enigma Square Apartments | L38: C | M38: Apartment | N38: 206 | O38: 529.8 | P38: 1 Bed | Q38: 1 | R38: 2 | S38: Amenity Pebble Roof | U38: Juliette | V38: [Select] | X38: [Select] | Y38: [Select]
D39: [Select] | H39: =$I$9 -> BTR-London & SE | I39: =$I$10 -> Enigma Square | J39: Enigma Square Apartments | L39: C | M39: Apartment | N39: 207 | O39: 509.56 | P39: 1 Bed | Q39: 1 | R39: 2 | S39: Carpark and other block | U39: Juliette | V39: [Select] | X39: [Select] | Y39: [Select]
D40: [Select] | H40: =$I$9 -> BTR-London & SE | I40: =$I$10 -> Enigma Square | J40: Enigma Square Apartments | L40: C | M40: Apartment | N40: 208 | O40: 489.44 | P40: 1 Bed | Q40: 1 | R40: 2 | S40: Nursery and mixed other buildings | U40: Cantilever Balcony | V40: [Select] | X40: [Select] | Y40: [Select]
D41: [Select] | H41: =$I$9 -> BTR-London & SE | I41: =$I$10 -> Enigma Square | J41: Enigma Square Apartments | L41: C | M41: Apartment | N41: 209 | O41: 509.56 | P41: 1 Bed | Q41: 1 | R41: 2 | S41: Carpark and other block | U41: Juliette | V41: [Select] | X41: [Select] | Y41: [Select]
D42: [Select] | H42: =$I$9 -> BTR-London & SE | I42: =$I$10 -> Enigma Square | J42: Enigma Square Apartments | L42: C | M42: Apartment | N42: 210 | O42: 506.87 | P42: 1 Bed | Q42: 1 | R42: 2 | S42: Nursery and mixed other buildings | U42: Cantilever Balcony | V42: [Select] | X42: [Select] | Y42: [Select]
D43: [Select] | H43: =$I$9 -> BTR-London & SE | I43: =$I$10 -> Enigma Square | J43: Enigma Square Apartments | L43: C | M43: Apartment | N43: 211 | O43: 509.56 | P43: 1 Bed | Q43: 1 | R43: 2 | S43: Carpark and other block | U43: Juliette | V43: [Select] | X43: [Select] | Y43: [Select]
D44: [Select] | H44: =$I$9 -> BTR-London & SE | I44: =$I$10 -> Enigma Square | J44: Enigma Square Apartments | L44: C | M44: Apartment | N44: 212 | O44: 747.02 | P44: 2 Bed | Q44: 2 | R44: 2 | S44: Nursery and mixed other buildings | U44: Cantilever Balcony | V44: [Select] | X44: [Select] | Y44: [Select]
D45: [Select] | H45: =$I$9 -> BTR-London & SE | I45: =$I$10 -> Enigma Square | J45: Enigma Square Apartments | L45: C | M45: Apartment | N45: 213 | O45: 506.76 | P45: 1 Bed | Q45: 1 | R45: 2 | S45: Carpark and other block | U45: Juliette | V45: [Select] | X45: [Select] | Y45: [Select]
D46: [Select] | H46: =$I$9 -> BTR-London & SE | I46: =$I$10 -> Enigma Square | J46: Enigma Square Apartments | L46: D | M46: Apartment | N46: 214 | O46: 507.41 | P46: 1 Bed | Q46: 1 | R46: 2 | S46: Carpark and other block | U46: Small Terrace Balcony | V46: [Select] | X46: [Select] | Y46: [Select]
D47: [Select] | H47: =$I$9 -> BTR-London & SE | I47: =$I$10 -> Enigma Square | J47: Enigma Square Apartments | L47: D | M47: Apartment | N47: 215 | O47: 749.38 | P47: 2 Bed | Q47: 2 | R47: 2 | S47: Private patio / Internal Courtyard | U47: Courtyard Terrace | V47: [Select] | X47: [Select] | Y47: [Select]
D48: [Select] | H48: =$I$9 -> BTR-London & SE | I48: =$I$10 -> Enigma Square | J48: Enigma Square Apartments | L48: D | M48: Apartment | N48: 216 | O48: 510.21 | P48: 1 Bed | Q48: 1 | R48: 2 | S48: Carpark and other block | U48: Small Terrace Balcony | V48: [Select] | X48: [Select] | Y48: [Select]
D49: [Select] | H49: =$I$9 -> BTR-London & SE | I49: =$I$10 -> Enigma Square | J49: Enigma Square Apartments | L49: D | M49: Apartment | N49: 217 | O49: 506.87 | P49: 1 Bed | Q49: 1 | R49: 2 | S49: Private patio / Internal Courtyard | U49: Courtyard Terrace | V49: [Select] | W49: Yes | X49: [Select] | Y49: [Select]
...

Sheet 2. GRI Pricing Inputs
C3: 2. GRAINGER PRICING INPUTS | AL3: METHODOLOGY
C5: 0. Accomodation information
C7: Home Type | D7: [Select] | E7: Apartment | F7: House | G7: Townhouse
C9: Block Name | D9: [Select]
C11: 1. Base price
C13: The base pricing for each bed type based on comparable evidence of the local market.
C15: Bedroom | D15: [Select] | E15: ='1. Accomodation'!L9 -> Studio | F15: ='1. Accomodation'!L10 -> 1 Bed | G15: ='1. Accomodation'!L11 -> 2 Bed | H15: ='1. Accomodation'!L12 -> 3 bed | I15: ='1. Accomodation'!L13 -> 0 | J15: ='1. Accomodation'!M13 -> 0
C16: Base Price (£pm) | E16: 1175 | F16: 1275 | G16: 1665 | H16: 1915
C18: 2. Bath premium
C20: The premium to the base pricing (assumes a standard X bed homes) to reflect either the discount for only have 1 bathroom or the premium for having two.
C22: Bath | D22: [Select] | E22: 1 | F22: 2
C23: Bath Premium
C25: 3. Size premium by range
C27: The premium to the base pricing (assumes a standard X bed homes) to reflect units which are above or below the standard size.
C29: Bedroom | D29: [Select] | E29: 1 Bed | F29: 2 Bed | G29: 3 Bed | H29: [Select] | I29: [Select] | J29: [Select] | K29: [Select] | L29: [Select] | M29: [Select] | N29: [Select]
C30: Average size (sqft) | E30: =IFERROR(INDEX('1. Accomodation'!$N$9:$N$14,MATCH('2. GRI Pricing Inputs'!E$29,'1. Accomodation'!$L$9:$L$14,0)),0) -> 504.70418 | F30: =IFERROR(INDEX('1. Accomodation'!$N$9:$N$14,MATCH('2. GRI Pricing Inputs'!F$29,'1. Accomodation'!$L$9:$L$14,0)),0) -> 734.66111 | G30: =IFERROR(INDEX('1. Accomodation'!$N$9:$N$14,MATCH('2. GRI Pricing Inputs'!G$29,'1. Accomodation'!$L$9:$L$14,0)),0) -> 1007.4292 | H30: =IFERROR(INDEX('1. Accomodation'!$N$9:$N$14,MATCH('2. GRI Pricing Inputs'!H$29,'1. Accomodation'!$L$9:$L$14,0)),0) -> 0 | I30: =IFERROR(INDEX('1. Accomodation'!$N$9:$N$14,MATCH('2. GRI Pricing Inputs'!I$29,'1. Accomodation'!$L$9:$L$14,0)),0) -> 0 | J30: =IFERROR(INDEX('1. Accomodation'!$N$9:$N$14,MATCH('2. GRI Pricing Inputs'!J$29,'1. Accomodation'!$L$9:$L$14,0)),0) -> 0 | K30: =IFERROR(INDEX('1. Accomodation'!$N$9:$N$14,MATCH('2. GRI Pricing Inputs'!K$29,'1. Accomodation'!$L$9:$L$14,0)),0) -> 0 | L30: =IFERROR(INDEX('1. Accomodation'!$N$9:$N$14,MATCH('2. GRI Pricing Inputs'!L$29,'1. Accomodation'!$L$9:$L$14,0)),0) -> 0 | ... N30: =IFERROR(INDEX('1. Accomodation'!$N$9:$N$14,MATCH('2. GRI Pricing Inputs'!N$29,'1. Accomodation'!$L$9:$L$14,0)),0) -> 0
C32: Size premium | D32: 1 | F32: 2 | H32: 3 | J32: 4 | L32: 5 | N32: 6 | P32: 7 | R32: 8 | T32: 9 | V32: 10 | X32: 11 | Z32: 12 | AB32: 13 | AD32: 14 | AF32: 15
D33: 385 | E33: 395 | F33: 437 | G33: 437 | H33: 485 | I33: 489 | J33: 492 | K33: 497 | L33: 506 | M33: 512 | N33: 517 | O33: 524 | P33: 529 | Q33: 532 | R33: 656 | S33: 666 | T33: 728 | U33: 728 | V33: 747 | W33: 749 | X33: 759 | Y33: 763 | Z33: 972 | AA33: 973 | AB33: 986 | AC33: 996 | AD33: 1015 | AE33: 1017 | AF33: 1052 | AG33: 1066
C34: Studio | D34: 0
C35: 1 Bed | F35: -10 | H35: -5 | J35: 0 | L35: 5 | N35: 10 | P35: 20
C36: 2 Bed | R36: -30 | T36: 0 | V36: 15 | X36: 30
C37: 3 bed | Z37: -5 | AB37: 0 | AD37: 10 | AF37: 20
C38: [Select]
C39: [Select]
C41: 4. Floor premium
C43: A discount or premium to the base price is dependent on what floor the unit is located on (typical increments are between £5 - £20 per floor).
C45: Floor | D45: [Select] | E45: 1 | F45: 2 | G45: 3 | H45: 4 | I45: 5 | J45: 6 | K45: 7 | L45: 8
C46: Floor premium | E46: 20 | F46: 25 | G46: 30 | H46: 35 | I46: 40 | J46: 45 | K46: 50 | L46: 55
C49: 5. Aspect premium
C51: The premium to the base pricing is dependent on which direction the unit is facing (for e.g. south being the best).
C53: Aspect | D53: [Select] | E53: North Row above Treeline | F53: Saxon Gate above Treeline | G53: North Row below Treeline | H53: Saxon Gate below Treeline | I53: Internal Courtyard | J53: Private patio / Internal Courtyard | K53: Amenity Pebble Roof | L53: Carpark and other block | M53: YMCA facing another block of apartments
C54: Aspect premium | E54: 50 | F54: 50 | G54: 30 | H54: 30 | I54: 15 | J54: 10 | K54: 10 | L54: 5 | M54: -20
C56: 6. Storage premium
C58: The premium to the base pricing is dependent on the storage offered in the units.
C60: Storage | D60: [Select] | E60: One storage
C61: Storage premium | E61: 10
C63: 7. Balcony premium
C65: A premium to base to reflect if there is a balcony present. Price is further broken down as below.
C67: Balcony | D67: [Select] | E67: Extra large concrete wall terrace | F67: Long Terrace Balcony | G67: Concrete Wall Terrace | H67: Long Concrete Wall Terrace | I67: Cantilever Balcony | J67: Small Terrace Balcony | K67: Enclosed Cantilever | L67: Courtyard Terrace | M67: Juliette | N67: None
C68: Balcony premium | E68: 80 | F68: 55 | G68: 30 | H68: 30 | I68: 40 | J68: 30 | K68: 30 | L68: 15 | M68: 10 | N68: 0
...

Sheet 3. GRI Pricing
C3: 3. GRAINGER PRICING SCHEDULE
C5: ='1. Accomodation'!L8 -> Bedroom | D5: ='1. Accomodation'!M8 -> No. of Homes | E5: Av. Size (sqft) | F5: Launch Rent (pcm) | G5: Launch Rent (pa) | H5: Launch Rent (psf) | AC5: =C5 -> Bedroom | AD5: =AD16 -> 45596 | AE5: =AE16 -> 45626 | AF5: =AF16 -> 45657 | AG5: =AG16 -> 45688 | AH5: =AH16 -> 45716 | AI5: =AI16 -> 45747 | AJ5: =AJ16 -> 45777 | AK5: =AK16 -> 45808 | ... AP5: =AP16 -> 45961
C6: ='1. Accomodation'!L9 -> Studio | D6: ='1. Accomodation'!M9 -> 13 | E6: ='1. Accomodation'!N9 -> 389.98462 | F6: =IFERROR(AVERAGEIF($E$17:$E$616,$C6,$Z$17:$Z$616),0) -> 1216.5385 | G6: =F6*12 -> 14598.462 | H6: =IFERROR(G6/E6,0) -> 37.433429 | AC6: =C6 -> Studio | AD6: =IFERROR(AVERAGEIF($E$17:$E$616,$C6,AD$17:AD$616),0) -> 1222.5739 | AE6: =IFERROR(AVERAGEIF($E$17:$E$616,$C6,AE$17:AE$616),0) -> 1228.4431 | AF6: =IFERROR(AVERAGEIF($E$17:$E$616,$C6,AF$17:AF$616),0) -> 1234.5376 | AG6: =IFERROR(AVERAGEIF($E$17:$E$616,$C6,AG$17:AG$616),0) -> 1240.6623 | AH6: =IFERROR(AVERAGEIF($E$17:$E$616,$C6,AH$17:AH$616),0) -> 1246.2204 | AI6: =IFERROR(AVERAGEIF($E$17:$E$616,$C6,AI$17:AI$616),0) -> 1252.403 | AJ6: =IFERROR(AVERAGEIF($E$17:$E$616,$C6,AJ$17:AJ$616),0) -> 1258.4155 | AK6: =IFERROR(AVERAGEIF($E$17:$E$616,$C6,AK$17:AK$616),0) -> 1264.6586 | ... AP6: =IFERROR(AVERAGEIF($E$17:$E$616,$C6,AP$17:AP$616),0) -> 1295.9283
C7: ='1. Accomodation'!L10 -> 1 Bed | D7: ='1. Accomodation'!M10 -> 182 | E7: ='1. Accomodation'!N10 -> 504.70418 | F7: =IFERROR(AVERAGEIF($E$17:$E$616,$C7,$Z$17:$Z$616),0) -> 1360.467 | G7: =F7*12 -> 16325.604 | H7: =IFERROR(G7/E7,0) -> 32.346878 | AC7: =C7 -> 1 Bed | AD7: =IFERROR(AVERAGEIF($E$17:$E$616,$C7,AD$17:AD$616),0) -> 1367.2165 | AE7: =IFERROR(AVERAGEIF($E$17:$E$616,$C7,AE$17:AE$616),0) -> 1373.7801 | AF7: =IFERROR(AVERAGEIF($E$17:$E$616,$C7,AF$17:AF$616),0) -> 1380.5956 | AG7: =IFERROR(AVERAGEIF($E$17:$E$616,$C7,AG$17:AG$616),0) -> 1387.4449 | AH7: =IFERROR(AVERAGEIF($E$17:$E$616,$C7,AH$17:AH$616),0) -> 1393.6606 | AI7: =IFERROR(AVERAGEIF($E$17:$E$616,$C7,AI$17:AI$616),0) -> 1400.5747 | AJ7: =IFERROR(AVERAGEIF($E$17:$E$616,$C7,AJ$17:AJ$616),0) -> 1407.2985 | AK7: =IFERROR(AVERAGEIF($E$17:$E$616,$C7,AK$17:AK$616),0) -> 1414.2803 | ... AP7: =IFERROR(AVERAGEIF($E$17:$E$616,$C7,AP$17:AP$616),0) -> 1449.2495
C8: ='1. Accomodation'!L11 -> 2 Bed | D8: ='1. Accomodation'!M11 -> 54 | E8: ='1. Accomodation'!N11 -> 734.66111 | F8: =IFERROR(AVERAGEIF($E$17:$E$616,$C8,$Z$17:$Z$616),0) -> 1770.8333 | G8: =F8*12 -> 21250 | H8: =IFERROR(G8/E8,0) -> 28.924901 | AC8: =C8 -> 2 Bed | AD8: =IFERROR(AVERAGEIF($E$17:$E$616,$C8,AD$17:AD$616),0) -> 1779.6187 | AE8: =IFERROR(AVERAGEIF($E$17:$E$616,$C8,AE$17:AE$616),0) -> 1788.1621 | AF8: =IFERROR(AVERAGEIF($E$17:$E$616,$C8,AF$17:AF$616),0) -> 1797.0334 | AG8: =IFERROR(AVERAGEIF($E$17:$E$616,$C8,AG$17:AG$616),0) -> 1805.9487 | AH8: =IFERROR(AVERAGEIF($E$17:$E$616,$C8,AH$17:AH$616),0) -> 1814.0393 | AI8: =IFERROR(AVERAGEIF($E$17:$E$616,$C8,AI$17:AI$616),0) -> 1823.039 | AJ8: =IFERROR(AVERAGEIF($E$17:$E$616,$C8,AJ$17:AJ$616),0) -> 1831.7909 | AK8: =IFERROR(AVERAGEIF($E$17:$E$616,$C8,AK$17:AK$616),0) -> 1840.8786 | ... AP8: =IFERROR(AVERAGEIF($E$17:$E$616,$C8,AP$17:AP$616),0) -> 1886.3958
C9: ='1. Accomodation'!L12 -> 3 bed | D9: ='1. Accomodation'!M12 -> 12 | E9: ='1. Accomodation'!N12 -> 1007.4292 | F9: =IFERROR(AVERAGEIF($E$17:$E$616,$C9,$Z$17:$Z$616),0) -> 2069.1667 | G9: =F9*12 -> 24830 | H9: =IFERROR(G9/E9,0) -> 24.646894 | AC9: =C9 -> 3 bed | AD9: =IFERROR(AVERAGEIF($E$17:$E$616,$C9,AD$17:AD$616),0) -> 2079.4321 | AE9: =IFERROR(AVERAGEIF($E$17:$E$616,$C9,AE$17:AE$616),0) -> 2089.4148 | AF9: =IFERROR(AVERAGEIF($E$17:$E$616,$C9,AF$17:AF$616),0) -> 2099.7807 | AG9: =IFERROR(AVERAGEIF($E$17:$E$616,$C9,AG$17:AG$616),0) -> 2110.198 | AH9: =IFERROR(AVERAGEIF($E$17:$E$616,$C9,AH$17:AH$616),0) -> 2119.6516 | AI9: =IFERROR(AVERAGEIF($E$17:$E$616,$C9,AI$17:AI$616),0) -> 2130.1674 | AJ9: =IFERROR(AVERAGEIF($E$17:$E$616,$C9,AJ$17:AJ$616),0) -> 2140.3938 | AK9: =IFERROR(AVERAGEIF($E$17:$E$616,$C9,AK$17:AK$616),0) -> 2151.0125 | ... AP9: =IFERROR(AVERAGEIF($E$17:$E$616,$C9,AP$17:AP$616),0) -> 2204.198
C10: ='1. Accomodation'!L13 -> 0 | D10: ='1. Accomodation'!M13 -> 0 | E10: ='1. Accomodation'!N13 -> - | F10: =IFERROR(AVERAGEIF($E$17:$E$616,$C10,$Z$17:$Z$616),0) -> 0 | G10: =F10*12 -> 0 | H10: =IFERROR(G10/E10,0) -> 0 | AC10: =C10 -> 0 | AD10: =IFERROR(AVERAGEIF($E$17:$E$616,$C10,AD$17:AD$616),0) -> 0 | AE10: =IFERROR(AVERAGEIF($E$17:$E$616,$C10,AE$17:AE$616),0) -> 0 | AF10: =IFERROR(AVERAGEIF($E$17:$E$616,$C10,AF$17:AF$616),0) -> 0 | AG10: =IFERROR(AVERAGEIF($E$17:$E$616,$C10,AG$17:AG$616),0) -> 0 | AH10: =IFERROR(AVERAGEIF($E$17:$E$616,$C10,AH$17:AH$616),0) -> 0 | AI10: =IFERROR(AVERAGEIF($E$17:$E$616,$C10,AI$17:AI$616),0) -> 0 | AJ10: =IFERROR(AVERAGEIF($E$17:$E$616,$C10,AJ$17:AJ$616),0) -> 0 | AK10: =IFERROR(AVERAGEIF($E$17:$E$616,$C10,AK$17:AK$616),0) -> 0 | ... AP10: =IFERROR(AVERAGEIF($E$17:$E$616,$C10,AP$17:AP$616),0) -> 0
C11: ='1. Accomodation'!L14 -> 0 | D11: ='1. Accomodation'!M14 -> 0 | E11: ='1. Accomodation'!N14 -> - | F11: =IFERROR(AVERAGEIF($E$17:$E$616,$C11,$Z$17:$Z$616),0) -> 0 | G11: =F11*12 -> 0 | H11: =IFERROR(G11/E11,0) -> 0 | AC11: =C11 -> 0 | AD11: =IFERROR(AVERAGEIF($E$17:$E$616,$C11,AD$17:AD$616),0) -> 0 | AE11: =IFERROR(AVERAGEIF($E$17:$E$616,$C11,AE$17:AE$616),0) -> 0 | AF11: =IFERROR(AVERAGEIF($E$17:$E$616,$C11,AF$17:AF$616),0) -> 0 | AG11: =IFERROR(AVERAGEIF($E$17:$E$616,$C11,AG$17:AG$616),0) -> 0 | AH11: =IFERROR(AVERAGEIF($E$17:$E$616,$C11,AH$17:AH$616),0) -> 0 | AI11: =IFERROR(AVERAGEIF($E$17:$E$616,$C11,AI$17:AI$616),0) -> 0 | AJ11: =IFERROR(AVERAGEIF($E$17:$E$616,$C11,AJ$17:AJ$616),0) -> 0 | AK11: =IFERROR(AVERAGEIF($E$17:$E$616,$C11,AK$17:AK$616),0) -> 0 | ... AP11: =IFERROR(AVERAGEIF($E$17:$E$616,$C11,AP$17:AP$616),0) -> 0
C12: AVERAGE | D12: ='1. Accomodation'!M15 -> 261 | E12: =IFERROR('1. Accomodation'!N15,0) -> 569.68126 | F12: =IFERROR(G12/12,0) -> 1470.7854 | G12: =IFERROR(Z617/$D$12,0) -> 17649.425 | H12: =IFERROR(G12/$E$12,0) -> 30.981228 | AC12: =C12 -> AVERAGE | AD12: =IFERROR(AVERAGEIF($E$17:$E$616,$C12,AD$17:AD$616),0) -> 0 | AE12: =IFERROR(AVERAGEIF($E$17:$E$616,$C12,AE$17:AE$616),0) -> 0 | AF12: =IFERROR(AVERAGEIF($E$17:$E$616,$C12,AF$17:AF$616),0) -> 0 | AG12: =IFERROR(AVERAGEIF($E$17:$E$616,$C12,AG$17:AG$616),0) -> 0 | AH12: =IFERROR(AVERAGEIF($E$17:$E$616,$C12,AH$17:AH$616),0) -> 0 | AI12: =IFERROR(AVERAGEIF($E$17:$E$616,$C12,AI$17:AI$616),0) -> 0 | AJ12: =IFERROR(AVERAGEIF($E$17:$E$616,$C12,AJ$17:AJ$616),0) -> 0 | AK12: =IFERROR(AVERAGEIF($E$17:$E$616,$C12,AK$17:AK$616),0) -> 0 | ... AP12: =IFERROR(AVERAGEIF($E$17:$E$616,$C12,AP$17:AP$616),0) -> 0
C13: Car park | D13: ='1. Accomodation'!M16 -> 178 | F13: ='2. GRI Pricing Inputs'!D122 -> 0 | G13: =F13*12 -> 0 | AC13: =C13 -> Car park | AD13: =IFERROR(AVERAGEIF($E$17:$E$616,$C13,AD$17:AD$616),0) -> 0 | AE13: =IFERROR(AVERAGEIF($E$17:$E$616,$C13,AE$17:AE$616),0) -> 0 | AF13: =IFERROR(AVERAGEIF($E$17:$E$616,$C13,AF$17:AF$616),0) -> 0 | AG13: =IFERROR(AVERAGEIF($E$17:$E$616,$C13,AG$17:AG$616),0) -> 0 | AH13: =IFERROR(AVERAGEIF($E$17:$E$616,$C13,AH$17:AH$616),0) -> 0 | AI13: =IFERROR(AVERAGEIF($E$17:$E$616,$C13,AI$17:AI$616),0) -> 0 | AJ13: =IFERROR(AVERAGEIF($E$17:$E$616,$C13,AJ$17:AJ$616),0) -> 0 | AK13: =IFERROR(AVERAGEIF($E$17:$E$616,$C13,AK$17:AK$616),0) -> 0 | ... AP13: =IFERROR(AVERAGEIF($E$17:$E$616,$C13,AP$17:AP$616),0) -> 0
C15: Accomodation Attributes | L15: GRI PRICING FRAMEWORK | AC15: 45565 | AD15: Monthly rent increase over 12 months (using Grainger growth rate)
A16: Unit Reference | C16: ='1. Accomodation'!N20 -> Door Number | D16: ='1. Accomodation'!L20 -> Block Name | E16: ='1. Accomodation'!P20 -> Bedroom | F16: ='1. Accomodation'!Q20 -> Bath | G16: ='1. Accomodation'!O20 -> Size (sq.ft) | H16: ='1. Accomodation'!R20 -> Floor | I16: ='1. Accomodation'!S20 -> Aspect | L16: ='2. GRI Pricing Inputs'!C16 -> Base Price (£pm) | M16: ='2. GRI Pricing Inputs'!C23 -> Bath Premium | N16: Area Range | O16: ='2. GRI Pricing Inputs'!C32 -> Size premium | P16: ='2. GRI Pricing Inputs'!C46 -> Floor premium | Q16: ='2. GRI Pricing Inputs'!C54 -> Aspect premium | R16: ='2. GRI Pricing Inputs'!C61 -> Storage premium | S16: ='2. GRI Pricing Inputs'!C68 -> Balcony premium | T16: ='2. GRI Pricing Inputs'!C75 -> Amenity premium | U16: ='2. GRI Pricing Inputs'!C83 -> Additional Toilet | V16: ='2. GRI Pricing Inputs'!C90 -> Larger Master Bedroom | W16: ='2. GRI Pricing Inputs'!C98 -> 0 | X16: ='2. GRI Pricing Inputs'!C105 -> 0 | Y16: Manual Adjustment (must provide reason) | Z16: Proposed Rent (pcm) | AD16: =EOMONTH(AC15,1) -> 45596 | AE16: =EOMONTH(AD16,1) -> 45626 | AF16: =EOMONTH(AE16,1) -> 45657 | AG16: =EOMONTH(AF16,1) -> 45688 | AH16: =EOMONTH(AG16,1) -> 45716 | AI16: =EOMONTH(AH16,1) -> 45747 | AJ16: =EOMONTH(AI16,1) -> 45777 | AK16: =EOMONTH(AJ16,1) -> 45808 | AL16: =EOMONTH(AK16,1) -> 45838 | ... AP16: =EOMONTH(AO16,1) -> 45961 | AQ16: Cumulative Annual Growth
A17: =_xlfn.XLOOKUP($C17,'Data Ref'!$D:$D,'Data Ref'!$B:$B,0) -> 222708001 | C17: ='1. Accomodation'!N21 -> 101 | D17: ='1. Accomodation'!L21 -> C | E17: ='1. Accomodation'!P21 -> 1 Bed | F17: ='1. Accomodation'!Q21 -> 1 | G17: ='1. Accomodation'!O21 -> 517.1 | H17: ='1. Accomodation'!R21 -> 1 | I17: ='1. Accomodation'!S21 -> North Row below Treeline | L17: =IFERROR(INDEX('2. GRI Pricing Inputs'!$C$15:$AI$16,MATCH($L$16,'2. GRI Pricing Inputs'!$C$15:$C$16,0),MATCH(E17,'2. GRI Pricing Inputs'!$C$15:$AI$15,0)),0) -> 1275 | M17: =IFERROR(INDEX('2. GRI Pricing Inputs'!$C$22:$AI$23,MATCH($M$16,'2. GRI Pricing Inputs'!$C$22:$C$23,0),MATCH(F17,'2. GRI Pricing Inputs'!$C$22:$AI$22,0)),0) -> 0 | N17: =IF(AND('3. GRI Pricing'!$G17>='2. GRI Pricing Inputs'!$D$33,'3. GRI Pricing'!$G17<='2. GRI Pricing Inputs'!$E$33),'2. GRI Pricing Inputs'!$D$32,IF(AND('3. GRI Pricing'!$G17>='2. GRI Pricing Inputs'!$F$33,'3. GRI Pricing'!$G17<='2. GRI Pricing Inputs'!$G$33),'2. GRI Pricing Inputs'!$F$32,IF(AND('3. GRI Pricing'!$G17>='2. GRI Pricing Inputs'!$H$33,'3. GRI Pricing'!$G17<='2. GRI Pricing Inputs'!$I$33),'2. GRI Pricing Inputs'!$H$32,IF(AND('3. GRI Pricing'!$G17>='2. GRI Pricing Inputs'!$J$33,'3. GRI Pricing'!$G17<='2. GRI Pricing Inputs'!$K$33),'2. GRI Pricing Inputs'!$J$32,IF(AND('3. GRI Pricing'!$G17>='2. GRI Pricing Inputs'!$L$33,'3. GRI Pricing'!$G17<='2. GRI Pricing Inputs'!$M$33),'2. GRI Pricing Inputs'!$L$32,IF(AND('3. GRI Pricing'!$G17>='2. GRI Pricing Inputs'!$N$33,'3. GRI Pricing'!$G17<='2. GRI Pricing Inputs'!$O$33),'2. GRI Pricing Inputs'!$N$32,IF(AND('3. GRI Pricing'!$G17>='2. GRI Pricing Inputs'!$P$33,'3. GRI Pricing'!$G17<='2. GRI Pricing Inputs'!$Q$33),'2. GRI Pricing Inputs'!$P$32,IF(AND('3. GRI Pricing'!$G17>='2. GRI Pricing Inputs'!$R$33,'3. GRI Pricing'!$G17<='2. GRI Pricing Inputs'!$S$33),'2. GRI Pricing Inputs'!$R$32,IF(AND('3. GRI Pricing'!$G17>='2. GRI Pricing Inputs'!$T$33,'3. GRI Pricing'!$G17<='2. GRI Pricing Inputs'!$U$33),'2. GRI Pricing Inputs'!$T$32,IF(AND('3. GRI Pricing'!$G17>='2. GRI Pricing Inputs'!$V$33,'3. GRI Pricing'!$G17<='2. GRI Pricing Inputs'!$W$33),'2. GRI Pricing Inputs'!$V$32,IF(AND('3. GRI Pricing'!$G17>='2. GRI Pricing Inputs'!$X$33,'3. GRI Pricing'!$G17<='2. GRI Pricing Inputs'!$Y$33),'2. GRI Pricing Inputs'!$X$32,IF(AND('3. GRI Pricing'!$G17>='2. GRI Pricing Inputs'!$Z$33,'3. GRI Pricing'!$G17<='2. GRI Pricing Inputs'!$AA$33),'2. GRI Pricing Inputs'!$Z$32,IF(AND('3. GRI Pricing'!$G17>='2. GRI Pricing Inputs'!$AB$33,'3. GRI Pricing'!$G17<='2. GRI Pricing Inputs'!$AC$33),'2. GRI Pricing Inputs'!$AB$32,IF(AND('3. GRI Pricing'!$G17>='2. GRI Pricing Inputs'!$AD$33,'3. GRI Pricing'!$G17<='2. GRI Pricing Inputs'!$AE$33),'2. GRI Pricing Inputs'!$AD$32,IF(AND('3. GRI Pricing'!$G17>='2. GRI Pricing Inputs'!$AF$33,'3. GRI Pricing'!$G17<='2. GRI Pricing Inputs'!$AG$33),'2. GRI Pricing Inputs'!$AF$32,IF(AND('3. GRI Pricing'!$G17>='2. GRI Pricing Inputs'!$AH$33,'3. GRI Pricing'!$G17<='2. GRI Pricing Inputs'!$AI$33),'2. GRI Pricing Inputs'!$AH$32,0)))))))))))))))) -> 6 | O17: {=IFERROR(INDEX('2. GRI Pricing Inputs'!$C$32:$AI$39,MATCH('3. GRI Pricing'!E17,'2. GRI Pricing Inputs'!$C$32:$C$39,0),(MATCH('3. GRI Pricing'!N17,'2. GRI Pricing Inputs'!$D$32:$AI$32,0)+1)),0)} -> 10 | P17: =IFERROR(INDEX('2. GRI Pricing Inputs'!$C$45:$AI$46,MATCH($P$16,'2. GRI Pricing Inputs'!$C$45:$C$46,0),MATCH(H17,'2. GRI Pricing Inputs'!$C$45:$AI$45,0)),0) -> 20 | Q17: =IFERROR(INDEX('2. GRI Pricing Inputs'!$C$53:$AI$54,MATCH('3. GRI Pricing'!$Q$16,'2. GRI Pricing Inputs'!$C$53:$C$54,0),MATCH('3. GRI Pricing'!I17,'2. GRI Pricing Inputs'!$C$53:$AI$53,0)),0) -> 30 | R17: =IFERROR(INDEX('2. GRI Pricing Inputs'!$C$60:$AI$61,MATCH('3. GRI Pricing'!$R$16,'2. GRI Pricing Inputs'!$C$60:$C$61,0),MATCH('1. Accomodation'!T21,'2. GRI Pricing Inputs'!$C$60:$AI$60,0)),0) -> 0 | S17: =IFERROR(INDEX('2. GRI Pricing Inputs'!$C$67:$AI$68,MATCH('3. GRI Pricing'!$S$16,'2. GRI Pricing Inputs'!$C$67:$C$68,0),MATCH('1. Accomodation'!U21,'2. GRI Pricing Inputs'!$C$67:$AI$67,0)),0) -> 30 | T17: =IF(E17=0,0,'2. GRI Pricing Inputs'!$AI$75) -> 0 | U17: =IFERROR(INDEX('2. GRI Pricing Inputs'!$C$82:$AI$83,MATCH('3. GRI Pricing'!$U$16,'2. GRI Pricing Inputs'!$C$82:$C$83,0),MATCH('1. Accomodation'!V21,'2. GRI Pricing Inputs'!$C$82:$AI$82,0)),0) -> 0 | V17: =IFERROR(INDEX('2. GRI Pricing Inputs'!$C$89:$AI$90,MATCH('3. GRI Pricing'!$V$16,'2. GRI Pricing Inputs'!$C$89:$C$90,0),MATCH('1. Accomodation'!W21,'2. GRI Pricing Inputs'!$C$89:$AI$89,0)),0) -> 0 | W17: =IFERROR(INDEX('2. GRI Pricing Inputs'!$C$97:$AI$98,MATCH('3. GRI Pricing'!$W$16,'2. GRI Pricing Inputs'!$C$97:$C$98,0),MATCH('1. Accomodation'!X21,'2. GRI Pricing Inputs'!$C$97:$AI$97,0)),0) -> 0 | X17: =IFERROR(INDEX('2. GRI Pricing Inputs'!$C$104:$AI$105,MATCH('3. GRI Pricing'!$X$16,'2. GRI Pricing Inputs'!$C$104:$C$105,0),MATCH('1. Accomodation'!Y21,'2. GRI Pricing Inputs'!$C$104:$AI$104,0)),0) -> 0 | Z17: =L17+M17+O17+P17+Q17+R17+S17+T17+U17+V17+W17+X17+Y17 -> 1365 | AD17: =Z17*(1+'2. GRI Pricing Inputs'!E$115)^(($AD$16-$AC$15)/365) -> 1371.7719 | AE17: =AD17*(1+'2. GRI Pricing Inputs'!F$115)^((AE$16-AD$16)/365) -> 1378.3574 | AF17: =AE17*(1+'2. GRI Pricing Inputs'!G$115)^((AF$16-AE$16)/365) -> 1385.1956 | AG17: =AF17*(1+'2. GRI Pricing Inputs'!H$115)^((AG$16-AF$16)/365) -> 1392.0678 | AH17: =AG17*(1+'2. GRI Pricing Inputs'!I$115)^((AH$16-AG$16)/365) -> 1398.3042 | AI17: =AH17*(1+'2. GRI Pricing Inputs'!J$115)^((AI$16-AH$16)/365) -> 1405.2413 | AJ17: =AI17*(1+'2. GRI Pricing Inputs'!K$115)^((AJ$16-AI$16)/365) -> 1411.9875 | AK17: =AJ17*(1+'2. GRI Pricing Inputs'!L$115)^((AK$16-AJ$16)/365) -> 1418.9926 | AL17: =AK17*(1+'2. GRI Pricing Inputs'!M$115)^((AL$16-AK$16)/365) -> 1425.8047 | ... AP17: =AO17*(1+'2. GRI Pricing Inputs'!Q$115)^((AP$16-AO$16)/365) -> 1454.0783 | AQ17: =IFERROR(AP17/AD17-1,0) -> 0.06
A18: =_xlfn.XLOOKUP($C18,'Data Ref'!$D:$D,'Data Ref'!$B:$B,0) -> 222708002 | C18: ='1. Accomodation'!N22 -> 102 | D18: ='1. Accomodation'!L22 -> C | E18: ='1. Accomodation'!P22 -> Studio | F18: ='1. Accomodation'!Q22 -> 1 | G18: ='1. Accomodation'!O22 -> 385.46 | H18: ='1. Accomodation'!R22 -> 1 | I18: ='1. Accomodation'!S22 -> Nursery and mixed other buildings | L18: =IFERROR(INDEX('2. GRI Pricing Inputs'!$C$15:$AI$16,MATCH($L$16,'2. GRI Pricing Inputs'!$C$15:$C$16,0),MATCH(E18,'2. GRI Pricing Inputs'!$C$15:$AI$15,0)),0) -> 1175 | M18: =IFERROR(INDEX('2. GRI Pricing Inputs'!$C$22:$AI$23,MATCH($M$16,'2. GRI Pricing Inputs'!$C$22:$C$23,0),MATCH(F18,'2. GRI Pricing Inputs'!$C$22:$AI$22,0)),0) -> 0 | N18: =IF(AND('3. GRI Pricing'!$G18>='2. GRI Pricing Inputs'!$D$33,'3. GRI Pricing'!$G18<='2. GRI Pricing Inputs'!$E$33),'2. GRI Pricing Inputs'!$D$32,IF(AND('3. GRI Pricing'!$G18>='2. GRI Pricing Inputs'!$F$33,'3. GRI Pricing'!$G18<='2. GRI Pricing Inputs'!$G$33),'2. GRI Pricing Inputs'!$F$32,IF(AND('3. GRI Pricing'!$G18>='2. GRI Pricing Inputs'!$H$33,'3. GRI Pricing'!$G18<='2. GRI Pricing Inputs'!$I$33),'2. GRI Pricing Inputs'!$H$32,IF(AND('3. GRI Pricing'!$G18>='2. GRI Pricing Inputs'!$J$33,'3. GRI Pricing'!$G18<='2. GRI Pricing Inputs'!$K$33),'2. GRI Pricing Inputs'!$J$32,IF(AND('3. GRI Pricing'!$G18>='2. GRI Pricing Inputs'!$L$33,'3. GRI Pricing'!$G18<='2. GRI Pricing Inputs'!$M$33),'2. GRI Pricing Inputs'!$L$32,IF(AND('3. GRI Pricing'!$G18>='2. GRI Pricing Inputs'!$N$33,'3. GRI Pricing'!$G18<='2. GRI Pricing Inputs'!$O$33),'2. GRI Pricing Inputs'!$N$32,IF(AND('3. GRI Pricing'!$G18>='2. GRI Pricing Inputs'!$P$33,'3. GRI Pricing'!$G18<='2. GRI Pricing Inputs'!$Q$33),'2. GRI Pricing Inputs'!$P$32,IF(AND('3. GRI Pricing'!$G18>='2. GRI Pricing Inputs'!$R$33,'3. GRI Pricing'!$G18<='2. GRI Pricing Inputs'!$S$33),'2. GRI Pricing Inputs'!$R$32,IF(AND('3. GRI Pricing'!$G18>='2. GRI Pricing Inputs'!$T$33,'3. GRI Pricing'!$G18<='2. GRI Pricing Inputs'!$U$33),'2. GRI Pricing Inputs'!$T$32,IF(AND('3. GRI Pricing'!$G18>='2. GRI Pricing Inputs'!$V$33,'3. GRI Pricing'!$G18<='2. GRI Pricing Inputs'!$W$33),'2. GRI Pricing Inputs'!$V$32,IF(AND('3. GRI Pricing'!$G18>='2. GRI Pricing Inputs'!$X$33,'3. GRI Pricing'!$G18<='2. GRI Pricing Inputs'!$Y$33),'2. GRI Pricing Inputs'!$X$32,IF(AND('3. GRI Pricing'!$G18>='2. GRI Pricing Inputs'!$Z$33,'3. GRI Pricing'!$G18<='2. GRI Pricing Inputs'!$AA$33),'2. GRI Pricing Inputs'!$Z$32,IF(AND('3. GRI Pricing'!$G18>='2. GRI Pricing Inputs'!$AB$33,'3. GRI Pricing'!$G18<='2. GRI Pricing Inputs'!$AC$33),'2. GRI Pricing Inputs'!$AB$32,IF(AND('3. GRI Pricing'!$G18>='2. GRI Pricing Inputs'!$AD$33,'3. GRI Pricing'!$G18<='2. GRI Pricing Inputs'!$AE$33),'2. GRI Pricing Inputs'!$AD$32,IF(AND('3. GRI Pricing'!$G18>='2. GRI Pricing Inputs'!$AF$33,'3. GRI Pricing'!$G18<='2. GRI Pricing Inputs'!$AG$33),'2. GRI Pricing Inputs'!$AF$32,IF(AND('3. GRI Pricing'!$G18>='2. GRI Pricing Inputs'!$AH$33,'3. GRI Pricing'!$G18<='2. GRI Pricing Inputs'!$AI$33),'2. GRI Pricing Inputs'!$AH$32,0)))))))))))))))) -> 1 | O18: {=IFERROR(INDEX('2. GRI Pricing Inputs'!$C$32:$AI$39,MATCH('3. GRI Pricing'!E18,'2. GRI Pricing Inputs'!$C$32:$C$39,0),(MATCH('3. GRI Pricing'!N18,'2. GRI Pricing Inputs'!$D$32:$AI$32,0)+1)),0)} -> 0 | P18: =IFERROR(INDEX('2. GRI Pricing Inputs'!$C$45:$AI$46,MATCH($P$16,'2. GRI Pricing Inputs'!$C$45:$C$46,0),MATCH(H18,'2. GRI Pricing Inputs'!$C$45:$AI$45,0)),0) -> 20 | Q18: =IFERROR(INDEX('2. GRI Pricing Inputs'!$C$53:$AI$54,MATCH('3. GRI Pricing'!$Q$16,'2. GRI Pricing Inputs'!$C$53:$C$54,0),MATCH('3. GRI Pricing'!I18,'2. GRI Pricing Inputs'!$C$53:$AI$53,0)),0) -> 0 | R18: =IFERROR(INDEX('2. GRI Pricing Inputs'!$C$60:$AI$61,MATCH('3. GRI Pricing'!$R$16,'2. GRI Pricing Inputs'!$C$60:$C$61,0),MATCH('1. Accomodation'!T22,'2. GRI Pricing Inputs'!$C$60:$AI$60,0)),0) -> 0 | S18: =IFERROR(INDEX('2. GRI Pricing Inputs'!$C$67:$AI$68,MATCH('3. GRI Pricing'!$S$16,'2. GRI Pricing Inputs'!$C$67:$C$68,0),MATCH('1. Accomodation'!U22,'2. GRI Pricing Inputs'!$C$67:$AI$67,0)),0) -> 0 | T18: =IF(E18=0,0,'2. GRI Pricing Inputs'!$AI$75) -> 0 | U18: =IFERROR(INDEX('2. GRI Pricing Inputs'!$C$82:$AI$83,MATCH('3. GRI Pricing'!$U$16,'2. GRI Pricing Inputs'!$C$82:$C$83,0),MATCH('1. Accomodation'!V22,'2. GRI Pricing Inputs'!$C$82:$AI$82,0)),0) -> 0 | V18: =IFERROR(INDEX('2. GRI Pricing Inputs'!$C$89:$AI$90,MATCH('3. GRI Pricing'!$V$16,'2. GRI Pricing Inputs'!$C$89:$C$90,0),MATCH('1. Accomodation'!W22,'2. GRI Pricing Inputs'!$C$89:$AI$89,0)),0) -> 0 | W18: =IFERROR(INDEX('2. GRI Pricing Inputs'!$C$97:$AI$98,MATCH('3. GRI Pricing'!$W$16,'2. GRI Pricing Inputs'!$C$97:$C$98,0),MATCH('1. Accomodation'!X22,'2. GRI Pricing Inputs'!$C$97:$AI$97,0)),0) -> 0 | X18: =IFERROR(INDEX('2. GRI Pricing Inputs'!$C$104:$AI$105,MATCH('3. GRI Pricing'!$X$16,'2. GRI Pricing Inputs'!$C$104:$C$105,0),MATCH('1. Accomodation'!Y22,'2. GRI Pricing Inputs'!$C$104:$AI$104,0)),0) -> 0 | Z18: =L18+M18+O18+P18+Q18+R18+S18+T18+U18+V18+W18+X18+Y18 -> 1195 | AD18: =Z18*(1+'2. GRI Pricing Inputs'!E$115)^(($AD$16-$AC$15)/365) -> 1200.9286 | AE18: =AD18*(1+'2. GRI Pricing Inputs'!F$115)^((AE$16-AD$16)/365) -> 1206.6939 | AF18: =AE18*(1+'2. GRI Pricing Inputs'!G$115)^((AF$16-AE$16)/365) -> 1212.6804 | AG18: =AF18*(1+'2. GRI Pricing Inputs'!H$115)^((AG$16-AF$16)/365) -> 1218.6967 | AH18: =AG18*(1+'2. GRI Pricing Inputs'!I$115)^((AH$16-AG$16)/365) -> 1224.1564 | AI18: =AH18*(1+'2. GRI Pricing Inputs'!J$115)^((AI$16-AH$16)/365) -> 1230.2296 | AJ18: =AI18*(1+'2. GRI Pricing Inputs'!K$115)^((AJ$16-AI$16)/365) -> 1236.1356 | AK18: =AJ18*(1+'2. GRI Pricing Inputs'!L$115)^((AK$16-AJ$16)/365) -> 1242.2682 | AL18: =AK18*(1+'2. GRI Pricing Inputs'!M$115)^((AL$16-AK$16)/365) -> 1248.232 | ... AP18: =AO18*(1+'2. GRI Pricing Inputs'!Q$115)^((AP$16-AO$16)/365) -> 1272.9843 | AQ18: =IFERROR(AP18/AD18-1,0) -> 0.06
A19: =_xlfn.XLOOKUP($C19,'Data Ref'!$D:$D,'Data Ref'!$B:$B,0) -> 222708003 | C19: ='1. Accomodation'!N23 -> 103 | D19: ='1. Accomodation'!L23 -> C | E19: ='1. Accomodation'!P23 -> Studio | F19: ='1. Accomodation'!Q23 -> 1 | G19: ='1. Accomodation'!O23 -> 394.17 | H19: ='1. Accomodation'!R23 -> 1 | I19: ='1. Accomodation'!S23 -> Nursery and mixed other buildings | L19: =IFERROR(INDEX('2. GRI Pricing Inputs'!$C$15:$AI$16,MATCH($L$16,'2. GRI Pricing Inputs'!$C$15:$C$16,0),MATCH(E19,'2. GRI Pricing Inputs'!$C$15:$AI$15,0)),0) -> 1175 | M19: =IFERROR(INDEX('2. GRI Pricing Inputs'!$C$22:$AI$23,MATCH($M$16,'2. GRI Pricing Inputs'!$C$22:$C$23,0),MATCH(F19,'2. GRI Pricing Inputs'!$C$22:$AI$22,0)),0) -> 0 | N19: =IF(AND('3. GRI Pricing'!$G19>='2. GRI Pricing Inputs'!$D$33,'3. GRI Pricing'!$G19<='2. GRI Pricing Inputs'!$E$33),'2. GRI Pricing Inputs'!$D$32,IF(AND('3. GRI Pricing'!$G19>='2. GRI Pricing Inputs'!$F$33,'3. GRI Pricing'!$G19<='2. GRI Pricing Inputs'!$G$33),'2. GRI Pricing Inputs'!$F$32,IF(AND('3. GRI Pricing'!$G19>='2. GRI Pricing Inputs'!$H$33,'3. GRI Pricing'!$G19<='2. GRI Pricing Inputs'!$I$33),'2. GRI Pricing Inputs'!$H$32,IF(AND('3. GRI Pricing'!$G19>='2. GRI Pricing Inputs'!$J$33,'3. GRI Pricing'!$G19<='2. GRI Pricing Inputs'!$K$33),'2. GRI Pricing Inputs'!$J$32,IF(AND('3. GRI Pricing'!$G19>='2. GRI Pricing Inputs'!$L$33,'3. GRI Pricing'!$G19<='2. GRI Pricing Inputs'!$M$33),'2. GRI Pricing Inputs'!$L$32,IF(AND('3. GRI Pricing'!$G19>='2. GRI Pricing Inputs'!$N$33,'3. GRI Pricing'!$G19<='2. GRI Pricing Inputs'!$O$33),'2. GRI Pricing Inputs'!$N$32,IF(AND('3. GRI Pricing'!$G19>='2. GRI Pricing Inputs'!$P$33,'3. GRI Pricing'!$G19<='2. GRI Pricing Inputs'!$Q$33),'2. GRI Pricing Inputs'!$P$32,IF(AND('3. GRI Pricing'!$G19>='2. GRI Pricing Inputs'!$R$33,'3. GRI Pricing'!$G19<='2. GRI Pricing Inputs'!$S$33),'2. GRI Pricing Inputs'!$R$32,IF(AND('3. GRI Pricing'!$G19>='2. GRI Pricing Inputs'!$T$33,'3. GRI Pricing'!$G19<='2. GRI Pricing Inputs'!$U$33),'2. GRI Pricing Inputs'!$T$32,IF(AND('3. GRI Pricing'!$G19>='2. GRI Pricing Inputs'!$V$33,'3. GRI Pricing'!$G19<='2. GRI Pricing Inputs'!$W$33),'2. GRI Pricing Inputs'!$V$32,IF(AND('3. GRI Pricing'!$G19>='2. GRI Pricing Inputs'!$X$33,'3. GRI Pricing'!$G19<='2. GRI Pricing Inputs'!$Y$33),'2. GRI Pricing Inputs'!$X$32,IF(AND('3. GRI Pricing'!$G19>='2. GRI Pricing Inputs'!$Z$33,'3. GRI Pricing'!$G19<='2. GRI Pricing Inputs'!$AA$33),'2. GRI Pricing Inputs'!$Z$32,IF(AND('3. GRI Pricing'!$G19>='2. GRI Pricing Inputs'!$AB$33,'3. GRI Pricing'!$G19<='2. GRI Pricing Inputs'!$AC$33),'2. GRI Pricing Inputs'!$AB$32,IF(AND('3. GRI Pricing'!$G19>='2. GRI Pricing Inputs'!$AD$33,'3. GRI Pricing'!$G19<='2. GRI Pricing Inputs'!$AE$33),'2. GRI Pricing Inputs'!$AD$32,IF(AND('3. GRI Pricing'!$G19>='2. GRI Pricing Inputs'!$AF$33,'3. GRI Pricing'!$G19<='2. GRI Pricing Inputs'!$AG$33),'2. GRI Pricing Inputs'!$AF$32,IF(AND('3. GRI Pricing'!$G19>='2. GRI Pricing Inputs'!$AH$33,'3. GRI Pricing'!$G19<='2. GRI Pricing Inputs'!$AI$33),'2. GRI Pricing Inputs'!$AH$32,0)))))))))))))))) -> 1 | O19: {=IFERROR(INDEX('2. GRI Pricing Inputs'!$C$32:$AI$39,MATCH('3. GRI Pricing'!E19,'2. GRI Pricing Inputs'!$C$32:$C$39,0),(MATCH('3. GRI Pricing'!N19,'2. GRI Pricing Inputs'!$D$32:$AI$32,0)+1)),0)} -> 0 | P19: =IFERROR(INDEX('2. GRI Pricing Inputs'!$C$45:$AI$46,MATCH($P$16,'2. GRI Pricing Inputs'!$C$45:$C$46,0),MATCH(H19,'2. GRI Pricing Inputs'!$C$45:$AI$45,0)),0) -> 20 | Q19: =IFERROR(INDEX('2. GRI Pricing Inputs'!$C$53:$AI$54,MATCH('3. GRI Pricing'!$Q$16,'2. GRI Pricing Inputs'!$C$53:$C$54,0),MATCH('3. GRI Pricing'!I19,'2. GRI Pricing Inputs'!$C$53:$AI$53,0)),0) -> 0 | R19: =IFERROR(INDEX('2. GRI Pricing Inputs'!$C$60:$AI$61,MATCH('3. GRI Pricing'!$R$16,'2. GRI Pricing Inputs'!$C$60:$C$61,0),MATCH('1. Accomodation'!T23,'2. GRI Pricing Inputs'!$C$60:$AI$60,0)),0) -> 0 | S19: =IFERROR(INDEX('2. GRI Pricing Inputs'!$C$67:$AI$68,MATCH('3. GRI Pricing'!$S$16,'2. GRI Pricing Inputs'!$C$67:$C$68,0),MATCH('1. Accomodation'!U23,'2. GRI Pricing Inputs'!$C$67:$AI$67,0)),0) -> 0 | T19: =IF(E19=0,0,'2. GRI Pricing Inputs'!$AI$75) -> 0 | U19: =IFERROR(INDEX('2. GRI Pricing Inputs'!$C$82:$AI$83,MATCH('3. GRI Pricing'!$U$16,'2. GRI Pricing Inputs'!$C$82:$C$83,0),MATCH('1. Accomodation'!V23,'2. GRI Pricing Inputs'!$C$82:$AI$82,0)),0) -> 0 | V19: =IFERROR(INDEX('2. GRI Pricing Inputs'!$C$89:$AI$90,MATCH('3. GRI Pricing'!$V$16,'2. GRI Pricing Inputs'!$C$89:$C$90,0),MATCH('1. Accomodation'!W23,'2. GRI Pricing Inputs'!$C$89:$AI$89,0)),0) -> 0 | W19: =IFERROR(INDEX('2. GRI Pricing Inputs'!$C$97:$AI$98,MATCH('3. GRI Pricing'!$W$16,'2. GRI Pricing Inputs'!$C$97:$C$98,0),MATCH('1. Accomodation'!X23,'2. GRI Pricing Inputs'!$C$97:$AI$97,0)),0) -> 0 | X19: =IFERROR(INDEX('2. GRI Pricing Inputs'!$C$104:$AI$105,MATCH('3. GRI Pricing'!$X$16,'2. GRI Pricing Inputs'!$C$104:$C$105,0),MATCH('1. Accomodation'!Y23,'2. GRI Pricing Inputs'!$C$104:$AI$104,0)),0) -> 0 | Z19: =L19+M19+O19+P19+Q19+R19+S19+T19+U19+V19+W19+X19+Y19 -> 1195 | AD19: =Z19*(1+'2. GRI Pricing Inputs'!E$115)^(($AD$16-$AC$15)/365) -> 1200.9286 | AE19: =AD19*(1+'2. GRI Pricing Inputs'!F$115)^((AE$16-AD$16)/365) -> 1206.6939 | AF19: =AE19*(1+'2. GRI Pricing Inputs'!G$115)^((AF$16-AE$16)/365) -> 1212.6804 | AG19: =AF19*(1+'2. GRI Pricing Inputs'!H$115)^((AG$16-AF$16)/365) -> 1218.6967 | AH19: =AG19*(1+'2. GRI Pricing Inputs'!I$115)^((AH$16-AG$16)/365) -> 1224.1564 | AI19: =AH19*(1+'2. GRI Pricing Inputs'!J$115)^((AI$16-AH$16)/365) -> 1230.2296 | AJ19: =AI19*(1+'2. GRI Pricing Inputs'!K$115)^((AJ$16-AI$16)/365) -> 1236.1356 | AK19: =AJ19*(1+'2. GRI Pricing Inputs'!L$115)^((AK$16-AJ$16)/365) -> 1242.2682 | AL19: =AK19*(1+'2. GRI Pricing Inputs'!M$115)^((AL$16-AK$16)/365) -> 1248.232 | ... AP19: =AO19*(1+'2. GRI Pricing Inputs'!Q$115)^((AP$16-AO$16)/365) -> 1272.9843 | AQ19: =IFERROR(AP19/AD19-1,0) -> 0.06
A20: =_xlfn.XLOOKUP($C20,'Data Ref'!$D:$D,'Data Ref'!$B:$B,0) -> 222708004 | C20: ='1. Accomodation'!N24 -> 104 | D20: ='1. Accomodation'!L24 -> C | E20: ='1. Accomodation'!P24 -> 1 Bed | F20: ='1. Accomodation'!Q24 -> 1 | G20: ='1. Accomodation'!O24 -> 521.51 | H20: ='1. Accomodation'!R24 -> 1 | I20: ='1. Accomodation'!S24 -> North Row below Treeline | L20: =IFERROR(INDEX('2. GRI Pricing Inputs'!$C$15:$AI$16,MATCH($L$16,'2. GRI Pricing Inputs'!$C$15:$C$16,0),MATCH(E20,'2. GRI Pricing Inputs'!$C$15:$AI$15,0)),0) -> 1275 | M20: =IFERROR(INDEX('2. GRI Pricing Inputs'!$C$22:$AI$23,MATCH($M$16,'2. GRI Pricing Inputs'!$C$22:$C$23,0),MATCH(F20,'2. GRI Pricing Inputs'!$C$22:$AI$22,0)),0) -> 0 | N20: =IF(AND('3. GRI Pricing'!$G20>='2. GRI Pricing Inputs'!$D$33,'3. GRI Pricing'!$G20<='2. GRI Pricing Inputs'!$E$33),'2. GRI Pricing Inputs'!$D$32,IF(AND('3. GRI Pricing'!$G20>='2. GRI Pricing Inputs'!$F$33,'3. GRI Pricing'!$G20<='2. GRI Pricing Inputs'!$G$33),'2. GRI Pricing Inputs'!$F$32,IF(AND('3. GRI Pricing'!$G20>='2. GRI Pricing Inputs'!$H$33,'3. GRI Pricing'!$G20<='2. GRI Pricing Inputs'!$I$33),'2. GRI Pricing Inputs'!$H$32,IF(AND('3. GRI Pricing'!$G20>='2. GRI Pricing Inputs'!$J$33,'3. GRI Pricing'!$G20<='2. GRI Pricing Inputs'!$K$33),'2. GRI Pricing Inputs'!$J$32,IF(AND('3. GRI Pricing'!$G20>='2. GRI Pricing Inputs'!$L$33,'3. GRI Pricing'!$G20<='2. GRI Pricing Inputs'!$M$33),'2. GRI Pricing Inputs'!$L$32,IF(AND('3. GRI Pricing'!$G20>='2. GRI Pricing Inputs'!$N$33,'3. GRI Pricing'!$G20<='2. GRI Pricing Inputs'!$O$33),'2. GRI Pricing Inputs'!$N$32,IF(AND('3. GRI Pricing'!$G20>='2. GRI Pricing Inputs'!$P$33,'3. GRI Pricing'!$G20<='2. GRI Pricing Inputs'!$Q$33),'2. GRI Pricing Inputs'!$P$32,IF(AND('3. GRI Pricing'!$G20>='2. GRI Pricing Inputs'!$R$33,'3. GRI Pricing'!$G20<='2. GRI Pricing Inputs'!$S$33),'2. GRI Pricing Inputs'!$R$32,IF(AND('3. GRI Pricing'!$G20>='2. GRI Pricing Inputs'!$T$33,'3. GRI Pricing'!$G20<='2. GRI Pricing Inputs'!$U$33),'2. GRI Pricing Inputs'!$T$32,IF(AND('3. GRI Pricing'!$G20>='2. GRI Pricing Inputs'!$V$33,'3. GRI Pricing'!$G20<='2. GRI Pricing Inputs'!$W$33),'2. GRI Pricing Inputs'!$V$32,IF(AND('3. GRI Pricing'!$G20>='2. GRI Pricing Inputs'!$X$33,'3. GRI Pricing'!$G20<='2. GRI Pricing Inputs'!$Y$33),'2. GRI Pricing Inputs'!$X$32,IF(AND('3. GRI Pricing'!$G20>='2. GRI Pricing Inputs'!$Z$33,'3. GRI Pricing'!$G20<='2. GRI Pricing Inputs'!$AA$33),'2. GRI Pricing Inputs'!$Z$32,IF(AND('3. GRI Pricing'!$G20>='2. GRI Pricing Inputs'!$AB$33,'3. GRI Pricing'!$G20<='2. GRI Pricing Inputs'!$AC$33),'2. GRI Pricing Inputs'!$AB$32,IF(AND('3. GRI Pricing'!$G20>='2. GRI Pricing Inputs'!$AD$33,'3. GRI Pricing'!$G20<='2. GRI Pricing Inputs'!$AE$33),'2. GRI Pricing Inputs'!$AD$32,IF(AND('3. GRI Pricing'!$G20>='2. GRI Pricing Inputs'!$AF$33,'3. GRI Pricing'!$G20<='2. GRI Pricing Inputs'!$AG$33),'2. GRI Pricing Inputs'!$AF$32,IF(AND('3. GRI Pricing'!$G20>='2. GRI Pricing Inputs'!$AH$33,'3. GRI Pricing'!$G20<='2. GRI Pricing Inputs'!$AI$33),'2. GRI Pricing Inputs'!$AH$32,0)))))))))))))))) -> 6 | O20: {=IFERROR(INDEX('2. GRI Pricing Inputs'!$C$32:$AI$39,MATCH('3. GRI Pricing'!E20,'2. GRI Pricing Inputs'!$C$32:$C$39,0),(MATCH('3. GRI Pricing'!N20,'2. GRI Pricing Inputs'!$D$32:$AI$32,0)+1)),0)} -> 10 | P20: =IFERROR(INDEX('2. GRI Pricing Inputs'!$C$45:$AI$46,MATCH($P$16,'2. GRI Pricing Inputs'!$C$45:$C$46,0),MATCH(H20,'2. GRI Pricing Inputs'!$C$45:$AI$45,0)),0) -> 20 | Q20: =IFERROR(INDEX('2. GRI Pricing Inputs'!$C$53:$AI$54,MATCH('3. GRI Pricing'!$Q$16,'2. GRI Pricing Inputs'!$C$53:$C$54,0),MATCH('3. GRI Pricing'!I20,'2. GRI Pricing Inputs'!$C$53:$AI$53,0)),0) -> 30 | R20: =IFERROR(INDEX('2. GRI Pricing Inputs'!$C$60:$AI$61,MATCH('3. GRI Pricing'!$R$16,'2. GRI Pricing Inputs'!$C$60:$C$61,0),MATCH('1. Accomodation'!T24,'2. GRI Pricing Inputs'!$C$60:$AI$60,0)),0) -> 0 | S20: =IFERROR(INDEX('2. GRI Pricing Inputs'!$C$67:$AI$68,MATCH('3. GRI Pricing'!$S$16,'2. GRI Pricing Inputs'!$C$67:$C$68,0),MATCH('1. Accomodation'!U24,'2. GRI Pricing Inputs'!$C$67:$AI$67,0)),0) -> 30 | T20: =IF(E20=0,0,'2. GRI Pricing Inputs'!$AI$75) -> 0 | U20: =IFERROR(INDEX('2. GRI Pricing Inputs'!$C$82:$AI$83,MATCH('3. GRI Pricing'!$U$16,'2. GRI Pricing Inputs'!$C$82:$C$83,0),MATCH('1. Accomodation'!V24,'2. GRI Pricing Inputs'!$C$82:$AI$82,0)),0) -> 0 | V20: =IFERROR(INDEX('2. GRI Pricing Inputs'!$C$89:$AI$90,MATCH('3. GRI Pricing'!$V$16,'2. GRI Pricing Inputs'!$C$89:$C$90,0),MATCH('1. Accomodation'!W24,'2. GRI Pricing Inputs'!$C$89:$AI$89,0)),0) -> 0 | W20: =IFERROR(INDEX('2. GRI Pricing Inputs'!$C$97:$AI$98,MATCH('3. GRI Pricing'!$W$16,'2. GRI Pricing Inputs'!$C$97:$C$98,0),MATCH('1. Accomodation'!X24,'2. GRI Pricing Inputs'!$C$97:$AI$97,0)),0) -> 0 | X20: =IFERROR(INDEX('2. GRI Pricing Inputs'!$C$104:$AI$105,MATCH('3. GRI Pricing'!$X$16,'2. GRI Pricing Inputs'!$C$104:$C$105,0),MATCH('1. Accomodation'!Y24,'2. GRI Pricing Inputs'!$C$104:$AI$104,0)),0) -> 0 | Z20: =L20+M20+O20+P20+Q20+R20+S20+T20+U20+V20+W20+X20+Y20 -> 1365 | AD20: =Z20*(1+'2. GRI Pricing Inputs'!E$115)^(($AD$16-$AC$15)/365) -> 1371.7719 | AE20: =AD20*(1+'2. GRI Pricing Inputs'!F$115)^((AE$16-AD$16)/365) -> 1378.3574 | AF20: =AE20*(1+'2. GRI Pricing Inputs'!G$115)^((AF$16-AE$16)/365) -> 1385.1956 | AG20: =AF20*(1+'2. GRI Pricing Inputs'!H$115)^((AG$16-AF$16)/365) -> 1392.0678 | AH20: =AG20*(1+'2. GRI Pricing Inputs'!I$115)^((AH$16-AG$16)/365) -> 1398.3042 | AI20: =AH20*(1+'2. GRI Pricing Inputs'!J$115)^((AI$16-AH$16)/365) -> 1405.2413 | AJ20: =AI20*(1+'2. GRI Pricing Inputs'!K$115)^((AJ$16-AI$16)/365) -> 1411.9875 | AK20: =AJ20*(1+'2. GRI Pricing Inputs'!L$115)^((AK$16-AJ$16)/365) -> 1418.9926 | AL20: =AK20*(1+'2. GRI Pricing Inputs'!M$115)^((AL$16-AK$16)/365) -> 1425.8047 | ... AP20: =AO20*(1+'2. GRI Pricing Inputs'!Q$115)^((AP$16-AO$16)/365) -> 1454.0783 | AQ20: =IFERROR(AP20/AD20-1,0) -> 0.06
A21: =_xlfn.XLOOKUP($C21,'Data Ref'!$D:$D,'Data Ref'!$B:$B,0) -> 222708005 | C21: ='1. Accomodation'!N25 -> 105 | D21: ='1. Accomodation'!L25 -> C | E21: ='1. Accomodation'!P25 -> 1 Bed | F21: ='1. Accomodation'!Q25 -> 1 | G21: ='1. Accomodation'!O25 -> 532.49 | H21: ='1. Accomodation'!R25 -> 1 | I21: ='1. Accomodation'!S25 -> North Row below Treeline | L21: =IFERROR(INDEX('2. GRI Pricing Inputs'!$C$15:$AI$16,MATCH($L$16,'2. GRI Pricing Inputs'!$C$15:$C$16,0),MATCH(E21,'2. GRI Pricing Inputs'!$C$15:$AI$15,0)),0) -> 1275 | M21: =IFERROR(INDEX('2. GRI Pricing Inputs'!$C$22:$AI$23,MATCH($M$16,'2. GRI Pricing Inputs'!$C$22:$C$23,0),MATCH(F21,'2. GRI Pricing Inputs'!$C$22:$AI$22,0)),0) -> 0 | N21: =IF(AND('3. GRI Pricing'!$G21>='2. GRI Pricing Inputs'!$D$33,'3. GRI Pricing'!$G21<='2. GRI Pricing Inputs'!$E$33),'2. GRI Pricing Inputs'!$D$32,IF(AND('3. GRI Pricing'!$G21>='2. GRI Pricing Inputs'!$F$33,'3. GRI Pricing'!$G21<='2. GRI Pricing Inputs'!$G$33),'2. GRI Pricing Inputs'!$F$32,IF(AND('3. GRI Pricing'!$G21>='2. GRI Pricing Inputs'!$H$33,'3. GRI Pricing'!$G21<='2. GRI Pricing Inputs'!$I$33),'2. GRI Pricing Inputs'!$H$32,IF(AND('3. GRI Pricing'!$G21>='2. GRI Pricing Inputs'!$J$33,'3. GRI Pricing'!$G21<='2. GRI Pricing Inputs'!$K$33),'2. GRI Pricing Inputs'!$J$32,IF(AND('3. GRI Pricing'!$G21>='2. GRI Pricing Inputs'!$L$33,'3. GRI Pricing'!$G21<='2. GRI Pricing Inputs'!$M$33),'2. GRI Pricing Inputs'!$L$32,IF(AND('3. GRI Pricing'!$G21>='2. GRI Pricing Inputs'!$N$33,'3. GRI Pricing'!$G21<='2. GRI Pricing Inputs'!$O$33),'2. GRI Pricing Inputs'!$N$32,IF(AND('3. GRI Pricing'!$G21>='2. GRI Pricing Inputs'!$P$33,'3. GRI Pricing'!$G21<='2. GRI Pricing Inputs'!$Q$33),'2. GRI Pricing Inputs'!$P$32,IF(AND('3. GRI Pricing'!$G21>='2. GRI Pricing Inputs'!$R$33,'3. GRI Pricing'!$G21<='2. GRI Pricing Inputs'!$S$33),'2. GRI Pricing Inputs'!$R$32,IF(AND('3. GRI Pricing'!$G21>='2. GRI Pricing Inputs'!$T$33,'3. GRI Pricing'!$G21<='2. GRI Pricing Inputs'!$U$33),'2. GRI Pricing Inputs'!$T$32,IF(AND('3. GRI Pricing'!$G21>='2. GRI Pricing Inputs'!$V$33,'3. GRI Pricing'!$G21<='2. GRI Pricing Inputs'!$W$33),'2. GRI Pricing Inputs'!$V$32,IF(AND('3. GRI Pricing'!$G21>='2. GRI Pricing Inputs'!$X$33,'3. GRI Pricing'!$G21<='2. GRI Pricing Inputs'!$Y$33),'2. GRI Pricing Inputs'!$X$32,IF(AND('3. GRI Pricing'!$G21>='2. GRI Pricing Inputs'!$Z$33,'3. GRI Pricing'!$G21<='2. GRI Pricing Inputs'!$AA$33),'2. GRI Pricing Inputs'!$Z$32,IF(AND('3. GRI Pricing'!$G21>='2. GRI Pricing Inputs'!$AB$33,'3. GRI Pricing'!$G21<='2. GRI Pricing Inputs'!$AC$33),'2. GRI Pricing Inputs'!$AB$32,IF(AND('3. GRI Pricing'!$G21>='2. GRI Pricing Inputs'!$AD$33,'3. GRI Pricing'!$G21<='2. GRI Pricing Inputs'!$AE$33),'2. GRI Pricing Inputs'!$AD$32,IF(AND('3. GRI Pricing'!$G21>='2. GRI Pricing Inputs'!$AF$33,'3. GRI Pricing'!$G21<='2. GRI Pricing Inputs'!$AG$33),'2. GRI Pricing Inputs'!$AF$32,IF(AND('3. GRI Pricing'!$G21>='2. GRI Pricing Inputs'!$AH$33,'3. GRI Pricing'!$G21<='2. GRI Pricing Inputs'!$AI$33),'2. GRI Pricing Inputs'!$AH$32,0)))))))))))))))) -> 0 | O21: {=IFERROR(INDEX('2. GRI Pricing Inputs'!$C$32:$AI$39,MATCH('3. GRI Pricing'!E21,'2. GRI Pricing Inputs'!$C$32:$C$39,0),(MATCH('3. GRI Pricing'!N21,'2. GRI Pricing Inputs'!$D$32:$AI$32,0)+1)),0)} -> 0 | P21: =IFERROR(INDEX('2. GRI Pricing Inputs'!$C$45:$AI$46,MATCH($P$16,'2. GRI Pricing Inputs'!$C$45:$C$46,0),MATCH(H21,'2. GRI Pricing Inputs'!$C$45:$AI$45,0)),0) -> 20 | Q21: =IFERROR(INDEX('2. GRI Pricing Inputs'!$C$53:$AI$54,MATCH('3. GRI Pricing'!$Q$16,'2. GRI Pricing Inputs'!$C$53:$C$54,0),MATCH('3. GRI Pricing'!I21,'2. GRI Pricing Inputs'!$C$53:$AI$53,0)),0) -> 30 | R21: =IFERROR(INDEX('2. GRI Pricing Inputs'!$C$60:$AI$61,MATCH('3. GRI Pricing'!$R$16,'2. GRI Pricing Inputs'!$C$60:$C$61,0),MATCH('1. Accomodation'!T25,'2. GRI Pricing Inputs'!$C$60:$AI$60,0)),0) -> 0 | S21: =IFERROR(INDEX('2. GRI Pricing Inputs'!$C$67:$AI$68,MATCH('3. GRI Pricing'!$S$16,'2. GRI Pricing Inputs'!$C$67:$C$68,0),MATCH('1. Accomodation'!U25,'2. GRI Pricing Inputs'!$C$67:$AI$67,0)),0) -> 30 | T21: =IF(E21=0,0,'2. GRI Pricing Inputs'!$AI$75) -> 0 | U21: =IFERROR(INDEX('2. GRI Pricing Inputs'!$C$82:$AI$83,MATCH('3. GRI Pricing'!$U$16,'2. GRI Pricing Inputs'!$C$82:$C$83,0),MATCH('1. Accomodation'!V25,'2. GRI Pricing Inputs'!$C$82:$AI$82,0)),0) -> 0 | V21: =IFERROR(INDEX('2. GRI Pricing Inputs'!$C$89:$AI$90,MATCH('3. GRI Pricing'!$V$16,'2. GRI Pricing Inputs'!$C$89:$C$90,0),MATCH('1. Accomodation'!W25,'2. GRI Pricing Inputs'!$C$89:$AI$89,0)),0) -> 0 | W21: =IFERROR(INDEX('2. GRI Pricing Inputs'!$C$97:$AI$98,MATCH('3. GRI Pricing'!$W$16,'2. GRI Pricing Inputs'!$C$97:$C$98,0),MATCH('1. Accomodation'!X25,'2. GRI Pricing Inputs'!$C$97:$AI$97,0)),0) -> 0 | X21: =IFERROR(INDEX('2. GRI Pricing Inputs'!$C$104:$AI$105,MATCH('3. GRI Pricing'!$X$16,'2. GRI Pricing Inputs'!$C$104:$C$105,0),MATCH('1. Accomodation'!Y25,'2. GRI Pricing Inputs'!$C$104:$AI$104,0)),0) -> 0 | Z21: =L21+M21+O21+P21+Q21+R21+S21+T21+U21+V21+W21+X21+Y21 -> 1355 | AD21: =Z21*(1+'2. GRI Pricing Inputs'!E$115)^(($AD$16-$AC$15)/365) -> 1361.7223 | AE21: =AD21*(1+'2. GRI Pricing Inputs'!F$115)^((AE$16-AD$16)/365) -> 1368.2596 | AF21: =AE21*(1+'2. GRI Pricing Inputs'!G$115)^((AF$16-AE$16)/365) -> 1375.0477 | AG21: =AF21*(1+'2. GRI Pricing Inputs'!H$115)^((AG$16-AF$16)/365) -> 1381.8695 | AH21: =AG21*(1+'2. GRI Pricing Inputs'!I$115)^((AH$16-AG$16)/365) -> 1388.0602 | AI21: =AH21*(1+'2. GRI Pricing Inputs'!J$115)^((AI$16-AH$16)/365) -> 1394.9465 | AJ21: =AI21*(1+'2. GRI Pricing Inputs'!K$115)^((AJ$16-AI$16)/365) -> 1401.6433 | AK21: =AJ21*(1+'2. GRI Pricing Inputs'!L$115)^((AK$16-AJ$16)/365) -> 1408.597 | AL21: =AK21*(1+'2. GRI Pricing Inputs'!M$115)^((AL$16-AK$16)/365) -> 1415.3593 | ... AP21: =AO21*(1+'2. GRI Pricing Inputs'!Q$115)^((AP$16-AO$16)/365) -> 1443.4257 | AQ21: =IFERROR(AP21/AD21-1,0) -> 0.06
