Workbook

Sheet Revision History
B2: Version | C2: Updated By | D2: Methods Affected by Change | E2: Revision Description
B3: V r1.0 | C3: - | E3: Initial release
B4: V r1.1 | C4: Lee Williams | D4: None - Documentation update | E4: Added Outcome status enum list and changed linkedApplicant ID description
B5: V r1.2 | C5: Lee Williams | D5: None - Documentation update | E5: Ameded Outcome Status enum and added applicant Status enum
B6: V r1.3 | C6: Lee Williams | D6: None - Documentation update | E6: Extended description of Cancel Tenancy
B7: V r1.4 | C7: Lee Williams | D7: None - Documentation update | E7: Extended descriptions and minor wording change
B8: V r1.5 | C8: Lee Williams | D8: None - Documentation update | E8: updated response for addApplicant and updated description to cancellation reason enum

Sheet API Services
B3: API Method Name (Link to Request & Response Examples with Data Structure) | C3: Method Version | D3: Method Description | E3: Method URL
B4: Get Authentication Token | C4: 0.1 | D4: Method to acquire an authentication (bearer) token, using the scope (always "standardapiaccess"), along with the provided clientID and Client secret | E4: Swagger - /standardapi/v1/ Postman - https://preprod-auth-service.letalliance.dev/connect/token
B5: CheckConnection | C5: 0.1 | D5: Simple ping method used to check connectivity between Vision+ API server and client with no parameters. As with all methods, if authentication token is missing or invalid, an error will be returned. If the authentication token is valid and the connection is successful, a success true will be returned. | E5: /standardapi/v1/CheckConnection
B6: CreateReferenceWithAllData | C6: 0.1 | D6: As one of the base methods of the Vision+ API, this method is used to create a property, create tenancy on property and add one or more applicants to be referenced in that property, for systems that gather and provide all required applicant data up front. | E6: /standardapi/v1/CreateReferenceWithAllData
B7: CreateReferenceWithInputFromApplicant | C7: 0.1 | D7: As another base methods of the Vision+ API, this method is used to create a property, create tenancy on property and add one or more applicants to be referenced in that property, for systems that require the applicant to fill in their own data. On submission, an email will be sent to any Applicant in the application, with details on how to log on to the Vision+ Portal and complete the required referencing data. | E7: /standardapi/v1/CreateReferenceWithInputFromApplicant
B8: GetApplicantReferenceStatus | C8: 0.1 | D8: This method is used to check the Applicant referencing status of one or more Applicants. | E8: /standardapi/v1/GetApplicantReferenceStatus/{ApplicantID}
B9: GetAgentActiveProducts | C9: 0.1 | D9: This method is used to get the list of products currently available to the agent to use in referencing applications. Using an invalid product code or a product the agent is not authorised for will cause the reference application request to fail and return an error. | E9: /standardapi/v1/GetAgentActiveProducts/{AgentCode}
B10: GetApplicantReferenceReports | C10: 0.1 | D10: This method provides the applicant available assessment reports as a base64 encoded string, which must be saved as PDF file. An interim report will be available if the appliants referencing application is in progress, and a final report will be avaible when the applicants reference application status is completed. | E10: /standardapi/v1/GetApplicantReferenceReports/{ApplicantID}
B11: PostApplicantReferenceDocument | C11: 0.1 | D11: This method is used to upload documents to support the applicant assessment process. Such as identification, proof of income, rent receipts etc. | E11: /standardapi/v1/PostApplicantReferenceDocument
B12: ResendApplicantReferenceLink | C12: 0.1 | D12: Used in conjunction with the references created with the CreateReferenceWithInputFromApplicant call, This method is used to resend the applicant referencing link to the applicant, to complete the required referencing data. This is not required for reference applications started with the CreateReferenceWithAllData call. | E12: ​/api​/workflow​/StandardIntegration​/ResendApplicantReferenceLink
B13: PostApplicantReferenceNote | C13: 0.1 | D13: This method is used to add notes to the applicant assessment. The note field supports free text and can be used to record additional data. | E13: ​/api​/workflow​/StandardIntegration​/PostApplicantReferenceNote
B14: AddApplicantToTenancy | C14: 0.1 | D14: This method is used to add an additional applicant to a tenancy application. It has a applicant type parameter that denotes whether the applicant will be sent a link to fill out the data themselves or that the data will be provided by the client system. | E14: ​/api​/workflow​/StandardIntegration​/AddApplicantToTenancy
B15: CancelApplicantFromTenancy | C15: 0.1 | D15: This method is used to get cancel a specific applicant from a tenancy application associated with the authenticated agent. | E15: ​/api​/workflow​/StandardIntegration​/CancelApplicantFromTenancy
... B20: CreateCompanyReferenceWithInputFromApplicant | C20: 0.1 | D20: As another base methods of the Vision+ API, this method is used to create a company reference with a property, create tenancy on property and add one or more applicants to be referenced in that property, for systems that require the applicant to fill in their own data. On submission, an email will be sent to any Applicant in the application, with details on how to log on to the Vision+ Portal and complete the required referencing data. | E20: ​/api​/workflow​/StandardIntegration​/CreateCompanyReferenceWithInputFromApplicant

Sheet Entity Relationship Model
A1: Entity Relationship Model

Sheet API Data Dictionary
H1: Methods Used
H2: CheckConnection | J2: CreateReferenceWithAllData | L2: CreateReferenceWithInputFromApplicant | N2: GetApplicantReferenceStatus | P2: GetAgentActiveProducts | R2: GetApplicantReferenceReports | T2: PostApplicantReferenceDocument | V2: ResendApplicantReferenceLink | X2: PostApplicantReferenceNote | Z2: AddApplicantToTenancy | AB2: AmendApplicantType | AD2: CancelApplicantFromTenancy | AF2: CancelTenancy | AH2: AmendTenancyDetails | AJ2: AmendApplicantProductType | AL2: CreateCompanyReferenceWithAllData | AN2: CreateCompanyReferenceWithInputFromApplicant
A3: ID | C3: Vision+ API Field Name | D3: Field Type | E3: API Max Field Length | F3: Field Validations | G3: Field Description | H3: Request | I3: Response | J3: Request | K3: Response | L3: Request | M3: Response | N3: Request | O3: Response | P3: Request | Q3: Response | R3: Request | S3: Response | T3: Request | U3: Response | V3: Request | W3: Response | X3: Request | Y3: Response | Z3: Request | AA3: Response | AB3: Request | AC3: Response | AD3: Request | AE3: Response | AF3: Request | AG3: Response | AH3: Request | AI3: Response | AJ3: Request | AK3: Response | AL3: Request | AM3: Response | AN3: Request | AO3: Response
A4: Agent and Tenancy Data
A5: 1 | B5: Agent and Tenancy Data | C5: tenancyID | D5: string | E5: 50 | G5: TenancyID is a unique key value for an Agent Property with Active referencing requests linked to one or more Applicants. An Agent Property may have one or more TenancyID's with simultaneous Applicant reference requests. TenancyID is created through API methods: CreateReferenceWithAllData CreateReferenceWithInputFromApplicant CreateCompanyReferenceWithAllData CreateCompanyReferenceWithInputFromApplicant | K5: X | M5: X | AM5: X
A6: 2 | C6: applicantID | D6: string | E6: 50 | G6: ApplicantID is a unique identifier for a person / Company to be referenced. ApplicantID may be linked to one or more TenancyID's executing in parallel. ApplicantID is created through API Methods: CreateReferenceWithAllData CreateReferenceWithInputFromApplicant CreateCompanyReferenceWithAllData CreateCompanyReferenceWithInputFromApplicant AddApplicantToTenancy | K6: X | M6: X | N6: M | O6: X | R6: M | T6: M | V6: M | X6: M | AM6: X
A7: 3 | C7: agentCode | D7: string | E7: 50 | G7: AgentCode is the Unique Key provided to the Agent when onboarding as a Barbon Customer. An AgentID may be linked to many Properties being managed by that Agent and Each property may be linked to 1 or more TenancyID's. | J7: M | K7: X | L7: M | P7: M | Q7: X | AL7: M | AM7: X
A8: 4 | C8: Product | D8: string | E8: 200 | G8: Product is a return value for Product description for product(s) available and enabled for the API Authenticated Agent. This includes Referencing Products (Ultimate, Express etc..) and Other services such as Insurance products (Rent on Time, Rent Guarantee etc…) and Media and Utilities. | Q8: X | AL8: M
A9: 5 | C9: rentGuarantee | D9: enum - Rent Guarantee | F9: Valid Values 1-4 (See enum definition) | G9: Rent guarantee is an indicator that determines which RG option if any the agent requires | J9: M | L9: M | AL9: M
A10: 6 | C10: tenancyTermMonths | D10: integer | G10: The term of the Tenancy in months (whole months only) | J10: M | L10: M | AL10: M
A11: 7 | C11: monthlyRental | D11: number (double) | F11: number($double) pattern: ^\d*.\d{0,2}$ | G11: The monthly rental cost | J11: M | L11: M | AL11: M
A12: 8 | C12: lettingType | D12: enum - Letting Type | F12: Valid Values 1-3 (See enum definition) | G12: The type of the letting, i.e. rent only or fully managed | J12: M | L12: M | AL12: M
A13: 9 | C13: estimatedMoveInDate | D13: string ($date-time) | F13: DD/MM/YYYY | G13: Estimated date of tenancy start (move in) | J13: M | L13: M | AL13: M
A14: 10 | C14: propertyType | D14: enum - Property Type | F14: Valid Values 1-6 (See enum definition) | G14: The Type of property | J14: M | L14: M | AL14: X
A15: 11 | C15: propertyConstructionPeriod | D15: enum - Property Construction Period | F15: Valid Values 1-9 (See enum definition) | G15: The time period in which the property was built | J15: X | L15: X | AL15: X
A16: 12 | C16: numberOfBedrooms | D16: integer | G16: The count of bedrooms in the property | J16: X | L16: X | AL16: X
A17: 13 | C17: noOfAdultOccupants | D17: integer | G17: Number of Adult occupants (18 or over) | J17: X | L17: X | AL17: X
A18: 14 | C18: noOfChildOccupants | D18: integer | G18: Number of Child Occupants (under 18) | J18: X | L18: X | AL18: X
A19: 15 | B19: Tenancy Address | C19: houseNumber | D19: string | E19: 100 | G19: The number of the property | J19: X | L19: X | AL19: X
A20: 16 | C20: houseName | D20: string | E20: 100 | G20: The name of the property | J20: X | L20: X | AL20: M
A21: 17 | C21: addressLine1 | D21: string | E21: 100 | G21: The first line of the property address | J21: M | L21: M | AL21: M
A22: 18 | C22: addressLine2 | D22: string | E22: 100 | G22: The second line of the property address | J22: x | L22: x | AL22: x
A23: 19 | C23: town | D23: string | E23: 50 | G23: The town in which the property exists | J23: M | L23: M | AL23: M
A24: 20 | C24: postcode | D24: string | E24: 50 | G24: the postcode of the property | J24: M | L24: M | AL24: M
A25: 21 | C25: ukCountryCode | D25: enum - UK Country List | F25: Valid Values 1-4 (See enum definition) | G25: The UK country Code | J25: M | L25: M | AL25: M
A26: Applicant Data (Tenant / Guarantor)
A27: 22 | B27: Tenant Name and Contact Data | C27: ApplicantStatus | D27: enum - Applicant Status | G27: A return value for the tenant's status (using method GetApplicantReferenceStatus) | O27: X
A28: 23 | C28: OutcomeStatus | D28: enum - outcome | G28: A return value for the reference grading status (using method GetApplicantReferenceStatus) | O28: X
A29: 24 | C29: tenantTypeId | D29: enum - Tenant Type | F29: Valid Values 1-4 (See enum definition) | G29: The Type of the Tenant, e.g. lead or Guarantor | J29: M | L29: M | AL29: M
A30: 25 | C30: referenceType | D30: enum - Reference Type | F30: Valid Values 1-2 (See enum definition) | G30: The Type of reference, e.g Full or Express | J30: M | L30: M | AL30: M
A31: 26 | C31: rightToRent | D31: boolean | G31: Use Right to rent product for this reference | J31: M | L31: M | AL31: M
A32: 27 | C32: title | D32: enum - Title | F32: Valid Values 1-7 (See enum definition) | G32: The persons title, e.g. Mr, Mrs, etc. | J32: M | L32: M
A33: 28 | C33: otherTitle | D33: string | E33: 100 | G33: If other is chosen for title, this is a text field to enter the specific title | J33: X | L33: X
A34: 29 | C34: firstName | D34: string | E34: 100 | F34: pattern: ^[a-zA-Z0-9\-' ]*$ | G34: First name, validated against the RegEx pattern | J34: M | L34: M
A35: 30 | C35: middleName | D35: string | E35: 50 | F35: pattern: ^[a-zA-Z0-9\-' ]*$ | G35: Middle name, validated against the RegEx pattern | J35: X | L35: X
A36: 31 | C36: surname | D36: string | E36: 100 | F36: pattern: ^[a-zA-Z0-9\-' ]*$ | G36: Surname name, validated against the RegEx pattern | J36: M | L36: M
A37: 32 | C37: shareOfRent | D37: number (double) | F37: pattern: ^\d*.\d{0,2}$ | G37: GBP value of the applicants share of the rent | J37: M | L37: M | AL37: M
A38: 33 | C38: dateOfBirth | D38: string ($date-time) | F38: DD/MM/YYYY | G38: The date of birth, formatted DD-MM-YYYY | J38: M
A39: 34 | C39: companyName | D39: string | E39: 100 | G39: Name of the company | J39: X | AL39: M
A40: 35 | C40: companyRegistrationNumber | D40: string | E40: 100 | G40: Registration number of the company | J40: X | AL40: M
...

Sheet Enum Countries
B2: Enum Field | C2: Country/Location Code
B3: Description | C3: The country or location - NB. includes legacy options Fields mapped to this enum list include: telephoneCountryID mobileCountryId country landlordContactCountryId landlordMobileCountryId countryOfEmployment employmentRefereeContactCountryID employmentRefereeMobileCountryID accountantContactNoCountryId accountantMobileNoCountryId
B4: Value ID | C4: Value Name | D4: Value Description
B5: 1 | C5: Cyprus
B6: 2 | C6: United Kingdom
B7: 3 | C7: India
B8: 4 | C8: USA
B9: 5 | C9: Andorra
B10: 6 | C10: United Arab Emirates
B11: 7 | C11: Afghanistan
B12: 8 | C12: Antigua and Barbuda
B13: 9 | C13: Anguilla
B14: 10 | C14: Albania
B15: 11 | C15: Armenia
B16: 12 | C16: Netherlands Antilles
... B238: 239 | C238: Zimbabwe

Sheet Enum Short Lists
B3: Enum Field | C3: RentGuarantee
B4: Description | C4: Rent guarantee is a product option in Vision+ that provides a guaranteed payment of rent. The options for the rent guarantee are in the table
B5: Value ID | C5: Value Name | D5: Value Description
B6: 1 | C6: Yes, Annual
B7: 2 | C7: Yes, Monthly
B8: 3 | C8: Tenant Evict Only
B9: 4 | C9: No
B12: Enum Field | C12: Title
B13: Description | C13: This is the name prefix for the tenant. If Other is chosen, a free text field is required to be filled in
B14: Value ID | C14: Value Name | D14: Value Description
B15: 1 | C15: Mr
B16: 2 | C16: Mrs
B17: 3 | C17: Miss
B18: 4 | C18: Dr
B19: 5 | C19: Ms
B20: 6 | C20: Other | D20: Free text field become mandatory
B21: 7 | C21: Mx
B24: Enum Field | C24: PropertyConstructionPeriod
B25: Description | C25: This is a range of years denoting the period in which the property was built
B26: Value ID | C26: Value Name | D26: Value Description
B27: 1 | C27: Pre 1850
B28: 2 | C28: 1850 – 1899
B29: 3 | C29: 1900 – 1919
B30: 4 | C30: 1920 – 1945
B31: 5 | C31: 1946 – 1979
B32: 6 | C32: 1980 – 1990
B33: 7 | C33: 1991 – 2000
B34: 8 | C34: 2001 – 2010
B35: 9 | C35: 2011 +
B38: Enum Field | C38: ? Which field is this in the Create Request
B39: Description | C39: Other name that the tenant has been known by
B40: Value ID | C40: Value Name | D40: Value Description
B41: 1 | C41: Other Name
B42: 2 | C42: Another Name
B45: Enum Field | C45: monthMovedIn
B46: Description | C46: The standard month options
B47: Value ID | C47: Value Name | D47: Value Description
B48: 1 | C48: January
B49: 2 | C49: February
B50: 3 | C50: March
...

Sheet Enum Nationalities
B2: Enum Field | C2: nationality
B3: Description | C3: The country or location - NB includes legacy options
B4: Value ID | C4: Value Name | D4: Value Description
B5: 1 | C5: Afghan
B6: 2 | C6: Albanian
B7: 3 | C7: Algerian
B8: 4 | C8: American
B9: 5 | C9: Andorran
B10: 6 | C10: Angolan
B11: 7 | C11: Anguillan
B12: 8 | C12: Citizen of Antigua and Barbuda
B13: 9 | C13: Argentine
B14: 10 | C14: Armenian
B15: 11 | C15: Australian
B16: 12 | C16: Austrian
... B235: 231 | C235: Zairian

Sheet CreateReferenceWithInputFromApp
A1: SF Mapping Details | B1: SF Field Mapping | C1: CreateReferenceWithInputFromApplicant Example JSON | D1: Vision+ API Field Name | E1: Mandatory Field | F1: Field Type | G1: API Max Field Length | H1: Field Validations | I1: Field Description
C2: Request Example
C3: { | D3: =IF(OR(ISNUMBER(SEARCH("{", C3)),ISNUMBER(SEARCH("[", C3))), "", IFERROR(MID(C3, SEARCH("""", C3) +1, SEARCH("""", C3, SEARCH("""",C3) +1) - SEARCH("""", C3) -1), "")) | E3: =IF(D3="", "", VLOOKUP(D3,'API Data Dictionary'!C:L,10,FALSE)) | F3: =IF(D3="", "", VLOOKUP(D3,'API Data Dictionary'!C:D,2,FALSE)) | G3: =IF(IF(D3="", "", VLOOKUP(D3,'API Data Dictionary'!C:E,3,FALSE))=0, "", IF(D3="", "", VLOOKUP(D3,'API Data Dictionary'!C:E,3,FALSE))) | H3: =IF(IF(D3="", "", VLOOKUP(D3,'API Data Dictionary'!C:F,4,FALSE))=0, "", IF(D3="", "", VLOOKUP(D3,'API Data Dictionary'!C:F,4,FALSE))) | I3: =IF(IF(D3="", "", VLOOKUP(D3,'API Data Dictionary'!C:G,5,FALSE))=0, "", IF(D3="", "", VLOOKUP(D3,'API Data Dictionary'!C:G,5,FALSE)))
B4: Referencing_HL_Auth_Setting__mdt.Agent_Code__c; | C4: "agentCode": "9999", | D4: =IF(OR(ISNUMBER(SEARCH("{", C4)),ISNUMBER(SEARCH("[", C4))), "", IFERROR(MID(C4, SEARCH("""", C4) +1, SEARCH("""", C4, SEARCH("""",C4) +1) - SEARCH("""", C4) -1), "")) -> agentCode | E4: =IF(D4="", "", VLOOKUP(D4,'API Data Dictionary'!C:L,10,FALSE)) -> M | F4: =IF(D4="", "", VLOOKUP(D4,'API Data Dictionary'!C:D,2,FALSE)) -> string | G4: =IF(IF(D4="", "", VLOOKUP(D4,'API Data Dictionary'!C:E,3,FALSE))=0, "", IF(D4="", "", VLOOKUP(D4,'API Data Dictionary'!C:E,3,FALSE))) -> 50 | H4: =IF(IF(D4="", "", VLOOKUP(D4,'API Data Dictionary'!C:F,4,FALSE))=0, "", IF(D4="", "", VLOOKUP(D4,'API Data Dictionary'!C:F,4,FALSE))) | I4: =IF(IF(D4="", "", VLOOKUP(D4,'API Data Dictionary'!C:G,5,FALSE))=0, "", IF(D4="", "", VLOOKUP(D4,'API Data Dictionary'!C:G,5,FALSE))) -> AgentCode is the Unique Key provided to the Agent when onboarding as a Barbon Customer. An AgentID may be linked to many Properties being managed by that Agent and Each property may be linked to 1 or more TenancyID's.
B5: <hard code to 4> | C5: "rentGuarantee": 4, | D5: =IF(OR(ISNUMBER(SEARCH("{", C5)),ISNUMBER(SEARCH("[", C5))), "", IFERROR(MID(C5, SEARCH("""", C5) +1, SEARCH("""", C5, SEARCH("""",C5) +1) - SEARCH("""", C5) -1), "")) -> rentGuarantee | E5: =IF(D5="", "", VLOOKUP(D5,'API Data Dictionary'!C:L,10,FALSE)) -> M | F5: =IF(D5="", "", VLOOKUP(D5,'API Data Dictionary'!C:D,2,FALSE)) -> enum - Rent Guarantee | G5: =IF(IF(D5="", "", VLOOKUP(D5,'API Data Dictionary'!C:E,3,FALSE))=0, "", IF(D5="", "", VLOOKUP(D5,'API Data Dictionary'!C:E,3,FALSE))) | H5: =IF(IF(D5="", "", VLOOKUP(D5,'API Data Dictionary'!C:F,4,FALSE))=0, "", IF(D5="", "", VLOOKUP(D5,'API Data Dictionary'!C:F,4,FALSE))) -> Valid Values 1-4 (See enum definition) | I5: =IF(IF(D5="", "", VLOOKUP(D5,'API Data Dictionary'!C:G,5,FALSE))=0, "", IF(D5="", "", VLOOKUP(D5,'API Data Dictionary'!C:G,5,FALSE))) -> Rent guarantee is an indicator that determines which RG option if any the agent requires
B6: opp.Agreed_Terms__c | C6: "tenancyTermMonths": 12, | D6: =IF(OR(ISNUMBER(SEARCH("{", C6)),ISNUMBER(SEARCH("[", C6))), "", IFERROR(MID(C6, SEARCH("""", C6) +1, SEARCH("""", C6, SEARCH("""",C6) +1) - SEARCH("""", C6) -1), "")) -> tenancyTermMonths | E6: =IF(D6="", "", VLOOKUP(D6,'API Data Dictionary'!C:L,10,FALSE)) -> M | F6: =IF(D6="", "", VLOOKUP(D6,'API Data Dictionary'!C:D,2,FALSE)) -> integer | G6: =IF(IF(D6="", "", VLOOKUP(D6,'API Data Dictionary'!C:E,3,FALSE))=0, "", IF(D6="", "", VLOOKUP(D6,'API Data Dictionary'!C:E,3,FALSE))) | H6: =IF(IF(D6="", "", VLOOKUP(D6,'API Data Dictionary'!C:F,4,FALSE))=0, "", IF(D6="", "", VLOOKUP(D6,'API Data Dictionary'!C:F,4,FALSE))) | I6: =IF(IF(D6="", "", VLOOKUP(D6,'API Data Dictionary'!C:G,5,FALSE))=0, "", IF(D6="", "", VLOOKUP(D6,'API Data Dictionary'!C:G,5,FALSE))) -> The term of the Tenancy in months (whole months only)
B7: opp.Monthly_Price__c | C7: "monthlyRental": 2000, | D7: =IF(OR(ISNUMBER(SEARCH("{", C7)),ISNUMBER(SEARCH("[", C7))), "", IFERROR(MID(C7, SEARCH("""", C7) +1, SEARCH("""", C7, SEARCH("""",C7) +1) - SEARCH("""", C7) -1), "")) -> monthlyRental | E7: =IF(D7="", "", VLOOKUP(D7,'API Data Dictionary'!C:L,10,FALSE)) -> M | F7: =IF(D7="", "", VLOOKUP(D7,'API Data Dictionary'!C:D,2,FALSE)) -> number (double) | G7: =IF(IF(D7="", "", VLOOKUP(D7,'API Data Dictionary'!C:E,3,FALSE))=0, "", IF(D7="", "", VLOOKUP(D7,'API Data Dictionary'!C:E,3,FALSE))) | H7: =IF(IF(D7="", "", VLOOKUP(D7,'API Data Dictionary'!C:F,4,FALSE))=0, "", IF(D7="", "", VLOOKUP(D7,'API Data Dictionary'!C:F,4,FALSE))) -> number($double) pattern: ^\d*.\d{0,2}$ | I7: =IF(IF(D7="", "", VLOOKUP(D7,'API Data Dictionary'!C:G,5,FALSE))=0, "", IF(D7="", "", VLOOKUP(D7,'API Data Dictionary'!C:G,5,FALSE))) -> The monthly rental cost
B8: <hard code to 2> | C8: "lettingType": 1, | D8: =IF(OR(ISNUMBER(SEARCH("{", C8)),ISNUMBER(SEARCH("[", C8))), "", IFERROR(MID(C8, SEARCH("""", C8) +1, SEARCH("""", C8, SEARCH("""",C8) +1) - SEARCH("""", C8) -1), "")) -> lettingType | E8: =IF(D8="", "", VLOOKUP(D8,'API Data Dictionary'!C:L,10,FALSE)) -> M | F8: =IF(D8="", "", VLOOKUP(D8,'API Data Dictionary'!C:D,2,FALSE)) -> enum - Letting Type | G8: =IF(IF(D8="", "", VLOOKUP(D8,'API Data Dictionary'!C:E,3,FALSE))=0, "", IF(D8="", "", VLOOKUP(D8,'API Data Dictionary'!C:E,3,FALSE))) | H8: =IF(IF(D8="", "", VLOOKUP(D8,'API Data Dictionary'!C:F,4,FALSE))=0, "", IF(D8="", "", VLOOKUP(D8,'API Data Dictionary'!C:F,4,FALSE))) -> Valid Values 1-3 (See enum definition) | I8: =IF(IF(D8="", "", VLOOKUP(D8,'API Data Dictionary'!C:G,5,FALSE))=0, "", IF(D8="", "", VLOOKUP(D8,'API Data Dictionary'!C:G,5,FALSE))) -> The type of the letting, i.e. rent only or fully managed
B9: opp.Move_In_Date__c | C9: "estimatedMoveInDate": "2023-04-01T10:55:02.383Z", | D9: =IF(OR(ISNUMBER(SEARCH("{", C9)),ISNUMBER(SEARCH("[", C9))), "", IFERROR(MID(C9, SEARCH("""", C9) +1, SEARCH("""", C9, SEARCH("""",C9) +1) - SEARCH("""", C9) -1), "")) -> estimatedMoveInDate | E9: =IF(D9="", "", VLOOKUP(D9,'API Data Dictionary'!C:L,10,FALSE)) -> M | F9: =IF(D9="", "", VLOOKUP(D9,'API Data Dictionary'!C:D,2,FALSE)) -> string ($date-time) | G9: =IF(IF(D9="", "", VLOOKUP(D9,'API Data Dictionary'!C:E,3,FALSE))=0, "", IF(D9="", "", VLOOKUP(D9,'API Data Dictionary'!C:E,3,FALSE))) | H9: =IF(IF(D9="", "", VLOOKUP(D9,'API Data Dictionary'!C:F,4,FALSE))=0, "", IF(D9="", "", VLOOKUP(D9,'API Data Dictionary'!C:F,4,FALSE))) -> DD/MM/YYYY | I9: =IF(IF(D9="", "", VLOOKUP(D9,'API Data Dictionary'!C:G,5,FALSE))=0, "", IF(D9="", "", VLOOKUP(D9,'API Data Dictionary'!C:G,5,FALSE))) -> Estimated date of tenancy start (move in)
A10: SF Picklist vs Homelet Enums //TODO | B10: <check with HomeLet if we can hard code to "Other"> Referencing_HL_Mapping_Constant__mdt.propertyType = 6 | C10: "propertyType": 1, | D10: =IF(OR(ISNUMBER(SEARCH("{", C10)),ISNUMBER(SEARCH("[", C10))), "", IFERROR(MID(C10, SEARCH("""", C10) +1, SEARCH("""", C10, SEARCH("""",C10) +1) - SEARCH("""", C10) -1), "")) -> propertyType | E10: =IF(D10="", "", VLOOKUP(D10,'API Data Dictionary'!C:L,10,FALSE)) -> M | F10: =IF(D10="", "", VLOOKUP(D10,'API Data Dictionary'!C:D,2,FALSE)) -> enum - Property Type | G10: =IF(IF(D10="", "", VLOOKUP(D10,'API Data Dictionary'!C:E,3,FALSE))=0, "", IF(D10="", "", VLOOKUP(D10,'API Data Dictionary'!C:E,3,FALSE))) | H10: =IF(IF(D10="", "", VLOOKUP(D10,'API Data Dictionary'!C:F,4,FALSE))=0, "", IF(D10="", "", VLOOKUP(D10,'API Data Dictionary'!C:F,4,FALSE))) -> Valid Values 1-6 (See enum definition) | I10: =IF(IF(D10="", "", VLOOKUP(D10,'API Data Dictionary'!C:G,5,FALSE))=0, "", IF(D10="", "", VLOOKUP(D10,'API Data Dictionary'!C:G,5,FALSE))) -> The Type of property
C11: "propertyConstructionPeriod": 4, | D11: =IF(OR(ISNUMBER(SEARCH("{", C11)),ISNUMBER(SEARCH("[", C11))), "", IFERROR(MID(C11, SEARCH("""", C11) +1, SEARCH("""", C11, SEARCH("""",C11) +1) - SEARCH("""", C11) -1), "")) -> propertyConstructionPeriod | E11: =IF(D11="", "", VLOOKUP(D11,'API Data Dictionary'!C:L,10,FALSE)) -> X | F11: =IF(D11="", "", VLOOKUP(D11,'API Data Dictionary'!C:D,2,FALSE)) -> enum - Property Construction Period | G11: =IF(IF(D11="", "", VLOOKUP(D11,'API Data Dictionary'!C:E,3,FALSE))=0, "", IF(D11="", "", VLOOKUP(D11,'API Data Dictionary'!C:E,3,FALSE))) | H11: =IF(IF(D11="", "", VLOOKUP(D11,'API Data Dictionary'!C:F,4,FALSE))=0, "", IF(D11="", "", VLOOKUP(D11,'API Data Dictionary'!C:F,4,FALSE))) -> Valid Values 1-9 (See enum definition) | I11: =IF(IF(D11="", "", VLOOKUP(D11,'API Data Dictionary'!C:G,5,FALSE))=0, "", IF(D11="", "", VLOOKUP(D11,'API Data Dictionary'!C:G,5,FALSE))) -> The time period in which the property was built
B12: opp.Primary_Offer__r.Unit__r.Bedrooms__c | C12: "numberOfBedrooms": 4, | D12: =IF(OR(ISNUMBER(SEARCH("{", C12)),ISNUMBER(SEARCH("[", C12))), "", IFERROR(MID(C12, SEARCH("""", C12) +1, SEARCH("""", C12, SEARCH("""",C12) +1) - SEARCH("""", C12) -1), "")) -> numberOfBedrooms | E12: x | F12: =IF(D12="", "", VLOOKUP(D12,'API Data Dictionary'!C:D,2,FALSE)) -> integer | G12: =IF(IF(D12="", "", VLOOKUP(D12,'API Data Dictionary'!C:E,3,FALSE))=0, "", IF(D12="", "", VLOOKUP(D12,'API Data Dictionary'!C:E,3,FALSE))) | H12: =IF(IF(D12="", "", VLOOKUP(D12,'API Data Dictionary'!C:F,4,FALSE))=0, "", IF(D12="", "", VLOOKUP(D12,'API Data Dictionary'!C:F,4,FALSE))) | I12: =IF(IF(D12="", "", VLOOKUP(D12,'API Data Dictionary'!C:G,5,FALSE))=0, "", IF(D12="", "", VLOOKUP(D12,'API Data Dictionary'!C:G,5,FALSE))) -> The count of bedrooms in the property
B13: opp.Number_of_occupants__c count number of OpportunityContactRole records where role in (Lead Tenant,Tenant,Permitted Occupier) and OpportunityContactRole.Active__c = true | C13: "noOfAdultOccupants": 2, | D13: =IF(OR(ISNUMBER(SEARCH("{", C13)),ISNUMBER(SEARCH("[", C13))), "", IFERROR(MID(C13, SEARCH("""", C13) +1, SEARCH("""", C13, SEARCH("""",C13) +1) - SEARCH("""", C13) -1), "")) -> noOfAdultOccupants | E13: =IF(D13="", "", VLOOKUP(D13,'API Data Dictionary'!C:L,10,FALSE)) -> X | F13: =IF(D13="", "", VLOOKUP(D13,'API Data Dictionary'!C:D,2,FALSE)) -> integer | G13: =IF(IF(D13="", "", VLOOKUP(D13,'API Data Dictionary'!C:E,3,FALSE))=0, "", IF(D13="", "", VLOOKUP(D13,'API Data Dictionary'!C:E,3,FALSE))) | H13: =IF(IF(D13="", "", VLOOKUP(D13,'API Data Dictionary'!C:F,4,FALSE))=0, "", IF(D13="", "", VLOOKUP(D13,'API Data Dictionary'!C:F,4,FALSE))) | I13: =IF(IF(D13="", "", VLOOKUP(D13,'API Data Dictionary'!C:G,5,FALSE))=0, "", IF(D13="", "", VLOOKUP(D13,'API Data Dictionary'!C:G,5,FALSE))) -> Number of Adult occupants (18 or over)
C14: "noOfChildOccupants": 2, | D14: =IF(OR(ISNUMBER(SEARCH("{", C14)),ISNUMBER(SEARCH("[", C14))), "", IFERROR(MID(C14, SEARCH("""", C14) +1, SEARCH("""", C14, SEARCH("""",C14) +1) - SEARCH("""", C14) -1), "")) -> noOfChildOccupants | E14: =IF(D14="", "", VLOOKUP(D14,'API Data Dictionary'!C:L,10,FALSE)) -> X | F14: =IF(D14="", "", VLOOKUP(D14,'API Data Dictionary'!C:D,2,FALSE)) -> integer | G14: =IF(IF(D14="", "", VLOOKUP(D14,'API Data Dictionary'!C:E,3,FALSE))=0, "", IF(D14="", "", VLOOKUP(D14,'API Data Dictionary'!C:E,3,FALSE))) | H14: =IF(IF(D14="", "", VLOOKUP(D14,'API Data Dictionary'!C:F,4,FALSE))=0, "", IF(D14="", "", VLOOKUP(D14,'API Data Dictionary'!C:F,4,FALSE))) | I14: =IF(IF(D14="", "", VLOOKUP(D14,'API Data Dictionary'!C:G,5,FALSE))=0, "", IF(D14="", "", VLOOKUP(D14,'API Data Dictionary'!C:G,5,FALSE))) -> Number of Child Occupants (under 18)
B15: opp.Advance_Paid__c | C15: "isAdvanceRent": false, | D15: =IF(OR(ISNUMBER(SEARCH("{", C15)),ISNUMBER(SEARCH("[", C15))), "", IFERROR(MID(C15, SEARCH("""", C15) +1, SEARCH("""", C15, SEARCH("""",C15) +1) - SEARCH("""", C15) -1), "")) -> isAdvanceRent | E15: x | F15: =IF(D15="", "", VLOOKUP(D15,'API Data Dictionary'!C:D,2,FALSE)) -> boolean | G15: =IF(IF(D15="", "", VLOOKUP(D15,'API Data Dictionary'!C:E,3,FALSE))=0, "", IF(D15="", "", VLOOKUP(D15,'API Data Dictionary'!C:E,3,FALSE))) | H15: =IF(IF(D15="", "", VLOOKUP(D15,'API Data Dictionary'!C:F,4,FALSE))=0, "", IF(D15="", "", VLOOKUP(D15,'API Data Dictionary'!C:F,4,FALSE))) | I15: =IF(IF(D15="", "", VLOOKUP(D15,'API Data Dictionary'!C:G,5,FALSE))=0, "", IF(D15="", "", VLOOKUP(D15,'API Data Dictionary'!C:G,5,FALSE))) -> Denotes whether rent is paid in advance
C16: "propertyAddress": { | D16: =IF(OR(ISNUMBER(SEARCH("{", C16)),ISNUMBER(SEARCH("[", C16))), "", IFERROR(MID(C16, SEARCH("""", C16) +1, SEARCH("""", C16, SEARCH("""",C16) +1) - SEARCH("""", C16) -1), "")) | E16: =IF(D16="", "", VLOOKUP(D16,'API Data Dictionary'!C:L,10,FALSE)) | F16: =IF(D16="", "", VLOOKUP(D16,'API Data Dictionary'!C:D,2,FALSE)) | G16: =IF(IF(D16="", "", VLOOKUP(D16,'API Data Dictionary'!C:E,3,FALSE))=0, "", IF(D16="", "", VLOOKUP(D16,'API Data Dictionary'!C:E,3,FALSE))) | H16: =IF(IF(D16="", "", VLOOKUP(D16,'API Data Dictionary'!C:F,4,FALSE))=0, "", IF(D16="", "", VLOOKUP(D16,'API Data Dictionary'!C:F,4,FALSE))) | I16: =IF(IF(D16="", "", VLOOKUP(D16,'API Data Dictionary'!C:G,5,FALSE))=0, "", IF(D16="", "", VLOOKUP(D16,'API Data Dictionary'!C:G,5,FALSE)))
B17: <Split Primary_Offer__r.Unit__r.Street_Name__c on comma>[2][1][0] | C17: "houseNumber": "Apartment 42", | D17: =IF(OR(ISNUMBER(SEARCH("{", C17)),ISNUMBER(SEARCH("[", C17))), "", IFERROR(MID(C17, SEARCH("""", C17) +1, SEARCH("""", C17, SEARCH("""",C17) +1) - SEARCH("""", C17) -1), "")) -> houseNumber | E17: =IF(D17="", "", VLOOKUP(D17,'API Data Dictionary'!C:L,10,FALSE)) -> X | F17: =IF(D17="", "", VLOOKUP(D17,'API Data Dictionary'!C:D,2,FALSE)) -> string | G17: =IF(IF(D17="", "", VLOOKUP(D17,'API Data Dictionary'!C:E,3,FALSE))=0, "", IF(D17="", "", VLOOKUP(D17,'API Data Dictionary'!C:E,3,FALSE))) -> 100 | H17: =IF(IF(D17="", "", VLOOKUP(D17,'API Data Dictionary'!C:F,4,FALSE))=0, "", IF(D17="", "", VLOOKUP(D17,'API Data Dictionary'!C:F,4,FALSE))) | I17: =IF(IF(D17="", "", VLOOKUP(D17,'API Data Dictionary'!C:G,5,FALSE))=0, "", IF(D17="", "", VLOOKUP(D17,'API Data Dictionary'!C:G,5,FALSE))) -> The number of the property
B18: <Split Primary_Offer__r.Unit__r.Street_Name__c on comma>[1][0] | C18: "houseName": "3 Millet Place", | D18: =IF(OR(ISNUMBER(SEARCH("{", C18)),ISNUMBER(SEARCH("[", C18))), "", IFERROR(MID(C18, SEARCH("""", C18) +1, SEARCH("""", C18, SEARCH("""",C18) +1) - SEARCH("""", C18) -1), "")) -> houseName | E18: =IF(D18="", "", VLOOKUP(D18,'API Data Dictionary'!C:L,10,FALSE)) -> X | F18: =IF(D18="", "", VLOOKUP(D18,'API Data Dictionary'!C:D,2,FALSE)) -> string | G18: =IF(IF(D18="", "", VLOOKUP(D18,'API Data Dictionary'!C:E,3,FALSE))=0, "", IF(D18="", "", VLOOKUP(D18,'API Data Dictionary'!C:E,3,FALSE))) -> 100 | H18: =IF(IF(D18="", "", VLOOKUP(D18,'API Data Dictionary'!C:F,4,FALSE))=0, "", IF(D18="", "", VLOOKUP(D18,'API Data Dictionary'!C:F,4,FALSE))) | I18: =IF(IF(D18="", "", VLOOKUP(D18,'API Data Dictionary'!C:G,5,FALSE))=0, "", IF(D18="", "", VLOOKUP(D18,'API Data Dictionary'!C:G,5,FALSE))) -> The name of the property
B19: <Split Primary_Offer__r.Unit__r.Street_Name__c on comma>[0][0][0] | C19: "addressLine1": "Adlay Apartments", | D19: =IF(OR(ISNUMBER(SEARCH("{", C19)),ISNUMBER(SEARCH("[", C19))), "", IFERROR(MID(C19, SEARCH("""", C19) +1, SEARCH("""", C19, SEARCH("""",C19) +1) - SEARCH("""", C19) -1), "")) -> addressLine1 | E19: =IF(D19="", "", VLOOKUP(D19,'API Data Dictionary'!C:L,10,FALSE)) -> M | F19: =IF(D19="", "", VLOOKUP(D19,'API Data Dictionary'!C:D,2,FALSE)) -> string | G19: =IF(IF(D19="", "", VLOOKUP(D19,'API Data Dictionary'!C:E,3,FALSE))=0, "", IF(D19="", "", VLOOKUP(D19,'API Data Dictionary'!C:E,3,FALSE))) -> 100 | H19: =IF(IF(D19="", "", VLOOKUP(D19,'API Data Dictionary'!C:F,4,FALSE))=0, "", IF(D19="", "", VLOOKUP(D19,'API Data Dictionary'!C:F,4,FALSE))) | I19: =IF(IF(D19="", "", VLOOKUP(D19,'API Data Dictionary'!C:G,5,FALSE))=0, "", IF(D19="", "", VLOOKUP(D19,'API Data Dictionary'!C:G,5,FALSE))) -> The first line of the property address
C20: "addressLine2": "Parkway", | D20: =IF(OR(ISNUMBER(SEARCH("{", C20)),ISNUMBER(SEARCH("[", C20))), "", IFERROR(MID(C20, SEARCH("""", C20) +1, SEARCH("""", C20, SEARCH("""",C20) +1) - SEARCH("""", C20) -1), "")) -> addressLine2 | E20: =IF(D20="", "", VLOOKUP(D20,'API Data Dictionary'!C:L,10,FALSE)) -> x | F20: =IF(D20="", "", VLOOKUP(D20,'API Data Dictionary'!C:D,2,FALSE)) -> string | G20: =IF(IF(D20="", "", VLOOKUP(D20,'API Data Dictionary'!C:E,3,FALSE))=0, "", IF(D20="", "", VLOOKUP(D20,'API Data Dictionary'!C:E,3,FALSE))) -> 100 | H20: =IF(IF(D20="", "", VLOOKUP(D20,'API Data Dictionary'!C:F,4,FALSE))=0, "", IF(D20="", "", VLOOKUP(D20,'API Data Dictionary'!C:F,4,FALSE))) | I20: =IF(IF(D20="", "", VLOOKUP(D20,'API Data Dictionary'!C:G,5,FALSE))=0, "", IF(D20="", "", VLOOKUP(D20,'API Data Dictionary'!C:G,5,FALSE))) -> The second line of the property address
B21: Primary_Offer__r.Unit__r.City__c | C21: "town": "Aberdare", | D21: =IF(OR(ISNUMBER(SEARCH("{", C21)),ISNUMBER(SEARCH("[", C21))), "", IFERROR(MID(C21, SEARCH("""", C21) +1, SEARCH("""", C21, SEARCH("""",C21) +1) - SEARCH("""", C21) -1), "")) -> town | E21: =IF(D21="", "", VLOOKUP(D21,'API Data Dictionary'!C:L,10,FALSE)) -> M | F21: =IF(D21="", "", VLOOKUP(D21,'API Data Dictionary'!C:D,2,FALSE)) -> string | G21: =IF(IF(D21="", "", VLOOKUP(D21,'API Data Dictionary'!C:E,3,FALSE))=0, "", IF(D21="", "", VLOOKUP(D21,'API Data Dictionary'!C:E,3,FALSE))) -> 50 | H21: =IF(IF(D21="", "", VLOOKUP(D21,'API Data Dictionary'!C:F,4,FALSE))=0, "", IF(D21="", "", VLOOKUP(D21,'API Data Dictionary'!C:F,4,FALSE))) | I21: =IF(IF(D21="", "", VLOOKUP(D21,'API Data Dictionary'!C:G,5,FALSE))=0, "", IF(D21="", "", VLOOKUP(D21,'API Data Dictionary'!C:G,5,FALSE))) -> The town in which the property exists
B22: Primary_Offer__r.Unit__r.Post_Code__c | C22: "postcode": "CF44 8BE", | D22: =IF(OR(ISNUMBER(SEARCH("{", C22)),ISNUMBER(SEARCH("[", C22))), "", IFERROR(MID(C22, SEARCH("""", C22) +1, SEARCH("""", C22, SEARCH("""",C22) +1) - SEARCH("""", C22) -1), "")) -> postcode | E22: =IF(D22="", "", VLOOKUP(D22,'API Data Dictionary'!C:L,10,FALSE)) -> M | F22: =IF(D22="", "", VLOOKUP(D22,'API Data Dictionary'!C:D,2,FALSE)) -> string | G22: =IF(IF(D22="", "", VLOOKUP(D22,'API Data Dictionary'!C:E,3,FALSE))=0, "", IF(D22="", "", VLOOKUP(D22,'API Data Dictionary'!C:E,3,FALSE))) -> 50 | H22: =IF(IF(D22="", "", VLOOKUP(D22,'API Data Dictionary'!C:F,4,FALSE))=0, "", IF(D22="", "", VLOOKUP(D22,'API Data Dictionary'!C:F,4,FALSE))) | I22: =IF(IF(D22="", "", VLOOKUP(D22,'API Data Dictionary'!C:G,5,FALSE))=0, "", IF(D22="", "", VLOOKUP(D22,'API Data Dictionary'!C:G,5,FALSE))) -> the postcode of the property
A23: SF Picklist vs Homelet Enums //TODO | B23: <Hard code to 1 for now - will need to address for later when building in Wales goes live> | C23: "ukCountryCode": 3 | D23: =IF(OR(ISNUMBER(SEARCH("{", C23)),ISNUMBER(SEARCH("[", C23))), "", IFERROR(MID(C23, SEARCH("""", C23) +1, SEARCH("""", C23, SEARCH("""",C23) +1) - SEARCH("""", C23) -1), "")) -> ukCountryCode | E23: =IF(D23="", "", VLOOKUP(D23,'API Data Dictionary'!C:L,10,FALSE)) -> M | F23: =IF(D23="", "", VLOOKUP(D23,'API Data Dictionary'!C:D,2,FALSE)) -> enum - UK Country List | G23: =IF(IF(D23="", "", VLOOKUP(D23,'API Data Dictionary'!C:E,3,FALSE))=0, "", IF(D23="", "", VLOOKUP(D23,'API Data Dictionary'!C:E,3,FALSE))) | H23: =IF(IF(D23="", "", VLOOKUP(D23,'API Data Dictionary'!C:F,4,FALSE))=0, "", IF(D23="", "", VLOOKUP(D23,'API Data Dictionary'!C:F,4,FALSE))) -> Valid Values 1-4 (See enum definition) | I23: =IF(IF(D23="", "", VLOOKUP(D23,'API Data Dictionary'!C:G,5,FALSE))=0, "", IF(D23="", "", VLOOKUP(D23,'API Data Dictionary'!C:G,5,FALSE))) -> The UK country Code
C24: }, | D24: =IF(OR(ISNUMBER(SEARCH("{", C24)),ISNUMBER(SEARCH("[", C24))), "", IFERROR(MID(C24, SEARCH("""", C24) +1, SEARCH("""", C24, SEARCH("""",C24) +1) - SEARCH("""", C24) -1), "")) | E24: =IF(D24="", "", VLOOKUP(D24,'API Data Dictionary'!C:L,10,FALSE)) | F24: =IF(D24="", "", VLOOKUP(D24,'API Data Dictionary'!C:D,2,FALSE)) | G24: =IF(IF(D24="", "", VLOOKUP(D24,'API Data Dictionary'!C:E,3,FALSE))=0, "", IF(D24="", "", VLOOKUP(D24,'API Data Dictionary'!C:E,3,FALSE))) | H24: =IF(IF(D24="", "", VLOOKUP(D24,'API Data Dictionary'!C:F,4,FALSE))=0, "", IF(D24="", "", VLOOKUP(D24,'API Data Dictionary'!C:F,4,FALSE))) | I24: =IF(IF(D24="", "", VLOOKUP(D24,'API Data Dictionary'!C:G,5,FALSE))=0, "", IF(D24="", "", VLOOKUP(D24,'API Data Dictionary'!C:G,5,FALSE)))
C25: "tenants": [ | D25: =IF(OR(ISNUMBER(SEARCH("{", C25)),ISNUMBER(SEARCH("[", C25))), "", IFERROR(MID(C25, SEARCH("""", C25) +1, SEARCH("""", C25, SEARCH("""",C25) +1) - SEARCH("""", C25) -1), "")) | E25: =IF(D25="", "", VLOOKUP(D25,'API Data Dictionary'!C:L,10,FALSE)) | F25: =IF(D25="", "", VLOOKUP(D25,'API Data Dictionary'!C:D,2,FALSE)) | G25: =IF(IF(D25="", "", VLOOKUP(D25,'API Data Dictionary'!C:E,3,FALSE))=0, "", IF(D25="", "", VLOOKUP(D25,'API Data Dictionary'!C:E,3,FALSE))) | H25: =IF(IF(D25="", "", VLOOKUP(D25,'API Data Dictionary'!C:F,4,FALSE))=0, "", IF(D25="", "", VLOOKUP(D25,'API Data Dictionary'!C:F,4,FALSE))) | I25: =IF(IF(D25="", "", VLOOKUP(D25,'API Data Dictionary'!C:G,5,FALSE))=0, "", IF(D25="", "", VLOOKUP(D25,'API Data Dictionary'!C:G,5,FALSE)))
C26: { | D26: =IF(OR(ISNUMBER(SEARCH("{", C26)),ISNUMBER(SEARCH("[", C26))), "", IFERROR(MID(C26, SEARCH("""", C26) +1, SEARCH("""", C26, SEARCH("""",C26) +1) - SEARCH("""", C26) -1), "")) | E26: =IF(D26="", "", VLOOKUP(D26,'API Data Dictionary'!C:L,10,FALSE)) | F26: =IF(D26="", "", VLOOKUP(D26,'API Data Dictionary'!C:D,2,FALSE)) | G26: =IF(IF(D26="", "", VLOOKUP(D26,'API Data Dictionary'!C:E,3,FALSE))=0, "", IF(D26="", "", VLOOKUP(D26,'API Data Dictionary'!C:E,3,FALSE))) | H26: =IF(IF(D26="", "", VLOOKUP(D26,'API Data Dictionary'!C:F,4,FALSE))=0, "", IF(D26="", "", VLOOKUP(D26,'API Data Dictionary'!C:F,4,FALSE))) | I26: =IF(IF(D26="", "", VLOOKUP(D26,'API Data Dictionary'!C:G,5,FALSE))=0, "", IF(D26="", "", VLOOKUP(D26,'API Data Dictionary'!C:G,5,FALSE)))
B27: OpportunityContactRole.Role | C27: "tenantTypeId": 1, | D27: =IF(OR(ISNUMBER(SEARCH("{", C27)),ISNUMBER(SEARCH("[", C27))), "", IFERROR(MID(C27, SEARCH("""", C27) +1, SEARCH("""", C27, SEARCH("""",C27) +1) - SEARCH("""", C27) -1), "")) -> tenantTypeId | E27: =IF(D27="", "", VLOOKUP(D27,'API Data Dictionary'!C:L,10,FALSE)) -> M | F27: =IF(D27="", "", VLOOKUP(D27,'API Data Dictionary'!C:D,2,FALSE)) -> enum - Tenant Type | G27: =IF(IF(D27="", "", VLOOKUP(D27,'API Data Dictionary'!C:E,3,FALSE))=0, "", IF(D27="", "", VLOOKUP(D27,'API Data Dictionary'!C:E,3,FALSE))) | H27: =IF(IF(D27="", "", VLOOKUP(D27,'API Data Dictionary'!C:F,4,FALSE))=0, "", IF(D27="", "", VLOOKUP(D27,'API Data Dictionary'!C:F,4,FALSE))) -> Valid Values 1-4 (See enum definition) | I27: =IF(IF(D27="", "", VLOOKUP(D27,'API Data Dictionary'!C:G,5,FALSE))=0, "", IF(D27="", "", VLOOKUP(D27,'API Data Dictionary'!C:G,5,FALSE))) -> The Type of the Tenant, e.g. lead or Guarantor
B28: <hard code to 1> | C28: "referenceType": 1, | D28: =IF(OR(ISNUMBER(SEARCH("{", C28)),ISNUMBER(SEARCH("[", C28))), "", IFERROR(MID(C28, SEARCH("""", C28) +1, SEARCH("""", C28, SEARCH("""",C28) +1) - SEARCH("""", C28) -1), "")) -> referenceType | E28: =IF(D28="", "", VLOOKUP(D28,'API Data Dictionary'!C:L,10,FALSE)) -> M | F28: =IF(D28="", "", VLOOKUP(D28,'API Data Dictionary'!C:D,2,FALSE)) -> enum - Reference Type | G28: =IF(IF(D28="", "", VLOOKUP(D28,'API Data Dictionary'!C:E,3,FALSE))=0, "", IF(D28="", "", VLOOKUP(D28,'API Data Dictionary'!C:E,3,FALSE))) | H28: =IF(IF(D28="", "", VLOOKUP(D28,'API Data Dictionary'!C:F,4,FALSE))=0, "", IF(D28="", "", VLOOKUP(D28,'API Data Dictionary'!C:F,4,FALSE))) -> Valid Values 1-2 (See enum definition) | I28: =IF(IF(D28="", "", VLOOKUP(D28,'API Data Dictionary'!C:G,5,FALSE))=0, "", IF(D28="", "", VLOOKUP(D28,'API Data Dictionary'!C:G,5,FALSE))) -> The Type of reference, e.g Full or Express
B29: contactRole.Right_to_Rent__c | C29: "rightToRent": true, | D29: =IF(OR(ISNUMBER(SEARCH("{", C29)),ISNUMBER(SEARCH("[", C29))), "", IFERROR(MID(C29, SEARCH("""", C29) +1, SEARCH("""", C29, SEARCH("""",C29) +1) - SEARCH("""", C29) -1), "")) -> rightToRent | E29: =IF(D29="", "", VLOOKUP(D29,'API Data Dictionary'!C:L,10,FALSE)) -> M | F29: =IF(D29="", "", VLOOKUP(D29,'API Data Dictionary'!C:D,2,FALSE)) -> boolean | G29: =IF(IF(D29="", "", VLOOKUP(D29,'API Data Dictionary'!C:E,3,FALSE))=0, "", IF(D29="", "", VLOOKUP(D29,'API Data Dictionary'!C:E,3,FALSE))) | H29: =IF(IF(D29="", "", VLOOKUP(D29,'API Data Dictionary'!C:F,4,FALSE))=0, "", IF(D29="", "", VLOOKUP(D29,'API Data Dictionary'!C:F,4,FALSE))) | I29: =IF(IF(D29="", "", VLOOKUP(D29,'API Data Dictionary'!C:G,5,FALSE))=0, "", IF(D29="", "", VLOOKUP(D29,'API Data Dictionary'!C:G,5,FALSE))) -> Use Right to rent product for this reference
B30: contactRole.Contact.Salutation [CMDT to map]. If Salutation is not populated in Salesforce, pass default enum of 6 (other) to HomeLet API. This default should be stored in CMDT. | C30: "title": 1, | D30: =IF(OR(ISNUMBER(SEARCH("{", C30)),ISNUMBER(SEARCH("[", C30))), "", IFERROR(MID(C30, SEARCH("""", C30) +1, SEARCH("""", C30, SEARCH("""",C30) +1) - SEARCH("""", C30) -1), "")) -> title | E30: =IF(D30="", "", VLOOKUP(D30,'API Data Dictionary'!C:L,10,FALSE)) -> M | F30: =IF(D30="", "", VLOOKUP(D30,'API Data Dictionary'!C:D,2,FALSE)) -> enum - Title | G30: =IF(IF(D30="", "", VLOOKUP(D30,'API Data Dictionary'!C:E,3,FALSE))=0, "", IF(D30="", "", VLOOKUP(D30,'API Data Dictionary'!C:E,3,FALSE))) | H30: =IF(IF(D30="", "", VLOOKUP(D30,'API Data Dictionary'!C:F,4,FALSE))=0, "", IF(D30="", "", VLOOKUP(D30,'API Data Dictionary'!C:F,4,FALSE))) -> Valid Values 1-7 (See enum definition) | I30: =IF(IF(D30="", "", VLOOKUP(D30,'API Data Dictionary'!C:G,5,FALSE))=0, "", IF(D30="", "", VLOOKUP(D30,'API Data Dictionary'!C:G,5,FALSE))) -> The persons title, e.g. Mr, Mrs, etc.
B31: If contactRole.Contact.Salutation is null, default to "Please Specify" via CMDT | C31: "otherTitle": "", | D31: =IF(OR(ISNUMBER(SEARCH("{", C31)),ISNUMBER(SEARCH("[", C31))), "", IFERROR(MID(C31, SEARCH("""", C31) +1, SEARCH("""", C31, SEARCH("""",C31) +1) - SEARCH("""", C31) -1), "")) -> otherTitle | E31: =IF(D31="", "", VLOOKUP(D31,'API Data Dictionary'!C:L,10,FALSE)) -> X | F31: =IF(D31="", "", VLOOKUP(D31,'API Data Dictionary'!C:D,2,FALSE)) -> string | G31: =IF(IF(D31="", "", VLOOKUP(D31,'API Data Dictionary'!C:E,3,FALSE))=0, "", IF(D31="", "", VLOOKUP(D31,'API Data Dictionary'!C:E,3,FALSE))) -> 100 | H31: =IF(IF(D31="", "", VLOOKUP(D31,'API Data Dictionary'!C:F,4,FALSE))=0, "", IF(D31="", "", VLOOKUP(D31,'API Data Dictionary'!C:F,4,FALSE))) | I31: =IF(IF(D31="", "", VLOOKUP(D31,'API Data Dictionary'!C:G,5,FALSE))=0, "", IF(D31="", "", VLOOKUP(D31,'API Data Dictionary'!C:G,5,FALSE))) -> If other is chosen for title, this is a text field to enter the specific title
B32: contactRole.Contact.FirstName | C32: "firstName": "Berty", | D32: =IF(OR(ISNUMBER(SEARCH("{", C32)),ISNUMBER(SEARCH("[", C32))), "", IFERROR(MID(C32, SEARCH("""", C32) +1, SEARCH("""", C32, SEARCH("""",C32) +1) - SEARCH("""", C32) -1), "")) -> firstName | E32: =IF(D32="", "", VLOOKUP(D32,'API Data Dictionary'!C:L,10,FALSE)) -> M | F32: =IF(D32="", "", VLOOKUP(D32,'API Data Dictionary'!C:D,2,FALSE)) -> string | G32: =IF(IF(D32="", "", VLOOKUP(D32,'API Data Dictionary'!C:E,3,FALSE))=0, "", IF(D32="", "", VLOOKUP(D32,'API Data Dictionary'!C:E,3,FALSE))) -> 100 | H32: =IF(IF(D32="", "", VLOOKUP(D32,'API Data Dictionary'!C:F,4,FALSE))=0, "", IF(D32="", "", VLOOKUP(D32,'API Data Dictionary'!C:F,4,FALSE))) -> pattern: ^[a-zA-Z0-9\-' ]*$ | I32: =IF(IF(D32="", "", VLOOKUP(D32,'API Data Dictionary'!C:G,5,FALSE))=0, "", IF(D32="", "", VLOOKUP(D32,'API Data Dictionary'!C:G,5,FALSE))) -> First name, validated against the RegEx pattern
C33: "middleName": "Boo", | D33: =IF(OR(ISNUMBER(SEARCH("{", C33)),ISNUMBER(SEARCH("[", C33))), "", IFERROR(MID(C33, SEARCH("""", C33) +1, SEARCH("""", C33, SEARCH("""",C33) +1) - SEARCH("""", C33) -1), "")) -> middleName | E33: =IF(D33="", "", VLOOKUP(D33,'API Data Dictionary'!C:L,10,FALSE)) -> X | F33: =IF(D33="", "", VLOOKUP(D33,'API Data Dictionary'!C:D,2,FALSE)) -> string | G33: =IF(IF(D33="", "", VLOOKUP(D33,'API Data Dictionary'!C:E,3,FALSE))=0, "", IF(D33="", "", VLOOKUP(D33,'API Data Dictionary'!C:E,3,FALSE))) -> 50 | H33: =IF(IF(D33="", "", VLOOKUP(D33,'API Data Dictionary'!C:F,4,FALSE))=0, "", IF(D33="", "", VLOOKUP(D33,'API Data Dictionary'!C:F,4,FALSE))) -> pattern: ^[a-zA-Z0-9\-' ]*$ | I33: =IF(IF(D33="", "", VLOOKUP(D33,'API Data Dictionary'!C:G,5,FALSE))=0, "", IF(D33="", "", VLOOKUP(D33,'API Data Dictionary'!C:G,5,FALSE))) -> Middle name, validated against the RegEx pattern
B34: contactRole.Contact.LastName | C34: "surname": "Basset", | D34: =IF(OR(ISNUMBER(SEARCH("{", C34)),ISNUMBER(SEARCH("[", C34))), "", IFERROR(MID(C34, SEARCH("""", C34) +1, SEARCH("""", C34, SEARCH("""",C34) +1) - SEARCH("""", C34) -1), "")) -> surname | E34: =IF(D34="", "", VLOOKUP(D34,'API Data Dictionary'!C:L,10,FALSE)) -> M | F34: =IF(D34="", "", VLOOKUP(D34,'API Data Dictionary'!C:D,2,FALSE)) -> string | G34: =IF(IF(D34="", "", VLOOKUP(D34,'API Data Dictionary'!C:E,3,FALSE))=0, "", IF(D34="", "", VLOOKUP(D34,'API Data Dictionary'!C:E,3,FALSE))) -> 100 | H34: =IF(IF(D34="", "", VLOOKUP(D34,'API Data Dictionary'!C:F,4,FALSE))=0, "", IF(D34="", "", VLOOKUP(D34,'API Data Dictionary'!C:F,4,FALSE))) -> pattern: ^[a-zA-Z0-9\-' ]*$ | I34: =IF(IF(D34="", "", VLOOKUP(D34,'API Data Dictionary'!C:G,5,FALSE))=0, "", IF(D34="", "", VLOOKUP(D34,'API Data Dictionary'!C:G,5,FALSE))) -> Surname name, validated against the RegEx pattern
B35: contactRole.Direct_Debit_Amount__c | C35: "shareOfRent": 600, | D35: =IF(OR(ISNUMBER(SEARCH("{", C35)),ISNUMBER(SEARCH("[", C35))), "", IFERROR(MID(C35, SEARCH("""", C35) +1, SEARCH("""", C35, SEARCH("""",C35) +1) - SEARCH("""", C35) -1), "")) -> shareOfRent | E35: =IF(D35="", "", VLOOKUP(D35,'API Data Dictionary'!C:L,10,FALSE)) -> M | F35: =IF(D35="", "", VLOOKUP(D35,'API Data Dictionary'!C:D,2,FALSE)) -> number (double) | G35: =IF(IF(D35="", "", VLOOKUP(D35,'API Data Dictionary'!C:E,3,FALSE))=0, "", IF(D35="", "", VLOOKUP(D35,'API Data Dictionary'!C:E,3,FALSE))) | H35: =IF(IF(D35="", "", VLOOKUP(D35,'API Data Dictionary'!C:F,4,FALSE))=0, "", IF(D35="", "", VLOOKUP(D35,'API Data Dictionary'!C:F,4,FALSE))) -> pattern: ^\d*.\d{0,2}$ | I35: =IF(IF(D35="", "", VLOOKUP(D35,'API Data Dictionary'!C:G,5,FALSE))=0, "", IF(D35="", "", VLOOKUP(D35,'API Data Dictionary'!C:G,5,FALSE))) -> GBP value of the applicants share of the rent
B36: <hard code to 2> Referencing_HL_Mapping_Constant__mdt.telephoneCountryID = 2 | C36: "telephoneCountryID": 2, | D36: =IF(OR(ISNUMBER(SEARCH("{", C36)),ISNUMBER(SEARCH("[", C36))), "", IFERROR(MID(C36, SEARCH("""", C36) +1, SEARCH("""", C36, SEARCH("""",C36) +1) - SEARCH("""", C36) -1), "")) -> telephoneCountryID | E36: =IF(D36="", "", VLOOKUP(D36,'API Data Dictionary'!C:L,10,FALSE)) -> M | F36: =IF(D36="", "", VLOOKUP(D36,'API Data Dictionary'!C:D,2,FALSE)) -> enum -Country/Location Code | G36: =IF(IF(D36="", "", VLOOKUP(D36,'API Data Dictionary'!C:E,3,FALSE))=0, "", IF(D36="", "", VLOOKUP(D36,'API Data Dictionary'!C:E,3,FALSE))) | H36: =IF(IF(D36="", "", VLOOKUP(D36,'API Data Dictionary'!C:F,4,FALSE))=0, "", IF(D36="", "", VLOOKUP(D36,'API Data Dictionary'!C:F,4,FALSE))) -> Valid Values 1-239 (See enum definition) | I36: =IF(IF(D36="", "", VLOOKUP(D36,'API Data Dictionary'!C:G,5,FALSE))=0, "", IF(D36="", "", VLOOKUP(D36,'API Data Dictionary'!C:G,5,FALSE))) -> The country/location code of the phone number
B37: contactRole.Contact.MobilePhone | C37: "contactTelephoneNo": "01234567891", | D37: =IF(OR(ISNUMBER(SEARCH("{", C37)),ISNUMBER(SEARCH("[", C37))), "", IFERROR(MID(C37, SEARCH("""", C37) +1, SEARCH("""", C37, SEARCH("""",C37) +1) - SEARCH("""", C37) -1), "")) -> contactTelephoneNo | E37: =IF(D37="", "", VLOOKUP(D37,'API Data Dictionary'!C:L,10,FALSE)) -> M | F37: =IF(D37="", "", VLOOKUP(D37,'API Data Dictionary'!C:D,2,FALSE)) -> string | G37: =IF(IF(D37="", "", VLOOKUP(D37,'API Data Dictionary'!C:E,3,FALSE))=0, "", IF(D37="", "", VLOOKUP(D37,'API Data Dictionary'!C:E,3,FALSE))) -> 15 | H37: =IF(IF(D37="", "", VLOOKUP(D37,'API Data Dictionary'!C:F,4,FALSE))=0, "", IF(D37="", "", VLOOKUP(D37,'API Data Dictionary'!C:F,4,FALSE))) -> pattern: ^(\d{11})$ | I37: =IF(IF(D37="", "", VLOOKUP(D37,'API Data Dictionary'!C:G,5,FALSE))=0, "", IF(D37="", "", VLOOKUP(D37,'API Data Dictionary'!C:G,5,FALSE))) -> The telephone number
B38: contactRole.Contact.Email | C38: "emailAddress": "test@testtesttest.test" | D38: =IF(OR(ISNUMBER(SEARCH("{", C38)),ISNUMBER(SEARCH("[", C38))), "", IFERROR(MID(C38, SEARCH("""", C38) +1, SEARCH("""", C38, SEARCH("""",C38) +1) - SEARCH("""", C38) -1), "")) -> emailAddress | E38: =IF(D38="", "", VLOOKUP(D38,'API Data Dictionary'!C:L,10,FALSE)) -> M | F38: =IF(D38="", "", VLOOKUP(D38,'API Data Dictionary'!C:D,2,FALSE)) -> string ($email) | G38: =IF(IF(D38="", "", VLOOKUP(D38,'API Data Dictionary'!C:E,3,FALSE))=0, "", IF(D38="", "", VLOOKUP(D38,'API Data Dictionary'!C:E,3,FALSE))) -> 200 | H38: =IF(IF(D38="", "", VLOOKUP(D38,'API Data Dictionary'!C:F,4,FALSE))=0, "", IF(D38="", "", VLOOKUP(D38,'API Data Dictionary'!C:F,4,FALSE))) -> pattern: ^(?!.*\.\.)(?!.*\\_\\_)(?!.*\-\-)[a-zA-Z0-9][-a-zA-Z0-9._]+[a-zA-Z0-9]@([-a-zA-Z0-9]+.)+[a-zA-Z]{2,5}$ | I38: =IF(IF(D38="", "", VLOOKUP(D38,'API Data Dictionary'!C:G,5,FALSE))=0, "", IF(D38="", "", VLOOKUP(D38,'API Data Dictionary'!C:G,5,FALSE))) -> The email address
C39: } | D39: =IF(OR(ISNUMBER(SEARCH("{", C39)),ISNUMBER(SEARCH("[", C39))), "", IFERROR(MID(C39, SEARCH("""", C39) +1, SEARCH("""", C39, SEARCH("""",C39) +1) - SEARCH("""", C39) -1), "")) | E39: =IF(D39="", "", VLOOKUP(D39,'API Data Dictionary'!C:L,10,FALSE)) | F39: =IF(D39="", "", VLOOKUP(D39,'API Data Dictionary'!C:D,2,FALSE)) | G39: =IF(IF(D39="", "", VLOOKUP(D39,'API Data Dictionary'!C:E,3,FALSE))=0, "", IF(D39="", "", VLOOKUP(D39,'API Data Dictionary'!C:E,3,FALSE))) | H39: =IF(IF(D39="", "", VLOOKUP(D39,'API Data Dictionary'!C:F,4,FALSE))=0, "", IF(D39="", "", VLOOKUP(D39,'API Data Dictionary'!C:F,4,FALSE))) | I39: =IF(IF(D39="", "", VLOOKUP(D39,'API Data Dictionary'!C:G,5,FALSE))=0, "", IF(D39="", "", VLOOKUP(D39,'API Data Dictionary'!C:G,5,FALSE)))
C40: ] | D40: =IF(OR(ISNUMBER(SEARCH("{", C40)),ISNUMBER(SEARCH("[", C40))), "", IFERROR(MID(C40, SEARCH("""", C40) +1, SEARCH("""", C40, SEARCH("""",C40) +1) - SEARCH("""", C40) -1), "")) | E40: =IF(D40="", "", VLOOKUP(D40,'API Data Dictionary'!C:L,10,FALSE)) | F40: =IF(D40="", "", VLOOKUP(D40,'API Data Dictionary'!C:D,2,FALSE)) | G40: =IF(IF(D40="", "", VLOOKUP(D40,'API Data Dictionary'!C:E,3,FALSE))=0, "", IF(D40="", "", VLOOKUP(D40,'API Data Dictionary'!C:E,3,FALSE))) | H40: =IF(IF(D40="", "", VLOOKUP(D40,'API Data Dictionary'!C:F,4,FALSE))=0, "", IF(D40="", "", VLOOKUP(D40,'API Data Dictionary'!C:F,4,FALSE))) | I40: =IF(IF(D40="", "", VLOOKUP(D40,'API Data Dictionary'!C:G,5,FALSE))=0, "", IF(D40="", "", VLOOKUP(D40,'API Data Dictionary'!C:G,5,FALSE)))
...

Sheet AddApplicantToTenancy
A1: Mapping Details | B1: SF Field Mapping | C1: AddApplicantToTenancy Example JSON | D1: Vision+ API Field Name | E1: Mandatory Field | F1: Field Type | G1: API Max Field Length | H1: Field Validations | I1: Field Description
C3: With Applicant Input Link Example Request | D3: =IF(OR(ISNUMBER(SEARCH("{", C3)),ISNUMBER(SEARCH("[", C3))), "", IFERROR(MID(C3, SEARCH("""", C3) +1, SEARCH("""", C3, SEARCH("""",C3) +1) - SEARCH("""", C3) -1), "")) | E3: =IF(D3="", "", VLOOKUP(D3,'API Data Dictionary'!C:L,10,FALSE)) | F3: =IF(D3="", "", VLOOKUP(D3,'API Data Dictionary'!C:D,2,FALSE)) | G3: =IF(IF(D3="", "", VLOOKUP(D3,'API Data Dictionary'!C:E,3,FALSE))=0, "", IF(D3="", "", VLOOKUP(D3,'API Data Dictionary'!C:E,3,FALSE))) | H3: =IF(IF(D3="", "", VLOOKUP(D3,'API Data Dictionary'!C:F,4,FALSE))=0, "", IF(D3="", "", VLOOKUP(D3,'API Data Dictionary'!C:F,4,FALSE))) | I3: =IF(IF(D3="", "", VLOOKUP(D3,'API Data Dictionary'!C:G,5,FALSE))=0, "", IF(D3="", "", VLOOKUP(D3,'API Data Dictionary'!C:G,5,FALSE)))
C4: { | D4: =IF(OR(ISNUMBER(SEARCH("{", C4)),ISNUMBER(SEARCH("[", C4))), "", IFERROR(MID(C4, SEARCH("""", C4) +1, SEARCH("""", C4, SEARCH("""",C4) +1) - SEARCH("""", C4) -1), "")) | E4: =IF(D4="", "", VLOOKUP(D4,'API Data Dictionary'!C:L,10,FALSE)) | F4: =IF(D4="", "", VLOOKUP(D4,'API Data Dictionary'!C:D,2,FALSE)) | G4: =IF(IF(D4="", "", VLOOKUP(D4,'API Data Dictionary'!C:E,3,FALSE))=0, "", IF(D4="", "", VLOOKUP(D4,'API Data Dictionary'!C:E,3,FALSE))) | H4: =IF(IF(D4="", "", VLOOKUP(D4,'API Data Dictionary'!C:F,4,FALSE))=0, "", IF(D4="", "", VLOOKUP(D4,'API Data Dictionary'!C:F,4,FALSE))) | I4: =IF(IF(D4="", "", VLOOKUP(D4,'API Data Dictionary'!C:G,5,FALSE))=0, "", IF(D4="", "", VLOOKUP(D4,'API Data Dictionary'!C:G,5,FALSE)))
B5: Referencing_HL_Auth_Setting__mdt.Agent_Code__c; | C5: "agentCode": "string", | D5: =IF(OR(ISNUMBER(SEARCH("{", C5)),ISNUMBER(SEARCH("[", C5))), "", IFERROR(MID(C5, SEARCH("""", C5) +1, SEARCH("""", C5, SEARCH("""",C5) +1) - SEARCH("""", C5) -1), "")) -> agentCode | E5: =IF(D5="", "", VLOOKUP(D5,'API Data Dictionary'!C:L,10,FALSE)) -> M | F5: =IF(D5="", "", VLOOKUP(D5,'API Data Dictionary'!C:D,2,FALSE)) -> string | G5: =IF(IF(D5="", "", VLOOKUP(D5,'API Data Dictionary'!C:E,3,FALSE))=0, "", IF(D5="", "", VLOOKUP(D5,'API Data Dictionary'!C:E,3,FALSE))) -> 50 | H5: =IF(IF(D5="", "", VLOOKUP(D5,'API Data Dictionary'!C:F,4,FALSE))=0, "", IF(D5="", "", VLOOKUP(D5,'API Data Dictionary'!C:F,4,FALSE))) | I5: =IF(IF(D5="", "", VLOOKUP(D5,'API Data Dictionary'!C:G,5,FALSE))=0, "", IF(D5="", "", VLOOKUP(D5,'API Data Dictionary'!C:G,5,FALSE))) -> AgentCode is the Unique Key provided to the Agent when onboarding as a Barbon Customer. An AgentID may be linked to many Properties being managed by that Agent and Each property may be linked to 1 or more TenancyID's.
B6: opp.Referencing_Property_Tenancy_Id__c | C6: "propertyTenancyId": 0, | D6: =IF(OR(ISNUMBER(SEARCH("{", C6)),ISNUMBER(SEARCH("[", C6))), "", IFERROR(MID(C6, SEARCH("""", C6) +1, SEARCH("""", C6, SEARCH("""",C6) +1) - SEARCH("""", C6) -1), "")) -> propertyTenancyId | E6: M | F6: =IF(D6="", "", VLOOKUP(D6,'API Data Dictionary'!C:D,2,FALSE)) -> integer | G6: =IF(IF(D6="", "", VLOOKUP(D6,'API Data Dictionary'!C:E,3,FALSE))=0, "", IF(D6="", "", VLOOKUP(D6,'API Data Dictionary'!C:E,3,FALSE))) | H6: =IF(IF(D6="", "", VLOOKUP(D6,'API Data Dictionary'!C:F,4,FALSE))=0, "", IF(D6="", "", VLOOKUP(D6,'API Data Dictionary'!C:F,4,FALSE))) | I6: =IF(IF(D6="", "", VLOOKUP(D6,'API Data Dictionary'!C:G,5,FALSE))=0, "", IF(D6="", "", VLOOKUP(D6,'API Data Dictionary'!C:G,5,FALSE))) -> The ID of the property tenancy
B7: <hard code to false> Referencing_HL_Mapping_Constant__mdt.isSentTenantLink | C7: "isSentTenantLink": true, | D7: =IF(OR(ISNUMBER(SEARCH("{", C7)),ISNUMBER(SEARCH("[", C7))), "", IFERROR(MID(C7, SEARCH("""", C7) +1, SEARCH("""", C7, SEARCH("""",C7) +1) - SEARCH("""", C7) -1), "")) -> isSentTenantLink | E7: M | F7: =IF(D7="", "", VLOOKUP(D7,'API Data Dictionary'!C:D,2,FALSE)) -> boolean | G7: =IF(IF(D7="", "", VLOOKUP(D7,'API Data Dictionary'!C:E,3,FALSE))=0, "", IF(D7="", "", VLOOKUP(D7,'API Data Dictionary'!C:E,3,FALSE))) | H7: =IF(IF(D7="", "", VLOOKUP(D7,'API Data Dictionary'!C:F,4,FALSE))=0, "", IF(D7="", "", VLOOKUP(D7,'API Data Dictionary'!C:F,4,FALSE))) | I7: =IF(IF(D7="", "", VLOOKUP(D7,'API Data Dictionary'!C:G,5,FALSE))=0, "", IF(D7="", "", VLOOKUP(D7,'API Data Dictionary'!C:G,5,FALSE))) -> Denotes whether the Tentant link is sent
C8: "linkedApplicantID": [ | D8: linkedApplicantID | E8: x | F8: =IF(D8="", "", VLOOKUP(D8,'API Data Dictionary'!C:D,2,FALSE)) -> integer | G8: =IF(IF(D8="", "", VLOOKUP(D8,'API Data Dictionary'!C:E,3,FALSE))=0, "", IF(D8="", "", VLOOKUP(D8,'API Data Dictionary'!C:E,3,FALSE))) | H8: =IF(IF(D8="", "", VLOOKUP(D8,'API Data Dictionary'!C:F,4,FALSE))=0, "", IF(D8="", "", VLOOKUP(D8,'API Data Dictionary'!C:F,4,FALSE))) | I8: =IF(IF(D8="", "", VLOOKUP(D8,'API Data Dictionary'!C:G,5,FALSE))=0, "", IF(D8="", "", VLOOKUP(D8,'API Data Dictionary'!C:G,5,FALSE))) -> The ID of the linked applicant
B9: <hard code to leave blank> | C9: 0 | D9: =IF(OR(ISNUMBER(SEARCH("{", C9)),ISNUMBER(SEARCH("[", C9))), "", IFERROR(MID(C9, SEARCH("""", C9) +1, SEARCH("""", C9, SEARCH("""",C9) +1) - SEARCH("""", C9) -1), "")) | E9: =IF(D9="", "", VLOOKUP(D9,'API Data Dictionary'!C:L,10,FALSE)) | F9: =IF(D9="", "", VLOOKUP(D9,'API Data Dictionary'!C:D,2,FALSE)) | G9: =IF(IF(D9="", "", VLOOKUP(D9,'API Data Dictionary'!C:E,3,FALSE))=0, "", IF(D9="", "", VLOOKUP(D9,'API Data Dictionary'!C:E,3,FALSE))) | H9: =IF(IF(D9="", "", VLOOKUP(D9,'API Data Dictionary'!C:F,4,FALSE))=0, "", IF(D9="", "", VLOOKUP(D9,'API Data Dictionary'!C:F,4,FALSE))) | I9: Can be blank
C10: ], | D10: =IF(OR(ISNUMBER(SEARCH("{", C10)),ISNUMBER(SEARCH("[", C10))), "", IFERROR(MID(C10, SEARCH("""", C10) +1, SEARCH("""", C10, SEARCH("""",C10) +1) - SEARCH("""", C10) -1), "")) | E10: =IF(D10="", "", VLOOKUP(D10,'API Data Dictionary'!C:L,10,FALSE)) | F10: =IF(D10="", "", VLOOKUP(D10,'API Data Dictionary'!C:D,2,FALSE)) | G10: =IF(IF(D10="", "", VLOOKUP(D10,'API Data Dictionary'!C:E,3,FALSE))=0, "", IF(D10="", "", VLOOKUP(D10,'API Data Dictionary'!C:E,3,FALSE))) | H10: =IF(IF(D10="", "", VLOOKUP(D10,'API Data Dictionary'!C:F,4,FALSE))=0, "", IF(D10="", "", VLOOKUP(D10,'API Data Dictionary'!C:F,4,FALSE))) | I10: =IF(IF(D10="", "", VLOOKUP(D10,'API Data Dictionary'!C:G,5,FALSE))=0, "", IF(D10="", "", VLOOKUP(D10,'API Data Dictionary'!C:G,5,FALSE)))
C11: "tenantTypeId": 1, | D11: =IF(OR(ISNUMBER(SEARCH("{", C11)),ISNUMBER(SEARCH("[", C11))), "", IFERROR(MID(C11, SEARCH("""", C11) +1, SEARCH("""", C11, SEARCH("""",C11) +1) - SEARCH("""", C11) -1), "")) -> tenantTypeId | E11: =IF(D11="", "", VLOOKUP(D11,'API Data Dictionary'!C:L,10,FALSE)) -> M | F11: =IF(D11="", "", VLOOKUP(D11,'API Data Dictionary'!C:D,2,FALSE)) -> enum - Tenant Type | G11: =IF(IF(D11="", "", VLOOKUP(D11,'API Data Dictionary'!C:E,3,FALSE))=0, "", IF(D11="", "", VLOOKUP(D11,'API Data Dictionary'!C:E,3,FALSE))) | H11: =IF(IF(D11="", "", VLOOKUP(D11,'API Data Dictionary'!C:F,4,FALSE))=0, "", IF(D11="", "", VLOOKUP(D11,'API Data Dictionary'!C:F,4,FALSE))) -> Valid Values 1-4 (See enum definition) | I11: =IF(IF(D11="", "", VLOOKUP(D11,'API Data Dictionary'!C:G,5,FALSE))=0, "", IF(D11="", "", VLOOKUP(D11,'API Data Dictionary'!C:G,5,FALSE))) -> The Type of the Tenant, e.g. lead or Guarantor
C12: "referenceType": 1, | D12: =IF(OR(ISNUMBER(SEARCH("{", C12)),ISNUMBER(SEARCH("[", C12))), "", IFERROR(MID(C12, SEARCH("""", C12) +1, SEARCH("""", C12, SEARCH("""",C12) +1) - SEARCH("""", C12) -1), "")) -> referenceType | E12: =IF(D12="", "", VLOOKUP(D12,'API Data Dictionary'!C:L,10,FALSE)) -> M | F12: =IF(D12="", "", VLOOKUP(D12,'API Data Dictionary'!C:D,2,FALSE)) -> enum - Reference Type | G12: =IF(IF(D12="", "", VLOOKUP(D12,'API Data Dictionary'!C:E,3,FALSE))=0, "", IF(D12="", "", VLOOKUP(D12,'API Data Dictionary'!C:E,3,FALSE))) | H12: =IF(IF(D12="", "", VLOOKUP(D12,'API Data Dictionary'!C:F,4,FALSE))=0, "", IF(D12="", "", VLOOKUP(D12,'API Data Dictionary'!C:F,4,FALSE))) -> Valid Values 1-2 (See enum definition) | I12: =IF(IF(D12="", "", VLOOKUP(D12,'API Data Dictionary'!C:G,5,FALSE))=0, "", IF(D12="", "", VLOOKUP(D12,'API Data Dictionary'!C:G,5,FALSE))) -> The Type of reference, e.g Full or Express
