Workbook

Sheet Version History
A1: Date | B1: Version | C1: Author | D1: Comments
A2: 44645 | B2: 1.0 | C2: Phil Cullum | D2: Created based on mapping doc CP-CORE-02_NominalCodeUpserted_CP-CORE-04 EntityUpserted_Mapping v1.29 (3.10).xlsx and review of current GREP implementation
A3: 44649 | B3: 1.1 | C3: Phil Cullum | D3: Corrected mapping logic around creation of Accounts for commercial and residential tenants

Sheet Qube to Salesforce
A1: Data Mapping | B1: CP-CORE-02/CP-CORE-04
A2: Sending Interface system | B2: MRI
A3: Outbound Data Structure | B3: XML
A4: Receiving Interface system 2 | B4: Concept Evolution
A5: Inbound Data Structure 2 | B5: XML
A6: Title | B6: ChartsOfAccountsUpserted/NominalUpserted
A8: Source -Qube | C8: XML Element / Attribute | D8: Mandatory/Optional | E8: Type | F8: Size | G8: Sample Data | H8: Transformation rule/logic | I8: Canonical | J8: Destination - Salesforce | L8: JSON Element | M8: Transformation rule/logic
A9: Table | B9: Source API | J9: Table | K9: Destination Object
K10: Call order: 1.UpsertEstate 2.UpsertBuilding 3.UpsertUnit 4.Upsert Account 5.Upsert Contact (commercial tenants) 6.Upsert Opportunity 7.Upsert OpportunityContactRole
B11: Qube Buildings, Units and Tenants | C11: <building><reference> | E11: String | F11: 12 | G11: 222485 | H11: Direct | I11: <EntityListing><EntityID> | K11: Building | L11: Id | M11: Look up Salesforce Building ID from GREP XREF using <EntityListing><EntityID>
K12: Unit | L12: Building__c
K13: Building | L13: Estate__c | M13: Look up Salesforce Estate ID from GREP XREF using <EntityListing><EntityID>
B14: Qube Buildings, Units and Tenants | C14: <building><name> | E14: String | F14: 30 | H14: Direct | I14: <EntityListing><EntityName> | K14: Building | L14: Building/Name | M14: Direct
B15: Qube Buildings, Units and Tenants | C15: <building><legalowner><reference> | H15: Direct | I15: <EntityListing><LegalOwner><entry><OwnerID> | K15: Unit | L15: SUN__c | M15: Refer to the Owner ID table and match <EntityListing><LegalOwner><entry><OwnerID> with the Salesforce value. Note: Values configured in QuickConnect ref data SalesforceData list, key Mapping|MRIOwnerId|[OwnerID]
B16: Qube Buildings, Units and Tenants | C16: <building><legalowner><name> | H16: Direct | I16: <EntityListing><LegalOwner><entry><OwnerName> | K16: Unit | L16: Landlord_Name__c | M16: Direct
B17: Qube Buildings, Units and Tenants | C17: <building><legalowner><address1> | H17: Direct | I17: <EntityListing><LegalOwner><entry><OwnerAddress1> | K17: Unit | L17: Landlord_Street__c | M17: Direct
B18: Qube Buildings, Units and Tenants | C18: <building><legalowner><city> | H18: Direct | I18: <EntityListing><LegalOwner><entry><OwnerCity> | K18: Unit | L18: Landlord_City__c | M18: Direct
H19: NOT MAPPED | I19: <EntityListing><LegalOwner><entry><OwnerState> | K19: Unit | L19: Landlord_County__c | M19: Direct
B20: Qube Buildings, Units and Tenants | C20: <building><legalowner><postcode> | H20: Direct | I20: <EntityListing><LegalOwner><entry><OwnerZip> | K20: Unit | L20: Landlord_Zip_Postal_Code__c | M20: Direct
B21: Qube Buildings, Units and Tenants | C21: <building><property-status> | E21: String | G21: Active | H21: If <property-status> = Active Send Y else send N | I21: <EntityListing><ACTIVE> | J21: NOT MAPPED
B22: Qube Buildings, Units and Tenants | C22: <building><building-tenure> | E22: String | G22: AST | H22: Direct | I22: <EntityListing><TenureTypeDesc> | J22: NOT MAPPED
B23: Qube Buildings, Units and Tenants | C23: <building><purchase-date> | D23: Optional | E23: date | H23: Send as dd-mm-yyyy | I23: <EntityListing><DateAquired> | J23: NOT MAPPED
B24: Qube Buildings, Units and Tenants | C24: <building><asset><code> | E24: String | H24: If code = 1 Investment then send Y, else if code = 2 then Send N for Trading otherwise send blank NOTE: If InvestmentOnly is blank do NOT send Building, Units or Tenants to any downstream system (FSI, Proactis, Salesforce, Customer Portal) | I24: <EntityListing><InvestmentOnly> | J24: NOT MAPPED
B25: Qube Buildings, Units and Tenants | C25: <building><asset><region> | D25: Optional | E25: String | F25: 49 | H25: Direct | I25: <EntityListing><RegionDesc>
B26: Qube Buildings, Units and Tenants | C26: <building><asset><fund> | D26: Optional | E26: String | F26: 49 | H26: Direct | I26: <EntityListing><ClientDesc> | K26: Unit | L26: Unit/Fund__c | M26: Direct
B27: Qube Buildings, Units and Tenants | C27: <building><estate><name> | H27: Direct | I27: <EntityListing><ProjectName> | K27: Estate | L27: Estate/Name | M27: Direct
B28: Qube Buildings, Units and Tenants | C28: <building><asset><portfolio-id> | E28: String | F28: 49 | H28: Direct | I28: <EntityListing><PortfolioID> | K28: Unit | L28: Portfolio__c | M28: Direct
B29: Qube Buildings, Units and Tenants | C29: <building><address1> | E29: String | F29: 45 | H29: Direct | I29: <EntityListing><SHIPADR1> | J29: NOT MAPPED
B30: Qube Buildings, Units and Tenants | C30: <building><address2> | E30: String | F30: 45 | H30: Direct | I30: <EntityListing><SHIPADR2> | J30: NOT MAPPED
B31: Qube Buildings, Units and Tenants | C31: <building><address3> | E31: String | F31: 45 | H31: Direct | I31: <EntityListing><SHIPADR3> | J31: NOT MAPPED
B32: Qube Buildings, Units and Tenants | C32: <building><address4> <building><city> | E32: String | F32: 45 | H32: If address4 is specified map address4 otherwise map city | I32: <EntityListing><SHIPCITY> | K32: Building | L32: City__c | M32: Direct
B33: Qube Buildings, Units and Tenants | C33: <building><address5> | E33: String | F33: 45 | H33: Direct | I33: <EntityListing><SHIPST> | J33: NOT MAPPED
B34: Qube Buildings, Units and Tenants | C34: <building><postcode> | E34: String | F34: 45 | H34: Direct | I34: <EntityListing><SHIPZIP> | J34: NOT MAPPED
B35: Qube Buildings, Units and Tenants | C35: <building><prop-type> | E35: String | H35: If specified then map direct otherwise send MIXED USE | I35: <EntityListing><PropertyType> | J35: NOT MAPPED
H36: Refer to the Property Type table and match <building><prop-type> with the canonical code. Note: Values configured in QuickConnect ref data QubeCOA list, key Mapping|PropertyType|[prop-type] | I36: <EntityListing><EntityType> | J36: NOT MAPPED
B37: Qube Buildings, Units and Tenants | C37: <units><unit><reference> | D37: Mandatory | E37: String | F37: 30 | G37: 222485035 | H37: Parse the first 6 digits and add an hypen and send i.e. convert 222485035 to 222485-035 | I37: <EntityListing><UnitReference><entry><UnitRef> | K37: Contract | L37: Unit__c | M37: Use the UnitRef to find the Salesforce Unit id value from the XREF.
K38: Unit | L38: Id | M38: Use the UnitRef to find the Salesforce Unit id value from the XREF.
B39: Qube Buildings, Units and Tenants | C39: <units><unit><description> | D39: Mandatory | E39: String | F39: 50 | G39: Flat 602, Indigoblu | H39: Direct | I39: <EntityListing><UnitReference><entry><Description> | K39: Unit | L39: Name | M39: Direct
B40: Qube Buildings, Units and Tenants | C40: <units><unit><address1> | H40: Direct | I40: <EntityListing><UnitReference><entry><AddressLine1> | K40: Unit | L40: Street_Name__c | M40: Direct
B41: Qube Buildings, Units and Tenants | C41: <units><unit><postcode> | H41: Direct | I41: <EntityListing><UnitReference><entry><UnitPostCode> | K41: Unit | L41: Post_Code__c | M41: Direct
...

Sheet Unit Type
A1: Qube | B1: Canonical
A2: Advertising | B2: AD
A3: Allotment | B3: AL
A4: Bedsit | B4: BE
A5: Choose Type | B5: DU
A6: Commercial | B6: CM
A7: COMMERCIAL | B7: CM
A8: Det House | B8: DH
A9: DetBungalow | B9: DB
A10: DEVELOPMENT | B10: DEV
A11: Dummy | B11: DU
A12: End Terrace | B12: EH
... A49: Woodland | B49: WO

Sheet Unit Status Code
A1: Qube Unit Status Code | B1: Canonical | C1: Salesforce Live Unit Status Code | D1: Canonical Description
A2: UnderConstr | B2: OTUC | C2: Awaiting handover | D2: =VLOOKUP(A2,'Unit Status Description'!A:B,2,FALSE) -> Under Construction
A3: For Let | B3: OTFL | C3: Future Vacant | D3: =VLOOKUP(A3,'Unit Status Description'!A:B,2,FALSE) -> For Let
A4: Potent Vacant | B4: OTPV | C4: Future Vacant | D4: =VLOOKUP(A4,'Unit Status Description'!A:B,2,FALSE) -> Potentially Vacant
A5: Refresh | B5: OTRE | C5: Future Vacant | D5: =VLOOKUP(A5,'Unit Status Description'!A:B,2,FALSE) -> Refresh
A6: Tenanted | B6: OTTE | C6: Leased | D6: =VLOOKUP(A6,'Unit Status Description'!A:B,2,FALSE) -> Tenanted
A7: AwaitDecision | B7: SAWD | C7: Property to be sold | D7: =VLOOKUP(A7,'Unit Status Description'!A:B,2,FALSE) -> Sales - Await Decision
A8: Awaiting Rpt | B8: SFOR | C8: Property to be sold | D8: =VLOOKUP(A8,'Unit Status Description'!A:B,2,FALSE) -> For Sale
A9: AwaitingOffer | B9: SFOR | C9: Property to be sold | D9: =VLOOKUP(A9,'Unit Status Description'!A:B,2,FALSE) -> For Sale
A10: Completed | B10: SSEX | C10: Property to be sold | D10: =VLOOKUP(A10,'Unit Status Description'!A:B,2,FALSE) -> Sales-Contracts Exchanged
A11: Contracts Xch | B11: SSEX | C11: Property to be sold | D11: =VLOOKUP(A11,'Unit Status Description'!A:B,2,FALSE) -> Sales-Contracts Exchanged
A12: For Sale | B12: SFOR | C12: Property to be sold | D12: =VLOOKUP(A12,'Unit Status Description'!A:B,2,FALSE) -> For Sale
A13: GRIPSALE | B13: SOLD | C13: Property to be sold | D13: =VLOOKUP(A13,'Unit Status Description'!A:B,2,FALSE) -> Sales-Sold
... A25: Vacant | B25: OTNL | C25: Void | D25: =VLOOKUP(A25,'Unit Status Description'!A:B,2,FALSE) -> Not Lettable
A26: Dummy | B26: OTDU | D26: =VLOOKUP(A26,'Unit Status Description'!A:B,2,FALSE) -> Dummy
A27: NTU | B27: NTU | D27: =VLOOKUP(A27,'Unit Status Description'!A:B,2,FALSE) -> NTU

Sheet Unit Status Description
A1: Qube Unit Status Code | B1: Canonical Description
A2: AwaitDecision | B2: Sales - Await Decision
A3: Awaiting Rpt | B3: For Sale
A4: AwaitingOffer | B4: For Sale
A5: Completed | B5: Sales-Contracts Exchanged
A6: Contracts Xch | B6: Sales-Contracts Exchanged
A7: Dummy | B7: Dummy
A8: For Let | B8: For Let
A9: For Sale | B9: For Sale
A10: GRIPSALE | B10: Sales-Sold
A11: Insurance | B11: Not Lettable
A12: Negotiation | B12: Sales-Solicitor Instruction
... A27: Valuation | B27: For Sale

Sheet Tenant Status
A2: Tenant Status from Qube | B2: Canonical | C2: Tenant Status to FSI
A3: At Legal-Curr | B3: C | C3: ACTIVE
A4: At Legal-Prev | B4: O | C4: INACTIVE
A5: Current | B5: C | C5: ACTIVE
A6: FallThrough | B6: I | C6: INACTIVE
A7: Future | B7: N | C7: INACTIVE
A8: Holding Over | B8: O | C8: ACTIVE
A9: In Breach | B9: O | C9: ACTIVE
A10: Insurance | B10: I | C10: ACTIVE
A11: Negotiation | B11: A | C11: INACTIVE
A12: ntu | B12: I | C12: INACTIVE
A13: Payment Plan | B13: C | C13: ACTIVE
... A17: Transfer | B17: O | C17: INACTIVE

Sheet Tenure Type
A1: Qube Unit Tenure Type | B1: Canonical MRI Tenure Type | C1: Salesforce Tenure Type | D1: Canonical Description
A2: Aff Rent | B2: AFF | C2: Live Unit | D2: =VLOOKUP(A2,'Tenure Type Description'!A:B,2,FALSE) -> AST Affordable
A3: AHA (Agr) | B3: AGP | C3: Live Unit | D3: =VLOOKUP(A3,'Tenure Type Description'!A:B,2,FALSE) -> Agricultural Protected Statutory
A4: Assd PHA | B4: ASH | C4: Live Unit | D4: =VLOOKUP(A4,'Tenure Type Description'!A:B,2,FALSE) -> Assured-Paignton Housing Association
A5: Assd.Per | B5: ASS | C5: Live Unit | D5: =VLOOKUP(A5,'Tenure Type Description'!A:B,2,FALSE) -> ASSURED- Statutory Periodic
A6: Assured | B6: ASS | C6: Live Unit | D6: =VLOOKUP(A6,'Tenure Type Description'!A:B,2,FALSE) -> Assured
A7: AST | B7: AST | C7: Live Unit | D7: =VLOOKUP(A7,'Tenure Type Description'!A:B,2,FALSE) -> Assured Shorthold Tenancy
A8: AST Chc | B8: ACC | C8: Live Unit | D8: =VLOOKUP(A8,'Tenure Type Description'!A:B,2,FALSE) -> AST Church Commissioners
A9: AST KW | B9: ASK | C9: Live Unit | D9: =VLOOKUP(A9,'Tenure Type Description'!A:B,2,FALSE) -> AST-Keyworkers
A10: AST Per | B10: ASP | C10: Live Unit | D10: =VLOOKUP(A10,'Tenure Type Description'!A:B,2,FALSE) -> AST- Statutory Periodic
A11: AST-REF | B11: APH | C11: Live Unit | D11: =VLOOKUP(A11,'Tenure Type Description'!A:B,2,FALSE) -> AST-Paignton Housing Association
A12: ChiefRent | B12: CHR | C12: Live Unit | D12: =VLOOKUP(A12,'Tenure Type Description'!A:B,2,FALSE) -> Chief Rent
A13: CommLease | B13: COM | C13: Commercial Unit | D13: =VLOOKUP(A13,'Tenure Type Description'!A:B,2,FALSE) -> Commercial Lease
... A51: VAC-SR | B51: VAC | C51: Live Unit | D51: =VLOOKUP(A51,'Tenure Type Description'!A:B,2,FALSE) -> Vacant

Sheet Tenure Type Description
A1: Qube Unit Tenure Type | B1: Canonical Description
A2: Aff Rent | B2: AST Affordable
A3: AHA (Agr) | B3: Agricultural Protected Statutory
A4: Assd PHA | B4: Assured-Paignton Housing Association
A5: Assd.Per | B5: ASSURED- Statutory Periodic
A6: Assured | B6: Assured
A7: AST | B7: Assured Shorthold Tenancy
A8: AST Chc | B8: AST Church Commissioners
A9: AST KW | B9: AST-Keyworkers
A10: AST Per | B10: AST- Statutory Periodic
A11: AST-REF | B11: AST-Paignton Housing Association
A12: ChiefRent | B12: Chief Rent
... A52: VAC-SR | B52: Vacant

Sheet CM Tenure Type
A1: Qube Unit Tenure Type | B1: Canonical MRI Tenure Type | C1: Salesforce CM Tenure Type
A2: Aff Rent | B2: AFF | C2: Residential
A3: AHA (Agr) | B3: AGP | C3: Residential
A4: Assd PHA | B4: ASH | C4: Residential
A5: Assd.Per | B5: ASS | C5: Residential
A6: Assured | B6: ASS | C6: Residential
A7: AST | B7: AST | C7: Residential
A8: AST Chc | B8: ACC | C8: Residential
A9: AST KW | B9: ASK | C9: Residential
A10: AST Per | B10: ASP | C10: Residential
A11: AST-REF | B11: APH | C11: Residential
A12: ChiefRent | B12: CHR | C12: Residential
... A51: VAC-SR | B51: VAC | C51: Commercial

Sheet Contact Status
A1: Tenant Status from Qube | B1: Canonical | C1: Tenant Status to FSI
A2: Active | B2: C | C2: ACTIVE
A3: Not Active | B3: I | C3: INACTIVE
A4: Future | B4: F | C4: Not sent to FSI

Sheet Property Type
A1: Property Type | B1: Canonical Entity Type
A2: RESIDENTIAL | B2: PRO
A3: AGRICULT. | B3: PRO
A4: COMMERCIAL | B4: PRO
A5: MIXED USE | B5: PRO
A6: Mid Terrace | B6: PRO
A7: Det House | B7: PRO
A8: S/D House | B8: PRO
A9: End Terrace | B9: PRO
A10: Flat PB | B10: PRO
A11: Flat Conv | B11: PRO
A12: SOCIALHOUSE | B12: PRO
... A20: No prop_type | B20: COR

Sheet Agreement Type
A1: Qube Unit Tenure Type | B1: Canonical MRI Tenure Type | C1: Salesforce Agreement Type
A2: Aff Rent | B2: AFF | C2: AST (Affordable)
A3: AHA (Agr) | B3: AGP | C3: Occupation Licence
A4: Assd PHA | B4: ASH | C4: AST (Affordable)
A5: Assd.Per | B5: ASS | C5: AST (Affordable)
A6: Assured | B6: ASS | C6: AST (Affordable)
A7: AST | B7: AST | C7: AST
A8: AST Chc | B8: ACC | C8: AST
A9: AST KW | B9: ASK | C9: AST
A10: AST Per | B10: ASP | C10: AST
A11: AST-REF | B11: APH | C11: AST (Affordable)
A12: ChiefRent | B12: CHR
A13: CommLease | B13: COM | C13: Other
A14: Comm-Let | B14: CML | C14: Other
A15: CommLic | B15: CLI | C15: Other
A16: Comp-Let | B16: COL | C16: Non-Housing (Company)
A17: CT SerLic | B17: SLC | C17: Occupation Licence
A18: CT SerTen | B18: STC | C18: Occupation Licence
A19: DMR-AST | B19: DMR | C19: AST (Affordable)
A20: Dummy | B20: DUM
A21: EstateChg | B21: EST
A22: FBT(Farm) | B22: AGA
A23: FixedRent | B23: FIX | C23: Other
A24: FREEHOLD | B24: VAC
A25: Gr Lets | B25: IMR | C25: AST (Affordable)
A26: GRIPSALE | B26: GRI
A27: Grnd Rent | B27: GRT | C27: Other
A28: Insurance | B28: APH | C28: AST (Affordable)
A29: Land | B29: LIC | C29: Other
A30: LEASEHOLD | B30: VAC
A31: Licence | B31: LIC | C31: Other
A32: Live Work | B32: ALW | C32: Live Work
A33: MOD | B33: TRI | C33: Other
A34: MORTGAGE | B34: MRT
A35: NHA | B35: NHA | C35: Non-Housing (Company)
A36: Nil GR | B36: NGR | C36: Other
A37: No Tenure | B37: DUM
A38: Regulated | B38: REG | C38: AST (Affordable)
A39: Reversion | B39: CHA | C39: AST (Affordable)
A40: Services | B40: SER
...

Sheet Bedrooms
A1: Canonical Value | B1: Salesforce Value
A2: 1 | B2: 1 Bedroom
A3: 2 | B3: 2 Bedrooms
A4: 3 | B4: 3 Bedrooms
A5: 4 | B5: 4 Bedrooms
A6: 5 | B6: 5 Bedrooms
A7: 6 | B7: 6 Bedrooms
A8: 7 | B8: 7 Bedrooms

Sheet Owner ID
A1: Qube Legal Owner Reference | B1: Canonical Owner ID | C1: Salesforce Owner ID
A2: [not specified] | B2: [not specified] | C2: GRML
A3: BEK | B3: BEK | C3: GTRUST
A4: BJN | B4: BJN | C4: PEARL
A5: BJT | B5: BJT | C5: PEARL
A6: BQG | B6: BQG | C6: GRML
A7: HAD | B7: HAD | C7: PEARL
A8: TAB | B8: TAB | C8: VESTA
A9: URE | B9: URE | C9: GRIPU

Sheet Contact Role
A1: Qube | B1: Canonical | C1: Salesforce
A2: <client><occupiertype> = "Tenant" and <client><subreference> =1 | B2: Lead Tenant | C2: 1 Lead Tenant
A3: <client><occupiertype> = "Tenant" and <client><subreference> <>1 | B3: Sub Tenant | C3: 2 Tenant
A4: Guarantor | B4: Guarantor | C4: 3 Guarantor
A5: Relevant Person | B5: Relevant Person | C5: 5 Relevant Person
A6: Permitted Occupier | B6: Permitted Occupier | C6: 4 Permitted Occupier

Sheet MRI to Salesforce - Update
A1: Data Mapping | B1: CP-CORE-02/CP-CORE-04
A2: Sending Interface system | B2: MRI
A3: Outbound Data Structure | B3: XML
A4: Receiving Interface system 1 | B4: Salesforce
A5: Inbound Data Structure 1 | B5: JSON
A6: Title | B6: ChartsOfAccountsUpserted/NominalUpserted - Update Customer
A7: Source - MRI | C7: Global/Entity | D7: Mandatory/Optional | E7: XML Element / Attribute | F7: Mandatory/Optional | G7: Type | H7: Size | I7: Sample Darta | J7: Transformation rule/logic | K7: Destination 1 - Salesforce | M7: Mandatory/Optional | N7: Data Type | O7: Length
A8: Table | B8: Source API | K8: Destination API | L8: Field Name
A9: Tenant Data - CM
M16: Mandatory
A19: Tenant Data - RM
M26: Mandatory
