Workbook

Sheet IL to HORIZON
A2: Interface code | D2: 1.1.2 & 1.2.2
A3: Destination system | D3: HORIZON
A4: Message Name
A5: Input Type (File/XML/Idoc/Others)?
A6: Fixed, Delimited or Tagged?
A7: Level | B7: Table Name | C7: Field Name | D7: Parent Table | E7: Mandatory / Optional | F7: Data Type / Size | G7: Format | H7: Description
C9: TNNT_REF | E9: Mandatory | F9: String(8) | H9: Tenant Ref | I9: y
C10: TNNT_LEVEL | E10: Mandatory | F10: String(3) | H10: Level | I10: y
C11: TNNT_GROUP_TNNT_REF | E11: Optional | F11: String(8) | H11: Group Tenant Ref | I11: Parent tenant id | J11: Need to be restricted to 3 levels in NAV
C12: TNNT_TRADE_NAME | E12: Optional | F12: String(60) | H12: Trade Name | I12: y
C13: TNNT_ADDR_REF | E13: Mandatory | F13: String(8) | H13: Address Ref | I13: default to customer ref
C14: TNNT_VALID_DEMANDS | E14: Mandatory | F14: String(1) | H14: Valid Demands | I14: Default Always B
C15: TNNT_TYPE_CODE | E15: Optional | F15: String(3) | H15: Type Code | I15: y
C16: TNNT_STATUS_CODE | E16: Optional | F16: String(3) | H16: Status Code | I16: y
C17: TNNT_USER_CODE | E17: Optional | F17: String(3) | H17: User Code | I17: not used
C18: TNNT_CUR_CODE | E18: Mandatory | F18: String(3) | H18: Currency Code | I18: y
C19: TNNT_LEGAL_NAME | E19: Optional | F19: String(60) | H19: Legal Name | I19: not used
C20: TNNT_EMAIL_INVOICE_FLAG | E20: Optional | F20: String(1) | H20: Email Invoice Flag | I20: defaulted based on email address
C21: TNNT_AGENT_CODE | E21: Optional | F21: String(3) | H21: Agent Code | I21: not used
C22: TNNT_DOC_LAN_CODE | E22: Optional | F22: String(3) | H22: Doc Lan Code | I22: default to English
C23: TNNT_TERI_CODE | E23: Optional | F23: String(3) | H23: Teri Code | I23: not used
... C52: TNNT_PRINT_RCPT | E52: Optional | F52: String(1) | H52: Print Rcpt | I52: not used
E53: Optional | F53: 256 | H53: Full legal name | I53: new field
C54: ADDR_REF | E54: Mandatory | F54: String(8) | H54: Address Ref | I54: default to customer ref
C55: ADDR_NAME | E55: Mandatory | F55: String(60) | H55: Name | I55: y
C56: ADDR_PROP_NAME | E56: Optional | F56: String(60) | H56: Property Name | I56: y
C57: ADDR_L1 | E57: Optional | F57: String(30) | H57: Address L1 | I57: y
C58: ADDR_L2 | E58: Optional | F58: String(30) | H58: Address L2 | I58: y
C59: ADDR_TOWN | E59: Optional | F59: String(30) | H59: Town | I59: y
C60: ADDR_COUNTY | E60: Optional | F60: String(30) | H60: County | I60: y
C61: ADDR_POSTCODE | E61: Optional | F61: String(12) | H61: Postcode | I61: y
C62: ADDR_COUNTRY | E62: Optional | F62: String(30) | H62: Country | I62: y
C63: ADDR_PHONE | E63: Optional | F63: String(20) | H63: Phone | I63: y
C64: ADDR_EMAIL | E64: Optional | F64: String(60) | H64: Email | I64: y
C65: ADDR_FAX | E65: Optional | F65: String(20) | H65: Address Fax | I65: not used
... C71: ADDR_COMP_REG_NUM | E71: Optional | F71: String(25) | H71: Operation Reg Num | I71: not used
E72: Optional | H72: Address L3 | I72: Add new 4th line of address
C73: TNAC_TNNT_REF | E73: Mandatory | F73: String(8) | H73: Tenant Ref | I73: y
C74: TNAC_REF | E74: Mandatory | F74: String(8) | H74: Tnac Ref | I74: HZN autogenerate
C75: TNAC_DESC | E75: Optional | F75: String(30) | H75: Description | I75: y
...

Sheet IL Data Mapping #WORKING#
A1: Data Mapping
A2: Sending Interface system | B2: NAV
A3: Outbound Data Structure
A4: Receiving Interface system | B4: HORIZON
A5: Inbound Data Structure
A6: Title
A7: Source | D7: Transformation rule/logic | E7: Destination
A8: Table | B8: Field Name | E8: Table | F8: Field Name
A9: Customer | B9: No. | C9: Code20 | D9: Direct | F9: TNNT_REF | H9: =IF(F9="","",VLOOKUP(F9,'IL to HORIZON'!$C$9:$F$93,4,FALSE)) -> String(8)
A10: Customer | B10: Name | C10: Text50 | D10: direct | F10: TNNT_TRADE_NAME | G10: ADDR_NAME | H10: =IF(F10="","",VLOOKUP(F10,'IL to HORIZON'!$C$9:$F$93,4,FALSE)) -> String(60) | I10: =IF(G10="","",VLOOKUP(G10,'IL to HORIZON'!$C$9:$F$93,4,FALSE)) -> String(60)
A11: Customer | B11: Search Name | C11: Code50 | H11: =IF(F11="","",VLOOKUP(F11,'IL to HORIZON'!$C$9:$F$93,4,FALSE))
A12: Customer | B12: Name 2 | C12: Text50 | H12: =IF(F12="","",VLOOKUP(F12,'IL to HORIZON'!$C$9:$F$93,4,FALSE))
A13: Customer | B13: Address | C13: Text50 | D13: Direct | F13: ADDR_PROP_NAME | H13: =IF(F13="","",VLOOKUP(F13,'IL to HORIZON'!$C$9:$F$93,4,FALSE)) -> String(60)
A14: Customer | B14: Address 2 | C14: Text50 | D14: Direct | F14: ADDR_L1 | H14: =IF(F14="","",VLOOKUP(F14,'IL to HORIZON'!$C$9:$F$93,4,FALSE)) -> String(30)
A15: Customer | B15: City | C15: Text30 | D15: Direct | F15: ADDR_TOWN | H15: =IF(F15="","",VLOOKUP(F15,'IL to HORIZON'!$C$9:$F$93,4,FALSE)) -> String(30)
A16: Customer | B16: Contact | C16: Text50 | H16: =IF(F16="","",VLOOKUP(F16,'IL to HORIZON'!$C$9:$F$93,4,FALSE))
A17: Customer | B17: Phone No. | C17: Text30 | D17: direct | F17: ADDR_PHONE | H17: =IF(F17="","",VLOOKUP(F17,'IL to HORIZON'!$C$9:$F$93,4,FALSE)) -> String(20)
A18: Customer | B18: Telex No. | C18: Text20 | H18: =IF(F18="","",VLOOKUP(F18,'IL to HORIZON'!$C$9:$F$93,4,FALSE))
A19: Customer | B19: Document Sending Profile | C19: Code20 | H19: =IF(F19="","",VLOOKUP(F19,'IL to HORIZON'!$C$9:$F$93,4,FALSE))
A20: Customer | B20: Our Account No. | C20: Text20 | H20: =IF(F20="","",VLOOKUP(F20,'IL to HORIZON'!$C$9:$F$93,4,FALSE))
A21: Customer | B21: Territory Code | C21: Code10 | H21: =IF(F21="","",VLOOKUP(F21,'IL to HORIZON'!$C$9:$F$93,4,FALSE))
A22: Customer | B22: Global Dimension 1 Code | C22: Code20 | H22: =IF(F22="","",VLOOKUP(F22,'IL to HORIZON'!$C$9:$F$93,4,FALSE))
A23: Customer | B23: Global Dimension 2 Code | C23: Code20 | H23: =IF(F23="","",VLOOKUP(F23,'IL to HORIZON'!$C$9:$F$93,4,FALSE))
A24: Customer | B24: Chain Name | C24: Code10 | H24: =IF(F24="","",VLOOKUP(F24,'IL to HORIZON'!$C$9:$F$93,4,FALSE))
A25: Customer | B25: Budgeted Amount | C25: Decimal | H25: =IF(F25="","",VLOOKUP(F25,'IL to HORIZON'!$C$9:$F$93,4,FALSE))
A26: Customer | B26: Credit Limit (LCY) | C26: Decimal | H26: =IF(F26="","",VLOOKUP(F26,'IL to HORIZON'!$C$9:$F$93,4,FALSE))
A27: Customer | B27: Customer Posting Group | C27: Code10 | D27: mapping code(10) to code(3) | F27: TNNT_TYPE_CODE | H27: =IF(F27="","",VLOOKUP(F27,'IL to HORIZON'!$C$9:$F$93,4,FALSE)) -> String(3) | I27: do these NAV codes align to HZN codes??
A28: Customer | B28: Currency Code | C28: Code10 | D28: map NULL = GBP otherwise direct if same 3 char code | F28: TNNT_CUR_CODE | H28: =IF(F28="","",VLOOKUP(F28,'IL to HORIZON'!$C$9:$F$93,4,FALSE)) -> String(3)
A29: Customer | B29: Customer Price Group | C29: Code10 | H29: =IF(F29="","",VLOOKUP(F29,'IL to HORIZON'!$C$9:$F$93,4,FALSE))
A30: Customer | B30: Language Code | C30: Code10 | H30: =IF(F30="","",VLOOKUP(F30,'IL to HORIZON'!$C$9:$F$93,4,FALSE))
A31: Customer | B31: Statistics Group | C31: Integer | H31: =IF(F31="","",VLOOKUP(F31,'IL to HORIZON'!$C$9:$F$93,4,FALSE))
A32: Customer | B32: Payment Terms Code | C32: Code10 | D32: map Code 10 to number of days | F32: TNNT_INV_DUE_DAYS | H32: =IF(F32="","",VLOOKUP(F32,'IL to HORIZON'!$C$9:$F$93,4,FALSE)) -> Number(3)
A33: Customer | B33: Fin. Charge Terms Code | C33: Code10 | H33: =IF(F33="","",VLOOKUP(F33,'IL to HORIZON'!$C$9:$F$93,4,FALSE))
A34: Customer | B34: Salesperson Code | C34: Code10 | H34: =IF(F34="","",VLOOKUP(F34,'IL to HORIZON'!$C$9:$F$93,4,FALSE))
A35: Customer | B35: Shipment Method Code | C35: Code10 | H35: =IF(F35="","",VLOOKUP(F35,'IL to HORIZON'!$C$9:$F$93,4,FALSE))
A36: Customer | B36: Shipping Agent Code | C36: Code10 | H36: =IF(F36="","",VLOOKUP(F36,'IL to HORIZON'!$C$9:$F$93,4,FALSE))
A37: Customer | B37: Place of Export | C37: Code20 | H37: =IF(F37="","",VLOOKUP(F37,'IL to HORIZON'!$C$9:$F$93,4,FALSE))
A38: Customer | B38: Invoice Disc. Code | C38: Code20 | H38: =IF(F38="","",VLOOKUP(F38,'IL to HORIZON'!$C$9:$F$93,4,FALSE))
A39: Customer | B39: Customer Disc. Group | C39: Code20 | H39: =IF(F39="","",VLOOKUP(F39,'IL to HORIZON'!$C$9:$F$93,4,FALSE))
A40: Customer | B40: Country/Region Code | C40: Code10 | D40: both using ISO 2 char code | F40: ADDR_COUNTRY | H40: =IF(F40="","",VLOOKUP(F40,'IL to HORIZON'!$C$9:$F$93,4,FALSE)) -> String(30)
...

Sheet Sheet1
A1: Field | B1: Description/Usage | C1: Comment
A2: Info_1 | B2: Trading as | C2: This would seem to be the logical place to store Commercial company number. 300 active child records (tenants) have been populated with data in Qube but very little of it seems to relate to "Trading As" reference so I am sure if we needed to we could leave this data on the non- commercial units or move it to one of the other fields mentioned below
A3: Info_2 | B3: Guarantor | C3: Indicates if a guarantor exists-avoiding the need for users to drill down into tenant data tab to obtain this information
A4: info_s1 | B4: Fixed increase | C4: Holds details of fixed increase and date. This data should come over from Salesforce for the commercial leases if possible but at the moment the integration is not designed to pass this data -therefore for now it would have to be input into Qube manually if required to be held there
A5: Info_s2 | B5: Rent concessions | C5: Used in the past to hold details of any rent concessions. Probably not being used now that the information is held on Salesforce other than for leases that do not pass through Salesforce. This would be another field where the information could feed from Salesforce but where the current integration does not cater for this
A6: Info_s3 | B6: Payment Plans | C6: Indicates if a tenant account is subject to a Payment Plan. Used by Credit Control Team and for Finance Reporting
A7: Info_s4 | B7: Prepaid Rent | C7: Indicates whether a tenant account includes any pre paid rent. Used for finance reporting.
A8: Info_s5 | B8: No of occupants | C8: Stores the number of occupants. Not really used now but holds legacy data.
A9: Info_s6 | B9: Salesforce Contact id | C9: Stores the Salesforce 18 digit contact id to link the Salesforce contact with the Qube child tenant

Sheet Version History
A1: Date | B1: Version | C1: Author | D1: Comments
A2: 44503 | B2: 1.0 | C2: Phil Cullum | D2: Created
A3: 11/112021 | B3: 1.0 | C3: Phil Cullum | D3: Updated to match Tenancy, Unit and Client APIs provided by Qube
A4: 44523 | B4: 1.1 | C4: Phil Cullum | D4: Added canonical message fields
A5: 44568 | B5: 1.2 | C5: Phil Cullum | D5: Added missing transformation logic for client phone numbers
A6: 44580 | B6: 1.3 | C6: Phil Cullum | D6: Removed transformation logic for client phone numbers, no longer required
B7: 1.4 | C7: Phil Cullum | D7: Removed tenancy end date mapping as requested by Anita/Scott
B8: 1.5 | C8: Phil Cullum | D8: Changed Salesforce move in date to map to tenancy start date
A9: 45042 | B9: 1.6 | C9: Phil Cullum | D9: Updated to match updated Qube v12 API and new Unit update requirements
A10: 45204 | B10: 1.7 | C10: Phil Cullum | D10: Update after review by Deb Stein
A11: 45070 | B11: 1.8 | C11: Phil Cullum | D11: Updated with lease-percentage mapping
A12: 45082 | B12: 1.9 | C12: Phil Cullum | D12: Agreement type and tenant-type mapping changes
A13: 45092 | B13: 1.10 | C13: Phil Cullum | D13: Added tenant-type mapping to child tenant elements
A14: 45104 | B14: 1.11 | C14: Phil Cullum | D14: Updated with Opportunity filter rules
A15: 45251 | B15: 1.12 | C15: Phil Cullum | D15: Updated Opportunity Filtering Logic tab to include "Closed Won"
A16: 45253 | B16: 1.13 | C16: Phil Cullum | D16: Corrected agreement type mappings
A17: 45261 | B17: 1.14 | C17: Phil Cullum | D17: Mapped Salesforce contact mobile number to Qube Tenant Telephone3 field. See https://graingerplc.atlassian.net/browse/QUP-923

Sheet Salesforce to Qube  - Units
A1: Data Mapping | B1: CP-LJ-01
A2: Sending Interface system | B2: Salesforce
A3: Outbound Data Structure | B3: JSON
A4: Receiving Interface system | B4: Qube
A5: Inbound Data Structure | B5: XML
A6: Title | B6: TenancyCreated
A7: Method | B7: POST
A8: Source - Salesforce | C8: JSON Element | D8: Mandatory/Optional | E8: Data Type | F8: Field Length | G8: Sample Data | H8: Transformation rule/logic | I8: ChartOfAccounts | K8: Target - Qube | M8: XML Element | N8: Mandatory/Optional | O8: Data Type | P8: Field Length | Q8: Notes
A9: Table | B9: Field Name | I9: Canonical field | J9: Source API | K9: Table | L9: Field
D10: string | H10: See Opportunity Filtering Logic tab for details of which Opportunities should be processed Only send update when tenancy start date is today or in the past
H11: Set to "false" | M11: lookup | O11: boolean
H12: Set to "true" | M12: update-if-exists | O12: boolean
H13: Set to "true" | M13: clear-empty-fields | O13: boolean
A14: Opportunity | C14: Id | H14: Read from XRef | I14: EntityListing/UnitReference/entry/EntityID | M14: unit-reference
H15: NOT MAPPED | M15: property-reference
H16: NOT MAPPED | M16: desc
A17: Opportunity | C17: Tenancy_Start_Date | H17: Convert to yyyy-mm-dd format | I17: EntityListing/UnitReference/entry/CMResidents/entry/LeaseStartDate | K17: units | L17: leasedate5 | M17: lease-start
A18: Opportunity | C18: Tenancy_End_Date__c | H18: Convert to yyyy-mm-dd format | I18: EntityListing/UnitReference/entry/CMResidents/entry/LeaseEndDate | K18: units | L18: leasedate6 | M18: lease-end | N18: M
H19: NOT MAPPED | K19: units | L19: leaseterm1 | M19: lease-term-years | Q19: Need to test this is set by default
H20: NOT MAPPED | K20: units | L20: leaseterm2 | M20: lease-term-months | Q20: Need to test this is set by default
H21: NOT MAPPED | K21: units | L21: leaseterm3 | M21: lease-term-days | Q21: Need to test this is set by default
A22: Opportunity | C22: Agreement_Type__c | H22: If current Qube Unit status value is "Tenanted" do not update. See Agreement Type Mappings tab - ref data | I22: EntityListing/UnitReference/entry/Tenure | K22: units | L22: tenure | M22: tenure
H23: NOT MAPPED | K23: units | L23: TBA | M23: rent-review-date
H24: NOT MAPPED | K24: units | L24: TBA | M24: rent-review-notice
H25: NOT MAPPED | K25: units | L25: TBA | M25: rent-review- frequency
C26: Primary_Offer_Break_Clause__c | H26: See Break Clause Rules | K26: units | L26: TBA | M26: break-date | Q26: See Primary Offer Break Clause and email from Jaic
C27: Primary_Offer_Break_Clause__c | H27: See Break Clause Rules | K27: units | L27: TBA | M27: break-notice
C28: Primary_Offer_Break_Clause__c | H28: See Break Clause Rules | K28: units | L28: TBA | M28: break-frequency
H29: Set to Tenanted - store in QuickConnect reference data | K29: units | L29: unit_stat | M29: status
Q30: New field: % rent increase field TBC Tenancy.Uplift
A32: Foreign Keys
A33: None
M36: ?
M48: <detail><nett> | N48: Mandatory | O48: Number | P48: 13,2
M49: <detail><gross> | N49: Mandatory | O49: Number | P49: 13,2
M50: <detail><vat-code> | N50: Optional | O50: string | P50: 1
M51: <detail><vat> | N51: Mandatory | O51: Number | P51: 13,2
M52: <detail><line-type> | N52: Mandatory | O52: string | P52: 45
M53: <detail><line-type> | N53: Mandatory | O53: string | P53: 45
M54: <detail><property-reference> | N54: Mandatory | O54: string | P54: 12
...

Sheet Salesforce to Qube  - Tenancy
A1: Data Mapping | B1: CP-LJ-01
A2: Sending Interface system | B2: Salesforce
A3: Outbound Data Structure | B3: JSON
A4: Receiving Interface system | B4: Qube
A5: Inbound Data Structure | B5: XML
A6: Title | B6: TenancyCreated
A7: Method | B7: POST
A8: Source - Salesforce | C8: Mandatory/Optional | D8: Data Type | E8: Field Length | G8: Transformation rule/logic | H8: ChartOfAccounts | J8: Target - Qube | M8: XML Element | N8: Mandatory/Optional | O8: Data Type | P8: Field Length | Q8: Notes
A9: Table | B9: JSON Element | F9: Sample Data | H9: Canonical field | I9: Source API | J9: Table | K9: Field | L9: Xpath
C10: Mandatory | G10: See Opportunity Filtering Logic tab for details of which Opportunities should be processed
C11: Mandatory | G11: Set to "false" | L11: [root] | M11: lookup | O11: boolean
G12: Set to "true" | L12: tenant | M12: update-if-exists | O12: boolean
G13: Set to "true" | L13: tenant | M13: clear-empty-fields | O13: boolean
B14: x | G14: The following mappings are for the parent tenancy
A15: Opportunity | B15: Primary_Offer_Live_Unit__c | G15: Read from XRef | H15: EntityListing/UnitReference/entry/EntityID | J15: units | K15: reference | L15: tenant | M15: unit-reference | O15: string | P15: 12
A16: Opportunity | B16: Id | C16: Mandatory | G16: Direct | H16: EntityListing/UnitReference/entry/OccupantReference | J16: tenant | K16: reference | L16: tenant | M16: tenant-reference | N16: M | O16: string | P16: 12 forced
G17: Direct - set to same value as tenant-reference | H17: EntityListing/UnitReference/entry/OccupantReference | L17: tenant | M17: parent-tenant
A18: Account | B18: Name | C18: Mandatory | G18: Direct | H18: EntityListing/UnitReference/entry/CMResidents/entry/OccupantName | J18: tenant | K18: name | L18: tenant | M18: name | N18: M | O18: string | P18: 45
G19: NOT MAPPED | J19: tenant | M19: lease-percentage
A20: Unit | B20: Street_Name__c | C20: Mandatory | G20: Only map if no address1 set. Truncate to 45 | H20: EntityListing/UnitReference/entry/AddressLine1 | J20: tenant | K20: address[1] | L20: tenant/address | M20: address1 | O20: string | P20: 45
G21: NOT MAPPED | J21: tenant | K21: address[2] | L21: tenant/address | M21: address2 | O21: string | P21: 45
G22: NOT MAPPED | J22: tenant | K22: address[3] | L22: tenant/address | M22: address3 | O22: string | P22: 45
G23: NOT MAPPED | J23: tenant | K23: address[4] | L23: tenant/address | M23: address4 | O23: string | P23: 45
G24: NOT MAPPED | J24: tenant | K24: address[5] | L24: tenant/address | M24: address5 | O24: string | P24: 45
G25: NOT MAPPED | J25: tenant | K25: address[6] | L25: tenant/address | M25: address6 | O25: string | P25: 45
A26: Unit | B26: Post_Code__c | G26: Direct | H26: EntityListing/UnitReference/entry/UnitPostCode | J26: tenant | K26: postcode | L26: tenant/address | M26: postcode | O26: string | P26: 11
A27: Account | B27: Phone | G27: Direct | H27: EntityListing/UnitReference/entry/CMResidents/entry/Phone1 | J27: tenant | K27: telephone[1] | L27: tenant/telephone | M27: telephone1 | O27: string | P27: 21
G28: NOT MAPPED | J28: tenant | K28: telephone[2] | L28: tenant/telephone | M28: telephone2 | O28: string | P28: 21
A29: Account | B29: PersonMobilePhone | G29: Direct | H29: EntityListing/UnitReference/entry/CMResidents/entry/Phone2 | J29: tenant | K29: telephone[3] | L29: tenant/telephone | M29: telephone3 | O29: string | P29: 21
G30: NOT MAPPED | J30: tenant | K30: telephone[4] | L30: tenant/telephone | M30: telephone4 | O30: string | P30: 21
A31: Account | B31: PersonEmail | G31: Direct | H31: EntityListing/UnitReference/entry/CMResidents/entry/Email | J31: tenant | K31: email[1] | L31: tenant/email | M31: email1 | O31: string | P31: 71
G32: NOT MAPPED | J32: tenant | K32: email[2] | L32: tenant/email | M32: email2 | O32: string | P32: 71
G33: NOT MAPPED | J33: tenant | K33: email[3] | L33: tenant/email | M33: email3 | O33: string | P33: 71
A34: Opportunity | B34: Tenancy_Start_Date__c | C34: Mandatory | G34: yyyy-mm-dd | H34: EntityListing/UnitReference/entry/CMResidents/entry/LeaseStartDate | J34: tenant | K34: ten_begin | L34: tenant | M34: start-date | O34: date
A35: Opportunity | B35: Removed | G35: NOT MAPPED | H35: EntityListing/UnitReference/entry/CMResidents/entry/LeaseEndDate | L35: tenant | M35: end-date
A36: Account | B36: Name | C36: Optional | G36: Direct | H36: EntityListing/UnitReference/entry/CMResidents/entry/OccupantName | J36: tenant | K36: dear | M36: dear | O36: string | P36: 45
C37: Optional | G37: Set to "Sincerely" - store in QuickConnect reference data | J37: tenant | K37: yours | L37: tenant | M37: yours | O37: choice
G38: NOT MAPPED | J38: tenant | K38: info-_[1] | L38: tenant | M38: info-l1 | O38: string | P38: 45
G39: NOT MAPPED | J39: tenant | K39: info-_[2] | L39: tenant | M39: info-l2 | O39: string | P39: 45
G40: NOT MAPPED | J40: tenant | K40: info_s[1] | L40: tenant | M40: info-s1 | O40: string | P40: 25
...

Sheet Salesforce to Qube  - Clients
A1: Data Mapping | B1: CP-LJ-01
A2: Sending Interface system | B2: Salesforce
A3: Outbound Data Structure | B3: JSON
A4: Receiving Interface system | B4: Qube
A5: Inbound Data Structure | B5: XML
A6: Title | B6: TenancyCreated
A7: Method | B7: POST
A8: Source - Salesforce | C8: Mandatory/Optional | D8: Data Type | E8: Field Length | G8: Transformation rule/logic | H8: ChartOfAccounts | J8: Target - Qube | M8: XML Element | N8: Mandatory/Optional | O8: Data Type | P8: Field Length | Q8: Notes
A9: Table | B9: JSON Element | F9: Sample Data | H9: Canonical field | I9: Source API | J9: Table | K9: Field | L9: Path
C10: Mandatory | G10: See Opportunity Filtering Logic tab for details of which Opportunities should be processed
C11: Mandatory | G11: Set to "false" | L11: [root] | M11: lookup | O11: boolean
G12: Set to "true" | L12: tenantsdata | M12: update-if-exists | O12: boolean
G13: Set to "true" | L13: tenantsdata | M13: clear-empty-fields | O13: boolean
C14: Mandatory | L14: tenantsdata | M14: tenant-reference | O14: string | P14: 12 forced
A15: Contact | B15: Name | H15: EntityListing/UnitReference/entry/CMResidents/entry/CMContacts/entry/Name | L15: tenantsdata | M15: name | O15: string | P15: 45
G16: NOT MAPPED | L16: tenantsdata | M16: title | O16: string | P16: 45
A17: Contact | B17: FirstName | G17: Direct | H17: EntityListing/UnitReference/entry/CMResidents/entry/CMContacts/entry/FirstName | L17: tenantsdata | M17: first-name | O17: string | P17: 20
G18: NOT MAPPED | L18: tenantsdata | M18: middle-name | O18: string | P18: 19
A19: Contact | B19: LastName | G19: Direct | H19: EntityListing/UnitReference/entry/CMResidents/entry/CMContacts/entry/LastName | L19: tenantsdata | M19: surname | O19: string | P19: 20
A20: OpportunityContactRole | B20: Role | G20: Tenant (from ref data), see Client Role Mappngs | H20: EntityListing/UnitReference/entry/CMResidents/entry/CMContacts/entry/ContactType | L20: tenantsdata | M20: occupier-type | O20: string | P20: 45
G21: NOT MAPPED | L21: tenantsdata | M21: method-of-contact | O21: string | P21: 45
A22: Contact | B22: Birthdate | G22: Direct | L22: tenantsdata | M22: date-of-birth | O22: date
G23: NOT MAPPED | L23: tenantsdata | M23: date-of-death | O23: date
G24: NOT MAPPED | L24: tenantsdata | M24: spouse-date-of-birth
G25: NOT MAPPED | L25: tenantsdata | M25: gender
G26: NOT MAPPED | L26: tenantsdata | M26: country-of-origin
G27: NOT MAPPED | L27: tenantsdata | M27: marital-status
G28: NOT MAPPED | L28: tenantsdata | M28: benefit-received
G29: NOT MAPPED | L29: tenantsdata | M29: benefit-provider
G30: NOT MAPPED | L30: tenantsdata | M30: ni-number
G31: NOT MAPPED | L31: tenantsdata | M31: benefit-refnumber
G32: NOT MAPPED | L32: tenantsdata | M32: reason-for-vacancy
G33: NOT MAPPED | L33: tenantsdata | M33: vip
A40: Salesforce Foreign Keys
A41: OpportunityContactRole.ContactId
A42: OpportunityContactRole.OpportunityId

Sheet Opportunity Filtering Logic
A1: Only send Salesforce Opportunities to Qube where:
A3: Opportunity Agreement Type is specified
A4: Opportunity Agreement Type <> AST (Affordable)
A5: Opportunity Tenancy Type = New
A6: Opportunity PMS Reference specified
A7: Opportunity Stage = "Audit" or "Closed Won"
A8: (Processed By GREP = Not Processed OR (Processed By GREP <> Processed - Current Tenancy AND Move In Date is today or in the past)
A10: Note: All conditions must be met for Opportunity to be processed

Sheet Break Clause Rules
A1: Salesforce Primary Offer Break Clause | B1: Meaning | C1: Break Date | D1: Break Notice | E1: Break Frequency
A2: 2 at 4 to expire at 6 | B2: 2 months notice after min 4 months to expire at 6 months | C2: Move in date + 6 months | D2: 2 | E2: Do not map
A3: 2 at 6 to expire at 8 | B3: 2 months notice after min 6 months to expire at 8 months | C3: Move in date + 8 months | D3: 2 | E3: Do not map
A4: 2 at 8 to expire at 10 | B4: 2 months notice after min 8 months to expire at 10 months | C4: Move in date + 10 months | D4: 2 | E4: Do not map
A5: 2 at 10 to expire at 12 | B5: 2 months notice after min 10 months to expire at 12 months | C5: Move in date + 12 months | D5: 2 | E5: Do not map
A6: Halfway on an 18 | B6: Expire after min 9 months | C6: Move in date + 9 months | D6: 2 | E6: Do not map
A7: Halfway on an 24 | B7: Expire after min 12 months | C7: Move in date + 12 months | D7: 2 | E7: Do not map
A8: Halfway on an 36 | B8: Expire after min 18 months | C8: Move in date + 18 months | D8: 2 | E8: Do not map
A9: No break | B9: Break not permitted | C9: Do not map | D9: Do not map | E9: Do not map
A10: Live work | B10: TBA | C10: Do not map | D10: Do not map | E10: Do not map
A11: Check Contract | B11: Old tenancy and so not listed in Salesforce | C11: Do not map | D11: Do not map | E11: Do not map
A12: Renewal 1 month | B12: 1m renewal, then tenant will leave | C12: Do not map | D12: Do not map | E12: Do not map
A13: Renewal 2 month | B13: 2m renewal and then tenant will leave | C13: Do not map | D13: Do not map | E13: Do not map
A14: LW Renewal 1 month | B14: 1m renewal, then tenant will leave | C14: Do not map | D14: Do not map | E14: Do not map
A15: LW Renewal 2 month | B15: 2m renewal and then tenant will leave | C15: Do not map | D15: Do not map | E15: Do not map

Sheet Client Role Mappings
A1: Salesforce Opportunity Contact Role | B1: Canonical | C1: Qube Occupier Type
A2: Lead Tenant | B2: Lead Tenant | C2: Lead Tenant
A3: Tenant | B3: Sub Tenant | C3: Tenant
A4: Permitted Occupier | B4: Permitted Occupier | C4: Additional occupier
A5: Guarantor | B5: Guarantor | C5: Guarantor
A6: Relevant Person | B6: Relevant Person | C6: Alternative contact

Sheet Agreement Type Mappings
A1: Salesforce | B1: Canonical | C1: Qube
A2: AST | B2: AST | C2: AST
A3: Non-Housing (Company) | B3: COL | C3: Comp-Let
A4: Live Work | B4: ALW | C4: Live Work
A5: Parking Licence | B5: LIC | C5: Licence
A6: Shed Licence | B6: LIC | C6: Licence
A7: Occupation Licence | B7: LIC | C7: Licence
