Workbook

Sheet Import
A1: ID | B1: _Tenure__c | C1: Tenure__c
A2: a1G4J0000025tShUAI | B2: Sold | C2: =IFERROR(VLOOKUP(B2, Mapping!A:B, 2, FALSE), B2) -> Sold
A3: a1G4J0000025tSmUAI | B3: Sold | C3: =IFERROR(VLOOKUP(B3, Mapping!A:B, 2, FALSE), B3) -> Sold
A4: a1G4J0000025tSnUAI | B4: ChiefRent | C4: =IFERROR(VLOOKUP(B4, Mapping!A:B, 2, FALSE), B4) -> ChiefRent
A5: a1G4J0000025tSrUAI | B5: Sold | C5: =IFERROR(VLOOKUP(B5, Mapping!A:B, 2, FALSE), B5) -> Sold
A6: a1G4J0000025tSsUAI | B6: Sold | C6: =IFERROR(VLOOKUP(B6, Mapping!A:B, 2, FALSE), B6) -> Sold
A7: a1G4J0000025tStUAI | B7: Sold | C7: =IFERROR(VLOOKUP(B7, Mapping!A:B, 2, FALSE), B7) -> Sold
A8: a1G4J0000025tSwUAI | B8: Sold | C8: =IFERROR(VLOOKUP(B8, Mapping!A:B, 2, FALSE), B8) -> Sold
A9: a1G4J0000025tSxUAI | B9: Sold | C9: =IFERROR(VLOOKUP(B9, Mapping!A:B, 2, FALSE), B9) -> Sold
A10: a1G4J0000025tSyUAI | B10: Regulated | C10: =IFERROR(VLOOKUP(B10, Mapping!A:B, 2, FALSE), B10) -> Regulated
A11: a1G4J0000025tSzUAI | B11: Sold | C11: =IFERROR(VLOOKUP(B11, Mapping!A:B, 2, FALSE), B11) -> Sold
A12: a1G4J0000025tT0UAI | B12: Grnd Rent | C12: =IFERROR(VLOOKUP(B12, Mapping!A:B, 2, FALSE), B12) -> Grnd Rent
A13: a1G4J0000025tT1UAI | B13: Sold | C13: =IFERROR(VLOOKUP(B13, Mapping!A:B, 2, FALSE), B13) -> Sold
... A10517: a1G4J0000025xSlUAI | B10517: Sold | C10517: =IFERROR(VLOOKUP(B10517, Mapping!A:B, 2, FALSE), B10517) -> Sold
A10518: a1G4J0000025xSmUAI | B10518: #N/A | C10518: =IFERROR(VLOOKUP(B10518, Mapping!A:B, 2, FALSE), B10518) -> #N/A
A10519: a1G4J0000025xSnUAI | B10519: AST | C10519: =IFERROR(VLOOKUP(B10519, Mapping!A:B, 2, FALSE), B10519) -> AST
A10520: a1G4J0000025xSqUAI | B10520: Dummy | C10520: =IFERROR(VLOOKUP(B10520, Mapping!A:B, 2, FALSE), B10520) -> Dummy
A10521: a1G4J0000025xSrUAI | B10521: Dummy | C10521: =IFERROR(VLOOKUP(B10521, Mapping!A:B, 2, FALSE), B10521) -> Dummy
A10522: a1G4J0000025xSsUAI | B10522: Sold | C10522: =IFERROR(VLOOKUP(B10522, Mapping!A:B, 2, FALSE), B10522) -> Sold
A10523: a1G4J0000025xStUAI | B10523: Sold | C10523: =IFERROR(VLOOKUP(B10523, Mapping!A:B, 2, FALSE), B10523) -> Sold
A10524: a1G4J0000025xSuUAI | B10524: Sold | C10524: =IFERROR(VLOOKUP(B10524, Mapping!A:B, 2, FALSE), B10524) -> Sold
A10525: a1G4J0000025xSvUAI | B10525: Sh Owner | C10525: =IFERROR(VLOOKUP(B10525, Mapping!A:B, 2, FALSE), B10525) -> Sh Owner
A10526: a1G4J0000025xSwUAI | B10526: Aff Rent | C10526: =IFERROR(VLOOKUP(B10526, Mapping!A:B, 2, FALSE), B10526) -> Aff Rent
A10527: a1G4J0000025xSxUAI | B10527: Sold | C10527: =IFERROR(VLOOKUP(B10527, Mapping!A:B, 2, FALSE), B10527) -> Sold
A10528: a1G4J0000025xSyUAI | B10528: Sold | C10528: =IFERROR(VLOOKUP(B10528, Mapping!A:B, 2, FALSE), B10528) -> Sold
A10529: a1G4J0000025xSzUAI | B10529: Sold | C10529: =IFERROR(VLOOKUP(B10529, Mapping!A:B, 2, FALSE), B10529) -> Sold
A10530: a1G4J0000025xT0UAI | B10530: Dummy | C10530: =IFERROR(VLOOKUP(B10530, Mapping!A:B, 2, FALSE), B10530) -> Dummy
... A10684: a1G4J0000025xWCUAY | B10684: EstateChg | C10684: =IFERROR(VLOOKUP(B10684, Mapping!A:B, 2, FALSE), B10684) -> EstateChg
A10685: a1G4J0000025xWDUAY | B10685: #N/A | C10685: =IFERROR(VLOOKUP(B10685, Mapping!A:B, 2, FALSE), B10685) -> #N/A
A10686: a1G4J0000025xWEUAY | B10686: Aff Rent | C10686: =IFERROR(VLOOKUP(B10686, Mapping!A:B, 2, FALSE), B10686) -> Aff Rent
A10687: a1G4J0000025xWFUAY | B10687: Sold | C10687: =IFERROR(VLOOKUP(B10687, Mapping!A:B, 2, FALSE), B10687) -> Sold
A10688: a1G4J0000025xWGUAY | B10688: Sold | C10688: =IFERROR(VLOOKUP(B10688, Mapping!A:B, 2, FALSE), B10688) -> Sold
A10689: a1G4J0000025xWHUAY | B10689: Grnd Rent | C10689: =IFERROR(VLOOKUP(B10689, Mapping!A:B, 2, FALSE), B10689) -> Grnd Rent
A10690: a1G4J0000025xWIUAY | B10690: Nil GR | C10690: =IFERROR(VLOOKUP(B10690, Mapping!A:B, 2, FALSE), B10690) -> Nil GR
A10691: a1G4J0000025xWJUAY | B10691: Aff Rent | C10691: =IFERROR(VLOOKUP(B10691, Mapping!A:B, 2, FALSE), B10691) -> Aff Rent
A10692: a1G4J0000025xWKUAY | B10692: Regulated | C10692: =IFERROR(VLOOKUP(B10692, Mapping!A:B, 2, FALSE), B10692) -> Regulated
A10693: a1G4J0000025xWLUAY | B10693: Sold | C10693: =IFERROR(VLOOKUP(B10693, Mapping!A:B, 2, FALSE), B10693) -> Sold
A10694: a1G4J0000025xWMUAY | B10694: Sold | C10694: =IFERROR(VLOOKUP(B10694, Mapping!A:B, 2, FALSE), B10694) -> Sold
A10695: a1G4J0000025xWNUAY | B10695: Sold | C10695: =IFERROR(VLOOKUP(B10695, Mapping!A:B, 2, FALSE), B10695) -> Sold
A10696: a1G4J0000025xWOUAY | B10696: Sh Owner | C10696: =IFERROR(VLOOKUP(B10696, Mapping!A:B, 2, FALSE), B10696) -> Sh Owner
...

Sheet Mapping
A1: Gr Lets | B1: DMR | C1: Gr Lets | D1: =IFERROR(VLOOKUP(C1, Mapping!A:B, 2, FALSE), C1) -> DMR
A2: DMR-AST | B2: DMR-SOC | C2: DMR-AST | D2: =IFERROR(VLOOKUP(C2, Mapping!A:B, 2, FALSE), C2) -> DMR-SOC

Sheet Excluded
A1: ID | B1: _Tenure__c | C1: Tenure__c
A2: Missing | B2: Vacant | C2: Vacant
A3: Missing | B3: Vacant | C3: Vacant
A4: Missing | B4: Insurance | C4: Insurance
A5: Missing | B5: Vacant | C5: Vacant
A6: Missing | B6: Vacant | C6: Vacant
A7: Missing | B7: CommLease | C7: CommLease
A8: Missing | B8: Vacant | C8: Vacant
A9: Missing | B9: Vacant | C9: Vacant
A10: Missing | B10: CommLease | C10: CommLease
A11: Missing | B11: Vacant | C11: Vacant
A12: Missing | B12: Vacant | C12: Vacant
... A66: Missing | B66: Land | C66: Land

Sheet imported
A1: ID | B1: _Tenure__c | C1: Tenure__c | D1: __Status | E1: __Id | F1: __Action | G1: __Errors
A2: a1G4J0000025tShUAI | B2: Sold | C2: Sold | D2: Succeeded | E2: a1G4J0000025tShUAI | F2: Updated
A3: a1G4J0000025tSmUAI | B3: Sold | C3: Sold | D3: Succeeded | E3: a1G4J0000025tSmUAI | F3: Updated
A4: a1G4J0000025tSnUAI | B4: ChiefRent | C4: ChiefRent | D4: Succeeded | E4: a1G4J0000025tSnUAI | F4: Updated
A5: a1G4J0000025tSrUAI | B5: Sold | C5: Sold | D5: Succeeded | E5: a1G4J0000025tSrUAI | F5: Updated
A6: a1G4J0000025tSsUAI | B6: Sold | C6: Sold | D6: Succeeded | E6: a1G4J0000025tSsUAI | F6: Updated
A7: a1G4J0000025tStUAI | B7: Sold | C7: Sold | D7: Succeeded | E7: a1G4J0000025tStUAI | F7: Updated
A8: a1G4J0000025tSwUAI | B8: Sold | C8: Sold | D8: Succeeded | E8: a1G4J0000025tSwUAI | F8: Updated
A9: a1G4J0000025tSxUAI | B9: Sold | C9: Sold | D9: Succeeded | E9: a1G4J0000025tSxUAI | F9: Updated
A10: a1G4J0000025tSyUAI | B10: Regulated | C10: Regulated | D10: Succeeded | E10: a1G4J0000025tSyUAI | F10: Updated
A11: a1G4J0000025tSzUAI | B11: Sold | C11: Sold | D11: Succeeded | E11: a1G4J0000025tSzUAI | F11: Updated
A12: a1G4J0000025tT0UAI | B12: Grnd Rent | C12: Grnd Rent | D12: Succeeded | E12: a1G4J0000025tT0UAI | F12: Updated
A13: a1G4J0000025tT1UAI | B13: Sold | C13: Sold | D13: Succeeded | E13: a1G4J0000025tT1UAI | F13: Updated
... A28085: a1GNz000003NbGTMA0 | B28085: Aff Rent | C28085: Aff Rent | D28085: Succeeded | E28085: a1GNz000003NbGTMA0 | F28085: Updated

Sheet Kick Outs
A1: ID | B1: _Tenure__c | C1: Tenure__c | D1: __Status | E1: __Id | F1: __Action | G1: __Errors
A2: a1G4J0000025tUqUAI | B2: Vac-A | C2: Vac-A | D2: Failed | E2: a1G4J0000025tUqUAI | G2: INVALID_OR_NULL_FOR_RESTRICTED_PICKLIST: Tenure: bad value for restricted picklist field: Vac-A [Tenure__c]
A3: a1G4J0000025tUsUAI | B3: Vac-A | C3: Vac-A | D3: Failed | E3: a1G4J0000025tUsUAI | G3: INVALID_OR_NULL_FOR_RESTRICTED_PICKLIST: Tenure: bad value for restricted picklist field: Vac-A [Tenure__c]
A4: a1G4J0000025tVAUAY | B4: Dummy | C4: Dummy | D4: Failed | E4: a1G4J0000025tVAUAY | G4: INVALID_OR_NULL_FOR_RESTRICTED_PICKLIST: Tenure: bad value for restricted picklist field: Dummy [Tenure__c]
A5: a1G4J0000025tWKUAY | B5: Vac-A | C5: Vac-A | D5: Failed | E5: a1G4J0000025tWKUAY | G5: INVALID_OR_NULL_FOR_RESTRICTED_PICKLIST: Tenure: bad value for restricted picklist field: Vac-A [Tenure__c]
A6: a1G4J0000025tWZUAY | B6: Vac-A | C6: Vac-A | D6: Failed | E6: a1G4J0000025tWZUAY | G6: INVALID_OR_NULL_FOR_RESTRICTED_PICKLIST: Tenure: bad value for restricted picklist field: Vac-A [Tenure__c]
A7: a1G4J0000025tWdUAI | B7: Vac-A | C7: Vac-A | D7: Failed | E7: a1G4J0000025tWdUAI | G7: INVALID_OR_NULL_FOR_RESTRICTED_PICKLIST: Tenure: bad value for restricted picklist field: Vac-A [Tenure__c]
A8: a1G4J0000025tWtUAI | B8: Vac-A | C8: Vac-A | D8: Failed | E8: a1G4J0000025tWtUAI | G8: INVALID_OR_NULL_FOR_RESTRICTED_PICKLIST: Tenure: bad value for restricted picklist field: Vac-A [Tenure__c]
A9: a1G4J0000025tX8UAI | B9: Vac-A | C9: Vac-A | D9: Failed | E9: a1G4J0000025tX8UAI | G9: INVALID_OR_NULL_FOR_RESTRICTED_PICKLIST: Tenure: bad value for restricted picklist field: Vac-A [Tenure__c]
A10: a1G4J0000025tXIUAY | B10: Vac-A | C10: Vac-A | D10: Failed | E10: a1G4J0000025tXIUAY | G10: INVALID_OR_NULL_FOR_RESTRICTED_PICKLIST: Tenure: bad value for restricted picklist field: Vac-A [Tenure__c]
A11: a1G4J0000025tXSUAY | B11: Vac-A | C11: Vac-A | D11: Failed | E11: a1G4J0000025tXSUAY | G11: INVALID_OR_NULL_FOR_RESTRICTED_PICKLIST: Tenure: bad value for restricted picklist field: Vac-A [Tenure__c]
A12: a1G4J0000025tdOUAQ | B12: Land | C12: Land | D12: Failed | E12: a1G4J0000025tdOUAQ | G12: INVALID_OR_NULL_FOR_RESTRICTED_PICKLIST: Tenure: bad value for restricted picklist field: Land [Tenure__c]
A13: a1G4J0000025tdrUAA | B13: Vac-A | C13: Vac-A | D13: Failed | E13: a1G4J0000025tdrUAA | G13: INVALID_OR_NULL_FOR_RESTRICTED_PICKLIST: Tenure: bad value for restricted picklist field: Vac-A [Tenure__c]
... A652: a1G4J0000025xSgUAI | B652: Dummy | C652: Dummy | D652: Failed | E652: a1G4J0000025xSgUAI | G652: INVALID_OR_NULL_FOR_RESTRICTED_PICKLIST: Tenure: bad value for restricted picklist field: Dummy [Tenure__c]
A653: a1G4J0000025xSmUAI | B653: #N/A | C653: #N/A | D653: Failed | E653: a1G4J0000025xSmUAI | G653: INVALID_OR_NULL_FOR_RESTRICTED_PICKLIST: Tenure: bad value for restricted picklist field: #N/A [Tenure__c]
A654: a1G4J0000025xSqUAI | B654: Dummy | C654: Dummy | D654: Failed | E654: a1G4J0000025xSqUAI | G654: INVALID_OR_NULL_FOR_RESTRICTED_PICKLIST: Tenure: bad value for restricted picklist field: Dummy [Tenure__c]
A655: a1G4J0000025xSrUAI | B655: Dummy | C655: Dummy | D655: Failed | E655: a1G4J0000025xSrUAI | G655: INVALID_OR_NULL_FOR_RESTRICTED_PICKLIST: Tenure: bad value for restricted picklist field: Dummy [Tenure__c]
A656: a1G4J0000025xT0UAI | B656: Dummy | C656: Dummy | D656: Failed | E656: a1G4J0000025xT0UAI | G656: INVALID_OR_NULL_FOR_RESTRICTED_PICKLIST: Tenure: bad value for restricted picklist field: Dummy [Tenure__c]
A657: a1G4J0000025xT5UAI | B657: Dummy | C657: Dummy | D657: Failed | E657: a1G4J0000025xT5UAI | G657: INVALID_OR_NULL_FOR_RESTRICTED_PICKLIST: Tenure: bad value for restricted picklist field: Dummy [Tenure__c]
A658: a1G4J0000025xTAUAY | B658: Dummy | C658: Dummy | D658: Failed | E658: a1G4J0000025xTAUAY | G658: INVALID_OR_NULL_FOR_RESTRICTED_PICKLIST: Tenure: bad value for restricted picklist field: Dummy [Tenure__c]
A659: a1G4J0000025xTFUAY | B659: Dummy | C659: Dummy | D659: Failed | E659: a1G4J0000025xTFUAY | G659: INVALID_OR_NULL_FOR_RESTRICTED_PICKLIST: Tenure: bad value for restricted picklist field: Dummy [Tenure__c]
A660: a1G4J0000025xTKUAY | B660: Dummy | C660: Dummy | D660: Failed | E660: a1G4J0000025xTKUAY | G660: INVALID_OR_NULL_FOR_RESTRICTED_PICKLIST: Tenure: bad value for restricted picklist field: Dummy [Tenure__c]
A661: a1G4J0000025xTPUAY | B661: Dummy | C661: Dummy | D661: Failed | E661: a1G4J0000025xTPUAY | G661: INVALID_OR_NULL_FOR_RESTRICTED_PICKLIST: Tenure: bad value for restricted picklist field: Dummy [Tenure__c]
A662: a1G4J0000025xTUUAY | B662: Dummy | C662: Dummy | D662: Failed | E662: a1G4J0000025xTUUAY | G662: INVALID_OR_NULL_FOR_RESTRICTED_PICKLIST: Tenure: bad value for restricted picklist field: Dummy [Tenure__c]
A663: a1G4J0000025xTZUAY | B663: Dummy | C663: Dummy | D663: Failed | E663: a1G4J0000025xTZUAY | G663: INVALID_OR_NULL_FOR_RESTRICTED_PICKLIST: Tenure: bad value for restricted picklist field: Dummy [Tenure__c]
A664: a1G4J0000025xTeUAI | B664: Dummy | C664: Dummy | D664: Failed | E664: a1G4J0000025xTeUAI | G664: INVALID_OR_NULL_FOR_RESTRICTED_PICKLIST: Tenure: bad value for restricted picklist field: Dummy [Tenure__c]
A665: a1G4J0000025xTjUAI | B665: Dummy | C665: Dummy | D665: Failed | E665: a1G4J0000025xTjUAI | G665: INVALID_OR_NULL_FOR_RESTRICTED_PICKLIST: Tenure: bad value for restricted picklist field: Dummy [Tenure__c]
... A674: a1G4J0000025xUcUAI | B674: Dummy | C674: Dummy | D674: Failed | E674: a1G4J0000025xUcUAI | G674: INVALID_OR_NULL_FOR_RESTRICTED_PICKLIST: Tenure: bad value for restricted picklist field: Dummy [Tenure__c]
A675: a1G4J0000025xWDUAY | B675: #N/A | C675: #N/A | D675: Failed | E675: a1G4J0000025xWDUAY | G675: INVALID_OR_NULL_FOR_RESTRICTED_PICKLIST: Tenure: bad value for restricted picklist field: #N/A [Tenure__c]
A676: a1G4J0000025xXBUAY | B676: #N/A | C676: #N/A | D676: Failed | E676: a1G4J0000025xXBUAY | G676: INVALID_OR_NULL_FOR_RESTRICTED_PICKLIST: Tenure: bad value for restricted picklist field: #N/A [Tenure__c]
A677: a1G4J0000025xh7UAA | B677: Vac-A | C677: Vac-A | D677: Failed | E677: a1G4J0000025xh7UAA | G677: INVALID_OR_NULL_FOR_RESTRICTED_PICKLIST: Tenure: bad value for restricted picklist field: Vac-A [Tenure__c]
A678: a1G4J0000025xtvUAA | B678: #N/A | C678: #N/A | D678: Failed | E678: a1G4J0000025xtvUAA | G678: INVALID_OR_NULL_FOR_RESTRICTED_PICKLIST: Tenure: bad value for restricted picklist field: #N/A [Tenure__c]
A679: a1G4J0000025xvZUAQ | B679: #N/A | C679: #N/A | D679: Failed | E679: a1G4J0000025xvZUAQ | G679: INVALID_OR_NULL_FOR_RESTRICTED_PICKLIST: Tenure: bad value for restricted picklist field: #N/A [Tenure__c]
A680: a1G4J0000025y2iUAA | B680: #N/A | C680: #N/A | D680: Failed | E680: a1G4J0000025y2iUAA | G680: INVALID_OR_NULL_FOR_RESTRICTED_PICKLIST: Tenure: bad value for restricted picklist field: #N/A [Tenure__c]
A681: a1G4J0000025y9YUAQ | B681: VAC-MW | C681: VAC-MW | D681: Failed | E681: a1G4J0000025y9YUAQ | G681: INVALID_OR_NULL_FOR_RESTRICTED_PICKLIST: Tenure: bad value for restricted picklist field: VAC-MW [Tenure__c]
A682: a1G4J0000025yFwUAI | B682: VAC-MW | C682: VAC-MW | D682: Failed | E682: a1G4J0000025yFwUAI | G682: INVALID_OR_NULL_FOR_RESTRICTED_PICKLIST: Tenure: bad value for restricted picklist field: VAC-MW [Tenure__c]
A683: a1G4J0000025yI9UAI | B683: VAC-MW | C683: VAC-MW | D683: Failed | E683: a1G4J0000025yI9UAI | G683: INVALID_OR_NULL_FOR_RESTRICTED_PICKLIST: Tenure: bad value for restricted picklist field: VAC-MW [Tenure__c]
A684: a1G4J0000025yIoUAI | B684: VAC-MW | C684: VAC-MW | D684: Failed | E684: a1G4J0000025yIoUAI | G684: INVALID_OR_NULL_FOR_RESTRICTED_PICKLIST: Tenure: bad value for restricted picklist field: VAC-MW [Tenure__c]
A685: a1G4J0000025yJiUAI | B685: #N/A | C685: #N/A | D685: Failed | E685: a1G4J0000025yJiUAI | G685: INVALID_OR_NULL_FOR_RESTRICTED_PICKLIST: Tenure: bad value for restricted picklist field: #N/A [Tenure__c]
A686: a1G4J0000025yKJUAY | B686: Dummy | C686: Dummy | D686: Failed | E686: a1G4J0000025yKJUAY | G686: INVALID_OR_NULL_FOR_RESTRICTED_PICKLIST: Tenure: bad value for restricted picklist field: Dummy [Tenure__c]
...
