Workbook

Sheet Apartments
A1: Diary Status | B1: Event month | C1: Event Date | D1: Portfolio | E1: Estate | F1: Unit Manager | G1: Unit Description | H1: Current Tenant Name | I1: PM Details | J1: Tenancy Status | K1: Tenancy Start Date | L1: Lease Start Date | M1: Lease End Date | N1: Action Type | O1: Unit Tenure | P1: September 23 Annual ERV | Q1: September 23 Monthly ERV | R1: March 24 Annual ERV | S1: March 24 Monthly ERV | T1: Current Annual Rent | U1: Current Monthly Rent | V1: Previous Rent | W1: Price Book Rent | X1: NEW PRICE BOOK RENT | Y1: NEW Price book rent /current rent % | Z1: Price Book / Current Rent % | AA1: Price Book / March 24 ERV % | AB1: AM Offering | AC1: AM Offering / Current Rent % | AD1: AM Offering / March 24 ERV % | AE1: AM Minimum | AF1: AM Minimum / Current Rent % | AG1: AM Minimum / March ERV % | AH1: AM Comments | AI1: Tenant Balance Status | AJ1: Unit Size | AK1: Beds | AL1: Baths | AM1: Description of Unit | AN1: rent acheived | AO1: Rent Acheived % | AP1: Renewal Neg | AQ1: Renewal Status | AR1: Renewal notes
A2: Active | B2: =TEXT(C2,"mmmm") -> August | C2: 45520 | D2: BTR-London & SE | E2: Abbeville Apartments | F2: Fatma Azakli | G2: Apt 308, Abbeville Apts, 37 London Rd, Barkin | H2: Mr Mayank Jha and Mrs Tanisha Prasad | I2: N/A | J2: Current | K2: 44790 | L2: 45155 | M2: 45520 | N2: Renewal | O2: AST | P2: 17880 | Q2: 2024 | R2: 18480 | S2: 2025 | T2: 18000 | U2: 1950 | V2: 0 | W2: 2058 | Z2: =(W2-U2)/U2 -> 0.055384615 | AA2: =(W2-S2)/S2 -> 0.016296296 | AB2: 2058 | AC2: =(AB2-U2)/U2 -> 0.055384615 | AD2: =(AB2-S2)/S2 -> 0.016296296 | AE2: 1900 | AF2: =(AE2-U2)/U2 -> -0.025641026 | AG2: =(AE2-S2)/S2 -> -0.061728395 | AI2: Cleared | AJ2: 574 | AK2: 1 | AL2: 1 | AM2: 1 Bed, Third Floor, Furnished1 Bathrooms | AO2: =SUM(AN2-U2)/U2 -> -1 | AP2: Jemma | AQ2: Sent
A3: Active | B3: =TEXT(C3,"mmmm") -> August | C3: 45527 | D3: BTR-London & SE | E3: Abbeville Apartments | F3: Fatma Azakli | G3: Apt 207, Abbeville Apts, 37 London Rd, Barkin | H3: Mr Edavalath Binesh & Mrs Sangeetha Binesh | I3: N/A | J3: Current | K3: 43701 | L3: 45162 | M3: 45527 | N3: Renewal | O3: AST | P3: 17796 | Q3: 1483 | R3: 18180 | S3: =R3/12 -> 1515 | T3: 17040 | U3: =T3/12 -> 1420 | V3: 15780 | W3: 1600 | Z3: =(W3-U3)/U3 -> 0.12676056 | AA3: =(W3-S3)/S3 -> 0.056105611 | AB3: 1540 | AC3: =(AB3-U3)/U3 -> 0.084507042 | AD3: =(AB3-S3)/S3 -> 0.01650165 | AE3: 1515 | AF3: =(AE3-U3)/U3 -> 0.066901408 | AG3: =(AE3-S3)/S3 -> 0 | AI3: Arrears | AJ3: 538 | AK3: 1 | AL3: 1 | AM3: 1 Bed, Second Floor, Furnished1 Bathrooms | AO3: =SUM(AN3-U3)/U3 -> -1 | AP3: Jemma | AQ3: NTQ
A4: Active | B4: =TEXT(C4,"mmmm") -> July | C4: 45479 | D4: BTR-London & SE | E4: Abbeville Apartments | F4: Fatma Azakli | G4: Apt 113, Abbeville Apts, 37 London Rd, Barkin | H4: Nishat Anjum & Khawaja Hassan Munir | I4: N/A | J4: Current | K4: 45114 | L4: 45114 | M4: 45479 | N4: New Let | O4: AST | P4: 17796 | Q4: 1483 | R4: 18180 | S4: =R4/12 -> 1515 | T4: 18120 | U4: =T4/12 -> 1510 | V4: 16680 | W4: 1640 | Z4: =(W4-U4)/U4 -> 0.086092715 | AA4: =(W4-S4)/S4 -> 0.082508251 | AB4: 1625 | AC4: =(AB4-U4)/U4 -> 0.07615894 | AD4: =(AB4-S4)/S4 -> 0.072607261 | AE4: 1600 | AF4: =(AE4-U4)/U4 -> 0.059602649 | AG4: =(AE4-S4)/S4 -> 0.056105611 | AI4: Cleared | AJ4: 538 | AK4: 1 | AL4: 1 | AM4: 1 Bed, First Floor, Furnished1 Bathrooms | AN4: 1600 | AO4: =SUM(AN4-U4)/U4 -> 0.059602649 | AP4: Jemma | AQ4: Sent
A5: Active | B5: =TEXT(C5,"mmmm") -> July | C5: 45482 | D5: BTR-London & SE | E5: Abbeville Apartments | F5: Fatma Azakli | G5: Apt 208, Abbeville Apts, 37 London Rd, Barkin | H5: Miss Batul Abbas & Mr Durani Prasonna Vijayan | I5: N/A | J5: Current | K5: 43291 | L5: 45117 | M5: 45482 | N5: Renewal | O5: AST | P5: 17880 | Q5: 1490 | R5: 18480 | S5: =R5/12 -> 1540 | T5: 17100 | U5: =T5/12 -> 1425 | V5: 15759 | W5: 1600 | Z5: =(W5-U5)/U5 -> 0.12280702 | AA5: =(W5-S5)/S5 -> 0.038961039 | AB5: 1575 | AC5: =(AB5-U5)/U5 -> 0.10526316 | AD5: =(AB5-S5)/S5 -> 0.022727273 | AE5: 1540 | AF5: =(AE5-U5)/U5 -> 0.080701754 | AG5: =(AE5-S5)/S5 -> 0 | AI5: Cleared | AJ5: 574 | AK5: 1 | AL5: 1 | AM5: 1 Bed, Second Floor, Furnished1 Bathrooms | AN5: 1540 | AO5: =SUM(AN5-U5)/U5 -> 0.080701754 | AP5: Jemma | AQ5: Sent
A6: Active | B6: =TEXT(C6,"mmmm") -> July | C6: 45490 | D6: BTR-London & SE | E6: Abbeville Apartments | F6: Fatma Azakli | G6: Apt 313, Abbeville Apts, 37 London Rd, Barkin | H6: Mohamed Khelloufi & Assia Al Jerrari | I6: N/A | J6: Current | K6: 45125 | L6: 45125 | M6: 45490 | N6: New Let | O6: AST | P6: 17796 | Q6: 1483 | R6: 18180 | S6: =R6/12 -> 1515 | T6: 18600 | U6: =T6/12 -> 1550 | V6: 17100 | W6: 1630 | Z6: =(W6-U6)/U6 -> 0.051612903 | AA6: =(W6-S6)/S6 -> 0.075907591 | AB6: 1650 | AC6: =(AB6-U6)/U6 -> 0.064516129 | AD6: =(AB6-S6)/S6 -> 0.089108911 | AE6: 1625 | AF6: =(AE6-U6)/U6 -> 0.048387097 | AG6: =(AE6-S6)/S6 -> 0.072607261 | AI6: Cleared | AJ6: 538 | AK6: 1 | AL6: 1 | AM6: 1 Bed, Third Floor, Furnished1 Bathrooms | AO6: =SUM(AN6-U6)/U6 -> -1 | AP6: Jemma | AQ6: Sent
A7: Active | B7: =TEXT(C7,"mmmm") -> July | C7: 45474 | D7: BTR-London & SE | E7: Abbeville Apartments | F7: Fatma Azakli | G7: Apt 402, Abbeville Apts, 37 London Rd, Barkin | H7: Mandy-Liza Lehnert,J Sowah,Elletina Mekkaoui | I7: N/A | J7: Current | K7: 44014 | L7: 45109 | M7: 45474 | N7: Renewal | O7: AST | P7: 24000 | Q7: 2000 | R7: 25656 | S7: =R7/12 -> 2138 | T7: 23700 | U7: =T7/12 -> 1975 | V7: 22740 | W7: 2150 | Z7: =(W7-U7)/U7 -> 0.088607595 | AA7: =(W7-S7)/S7 -> 0.0056127222 | AB7: 2150 | AC7: =(AB7-U7)/U7 -> 0.088607595 | AD7: =(AB7-S7)/S7 -> 0.0056127222 | AE7: 2140 | AF7: =(AE7-U7)/U7 -> 0.083544304 | AG7: =(AE7-S7)/S7 -> 0.0009354537 | AI7: Credit | AJ7: 958 | AK7: 3 | AL7: 2 | AM7: 3 Bed, Forth Floor, Furnished2 Bathrooms | AO7: =SUM(AN7-U7)/U7 -> -1 | AP7: Jemma | AQ7: Sent
A8: Active | B8: =TEXT(C8,"mmmm") -> July | C8: 45497 | D8: BTR-London & SE | E8: Abbeville Apartments | F8: Fatma Azakli | G8: Apt 405, Abbeville Apts, 37 London Rd, Barkin | H8: Dr Anusuya Rajendran | I8: N/A | J8: Current | K8: 43671 | L8: 45132 | M8: 45497 | N8: Renewal | O8: AST | P8: 17796 | Q8: 1483 | R8: 18180 | S8: =R8/12 -> 1515 | T8: 17280 | U8: =T8/12 -> 1440 | V8: 15840 | W8: 1620 | Z8: =(W8-U8)/U8 -> 0.125 | AA8: =(W8-S8)/S8 -> 0.069306931 | AB8: 1575 | AC8: =(AB8-U8)/U8 -> 0.09375 | AD8: =(AB8-S8)/S8 -> 0.03960396 | AE8: 1540 | AF8: =(AE8-U8)/U8 -> 0.069444444 | AG8: =(AE8-S8)/S8 -> 0.01650165 | AI8: Cleared | AJ8: 538 | AK8: 1 | AL8: 1 | AM8: 1 Bed, Forth Floor, Furnished1 Bathrooms | AN8: 1540 | AO8: =SUM(AN8-U8)/U8 -> 0.069444444 | AP8: Jemma | AQ8: Sent
A9: Active | B9: =TEXT(C9,"mmmm") -> July | C9: 45499 | D9: BTR-London & SE | E9: Abbeville Apartments | F9: Fatma Azakli | G9: Apt 409, Abbeville Apts, 37 London Rd, Barkin | H9: Amrita Poojari and Raghavendra Poojari | I9: N/A | J9: Current | K9: 44769 | L9: 45134 | M9: 45499 | N9: Renewal | O9: AST | P9: 17796 | Q9: 1483 | R9: 18180 | S9: =R9/12 -> 1515 | T9: 17400 | U9: =T9/12 -> 1450 | V9: 16080 | W9: 1600 | Z9: =(W9-U9)/U9 -> 0.10344828 | AA9: =(W9-S9)/S9 -> 0.056105611 | AB9: 1575 | AC9: =(AB9-U9)/U9 -> 0.086206897 | AD9: =(AB9-S9)/S9 -> 0.03960396 | AE9: 1535 | AF9: =(AE9-U9)/U9 -> 0.05862069 | AG9: =(AE9-S9)/S9 -> 0.01320132 | AI9: Cleared | AJ9: 538 | AK9: 1 | AL9: 1 | AM9: 1 Bed, Forth Floor, Furnished1 Bathrooms | AN9: 1535 | AO9: =SUM(AN9-U9)/U9 -> 0.05862069 | AP9: Jemma | AQ9: Sent
A10: Active | B10: =TEXT(C10,"mmmm") -> July | C10: 45487 | D10: BTR-London & SE | E10: Abbeville Apartments | F10: Fatma Azakli | G10: Apt 412, Abbeville Apts, 37 London Rd, Barkin | H10: Rakesh Singh & Rekha Kumari | I10: N/A | J10: Current | K10: 44392 | L10: 45122 | M10: 45487 | N10: Renewal | O10: AST | P10: 20100 | Q10: 1675 | R10: 21480 | S10: =R10/12 -> 1790 | T10: 19560 | U10: =T10/12 -> 1630 | V10: 17940 | W10: 1890 | Z10: =(W10-U10)/U10 -> 0.1595092 | AA10: =(W10-S10)/S10 -> 0.055865922 | AB10: 1835 | AC10: =(AB10-U10)/U10 -> 0.12576687 | AD10: =(AB10-S10)/S10 -> 0.025139665 | AE10: 1800 | AF10: =(AE10-U10)/U10 -> 0.10429448 | AG10: =(AE10-S10)/S10 -> 0.0055865922 | AI10: Cleared | AJ10: 661 | AK10: 2 | AL10: 1 | AM10: 2 Bed, Forth Floor, Furnished1 Bathrooms | AO10: =SUM(AN10-U10)/U10 -> -1 | AP10: Jemma | AQ10: Sent
A11: Active | B11: =TEXT(C11,"mmmm") -> July | C11: 45485 | D11: BTR-London & SE | E11: Abbeville Apartments | F11: Fatma Azakli | G11: Apt 509, Abbeville Apts, 37 London Rd, Barkin | H11: Ms Sarah Gifford & Mr Wayne Brown | I11: N/A | J11: Current | K11: 42198 | L11: 45120 | M11: 45485 | N11: Renewal | O11: AST | P11: 17916 | Q11: 1493 | R11: 18180 | S11: =R11/12 -> 1515 | T11: 17580 | U11: =T11/12 -> 1465 | V11: 15744 | W11: 1610 | Z11: =(W11-U11)/U11 -> 0.098976109 | AA11: =(W11-S11)/S11 -> 0.062706271 | AB11: 1575 | AC11: =(AB11-U11)/U11 -> 0.075085324 | AD11: =(AB11-S11)/S11 -> 0.03960396 | AE11: 1540 | AF11: =(AE11-U11)/U11 -> 0.051194539 | AG11: =(AE11-S11)/S11 -> 0.01650165 | AI11: Cleared | AJ11: 538 | AK11: 1 | AL11: 1 | AM11: 1 Bed, Fifth Floor, Furnished1 Bathrooms | AN11: 1540 | AO11: =SUM(AN11-U11)/U11 -> 0.051194539 | AP11: Jemma | AQ11: Sent
A12: Active | B12: =TEXT(C12,"mmmm") -> August | C12: 45528 | D12: BTR-London & SE | E12: Abbeville Apartments | F12: Fatma Azakli | G12: Apt 609, Abbeville Apts, 37 London Rd, Barkin | H12: Arinze Sunday Ogbonna & Adriana Roccalumera | I12: N/A | J12: Current | K12: 45163 | L12: 45163 | M12: 45528 | N12: New Let | O12: AST | P12: 18000 | Q12: 1500 | R12: 18180 | S12: =R12/12 -> 1515 | T12: 18600 | U12: =T12/12 -> 1550 | V12: 16680 | W12: 1620 | Z12: =(W12-U12)/U12 -> 0.04516129 | AA12: =(W12-S12)/S12 -> 0.069306931 | AB12: 1630 | AC12: =(AB12-U12)/U12 -> 0.051612903 | AD12: =(AB12-S12)/S12 -> 0.075907591 | AE12: 1595 | AF12: =(AE12-U12)/U12 -> 0.029032258 | AG12: =(AE12-S12)/S12 -> 0.052805281 | AI12: Cleared | AJ12: 538 | AK12: 1 | AL12: 1 | AM12: 1 Bed, Sixth Floor, Furnished1 Bathrooms | AO12: =SUM(AN12-U12)/U12 -> -1 | AP12: Jemma | AQ12: Sent
A13: Pending | B13: =TEXT(C13,"mmmm") -> August | C13: 45530 | D13: BTR-London & SE | E13: Abbeville Apartments | F13: Fatma Azakli | G13: Apt 505, Abbeville Apts, 37 London Rd, Barkin | H13: Aanand Natarajan Rajahsekharun & Aditi Ravichandran | I13: N/A | J13: Current | K13: 45349 | L13: 45349 | M13: 45530 | N13: New Let | O13: AST | P13: 17916 | Q13: 1493 | R13: 18180 | S13: =R13/12 -> 1515 | T13: 18300 | U13: =T13/12 -> 1525 | V13: 16740 | W13: 1630 | Z13: =(W13-U13)/U13 -> 0.068852459 | AA13: =(W13-S13)/S13 -> 0.075907591 | AB13: 1605 | AC13: =(AB13-U13)/U13 -> 0.052459016 | AD13: =(AB13-S13)/S13 -> 0.059405941 | AE13: 1585 | AF13: =(AE13-U13)/U13 -> 0.039344262 | AG13: =(AE13-S13)/S13 -> 0.04620462 | AI13: Cleared | AJ13: 538 | AK13: 1 | AL13: 1 | AM13: 1 Bed, Fifth Floor, Furnished1 Bathrooms | AO13: =SUM(AN13-U13)/U13 -> -1 | AP13: Jemma | AQ13: Sent
A14: Active | B14: =TEXT(C14,"mmmm") -> August | C14: 45535 | D14: BTR-London & SE | E14: Abbeville Apartments | F14: Fatma Azakli | G14: Apt 104, Abbeville Apts, 37 London Rd, Barkin | H14: Mrs Durgesh Rattan Mehta | I14: This resident is our only venerable elderly woman. We deal with her daughter Veena and her details are in Qube. Happy to renew. | J14: Current | K14: 42244 | L14: 45170 | M14: 45535 | N14: Renewal | O14: AST | P14: 17796 | Q14: 1483 | R14: 18180 | S14: =R14/12 -> 1515 | T14: 17220 | U14: =T14/12 -> 1435 | V14: 15780 | W14: 1630 | Z14: =(W14-U14)/U14 -> 0.1358885 | AA14: =(W14-S14)/S14 -> 0.075907591 | AB14: 1540 | AC14: =(AB14-U14)/U14 -> 0.073170732 | AD14: =(AB14-S14)/S14 -> 0.01650165 | AE14: 1515 | AF14: =(AE14-U14)/U14 -> 0.055749129 | AG14: =(AE14-S14)/S14 -> 0 | AI14: Cleared | AJ14: 538 | AK14: 1 | AL14: 1 | AM14: 1 Bed, First Floor, Furnished1 Bathrooms | AN14: 1515 | AO14: =SUM(AN14-U14)/U14 -> 0.055749129 | AP14: Jemma | AQ14: Sent
A15: Active | B15: =TEXT(C15,"mmmm") -> August | C15: 45511 | D15: BTR-London & SE | E15: Abbeville Apartments | F15: Fatma Azakli | G15: Apt 501, Abbeville Apts, 37 London Rd, Barkin | H15: Mr Raees Patel | I15: N/A | J15: Current | K15: 44051 | L15: 45146 | M15: 45511 | N15: Renewal | O15: AST | P15: 20436 | Q15: 1703 | R15: 21696 | S15: =R15/12 -> 1808 | T15: 20160 | U15: =T15/12 -> 1680 | V15: 18840 | W15: 1890 | Z15: =(W15-U15)/U15 -> 0.125 | AA15: =(W15-S15)/S15 -> 0.045353982 | AB15: 1875 | AC15: =(AB15-U15)/U15 -> 0.11607143 | AD15: =(AB15-S15)/S15 -> 0.037057522 | AE15: 1810 | AF15: =(AE15-U15)/U15 -> 0.077380952 | AG15: =(AE15-S15)/S15 -> 0.0011061947 | AI15: Arrears | AJ15: 756 | AK15: 2 | AL15: 1 | AM15: 2 Bed, Fifth Floor, Furnished1 Bathrooms | AN15: 1810 | AO15: =SUM(AN15-U15)/U15 -> 0.077380952 | AP15: Jemma | AQ15: Sent
A16: Active | B16: =TEXT(C16,"mmmm") -> August | C16: 45524 | D16: BTR-London & SE | E16: Abbeville Apartments | F16: Fatma Azakli | G16: Apt 612, Abbeville Apts, 37 London Rd, Barkin | H16: Reece Ballett and Charlotte Hardy | I16: N/A | J16: Current | K16: 44733 | L16: 45098 | M16: 45524 | N16: Renewal | O16: AST | P16: 20280 | Q16: 1690 | R16: 21480 | S16: =R16/12 -> 1790 | T16: 20220 | U16: =T16/12 -> 1685 | V16: 19020 | W16: 1910 | Z16: =(W16-U16)/U16 -> 0.13353116 | AA16: =(W16-S16)/S16 -> 0.067039106 | AB16: 1825 | AC16: =(AB16-U16)/U16 -> 0.083086053 | AD16: =(AB16-S16)/S16 -> 0.019553073 | AE16: 1795 | AF16: =(AE16-U16)/U16 -> 0.065281899 | AG16: =(AE16-S16)/S16 -> 0.0027932961 | AI16: Cleared | AJ16: 661 | AK16: 2 | AL16: 1 | AM16: 2 Bed, Sixth Floor, Furnished1 Bathrooms | AO16: =SUM(AN16-U16)/U16 -> -1 | AP16: Jemma | AQ16: NTQ
A17: Active | B17: =TEXT(C17,"mmmm") -> August | C17: 45531 | D17: BTR-London & SE | E17: Abbeville Apartments | F17: Fatma Azakli | G17: Apt 506, Abbeville Apts, 37 London Rd, Barkin | H17: Giacomo Mazza & Angelica Mazza | I17: N/A | J17: Current | K17: 45166 | L17: 45166 | M17: 45531 | N17: New Let | O17: AST | P17: 20220 | Q17: 1685 | R17: 21480 | S17: =R17/12 -> 1790 | T17: 21420 | U17: =T17/12 -> 1785 | V17: 19800 | W17: 1890 | Z17: =(W17-U17)/U17 -> 0.058823529 | AA17: =(W17-S17)/S17 -> 0.055865922 | AB17: 1885 | AC17: =(AB17-U17)/U17 -> 0.056022409 | AD17: =(AB17-S17)/S17 -> 0.053072626 | AE17: 1860 | AF17: =(AE17-U17)/U17 -> 0.042016807 | AG17: =(AE17-S17)/S17 -> 0.039106145 | AI17: Cleared | AJ17: 660 | AK17: 2 | AL17: 1 | AM17: 2 Bed, Fifth Floor, Furnished1 Bathrooms | AN17: 1890 | AO17: =SUM(AN17-U17)/U17 -> 0.058823529 | AP17: Jemma | AQ17: signing
A18: Active | B18: =TEXT(C18,"mmmm") -> August | C18: 45535 | D18: BTR-London & SE | E18: Abbeville Apartments | F18: Fatma Azakli | G18: Apt 210, Abbeville Apts, 37 London Rd, Barkin | H18: Sateesh Mani and Gayathri Raman | I18: N/A | J18: Current | K18: 45170 | L18: 45170 | M18: 45535 | N18: New Let | O18: AST | P18: 20376 | Q18: 1698 | R18: 21756 | S18: =R18/12 -> 1813 | T18: 21000 | U18: =T18/12 -> 1750 | V18: 19440 | W18: 1920 | Z18: =(W18-U18)/U18 -> 0.097142857 | AA18: =(W18-S18)/S18 -> 0.059018202 | AB18: 1875 | AC18: =(AB18-U18)/U18 -> 0.071428571 | AD18: =(AB18-S18)/S18 -> 0.034197463 | AE18: 1850 | AF18: =(AE18-U18)/U18 -> 0.057142857 | AG18: =(AE18-S18)/S18 -> 0.020408163 | AI18: Cleared | AJ18: 778 | AK18: 2 | AL18: 1 | AM18: 2 Bed, Second Floor, Furnished1 Bathrooms | AO18: =SUM(AN18-U18)/U18 -> -1 | AP18: Jemma | AQ18: Sent | AR18: r2r required
A19: Active | B19: =TEXT(C19,"mmmm") -> August | C19: 45510 | D19: BTR-London & SE | E19: Abbeville Apartments | F19: Fatma Azakli | G19: Apt 317, Abbeville Apts, 37 London Rd, Barkin | H19: Eoin Mullan, Felix Price & Ewan Orton | I19: N/A | J19: Current | K19: 45145 | L19: 45145 | M19: 45510 | N19: New Let | O19: AST | P19: 24000 | Q19: 2000 | R19: 25680 | S19: =R19/12 -> 2140 | T19: 25200 | U19: =T19/12 -> 2100 | V19: 22740 | W19: 2170 | Z19: =(W19-U19)/U19 -> 0.033333333 | AA19: =(W19-S19)/S19 -> 0.014018692 | AB19: 2200 | AC19: =(AB19-U19)/U19 -> 0.047619048 | AD19: =(AB19-S19)/S19 -> 0.028037383 | AE19: 2165 | AF19: =(AE19-U19)/U19 -> 0.030952381 | AG19: =(AE19-S19)/S19 -> 0.011682243 | AI19: Arrears | AJ19: 987 | AK19: 3 | AL19: 2 | AM19: 3 Bed, Third Floor, Furnished2 Bathrooms | AO19: =SUM(AN19-U19)/U19 -> -1 | AP19: Jemma | AQ19: Denied
A20: Active | B20: =TEXT(C20,"mmmm") -> July | C20: 45487 | D20: PRS-London & SE | E20: Ability Plaza | F20: Younis Miho | G20: Flat 16 Ability Plaza, London, E8 | H20: Mr Justin Georges Guy Seghers | I20: N/A | J20: Current | K20: 44392 | L20: 45122 | M20: 45487 | N20: Renewal | O20: Live Work | P20: 23920 | Q20: 1993.3333 | R20: 25220 | S20: =R20/12 -> 2101.6667 | T20: 20700 | U20: =T20/12 -> 1725 | V20: 19020 | W20: NPB | Z20: =(W20-U20)/U20 -> #VALUE! | AA20: =(W20-S20)/S20 -> #VALUE! | AB20: 2150 | AC20: =(AB20-U20)/U20 -> 0.24637681 | AD20: =(AB20-S20)/S20 -> 0.022997621 | AE20: 2125 | AF20: =(AE20-U20)/U20 -> 0.23188406 | AG20: =(AE20-S20)/S20 -> 0.0111023 | AH20: The passing rent is incredibly low on this. Please offer but the increase will be high to bring in line with the wider market | AI20: Arrears | AJ20: 471.39 | AK20: 1 | AL20: 1 | AM20: S/C 1 bed/1 bath w/balcony, o/p kit/livingFF | AO20: =SUM(AN20-U20)/U20 -> -1 | AP20: Jemma | AQ20: Sent
A21: Active | B21: =TEXT(C21,"mmmm") -> July | C21: 45496 | D21: PRS-London & SE | E21: Ability Plaza | F21: Younis Miho | G21: EX 7 Ability Plaza, 310 Kingsland Rd, Lon E8 | H21: Alfred Adeoye | I21: N/A | J21: Current | K21: 44401 | L21: 45131 | M21: 45496 | N21: Renewal | O21: Live Work | P21: 24076 | Q21: 2006.3333 | R21: 25324 | S21: =R21/12 -> 2110.3333 | T21: 25140 | U21: =T21/12 -> 2095 | V21: 23411.76 | W21: NPB | Z21: =(W21-U21)/U21 -> #VALUE! | AA21: =(W21-S21)/S21 -> #VALUE! | AB21: 2225 | AC21: =(AB21-U21)/U21 -> 0.062052506 | AD21: =(AB21-S21)/S21 -> 0.054335808 | AE21: 2200 | AF21: =(AE21-U21)/U21 -> 0.050119332 | AG21: =(AE21-S21)/S21 -> 0.042489338 | AI21: Cleared | AJ21: 524.72 | AK21: 1 | AL21: 1 | AM21: S/C 1 bed/1 bath, o/p kitchen/living rm Rfb21FF | AN21: 2225 | AO21: =SUM(AN21-U21)/U21 -> 0.062052506 | AP21: Jemma | AQ21: Sent
A22: Active | B22: =TEXT(C22,"mmmm") -> July | C22: 45484 | D22: PRS-London & SE | E22: Ability Plaza | F22: Younis Miho | G22: EX 16 Ability Plaza, 310 Kingsland Rd, Lon E8 | H22: Anne Lancaster | I22: N/A | J22: Current | K22: 45119 | L22: 45119 | M22: 45484 | N22: New Let | O22: Live Work | P22: 25272 | Q22: 2106 | R22: 26520 | S22: =R22/12 -> 2210 | T22: 25800 | U22: =T22/12 -> 2150 | V22: 24000 | W22: NPB | Z22: =(W22-U22)/U22 -> #VALUE! | AA22: =(W22-S22)/S22 -> #VALUE! | AB22: 2275 | AC22: =(AB22-U22)/U22 -> 0.058139535 | AD22: =(AB22-S22)/S22 -> 0.029411765 | AE22: 2250 | AF22: =(AE22-U22)/U22 -> 0.046511628 | AG22: =(AE22-S22)/S22 -> 0.018099548 | AI22: Cleared | AJ22: 558.82 | AK22: 1 | AL22: 1 | AM22: S/C 1 bed/1 bath, o/p kit/liv, Rfrb 2014TF | AN22: 2275 | AO22: =SUM(AN22-U22)/U22 -> 0.058139535 | AP22: Jemma | AQ22: Sent
A23: Active | B23: =TEXT(C23,"mmmm") -> July | C23: 45503 | D23: PRS-London & SE | E23: Ability Plaza | F23: Younis Miho | G23: EX 19 Ability Plaza, 310 Kingsland Rd, Lon E8 | H23: Mr David Ralph & Miss Prudence Bond | I23: N/A | J23: Current | K23: 43677 | L23: 45138 | M23: 45503 | N23: Renewal | O23: Live Work | P23: 26000 | Q23: 2166.6667 | R23: 27248 | S23: =R23/12 -> 2270.6667 | T23: 24300 | U23: =T23/12 -> 2025 | V23: 22680 | W23: NPB | Z23: =(W23-U23)/U23 -> #VALUE! | AA23: =(W23-S23)/S23 -> #VALUE! | AB23: 2235 | AC23: =(AB23-U23)/U23 -> 0.1037037 | AD23: =(AB23-S23)/S23 -> -0.015707575 | AE23: 2215 | AF23: =(AE23-U23)/U23 -> 0.09382716 | AG23: =(AE23-S23)/S23 -> -0.024515561 | AI23: Cleared | AJ23: 609.17 | AK23: 1 | AL23: 1 | AM23: S/C 1 bed/1 bath, o/p kitchen/liv, Rfrb 20144F | AN23: 2215 | AO23: =SUM(AN23-U23)/U23 -> 0.09382716 | AP23: Jemma | AQ23: Sent
A24: Active | B24: =TEXT(C24,"mmmm") -> July | C24: 45492 | D24: PRS-London & SE | E24: Ability Plaza | F24: Younis Miho | G24: Flat 76 Ability Plaza, London, E8 | H24: Mr Jesse Laitinen | I24: N/A | J24: Current | K24: 43456 | L24: 45127 | M24: 45492 | N24: Renewal | O24: Live Work | P24: 24700 | Q24: 2058.3333 | R24: 25480 | S24: =R24/12 -> 2123.3333 | T24: 24780 | U24: =T24/12 -> 2065 | V24: 22800 | W24: NPB | Z24: =(W24-U24)/U24 -> #VALUE! | AA24: =(W24-S24)/S24 -> #VALUE! | AB24: 2275 | AC24: =(AB24-U24)/U24 -> 0.10169492 | AD24: =(AB24-S24)/S24 -> 0.071428571 | AE24: 2250 | AF24: =(AE24-U24)/U24 -> 0.089588378 | AG24: =(AE24-S24)/S24 -> 0.059654631 | AI24: Arrears | AJ24: 705.53 | AK24: 1 | AL24: 1 | AM24: studio/mezz/bathroom - PRfb '176F/6FA | AO24: =SUM(AN24-U24)/U24 -> -1 | AP24: Jemma | AQ24: Sent
A25: Active | B25: =TEXT(C25,"mmmm") -> July | C25: 45476 | D25: PRS-London & SE | E25: Ability Plaza | F25: Younis Miho | G25: Flat 75 Ability Plaza, London, E8 | H25: My Taylan Aygun | I25: N/A | J25: Current | K25: 44016 | L25: 45111 | M25: 45476 | N25: Renewal | O25: Live Work | P25: 27248 | Q25: 2270.6667 | R25: 28028 | S25: =R25/12 -> 2335.6667 | T25: 25020 | U25: =T25/12 -> 2085 | V25: 23160 | W25: NPB | Z25: =(W25-U25)/U25 -> #VALUE! | AA25: =(W25-S25)/S25 -> #VALUE! | AB25: 2350 | AC25: =(AB25-U25)/U25 -> 0.12709832 | AD25: =(AB25-S25)/S25 -> 0.0061367204 | AE25: 2300 | AF25: =(AE25-U25)/U25 -> 0.10311751 | AG25: =(AE25-S25)/S25 -> -0.015270444 | AI25: Cleared | AJ25: 746.18 | AK25: 1 | AL25: 1 | AM25: studio/mezz/bathroom/balcony, PRfb 206F/6FA | AN25: 2300 | AO25: =SUM(AN25-U25)/U25 -> 0.10311751 | AP25: Jemma | AQ25: Sent
A26: Active | B26: =TEXT(C26,"mmmm") -> July | C26: 45490 | D26: PRS-London & SE | E26: Ability Plaza | F26: Younis Miho | G26: Flat 64 Ability Plaza, London, E8 | H26: Peter Booth | I26: N/A | J26: Current | K26: 44394 | L26: 45125 | M26: 45490 | N26: Renewal | O26: Live Work | P26: 27144 | Q26: 2262 | R26: 29328 | S26: =R26/12 -> 2444 | T26: 25200 | U26: =T26/12 -> 2100 | V26: 22920 | W26: NPB | Z26: =(W26-U26)/U26 -> #VALUE! | AA26: =(W26-S26)/S26 -> #VALUE! | AB26: 2375 | AC26: =(AB26-U26)/U26 -> 0.13095238 | AD26: =(AB26-S26)/S26 -> -0.028232406 | AE26: 2325 | AF26: =(AE26-U26)/U26 -> 0.10714286 | AG26: =(AE26-S26)/S26 -> -0.048690671 | AH26: Passing rent is low copared to ERV and other 2 bed rents | AI26: Cleared | AJ26: 678.18 | AK26: 2 | AL26: 1 | AM26: S/C 2 bed/1 bath, kitchen, living room4FA | AO26: =SUM(AN26-U26)/U26 -> -1 | AP26: Jemma | AQ26: Sent
A27: Active | B27: =TEXT(C27,"mmmm") -> July | C27: 45489 | D27: PRS-London & SE | E27: Ability Plaza | F27: Younis Miho | G27: Flat 67 Ability Plaza, London, E8 | H27: Mr S van Oossanen, Ms S Lee & Mr D Cutler | I27: N/A | J27: Current | K27: 44394 | L27: 45124 | M27: 45489 | N27: Renewal | O27: Live Work | P27: 28392 | Q27: 2366 | R27: 30576 | S27: =R27/12 -> 2548 | T27: 26100 | U27: =T27/12 -> 2175 | V27: 24000 | W27: NPB | Z27: =(W27-U27)/U27 -> #VALUE! | AA27: =(W27-S27)/S27 -> #VALUE! | AB27: 2400 | AC27: =(AB27-U27)/U27 -> 0.10344828 | AD27: =(AB27-S27)/S27 -> -0.058084772 | AE27: 2350 | AF27: =(AE27-U27)/U27 -> 0.08045977 | AG27: =(AE27-S27)/S27 -> -0.077708006 | AI27: Cleared | AJ27: 690.25 | AK27: 2 | AL27: 1 | AM27: 2 bed/1 bath flat, kitchen, living rm PRfb205F | AN27: 2350 | AO27: =SUM(AN27-U27)/U27 -> 0.08045977 | AP27: Jemma | AQ27: Sent
A28: Active | B28: =TEXT(C28,"mmmm") -> July | C28: 45500 | D28: PRS-London & SE | E28: Ability Plaza | F28: Younis Miho | G28: Flat 85 Ability Plaza, London, E8 | H28: Theo Quarendon & Amaechi Obasi | I28: N/A | J28: Current | K28: 44770 | L28: 44770 | M28: 45500 | N28: Renewal | O28: Live Work | P28: 28600 | Q28: 2383.3333 | R28: 30836 | S28: =R28/12 -> 2569.6667 | T28: 25800 | U28: =T28/12 -> 2150 | V28: 25800 | W28: NPB | Z28: =(W28-U28)/U28 -> #VALUE! | AA28: =(W28-S28)/S28 -> #VALUE! | AB28: 2425 | AC28: =(AB28-U28)/U28 -> 0.12790698 | AD28: =(AB28-S28)/S28 -> -0.056297834 | AE28: 2375 | AF28: =(AE28-U28)/U28 -> 0.10465116 | AG28: =(AE28-S28)/S28 -> -0.07575561 | AH28: Passing rent is low compared to ERV and other 2 bed rents | AI28: Cleared | AJ28: 737.02 | AK28: 2 | AL28: 1 | AM28: 2 bed/1 bath, kitch, liv rm - P Refurb '176FA | AO28: =SUM(AN28-U28)/U28 -> -1 | AP28: Jemma | AQ28: Sent
A29: Active | B29: =TEXT(C29,"mmmm") -> August | C29: 45527 | D29: PRS-London & SE | E29: Ability Plaza | F29: Younis Miho | G29: Flat 47 Ability Plaza, London, E8 | H29: Sarah Yazouri & Austin Bly | I29: N/A | J29: Current | K29: 45162 | L29: 45162 | M29: 45527 | N29: New Let | O29: Live Work | P29: 27040 | Q29: 2253.3333 | R29: 27820 | S29: =R29/12 -> 2318.3333 | T29: 26400 | U29: =T29/12 -> 2200 | V29: 23340 | W29: NPB | Z29: =(W29-U29)/U29 -> #VALUE! | AA29: =(W29-S29)/S29 -> #VALUE! | AB29: 2350 | AC29: =(AB29-U29)/U29 -> 0.068181818 | AD29: =(AB29-S29)/S29 -> 0.013659238 | AE29: 2325 | AF29: =(AE29-U29)/U29 -> 0.056818182 | AG29: =(AE29-S29)/S29 -> 0.002875629 | AI29: Arrears | AJ29: 727.97 | AK29: 1 | AL29: 1 | AM29: studio/mezz/bathroom/balcony - PRefurb'17TF/TFA | AO29: =SUM(AN29-U29)/U29 -> -1 | AP29: Jemma | AQ29: Sent
A30: Active | B30: =TEXT(C30,"mmmm") -> August | C30: 45527 | D30: PRS-London & SE | E30: Ability Plaza | F30: Younis Miho | G30: Flat 53 Ability Plaza, London, E8 | H30: Mr Nicholas Derewlany | I30: N/A | J30: Current | K30: 44432 | L30: 45162 | M30: 45527 | N30: Renewal | O30: Live Work | P30: 30316 | Q30: 2526.3333 | R30: 31564 | S30: =R30/12 -> 2630.3333 | T30: 28380 | U30: =T30/12 -> 2365 | V30: 26160 | W30: NPB | Z30: =(W30-U30)/U30 -> #VALUE! | AA30: =(W30-S30)/S30 -> #VALUE! | AB30: 2550 | AC30: =(AB30-U30)/U30 -> 0.078224101 | AD30: =(AB30-S30)/S30 -> -0.030541123 | AE30: 2500 | AF30: =(AE30-U30)/U30 -> 0.057082452 | AG30: =(AE30-S30)/S30 -> -0.04955012 | AH30: ERV is high due to size of this unit | AI30: Cleared | AJ30: 1099.81 | AK30: 1 | AL30: 1 | AM30: 1 bed/1 bath w/mezz,o/p kit/liv,balc.-PRfb'174F/4FA | AO30: =SUM(AN30-U30)/U30 -> -1 | AP30: Jemma | AQ30: NTQ
A31: Active | B31: =TEXT(C31,"mmmm") -> August | C31: 45533 | D31: PRS-London & SE | E31: Ability Plaza | F31: Younis Miho | G31: EX 12 Ability Plaza, 310 Kingsland Rd, Lon E8 | H31: Sajani Sagar & Alice Thomson | I31: N/A | J31: Current | K31: 45168 | L31: 45168 | M31: 45533 | N31: New Let | O31: Live Work | P31: 25376 | Q31: 2114.6667 | R31: 26624 | S31: =R31/12 -> 2218.6667 | T31: 27000 | U31: =T31/12 -> 2250 | V31: 21960 | W31: NPB | Z31: =(W31-U31)/U31 -> #VALUE! | AA31: =(W31-S31)/S31 -> #VALUE! | AB31: 2300 | AC31: =(AB31-U31)/U31 -> 0.022222222 | AD31: =(AB31-S31)/S31 -> 0.036658654 | AE31: 2300 | AF31: =(AE31-U31)/U31 -> 0.022222222 | AG31: =(AE31-S31)/S31 -> 0.036658654 | AI31: Cleared | AJ31: 561.53 | AK31: 1 | AL31: 1 | AM31: S/C 1 bed/1 bath, o/p kit/liv, balc-Rfrb 2015SF | AO31: =SUM(AN31-U31)/U31 -> -1 | AP31: Jemma | AQ31: Sent
A32: Active | B32: =TEXT(C32,"mmmm") -> August | C32: 45505 | D32: PRS-London & SE | E32: Ability View | F32: Younis Miho | G32: Unit 5 Ability view, 218 Kingsland Road, Lond | H32: Sérgio Takahata & Suelen Neri Frazzato | I32: N/A | J32: Current | K32: 44775 | L32: 45140 | M32: 45505 | N32: Renewal | O32: Live Work | P32: 25740 | Q32: 2145 | R32: 27248 | S32: =R32/12 -> 2270.6667 | T32: 24780 | U32: =T32/12 -> 2065 | V32: 22920 | W32: NPB | Z32: =(W32-U32)/U32 -> #VALUE! | AA32: =(W32-S32)/S32 -> #VALUE! | AB32: 2285 | AC32: =(AB32-U32)/U32 -> 0.10653753 | AD32: =(AB32-S32)/S32 -> 0.0063123899 | AE32: 2275 | AF32: =(AE32-U32)/U32 -> 0.10169492 | AG32: =(AE32-S32)/S32 -> 0.0019083969 | AI32: Cleared | AJ32: 734.52 | AK32: 1 | AL32: 1 | AM32: S/C 1 bed/1 bath flat, o/p kitchen/living rm- | AO32: =SUM(AN32-U32)/U32 -> -1 | AP32: Jemma | AQ32: Sent
A33: Active | B33: =TEXT(C33,"mmmm") -> August | C33: 45505 | D33: PRS-London & SE | E33: Ability View | F33: Younis Miho | G33: Flat 17 Ability View, 220 Kingsland Road, Lon | H33: Mr Tristan Kinloch Hallis | I33: N/A | J33: Current | K33: 44410 | L33: 45140 | M33: 45505 | N33: Renewal | O33: Live Work | P33: 29172 | Q33: 2431 | R33: 29172 | S33: =R33/12 -> 2431 | T33: 28920 | U33: =T33/12 -> 2410 | V33: 26760 | W33: NPB | Z33: =(W33-U33)/U33 -> #VALUE! | AA33: =(W33-S33)/S33 -> #VALUE! | AB33: 2550 | AC33: =(AB33-U33)/U33 -> 0.058091286 | AD33: =(AB33-S33)/S33 -> 0.048951049 | AE33: 2525 | AF33: =(AE33-U33)/U33 -> 0.047717842 | AG33: =(AE33-S33)/S33 -> 0.038667215 | AI33: Cleared | AJ33: 813.54 | AK33: 2 | AL33: 1 | AM33: S/C 2 bed/1 bath, o/p kitchen/living rm Rfb217F | AO33: =SUM(AN33-U33)/U33 -> -1 | AP33: Jemma | AQ33: Sent
A34: Active | B34: =TEXT(C34,"mmmm") -> August | C34: 45506 | D34: PRS-London & SE | E34: Ability View | F34: Younis Miho | G34: Unit 3 Ability view, 218 Kingsland Road, Lond | H34: Henry McLean & Maria Kontorravdis | I34: N/A | J34: Current | K34: 45141 | L34: 45141 | M34: 45506 | N34: New Let | O34: Live Work | P34: 28496 | Q34: 2374.6667 | R34: 29328 | S34: =R34/12 -> 2444 | T34: 29400 | U34: =T34/12 -> 2450 | V34: 27120 | W34: NPB | Z34: =(W34-U34)/U34 -> #VALUE! | AA34: =(W34-S34)/S34 -> #VALUE! | AB34: 2575 | AC34: =(AB34-U34)/U34 -> 0.051020408 | AD34: =(AB34-S34)/S34 -> 0.053600655 | AE34: 2550 | AF34: =(AE34-U34)/U34 -> 0.040816327 | AG34: =(AE34-S34)/S34 -> 0.043371522 | AI34: Cleared | AJ34: 1165 | AK34: 1 | AL34: 1 | AM34: Studio (w/partition,o/p kit/liv - PRfb'19- | AO34: =SUM(AN34-U34)/U34 -> -1 | AP34: Jemma | AQ34: Sent
A35: Active | B35: =TEXT(C35,"mmmm") -> July | C35: 45495 | D35: PRS-London & SE | E35: Ability View | F35: Younis Miho | G35: Flat 7 Ability view, 220 Kingsland Road, Lond | H35: Mr Tamas Koloti | I35: N/A | J35: Current | K35: 43304 | L35: 45130 | M35: 45495 | N35: Renewal | O35: Live Work | P35: 26052 | Q35: 2171 | R35: 27560 | S35: =R35/12 -> 2296.6667 | T35: 25200 | U35: =T35/12 -> 2100 | V35: 23580 | W35: NPB | Z35: =(W35-U35)/U35 -> #VALUE! | AA35: =(W35-S35)/S35 -> #VALUE! | AB35: 2295 | AC35: =(AB35-U35)/U35 -> 0.092857143 | AD35: =(AB35-S35)/S35 -> -0.0007256894 | AE35: 2265 | AF35: =(AE35-U35)/U35 -> 0.078571429 | AG35: =(AE35-S35)/S35 -> -0.013788099 | AI35: Cleared | AJ35: 850.13 | AK35: 1 | AL35: 1 | AM35: 1 bed/1 bath, o/p kitch/liv rm - P Refurb '184F | AN35: 2265 | AO35: =SUM(AN35-U35)/U35 -> 0.078571429 | AP35: Jemma | AQ35: Sent
A36: Active | B36: =TEXT(C36,"mmmm") -> July | C36: 45504 | D36: PRS-London & SE | E36: Ability View | F36: Younis Miho | G36: Flat 13 Ability view, 220 Kingsland Road, Lon | H36: Miss Rachael Valters & Mr Samuel Thomas | I36: N/A | J36: Current | K36: 43301 | L36: 45139 | M36: 45504 | N36: Renewal | O36: Live Work | P36: 27924 | Q36: 2327 | R36: 29380 | S36: =R36/12 -> 2448.3333 | T36: 25500 | U36: =T36/12 -> 2125 | V36: 23493 | W36: NPB | Z36: =(W36-U36)/U36 -> #VALUE! | AA36: =(W36-S36)/S36 -> #VALUE! | AB36: 2450 | AC36: =(AB36-U36)/U36 -> 0.15294118 | AD36: =(AB36-S36)/S36 -> 0.00068073519 | AE36: 2375 | AF36: =(AE36-U36)/U36 -> 0.11764706 | AG36: =(AE36-S36)/S36 -> -0.029952349 | AH36: Passing rent is low copared to ERV and other 2 bed rents | AI36: Arrears | AJ36: 1052.92 | AK36: 1 | AL36: 1 | AM36: 1 bed / 1 bath/ opne plan kitchen/living room5F | AN36: 2450 | AO36: =SUM(AN36-U36)/U36 -> 0.15294118 | AP36: Jemma | AQ36: Sent
A37: Active | B37: =TEXT(C37,"mmmm") -> August | C37: 45521 | D37: PRS-London & SE | E37: Ability View | F37: Younis Miho | G37: Flat 6 Ability view, 220 Kingsland Road, Lond | H37: Emma Morton & Ben Rubinsztein | I37: N/A | J37: Current | K37: 45156 | L37: 45156 | M37: 45521 | N37: New Let | O37: Live Work | P37: 25844 | Q37: 2153.6667 | R37: 27352 | S37: =R37/12 -> 2279.3333 | T37: 27000 | U37: =T37/12 -> 2250 | V37: 24600 | W37: NPB | Z37: =(W37-U37)/U37 -> #VALUE! | AA37: =(W37-S37)/S37 -> #VALUE! | AB37: 2375 | AC37: =(AB37-U37)/U37 -> 0.055555556 | AD37: =(AB37-S37)/S37 -> 0.041971337 | AE37: 2350 | AF37: =(AE37-U37)/U37 -> 0.044444444 | AG37: =(AE37-S37)/S37 -> 0.031003217 | AI37: Cleared | AJ37: 796.08 | AK37: 1 | AL37: 1 | AM37: 1 bed/1 bath, kitch, liv rm - P Refurb '184F | AO37: =SUM(AN37-U37)/U37 -> -1 | AP37: Jemma | AQ37: Sent
A38: Active | B38: =TEXT(C38,"mmmm") -> August | C38: 45528 | D38: PRS-London & SE | E38: Ability View | F38: Younis Miho | G38: Flat 4 Ability view, 220 Kingsland Road, Lond | H38: Jacob Hill-Anderson | I38: N/A | J38: Current | K38: 45163 | L38: 45163 | M38: 45528 | N38: New Let | O38: Live Work | P38: 26000 | Q38: 2166.6667 | R38: 27456 | S38: =R38/12 -> 2288 | T38: 27600 | U38: =T38/12 -> 2300 | V38: 24960 | W38: NPB | Z38: =(W38-U38)/U38 -> #VALUE! | AA38: =(W38-S38)/S38 -> #VALUE! | AB38: 2425 | AC38: =(AB38-U38)/U38 -> 0.054347826 | AD38: =(AB38-S38)/S38 -> 0.059877622 | AE38: 2400 | AF38: =(AE38-U38)/U38 -> 0.043478261 | AG38: =(AE38-S38)/S38 -> 0.048951049 | AI38: Cleared | AJ38: 847.26 | AK38: 1 | AL38: 1 | AM38: S/C 1 bed/1 bath, o/p kitchen/living rm Rfb21TF | AO38: =SUM(AN38-U38)/U38 -> -1 | AP38: Jemma | AQ38: Sent
A39: Active | B39: =TEXT(C39,"mmmm") -> August | C39: 45517 | D39: BTR-London & SE | E39: Apex Gardens | F39: Nicole Freeman | G39: 1802 Aster Apts 822 Seven Sisters Rd London N | H39: Miao Ju and Daniel Kelshaw | I39: N/A | J39: Current | K39: 45152 | L39: 45152 | M39: 45517 | N39: New Let | O39: AST | P39: 24180 | Q39: 2015 | R39: 25584 | S39: =R39/12 -> 2132 | T39: 23880 | U39: =T39/12 -> 1990 | V39: 22560 | W39: 2165 | Z39: =(W39-U39)/U39 -> 0.087939698 | AA39: =(W39-S39)/S39 -> 0.015478424 | AB39: 2150 | AC39: =(AB39-U39)/U39 -> 0.08040201 | AD39: =(AB39-S39)/S39 -> 0.0084427767 | AE39: 2130 | AF39: =(AE39-U39)/U39 -> 0.070351759 | AG39: =(AE39-S39)/S39 -> -0.0009380863 | AI39: Cleared | AJ39: 548.964 | AK39: 1 | AL39: 1 | AM39: 1 bedroomWest | AN39: 2100 | AO39: =SUM(AN39-U39)/U39 -> 0.055276382 | AP39: Jemma | AQ39: Sent
A40: Active | B40: =TEXT(C40,"mmmm") -> August | C40: 45534 | D40: BTR-London & SE | E40: Apex Gardens | F40: Nicole Freeman | G40: 1105 Aster Apts 822 Seven Sisters Rd London N | H40: Mr Runjia Chen | I40: N/A | J40: Current | K40: 45169 | L40: 45169 | M40: 45534 | N40: New Let | O40: AST | P40: 23608 | Q40: 1967.3333 | R40: 25012 | S40: =R40/12 -> 2084.3333 | T40: 24600 | U40: =T40/12 -> 2050 | V40: 22560 | W40: 2045 | Z40: =(W40-U40)/U40 -> -0.0024390244 | AA40: =(W40-S40)/S40 -> -0.018870942 | AB40: 2150 | AC40: =(AB40-U40)/U40 -> 0.048780488 | AD40: =(AB40-S40)/S40 -> 0.031504878 | AE40: 2100 | AF40: =(AE40-U40)/U40 -> 0.024390244 | AG40: =(AE40-S40)/S40 -> 0.0075163921 | AI40: Cleared | AJ40: 548.964 | AK40: 1 | AL40: 1 | AM40: 1 bedroomEast | AO40: =SUM(AN40-U40)/U40 -> -1 | AP40: Jemma | AQ40: Sent
...

Sheet Licences
A1: Diary Status | B1: Event Date | C1: Portfolio | D1: Estate | E1: Unit Manager | F1: Unit Description | G1: Current Tenant Name | H1: PM Details | I1: Tenancy Status | J1: Tenancy Start Date | K1: Tenancy End Date | L1: Lease Start Date | M1: Lease End Date | N1: Action Type | O1: Unit Tenure | P1: ERV | Q1: Monthly ERV | R1: March ERV | S1: Annual Rent | T1: Passing Rent | U1: Passing Rent -1 | V1: Tenant Balance Status | W1: Unit Size | X1: Number of Beds | Y1: Number of Baths | Z1: Description of Unit | AA1: Renewal Neg | AB1: Renewal Notes Date | AC1: Renewal Notes
A2: Active | B2: 45481 | C2: BTR-London & SE | D2: Argo Apartments | E2: Raihana Parveen | F2: Car Space 80 Argo Apartments,4 Silvertown Way | G2: Mears Ltd | I2: Current | J2: 44751 | L2: 45116 | M2: 45481 | N2: Renewal | O2: Licence | P2: 1200 | Q2: 100 | R2: 1440 | S2: 1440 | T2: 1440 | U2: 1200 | V2: Credit | W2: 0 | X2: 0 | Y2: 0 | AA2: RP3 | AB2: 45481
A3: Active | B3: 45481 | C3: BTR-London & SE | D3: Argo Apartments | E3: Raihana Parveen | F3: Car Space 81 Argo Apartments,4 Silvertown Way | G3: Mears Ltd | I3: Current | J3: 44751 | L3: 45116 | M3: 45481 | N3: Renewal | O3: Licence | P3: 1200 | Q3: 100 | R3: 1440 | S3: 1440 | T3: 1440 | U3: 1200 | V3: Arrears | W3: 0 | X3: 0 | Y3: 0 | AA3: RP3 | AB3: 45481
A4: Active | B4: 45482 | C4: BTR-London & SE | D4: Argo Apartments | E4: Raihana Parveen | F4: Car Space 63 Argo Apartments,4 Silvertown Way | G4: Mears Ltd | I4: Current | J4: 45117 | L4: 45117 | M4: 45482 | N4: New Let | O4: Licence | P4: 1200 | Q4: 100 | R4: 1200 | S4: 1440 | T4: 1260 | U4: 1200 | V4: Cleared | W4: 0 | X4: 0 | Y4: 0 | AA4: RP3 | AB4: 45482
A5: Active | B5: 45508 | C5: BTR-London & SE | D5: Argo Apartments | E5: Raihana Parveen | F5: Car Space 71 Argo Apartments,4 Silvertown Way | G5: Mears Ltd | I5: Current | J5: 43217 | L5: 45143 | M5: 45508 | N5: Renewal | O5: Licence | P5: 1200 | Q5: 100 | R5: 1200 | S5: 1440 | T5: 1200 | U5: 1200 | V5: Cleared | W5: 0 | X5: 0 | Y5: 0 | AA5: RP3 | AB5: 45508
A6: Active | B6: 45508 | C6: BTR-London & SE | D6: Argo Apartments | E6: Raihana Parveen | F6: Car Space 74 Argo Apartments,4 Silvertown Way | G6: Mears Ltd | I6: Current | J6: 43217 | L6: 45143 | M6: 45508 | N6: Renewal | O6: Licence | P6: 1200 | Q6: 100 | R6: 1200 | S6: 1440 | T6: 1200 | U6: 1200 | V6: Cleared | W6: 0 | X6: 0 | Y6: 0 | AA6: RP3 | AB6: 45508
A7: Active | B7: 45485 | C7: BTR-London & SE | D7: Berewood PRS | E7: Megan Fleming | F7: Car Park Bay 9, Langford House, Carey Lane, | G7: Mr Benjo Balolong, Mrs Vanessa Kae Jose | I7: Current | J7: 44939 | L7: 44939 | M7: 45485 | N7: New Let | O7: Licence | P7: 0 | Q7: 0 | R7: 0 | S7: 0 | T7: 0 | U7: 0 | V7: Cleared | W7: 0 | X7: 0 | Y7: 0 | Z7: Car Park space | AA7: AG4 | AB7: 45485
A8: Active | B8: 45495 | C8: BTR-London & SE | D8: Berewood PRS | E8: Megan Fleming | F8: Car Park Bay 17, Fielding House, Carey Lane, | G8: Miss Hajnalka Fogarasi | I8: Current | J8: 44949 | L8: 44949 | M8: 45495 | N8: New Let | O8: Licence | P8: 0 | Q8: 0 | S8: 0 | T8: 0 | U8: 0 | V8: Cleared | W8: 0 | X8: 0 | Y8: 0 | Z8: Car Park space | AA8: AG4 | AB8: 45495
A9: Active | B9: 45483 | C9: BTR-Regions | D9: Brook Place | E9: Emma Cramer- Mitchell | F9: Parking 24 Brook Place Apts, Sheffield, S11 | G9: Frances McGee | H9: Linked to 503- no issues | I9: Current | J9: 45118 | L9: 45118 | M9: 45483 | N9: New Let | O9: Licence | P9: 1500 | Q9: 125 | R9: 1560 | S9: 1560 | T9: 1560 | U9: 1500 | V9: Cleared | W9: 0 | X9: 0 | Y9: 0 | AA9: MC2 | AB9: 45483
A10: Active | B10: 45489 | C10: BTR-Regions | D10: Brook Place | E10: Emma Cramer- Mitchell | F10: Parking 43 Brook Place Apts, Sheffield, S11 | G10: Oliver Rathbone | H10: Linked to 725- no issues | I10: Current | J10: 45124 | L10: 45124 | M10: 45489 | N10: New Let | O10: Licence | P10: 1500 | Q10: 125 | R10: 1440 | S10: 1560 | T10: 1440 | U10: 1500 | V10: Cleared | W10: 0 | X10: 0 | Y10: 0 | AA10: MC2 | AB10: 45489
A11: Active | B11: 45490 | C11: BTR-Regions | D11: Brook Place | E11: Emma Cramer- Mitchell | F11: Parking 42 Brook Place Apts, Sheffield, S11 | G11: Harshit Kondapally | H11: Linked to 418- no issues | I11: Current | J11: 44760 | L11: 45125 | M11: 45490 | N11: Renewal | O11: Licence | P11: 1500 | Q11: 125 | R11: 1440 | S11: 1560 | T11: 1440 | U11: 1500 | V11: Cleared | W11: 0 | X11: 0 | Y11: 0 | AA11: MC2 | AB11: 45490
A12: Active | B12: 45492 | C12: BTR-Regions | D12: Brook Place | E12: Emma Cramer- Mitchell | F12: Parking 23 Brook Place Apts, Sheffield, S11 | G12: James Warrington | H12: Linked to 703- no issues | I12: Current | J12: 45127 | L12: 45127 | M12: 45492 | N12: New Let | O12: Licence | P12: 1500 | Q12: 125 | R12: 1440 | S12: 1560 | T12: 1440 | U12: 1500 | V12: Cleared | W12: 0 | X12: 0 | Y12: 0 | AA12: MC2 | AB12: 45492
A13: Active | B13: 45497 | C13: BTR-Regions | D13: Brook Place | E13: Emma Cramer- Mitchell | F13: Parking 04 Brook Place Apts, Sheffield, S11 | G13: Dina Ibrahim | H13: Linked to 529- no issues | I13: Current | J13: 45132 | L13: 45132 | M13: 45497 | N13: New Let | O13: Licence | P13: 1500 | Q13: 125 | R13: 1440 | S13: 1560 | T13: 1440 | U13: 1500 | V13: Cleared | W13: 0 | X13: 0 | Y13: 0 | AA13: MC2 | AB13: 45497
A14: Active | B14: 45504 | C14: BTR-Regions | D14: Brook Place | E14: Emma Cramer- Mitchell | F14: Parking 31 Brook Place Apts, Sheffield, S11 | G14: Asha Wright | H14: Linked to 324- no issues | I14: Current | J14: 45139 | L14: 45139 | M14: 45504 | N14: New Let | O14: Licence | P14: 1500 | Q14: 125 | R14: 1440 | S14: 1560 | T14: 1560 | U14: 1500 | V14: Cleared | W14: 0 | X14: 0 | Y14: 0 | AA14: MC2 | AB14: 45504
A15: Active | B15: 45516 | C15: BTR-Regions | D15: Brook Place | E15: Emma Cramer- Mitchell | F15: Parking 01 Brook Place Apts, Sheffield, S11 | G15: Amrit Jani | H15: Linked to 422- no issues | I15: Current | J15: 44694 | L15: 45059 | M15: 45516 | N15: Renewal | O15: Licence | P15: 1500 | Q15: 125 | R15: 1440 | S15: 1500 | T15: 1440 | U15: 1500 | V15: Cleared | W15: 0 | X15: 0 | Y15: 0 | AA15: MC2 | AB15: 45516
A16: Active | B16: 45535 | C16: BTR-Regions | D16: Brook Place | E16: Emma Cramer- Mitchell | F16: Parking 44 Brook Place Apts, Sheffield, S11 | G16: Bojian Li | H16: Linked to 411- DDM needs setting up- rent not being paid automatically | I16: Current | J16: 45170 | K16: 45535 | L16: 45170 | M16: 45535 | N16: New Let | O16: Licence | P16: 1500 | Q16: 125 | R16: 1440 | S16: 1560 | T16: 1440 | U16: 1500 | V16: Arrears | W16: 0 | X16: 0 | Y16: 0 | AA16: MC2 | AB16: 45535
A17: Pending | B17: 45531 | C17: BTR-Regions | D17: Brook Place | E17: Emma Cramer- Mitchell | F17: Parking 19 Brook Place Apts, Sheffield, S11 | G17: Aydin Can | H17: Linked to 303- no issues | I17: Current | J17: 44985 | L17: 45350 | M17: 45531 | N17: Renewal | O17: Licence | P17: 1500 | Q17: 125 | R17: 1560 | S17: 1560 | T17: 1560 | U17: 1500 | V17: Cleared | W17: 0 | X17: 0 | Y17: 0 | AA17: EC1 | AB17: 45531
A18: Active | B18: 45507 | C18: PRS-London & SE | D18: Churston Close | E18: Nadia Rogers | F18: Garage O,Churston Cl,162-164Tulse Hill,SW23BX | G18: Abir The Colour Of Life | I18: Current | J18: 45142 | L18: 45142 | M18: 45507 | N18: New Let | O18: Licence | P18: 600 | Q18: 50 | R18: 1440 | S18: 1800 | T18: 1440 | U18: 600 | V18: Cleared | W18: 0 | Z18: Garage | AA18: NRX | AB18: 45507
A19: Active | B19: 45478 | C19: BTR-Regions | D19: Clippers Quay | E19: Helen Bowers | F19: Parking D35 Torrens Apt, Salford M50 | G19: Wendy Moneke | I19: Current | J19: 45113 | L19: 45113 | M19: 45478 | N19: New Let | O19: Licence | P19: 1380 | Q19: 115 | R19: 1200 | S19: 1380 | T19: 1200 | U19: 1380 | V19: Cleared | W19: 0 | X19: 0 | Y19: 0 | AA19: HB2 | AB19: 45478
A20: Active | B20: 45482 | C20: BTR-Regions | D20: Clippers Quay | E20: Helen Bowers | F20: Parking D39 Torrens Apt, Salford M50 | G20: Max Walters | I20: Current | J20: 45117 | L20: 45117 | M20: 45482 | N20: New Let | O20: Licence | P20: 1380 | Q20: 115 | R20: 1380 | S20: 1500 | T20: 1380 | U20: 1380 | V20: Cleared | W20: 0 | X20: 0 | Y20: 0 | AA20: HB2 | AB20: 45482
A21: Active | B21: 45484 | C21: BTR-Regions | D21: Clippers Quay | E21: Helen Bowers | F21: Parking D32 Torrens Apt, Salford M50 | G21: Rakeeb Patel | I21: Current | J21: 44069 | L21: 45119 | M21: 45484 | N21: Renewal | O21: Licence | P21: 1380 | Q21: 115 | R21: 1260 | S21: 1500 | T21: 1260 | U21: 1380 | V21: Cleared | W21: 0 | X21: 0 | Y21: 0 | AA21: HB2 | AB21: 45484
A22: Active | B22: 45486 | C22: BTR-Regions | D22: Clippers Quay | E22: Helen Bowers | F22: Parking D6 Torrens Apt, Salford M50 | G22: Tsz Fung Lo | I22: Current | J22: 45121 | L22: 45121 | M22: 45486 | N22: New Let | O22: Licence | P22: 1380 | Q22: 115 | R22: 1380 | S22: 1500 | T22: 1380 | U22: 1380 | V22: Cleared | W22: 0 | X22: 0 | Y22: 0 | AA22: HB2 | AB22: 45486
A23: Active | B23: 45486 | C23: BTR-Regions | D23: Clippers Quay | E23: Helen Bowers | F23: Parking E9 Ambassador Apt , Salford M50 | G23: Nick Overd | I23: Current | J23: 45121 | L23: 45121 | M23: 45486 | N23: New Let | O23: Licence | P23: 1380 | Q23: 115 | R23: 1200 | S23: 1500 | T23: 1200 | U23: 1380 | V23: Cleared | W23: 0 | X23: 0 | Y23: 0 | AA23: HB2 | AB23: 45486
A24: Active | B24: 45492 | C24: BTR-Regions | D24: Clippers Quay | E24: Helen Bowers | F24: Parking B25 Syren Apt , Salford M50 | G24: Chung Yee Fung | I24: Current | J24: 45127 | L24: 45127 | M24: 45492 | N24: New Let | O24: Licence | P24: 1380 | Q24: 115 | R24: 1380 | S24: 1500 | T24: 1380 | U24: 1380 | V24: Arrears | W24: 0 | X24: 0 | Y24: 0 | AA24: HB2 | AB24: 45492
A25: Active | B25: 45492 | C25: BTR-Regions | D25: Clippers Quay | E25: Helen Bowers | F25: Parking E36 Ambassador Apt , Salford M50 | G25: Madi Eastham | I25: Current | J25: 45127 | L25: 45127 | M25: 45492 | N25: New Let | O25: Licence | P25: 1380 | Q25: 115 | R25: 1200 | S25: 1500 | T25: 1200 | U25: 1380 | V25: Cleared | W25: 0 | X25: 0 | Y25: 0 | AA25: HB2 | AB25: 45492
A26: Active | B26: 45494 | C26: BTR-Regions | D26: Clippers Quay | E26: Helen Bowers | F26: Parking C18 Tayleur Apt, Salford M50 | G26: Eduardo De la Cotera Morales | I26: Current | J26: 44764 | L26: 45129 | M26: 45494 | N26: Renewal | O26: Licence | P26: 1380 | Q26: 115 | R26: 1200 | S26: 1500 | T26: 1200 | U26: 1380 | V26: Cleared | W26: 0 | X26: 1 | Y26: 0 | Z26: Car Parking Space | AA26: HB2 | AB26: 45494
A27: Active | B27: 45494 | C27: BTR-Regions | D27: Clippers Quay | E27: Helen Bowers | F27: Parking C28 Tayleur Apt, Salford M50 | G27: Rosie Boyer | I27: Current | J27: 44948 | L27: 45129 | M27: 45494 | N27: Renewal | O27: Licence | P27: 1380 | Q27: 115 | R27: 1200 | S27: 1500 | T27: 1200 | U27: 1380 | V27: Cleared | W27: 0 | X27: 3 | Y27: 0 | Z27: Car Parking Space | AA27: HB2 | AB27: 45494
A28: Active | B28: 45496 | C28: BTR-Regions | D28: Clippers Quay | E28: Helen Bowers | F28: Parking D7 Torrens Apt, Salford M50 | G28: Cheuk Kin Lee | I28: Current | J28: 45131 | L28: 45131 | M28: 45496 | N28: New Let | O28: Licence | P28: 1380 | Q28: 115 | R28: 1200 | S28: 1500 | T28: 1200 | U28: 1380 | V28: Cleared | W28: 0 | X28: 0 | Y28: 0 | AA28: HB2 | AB28: 45496
A29: Active | B29: 45501 | C29: BTR-Regions | D29: Clippers Quay | E29: Helen Bowers | F29: Parking B33 Syren Apt , Salford M50 | G29: James Lancaster | I29: Current | J29: 45136 | L29: 45136 | M29: 45501 | N29: New Let | O29: Licence | P29: 1380 | Q29: 115 | R29: 1200 | S29: 1500 | T29: 1200 | U29: 1380 | V29: Cleared | W29: 0 | X29: 0 | Y29: 0 | AA29: HB2 | AB29: 45501
A30: Active | B30: 45501 | C30: BTR-Regions | D30: Clippers Quay | E30: Helen Bowers | F30: Parking B4 Syren Apt , Salford M50 | G30: Tsz Tsun Lam | I30: Current | J30: 45136 | L30: 45136 | M30: 45501 | N30: New Let | O30: Licence | P30: 1380 | Q30: 115 | R30: 1200 | S30: 1500 | T30: 1200 | U30: 1380 | V30: Cleared | W30: 0 | X30: 0 | Y30: 0 | AA30: HB2 | AB30: 45501
A31: Active | B31: 45504 | C31: BTR-Regions | D31: Clippers Quay | E31: Helen Bowers | F31: Parking C24 Tayleur Apt, Salford M50 | G31: Yik Lau | I31: Current | J31: 45362 | L31: 45362 | M31: 45726 | N31: New Let | O31: Licence | P31: 1380 | Q31: 115 | R31: 1200 | S31: 1500 | T31: 1500 | U31: 1380 | V31: Arrears | W31: 0 | X31: 2 | Y31: 0 | Z31: Car Parking Space | AA31: HB2 | AB31: 45726
A32: Active | B32: 45504 | C32: BTR-Regions | D32: Clippers Quay | E32: Helen Bowers | F32: Parking C29 Tayleur Apt, Salford M50 | G32: Victoria Quinn | I32: Current | J32: 44043 | L32: 45139 | M32: 45504 | N32: Renewal | O32: Licence | P32: 1380 | Q32: 115 | R32: 1260 | S32: 1500 | T32: 1260 | U32: 1380 | V32: Cleared | W32: 0 | X32: 2 | Y32: 0 | Z32: Car Parking Space | AA32: HB2 | AB32: 45504
A33: Active | B33: 45504 | C33: BTR-Regions | D33: Clippers Quay | E33: Helen Bowers | F33: Parking C33 Tayleur Apt, Salford M50 | G33: Dimitra Maniakdaki | I33: Current | J33: 44378 | L33: 45139 | M33: 45504 | N33: Renewal | O33: Licence | P33: 1380 | Q33: 115 | R33: 1200 | S33: 1500 | T33: 1200 | U33: 1380 | V33: Cleared | W33: 0 | X33: 2 | Y33: 0 | Z33: Car Parking Space | AA33: HB2 | AB33: 45504
A34: Active | B34: 45504 | C34: BTR-Regions | D34: Clippers Quay | E34: Helen Bowers | F34: Parking D18 Torrens Apt, Salford M50 | G34: Francis D'Sa | I34: Current | J34: 45139 | L34: 45139 | M34: 45504 | N34: New Let | O34: Licence | P34: 1380 | Q34: 115 | R34: 1200 | S34: 1500 | T34: 1200 | U34: 1380 | V34: Cleared | W34: 0 | X34: 0 | Y34: 0 | AA34: HB2 | AB34: 45504
A35: Active | B35: 45504 | C35: BTR-Regions | D35: Clippers Quay | E35: Helen Bowers | F35: Parking E38 Ambassador Apt , Salford M50 | G35: Kate Stafford | I35: Current | J35: 45139 | L35: 45139 | M35: 45504 | N35: New Let | O35: Licence | P35: 1380 | Q35: 115 | R35: 1200 | S35: 1500 | T35: 1200 | U35: 1380 | V35: Cleared | W35: 0 | X35: 0 | Y35: 0 | AA35: HB2 | AB35: 45504
A36: Active | B36: 45511 | C36: BTR-Regions | D36: Clippers Quay | E36: Helen Bowers | F36: Parking C20 Tayleur Apt, Salford M50 | G36: Long Cheng | I36: Current | J36: 45146 | L36: 45146 | M36: 45511 | N36: New Let | O36: Licence | P36: 1380 | Q36: 115 | R36: 1260 | S36: 1500 | T36: 1260 | U36: 1380 | V36: Cleared | W36: 0 | X36: 3 | Y36: 0 | Z36: Car Parking Space | AA36: HB2 | AB36: 45511
A37: Active | B37: 45511 | C37: BTR-Regions | D37: Clippers Quay | E37: Helen Bowers | F37: Parking D41 Torrens Apt, Salford M50 | G37: Cheung Kit Danny | I37: Current | J37: 45146 | L37: 45146 | M37: 45511 | N37: New Let | O37: Licence | P37: 1380 | Q37: 115 | R37: 1200 | S37: 1500 | T37: 1200 | U37: 1380 | V37: Cleared | W37: 0 | X37: 0 | Y37: 0 | AA37: HB2 | AB37: 45511
A38: Active | B38: 45513 | C38: BTR-Regions | D38: Clippers Quay | E38: Helen Bowers | F38: Parking E10 Ambassador Apt , Salford M50 | G38: Chung Kong Tse | I38: Current | J38: 45148 | L38: 45148 | M38: 45513 | N38: New Let | O38: Licence | P38: 1380 | Q38: 115 | R38: 1260 | S38: 1500 | T38: 1260 | U38: 1380 | V38: Cleared | W38: 0 | X38: 0 | Y38: 0 | AA38: HB2 | AB38: 45513
A39: Active | B39: 45513 | C39: BTR-Regions | D39: Clippers Quay | E39: Helen Bowers | F39: Parking E19 Ambassador Apt , Salford M50 | G39: Dr Sunil Anirudhprasad Jayaswal | I39: Current | J39: 44067 | L39: 45148 | M39: 45513 | N39: Renewal | O39: Licence | P39: 1380 | Q39: 115 | R39: 1260 | S39: 1500 | T39: 1260 | U39: 1380 | V39: Cleared | W39: 0 | X39: 0 | Y39: 0 | AA39: HB2 | AB39: 45513
A40: Active | B40: 45515 | C40: BTR-Regions | D40: Clippers Quay | E40: Helen Bowers | F40: Parking E28 Ambassador Apt , Salford M50 | G40: Ruby Fisher | I40: Current | J40: 44785 | L40: 45150 | M40: 45515 | N40: Renewal | O40: Licence | P40: 1380 | Q40: 115 | R40: 1200 | S40: 1500 | T40: 1200 | U40: 1380 | V40: Cleared | W40: 0 | X40: 0 | Y40: 0 | AA40: HB2 | AB40: 45515
...

Sheet DO NOT APPROACH
A1: Diary Status | B1: Event Date | C1: Portfolio | D1: Estate | E1: Unit Manager | F1: Unit Description | G1: Current Tenant Name | H1: PM Details | I1: Tenancy Status | J1: Tenancy Start Date | K1: Lease Start Date | L1: Lease End Date | M1: Action Type | N1: Unit Tenure | O1: September 23 Annual ERV | P1: September 23 Monthly ERV | Q1: March 24 Annual ERV | R1: March 24 Monthly ERV | S1: Current Annual Rent | T1: Current Monthly Rent | U1: Previous Rent | V1: Price Book Rent | W1: Price Book / Current Rent % | X1: Price Book / March 24 ERV % | Y1: AM Offering | Z1: AM Offering / Current Rent % | AA1: AM Offering / March 24 ERV % | AB1: AM Minimum | AC1: AM Minimum / Current Rent % | AD1: AM Minimum / Sept ERV % | AE1: AM Comments | AF1: Tenant Balance Status | AG1: Unit Size | AH1: Number of Beds | AI1: Number of Baths | AJ1: Description of Unit | AK1: Renewal Neg | AL1: Renewal Notes Date | AM1: Renewal Notes
A2: denied | B2: 45521 | C2: BTR-Regions | D2: Clippers Quay | E2: Helen Bowers | F2: 808 Syren Apt , Ottinger Close, Salford M50 | G2: Revanth Challa, Venjata Chebiam, Sreeja Balne | H2: do not renew - residents have fallen out/wont agree to change of sharer. | I2: Current | J2: 44791 | K2: 45156 | L2: 45521 | M2: Renewal | N2: AST | O2: 16020 | P2: 1335 | Q2: 16560 | R2: =Q2/12 -> 1380 | S2: 15720 | T2: =S2/12 -> 1310 | U2: 14340 | V2: 1410 | W2: =(V2-T2)/T2 -> 0.076335878 | X2: =(V2-R2)/R2 -> 0.02173913 | Z2: =(Y2-T2)/T2 -> -1 | AA2: =(Y2-R2)/R2 -> -1 | AC2: =(AB2-T2)/T2 -> -1 | AD2: =(AB2-R2)/R2 -> -1 | AF2: Cleared | AG2: 668 | AH2: 2 | AI2: 2 | AJ2: 2 BedValencia | AK2: Lacey | AL2: 45521
A3: denied | B3: 45490 | C3: BTR-Regions | D3: Enigma Square | E3: Tina Viragh | F3: 506 Enigma Square, 414 North Row, MK9 2FU | G3: Akanksha Mehta & Ayush Jain | H3: Do not offer renewal - problematic towards site team | I3: Current | J3: 45125 | K3: 45125 | L3: 45490 | M3: New Let | N3: AST | O3: 15912 | P3: 1326 | Q3: 17316 | R3: =Q3/12 -> 1443 | S3: 15600 | T3: =S3/12 -> 1300 | U3: 15912 | V3: 1470 | W3: =(V3-T3)/T3 -> 0.13076923 | X3: =(V3-R3)/R3 -> 0.018711019 | Z3: =(Y3-T3)/T3 -> -1 | AA3: =(Y3-R3)/R3 -> -1 | AC3: =(AB3-T3)/T3 -> -1 | AD3: =(AB3-R3)/R3 -> -1 | AF3: Cleared | AG3: 528.6 | AH3: 1 | AI3: 1 | AJ3: 1B2P, 01D(J)North East, Balcony | AK3: Sophie | AL3: 45490
A4: denied | B4: 45486 | C4: BTR-Regions | D4: Enigma Square | E4: Tina Viragh | F4: 708 Enigma Square, 414 North Row, MK9 2FU | G4: S Bedre, R Patil, S Amin and S Chavan | H4: Do not offer renewal. Residents have been verbally abusive to site team and caused lots of issues | I4: Current | J4: 45121 | K4: 45121 | L4: 45486 | M4: New Let | N4: AST | O4: 20540 | P4: 1711.6667 | Q4: 21320 | R4: =Q4/12 -> 1776.6667 | S4: 21240 | T4: =S4/12 -> 1770 | U4: 20540 | V4: 1890 | W4: =(V4-T4)/T4 -> 0.06779661 | X4: =(V4-R4)/R4 -> 0.063789869 | Z4: =(Y4-T4)/T4 -> -1 | AA4: =(Y4-R4)/R4 -> -1 | AC4: =(AB4-T4)/T4 -> -1 | AD4: =(AB4-R4)/R4 -> -1 | AF4: Cleared | AG4: 664.3 | AH4: 2 | AI4: 2 | AJ4: 2B4P, 02D(M)North East, Balcony | AK4: Sophie | AL4: 45486
A5: denied | B5: 45521 | C5: BTR-Regions | D5: The Filaments | E5: Samantha Lancaster | F5: 804, Halogen House, 217 Chapel St, Salford, M | G5: Okikioluwa Fagbemi & Khalid Adeleke | H5: No - Do not offer, too many noise disturbances - check with PM | I5: Current | J5: 45156 | K5: 45156 | L5: 45521 | M5: New Let | N5: AST | O5: 24600 | P5: 2050 | Q5: 25200 | R5: =Q5/12 -> 2100 | S5: 24600 | T5: =S5/12 -> 2050 | U5: 21540 | V5: 2195 | W5: =(V5-T5)/T5 -> 0.070731707 | X5: =(V5-R5)/R5 -> 0.045238095 | Z5: =(Y5-T5)/T5 -> -1 | AA5: =(Y5-R5)/R5 -> -1 | AC5: =(AB5-T5)/T5 -> -1 | AD5: =(AB5-R5)/R5 -> -1 | AF5: Arrears | AG5: 874 | AH5: 3 | AI5: 2 | AJ5: Balcony, ESE3 Bed - TYPE A | AK5: Lacey | AL5: 45521
A6: denied | B6: 45533 | C6: BTR-London & SE | D6: The Mint | E6: Kimberley Pope | F6: 315 Assay Apartments, Station View, Guildford | G6: Khaled Alalawi | H6: Resident has had final warnings relating to smoke on apartment balcony. Reports this is ongoing. Therefore, no renewal will be offered. | I6: Current | J6: 45168 | K6: 45168 | L6: 45533 | M6: New Let | N6: AST | O6: 19920 | P6: 1660 | Q6: 20040 | R6: =Q6/12 -> 1670 | S6: 19740 | T6: =S6/12 -> 1645 | U6: 19920 | V6: 1750 | W6: =(V6-T6)/T6 -> 0.063829787 | X6: =(V6-R6)/R6 -> 0.047904192 | Z6: =(Y6-T6)/T6 -> -1 | AA6: =(Y6-R6)/R6 -> -1 | AC6: =(AB6-T6)/T6 -> -1 | AD6: =(AB6-R6)/R6 -> -1 | AF6: Cleared | AG6: 586.97 | AH6: 1 | AI6: 1 | AJ6: 1b2p, 1DNorth, Balcony | AK6: Jemma | AL6: 45533
A7: Aborted | B7: 45530 | C7: BTR-London & SE | D7: Argo Apartments | E7: Fatma Azakli | F7: 108 Argo Apts,4 Silvertown Way,London,E16 1YD | G7: Zitong Zhao & Oliver Firth | H7: They have vacated. | I7: Current | J7: 44435 | K7: 45165 | L7: 45530 | M7: Renewal | N7: AST | O7: 23640 | P7: 1970 | Q7: 23820 | R7: =Q7/12 -> 1985 | S7: 22140 | T7: =S7/12 -> 1845 | U7: 20400 | V7: 2130 | W7: =(V7-T7)/T7 -> 0.15447154 | X7: =(V7-R7)/R7 -> 0.073047859 | Z7: =(Y7-T7)/T7 -> -1 | AA7: =(Y7-R7)/R7 -> -1 | AC7: =(AB7-T7)/T7 -> -1 | AD7: =(AB7-R7)/R7 -> -1 | AF7: Cleared | AG7: 572 | AH7: 1 | AI7: 1 | AJ7: 1 bed & 1 bath South-West Right13th floor | AK7: Jemma | AL7: 45530
A8: ntq | B8: 45534 | C8: BTR-Regions | D8: Enigma Square | E8: Tina Viragh | F8: 719 Enigma Square, 414 North Row, MK9 2GE | G8: Mr Radhakrishnan, Miss Khambete, Mr Sundarraj | H8: Wants early release - do not offer renewal if they change their mind | I8: Current | J8: 45169 | K8: 45169 | L8: 45534 | M8: New Let | N8: AST | O8: 23504 | P8: 1958.6667 | Q8: 25168 | R8: =Q8/12 -> 2097.3333 | S8: 23940 | T8: =S8/12 -> 1995 | U8: 22620 | V8: 2020 | W8: =(V8-T8)/T8 -> 0.012531328 | X8: =(V8-R8)/R8 -> -0.036872219 | Z8: =(Y8-T8)/T8 -> -1 | AA8: =(Y8-R8)/R8 -> -1 | AC8: =(AB8-T8)/T8 -> -1 | AD8: =(AB8-R8)/R8 -> -1 | AF8: Cleared | AG8: 1065.8 | AH8: 3 | AI8: 1 | AJ8: 3B6P, 03BSouth East, Balcony | AK8: Sophie | AL8: 45534
A9: ntq | B9: 45510 | C9: BTR-Regions | D9: Enigma Square | E9: Tina Viragh | F9: 809 Enigma Square, 414 North Row, MK9 2GE | G9: Carly McGill and Marc Leonard | H9: Has requested early release - will not be renewing | I9: Current | J9: 45145 | K9: 45145 | L9: 45510 | M9: New Let | N9: AST | O9: 15288 | P9: 1274 | Q9: 16848 | R9: =Q9/12 -> 1404 | S9: 15600 | T9: =S9/12 -> 1300 | U9: 15288 | V9: 1445 | W9: =(V9-T9)/T9 -> 0.11153846 | X9: =(V9-R9)/R9 -> 0.029202279 | Z9: =(Y9-T9)/T9 -> -1 | AA9: =(Y9-R9)/R9 -> -1 | AC9: =(AB9-T9)/T9 -> -1 | AD9: =(AB9-R9)/R9 -> -1 | AF9: Credit | AG9: 437.2 | AH9: 1 | AI9: 1 | AJ9: 1B2P, 01E(M)South West, Balcony | AK9: Sophie | AL9: 45510
A10: aborted | B10: 45533 | C10: BTR-London & SE | D10: Gatehouse Apartments | E10: Alice Shaw | F10: 103 Gatehouse Apts, 86 East St, Southampton | G10: Miss Keri Cooper, Miss Frances Phillis | H10: Leaving - already on market | I10: Current | J10: 45168 | K10: 45168 | L10: 45533 | M10: New Let | N10: AST | O10: 18600 | P10: 1550 | Q10: 18600 | R10: =Q10/12 -> 1550 | S10: 18600 | T10: =S10/12 -> 1550 | U10: 17820 | V10: 1575 | W10: =(V10-T10)/T10 -> 0.016129032 | X10: =(V10-R10)/R10 -> 0.016129032 | Z10: =(Y10-T10)/T10 -> -1 | AA10: =(Y10-R10)/R10 -> -1 | AC10: =(AB10-T10)/T10 -> -1 | AD10: =(AB10-R10)/R10 -> -1 | AF10: Cleared | AG10: 777 | AH10: 2 | AI10: 2 | AJ10: L7, Encl. balcony, River Itchen/Cruise ship2Bed 4P, Type 2B | AK10: Jemma | AL10: 45533
A11: aborted | B11: 45513 | C11: BTR-London & SE | D11: Gatehouse Apartments | E11: Alice Shaw | F11: 126 Gatehouse Apts, 86 East St, Southampton | G11: Chi Kong Cheung & Wai Man Lee | H11: Leaving - already on market | I11: Current | J11: 44783 | K11: 45148 | L11: 45513 | M11: Renewal | N11: AST | O11: 18600 | P11: 1550 | Q11: 19740 | R11: =Q11/12 -> 1645 | S11: 18540 | T11: =S11/12 -> 1545 | U11: 17280 | V11: 1750 | W11: =(V11-T11)/T11 -> 0.13268608 | X11: =(V11-R11)/R11 -> 0.063829787 | Z11: =(Y11-T11)/T11 -> -1 | AA11: =(Y11-R11)/R11 -> -1 | AC11: =(AB11-T11)/T11 -> -1 | AD11: =(AB11-R11)/R11 -> -1 | AF11: Cleared | AG11: 742 | AH11: 2 | AI11: 2 | AJ11: L13, Encl. balcony, Town Hall/River Itchen2Bed 4P, Type 2A | AK11: Jemma | AL11: 45513
A12: ntq | B12: 45503 | C12: BTR-Regions | D12: Enigma Square | E12: Tina Viragh | F12: 814 Enigma Square, 414 North Row, MK9 2GE | G12: Owen and Tamara Lane | H12: Has requested early release - will not be renewing | I12: Current | J12: 45138 | K12: 45138 | L12: 45503 | M12: New Let | N12: AST | O12: 15600 | P12: 1300 | Q12: 17108 | R12: =Q12/12 -> 1425.6667 | S12: 15720 | T12: =S12/12 -> 1310 | U12: 15600 | V12: 1470 | W12: =(V12-T12)/T12 -> 0.1221374 | X12: =(V12-R12)/R12 -> 0.031096563 | Z12: =(Y12-T12)/T12 -> -1 | AA12: =(Y12-R12)/R12 -> -1 | AC12: =(AB12-T12)/T12 -> -1 | AD12: =(AB12-R12)/R12 -> -1 | AF12: Cleared | AG12: 486 | AH12: 1 | AI12: 1 | AJ12: 1B2P, 01C_S(MJ)North East, Balcony | AK12: Sophie | AL12: 45503
A13: completed | B13: 45504 | C13: Rev-London & SE | D13: Outer London | E13: Robert Steel | F13: 52, Morieux Road, Leyton, London | G13: Mr Harold George Doy | H13: Issue section 13 notice to increase rent to £800 PCM with effect from 1st August 2024. | I13: Current | J13: 45139 | M13: New Let | N13: Assured | O13: 7200 | P13: 600 | R13: =Q13/12 -> 0 | S13: 7200 | T13: =S13/12 -> 600 | U13: 175 | W13: =(V13-T13)/T13 -> -1 | X13: =(V13-R13)/R13 -> #DIV/0! | Z13: =(Y13-T13)/T13 -> -1 | AA13: =(Y13-R13)/R13 -> #DIV/0! | AC13: =(AB13-T13)/T13 -> -1 | AD13: =(AB13-R13)/R13 -> #DIV/0! | AF13: Cleared | AG13: 0 | AJ13: Purpose-built flat ground floor1 bedroom, 1 reception | AK13: Jemma | AL13: 45504
