Workbook
Name aspectpremium: '2. GRI Pricing Inputs'!$C$53:$E$55
Name balcony: '2. GRI Pricing Inputs'!$C$67:$E$69
Name baseprice: '2. GRI Pricing Inputs'!$C$15:$F$17
Name bathpremium: '2. GRI Pricing Inputs'!$C$21:$E$24
Name floorpremium: '2. GRI Pricing Inputs'!$C$45:$E$47
Name other: '2. GRI Pricing Inputs'!$O$32:$P$47
Name phasedrelease: '2. GRI Pricing Inputs'!$I$54
Name sizepremium: '2. GRI Pricing Inputs'!$C$28:$E$31

Sheet Cover
C3: BTR PRICING WORKBOOK
K5: ACQ | L5: CFT | M5: ONB | N5: AM | O5: LET
C6: Project: | E6: The Forge, Newcastle | J6: Project Team | K6: [Name] | L6: [Name] | M6: [Name] | N6: [Name] | O6: [Name]
C7: Pricing Date: | E7: 44538 | J7: Reviewer | K7: [Name] | L7: [Name] | M7: [Name] | N7: [Name] | O7: [Name]
C9: INSTRUCTIONS
C11: Key: | E11: Light blue = input | G11: White = calculation
C13: Tab | D13: Process
C14: 1. Accomodation tab | D14: 1 | E14: Input accomodation to be constructed, as per the Development agreement, in columns D-F (request final DA from the acquistions manager)
D15: 2 | E15: Update Qube for Qube location data (fund/portfolio/estate) as per BTR example provided (check with asset manager if unsure)
D16: 3 | E16: Create Grainger schedule as required in the format provided (Col L-AA)
D17: 4 | E17: Input Grainger required accomodation attributes (Col S-AA)
C19: 2. GRI Pricing inputs | D19: 5 | E19: Input premium values and growth inputs (Number 1-15)
D20: 6 | E20: Describe methodology for each inputs
C22: 3. GRI Pricing | D22: 7 | E22: Review and sense check pricing framework unit by unit
D23: 8 | E23: Add any manual adjustment and provide rationale for adjustments
D24: 9 | E24: Review and sense check overall and average pricing
C26: 4. CBRE ERV's | D26: 10 | E26: CFT to provide i) approved underwritten rents ii) market ERV per the latest CBRE valuation
D27: 11 | E27: Communication expected launch date to CFT in order to grow benchmarks to same point in time.
D28: 12 | E28: All rents must be compared at the same point in time, on a like for like basis.
D29: 13 | E29: If appraising the current market rent today, we must grow both the underwriting and CBRE from their respective points in time to today.
D30: 14 | E30: Grainger underwrite rental growth for each project and CBRE assume rental growth in their valuation (check growth % for each specific project).
C32: 5. Dashboard | D32: 15 | E32: Review dashboard, ensure current pricing are in line as expected of the current view of the market
D33: 16 | E33: Aim to launch at and outperform the higher of i) ‘grown underwritten ERV’ and ii) ‘CBRE Est. Forecast' ERV
D34: 17 | E34: Append the table within leasing and marketing report
C36: 6. IC Appendix | D36: 18 | E36: Append the full master schedule within leasing and marketing report.
C38: 7. Archive Pricing | D38: 19 | E38: To allow tracking of previously approved prices for each unit.

Sheet 1. Accomodation
H3: 1. ACCOMODATION SCHEDULE | Y3: ='4. Valuation'!$D$6 -> 45199
H5: Project | I5: =Cover!E6 -> The Forge, Newcastle
H7: Qube Location Data | L7: Grainger Accomodation
H8: Qube Field | I8: Inputs | J8: Example | L8: Bedroom | M8: No. of Homes | N8: Av. Size (sqft) | O8: Notes
H9: Fund | I9: BTR-Regions | L9: 1 Bed | M9: =IFERROR(COUNTIF($P$21:$P$622,$L9),"-") -> 78 | N9: =IFERROR(AVERAGEIF($P$21:$P$622,$L9,$O$21:$O$622),"-") -> 503.5641
H10: Portfolio | I10: The Forge | L10: 2 Bed | M10: =IFERROR(COUNTIF($P$21:$P$622,$L10),"-") -> 179 | N10: =IFERROR(AVERAGEIF($P$21:$P$622,$L10,$O$21:$O$622),"-") -> 652.34637
H11: Estate | I11: The Forge - Apts | J11: XXXX - Apartments | L11: 3 Bed | M11: =IFERROR(COUNTIF($P$21:$P$622,$L11),"-") -> 26 | N11: =IFERROR(AVERAGEIF($P$21:$P$622,$L11,$O$21:$O$622),"-") -> 823.19231
J12: XXXX - XXX Apts | M12: =IFERROR(COUNTIF($P$21:$P$622,$L12),"-") -> 0 | N12: =IFERROR(AVERAGEIF($P$21:$P$622,$L12,$O$21:$O$622),"-") -> -
J13: XXXX - Amenity | M13: =IFERROR(COUNTIF($P$21:$P$622,$L13),"-") -> 0 | N13: =IFERROR(AVERAGEIF($P$21:$P$622,$L13,$O$21:$O$622),"-") -> -
J14: XXXX - Commercial | M14: =IFERROR(COUNTIF($P$21:$P$622,$L14),"-") -> 0 | N14: =IFERROR(AVERAGEIF($P$21:$P$622,$L14,$O$21:$O$622),"-") -> -
L15: Total | M15: =SUM(M9:M13) -> 283 | N15: =IFERROR(SUM(O21:O620)/M15,0) -> 627.03534
J16: XXXX - Car Parking | L16: Car Park
D19: DA ACCOMODATION | H19: Qube Property Location Inputs | L19: GRAINGER ACCOMODATION
C20: Plot Number | D20: Home type | E20: Size (sq.ft) | F20: Bedroom | H20: Fund | I20: Portfolio | J20: Estate | L20: Block Name | M20: =D20 -> Home type | N20: Door Number | O20: =E20 -> Size (sq.ft) | P20: ='2. GRI Pricing Inputs'!C15 -> Bedroom | Q20: ='2. GRI Pricing Inputs'!C22 -> Bath | R20: ='2. GRI Pricing Inputs'!C45 -> Floor | S20: ='2. GRI Pricing Inputs'!C53 -> Aspect | T20: ='2. GRI Pricing Inputs'!C60 -> Storage | U20: ='2. GRI Pricing Inputs'!C67 -> Balcony | V20: ='2. GRI Pricing Inputs'!C83 -> Window Premium | W20: ='2. GRI Pricing Inputs'!C90 -> Restricted Light | X20: ='2. GRI Pricing Inputs'!C98 -> 0 | Y20: ='2. GRI Pricing Inputs'!C105 -> Character premium #4
D21: [Select] | H21: =$I$9 -> BTR-Regions | I21: =$I$10 -> The Forge | J21: The Forge - Apts | L21: North | M21: Apartment | N21: 101N | O21: 484 | P21: 1 Bed | Q21: 1 | R21: Ground | S21: Courtyard | T21: [Select] | U21: No | V21: External Access | W21: No | X21: No | Y21: [A-4]
D22: [Select] | H22: =$I$9 -> BTR-Regions | I22: =$I$10 -> The Forge | J22: The Forge - Apts | L22: North | M22: Apartment | N22: 102N | O22: 678 | P22: 2 Bed | Q22: 2 | R22: Ground | S22: Courtyard | T22: [Select] | U22: No | V22: External Access | W22: No | X22: No | Y22: [Select]
D23: [Select] | H23: =$I$9 -> BTR-Regions | I23: =$I$10 -> The Forge | J23: The Forge - Apts | L23: North | M23: Apartment | N23: 103N | O23: 657 | P23: 2 Bed | Q23: 2 | R23: Ground | S23: Courtyard | T23: [Select] | U23: No | V23: Normal | W23: No | X23: No | Y23: [Select]
D24: [Select] | H24: =$I$9 -> BTR-Regions | I24: =$I$10 -> The Forge | J24: The Forge - Apts | L24: North | M24: Apartment | N24: 104N | O24: 818 | P24: 3 Bed | Q24: 2 | R24: 1 | S24: Pottery Lane | T24: [Select] | U24: No | V24: Normal | W24: No | X24: No | Y24: [Select]
D25: [Select] | H25: =$I$9 -> BTR-Regions | I25: =$I$10 -> The Forge | J25: The Forge - Apts | L25: North | M25: Apartment | N25: 105N | O25: 667 | P25: 2 Bed | Q25: 2 | R25: 1 | S25: Forth Banks/Pottery Lane | T25: [Select] | U25: No | V25: Normal | W25: No | X25: No | Y25: [Select]
D26: [Select] | H26: =$I$9 -> BTR-Regions | I26: =$I$10 -> The Forge | J26: The Forge - Apts | L26: North | M26: Apartment | N26: 106N | O26: 441 | P26: 1 Bed | Q26: 1 | R26: 1 | S26: Forth Banks | T26: [Select] | U26: No | V26: Normal | W26: No | X26: Adjustment - 15 | Y26: [Select]
D27: [Select] | H27: =$I$9 -> BTR-Regions | I27: =$I$10 -> The Forge | J27: The Forge - Apts | L27: North | M27: Apartment | N27: 107N | O27: 624 | P27: 2 Bed | Q27: 2 | R27: 1 | S27: Forth Banks | T27: [Select] | U27: No | V27: Normal | W27: No | X27: No | Y27: [Select]
D28: [Select] | H28: =$I$9 -> BTR-Regions | I28: =$I$10 -> The Forge | J28: The Forge - Apts | L28: North | M28: Apartment | N28: 108N | O28: 624 | P28: 2 Bed | Q28: 2 | R28: 1 | S28: Forth Banks | T28: [Select] | U28: No | V28: Normal | W28: No | X28: No | Y28: [Select]
D29: [Select] | H29: =$I$9 -> BTR-Regions | I29: =$I$10 -> The Forge | J29: The Forge - Apts | L29: North | M29: Apartment | N29: 109N | O29: 657 | P29: 2 Bed | Q29: 2 | R29: 1 | S29: River - Partial | T29: [Select] | U29: No | V29: Normal | W29: No | X29: No | Y29: [Select]
D30: [Select] | H30: =$I$9 -> BTR-Regions | I30: =$I$10 -> The Forge | J30: The Forge - Apts | L30: North | M30: Apartment | N30: 110N | O30: 700 | P30: 2 Bed | Q30: 2 | R30: 1 | S30: Forth Banks - Partial | T30: [Select] | U30: No | V30: Normal | W30: No | X30: No | Y30: [Select]
D31: [Select] | H31: =$I$9 -> BTR-Regions | I31: =$I$10 -> The Forge | J31: The Forge - Apts | L31: North | M31: Apartment | N31: 111N | O31: 689 | P31: 2 Bed | Q31: 2 | R31: 1 | S31: Courtyard - dual | T31: [Select] | U31: Yes | V31: Normal | W31: No | X31: No | Y31: [Select]
D32: [Select] | H32: =$I$9 -> BTR-Regions | I32: =$I$10 -> The Forge | J32: The Forge - Apts | L32: North | M32: Apartment | N32: 112N | O32: 506 | P32: 1 Bed | Q32: 1 | R32: Ground | S32: Courtyard | T32: [Select] | U32: No | V32: External Access | W32: No | X32: No | Y32: [Select]
D33: [Select] | H33: =$I$9 -> BTR-Regions | I33: =$I$10 -> The Forge | J33: The Forge - Apts | L33: North | M33: Apartment | N33: 113N | O33: 538 | P33: 1 Bed | Q33: 1 | R33: Ground | S33: Courtyard | T33: [Select] | U33: No | V33: External Access | W33: No | X33: No | Y33: [Select]
D34: [Select] | H34: =$I$9 -> BTR-Regions | I34: =$I$10 -> The Forge | J34: The Forge - Apts | L34: North | M34: Apartment | N34: 114N | O34: 560 | P34: 1 Bed | Q34: 1 | R34: Ground | S34: Courtyard | T34: [Select] | U34: No | V34: External Access | W34: Resticted - 25 | X34: No | Y34: [Select]
D35: [Select] | H35: =$I$9 -> BTR-Regions | I35: =$I$10 -> The Forge | J35: The Forge - Apts | L35: North | M35: Apartment | N35: 115N | O35: 624 | P35: 2 Bed | Q35: 2 | R35: Ground | S35: Courtyard | T35: [Select] | U35: No | V35: External Access | W35: No | X35: No | Y35: [Select]
D36: [Select] | H36: =$I$9 -> BTR-Regions | I36: =$I$10 -> The Forge | J36: The Forge - Apts | L36: North | M36: Apartment | N36: 116N | O36: 624 | P36: 2 Bed | Q36: 2 | R36: Ground | S36: Courtyard | T36: [Select] | U36: No | V36: External Access | W36: No | X36: No | Y36: [Select]
D37: [Select] | H37: =$I$9 -> BTR-Regions | I37: =$I$10 -> The Forge | J37: The Forge - Apts | L37: North | M37: Apartment | N37: 201N | O37: 484 | P37: 1 Bed | Q37: 1 | R37: 2 | S37: Courtyard | T37: [Select] | U37: No | V37: Normal | W37: No | X37: No | Y37: [Select]
D38: [Select] | H38: =$I$9 -> BTR-Regions | I38: =$I$10 -> The Forge | J38: The Forge - Apts | L38: North | M38: Apartment | N38: 202N | O38: 678 | P38: 2 Bed | Q38: 2 | R38: 2 | S38: Courtyard | T38: [Select] | U38: No | V38: Normal | W38: No | X38: No | Y38: [Select]
D39: [Select] | H39: =$I$9 -> BTR-Regions | I39: =$I$10 -> The Forge | J39: The Forge - Apts | L39: North | M39: Apartment | N39: 203N | O39: 657 | P39: 2 Bed | Q39: 2 | R39: 2 | S39: Courtyard | T39: [Select] | U39: No | V39: Normal | W39: No | X39: No | Y39: [Select]
D40: [Select] | H40: =$I$9 -> BTR-Regions | I40: =$I$10 -> The Forge | J40: The Forge - Apts | L40: North | M40: Apartment | N40: 204N | O40: 818 | P40: 3 Bed | Q40: 2 | R40: 2 | S40: Pottery Lane | T40: [Select] | U40: No | V40: Normal | W40: No | X40: No | Y40: [Select]
D41: [Select] | H41: =$I$9 -> BTR-Regions | I41: =$I$10 -> The Forge | J41: The Forge - Apts | L41: North | M41: Apartment | N41: 205N | O41: 667 | P41: 2 Bed | Q41: 2 | R41: 2 | S41: Forth Banks/Pottery Lane | T41: [Select] | U41: No | V41: Normal | W41: No | X41: No | Y41: [Select]
D42: [Select] | H42: =$I$9 -> BTR-Regions | I42: =$I$10 -> The Forge | J42: The Forge - Apts | L42: North | M42: Apartment | N42: 206N | O42: 441 | P42: 1 Bed | Q42: 1 | R42: 2 | S42: Forth Banks | T42: [Select] | U42: No | V42: Normal | W42: No | X42: Adjustment - 15 | Y42: [Select]
D43: [Select] | H43: =$I$9 -> BTR-Regions | I43: =$I$10 -> The Forge | J43: The Forge - Apts | L43: North | M43: Apartment | N43: 207N | O43: 624 | P43: 2 Bed | Q43: 2 | R43: 2 | S43: Forth Banks | T43: [Select] | U43: No | V43: Normal | W43: No | X43: No | Y43: [Select]
D44: [Select] | H44: =$I$9 -> BTR-Regions | I44: =$I$10 -> The Forge | J44: The Forge - Apts | L44: North | M44: Apartment | N44: 208N | O44: 624 | P44: 2 Bed | Q44: 2 | R44: 2 | S44: Forth Banks | T44: [Select] | U44: No | V44: Normal | W44: No | X44: No | Y44: [Select]
D45: [Select] | H45: =$I$9 -> BTR-Regions | I45: =$I$10 -> The Forge | J45: The Forge - Apts | L45: North | M45: Apartment | N45: 209N | O45: 657 | P45: 2 Bed | Q45: 2 | R45: 2 | S45: River - Partial | T45: [Select] | U45: No | V45: Normal | W45: No | X45: No | Y45: [Select]
D46: [Select] | H46: =$I$9 -> BTR-Regions | I46: =$I$10 -> The Forge | J46: The Forge - Apts | L46: North | M46: Apartment | N46: 210N | O46: 700 | P46: 2 Bed | Q46: 2 | R46: 2 | S46: Forth Banks - Partial | T46: [Select] | U46: No | V46: Normal | W46: No | X46: No | Y46: [Select]
...

Sheet 2. GRI Pricing Inputs
C3: 2. GRAINGER PRICING INPUTS | AL3: METHODOLOGY
C5: 0. Accomodation information
C7: Home Type | D7: [Select] | E7: Apartment
C9: Block Name | D9: [Select] | E9: North | F9: South | G9: West
C11: 1. Base price
C13: The base pricing for each bed type based on comparable evidence of the local market.
C15: Bedroom | D15: [Select] | E15: ='1. Accomodation'!L9 -> 1 Bed | F15: ='1. Accomodation'!L10 -> 2 Bed | G15: ='1. Accomodation'!L11 -> 3 Bed | H15: ='1. Accomodation'!L12 -> 0 | I15: ='1. Accomodation'!L13 -> 0 | J15: ='1. Accomodation'!M13 -> 0
C16: Base Price (£pm) | E16: 845 | F16: 1110 | G16: 1485
C18: 2. Bath premium
C20: The premium to the base pricing (assumes a standard X bed homes) to reflect either the discount for only have 1 bathroom or the premium for having two.
C22: Bath | D22: [Select] | E22: 1 | F22: 2 | G22: 3
C23: Bath Premium | E23: 0 | F23: 0 | G23: 0
C25: 3. Size premium by range
C27: The premium to the base pricing (assumes a standard X bed homes) to reflect units which are above or below the standard size.
C29: Bedroom | D29: [Select] | E29: 1 Bed | F29: 2 Bed | G29: 3 Bed | H29: [Select] | I29: [Select] | J29: [Select] | K29: [Select] | L29: [Select] | M29: [Select] | N29: [Select]
C30: Average size (sqft) | E30: =IFERROR(INDEX('1. Accomodation'!$F$9:$F$11,MATCH('2. GRI Pricing Inputs'!E$29,'1. Accomodation'!$D$9:$D$11,0)),0) -> 0 | F30: =IFERROR(INDEX('1. Accomodation'!$F$9:$F$11,MATCH('2. GRI Pricing Inputs'!F$29,'1. Accomodation'!$D$9:$D$11,0)),0) -> 0 | G30: =IFERROR(INDEX('1. Accomodation'!$F$9:$F$11,MATCH('2. GRI Pricing Inputs'!G$29,'1. Accomodation'!$D$9:$D$11,0)),0) -> 0 | H30: =IFERROR(INDEX('1. Accomodation'!$F$9:$F$11,MATCH('2. GRI Pricing Inputs'!H$29,'1. Accomodation'!$D$9:$D$11,0)),0) -> 0 | I30: =IFERROR(INDEX('1. Accomodation'!$F$9:$F$11,MATCH('2. GRI Pricing Inputs'!I$29,'1. Accomodation'!$D$9:$D$11,0)),0) -> 0 | J30: =IFERROR(INDEX('1. Accomodation'!$F$9:$F$11,MATCH('2. GRI Pricing Inputs'!J$29,'1. Accomodation'!$D$9:$D$11,0)),0) -> 0
C32: Size premium | D32: 1 | F32: 2 | H32: 3 | J32: 4 | L32: 5 | N32: 6 | P32: 7 | R32: 8 | T32: 9 | V32: 10 | X32: 11 | Z32: 12 | AB32: 13 | AD32: 14 | AF32: 15
D33: 484 | E33: 484 | F33: 495 | G33: 506 | H33: 517 | I33: 527 | J33: 538 | K33: 553 | L33: 560 | M33: 570 | N33: 603 | O33: 614 | P33: 623 | Q33: 636 | R33: 646 | S33: 657 | T33: 667 | U33: 667 | V33: 678 | W33: 678 | X33: 689 | Y33: 689 | Z33: 700 | AA33: 701 | AB33: 818 | AC33: 818 | AD33: 829 | AE33: 829 | AF33: 840 | AG33: 840
C34: 1 Bed | D34: 10 | F34: 15 | H34: 20 | J34: 25 | L34: 35
C35: 2 Bed | N35: 5 | P35: 10 | R35: 20 | T35: 30 | V35: 40 | X35: 65 | Z35: 70
C36: 3 Bed | AB36: 50 | AD36: 60 | AF36: 70
C37: [Select]
C38: [Select]
C39: [Select]
C41: 4. Floor premium
C43: A discount or premium to the base price is dependent on what floor the unit is located on (typical increments are between £5 - £20 per floor).
C45: Floor | D45: [Select] | E45: Ground | F45: 1 | G45: 2 | H45: 3 | I45: 4 | J45: 5 | K45: 6 | L45: 7 | M45: 8
C46: Floor premium | E46: 0 | F46: 30 | G46: 40 | H46: 50 | I46: 70 | J46: 70 | K46: 80 | L46: 90 | M46: 100
C49: 5. Aspect premium
C51: The premium to the base pricing is dependent on which direction the unit is facing (for e.g. south being the best).
C53: Aspect | D53: [Select] | E53: Fence | F53: Forth Banks | G53: Forth Banks/Pottery Lane | H53: Pottery Lane | I53: Railway Bridge | J53: Railway Bridge - Mid | K53: Courtyard | L53: River- Trees | M53: Railway Bridge - Higher | N53: Cityscape | O53: Forth Banks - Partial | P53: River - Partial | Q53: Courtyard - dual | R53: River- full
C54: Aspect premium | E54: 0 | F54: 5 | G54: 10 | H54: 10 | I54: 10 | J54: 20 | K54: 25 | L54: 30 | M54: 30 | N54: 35 | O54: 40 | P54: 45 | Q54: 55 | R54: 60
C56: 6. Storage premium
C58: The premium to the base pricing is dependent on the storage offered in the units.
C60: Storage | D60: [Select] | E60: Open Storage | F60: Traditional Wardrobe
C61: Storage premium | E61: 5 | F61: 0
C63: 7. Balcony premium
C65: A premium to base to reflect if there is a balcony present. Price is further broken down as below.
C67: Balcony | D67: [Select] | E67: Yes | F67: Recessed - Glass | G67: Recessed - Solid | H67: No
C68: Balcony premium | E68: 40 | F68: 20 | G68: 10 | H68: 0
...

Sheet 3. GRI Pricing
C3: 3. GRAINGER PRICING SCHEDULE
C5: Bedroom | D5: ='1. Accomodation'!N20 -> Door Number | E5: Av. Size (sqft) | F5: Launch Rent (pcm) | G5: Launch Rent (pa) | H5: Launch Rent (psf) | AB5: =C5 -> Bedroom | AC5: =AC16 -> 45230 | AD5: =AD16 -> 45260 | AE5: =AE16 -> 45291 | AF5: =AF16 -> 45322 | AG5: =AG16 -> 45351 | AH5: =AH16 -> 45382 | AI5: =AI16 -> 45412 | AJ5: =AJ16 -> 45443 | ... AO5: =AO16 -> 45596
C6: ='1. Accomodation'!L9 -> 1 Bed | D6: ='1. Accomodation'!M9 -> 78 | E6: ='1. Accomodation'!N9 -> 503.5641 | F6: =IFERROR(AVERAGEIF($D$17:$D$616,$C6,$Y$17:$Y$616),0) -> 999.80769 | G6: =F6*12 -> 11997.692 | H6: =IFERROR(G6/E6,0) -> 23.825551 | AB6: =C6 -> 1 Bed | AC6: =IFERROR(AVERAGEIF($D$17:$D$616,$C6,AC$17:AC$616),0) -> 1003.1437 | AD6: =IFERROR(AVERAGEIF($D$17:$D$616,$C6,AD$17:AD$616),0) -> 1006.3827 | AE6: =IFERROR(AVERAGEIF($D$17:$D$616,$C6,AE$17:AE$616),0) -> 1009.7406 | AF6: =IFERROR(AVERAGEIF($D$17:$D$616,$C6,AF$17:AF$616),0) -> 1013.1097 | AG6: =IFERROR(AVERAGEIF($D$17:$D$616,$C6,AG$17:AG$616),0) -> 1016.2716 | AH6: =IFERROR(AVERAGEIF($D$17:$D$616,$C6,AH$17:AH$616),0) -> 1019.6626 | AI6: =IFERROR(AVERAGEIF($D$17:$D$616,$C6,AI$17:AI$616),0) -> 1022.9549 | AJ6: =IFERROR(AVERAGEIF($D$17:$D$616,$C6,AJ$17:AJ$616),0) -> 1026.3681 | ... AO6: =IFERROR(AVERAGEIF($D$17:$D$616,$C6,AO$17:AO$616),0) -> 1043.3815
C7: ='1. Accomodation'!L10 -> 2 Bed | D7: ='1. Accomodation'!M10 -> 179 | E7: ='1. Accomodation'!N10 -> 652.34637 | F7: =IFERROR(AVERAGEIF($D$17:$D$616,$C7,$Y$17:$Y$616),0) -> 1293.4358 | G7: =F7*12 -> 15521.229 | H7: =IFERROR(G7/E7,0) -> 23.792926 | AB7: =C7 -> 2 Bed | AC7: =IFERROR(AVERAGEIF($D$17:$D$616,$C7,AC$17:AC$616),0) -> 1297.7515 | AD7: =IFERROR(AVERAGEIF($D$17:$D$616,$C7,AD$17:AD$616),0) -> 1301.9417 | AE7: =IFERROR(AVERAGEIF($D$17:$D$616,$C7,AE$17:AE$616),0) -> 1306.2858 | AF7: =IFERROR(AVERAGEIF($D$17:$D$616,$C7,AF$17:AF$616),0) -> 1310.6444 | AG7: =IFERROR(AVERAGEIF($D$17:$D$616,$C7,AG$17:AG$616),0) -> 1314.7349 | AH7: =IFERROR(AVERAGEIF($D$17:$D$616,$C7,AH$17:AH$616),0) -> 1319.1217 | AI7: =IFERROR(AVERAGEIF($D$17:$D$616,$C7,AI$17:AI$616),0) -> 1323.3809 | AJ7: =IFERROR(AVERAGEIF($D$17:$D$616,$C7,AJ$17:AJ$616),0) -> 1327.7965 | ... AO7: =IFERROR(AVERAGEIF($D$17:$D$616,$C7,AO$17:AO$616),0) -> 1349.8066
C8: ='1. Accomodation'!L11 -> 3 Bed | D8: ='1. Accomodation'!M11 -> 26 | E8: ='1. Accomodation'!N11 -> 823.19231 | F8: =IFERROR(AVERAGEIF($D$17:$D$616,$C8,$Y$17:$Y$616),0) -> 1698.6538 | G8: =F8*12 -> 20383.846 | H8: =IFERROR(G8/E8,0) -> 24.761949 | AB8: =C8 -> 3 Bed | AC8: =IFERROR(AVERAGEIF($D$17:$D$616,$C8,AC$17:AC$616),0) -> 1704.3216 | AD8: =IFERROR(AVERAGEIF($D$17:$D$616,$C8,AD$17:AD$616),0) -> 1709.8246 | AE8: =IFERROR(AVERAGEIF($D$17:$D$616,$C8,AE$17:AE$616),0) -> 1715.5296 | AF8: =IFERROR(AVERAGEIF($D$17:$D$616,$C8,AF$17:AF$616),0) -> 1721.2537 | AG8: =IFERROR(AVERAGEIF($D$17:$D$616,$C8,AG$17:AG$616),0) -> 1726.6258 | AH8: =IFERROR(AVERAGEIF($D$17:$D$616,$C8,AH$17:AH$616),0) -> 1732.3869 | AI8: =IFERROR(AVERAGEIF($D$17:$D$616,$C8,AI$17:AI$616),0) -> 1737.9805 | AJ8: =IFERROR(AVERAGEIF($D$17:$D$616,$C8,AJ$17:AJ$616),0) -> 1743.7795 | ... AO8: =IFERROR(AVERAGEIF($D$17:$D$616,$C8,AO$17:AO$616),0) -> 1772.685
C9: ='1. Accomodation'!L12 -> 0 | D9: ='1. Accomodation'!M12 -> 0 | E9: ='1. Accomodation'!N12 -> - | F9: =IFERROR(AVERAGEIF($D$17:$D$616,$C9,$Y$17:$Y$616),0) -> 0 | G9: =F9*12 -> 0 | H9: =IFERROR(G9/E9,0) -> 0 | AB9: =C9 -> 0 | AC9: =IFERROR(AVERAGEIF($D$17:$D$616,$C9,AC$17:AC$616),0) -> 0 | AD9: =IFERROR(AVERAGEIF($D$17:$D$616,$C9,AD$17:AD$616),0) -> 0 | AE9: =IFERROR(AVERAGEIF($D$17:$D$616,$C9,AE$17:AE$616),0) -> 0 | AF9: =IFERROR(AVERAGEIF($D$17:$D$616,$C9,AF$17:AF$616),0) -> 0 | AG9: =IFERROR(AVERAGEIF($D$17:$D$616,$C9,AG$17:AG$616),0) -> 0 | AH9: =IFERROR(AVERAGEIF($D$17:$D$616,$C9,AH$17:AH$616),0) -> 0 | AI9: =IFERROR(AVERAGEIF($D$17:$D$616,$C9,AI$17:AI$616),0) -> 0 | AJ9: =IFERROR(AVERAGEIF($D$17:$D$616,$C9,AJ$17:AJ$616),0) -> 0 | ... AO9: =IFERROR(AVERAGEIF($D$17:$D$616,$C9,AO$17:AO$616),0) -> 0
C10: ='1. Accomodation'!L13 -> 0 | D10: ='1. Accomodation'!M13 -> 0 | E10: ='1. Accomodation'!N13 -> - | F10: =IFERROR(AVERAGEIF($D$17:$D$616,$C10,$Y$17:$Y$616),0) -> 0 | G10: =F10*12 -> 0 | H10: =IFERROR(G10/E10,0) -> 0 | AB10: =C10 -> 0 | AC10: =IFERROR(AVERAGEIF($D$17:$D$616,$C10,AC$17:AC$616),0) -> 0 | AD10: =IFERROR(AVERAGEIF($D$17:$D$616,$C10,AD$17:AD$616),0) -> 0 | AE10: =IFERROR(AVERAGEIF($D$17:$D$616,$C10,AE$17:AE$616),0) -> 0 | AF10: =IFERROR(AVERAGEIF($D$17:$D$616,$C10,AF$17:AF$616),0) -> 0 | AG10: =IFERROR(AVERAGEIF($D$17:$D$616,$C10,AG$17:AG$616),0) -> 0 | AH10: =IFERROR(AVERAGEIF($D$17:$D$616,$C10,AH$17:AH$616),0) -> 0 | AI10: =IFERROR(AVERAGEIF($D$17:$D$616,$C10,AI$17:AI$616),0) -> 0 | AJ10: =IFERROR(AVERAGEIF($D$17:$D$616,$C10,AJ$17:AJ$616),0) -> 0 | ... AO10: =IFERROR(AVERAGEIF($D$17:$D$616,$C10,AO$17:AO$616),0) -> 0
C11: ='1. Accomodation'!L14 -> 0 | D11: ='1. Accomodation'!M14 -> 0 | E11: ='1. Accomodation'!N14 -> - | F11: =IFERROR(AVERAGEIF($D$17:$D$616,$C11,$Y$17:$Y$616),0) -> 0 | G11: =F11*12 -> 0 | H11: =IFERROR(G11/E11,0) -> 0 | AB11: =C11 -> 0 | AC11: =IFERROR(AVERAGEIF($D$17:$D$616,$C11,AC$17:AC$616),0) -> 0 | AD11: =IFERROR(AVERAGEIF($D$17:$D$616,$C11,AD$17:AD$616),0) -> 0 | AE11: =IFERROR(AVERAGEIF($D$17:$D$616,$C11,AE$17:AE$616),0) -> 0 | AF11: =IFERROR(AVERAGEIF($D$17:$D$616,$C11,AF$17:AF$616),0) -> 0 | AG11: =IFERROR(AVERAGEIF($D$17:$D$616,$C11,AG$17:AG$616),0) -> 0 | AH11: =IFERROR(AVERAGEIF($D$17:$D$616,$C11,AH$17:AH$616),0) -> 0 | AI11: =IFERROR(AVERAGEIF($D$17:$D$616,$C11,AI$17:AI$616),0) -> 0 | AJ11: =IFERROR(AVERAGEIF($D$17:$D$616,$C11,AJ$17:AJ$616),0) -> 0 | ... AO11: =IFERROR(AVERAGEIF($D$17:$D$616,$C11,AO$17:AO$616),0) -> 0
C12: AVERAGE | D12: ='1. Accomodation'!M15 -> 283 | E12: =IFERROR('1. Accomodation'!N15,0) -> 627.03534 | F12: =IFERROR(G12/12,0) -> 1249.735 | G12: =IFERROR(Y617/$D$12,0) -> 14996.82 | H12: =IFERROR(G12/$E$12,0) -> 23.917025 | AB12: =C12 -> AVERAGE | AC12: =IFERROR(AVERAGEIF($D$17:$D$616,$C12,AC$17:AC$616),0) -> 0 | AD12: =IFERROR(AVERAGEIF($D$17:$D$616,$C12,AD$17:AD$616),0) -> 0 | AE12: =IFERROR(AVERAGEIF($D$17:$D$616,$C12,AE$17:AE$616),0) -> 0 | AF12: =IFERROR(AVERAGEIF($D$17:$D$616,$C12,AF$17:AF$616),0) -> 0 | AG12: =IFERROR(AVERAGEIF($D$17:$D$616,$C12,AG$17:AG$616),0) -> 0 | AH12: =IFERROR(AVERAGEIF($D$17:$D$616,$C12,AH$17:AH$616),0) -> 0 | AI12: =IFERROR(AVERAGEIF($D$17:$D$616,$C12,AI$17:AI$616),0) -> 0 | AJ12: =IFERROR(AVERAGEIF($D$17:$D$616,$C12,AJ$17:AJ$616),0) -> 0 | ... AO12: =IFERROR(AVERAGEIF($D$17:$D$616,$C12,AO$17:AO$616),0) -> 0
C13: Car park | D13: ='1. Accomodation'!M16 -> 0 | F13: ='2. GRI Pricing Inputs'!D119 -> 10 | G13: =F13*12 -> 120 | AB13: =C13 -> Car park | AC13: =IFERROR(AVERAGEIF($D$17:$D$616,$C13,AC$17:AC$616),0) -> 0 | AD13: =IFERROR(AVERAGEIF($D$17:$D$616,$C13,AD$17:AD$616),0) -> 0 | AE13: =IFERROR(AVERAGEIF($D$17:$D$616,$C13,AE$17:AE$616),0) -> 0 | AF13: =IFERROR(AVERAGEIF($D$17:$D$616,$C13,AF$17:AF$616),0) -> 0 | AG13: =IFERROR(AVERAGEIF($D$17:$D$616,$C13,AG$17:AG$616),0) -> 0 | AH13: =IFERROR(AVERAGEIF($D$17:$D$616,$C13,AH$17:AH$616),0) -> 0 | AI13: =IFERROR(AVERAGEIF($D$17:$D$616,$C13,AI$17:AI$616),0) -> 0 | AJ13: =IFERROR(AVERAGEIF($D$17:$D$616,$C13,AJ$17:AJ$616),0) -> 0 | ... AO13: =IFERROR(AVERAGEIF($D$17:$D$616,$C13,AO$17:AO$616),0) -> 0
C15: Accomodation Attributes | K15: GRI PRICING FRAMEWORK | AB15: 45199 | AC15: Monthly rent increase over 12 months (using Grainger growth rate)
C16: ='1. Accomodation'!N20 -> Door Number | D16: ='1. Accomodation'!P20 -> Bedroom | E16: ='1. Accomodation'!Q20 -> Bath | F16: ='1. Accomodation'!O20 -> Size (sq.ft) | G16: ='1. Accomodation'!R20 -> Floor | H16: ='1. Accomodation'!S20 -> Aspect | K16: ='2. GRI Pricing Inputs'!C16 -> Base Price (£pm) | L16: ='2. GRI Pricing Inputs'!C23 -> Bath Premium | M16: Area Range | N16: ='2. GRI Pricing Inputs'!C32 -> Size premium | O16: ='2. GRI Pricing Inputs'!C46 -> Floor premium | P16: ='2. GRI Pricing Inputs'!C54 -> Aspect premium | Q16: ='2. GRI Pricing Inputs'!C61 -> Storage premium | R16: ='2. GRI Pricing Inputs'!C68 -> Balcony premium | S16: ='2. GRI Pricing Inputs'!C75 -> Amenity premium | T16: ='2. GRI Pricing Inputs'!C83 -> Window Premium | U16: ='2. GRI Pricing Inputs'!C90 -> Restricted Light | V16: ='2. GRI Pricing Inputs'!C98 -> 0 | W16: ='2. GRI Pricing Inputs'!C105 -> Character premium #4 | X16: Manual Adjustment (must provide reason) | Y16: Proposed Rent (pcm) | AC16: =EOMONTH(AB15,1) -> 45230 | AD16: =EOMONTH(AC16,1) -> 45260 | AE16: =EOMONTH(AD16,1) -> 45291 | AF16: =EOMONTH(AE16,1) -> 45322 | AG16: =EOMONTH(AF16,1) -> 45351 | AH16: =EOMONTH(AG16,1) -> 45382 | AI16: =EOMONTH(AH16,1) -> 45412 | AJ16: =EOMONTH(AI16,1) -> 45443 | AK16: =EOMONTH(AJ16,1) -> 45473 | ... AO16: =EOMONTH(AN16,1) -> 45596
C17: ='1. Accomodation'!N21 -> 101N | D17: ='1. Accomodation'!P21 -> 1 Bed | E17: ='1. Accomodation'!Q21 -> 1 | F17: ='1. Accomodation'!O21 -> 484 | G17: ='1. Accomodation'!R21 -> Ground | H17: ='1. Accomodation'!S21 -> Courtyard | K17: =IFERROR(INDEX('2. GRI Pricing Inputs'!$C$15:$AI$16,MATCH($K$16,'2. GRI Pricing Inputs'!$C$15:$C$16,0),MATCH(D17,'2. GRI Pricing Inputs'!$C$15:$AI$15,0)),0) -> 845 | L17: =IFERROR(INDEX('2. GRI Pricing Inputs'!$C$22:$AI$23,MATCH($L$16,'2. GRI Pricing Inputs'!$C$22:$C$23,0),MATCH(E17,'2. GRI Pricing Inputs'!$C$22:$AI$22,0)),0) -> 0 | M17: =IF(AND('3. GRI Pricing'!$F17>='2. GRI Pricing Inputs'!$D$33,'3. GRI Pricing'!$F17<='2. GRI Pricing Inputs'!$E$33),'2. GRI Pricing Inputs'!$D$32,IF(AND('3. GRI Pricing'!$F17>='2. GRI Pricing Inputs'!$F$33,'3. GRI Pricing'!$F17<='2. GRI Pricing Inputs'!$G$33),'2. GRI Pricing Inputs'!$F$32,IF(AND('3. GRI Pricing'!$F17>='2. GRI Pricing Inputs'!$H$33,'3. GRI Pricing'!$F17<='2. GRI Pricing Inputs'!$I$33),'2. GRI Pricing Inputs'!$H$32,IF(AND('3. GRI Pricing'!$F17>='2. GRI Pricing Inputs'!$J$33,'3. GRI Pricing'!$F17<='2. GRI Pricing Inputs'!$K$33),'2. GRI Pricing Inputs'!$J$32,IF(AND('3. GRI Pricing'!$F17>='2. GRI Pricing Inputs'!$L$33,'3. GRI Pricing'!$F17<='2. GRI Pricing Inputs'!$M$33),'2. GRI Pricing Inputs'!$L$32,IF(AND('3. GRI Pricing'!$F17>='2. GRI Pricing Inputs'!$N$33,'3. GRI Pricing'!$F17<='2. GRI Pricing Inputs'!$O$33),'2. GRI Pricing Inputs'!$N$32,IF(AND('3. GRI Pricing'!$F17>='2. GRI Pricing Inputs'!$P$33,'3. GRI Pricing'!$F17<='2. GRI Pricing Inputs'!$Q$33),'2. GRI Pricing Inputs'!$P$32,IF(AND('3. GRI Pricing'!$F17>='2. GRI Pricing Inputs'!$R$33,'3. GRI Pricing'!$F17<='2. GRI Pricing Inputs'!$S$33),'2. GRI Pricing Inputs'!$R$32,IF(AND('3. GRI Pricing'!$F17>='2. GRI Pricing Inputs'!$T$33,'3. GRI Pricing'!$F17<='2. GRI Pricing Inputs'!$U$33),'2. GRI Pricing Inputs'!$T$32,IF(AND('3. GRI Pricing'!$F17>='2. GRI Pricing Inputs'!$V$33,'3. GRI Pricing'!$F17<='2. GRI Pricing Inputs'!$W$33),'2. GRI Pricing Inputs'!$V$32,IF(AND('3. GRI Pricing'!$F17>='2. GRI Pricing Inputs'!$X$33,'3. GRI Pricing'!$F17<='2. GRI Pricing Inputs'!$Y$33),'2. GRI Pricing Inputs'!$X$32,IF(AND('3. GRI Pricing'!$F17>='2. GRI Pricing Inputs'!$Z$33,'3. GRI Pricing'!$F17<='2. GRI Pricing Inputs'!$AA$33),'2. GRI Pricing Inputs'!$Z$32,IF(AND('3. GRI Pricing'!$F17>='2. GRI Pricing Inputs'!$AB$33,'3. GRI Pricing'!$F17<='2. GRI Pricing Inputs'!$AC$33),'2. GRI Pricing Inputs'!$AB$32,IF(AND('3. GRI Pricing'!$F17>='2. GRI Pricing Inputs'!$AD$33,'3. GRI Pricing'!$F17<='2. GRI Pricing Inputs'!$AE$33),'2. GRI Pricing Inputs'!$AD$32,IF(AND('3. GRI Pricing'!$F17>='2. GRI Pricing Inputs'!$AF$33,'3. GRI Pricing'!$F17<='2. GRI Pricing Inputs'!$AG$33),'2. GRI Pricing Inputs'!$AF$32,IF(AND('3. GRI Pricing'!$F17>='2. GRI Pricing Inputs'!$AH$33,'3. GRI Pricing'!$F17<='2. GRI Pricing Inputs'!$AI$33),'2. GRI Pricing Inputs'!$AH$32,0)))))))))))))))) -> 1 | N17: {=IFERROR(INDEX('2. GRI Pricing Inputs'!$C$32:$AI$39,MATCH('3. GRI Pricing'!D17,'2. GRI Pricing Inputs'!$C$32:$C$39,0),(MATCH('3. GRI Pricing'!M17,'2. GRI Pricing Inputs'!$D$32:$AI$32,0)+1)),0)} -> 10 | O17: =IFERROR(INDEX('2. GRI Pricing Inputs'!$C$45:$AI$46,MATCH($O$16,'2. GRI Pricing Inputs'!$C$45:$C$46,0),MATCH(G17,'2. GRI Pricing Inputs'!$C$45:$AI$45,0)),0) -> 0 | P17: =IFERROR(INDEX('2. GRI Pricing Inputs'!$C$53:$AI$54,MATCH('3. GRI Pricing'!$P$16,'2. GRI Pricing Inputs'!$C$53:$C$54,0),MATCH('3. GRI Pricing'!H17,'2. GRI Pricing Inputs'!$C$53:$AI$53,0)),0) -> 25 | Q17: =IFERROR(INDEX('2. GRI Pricing Inputs'!$C$60:$AI$61,MATCH('3. GRI Pricing'!$Q$16,'2. GRI Pricing Inputs'!$C$60:$C$61,0),MATCH('1. Accomodation'!T21,'2. GRI Pricing Inputs'!$C$60:$AI$60,0)),0) -> 0 | R17: =IFERROR(INDEX('2. GRI Pricing Inputs'!$C$67:$AI$68,MATCH('3. GRI Pricing'!$R$16,'2. GRI Pricing Inputs'!$C$67:$C$68,0),MATCH('1. Accomodation'!U21,'2. GRI Pricing Inputs'!$C$67:$AI$67,0)),0) -> 0 | S17: =IF(D17=0,0,'2. GRI Pricing Inputs'!$AI$75) -> 70 | T17: =IFERROR(INDEX('2. GRI Pricing Inputs'!$C$82:$AI$83,MATCH('3. GRI Pricing'!$T$16,'2. GRI Pricing Inputs'!$C$82:$C$83,0),MATCH('1. Accomodation'!V21,'2. GRI Pricing Inputs'!$C$82:$AI$82,0)),0) -> 20 | U17: =IFERROR(INDEX('2. GRI Pricing Inputs'!$C$89:$AI$90,MATCH('3. GRI Pricing'!$U$16,'2. GRI Pricing Inputs'!$C$89:$C$90,0),MATCH('1. Accomodation'!W21,'2. GRI Pricing Inputs'!$C$89:$AI$89,0)),0) -> 0 | V17: =IFERROR(INDEX('2. GRI Pricing Inputs'!$C$97:$AI$98,MATCH('3. GRI Pricing'!$V$16,'2. GRI Pricing Inputs'!$C$97:$C$98,0),MATCH('1. Accomodation'!X21,'2. GRI Pricing Inputs'!$C$97:$AI$97,0)),0) -> 0 | W17: =IFERROR(INDEX('2. GRI Pricing Inputs'!$C$104:$AI$105,MATCH('3. GRI Pricing'!$W$16,'2. GRI Pricing Inputs'!$C$104:$C$105,0),MATCH('1. Accomodation'!Y21,'2. GRI Pricing Inputs'!$C$104:$AI$104,0)),0) -> 0 | X17: 0 | Y17: =K17+L17+N17+O17+P17+Q17+R17+S17+T17+U17+V17+W17+X17 -> 970 | AC17: =Y17*(1+'2. GRI Pricing Inputs'!$D$114)^(($AC$16-$AB$15)/365) -> 973.23653 | AD17: =AC17*(1+'2. GRI Pricing Inputs'!$D$114)^((AD$16-AC$16)/365) -> 976.37894 | AE17: =AD17*(1+'2. GRI Pricing Inputs'!$D$114)^((AE$16-AD$16)/365) -> 979.63675 | AF17: =AE17*(1+'2. GRI Pricing Inputs'!$D$114)^((AF$16-AE$16)/365) -> 982.90543 | AG17: =AF17*(1+'2. GRI Pricing Inputs'!$D$114)^((AG$16-AF$16)/365) -> 985.97311 | AH17: =AG17*(1+'2. GRI Pricing Inputs'!$D$114)^((AH$16-AG$16)/365) -> 989.26293 | AI17: =AH17*(1+'2. GRI Pricing Inputs'!$D$114)^((AI$16-AH$16)/365) -> 992.45709 | AJ17: =AI17*(1+'2. GRI Pricing Inputs'!$D$114)^((AJ$16-AI$16)/365) -> 995.76855 | AK17: =AJ17*(1+'2. GRI Pricing Inputs'!$D$114)^((AK$16-AJ$16)/365) -> 998.98371 | ... AO17: =AN17*(1+'2. GRI Pricing Inputs'!$D$114)^((AO$16-AN$16)/365) -> 1012.2748
C18: ='1. Accomodation'!N22 -> 102N | D18: ='1. Accomodation'!P22 -> 2 Bed | E18: ='1. Accomodation'!Q22 -> 2 | F18: ='1. Accomodation'!O22 -> 678 | G18: ='1. Accomodation'!R22 -> Ground | H18: ='1. Accomodation'!S22 -> Courtyard | K18: =IFERROR(INDEX('2. GRI Pricing Inputs'!$C$15:$AI$16,MATCH($K$16,'2. GRI Pricing Inputs'!$C$15:$C$16,0),MATCH(D18,'2. GRI Pricing Inputs'!$C$15:$AI$15,0)),0) -> 1110 | L18: =IFERROR(INDEX('2. GRI Pricing Inputs'!$C$22:$AI$23,MATCH($L$16,'2. GRI Pricing Inputs'!$C$22:$C$23,0),MATCH(E18,'2. GRI Pricing Inputs'!$C$22:$AI$22,0)),0) -> 0 | M18: =IF(AND('3. GRI Pricing'!$F18>='2. GRI Pricing Inputs'!$D$33,'3. GRI Pricing'!$F18<='2. GRI Pricing Inputs'!$E$33),'2. GRI Pricing Inputs'!$D$32,IF(AND('3. GRI Pricing'!$F18>='2. GRI Pricing Inputs'!$F$33,'3. GRI Pricing'!$F18<='2. GRI Pricing Inputs'!$G$33),'2. GRI Pricing Inputs'!$F$32,IF(AND('3. GRI Pricing'!$F18>='2. GRI Pricing Inputs'!$H$33,'3. GRI Pricing'!$F18<='2. GRI Pricing Inputs'!$I$33),'2. GRI Pricing Inputs'!$H$32,IF(AND('3. GRI Pricing'!$F18>='2. GRI Pricing Inputs'!$J$33,'3. GRI Pricing'!$F18<='2. GRI Pricing Inputs'!$K$33),'2. GRI Pricing Inputs'!$J$32,IF(AND('3. GRI Pricing'!$F18>='2. GRI Pricing Inputs'!$L$33,'3. GRI Pricing'!$F18<='2. GRI Pricing Inputs'!$M$33),'2. GRI Pricing Inputs'!$L$32,IF(AND('3. GRI Pricing'!$F18>='2. GRI Pricing Inputs'!$N$33,'3. GRI Pricing'!$F18<='2. GRI Pricing Inputs'!$O$33),'2. GRI Pricing Inputs'!$N$32,IF(AND('3. GRI Pricing'!$F18>='2. GRI Pricing Inputs'!$P$33,'3. GRI Pricing'!$F18<='2. GRI Pricing Inputs'!$Q$33),'2. GRI Pricing Inputs'!$P$32,IF(AND('3. GRI Pricing'!$F18>='2. GRI Pricing Inputs'!$R$33,'3. GRI Pricing'!$F18<='2. GRI Pricing Inputs'!$S$33),'2. GRI Pricing Inputs'!$R$32,IF(AND('3. GRI Pricing'!$F18>='2. GRI Pricing Inputs'!$T$33,'3. GRI Pricing'!$F18<='2. GRI Pricing Inputs'!$U$33),'2. GRI Pricing Inputs'!$T$32,IF(AND('3. GRI Pricing'!$F18>='2. GRI Pricing Inputs'!$V$33,'3. GRI Pricing'!$F18<='2. GRI Pricing Inputs'!$W$33),'2. GRI Pricing Inputs'!$V$32,IF(AND('3. GRI Pricing'!$F18>='2. GRI Pricing Inputs'!$X$33,'3. GRI Pricing'!$F18<='2. GRI Pricing Inputs'!$Y$33),'2. GRI Pricing Inputs'!$X$32,IF(AND('3. GRI Pricing'!$F18>='2. GRI Pricing Inputs'!$Z$33,'3. GRI Pricing'!$F18<='2. GRI Pricing Inputs'!$AA$33),'2. GRI Pricing Inputs'!$Z$32,IF(AND('3. GRI Pricing'!$F18>='2. GRI Pricing Inputs'!$AB$33,'3. GRI Pricing'!$F18<='2. GRI Pricing Inputs'!$AC$33),'2. GRI Pricing Inputs'!$AB$32,IF(AND('3. GRI Pricing'!$F18>='2. GRI Pricing Inputs'!$AD$33,'3. GRI Pricing'!$F18<='2. GRI Pricing Inputs'!$AE$33),'2. GRI Pricing Inputs'!$AD$32,IF(AND('3. GRI Pricing'!$F18>='2. GRI Pricing Inputs'!$AF$33,'3. GRI Pricing'!$F18<='2. GRI Pricing Inputs'!$AG$33),'2. GRI Pricing Inputs'!$AF$32,IF(AND('3. GRI Pricing'!$F18>='2. GRI Pricing Inputs'!$AH$33,'3. GRI Pricing'!$F18<='2. GRI Pricing Inputs'!$AI$33),'2. GRI Pricing Inputs'!$AH$32,0)))))))))))))))) -> 10 | N18: {=IFERROR(INDEX('2. GRI Pricing Inputs'!$C$32:$AI$39,MATCH('3. GRI Pricing'!D18,'2. GRI Pricing Inputs'!$C$32:$C$39,0),(MATCH('3. GRI Pricing'!M18,'2. GRI Pricing Inputs'!$D$32:$AI$32,0)+1)),0)} -> 40 | O18: =IFERROR(INDEX('2. GRI Pricing Inputs'!$C$45:$AI$46,MATCH($O$16,'2. GRI Pricing Inputs'!$C$45:$C$46,0),MATCH(G18,'2. GRI Pricing Inputs'!$C$45:$AI$45,0)),0) -> 0 | P18: =IFERROR(INDEX('2. GRI Pricing Inputs'!$C$53:$AI$54,MATCH('3. GRI Pricing'!$P$16,'2. GRI Pricing Inputs'!$C$53:$C$54,0),MATCH('3. GRI Pricing'!H18,'2. GRI Pricing Inputs'!$C$53:$AI$53,0)),0) -> 25 | Q18: =IFERROR(INDEX('2. GRI Pricing Inputs'!$C$60:$AI$61,MATCH('3. GRI Pricing'!$Q$16,'2. GRI Pricing Inputs'!$C$60:$C$61,0),MATCH('1. Accomodation'!T22,'2. GRI Pricing Inputs'!$C$60:$AI$60,0)),0) -> 0 | R18: =IFERROR(INDEX('2. GRI Pricing Inputs'!$C$67:$AI$68,MATCH('3. GRI Pricing'!$R$16,'2. GRI Pricing Inputs'!$C$67:$C$68,0),MATCH('1. Accomodation'!U22,'2. GRI Pricing Inputs'!$C$67:$AI$67,0)),0) -> 0 | S18: =IF(D18=0,0,'2. GRI Pricing Inputs'!$AI$75) -> 70 | T18: =IFERROR(INDEX('2. GRI Pricing Inputs'!$C$82:$AI$83,MATCH('3. GRI Pricing'!$T$16,'2. GRI Pricing Inputs'!$C$82:$C$83,0),MATCH('1. Accomodation'!V22,'2. GRI Pricing Inputs'!$C$82:$AI$82,0)),0) -> 20 | U18: =IFERROR(INDEX('2. GRI Pricing Inputs'!$C$89:$AI$90,MATCH('3. GRI Pricing'!$U$16,'2. GRI Pricing Inputs'!$C$89:$C$90,0),MATCH('1. Accomodation'!W22,'2. GRI Pricing Inputs'!$C$89:$AI$89,0)),0) -> 0 | V18: =IFERROR(INDEX('2. GRI Pricing Inputs'!$C$97:$AI$98,MATCH('3. GRI Pricing'!$V$16,'2. GRI Pricing Inputs'!$C$97:$C$98,0),MATCH('1. Accomodation'!X22,'2. GRI Pricing Inputs'!$C$97:$AI$97,0)),0) -> 0 | W18: =IFERROR(INDEX('2. GRI Pricing Inputs'!$C$104:$AI$105,MATCH('3. GRI Pricing'!$W$16,'2. GRI Pricing Inputs'!$C$104:$C$105,0),MATCH('1. Accomodation'!Y22,'2. GRI Pricing Inputs'!$C$104:$AI$104,0)),0) -> 0 | X18: 0 | Y18: =K18+L18+N18+O18+P18+Q18+R18+S18+T18+U18+V18+W18+X18 -> 1265 | AC18: =Y18*(1+'2. GRI Pricing Inputs'!$D$114)^(($AC$16-$AB$15)/365) -> 1269.2208 | AD18: =AC18*(1+'2. GRI Pricing Inputs'!$D$114)^((AD$16-AC$16)/365) -> 1273.3189 | AE18: =AD18*(1+'2. GRI Pricing Inputs'!$D$114)^((AE$16-AD$16)/365) -> 1277.5675 | AF18: =AE18*(1+'2. GRI Pricing Inputs'!$D$114)^((AF$16-AE$16)/365) -> 1281.8303 | AG18: =AF18*(1+'2. GRI Pricing Inputs'!$D$114)^((AG$16-AF$16)/365) -> 1285.8309 | AH18: =AG18*(1+'2. GRI Pricing Inputs'!$D$114)^((AH$16-AG$16)/365) -> 1290.1212 | AI18: =AH18*(1+'2. GRI Pricing Inputs'!$D$114)^((AI$16-AH$16)/365) -> 1294.2868 | AJ18: =AI18*(1+'2. GRI Pricing Inputs'!$D$114)^((AJ$16-AI$16)/365) -> 1298.6054 | AK18: =AJ18*(1+'2. GRI Pricing Inputs'!$D$114)^((AK$16-AJ$16)/365) -> 1302.7983 | ... AO18: =AN18*(1+'2. GRI Pricing Inputs'!$D$114)^((AO$16-AN$16)/365) -> 1320.1315
C19: ='1. Accomodation'!N23 -> 103N | D19: ='1. Accomodation'!P23 -> 2 Bed | E19: ='1. Accomodation'!Q23 -> 2 | F19: ='1. Accomodation'!O23 -> 657 | G19: ='1. Accomodation'!R23 -> Ground | H19: ='1. Accomodation'!S23 -> Courtyard | K19: =IFERROR(INDEX('2. GRI Pricing Inputs'!$C$15:$AI$16,MATCH($K$16,'2. GRI Pricing Inputs'!$C$15:$C$16,0),MATCH(D19,'2. GRI Pricing Inputs'!$C$15:$AI$15,0)),0) -> 1110 | L19: =IFERROR(INDEX('2. GRI Pricing Inputs'!$C$22:$AI$23,MATCH($L$16,'2. GRI Pricing Inputs'!$C$22:$C$23,0),MATCH(E19,'2. GRI Pricing Inputs'!$C$22:$AI$22,0)),0) -> 0 | M19: =IF(AND('3. GRI Pricing'!$F19>='2. GRI Pricing Inputs'!$D$33,'3. GRI Pricing'!$F19<='2. GRI Pricing Inputs'!$E$33),'2. GRI Pricing Inputs'!$D$32,IF(AND('3. GRI Pricing'!$F19>='2. GRI Pricing Inputs'!$F$33,'3. GRI Pricing'!$F19<='2. GRI Pricing Inputs'!$G$33),'2. GRI Pricing Inputs'!$F$32,IF(AND('3. GRI Pricing'!$F19>='2. GRI Pricing Inputs'!$H$33,'3. GRI Pricing'!$F19<='2. GRI Pricing Inputs'!$I$33),'2. GRI Pricing Inputs'!$H$32,IF(AND('3. GRI Pricing'!$F19>='2. GRI Pricing Inputs'!$J$33,'3. GRI Pricing'!$F19<='2. GRI Pricing Inputs'!$K$33),'2. GRI Pricing Inputs'!$J$32,IF(AND('3. GRI Pricing'!$F19>='2. GRI Pricing Inputs'!$L$33,'3. GRI Pricing'!$F19<='2. GRI Pricing Inputs'!$M$33),'2. GRI Pricing Inputs'!$L$32,IF(AND('3. GRI Pricing'!$F19>='2. GRI Pricing Inputs'!$N$33,'3. GRI Pricing'!$F19<='2. GRI Pricing Inputs'!$O$33),'2. GRI Pricing Inputs'!$N$32,IF(AND('3. GRI Pricing'!$F19>='2. GRI Pricing Inputs'!$P$33,'3. GRI Pricing'!$F19<='2. GRI Pricing Inputs'!$Q$33),'2. GRI Pricing Inputs'!$P$32,IF(AND('3. GRI Pricing'!$F19>='2. GRI Pricing Inputs'!$R$33,'3. GRI Pricing'!$F19<='2. GRI Pricing Inputs'!$S$33),'2. GRI Pricing Inputs'!$R$32,IF(AND('3. GRI Pricing'!$F19>='2. GRI Pricing Inputs'!$T$33,'3. GRI Pricing'!$F19<='2. GRI Pricing Inputs'!$U$33),'2. GRI Pricing Inputs'!$T$32,IF(AND('3. GRI Pricing'!$F19>='2. GRI Pricing Inputs'!$V$33,'3. GRI Pricing'!$F19<='2. GRI Pricing Inputs'!$W$33),'2. GRI Pricing Inputs'!$V$32,IF(AND('3. GRI Pricing'!$F19>='2. GRI Pricing Inputs'!$X$33,'3. GRI Pricing'!$F19<='2. GRI Pricing Inputs'!$Y$33),'2. GRI Pricing Inputs'!$X$32,IF(AND('3. GRI Pricing'!$F19>='2. GRI Pricing Inputs'!$Z$33,'3. GRI Pricing'!$F19<='2. GRI Pricing Inputs'!$AA$33),'2. GRI Pricing Inputs'!$Z$32,IF(AND('3. GRI Pricing'!$F19>='2. GRI Pricing Inputs'!$AB$33,'3. GRI Pricing'!$F19<='2. GRI Pricing Inputs'!$AC$33),'2. GRI Pricing Inputs'!$AB$32,IF(AND('3. GRI Pricing'!$F19>='2. GRI Pricing Inputs'!$AD$33,'3. GRI Pricing'!$F19<='2. GRI Pricing Inputs'!$AE$33),'2. GRI Pricing Inputs'!$AD$32,IF(AND('3. GRI Pricing'!$F19>='2. GRI Pricing Inputs'!$AF$33,'3. GRI Pricing'!$F19<='2. GRI Pricing Inputs'!$AG$33),'2. GRI Pricing Inputs'!$AF$32,IF(AND('3. GRI Pricing'!$F19>='2. GRI Pricing Inputs'!$AH$33,'3. GRI Pricing'!$F19<='2. GRI Pricing Inputs'!$AI$33),'2. GRI Pricing Inputs'!$AH$32,0)))))))))))))))) -> 8 | N19: {=IFERROR(INDEX('2. GRI Pricing Inputs'!$C$32:$AI$39,MATCH('3. GRI Pricing'!D19,'2. GRI Pricing Inputs'!$C$32:$C$39,0),(MATCH('3. GRI Pricing'!M19,'2. GRI Pricing Inputs'!$D$32:$AI$32,0)+1)),0)} -> 20 | O19: =IFERROR(INDEX('2. GRI Pricing Inputs'!$C$45:$AI$46,MATCH($O$16,'2. GRI Pricing Inputs'!$C$45:$C$46,0),MATCH(G19,'2. GRI Pricing Inputs'!$C$45:$AI$45,0)),0) -> 0 | P19: =IFERROR(INDEX('2. GRI Pricing Inputs'!$C$53:$AI$54,MATCH('3. GRI Pricing'!$P$16,'2. GRI Pricing Inputs'!$C$53:$C$54,0),MATCH('3. GRI Pricing'!H19,'2. GRI Pricing Inputs'!$C$53:$AI$53,0)),0) -> 25 | Q19: =IFERROR(INDEX('2. GRI Pricing Inputs'!$C$60:$AI$61,MATCH('3. GRI Pricing'!$Q$16,'2. GRI Pricing Inputs'!$C$60:$C$61,0),MATCH('1. Accomodation'!T23,'2. GRI Pricing Inputs'!$C$60:$AI$60,0)),0) -> 0 | R19: =IFERROR(INDEX('2. GRI Pricing Inputs'!$C$67:$AI$68,MATCH('3. GRI Pricing'!$R$16,'2. GRI Pricing Inputs'!$C$67:$C$68,0),MATCH('1. Accomodation'!U23,'2. GRI Pricing Inputs'!$C$67:$AI$67,0)),0) -> 0 | S19: =IF(D19=0,0,'2. GRI Pricing Inputs'!$AI$75) -> 70 | T19: =IFERROR(INDEX('2. GRI Pricing Inputs'!$C$82:$AI$83,MATCH('3. GRI Pricing'!$T$16,'2. GRI Pricing Inputs'!$C$82:$C$83,0),MATCH('1. Accomodation'!V23,'2. GRI Pricing Inputs'!$C$82:$AI$82,0)),0) -> 0 | U19: =IFERROR(INDEX('2. GRI Pricing Inputs'!$C$89:$AI$90,MATCH('3. GRI Pricing'!$U$16,'2. GRI Pricing Inputs'!$C$89:$C$90,0),MATCH('1. Accomodation'!W23,'2. GRI Pricing Inputs'!$C$89:$AI$89,0)),0) -> 0 | V19: =IFERROR(INDEX('2. GRI Pricing Inputs'!$C$97:$AI$98,MATCH('3. GRI Pricing'!$V$16,'2. GRI Pricing Inputs'!$C$97:$C$98,0),MATCH('1. Accomodation'!X23,'2. GRI Pricing Inputs'!$C$97:$AI$97,0)),0) -> 0 | W19: =IFERROR(INDEX('2. GRI Pricing Inputs'!$C$104:$AI$105,MATCH('3. GRI Pricing'!$W$16,'2. GRI Pricing Inputs'!$C$104:$C$105,0),MATCH('1. Accomodation'!Y23,'2. GRI Pricing Inputs'!$C$104:$AI$104,0)),0) -> 0 | X19: 0 | Y19: =K19+L19+N19+O19+P19+Q19+R19+S19+T19+U19+V19+W19+X19 -> 1225 | AC19: =Y19*(1+'2. GRI Pricing Inputs'!$D$114)^(($AC$16-$AB$15)/365) -> 1229.0874 | AD19: =AC19*(1+'2. GRI Pricing Inputs'!$D$114)^((AD$16-AC$16)/365) -> 1233.0559 | AE19: =AD19*(1+'2. GRI Pricing Inputs'!$D$114)^((AE$16-AD$16)/365) -> 1237.1701 | AF19: =AE19*(1+'2. GRI Pricing Inputs'!$D$114)^((AF$16-AE$16)/365) -> 1241.2981 | AG19: =AF19*(1+'2. GRI Pricing Inputs'!$D$114)^((AG$16-AF$16)/365) -> 1245.1722 | AH19: =AG19*(1+'2. GRI Pricing Inputs'!$D$114)^((AH$16-AG$16)/365) -> 1249.3269 | AI19: =AH19*(1+'2. GRI Pricing Inputs'!$D$114)^((AI$16-AH$16)/365) -> 1253.3608 | AJ19: =AI19*(1+'2. GRI Pricing Inputs'!$D$114)^((AJ$16-AI$16)/365) -> 1257.5428 | AK19: =AJ19*(1+'2. GRI Pricing Inputs'!$D$114)^((AK$16-AJ$16)/365) -> 1261.6031 | ... AO19: =AN19*(1+'2. GRI Pricing Inputs'!$D$114)^((AO$16-AN$16)/365) -> 1278.3882
C20: ='1. Accomodation'!N24 -> 104N | D20: ='1. Accomodation'!P24 -> 3 Bed | E20: ='1. Accomodation'!Q24 -> 2 | F20: ='1. Accomodation'!O24 -> 818 | G20: ='1. Accomodation'!R24 -> 1 | H20: ='1. Accomodation'!S24 -> Pottery Lane | K20: =IFERROR(INDEX('2. GRI Pricing Inputs'!$C$15:$AI$16,MATCH($K$16,'2. GRI Pricing Inputs'!$C$15:$C$16,0),MATCH(D20,'2. GRI Pricing Inputs'!$C$15:$AI$15,0)),0) -> 1485 | L20: =IFERROR(INDEX('2. GRI Pricing Inputs'!$C$22:$AI$23,MATCH($L$16,'2. GRI Pricing Inputs'!$C$22:$C$23,0),MATCH(E20,'2. GRI Pricing Inputs'!$C$22:$AI$22,0)),0) -> 0 | M20: =IF(AND('3. GRI Pricing'!$F20>='2. GRI Pricing Inputs'!$D$33,'3. GRI Pricing'!$F20<='2. GRI Pricing Inputs'!$E$33),'2. GRI Pricing Inputs'!$D$32,IF(AND('3. GRI Pricing'!$F20>='2. GRI Pricing Inputs'!$F$33,'3. GRI Pricing'!$F20<='2. GRI Pricing Inputs'!$G$33),'2. GRI Pricing Inputs'!$F$32,IF(AND('3. GRI Pricing'!$F20>='2. GRI Pricing Inputs'!$H$33,'3. GRI Pricing'!$F20<='2. GRI Pricing Inputs'!$I$33),'2. GRI Pricing Inputs'!$H$32,IF(AND('3. GRI Pricing'!$F20>='2. GRI Pricing Inputs'!$J$33,'3. GRI Pricing'!$F20<='2. GRI Pricing Inputs'!$K$33),'2. GRI Pricing Inputs'!$J$32,IF(AND('3. GRI Pricing'!$F20>='2. GRI Pricing Inputs'!$L$33,'3. GRI Pricing'!$F20<='2. GRI Pricing Inputs'!$M$33),'2. GRI Pricing Inputs'!$L$32,IF(AND('3. GRI Pricing'!$F20>='2. GRI Pricing Inputs'!$N$33,'3. GRI Pricing'!$F20<='2. GRI Pricing Inputs'!$O$33),'2. GRI Pricing Inputs'!$N$32,IF(AND('3. GRI Pricing'!$F20>='2. GRI Pricing Inputs'!$P$33,'3. GRI Pricing'!$F20<='2. GRI Pricing Inputs'!$Q$33),'2. GRI Pricing Inputs'!$P$32,IF(AND('3. GRI Pricing'!$F20>='2. GRI Pricing Inputs'!$R$33,'3. GRI Pricing'!$F20<='2. GRI Pricing Inputs'!$S$33),'2. GRI Pricing Inputs'!$R$32,IF(AND('3. GRI Pricing'!$F20>='2. GRI Pricing Inputs'!$T$33,'3. GRI Pricing'!$F20<='2. GRI Pricing Inputs'!$U$33),'2. GRI Pricing Inputs'!$T$32,IF(AND('3. GRI Pricing'!$F20>='2. GRI Pricing Inputs'!$V$33,'3. GRI Pricing'!$F20<='2. GRI Pricing Inputs'!$W$33),'2. GRI Pricing Inputs'!$V$32,IF(AND('3. GRI Pricing'!$F20>='2. GRI Pricing Inputs'!$X$33,'3. GRI Pricing'!$F20<='2. GRI Pricing Inputs'!$Y$33),'2. GRI Pricing Inputs'!$X$32,IF(AND('3. GRI Pricing'!$F20>='2. GRI Pricing Inputs'!$Z$33,'3. GRI Pricing'!$F20<='2. GRI Pricing Inputs'!$AA$33),'2. GRI Pricing Inputs'!$Z$32,IF(AND('3. GRI Pricing'!$F20>='2. GRI Pricing Inputs'!$AB$33,'3. GRI Pricing'!$F20<='2. GRI Pricing Inputs'!$AC$33),'2. GRI Pricing Inputs'!$AB$32,IF(AND('3. GRI Pricing'!$F20>='2. GRI Pricing Inputs'!$AD$33,'3. GRI Pricing'!$F20<='2. GRI Pricing Inputs'!$AE$33),'2. GRI Pricing Inputs'!$AD$32,IF(AND('3. GRI Pricing'!$F20>='2. GRI Pricing Inputs'!$AF$33,'3. GRI Pricing'!$F20<='2. GRI Pricing Inputs'!$AG$33),'2. GRI Pricing Inputs'!$AF$32,IF(AND('3. GRI Pricing'!$F20>='2. GRI Pricing Inputs'!$AH$33,'3. GRI Pricing'!$F20<='2. GRI Pricing Inputs'!$AI$33),'2. GRI Pricing Inputs'!$AH$32,0)))))))))))))))) -> 13 | N20: {=IFERROR(INDEX('2. GRI Pricing Inputs'!$C$32:$AI$39,MATCH('3. GRI Pricing'!D20,'2. GRI Pricing Inputs'!$C$32:$C$39,0),(MATCH('3. GRI Pricing'!M20,'2. GRI Pricing Inputs'!$D$32:$AI$32,0)+1)),0)} -> 50 | O20: =IFERROR(INDEX('2. GRI Pricing Inputs'!$C$45:$AI$46,MATCH($O$16,'2. GRI Pricing Inputs'!$C$45:$C$46,0),MATCH(G20,'2. GRI Pricing Inputs'!$C$45:$AI$45,0)),0) -> 30 | P20: =IFERROR(INDEX('2. GRI Pricing Inputs'!$C$53:$AI$54,MATCH('3. GRI Pricing'!$P$16,'2. GRI Pricing Inputs'!$C$53:$C$54,0),MATCH('3. GRI Pricing'!H20,'2. GRI Pricing Inputs'!$C$53:$AI$53,0)),0) -> 10 | Q20: =IFERROR(INDEX('2. GRI Pricing Inputs'!$C$60:$AI$61,MATCH('3. GRI Pricing'!$Q$16,'2. GRI Pricing Inputs'!$C$60:$C$61,0),MATCH('1. Accomodation'!T24,'2. GRI Pricing Inputs'!$C$60:$AI$60,0)),0) -> 0 | R20: =IFERROR(INDEX('2. GRI Pricing Inputs'!$C$67:$AI$68,MATCH('3. GRI Pricing'!$R$16,'2. GRI Pricing Inputs'!$C$67:$C$68,0),MATCH('1. Accomodation'!U24,'2. GRI Pricing Inputs'!$C$67:$AI$67,0)),0) -> 0 | S20: =IF(D20=0,0,'2. GRI Pricing Inputs'!$AI$75) -> 70 | T20: =IFERROR(INDEX('2. GRI Pricing Inputs'!$C$82:$AI$83,MATCH('3. GRI Pricing'!$T$16,'2. GRI Pricing Inputs'!$C$82:$C$83,0),MATCH('1. Accomodation'!V24,'2. GRI Pricing Inputs'!$C$82:$AI$82,0)),0) -> 0 | U20: =IFERROR(INDEX('2. GRI Pricing Inputs'!$C$89:$AI$90,MATCH('3. GRI Pricing'!$U$16,'2. GRI Pricing Inputs'!$C$89:$C$90,0),MATCH('1. Accomodation'!W24,'2. GRI Pricing Inputs'!$C$89:$AI$89,0)),0) -> 0 | V20: =IFERROR(INDEX('2. GRI Pricing Inputs'!$C$97:$AI$98,MATCH('3. GRI Pricing'!$V$16,'2. GRI Pricing Inputs'!$C$97:$C$98,0),MATCH('1. Accomodation'!X24,'2. GRI Pricing Inputs'!$C$97:$AI$97,0)),0) -> 0 | W20: =IFERROR(INDEX('2. GRI Pricing Inputs'!$C$104:$AI$105,MATCH('3. GRI Pricing'!$W$16,'2. GRI Pricing Inputs'!$C$104:$C$105,0),MATCH('1. Accomodation'!Y24,'2. GRI Pricing Inputs'!$C$104:$AI$104,0)),0) -> 0 | X20: 0 | Y20: =K20+L20+N20+O20+P20+Q20+R20+S20+T20+U20+V20+W20+X20 -> 1645 | AC20: =Y20*(1+'2. GRI Pricing Inputs'!$D$114)^(($AC$16-$AB$15)/365) -> 1650.4888 | AD20: =AC20*(1+'2. GRI Pricing Inputs'!$D$114)^((AD$16-AC$16)/365) -> 1655.8179 | AE20: =AD20*(1+'2. GRI Pricing Inputs'!$D$114)^((AE$16-AD$16)/365) -> 1661.3427 | AF20: =AE20*(1+'2. GRI Pricing Inputs'!$D$114)^((AF$16-AE$16)/365) -> 1666.886 | AG20: =AF20*(1+'2. GRI Pricing Inputs'!$D$114)^((AG$16-AF$16)/365) -> 1672.0884 | AH20: =AG20*(1+'2. GRI Pricing Inputs'!$D$114)^((AH$16-AG$16)/365) -> 1677.6676 | AI20: =AH20*(1+'2. GRI Pricing Inputs'!$D$114)^((AI$16-AH$16)/365) -> 1683.0844 | AJ20: =AI20*(1+'2. GRI Pricing Inputs'!$D$114)^((AJ$16-AI$16)/365) -> 1688.7003 | AK20: =AJ20*(1+'2. GRI Pricing Inputs'!$D$114)^((AK$16-AJ$16)/365) -> 1694.1528 | ... AO20: =AN20*(1+'2. GRI Pricing Inputs'!$D$114)^((AO$16-AN$16)/365) -> 1716.6928
C21: ='1. Accomodation'!N25 -> 105N | D21: ='1. Accomodation'!P25 -> 2 Bed | E21: ='1. Accomodation'!Q25 -> 2 | F21: ='1. Accomodation'!O25 -> 667 | G21: ='1. Accomodation'!R25 -> 1 | H21: ='1. Accomodation'!S25 -> Forth Banks/Pottery Lane | K21: =IFERROR(INDEX('2. GRI Pricing Inputs'!$C$15:$AI$16,MATCH($K$16,'2. GRI Pricing Inputs'!$C$15:$C$16,0),MATCH(D21,'2. GRI Pricing Inputs'!$C$15:$AI$15,0)),0) -> 1110 | L21: =IFERROR(INDEX('2. GRI Pricing Inputs'!$C$22:$AI$23,MATCH($L$16,'2. GRI Pricing Inputs'!$C$22:$C$23,0),MATCH(E21,'2. GRI Pricing Inputs'!$C$22:$AI$22,0)),0) -> 0 | M21: =IF(AND('3. GRI Pricing'!$F21>='2. GRI Pricing Inputs'!$D$33,'3. GRI Pricing'!$F21<='2. GRI Pricing Inputs'!$E$33),'2. GRI Pricing Inputs'!$D$32,IF(AND('3. GRI Pricing'!$F21>='2. GRI Pricing Inputs'!$F$33,'3. GRI Pricing'!$F21<='2. GRI Pricing Inputs'!$G$33),'2. GRI Pricing Inputs'!$F$32,IF(AND('3. GRI Pricing'!$F21>='2. GRI Pricing Inputs'!$H$33,'3. GRI Pricing'!$F21<='2. GRI Pricing Inputs'!$I$33),'2. GRI Pricing Inputs'!$H$32,IF(AND('3. GRI Pricing'!$F21>='2. GRI Pricing Inputs'!$J$33,'3. GRI Pricing'!$F21<='2. GRI Pricing Inputs'!$K$33),'2. GRI Pricing Inputs'!$J$32,IF(AND('3. GRI Pricing'!$F21>='2. GRI Pricing Inputs'!$L$33,'3. GRI Pricing'!$F21<='2. GRI Pricing Inputs'!$M$33),'2. GRI Pricing Inputs'!$L$32,IF(AND('3. GRI Pricing'!$F21>='2. GRI Pricing Inputs'!$N$33,'3. GRI Pricing'!$F21<='2. GRI Pricing Inputs'!$O$33),'2. GRI Pricing Inputs'!$N$32,IF(AND('3. GRI Pricing'!$F21>='2. GRI Pricing Inputs'!$P$33,'3. GRI Pricing'!$F21<='2. GRI Pricing Inputs'!$Q$33),'2. GRI Pricing Inputs'!$P$32,IF(AND('3. GRI Pricing'!$F21>='2. GRI Pricing Inputs'!$R$33,'3. GRI Pricing'!$F21<='2. GRI Pricing Inputs'!$S$33),'2. GRI Pricing Inputs'!$R$32,IF(AND('3. GRI Pricing'!$F21>='2. GRI Pricing Inputs'!$T$33,'3. GRI Pricing'!$F21<='2. GRI Pricing Inputs'!$U$33),'2. GRI Pricing Inputs'!$T$32,IF(AND('3. GRI Pricing'!$F21>='2. GRI Pricing Inputs'!$V$33,'3. GRI Pricing'!$F21<='2. GRI Pricing Inputs'!$W$33),'2. GRI Pricing Inputs'!$V$32,IF(AND('3. GRI Pricing'!$F21>='2. GRI Pricing Inputs'!$X$33,'3. GRI Pricing'!$F21<='2. GRI Pricing Inputs'!$Y$33),'2. GRI Pricing Inputs'!$X$32,IF(AND('3. GRI Pricing'!$F21>='2. GRI Pricing Inputs'!$Z$33,'3. GRI Pricing'!$F21<='2. GRI Pricing Inputs'!$AA$33),'2. GRI Pricing Inputs'!$Z$32,IF(AND('3. GRI Pricing'!$F21>='2. GRI Pricing Inputs'!$AB$33,'3. GRI Pricing'!$F21<='2. GRI Pricing Inputs'!$AC$33),'2. GRI Pricing Inputs'!$AB$32,IF(AND('3. GRI Pricing'!$F21>='2. GRI Pricing Inputs'!$AD$33,'3. GRI Pricing'!$F21<='2. GRI Pricing Inputs'!$AE$33),'2. GRI Pricing Inputs'!$AD$32,IF(AND('3. GRI Pricing'!$F21>='2. GRI Pricing Inputs'!$AF$33,'3. GRI Pricing'!$F21<='2. GRI Pricing Inputs'!$AG$33),'2. GRI Pricing Inputs'!$AF$32,IF(AND('3. GRI Pricing'!$F21>='2. GRI Pricing Inputs'!$AH$33,'3. GRI Pricing'!$F21<='2. GRI Pricing Inputs'!$AI$33),'2. GRI Pricing Inputs'!$AH$32,0)))))))))))))))) -> 9 | N21: {=IFERROR(INDEX('2. GRI Pricing Inputs'!$C$32:$AI$39,MATCH('3. GRI Pricing'!D21,'2. GRI Pricing Inputs'!$C$32:$C$39,0),(MATCH('3. GRI Pricing'!M21,'2. GRI Pricing Inputs'!$D$32:$AI$32,0)+1)),0)} -> 30 | O21: =IFERROR(INDEX('2. GRI Pricing Inputs'!$C$45:$AI$46,MATCH($O$16,'2. GRI Pricing Inputs'!$C$45:$C$46,0),MATCH(G21,'2. GRI Pricing Inputs'!$C$45:$AI$45,0)),0) -> 30 | P21: =IFERROR(INDEX('2. GRI Pricing Inputs'!$C$53:$AI$54,MATCH('3. GRI Pricing'!$P$16,'2. GRI Pricing Inputs'!$C$53:$C$54,0),MATCH('3. GRI Pricing'!H21,'2. GRI Pricing Inputs'!$C$53:$AI$53,0)),0) -> 10 | Q21: =IFERROR(INDEX('2. GRI Pricing Inputs'!$C$60:$AI$61,MATCH('3. GRI Pricing'!$Q$16,'2. GRI Pricing Inputs'!$C$60:$C$61,0),MATCH('1. Accomodation'!T25,'2. GRI Pricing Inputs'!$C$60:$AI$60,0)),0) -> 0 | R21: =IFERROR(INDEX('2. GRI Pricing Inputs'!$C$67:$AI$68,MATCH('3. GRI Pricing'!$R$16,'2. GRI Pricing Inputs'!$C$67:$C$68,0),MATCH('1. Accomodation'!U25,'2. GRI Pricing Inputs'!$C$67:$AI$67,0)),0) -> 0 | S21: =IF(D21=0,0,'2. GRI Pricing Inputs'!$AI$75) -> 70 | T21: =IFERROR(INDEX('2. GRI Pricing Inputs'!$C$82:$AI$83,MATCH('3. GRI Pricing'!$T$16,'2. GRI Pricing Inputs'!$C$82:$C$83,0),MATCH('1. Accomodation'!V25,'2. GRI Pricing Inputs'!$C$82:$AI$82,0)),0) -> 0 | U21: =IFERROR(INDEX('2. GRI Pricing Inputs'!$C$89:$AI$90,MATCH('3. GRI Pricing'!$U$16,'2. GRI Pricing Inputs'!$C$89:$C$90,0),MATCH('1. Accomodation'!W25,'2. GRI Pricing Inputs'!$C$89:$AI$89,0)),0) -> 0 | V21: =IFERROR(INDEX('2. GRI Pricing Inputs'!$C$97:$AI$98,MATCH('3. GRI Pricing'!$V$16,'2. GRI Pricing Inputs'!$C$97:$C$98,0),MATCH('1. Accomodation'!X25,'2. GRI Pricing Inputs'!$C$97:$AI$97,0)),0) -> 0 | W21: =IFERROR(INDEX('2. GRI Pricing Inputs'!$C$104:$AI$105,MATCH('3. GRI Pricing'!$W$16,'2. GRI Pricing Inputs'!$C$104:$C$105,0),MATCH('1. Accomodation'!Y25,'2. GRI Pricing Inputs'!$C$104:$AI$104,0)),0) -> 0 | X21: 0 | Y21: =K21+L21+N21+O21+P21+Q21+R21+S21+T21+U21+V21+W21+X21 -> 1250 | AC21: =Y21*(1+'2. GRI Pricing Inputs'!$D$114)^(($AC$16-$AB$15)/365) -> 1254.1708 | AD21: =AC21*(1+'2. GRI Pricing Inputs'!$D$114)^((AD$16-AC$16)/365) -> 1258.2203 | AE21: =AD21*(1+'2. GRI Pricing Inputs'!$D$114)^((AE$16-AD$16)/365) -> 1262.4185 | AF21: =AE21*(1+'2. GRI Pricing Inputs'!$D$114)^((AF$16-AE$16)/365) -> 1266.6307 | AG21: =AF21*(1+'2. GRI Pricing Inputs'!$D$114)^((AG$16-AF$16)/365) -> 1270.5839 | AH21: =AG21*(1+'2. GRI Pricing Inputs'!$D$114)^((AH$16-AG$16)/365) -> 1274.8234 | AI21: =AH21*(1+'2. GRI Pricing Inputs'!$D$114)^((AI$16-AH$16)/365) -> 1278.9395 | AJ21: =AI21*(1+'2. GRI Pricing Inputs'!$D$114)^((AJ$16-AI$16)/365) -> 1283.2069 | AK21: =AJ21*(1+'2. GRI Pricing Inputs'!$D$114)^((AK$16-AJ$16)/365) -> 1287.3501 | ... AO21: =AN21*(1+'2. GRI Pricing Inputs'!$D$114)^((AO$16-AN$16)/365) -> 1304.4778
C22: ='1. Accomodation'!N26 -> 106N | D22: ='1. Accomodation'!P26 -> 1 Bed | E22: ='1. Accomodation'!Q26 -> 1 | F22: ='1. Accomodation'!O26 -> 441 | G22: ='1. Accomodation'!R26 -> 1 | H22: ='1. Accomodation'!S26 -> Forth Banks | K22: =IFERROR(INDEX('2. GRI Pricing Inputs'!$C$15:$AI$16,MATCH($K$16,'2. GRI Pricing Inputs'!$C$15:$C$16,0),MATCH(D22,'2. GRI Pricing Inputs'!$C$15:$AI$15,0)),0) -> 845 | L22: =IFERROR(INDEX('2. GRI Pricing Inputs'!$C$22:$AI$23,MATCH($L$16,'2. GRI Pricing Inputs'!$C$22:$C$23,0),MATCH(E22,'2. GRI Pricing Inputs'!$C$22:$AI$22,0)),0) -> 0 | M22: =IF(AND('3. GRI Pricing'!$F22>='2. GRI Pricing Inputs'!$D$33,'3. GRI Pricing'!$F22<='2. GRI Pricing Inputs'!$E$33),'2. GRI Pricing Inputs'!$D$32,IF(AND('3. GRI Pricing'!$F22>='2. GRI Pricing Inputs'!$F$33,'3. GRI Pricing'!$F22<='2. GRI Pricing Inputs'!$G$33),'2. GRI Pricing Inputs'!$F$32,IF(AND('3. GRI Pricing'!$F22>='2. GRI Pricing Inputs'!$H$33,'3. GRI Pricing'!$F22<='2. GRI Pricing Inputs'!$I$33),'2. GRI Pricing Inputs'!$H$32,IF(AND('3. GRI Pricing'!$F22>='2. GRI Pricing Inputs'!$J$33,'3. GRI Pricing'!$F22<='2. GRI Pricing Inputs'!$K$33),'2. GRI Pricing Inputs'!$J$32,IF(AND('3. GRI Pricing'!$F22>='2. GRI Pricing Inputs'!$L$33,'3. GRI Pricing'!$F22<='2. GRI Pricing Inputs'!$M$33),'2. GRI Pricing Inputs'!$L$32,IF(AND('3. GRI Pricing'!$F22>='2. GRI Pricing Inputs'!$N$33,'3. GRI Pricing'!$F22<='2. GRI Pricing Inputs'!$O$33),'2. GRI Pricing Inputs'!$N$32,IF(AND('3. GRI Pricing'!$F22>='2. GRI Pricing Inputs'!$P$33,'3. GRI Pricing'!$F22<='2. GRI Pricing Inputs'!$Q$33),'2. GRI Pricing Inputs'!$P$32,IF(AND('3. GRI Pricing'!$F22>='2. GRI Pricing Inputs'!$R$33,'3. GRI Pricing'!$F22<='2. GRI Pricing Inputs'!$S$33),'2. GRI Pricing Inputs'!$R$32,IF(AND('3. GRI Pricing'!$F22>='2. GRI Pricing Inputs'!$T$33,'3. GRI Pricing'!$F22<='2. GRI Pricing Inputs'!$U$33),'2. GRI Pricing Inputs'!$T$32,IF(AND('3. GRI Pricing'!$F22>='2. GRI Pricing Inputs'!$V$33,'3. GRI Pricing'!$F22<='2. GRI Pricing Inputs'!$W$33),'2. GRI Pricing Inputs'!$V$32,IF(AND('3. GRI Pricing'!$F22>='2. GRI Pricing Inputs'!$X$33,'3. GRI Pricing'!$F22<='2. GRI Pricing Inputs'!$Y$33),'2. GRI Pricing Inputs'!$X$32,IF(AND('3. GRI Pricing'!$F22>='2. GRI Pricing Inputs'!$Z$33,'3. GRI Pricing'!$F22<='2. GRI Pricing Inputs'!$AA$33),'2. GRI Pricing Inputs'!$Z$32,IF(AND('3. GRI Pricing'!$F22>='2. GRI Pricing Inputs'!$AB$33,'3. GRI Pricing'!$F22<='2. GRI Pricing Inputs'!$AC$33),'2. GRI Pricing Inputs'!$AB$32,IF(AND('3. GRI Pricing'!$F22>='2. GRI Pricing Inputs'!$AD$33,'3. GRI Pricing'!$F22<='2. GRI Pricing Inputs'!$AE$33),'2. GRI Pricing Inputs'!$AD$32,IF(AND('3. GRI Pricing'!$F22>='2. GRI Pricing Inputs'!$AF$33,'3. GRI Pricing'!$F22<='2. GRI Pricing Inputs'!$AG$33),'2. GRI Pricing Inputs'!$AF$32,IF(AND('3. GRI Pricing'!$F22>='2. GRI Pricing Inputs'!$AH$33,'3. GRI Pricing'!$F22<='2. GRI Pricing Inputs'!$AI$33),'2. GRI Pricing Inputs'!$AH$32,0)))))))))))))))) -> 0 | N22: {=IFERROR(INDEX('2. GRI Pricing Inputs'!$C$32:$AI$39,MATCH('3. GRI Pricing'!D22,'2. GRI Pricing Inputs'!$C$32:$C$39,0),(MATCH('3. GRI Pricing'!M22,'2. GRI Pricing Inputs'!$D$32:$AI$32,0)+1)),0)} -> 0 | O22: =IFERROR(INDEX('2. GRI Pricing Inputs'!$C$45:$AI$46,MATCH($O$16,'2. GRI Pricing Inputs'!$C$45:$C$46,0),MATCH(G22,'2. GRI Pricing Inputs'!$C$45:$AI$45,0)),0) -> 30 | P22: =IFERROR(INDEX('2. GRI Pricing Inputs'!$C$53:$AI$54,MATCH('3. GRI Pricing'!$P$16,'2. GRI Pricing Inputs'!$C$53:$C$54,0),MATCH('3. GRI Pricing'!H22,'2. GRI Pricing Inputs'!$C$53:$AI$53,0)),0) -> 5 | Q22: =IFERROR(INDEX('2. GRI Pricing Inputs'!$C$60:$AI$61,MATCH('3. GRI Pricing'!$Q$16,'2. GRI Pricing Inputs'!$C$60:$C$61,0),MATCH('1. Accomodation'!T26,'2. GRI Pricing Inputs'!$C$60:$AI$60,0)),0) -> 0 | R22: =IFERROR(INDEX('2. GRI Pricing Inputs'!$C$67:$AI$68,MATCH('3. GRI Pricing'!$R$16,'2. GRI Pricing Inputs'!$C$67:$C$68,0),MATCH('1. Accomodation'!U26,'2. GRI Pricing Inputs'!$C$67:$AI$67,0)),0) -> 0 | S22: =IF(D22=0,0,'2. GRI Pricing Inputs'!$AI$75) -> 70 | T22: =IFERROR(INDEX('2. GRI Pricing Inputs'!$C$82:$AI$83,MATCH('3. GRI Pricing'!$T$16,'2. GRI Pricing Inputs'!$C$82:$C$83,0),MATCH('1. Accomodation'!V26,'2. GRI Pricing Inputs'!$C$82:$AI$82,0)),0) -> 0 | U22: =IFERROR(INDEX('2. GRI Pricing Inputs'!$C$89:$AI$90,MATCH('3. GRI Pricing'!$U$16,'2. GRI Pricing Inputs'!$C$89:$C$90,0),MATCH('1. Accomodation'!W26,'2. GRI Pricing Inputs'!$C$89:$AI$89,0)),0) -> 0 | V22: =IFERROR(INDEX('2. GRI Pricing Inputs'!$C$97:$AI$98,MATCH('3. GRI Pricing'!$V$16,'2. GRI Pricing Inputs'!$C$97:$C$98,0),MATCH('1. Accomodation'!X26,'2. GRI Pricing Inputs'!$C$97:$AI$97,0)),0) -> 0 | W22: =IFERROR(INDEX('2. GRI Pricing Inputs'!$C$104:$AI$105,MATCH('3. GRI Pricing'!$W$16,'2. GRI Pricing Inputs'!$C$104:$C$105,0),MATCH('1. Accomodation'!Y26,'2. GRI Pricing Inputs'!$C$104:$AI$104,0)),0) -> 0 | X22: 0 | Y22: =K22+L22+N22+O22+P22+Q22+R22+S22+T22+U22+V22+W22+X22 -> 950 | AC22: =Y22*(1+'2. GRI Pricing Inputs'!$D$114)^(($AC$16-$AB$15)/365) -> 953.1698 | AD22: =AC22*(1+'2. GRI Pricing Inputs'!$D$114)^((AD$16-AC$16)/365) -> 956.24741 | AE22: =AD22*(1+'2. GRI Pricing Inputs'!$D$114)^((AE$16-AD$16)/365) -> 959.43805 | AF22: =AE22*(1+'2. GRI Pricing Inputs'!$D$114)^((AF$16-AE$16)/365) -> 962.63934 | AG22: =AF22*(1+'2. GRI Pricing Inputs'!$D$114)^((AG$16-AF$16)/365) -> 965.64377 | AH22: =AG22*(1+'2. GRI Pricing Inputs'!$D$114)^((AH$16-AG$16)/365) -> 968.86576 | AI22: =AH22*(1+'2. GRI Pricing Inputs'!$D$114)^((AI$16-AH$16)/365) -> 971.99406 | AJ22: =AI22*(1+'2. GRI Pricing Inputs'!$D$114)^((AJ$16-AI$16)/365) -> 975.23724 | AK22: =AJ22*(1+'2. GRI Pricing Inputs'!$D$114)^((AK$16-AJ$16)/365) -> 978.38611 | ... AO22: =AN22*(1+'2. GRI Pricing Inputs'!$D$114)^((AO$16-AN$16)/365) -> 991.40311
