Workbook

Sheet Original
A1: Grainger plc
A2: Unit tenure Type to be held on SF unit and interfaced from Qube to SF
A4: Grainger Tenure Type | B4: Description | C4: Rent Review
A5: Aff Rent | B5: Affordable Rent | C5: Annual
A6: AHA (Agr) | B6: Agricultural (Housing Act 1988) | C6: One tenancy has annual rent review. Other 2 have no rent review
A7: Assd PHA | B7: Assured Paignton Housing Association | C7: Annual
A8: Assd.Per | B8: Assured Periodic | C8: Annual
A9: Assured | B9: Assured | C9: Annual
A10: AST | B10: Assured Short Term | C10: Annual
A11: AST Chc | B11: Assured Short Term -Church Workers | C11: Annual
A12: AST KW | B12: Assured Short Term -Key Worker | C12: Annual
A13: AST Per | B13: Assured Short Term - Periodic | C13: Varies
A14: AST-REF | B14: Assured Short Term - Refer to Manager | C14: Every 2 Years
A15: ChiefRent | B15: Chief Rent | C15: N/A
... A39: Vac-C | B39: Vacant-Commercial | C39: N/A

Sheet updated 22.4
A1: Grainger plc
A2: Unit tenure Type to be held on SF unit and interfaced from Qube to SF
A4: Grainger Tenure Type | B4: Description | C4: Rent Review
A5: Aff Rent | B5: Affordable Rent | C5: Annual
A6: AHA (Agr) | B6: Agricultural (Housing Act 1988) | C6: One tenancy has annual rent review. Other 2 have no rent review
A7: Assd PHA | B7: Assured Paignton Housing Association | C7: Annual
A8: Assd.Per | B8: Assured Periodic | C8: Annual
A9: Assured | B9: Assured | C9: Annual
A10: AST | B10: Assured Short Term | C10: Annual
A11: AST Chc | B11: Assured Short Term -Church Workers | C11: Annual
A12: AST KW | B12: Assured Short Term -Key Worker | C12: Annual
A13: AST Per | B13: Assured Short Term - Periodic | C13: Varies
A14: AST-REF | B14: Assured Short Term - Refer to Manager | C14: Every 2 Years
A15: ChiefRent | B15: Chief Rent | C15: N/A
... A39: Vac-C | B39: Vacant-Commercial | C39: N/A

Sheet updated 22.4 with end date
A1: Event | B1: Action Date | C1: Event Date | D1: Status | E1: Attention Of | F1: Unit Reference | G1: Tenure | H1: Status | I1: Type | J1: Lease end date
A2: Rent Review | B2: 46011 | C2: 46101 | D2: Pending | E2: SR1 | F2: 103057001 | G2: Assd.Per | H2: Tenanted | I2: Mid Terrace | J2: n/a
A3: Rent Review | B3: 45907 | C3: 46029 | D3: Pending | E3: SR1 | F3: 103065001 | G3: Regulated | H3: Tenanted | I3: Mid Terrace | J3: n/a
A4: Rent Review | B4: 46096 | C4: 46218 | D4: Pending | E4: SR1 | F4: 103066001 | G4: Regulated | H4: Tenanted | I4: Mid Terrace | J4: n/a
A5: Rent Review | B5: 45712 | C5: 45862 | D5: Active | E5: SR1 | F5: 103070001 | G5: Regulated | H5: Tenanted | I5: Mid Terrace | J5: n/a
A6: Rent Review | B6: 46163 | C6: 46286 | D6: Pending | E6: SR1 | F6: 103071001 | G6: Regulated | H6: Tenanted | I6: Mid Terrace | J6: n/a
A7: Rent Review | B7: 46185 | C7: 46307 | D7: Pending | E7: SR1 | F7: 103075001 | G7: Regulated | H7: Tenanted | I7: Mid Terrace | J7: n/a
A8: Rent Review | B8: 45880 | C8: 46002 | D8: Pending | E8: SR1 | F8: 103078001 | G8: Regulated | H8: Tenanted | I8: Mid Terrace | J8: n/a
A9: Rent Review | B9: 46181 | C9: 46303 | D9: Pending | E9: SR1 | F9: 103082002 | G9: Regulated | H9: Tenanted | I9: Flat PB | J9: n/a
A10: Rent Review | B10: 46082 | C10: 46174 | D10: Pending | E10: SW4 | F10: 103086001 | G10: Regulated | H10: Tenanted | I10: Flat PB | J10: n/a
A11: Rent Review | B11: 77433 | C11: 77433 | D11: Pending | E11: JB0 | F11: 103086002 | G11: Grnd Rent | H11: Tenanted | I11: Flat PB | J11: 84737
A12: Rent Review | B12: 70129 | C12: 70129 | D12: Pending | E12: JB0 | F12: 103086002 | G12: Grnd Rent | H12: Tenanted | I12: Flat PB | J12: 84737
A13: Rent Review | B13: 62824 | C13: 62824 | D13: Pending | E13: JB0 | F13: 103086002 | G13: Grnd Rent | H13: Tenanted | I13: Flat PB | J13: 84737
A14: Rent Review | B14: 55519 | C14: 55519 | D14: Pending | E14: JB0 | F14: 103086002 | G14: Grnd Rent | H14: Tenanted | I14: Flat PB | J14: 84737
A15: Rent Review | B15: 48214 | C15: 48214 | D15: Active | E15: JB0 | F15: 103086002 | G15: Grnd Rent | H15: Tenanted | I15: Flat PB | J15: 84737
A16: Rent Review | B16: 77433 | C16: 77433 | D16: Pending | E16: JB0 | F16: 103086003 | G16: Grnd Rent | H16: Tenanted | I16: Flat PB | J16: 84737
A17: Rent Review | B17: 70129 | C17: 70129 | D17: Pending | E17: JB0 | F17: 103086003 | G17: Grnd Rent | H17: Tenanted | I17: Flat PB | J17: 84737
A18: Rent Review | B18: 62824 | C18: 62824 | D18: Pending | E18: JB0 | F18: 103086003 | G18: Grnd Rent | H18: Tenanted | I18: Flat PB | J18: 84737
A19: Rent Review | B19: 55519 | C19: 55519 | D19: Pending | E19: JB0 | F19: 103086003 | G19: Grnd Rent | H19: Tenanted | I19: Flat PB | J19: 84737
A20: Rent Review | B20: 48214 | C20: 48214 | D20: Active | E20: JB0 | F20: 103086003 | G20: Grnd Rent | H20: Tenanted | I20: Flat PB | J20: 84737
A21: Rent Review | B21: 77432 | C21: 77432 | D21: Pending | E21: JB0 | F21: 103086004 | G21: Grnd Rent | H21: Tenanted | I21: Flat PB | J21: 84737
A22: Rent Review | B22: 70128 | C22: 70128 | D22: Pending | E22: JB0 | F22: 103086004 | G22: Grnd Rent | H22: Tenanted | I22: Flat PB | J22: 84737
... A60: Rent Review | B60: 48214 | C60: 48214 | D60: Active | E60: JB0 | F60: 103086013 | G60: Grnd Rent | H60: Tenanted | I60: Flat PB | J60: 84737
A61: Rent Review | B61: 46082 | C61: 46174 | D61: Pending | E61: SW4 | F61: 103086014 | G61: Regulated | H61: Tenanted | I61: Flat PB | J61: n/a
A62: Rent Review | B62: 80721 | C62: 80721 | D62: Active | E62: NR1 | F62: 103086016 | G62: Grnd Rent | H62: Tenanted | I62: ParkingSpac | J62: 88025
A63: Rent Review | B63: 73416 | C63: 73416 | D63: Active | E63: NR1 | F63: 103086016 | G63: Grnd Rent | H63: Tenanted | I63: ParkingSpac | J63: 88025
A64: Rent Review | B64: 66112 | C64: 66112 | D64: Active | E64: NR1 | F64: 103086016 | G64: Grnd Rent | H64: Tenanted | I64: ParkingSpac | J64: 88025
A65: Rent Review | B65: 58807 | C65: 58807 | D65: Active | E65: NR1 | F65: 103086016 | G65: Grnd Rent | H65: Tenanted | I65: ParkingSpac | J65: 88025
A66: Rent Review | B66: 51502 | C66: 51502 | D66: Active | E66: NR1 | F66: 103086016 | G66: Grnd Rent | H66: Tenanted | I66: ParkingSpac | J66: 88025
A67: Rent Review | B67: 77433 | C67: 77433 | D67: Pending | E67: JB0 | F67: 103086019 | G67: Grnd Rent | H67: Tenanted | I67: ParkingSpac | J67: 84737
A68: Rent Review | B68: 70129 | C68: 70129 | D68: Pending | E68: JB0 | F68: 103086019 | G68: Grnd Rent | H68: Tenanted | I68: ParkingSpac | J68: 84737
A69: Rent Review | B69: 62824 | C69: 62824 | D69: Pending | E69: JB0 | F69: 103086019 | G69: Grnd Rent | H69: Tenanted | I69: ParkingSpac | J69: 84737
A70: Rent Review | B70: 55519 | C70: 55519 | D70: Pending | E70: JB0 | F70: 103086019 | G70: Grnd Rent | H70: Tenanted | I70: ParkingSpac | J70: 84737
A71: Rent Review | B71: 48214 | C71: 48214 | D71: Active | E71: JB0 | F71: 103086019 | G71: Grnd Rent | H71: Tenanted | I71: ParkingSpac | J71: 84737
A72: Rent Review | B72: 77433 | C72: 77433 | D72: Pending | E72: JB0 | F72: 103086020 | G72: Grnd Rent | H72: Tenanted | I72: ParkingSpac | J72: 84737
A73: Rent Review | B73: 70129 | C73: 70129 | D73: Pending | E73: JB0 | F73: 103086020 | G73: Grnd Rent | H73: Tenanted | I73: ParkingSpac | J73: 84737
... A101: Rent Review | B101: 49392 | C101: 49484 | D101: InProgress | E101: JB0 | F101: 103087001 | G101: Grnd Rent | H101: Tenanted | I101: Flat Conv. | J101: 86564
A102: Rent Review | B102: 46212 | C102: 46335 | D102: Pending | E102: HP3 | F102: 103087002 | G102: Regulated | H102: Tenanted | I102: Flat Conv. | J102: n/a
A103: Rent Review | B103: 53321 | C103: 53321 | D103: Active | E103: JB0 | F103: 103088001 | G103: Grnd Rent | H103: Tenanted | I103: Flat Conv. | J103: 65373
A104: Rent Review | B104: 41268 | C104: 41268 | D104: Active | E104: JB0 | F104: 103088001 | G104: Grnd Rent | H104: Tenanted | I104: Flat Conv. | J104: 65373
...

Sheet end date after review date
A1: Event | B1: Action Date | C1: Event Date | D1: Status | E1: Attention Of | F1: Unit Reference | G1: Tenure | H1: Status | I1: Type | J1: Lease end date | K1: Notes
A2: Rent Review | B2: 46738 | C2: 46829 | D2: Active | E2: MM2 | F2: 110038001 | G2: Gr Lets | H2: Tenanted | I2: Flat PB | J2: 47193 | K2: 6 year tenancy with Rent Reviews yearly during the 6 year term
A3: Rent Review | B3: 46017 | C3: 46107 | D3: Active | E3: MM2 | F3: 110038004 | G3: Gr Lets | H3: Tenanted | I3: Flat PB | J3: 47932 | K3: 6 year tenancy with Rent Reviews yearly during the 6 year term
A4: Rent Review | B4: 47002 | C4: 47093 | D4: Active | E4: MM2 | F4: 122168003 | G4: Gr Lets | H4: Tenanted | I4: Flat PB | J4: 47457 | K4: 6 year tenancy with Rent Reviews yearly during the 6 year term
A5: Rent Review | B5: 45755 | C5: 45846 | D5: Active | E5: SO3 | F5: 127060001 | G5: Aff Rent | H5: Tenanted | I5: Det House | J5: 47671 | K5: 6 year tenancy with Rent Reviews yearly during the 6 year term
A6: Rent Review | B6: 45766 | C6: 45857 | D6: Active | E6: MM2 | F6: 127066007 | G6: Aff Rent | H6: Tenanted | I6: Flat PB | J6: 47682 | K6: 6 year tenancy with Rent Reviews yearly during the 6 year term
A7: Rent Review | B7: 46298 | C7: 46025 | D7: InProgress | E7: SO3 | F7: 127483063 | G7: DMR-AST | H7: Tenanted | I7: Flat PB | J7: 47485 | K7: 3 year tenancy with Rent Reviews yearly during the 3 year term
A10: Rent Review | B10: 45682 | C10: 45802 | D10: Active | E10: SR1 | F10: 114035002 | G10: FixedRent | H10: Tenanted | I10: Studio | J10: 55896 | K10: We do not intend to create a Regulated Tenancy and the Tenancy will remain a 60 fixed term tenancy as shown attached. But we need the rent assessed by the Rent Officer. One the new rent has been assessed a new diary will be added for 2 years after the increase.

Sheet Reviewed
A1: Grainger plc
A2: Unit tenure Type to be held on SF unit and interfaced from Qube to SF
A4: Grainger Tenure Type | B4: Current Tenure | C4: Description | D4: Rent Review | E4: Payment Periodicity | F4: Responsible for Rent Review | G4: Notes | H4: Action
A5: Aff Rent | C5: Affordable Rent | D5: Annual | F5: Deborah Caslaw/ GT Team | G5: PBI report generated from qube Rent Review Diaries to prompt review | H5: =VLOOKUP($A5,'update 25.4'!$A:RH,7,FALSE) -> 0 | I5: May require annual reviews during lease term
A6: AHA (Agr) | C6: Agricultural (Housing Act 1988) | D6: One tenancy has annual rent review. Other 2 have no rent review | F6: Deborah Caslaw/Local agent performs rent reviews | G6: PBI report generated from qube Rent Review Diaries to prompt review | H6: =VLOOKUP($A6,'update 25.4'!$A:RH,7,FALSE) -> 0
A7: Assd PHA | C7: Assured Paignton Housing Association | D7: Annual | F7: Deborah Caslaw/Property managers | G7: PBI report generated from qube Rent Review Diaries to prompt review | H7: =VLOOKUP($A7,'update 25.4'!$A:RH,7,FALSE) -> 0
A8: Assd.Per | C8: Assured Periodic | D8: Annual | F8: Deborah Caslaw/Property managers | G8: PBI report generated from qube Rent Review Diaries to prompt review | H8: =VLOOKUP($A8,'update 25.4'!$A:RH,7,FALSE) -> 0
A9: Assured | C9: Assured | D9: Annual | F9: Deborah Caslaw | H9: =VLOOKUP($A9,'update 25.4'!$A:RH,7,FALSE) -> 0
A10: AST | C10: Assured Short Term | D10: Annual | F10: Asset Manager/Renewals team | H10: =VLOOKUP($A10,'update 25.4'!$A:RH,7,FALSE) -> 0
A11: AST Chc | C11: Assured Short Term -Church Workers | D11: Annual | F11: Deborah Caslaw/Property managers | G11: PBI report generated from qube Rent Review Diaries to prompt review | H11: =VLOOKUP($A11,'update 25.4'!$A:RH,7,FALSE) -> 0
A12: AST KW | C12: Assured Short Term -Key Worker | D12: Annual | F12: Deborah Caslaw/Property managers | G12: PBI report generated from qube Rent Review Diaries to prompt review | H12: =VLOOKUP($A12,'update 25.4'!$A:RH,7,FALSE) -> 0
A13: AST Per | C13: Assured Short Term - Periodic | D13: Varies | F13: Deborah Caslaw/Property managers | G13: PBI report generated from qube Rent Review Diaries to prompt review | H13: =VLOOKUP($A13,'update 25.4'!$A:RH,7,FALSE) -> 0
A14: AST-REF | C14: Assured Short Term - Refer to Manager | D14: Every 2 Years | F14: Deborah Caslaw/Property managers | G14: PBI report generated from qube Rent Review Diaries to prompt review | H14: =VLOOKUP($A14,'update 25.4'!$A:RH,7,FALSE) -> 0
A15: ChiefRent | C15: Chief Rent | D15: N/A | F15: N/A | H15: =VLOOKUP($A15,'update 25.4'!$A:RH,7,FALSE) -> 0
A16: CommLease | C16: Commercial Lease | D16: According to Lease | F16: Commercial team | H16: =VLOOKUP($A16,'update 25.4'!$A:RH,7,FALSE) -> 0
A17: Comm-Let | C17: Commercial Let | D17: According to Lease | F17: Commercial team | H17: =VLOOKUP($A17,'update 25.4'!$A:RH,7,FALSE) -> 0
A18: CommLic | C18: Commercial License | D18: According to Lease | F18: Commercial team | H18: =VLOOKUP($A18,'update 25.4'!$A:RH,7,FALSE) -> 0
A19: Comp-Let | C19: Company Let | D19: Annual | F19: Asset Manager/Renewals team | H19: =VLOOKUP($A19,'update 25.4'!$A:RH,7,FALSE) -> 0
A20: CT SerLic | C20: Caretaker Service License | D20: No tenancies exist on this tenure type | F20: Deborah Caslaw/Property managers | G20: PBI report generated from qube Rent Review Diaries to prompt review | H20: =VLOOKUP($A20,'update 25.4'!$A:RH,7,FALSE) -> 0
A21: CT SerTen | C21: Caretaker Service Tenancy | D21: One tenancy has annual rent review. Other 2 have no rent review. Only 3 units occupied by Grainger staff or caretakers-rent review by exception? | F21: N/A | H21: =VLOOKUP($A21,'update 25.4'!$A:RH,7,FALSE) -> 0
A22: DMR | B22: DMR-AST | C22: Discounted Market Rent- Non Social Housing | D22: Annual | F22: Deborah Caslaw/ GT Team/Local Authority | G22: PBI report generated from qube Rent Review Diaries to prompt review | H22: =VLOOKUP($A22,'update 25.4'!$A:RH,7,FALSE) -> 0 | I22: May require annual reviews during lease term
A23: DMR-SOC | B23: Gr Lets | C23: Discounted Market Rent-Social Housing | D23: Annual | F23: GT Team/Local Authority | G23: PBI report generated from qube Rent Review Diaries to prompt review | H23: =VLOOKUP($A23,'update 25.4'!$A:RH,7,FALSE) -> 0 | I23: May require annual reviews during lease term
A24: EstateChg | C24: Esatte Charge | D24: N/A | F24: N/A | H24: =VLOOKUP($A24,'update 25.4'!$A:RH,7,FALSE) -> 0
A25: FixedRent | C25: Fixed Rent | D25: 4 tenancies. 3 have rent reviews every 2 to 4 years. 1 hasno rent review | F25: Deborah Caslaw/Rent Review Diary created in Qube when lease is first set up | G25: PBI report generated from qube Rent Review Diaries to prompt review | H25: =VLOOKUP($A25,'update 25.4'!$A:RH,7,FALSE) -> 0 | I25: May require annual reviews during lease term
A26: Grnd Rent | C26: Ground rent | D26: Based on lease term | F26: Rent Review Diary created in Qube when lease is first set up | G26: PBI report generated from qube Rent Review Diaries to prompt review | H26: =VLOOKUP($A26,'update 25.4'!$A:RH,7,FALSE) -> 0
A27: Licence | C27: Licence | D27: Varies -see below | F27: Asset Manager/Renewals team | H27: =VLOOKUP($A27,'update 25.4'!$A:RH,7,FALSE) -> 0
A28: Live Work | C28: Live Work | D28: Annual | F28: Asset Manager/Renewals team | H28: =VLOOKUP($A28,'update 25.4'!$A:RH,7,FALSE) -> 0
A29: MOD | C29: Ministry of Defence | D29: No rent reviews performed | F29: N/A | H29: =VLOOKUP($A29,'update 25.4'!$A:RH,7,FALSE) -> 0
A30: Nil GR | C30: Nil Ground Rent | D30: Based on lease term | F30: Rent Review Diary created in Qube when lease is first set up | G30: PBI report generated from qube Rent Review Diaries to prompt review | H30: =VLOOKUP($A30,'update 25.4'!$A:RH,7,FALSE) -> 0
A31: No Tenure | C31: No tenure | D31: All non lettable units-no rent reviews | F31: N/A | H31: =VLOOKUP($A31,'update 25.4'!$A:RH,7,FALSE) -> 0
A32: Occ Con | C32: Occupational Contract | D32: Annual | F32: Asset Manager/Renewals team | H32: =VLOOKUP($A32,'update 25.4'!$A:RH,7,FALSE) -> 0
A33: Regulated | C33: Regulated | D33: Every 2 Years | F33: Deborah Caslaw | H33: =VLOOKUP($A33,'update 25.4'!$A:RH,7,FALSE) -> 0
A34: Reversion | C34: Reversionary | D34: N/A | E34: Weekly, Monthly, Quarterly, Annual | F34: N/A | H34: =VLOOKUP($A34,'update 25.4'!$A:RH,7,FALSE) -> 0
A35: Services | C35: Services | D35: N/A | F35: N/A | H35: =VLOOKUP($A35,'update 25.4'!$A:RH,7,FALSE) -> 0
A36: Sh Owner | C36: Shared Ownership | D36: Annual | F36: Deborah Caslaw/ GT Team | G36: PBI report generated from qube Rent Review Diaries to prompt review | H36: =VLOOKUP($A36,'update 25.4'!$A:RH,7,FALSE) -> 0
A37: Sold | C37: Sold | D37: N/A | F37: N/A | H37: =VLOOKUP($A37,'update 25.4'!$A:RH,7,FALSE) -> 0
A38: Vacant | C38: Vacant | D38: N/A | F38: N/A | H38: =VLOOKUP($A38,'update 25.4'!$A:RH,7,FALSE) -> 0
A39: Vac-C | C39: Vacant-Commercial | D39: N/A | F39: N/A | H39: =VLOOKUP($A39,'update 25.4'!$A:RH,7,FALSE) -> 0
A40: Vac-S | C40: Vacant for Sale | H40: =VLOOKUP($A40,'update 25.4'!$A:RH,7,FALSE) -> #N/A

Sheet update 25.4
A1: Grainger plc
A2: Unit tenure Type to be held on SF unit and interfaced from Qube to SF
A4: Grainger Tenure Type | B4: Description | C4: Rent Review | D4: Responsible for Rent Review | E4: Notes | F4: Action
A5: AST | B5: Assured Short Term | C5: Annual | D5: Asset Manager/Renewals team
A6: Comp-Let | B6: Company Let | C6: Annual | D6: Asset Manager/Renewals team
A7: Licence | B7: Licence | C7: Varies -see below | D7: Asset Manager/Renewals team
A8: Live Work | B8: Live Work | C8: Annual | D8: Asset Manager/Renewals team
A9: Occ Con | B9: Occupational Contract | C9: Annual | D9: Asset Manager/Renewals team
A10: CommLease | B10: Commercial Lease | C10: According to Lease | D10: Commercial team | F10: details awaited from SB
A11: Comm-Let | B11: Commercial Let | C11: According to Lease | D11: Commercial team | F11: details awaited from SB
A12: CommLic | B12: Commercial License | C12: According to Lease | D12: Commercial team | F12: details awaited from SB
A13: Regulated | B13: Regulated | C13: Every 2 Years | D13: Deborah Caslaw
A14: Assured | B14: Assured | C14: Annual | D14: Deborah Caslaw
A15: AHA (Agr) | B15: Agricultural (Housing Act 1988) | C15: One tenancy has annual rent review. Other 2 have no rent review | D15: Deborah Caslaw/Local agent performs rent reviews | E15: PBI report generated from qube Rent Review Diaries to prompt review
A16: Assd.Per | B16: Assured Periodic | C16: Annual | D16: Deborah Caslaw/Property managers | E16: PBI report generated from qube Rent Review Diaries to prompt review
A17: Assd PHA | B17: Assured Paignton Housing Association | C17: Annual | D17: Deborah Caslaw/Property managers | E17: PBI report generated from qube Rent Review Diaries to prompt review
A18: AST Chc | B18: Assured Short Term -Church Workers | C18: Annual | D18: Deborah Caslaw/Property managers | E18: PBI report generated from qube Rent Review Diaries to prompt review
A19: AST KW | B19: Assured Short Term -Key Worker | C19: Annual | D19: Deborah Caslaw/Property managers | E19: PBI report generated from qube Rent Review Diaries to prompt review
A20: AST Per | B20: Assured Short Term - Periodic | C20: Varies | D20: Deborah Caslaw/Property managers | E20: PBI report generated from qube Rent Review Diaries to prompt review
A21: AST-REF | B21: Assured Short Term - Refer to Manager | C21: Every 2 Years | D21: Deborah Caslaw/Property managers | E21: PBI report generated from qube Rent Review Diaries to prompt review
A22: CT SerLic | B22: Caretaker Service License | C22: Only 3 units occupied by Grainger staff or caretakers-rent review by exception? | D22: Deborah Caslaw/Property managers | E22: PBI report generated from qube Rent Review Diaries to prompt review
A23: Assd.Per | B23: Assured Periodic | C23: Annual | D23: Deborah Caslaw/Property managers | E23: PBI report generated from qube Rent Review Diaries to prompt review
A24: Sh Owner | B24: Shared Ownership | C24: Annual | D24: Deborah Caslaw/ GT Team | E24: PBI report generated from qube Rent Review Diaries to prompt review
A25: Aff Rent | B25: Affordable Rent | C25: Annual | D25: Deborah Caslaw/ GT Team | E25: PBI report generated from qube Rent Review Diaries to prompt review
A26: DMR | B26: Discounted Market Rent- Non Social Housing | C26: Annual | D26: Deborah Caslaw/ GT Team/Local Authority | E26: PBI report generated from qube Rent Review Diaries to prompt review
A27: DMR-SOC | B27: Discounted Market Rent-Social Housing | C27: Annual? TBC | D27: GT Team/Local Authority | E27: PBI report generated from qube Rent Review Diaries to prompt review
A28: ChiefRent | B28: Chief Rent | C28: N/A | D28: N/A
A29: CT SerTen | B29: Caretaker Service Tenancy | C29: No tenancies exist on this tenure type | D29: N/A
A30: EstateChg | B30: Estate Charge | C30: N/A | D30: N/A
A31: MOD | B31: Ministry of Defence | C31: N/A | D31: N/A
A32: No Tenure | B32: No tenure | C32: N/A | D32: N/A
A33: Reversion | B33: Reversionary (CHARM) | C33: N/A | D33: N/A
A34: Services | B34: Services (amenities) | C34: N/A | D34: N/A
A35: Sold | B35: Sold | C35: N/A | D35: N/A
A36: Vacant | B36: Vacant | C36: N/A | D36: N/A
A37: Vac-C | B37: Vacant-Commercial | C37: N/A | D37: N/A
A38: FixedRent | B38: Fixed Rent | C38: Varies | D38: Deborah Caslaw/Rent Review Diary created in Qube when lease is first set up | E38: PBI report generated from qube Rent Review Diaries to prompt review
A39: Grnd Rent | B39: Ground rent | C39: Based on lease term | D39: Rent Review Diary created in Qube when lease is first set up | E39: PBI report generated from qube Rent Review Diaries to prompt review
A40: Nil GR | B40: Nil Ground Rent | C40: Based on lease term | D40: Rent Review Diary created in Qube when lease is first set up | E40: PBI report generated from qube Rent Review Diaries to prompt review
