Workbook

Sheet Old Building Queues
A1: Name | B1: Building ID | C1: Queue Type | D1: Salesforce Queue Name / User
A2: Pin Yard - Apartments | B2: a188d0000009nRPAAY | C2: Finance
A3: Pin Yard - Apartments | B3: a188d0000009nRPAAY | C3: Centralised PM | D3: Pin Yard Team
A4: Pin Yard - Apartments | B4: a188d0000009nRPAAY | C4: Onsite PM | D4: Pin Yard Team
A5: Pin Yard - Apartments | B5: a188d0000009nRPAAY | C5: Asset Management | D5: AM: BTR-Regions
A6: Pin Yard - Apartments | B6: a188d0000009nRPAAY | C6: Letting | D6: Lettings North East
A7: Pin Yard - Car Parking | B7: a188d0000009nRUAAY | C7: Finance
A8: Pin Yard - Car Parking | B8: a188d0000009nRUAAY | C8: Centralised PM | D8: Pin Yard Team
A9: Pin Yard - Car Parking | B9: a188d0000009nRUAAY | C9: Onsite PM | D9: Pin Yard Team
A10: Pin Yard - Car Parking | B10: a188d0000009nRUAAY | C10: Asset Management | D10: AM: BTR-Regions
A11: Pin Yard - Car Parking | B11: a188d0000009nRUAAY | C11: Letting | D11: Lettings North East
A12: The Headline Apts, Wellington Park Way, Leeds | B12: a184J000001UvzFQAS | C12: Finance
A13: The Headline Apts, Wellington Park Way, Leeds | B13: a184J000001UvzFQAS | C13: Centralised PM | D13: The Headline Team
A14: The Headline Apts, Wellington Park Way, Leeds | B14: a184J000001UvzFQAS | C14: Onsite PM | D14: The Headline Team
A15: The Headline Apts, Wellington Park Way, Leeds | B15: a184J000001UvzFQAS | C15: Asset Management | D15: AM: BTR-Regions
A16: The Headline Apts, Wellington Park Way, Leeds | B16: a184J000001UvzFQAS | C16: Letting | D16: Lettings North East
A17: The Headline Car Pk Wellington Park Way Leeds | B17: a184J000001UvzKQAS | C17: Finance
A18: The Headline Car Pk Wellington Park Way Leeds | B18: a184J000001UvzKQAS | C18: Centralised PM | D18: The Headline Team
A19: The Headline Car Pk Wellington Park Way Leeds | B19: a184J000001UvzKQAS | C19: Onsite PM | D19: The Headline Team
A20: The Headline Car Pk Wellington Park Way Leeds | B20: a184J000001UvzKQAS | C20: Asset Management | D20: AM: BTR-Regions
A21: The Headline Car Pk Wellington Park Way Leeds | B21: a184J000001UvzKQAS | C21: Letting | D21: Lettings North East
A22: The Forge Apts, North, Newcastle, NE1 3AA | B22: a188d0000008PiSAAU | C22: Finance
A23: The Forge Apts, North, Newcastle, NE1 3AA | B23: a188d0000008PiSAAU | C23: Centralised PM | D23: The Forge Team
A24: The Forge Apts, North, Newcastle, NE1 3AA | B24: a188d0000008PiSAAU | C24: Onsite PM | D24: The Forge Team
A25: The Forge Apts, North, Newcastle, NE1 3AA | B25: a188d0000008PiSAAU | C25: Asset Management | D25: AM: BTR-Regions
A26: The Forge Apts, North, Newcastle, NE1 3AA | B26: a188d0000008PiSAAU | C26: Letting | D26: Lettings North East
A27: The Forge Apts, South, Newcastle, NE1 3AA | B27: a188d0000008PiXAAU | C27: Finance
A28: The Forge Apts, South, Newcastle, NE1 3AA | B28: a188d0000008PiXAAU | C28: Centralised PM | D28: The Forge Team
A29: The Forge Apts, South, Newcastle, NE1 3AA | B29: a188d0000008PiXAAU | C29: Onsite PM | D29: The Forge Team
A30: The Forge Apts, South, Newcastle, NE1 3AA | B30: a188d0000008PiXAAU | C30: Asset Management | D30: AM: BTR-Regions
A31: The Forge Apts, South, Newcastle, NE1 3AA | B31: a188d0000008PiXAAU | C31: Letting | D31: Lettings North East
A32: The Forge Apts, West, Newcastle, NE1 3AA | B32: a188d0000008PicAAE | C32: Finance
A33: The Forge Apts, West, Newcastle, NE1 3AA | B33: a188d0000008PicAAE | C33: Centralised PM | D33: The Forge Team
A34: The Forge Apts, West, Newcastle, NE1 3AA | B34: a188d0000008PicAAE | C34: Onsite PM | D34: The Forge Team
A35: The Forge Apts, West, Newcastle, NE1 3AA | B35: a188d0000008PicAAE | C35: Asset Management | D35: AM: BTR-Regions
A36: The Forge Apts, West, Newcastle, NE1 3AA | B36: a188d0000008PicAAE | C36: Letting | D36: Lettings North East
A37: The Tilt Works - Ingot Place | B37: a18Nz000000cxbqIAA | C37: Finance
A38: The Tilt Works - Ingot Place | B38: a18Nz000000cxbqIAA | C38: Centralised PM | D38: The Tilt Works Team
A39: The Tilt Works - Ingot Place | B39: a18Nz000000cxbqIAA | C39: Onsite PM | D39: The Tilt Works Team
A40: The Tilt Works - Ingot Place | B40: a18Nz000000cxbqIAA | C40: Asset Management | D40: AM: New Launches
...

Sheet Building Queues
C1: Table 1: | I1: Table 2:
A2: Name | B2: Building ID | C2: Finance | D2: Centralised PM | E2: Onsite PM | F2: Asset Management | G2: Letting | I2: ID | J2: Finance_Team__c | K2: Centralised_PM_Team__c | L2: Onsite_PM_Team__c | M2: Asset_Management_Team__c | N2: Lettings_Team__c
A3: 123 Union Street, London, SE1 0LG | B3: a1826000001pj8kAAA | C3: Finance Team | D3: Customer Service Team | E3: PRS: London | F3: AM: PRS-London | G3: Lettings South | I3: =Table1[[#This Row],[Building ID]] -> a1826000001pj8kAAA | J3: =VLOOKUP(C3,'Distinct Queues'!$A$3:$B$39,2,FALSE) -> Finance_Team | K3: =VLOOKUP(D3,'Distinct Queues'!$A$3:$B$39,2,FALSE) -> Customer_Service_Team | L3: =VLOOKUP(E3,'Distinct Queues'!$A$3:$B$39,2,FALSE) -> PRS_London | M3: =VLOOKUP(F3,'Distinct Queues'!$A$3:$B$39,2,FALSE) -> AM_PRS_London | N3: =VLOOKUP(G3,'Distinct Queues'!$A$3:$B$39,2,FALSE) -> Lettings_South
A4: 13 Ufford Street, London, SE1 8QD | B4: a1826000001pj0HAAQ | C4: Finance Team | D4: Customer Service Team | E4: PRS: London | F4: AM: PRS-London | G4: Lettings South | I4: =Table1[[#This Row],[Building ID]] -> a1826000001pj0HAAQ | J4: =VLOOKUP(C4,'Distinct Queues'!$A$3:$B$39,2,FALSE) -> Finance_Team | K4: =VLOOKUP(D4,'Distinct Queues'!$A$3:$B$39,2,FALSE) -> Customer_Service_Team | L4: =VLOOKUP(E4,'Distinct Queues'!$A$3:$B$39,2,FALSE) -> PRS_London | M4: =VLOOKUP(F4,'Distinct Queues'!$A$3:$B$39,2,FALSE) -> AM_PRS_London | N4: =VLOOKUP(G4,'Distinct Queues'!$A$3:$B$39,2,FALSE) -> Lettings_South
A5: 15 Ufford Street, London, SE1 8QD | B5: a1826000001pj1AAAQ | C5: Finance Team | D5: Customer Service Team | E5: PRS: London | F5: AM: PRS-London | G5: Lettings South | I5: =Table1[[#This Row],[Building ID]] -> a1826000001pj1AAAQ | J5: =VLOOKUP(C5,'Distinct Queues'!$A$3:$B$39,2,FALSE) -> Finance_Team | K5: =VLOOKUP(D5,'Distinct Queues'!$A$3:$B$39,2,FALSE) -> Customer_Service_Team | L5: =VLOOKUP(E5,'Distinct Queues'!$A$3:$B$39,2,FALSE) -> PRS_London | M5: =VLOOKUP(F5,'Distinct Queues'!$A$3:$B$39,2,FALSE) -> AM_PRS_London | N5: =VLOOKUP(G5,'Distinct Queues'!$A$3:$B$39,2,FALSE) -> Lettings_South
A6: Ability Plaza | B6: a1826000001piYOAAY | C6: Finance Team | D6: Customer Service Team | E6: PRS: London | F6: AM: PRS-London | G6: Lettings South | I6: =Table1[[#This Row],[Building ID]] -> a1826000001piYOAAY | J6: =VLOOKUP(C6,'Distinct Queues'!$A$3:$B$39,2,FALSE) -> Finance_Team | K6: =VLOOKUP(D6,'Distinct Queues'!$A$3:$B$39,2,FALSE) -> Customer_Service_Team | L6: =VLOOKUP(E6,'Distinct Queues'!$A$3:$B$39,2,FALSE) -> PRS_London | M6: =VLOOKUP(F6,'Distinct Queues'!$A$3:$B$39,2,FALSE) -> AM_PRS_London | N6: =VLOOKUP(G6,'Distinct Queues'!$A$3:$B$39,2,FALSE) -> Lettings_South
A7: Ability View | B7: a1826000001SA7BAAW | C7: Finance Team | D7: Customer Service Team | E7: PRS: London | F7: AM: PRS-London | G7: Lettings South | I7: =Table1[[#This Row],[Building ID]] -> a1826000001SA7BAAW | J7: =VLOOKUP(C7,'Distinct Queues'!$A$3:$B$39,2,FALSE) -> Finance_Team | K7: =VLOOKUP(D7,'Distinct Queues'!$A$3:$B$39,2,FALSE) -> Customer_Service_Team | L7: =VLOOKUP(E7,'Distinct Queues'!$A$3:$B$39,2,FALSE) -> PRS_London | M7: =VLOOKUP(F7,'Distinct Queues'!$A$3:$B$39,2,FALSE) -> AM_PRS_London | N7: =VLOOKUP(G7,'Distinct Queues'!$A$3:$B$39,2,FALSE) -> Lettings_South
A8: Adlay Apartments, 3 Millet Place, London E16 | B8: a1826000001SB7aAAG | C8: Finance Team | D8: Millet Place Team | E8: Millet Place Team | F8: AM: BTR-London | G8: Lettings South | I8: =Table1[[#This Row],[Building ID]] -> a1826000001SB7aAAG | J8: =VLOOKUP(C8,'Distinct Queues'!$A$3:$B$39,2,FALSE) -> Finance_Team | K8: =VLOOKUP(D8,'Distinct Queues'!$A$3:$B$39,2,FALSE) -> Millet_Place_Team | L8: =VLOOKUP(E8,'Distinct Queues'!$A$3:$B$39,2,FALSE) -> Millet_Place_Team | M8: =VLOOKUP(F8,'Distinct Queues'!$A$3:$B$39,2,FALSE) -> AM_BTR_London | N8: =VLOOKUP(G8,'Distinct Queues'!$A$3:$B$39,2,FALSE) -> Lettings_South
A9: Adlay Apt, Parking bays, 3 Millet Place, E16 | B9: a1826000001peHKAAY | C9: Finance Team | D9: Millet Place Team | E9: Millet Place Team | F9: AM: BTR-London | G9: Lettings South | I9: =Table1[[#This Row],[Building ID]] -> a1826000001peHKAAY | J9: =VLOOKUP(C9,'Distinct Queues'!$A$3:$B$39,2,FALSE) -> Finance_Team | K9: =VLOOKUP(D9,'Distinct Queues'!$A$3:$B$39,2,FALSE) -> Millet_Place_Team | L9: =VLOOKUP(E9,'Distinct Queues'!$A$3:$B$39,2,FALSE) -> Millet_Place_Team | M9: =VLOOKUP(F9,'Distinct Queues'!$A$3:$B$39,2,FALSE) -> AM_BTR_London | N9: =VLOOKUP(G9,'Distinct Queues'!$A$3:$B$39,2,FALSE) -> Lettings_South
A10: Agate Mews, Colman Gardens, M53LP | B10: a1826000001raxbAAA | C10: Finance Team | D10: Customer Service Team | E10: PRS: Regions | F10: AM: PRS-Regions | G10: Lettings North West | I10: =Table1[[#This Row],[Building ID]] -> a1826000001raxbAAA | J10: =VLOOKUP(C10,'Distinct Queues'!$A$3:$B$39,2,FALSE) -> Finance_Team | K10: =VLOOKUP(D10,'Distinct Queues'!$A$3:$B$39,2,FALSE) -> Customer_Service_Team | L10: =VLOOKUP(E10,'Distinct Queues'!$A$3:$B$39,2,FALSE) -> PRS_Regions | M10: =VLOOKUP(F10,'Distinct Queues'!$A$3:$B$39,2,FALSE) -> AM_PRS_Regions | N10: =VLOOKUP(G10,'Distinct Queues'!$A$3:$B$39,2,FALSE) -> Lettings_North_West
A11: Aldwyn House, Davidson Gardens, London, SW8 2 | B11: a1826000001pj9cAAA | C11: Finance Team | D11: Customer Service Team | E11: PRS: London | F11: AM: PRS-London | G11: Lettings South | I11: =Table1[[#This Row],[Building ID]] -> a1826000001pj9cAAA | J11: =VLOOKUP(C11,'Distinct Queues'!$A$3:$B$39,2,FALSE) -> Finance_Team | K11: =VLOOKUP(D11,'Distinct Queues'!$A$3:$B$39,2,FALSE) -> Customer_Service_Team | L11: =VLOOKUP(E11,'Distinct Queues'!$A$3:$B$39,2,FALSE) -> PRS_London | M11: =VLOOKUP(F11,'Distinct Queues'!$A$3:$B$39,2,FALSE) -> AM_PRS_London | N11: =VLOOKUP(G11,'Distinct Queues'!$A$3:$B$39,2,FALSE) -> Lettings_South
A12: Ancoats, Manchester, M4 6BZ | B12: a1826000001pivuAAA | C12: Finance Team | D12: Customer Service Team | E12: PRS: Regions | F12: AM: PRS-Regions | G12: Lettings North West | I12: =Table1[[#This Row],[Building ID]] -> a1826000001pivuAAA | J12: =VLOOKUP(C12,'Distinct Queues'!$A$3:$B$39,2,FALSE) -> Finance_Team | K12: =VLOOKUP(D12,'Distinct Queues'!$A$3:$B$39,2,FALSE) -> Customer_Service_Team | L12: =VLOOKUP(E12,'Distinct Queues'!$A$3:$B$39,2,FALSE) -> PRS_Regions | M12: =VLOOKUP(F12,'Distinct Queues'!$A$3:$B$39,2,FALSE) -> AM_PRS_Regions | N12: =VLOOKUP(G12,'Distinct Queues'!$A$3:$B$39,2,FALSE) -> Lettings_North_West
A13: Apex Gardens, Aster Apts, PRS | B13: a1826000001SZpeAAG | C13: Finance Team | D13: Apex Gardens Team | E13: Apex Gardens Team | F13: AM: BTR-London | G13: Lettings South | I13: =Table1[[#This Row],[Building ID]] -> a1826000001SZpeAAG | J13: =VLOOKUP(C13,'Distinct Queues'!$A$3:$B$39,2,FALSE) -> Finance_Team | K13: =VLOOKUP(D13,'Distinct Queues'!$A$3:$B$39,2,FALSE) -> Apex_Gardens_Team | L13: =VLOOKUP(E13,'Distinct Queues'!$A$3:$B$39,2,FALSE) -> Apex_Gardens_Team | M13: =VLOOKUP(F13,'Distinct Queues'!$A$3:$B$39,2,FALSE) -> AM_BTR_London | N13: =VLOOKUP(G13,'Distinct Queues'!$A$3:$B$39,2,FALSE) -> Lettings_South
A14: Apex Gardens, Juniper House, GT | B14: a1826000001SRknAAG | C14: Finance Team | D14: Apex Gardens Team | E14: Apex Gardens Team | F14: AM: BTR-London | G14: Lettings South | I14: =Table1[[#This Row],[Building ID]] -> a1826000001SRknAAG | J14: =VLOOKUP(C14,'Distinct Queues'!$A$3:$B$39,2,FALSE) -> Finance_Team | K14: =VLOOKUP(D14,'Distinct Queues'!$A$3:$B$39,2,FALSE) -> Apex_Gardens_Team | L14: =VLOOKUP(E14,'Distinct Queues'!$A$3:$B$39,2,FALSE) -> Apex_Gardens_Team | M14: =VLOOKUP(F14,'Distinct Queues'!$A$3:$B$39,2,FALSE) -> AM_BTR_London | N14: =VLOOKUP(G14,'Distinct Queues'!$A$3:$B$39,2,FALSE) -> Lettings_South
... A332: Wykeham House, Union Street, London, SE1 0LG | B332: a1826000001pj82AAA | C332: Finance Team | D332: Customer Service Team | E332: PRS: London | F332: AM: PRS-London | G332: Lettings South | I332: =Table1[[#This Row],[Building ID]] -> a1826000001pj82AAA | J332: =VLOOKUP(C332,'Distinct Queues'!$A$3:$B$39,2,FALSE) -> Finance_Team | K332: =VLOOKUP(D332,'Distinct Queues'!$A$3:$B$39,2,FALSE) -> Customer_Service_Team | L332: =VLOOKUP(E332,'Distinct Queues'!$A$3:$B$39,2,FALSE) -> PRS_London | M332: =VLOOKUP(F332,'Distinct Queues'!$A$3:$B$39,2,FALSE) -> AM_PRS_London | N332: =VLOOKUP(G332,'Distinct Queues'!$A$3:$B$39,2,FALSE) -> Lettings_South
I333: =Table1[[#This Row],[Building ID]] -> 0 | J333: =VLOOKUP(C333,'Distinct Queues'!$A$3:$B$39,2,FALSE) -> #N/A | K333: =VLOOKUP(D333,'Distinct Queues'!$A$3:$B$39,2,FALSE) -> #N/A | L333: =VLOOKUP(E333,'Distinct Queues'!$A$3:$B$39,2,FALSE) -> #N/A | M333: =VLOOKUP(F333,'Distinct Queues'!$A$3:$B$39,2,FALSE) -> #N/A | N333: =VLOOKUP(G333,'Distinct Queues'!$A$3:$B$39,2,FALSE) -> #N/A
I334: =Table1[[#This Row],[Building ID]] -> 0 | J334: =VLOOKUP(C334,'Distinct Queues'!$A$3:$B$39,2,FALSE) -> #N/A | K334: =VLOOKUP(D334,'Distinct Queues'!$A$3:$B$39,2,FALSE) -> #N/A | L334: =VLOOKUP(E334,'Distinct Queues'!$A$3:$B$39,2,FALSE) -> #N/A | M334: =VLOOKUP(F334,'Distinct Queues'!$A$3:$B$39,2,FALSE) -> #N/A | N334: =VLOOKUP(G334,'Distinct Queues'!$A$3:$B$39,2,FALSE) -> #N/A
I335: =Table1[[#This Row],[Building ID]] -> 0 | J335: =VLOOKUP(C335,'Distinct Queues'!$A$3:$B$39,2,FALSE) -> #N/A | K335: =VLOOKUP(D335,'Distinct Queues'!$A$3:$B$39,2,FALSE) -> #N/A | L335: =VLOOKUP(E335,'Distinct Queues'!$A$3:$B$39,2,FALSE) -> #N/A | M335: =VLOOKUP(F335,'Distinct Queues'!$A$3:$B$39,2,FALSE) -> #N/A | N335: =VLOOKUP(G335,'Distinct Queues'!$A$3:$B$39,2,FALSE) -> #N/A
I336: =Table1[[#This Row],[Building ID]] -> 0 | J336: =VLOOKUP(C336,'Distinct Queues'!$A$3:$B$39,2,FALSE) -> #N/A | K336: =VLOOKUP(D336,'Distinct Queues'!$A$3:$B$39,2,FALSE) -> #N/A | L336: =VLOOKUP(E336,'Distinct Queues'!$A$3:$B$39,2,FALSE) -> #N/A | M336: =VLOOKUP(F336,'Distinct Queues'!$A$3:$B$39,2,FALSE) -> #N/A | N336: =VLOOKUP(G336,'Distinct Queues'!$A$3:$B$39,2,FALSE) -> #N/A
I337: =Table1[[#This Row],[Building ID]] -> 0 | J337: =VLOOKUP(C337,'Distinct Queues'!$A$3:$B$39,2,FALSE) -> #N/A | K337: =VLOOKUP(D337,'Distinct Queues'!$A$3:$B$39,2,FALSE) -> #N/A | L337: =VLOOKUP(E337,'Distinct Queues'!$A$3:$B$39,2,FALSE) -> #N/A | M337: =VLOOKUP(F337,'Distinct Queues'!$A$3:$B$39,2,FALSE) -> #N/A | N337: =VLOOKUP(G337,'Distinct Queues'!$A$3:$B$39,2,FALSE) -> #N/A
I338: =Table1[[#This Row],[Building ID]] -> 0 | J338: =VLOOKUP(C338,'Distinct Queues'!$A$3:$B$39,2,FALSE) -> #N/A | K338: =VLOOKUP(D338,'Distinct Queues'!$A$3:$B$39,2,FALSE) -> #N/A | L338: =VLOOKUP(E338,'Distinct Queues'!$A$3:$B$39,2,FALSE) -> #N/A | M338: =VLOOKUP(F338,'Distinct Queues'!$A$3:$B$39,2,FALSE) -> #N/A | N338: =VLOOKUP(G338,'Distinct Queues'!$A$3:$B$39,2,FALSE) -> #N/A
I339: =Table1[[#This Row],[Building ID]] -> 0 | J339: =VLOOKUP(C339,'Distinct Queues'!$A$3:$B$39,2,FALSE) -> #N/A | K339: =VLOOKUP(D339,'Distinct Queues'!$A$3:$B$39,2,FALSE) -> #N/A | L339: =VLOOKUP(E339,'Distinct Queues'!$A$3:$B$39,2,FALSE) -> #N/A | M339: =VLOOKUP(F339,'Distinct Queues'!$A$3:$B$39,2,FALSE) -> #N/A | N339: =VLOOKUP(G339,'Distinct Queues'!$A$3:$B$39,2,FALSE) -> #N/A
I340: =Table1[[#This Row],[Building ID]] -> 0 | J340: =VLOOKUP(C340,'Distinct Queues'!$A$3:$B$39,2,FALSE) -> #N/A | K340: =VLOOKUP(D340,'Distinct Queues'!$A$3:$B$39,2,FALSE) -> #N/A | L340: =VLOOKUP(E340,'Distinct Queues'!$A$3:$B$39,2,FALSE) -> #N/A | M340: =VLOOKUP(F340,'Distinct Queues'!$A$3:$B$39,2,FALSE) -> #N/A | N340: =VLOOKUP(G340,'Distinct Queues'!$A$3:$B$39,2,FALSE) -> #N/A
I341: =Table1[[#This Row],[Building ID]] -> 0 | J341: =VLOOKUP(C341,'Distinct Queues'!$A$3:$B$39,2,FALSE) -> #N/A | K341: =VLOOKUP(D341,'Distinct Queues'!$A$3:$B$39,2,FALSE) -> #N/A | L341: =VLOOKUP(E341,'Distinct Queues'!$A$3:$B$39,2,FALSE) -> #N/A | M341: =VLOOKUP(F341,'Distinct Queues'!$A$3:$B$39,2,FALSE) -> #N/A | N341: =VLOOKUP(G341,'Distinct Queues'!$A$3:$B$39,2,FALSE) -> #N/A
I342: =Table1[[#This Row],[Building ID]] -> 0 | J342: =VLOOKUP(C342,'Distinct Queues'!$A$3:$B$39,2,FALSE) -> #N/A | K342: =VLOOKUP(D342,'Distinct Queues'!$A$3:$B$39,2,FALSE) -> #N/A | L342: =VLOOKUP(E342,'Distinct Queues'!$A$3:$B$39,2,FALSE) -> #N/A | M342: =VLOOKUP(F342,'Distinct Queues'!$A$3:$B$39,2,FALSE) -> #N/A | N342: =VLOOKUP(G342,'Distinct Queues'!$A$3:$B$39,2,FALSE) -> #N/A
I343: =Table1[[#This Row],[Building ID]] -> 0 | J343: =VLOOKUP(C343,'Distinct Queues'!$A$3:$B$39,2,FALSE) -> #N/A | K343: =VLOOKUP(D343,'Distinct Queues'!$A$3:$B$39,2,FALSE) -> #N/A | L343: =VLOOKUP(E343,'Distinct Queues'!$A$3:$B$39,2,FALSE) -> #N/A | M343: =VLOOKUP(F343,'Distinct Queues'!$A$3:$B$39,2,FALSE) -> #N/A | N343: =VLOOKUP(G343,'Distinct Queues'!$A$3:$B$39,2,FALSE) -> #N/A
I344: =Table1[[#This Row],[Building ID]] -> 0 | J344: =VLOOKUP(C344,'Distinct Queues'!$A$3:$B$39,2,FALSE) -> #N/A | K344: =VLOOKUP(D344,'Distinct Queues'!$A$3:$B$39,2,FALSE) -> #N/A | L344: =VLOOKUP(E344,'Distinct Queues'!$A$3:$B$39,2,FALSE) -> #N/A | M344: =VLOOKUP(F344,'Distinct Queues'!$A$3:$B$39,2,FALSE) -> #N/A | N344: =VLOOKUP(G344,'Distinct Queues'!$A$3:$B$39,2,FALSE) -> #N/A
I345: =Table1[[#This Row],[Building ID]] -> 0 | J345: =VLOOKUP(C345,'Distinct Queues'!$A$3:$B$39,2,FALSE) -> #N/A | K345: =VLOOKUP(D345,'Distinct Queues'!$A$3:$B$39,2,FALSE) -> #N/A | L345: =VLOOKUP(E345,'Distinct Queues'!$A$3:$B$39,2,FALSE) -> #N/A | M345: =VLOOKUP(F345,'Distinct Queues'!$A$3:$B$39,2,FALSE) -> #N/A | N345: =VLOOKUP(G345,'Distinct Queues'!$A$3:$B$39,2,FALSE) -> #N/A

Sheet Salesforce Queues
A1: User | B1: Salesforce Queue Name
A2: Jack Howe | B2: Lettings North East
A3: Deanne Coss | B3: Lettings North East
A4: Nathan White | B4: Lettings North East
A5: Ruth Friend | B5: Pin Yard Team
A6: Bailey King | B6: Pin Yard Team
A7: Jessica Warnes | B7: Pin Yard Team
A8: Rachel Creer | B8: Pin Yard Team
A9: Joseph Scarrott | B9: The Headline Team
A10: Coren Macniven | B10: The Headline Team
A11: Corinne Lawrenson | B11: The Headline Team
A12: Sam Robson | B12: The Forge Team
... A138: Lynn Robson | B138: Customer Service Team

Sheet Distinct Queues
A1: Table 1: | F1: Table 2:
A2: Name | B2: DeveloperName | C2: Type | F2: Queue:Group:Name | G2: SobjectType
A3: Finance Team | B3: Finance_Team | C3: Queue | F3: =A3 -> Finance Team | G3: End_of_Tenancy_Task__c
A4: Pin Yard Team | B4: Pin_Yard_Team | C4: Queue | F4: =A4 -> Pin Yard Team | G4: End_of_Tenancy_Task__c
A5: The Headline Team | B5: The_Headline_Team | C5: Queue | F5: =A5 -> The Headline Team | G5: End_of_Tenancy_Task__c
A6: The Forge Team | B6: The_Forge_Team | C6: Queue | F6: =A6 -> The Forge Team | G6: End_of_Tenancy_Task__c
A7: The Tilt Works Team | B7: The_Tilt_Works_Team | C7: Queue | F7: =A7 -> The Tilt Works Team | G7: End_of_Tenancy_Task__c
A8: Brook Place Team | B8: Brook_Place_Team | C8: Queue | F8: =A8 -> Brook Place Team | G8: End_of_Tenancy_Task__c
A9: Clippers Quay Team | B9: Clippers_Quay_Team | C9: Queue | F9: =A9 -> Clippers Quay Team | G9: End_of_Tenancy_Task__c
A10: Hawkins & George Team | B10: Hawkins_and_George_Team | C10: Queue | F10: =A10 -> Hawkins & George Team | G10: End_of_Tenancy_Task__c
A11: The Condor Team | B11: The_Condor_Team | C11: Queue | F11: =A11 -> The Condor Team | G11: End_of_Tenancy_Task__c
A12: The Barnum Team | B12: The_Barnum_Team | C12: Queue | F12: =A12 -> The Barnum Team | G12: End_of_Tenancy_Task__c
A13: Enigma Square Team | B13: Enigma_Square_Team | C13: Queue | F13: =A13 -> Enigma Square Team | G13: End_of_Tenancy_Task__c
A14: Solstice Apartments Team | B14: Solstice_Apartments_Team | C14: Queue | F14: =A14 -> Solstice Apartments Team | G14: End_of_Tenancy_Task__c
... A39: Lettings South | B39: Lettings_South | C39: Queue | F39: =A39 -> Lettings South | G39: End_of_Tenancy_Task__c

Sheet GroupMember Insert
A1: User | B1: Group:Group:Name | C1: UserOrGroupId
A2: Sam Robson | B2: The Forge Team | C2: =VLOOKUP(A2,'User Extract'!$C$2:$D$563,2,FALSE) -> #N/A
A3: Sam Robson | B3: PRS: Regions | C3: =VLOOKUP(A3,'User Extract'!$C$2:$D$563,2,FALSE) -> #N/A
A4: Vicki Turnbull | B4: AM: BTR-Regions | C4: =VLOOKUP(A4,'User Extract'!$C$2:$D$563,2,FALSE) -> #N/A
A5: Vicki Turnbull | B5: AM: PRS-Regions | C5: =VLOOKUP(A5,'User Extract'!$C$2:$D$563,2,FALSE) -> #N/A
A6: Alice Shaw | B6: Gatehouse Team | C6: =VLOOKUP(A6,'User Extract'!$C$2:$D$563,2,FALSE) -> 0058d0000034L6QAAU
A7: Alison Adamson | B7: Finance Team | C7: =VLOOKUP(A7,'User Extract'!$C$2:$D$563,2,FALSE) -> 0054J000004vXPIQA2
A8: David Hancock | B8: PRS: Regions | C8: =VLOOKUP(A8,'User Extract'!$C$2:$D$563,2,FALSE) -> #N/A
A9: Helen Bowers | B9: Clippers Quay Team | C9: =VLOOKUP(A9,'User Extract'!$C$2:$D$563,2,FALSE) -> #N/A
A10: Sarah Norstrom | B10: AM: New Launches | C10: =VLOOKUP(A10,'User Extract'!$C$2:$D$563,2,FALSE) -> #N/A
A11: Alison Rock | B11: Finance Team | C11: =VLOOKUP(A11,'User Extract'!$C$2:$D$563,2,FALSE) -> 0052600000BnKKdAAN
A12: Anne Stephenson | B12: Finance Team | C12: =VLOOKUP(A12,'User Extract'!$C$2:$D$563,2,FALSE) -> 0054J000004vXPHQA2
A13: Bailey King | B13: Pin Yard Team | C13: =VLOOKUP(A13,'User Extract'!$C$2:$D$563,2,FALSE) -> 0058d0000034KskAAE
... A19: Colette Taylor | B19: Lettings North West | C19: =VLOOKUP(A19,'User Extract'!$C$2:$D$563,2,FALSE) -> 0054J000004vXOWQA2
A20: Connor Berry | B20: Clippers Quay Team | C20: =VLOOKUP(TRIM(A20),'User Extract'!$C$2:$D$563,2,FALSE) -> 0058d000004GtmhAAC
A21: Coren Macniven | B21: The Headline Team | C21: =VLOOKUP(A21,'User Extract'!$C$2:$D$563,2,FALSE) -> 0058d0000034Kn5AAE
A22: Corinne Lawrenson | B22: The Headline Team | C22: =VLOOKUP(A22,'User Extract'!$C$2:$D$563,2,FALSE) -> 0058d000005RQ1sAAG
A23: Helen Bell | B23: Finance Team | C23: =VLOOKUP(A23,'User Extract'!$C$2:$D$563,2,FALSE) -> #N/A
A24: Daniel Hind | B24: Weavers Yard Team | C24: =VLOOKUP(A24,'User Extract'!$C$2:$D$563,2,FALSE) -> 0058d000006csAqAAI
A25: Darin Solomon | B25: PRS: London | C25: =VLOOKUP(A25,'User Extract'!$C$2:$D$563,2,FALSE) -> 0054J000004vm8wQAA
A26: Samantha Lancaster | B26: The Filaments Team | C26: =VLOOKUP(A26,'User Extract'!$C$2:$D$563,2,FALSE) -> #N/A
A27: Darren Pritchard | B27: Clippers Quay Team | C27: =VLOOKUP(TRIM(A27),'User Extract'!$C$2:$D$563,2,FALSE) -> 0058d000004H4neAAC
A28: Deanne Coss | B28: Lettings North East | C28: =VLOOKUP(A28,'User Extract'!$C$2:$D$563,2,FALSE) -> 0058d00000202rVAAQ
A29: Edyta Forysiuk | B29: PRS: London | C29: =VLOOKUP(A29,'User Extract'!$C$2:$D$563,2,FALSE) -> 0054J000004vm8xQAA
A30: Emma Cramer-Mitchell | B30: Brook Place Team | C30: =VLOOKUP(A30,'User Extract'!$C$2:$D$563,2,FALSE) -> 0058d0000034c7KAAQ
A31: Gemma Gavin | B31: EOT Lettings South | C31: =VLOOKUP(A31,'User Extract'!$C$2:$D$563,2,FALSE) -> 0058d000001yXerAAE
A32: Grace Fiske | B32: Enigma Square Team | C32: =VLOOKUP(TRIM(A32),'User Extract'!$C$2:$D$563,2,FALSE) -> 0058d00000343K8AAI
A33: Alexa Byrne | B33: AM: PRS-London | C33: =VLOOKUP(A33,'User Extract'!$C$2:$D$563,2,FALSE) -> #N/A
A34: Daisy Stuckey | B34: AM: PRS-London | C34: =VLOOKUP(A34,'User Extract'!$C$2:$D$563,2,FALSE) -> #N/A
A35: Grace Thompson | B35: Finance Team | C35: =VLOOKUP(A35,'User Extract'!$C$2:$D$563,2,FALSE) -> 0054J000006BlkiQAC
A36: Gurinder Punia | B36: Gilders Yard Team | C36: =VLOOKUP(TRIM(A36),'User Extract'!$C$2:$D$563,2,FALSE) -> 0058d0000034KYsAAM
A37: Hayley Fry | B37: Gatehouse Team | C37: =VLOOKUP(A37,'User Extract'!$C$2:$D$563,2,FALSE) -> 0058d0000034KYTAA2
A38: Hazel Armstrong | B38: Finance Team | C38: =VLOOKUP(A38,'User Extract'!$C$2:$D$563,2,FALSE) -> 0054J000004vXPLQA2
A39: Holly Boggis | B39: Argo Apartments Team | C39: =VLOOKUP(A39,'User Extract'!$C$2:$D$563,2,FALSE) -> 0058d000006cbqpAAA
A40: Isaac Turner | B40: Brook Place Team | C40: =VLOOKUP(TRIM(A40),'User Extract'!$C$2:$D$563,2,FALSE) -> 0058d0000034KliAAE
A41: Jack Howe | B41: Lettings North East | C41: =VLOOKUP(A41,'User Extract'!$C$2:$D$563,2,FALSE) -> 0054J000006BkQgQAK
A42: Jack Wellings | B42: Lettings North West | C42: =VLOOKUP(A42,'User Extract'!$C$2:$D$563,2,FALSE) -> 0054J000004wSINQA2
A43: Craig Parkinson | B43: Hawkins & George Team | C43: =VLOOKUP(A43,'User Extract'!$C$2:$D$563,2,FALSE) -> #N/A
A44: Jacqueline Cooper | B44: The Condor Team | C44: =VLOOKUP(A44,'User Extract'!$C$2:$D$563,2,FALSE) -> 0058d000005TEYFAA4
A45: Jacqui Dobson | B45: Customer Service Team | C45: =VLOOKUP(A45,'User Extract'!$C$2:$D$563,2,FALSE) -> 0058d000004FsUgAAK
...

Sheet EoT user perm set assignment
A1: User | B1: AssigneeId | C1: PermissionSetId | D1: Result
A2: Sam Robson | B2: 0054J000004vm8VQAQ | C2: 0PSNz0000001NXIOA2 | D2: Succeeded
A3: Vicki Turnbull | B3: 0054J000004vm8YQAQ | C3: 0PSNz0000001NXIOA2 | D3: Succeeded
A4: Luke Pollard | B4: 0054J000004vm99QAA | C4: 0PSNz0000001NXIOA2 | D4: Succeeded
A5: Louise Spooner | B5: 0054J000004vm9BQAQ | C5: 0PSNz0000001NXIOA2 | D5: Succeeded
A6: David Hancock | B6: 0054J000004vm9CQAQ | C6: 0PSNz0000001NXIOA2 | D6: Succeeded
A7: Helen Bowers | B7: 0054J000004vm9DQAQ | C7: 0PSNz0000001NXIOA2 | D7: Succeeded
A8: Sarah Norstrom | B8: 0054J000004vm9KQAQ | C8: 0PSNz0000001NXIOA2 | D8: Succeeded
A9: Lucy Staniland | B9: 0054J000004vXObQAM | C9: 0PSNz0000001NXIOA2 | D9: Failed - inactive user
A10: Colette Taylor | B10: 0054J000004vXOWQA2 | C10: 0PSNz0000001NXIOA2 | D10: Succeeded
A11: Ruben Cancio | B11: 0054J000004vXOYQA2 | C11: 0PSNz0000001NXIOA2 | D11: Succeeded
A12: Melanie Haughey | B12: 0054J000004vXOyQAM | C12: 0PSNz0000001NXIOA2 | D12: Succeeded
... A123: Matthew Grayton | B123: 005Nz0000020wIzIAI | C123: 0PSNz0000001NXIOA2 | D123: Succeeded

Sheet Unit Manager perm set
A1: Name | B1: AssigneeId | C1: PermissionSetId | D1: Status
A2: Mark Churchard | B2: 0054J000004vm86QAA | C2: 0PSNz0000001NXHOA2 | D2: Succeeded
A3: Yvonne Leggett | B3: 0054J000004vm8GQAQ | C3: 0PSNz0000001NXHOA2 | D3: Succeeded
A4: Sam Robson | B4: 0054J000004vm8VQAQ | C4: 0PSNz0000001NXHOA2 | D4: Succeeded
A5: Robert Steel | B5: 0054J000004vm8hQAA | C5: 0PSNz0000001NXHOA2 | D5: Succeeded
A6: Miranda Rowe | B6: 0054J000004vm8oQAA | C6: 0PSNz0000001NXHOA2 | D6: Succeeded
A7: Nicolette McRae | B7: 0054J000004vm8pQAA | C7: 0PSNz0000001NXHOA2 | D7: Succeeded
A8: Darin Solomon | B8: 0054J000004vm8wQAA | C8: 0PSNz0000001NXHOA2 | D8: Succeeded
A9: Edyta Forysiuk | B9: 0054J000004vm8xQAA | C9: 0PSNz0000001NXHOA2 | D9: Failed - inactive user
A10: Mark Weeden | B10: 0054J000004vm95QAA | C10: 0PSNz0000001NXHOA2 | D10: Succeeded
A11: Luke Pollard | B11: 0054J000004vm99QAA | C11: 0PSNz0000001NXHOA2 | D11: Succeeded
A12: Louise Spooner | B12: 0054J000004vm9BQAQ | C12: 0PSNz0000001NXHOA2 | D12: Succeeded
... A29: Tina Viragh | B29: 005Nz000000C72YIAS | C29: 0PSNz0000001NXHOA2 | D29: Succeeded

Sheet User Extract
A1: _ | B1: Id | C1: Name | D1: Id
A2: [User] | B2: 0052600000Ac7aoAAB | C2: Sam Duncan | D2: =B2 -> 0052600000Ac7aoAAB
A3: [User] | B3: 0052600000Ac7atAAB | C3: Nikki Papenfus | D3: =B3 -> 0052600000Ac7atAAB
A4: [User] | B4: 0052600000AcPSIAA3 | C4: G SAJI | D4: =B4 -> 0052600000AcPSIAA3
A5: [User] | B5: 0052600000AcPzmAAF | C5: Anjali Salecha | D5: =B5 -> 0052600000AcPzmAAF
A6: [User] | B6: 0052600000Ar27XAAR | C6: Nevin Lia | D6: =B6 -> 0052600000Ar27XAAR
A7: [User] | B7: 0052600000ArJSbAAN | C7: Abigale Boaler | D7: =B7 -> 0052600000ArJSbAAN
A8: [User] | B8: 0052600000ArwIhAAJ | C8: Khonani Davhana | D8: =B8 -> 0052600000ArwIhAAJ
A9: [User] | B9: 0052600000AtV3EAAV | C9: Jameelah Forfarnah | D9: =B9 -> 0052600000AtV3EAAV
A10: [User] | B10: 0052600000B30btAAB | C10: David Hitt | D10: =B10 -> 0052600000B30btAAB
A11: [User] | B11: 0052600000B30bzAAB | C11: Simon Aldridge | D11: =B11 -> 0052600000B30bzAAB
A12: [User] | B12: 0052600000B30c0AAB | C12: Connor Manuel | D12: =B12 -> 0052600000B30c0AAB
A13: [User] | B13: 0052600000B30c2AAB | C13: Sarah Nolan | D13: =B13 -> 0052600000B30c2AAB
... A330: [User] | B330: 005UE000001lHaLYAU | C330: New Marketing Website | D330: =B330 -> 005UE000001lHaLYAU
D331: =B331 -> 0
D332: =B332 -> 0
D333: =B333 -> 0
D334: =B334 -> 0
D335: =B335 -> 0
D336: =B336 -> 0
D337: =B337 -> 0
D338: =B338 -> 0
D339: =B339 -> 0
D340: =B340 -> 0
D341: =B341 -> 0
D342: =B342 -> 0
... D563: =B563 -> 0
