Workbook

Sheet Revision History
B2: Version | C2: Updated By | D2: Methods Affected by Change | E2: Revision Description
B3: V r1.0 | C3: - | E3: Initial release
B4: V r1.1 | C4: Lee Williams | D4: None - Documentation update | E4: Added Outcome status enum list and changed linkedApplicant ID description
B5: V r1.2 | C5: Lee Williams | D5: None - Documentation update | E5: Ameded Outcome Status enum and added applicant Status enum
B6: V r1.3 | C6: Lee Williams | D6: None - Documentation update | E6: Extended description of Cancel Tenancy
B7: V r1.4 | C7: Lee Williams | D7: None - Documentation update | E7: Extended descriptions and minor wording change
B8: V r1.5 | C8: Lee Williams | D8: None - Documentation update | E8: Updated response for addApplicant and updated description to cancellation reason enum
B9: V r1.5 | C9: Lee Williams | D9: None - Documentation update | E9: Updated ApplicantID description
B10: V r1.6 | C10: Lee Williams | D10: Error Response Normalisation | E10: Document QA review and error responses added
B11: V r1.7 | C11: Lee Williams | D11: 2 Iframe Calls added | E11: Create reference and add applicant for iframe added
B12: V r1.8 | C12: Lee Williams | D12: GetReferenceStatus | E12: Granular task status added to GetReferenceStatusCall, more detailed error keys added, Pending GetApplicantNotes call added
B13: V r1.9 | C13: Lee Williams | D13: None - Documentation update | E13: Additional report types added to enum list
B14: V r2.0 | C14: Lee Williams | D14: Added GetApplicantNotes call | E14: GetApplicantNotes Call added, PostApplicantReferenceNote responses updated

Sheet API Services
B3: API Method Name (Link to Request & Response Examples with Data Structure) | C3: Method Version | D3: Method Description | E3: Method URL
B4: Get Authentication Token | C4: 0.1 | D4: Method to acquire an authentication (bearer) token, using the scope (always "standardapiaccess"), along with the provided clientID and Client secret | E4: Swagger - /standardapi/v1/ Postman - https://preprod-auth-service.letalliance.dev/connect/token
B5: CheckConnection | C5: 0.1 | D5: Simple ping method used to check connectivity between Vision+ API server and client with no parameters. As with all methods, if authentication token is missing or invalid, an error will be returned. If the authentication token is valid and the connection is successful, a success true will be returned. | E5: /standardapi/v1/CheckConnection
B6: CreateReferenceWithAllData | C6: 0.1 | D6: As one of the base methods of the Vision+ API, this method is used to create a property, create tenancy on property and add one or more applicants to be referenced in that property, for systems that gather and provide all required applicant data up front. | E6: /standardapi/v1/CreateReferenceWithAllData
B7: CreateReferenceWithInputFromApplicant | C7: 0.1 | D7: As another base methods of the Vision+ API, this method is used to create a property, create tenancy on property and add one or more applicants to be referenced in that property, for systems that require the applicant to fill in their own data. On submission, an email will be sent to any Applicant in the application, with details on how to log on to the Vision+ Portal and complete the required referencing data. | E7: /standardapi/v1/CreateReferenceWithInputFromApplicant
B8: CreateReferenceWithApplicantIframe | C8: 0.1 | D8: As another base methods of the Vision+ API, this method is used to create a property, create tenancy on property and add one or more applicants to be referenced in that property, for systems that require the applicant to fill in their own data. On submission, an email will be sent to any Applicant in the application, with details on how to log on to the Vision+ Portal and complete the required referencing data. | E8: /standardapi/v1/CreateReferenceWithApplicantIframe
B9: GetApplicantReferenceStatus | C9: 0.1 | D9: This method is used to check the Applicant referencing status of one or more Applicants. | E9: /standardapi/v1/GetApplicantReferenceStatus/{ApplicantID}
B10: GetAgentActiveProducts | C10: 0.1 | D10: This method is used to get the list of products currently available to the agent to use in referencing applications. Using an invalid product code or a product the agent is not authorised for will cause the reference application request to fail and return an error. | E10: /standardapi/v1/GetAgentActiveProducts/{AgentCode}
B11: GetApplicantReferenceReports | C11: 0.1 | D11: This method provides the applicant available assessment reports as a base64 encoded string, which must be saved as PDF file. An interim report will be available if the appliants referencing application is in progress, and a final report will be avaible when the applicants reference application status is completed. | E11: /standardapi/v1/GetApplicantReferenceReports/{ApplicantID}
B12: PostApplicantReferenceDocument | C12: 0.1 | D12: This method is used to upload documents to support the applicant assessment process. Such as identification, proof of income, rent receipts etc. | E12: /standardapi/v1/PostApplicantReferenceDocument
B13: ResendApplicantReferenceLink | C13: 0.1 | D13: Used in conjunction with the references created with the CreateReferenceWithInputFromApplicant call, This method is used to resend the applicant referencing link to the applicant, to complete the required referencing data. This is not required for reference applications started with the CreateReferenceWithAllData call. | E13: ​/api​/workflow​/StandardIntegration​/ResendApplicantReferenceLink
B14: PostApplicantReferenceNote | C14: 0.1 | D14: This method is used to add notes to the applicant assessment. The note field supports free text and can be used to record additional data. | E14: ​/api​/workflow​/StandardIntegration​/PostApplicantReferenceNote
B15: AddApplicantToTenancy | C15: 0.1 | D15: This method is used to add an additional applicant to a tenancy application. It has a applicant type parameter that denotes whether the applicant will be sent a link to fill out the data themselves or that the data will be provided by the client system. | E15: ​/api​/workflow​/StandardIntegration​/AddApplicantToTenancy
... B23: GetApplicantNotes | C23: 0.1 | D23: Used to retrieve notes attached to applicant, by applicant ID | E23: ​/api​/workflow​/StandardIntegration​/GetApplicantNotes

Sheet Entity Relationship Model
A1: Entity Relationship Model

Sheet API Data Dictionary
H1: Methods Used
H2: CheckConnection | J2: CreateReferenceWithAllData | L2: CreateReferenceWithInputFromApplicant | N2: GetApplicantReferenceStatus | P2: GetAgentActiveProducts | R2: GetApplicantReferenceReports | T2: PostApplicantReferenceDocument | V2: ResendApplicantReferenceLink | X2: PostApplicantReferenceNote | Z2: AddApplicantToTenancy | AB2: AmendApplicantType | AD2: CancelApplicantFromTenancy | AF2: CancelTenancy | AH2: AmendTenancyDetails | AJ2: AmendApplicantProductType | AL2: CreateCompanyReferenceWithAllData | AN2: CreateCompanyReferenceWithInputFromApplicant
A3: ID | C3: Vision+ API Field Name | D3: Field Type | E3: API Max Field Length | F3: Field Validations | G3: Field Description | H3: Request | I3: Response | J3: Request | K3: Response | L3: Request | M3: Response | N3: Request | O3: Response | P3: Request | Q3: Response | R3: Request | S3: Response | T3: Request | U3: Response | V3: Request | W3: Response | X3: Request | Y3: Response | Z3: Request | AA3: Response | AB3: Request | AC3: Response | AD3: Request | AE3: Response | AF3: Request | AG3: Response | AH3: Request | AI3: Response | AJ3: Request | AK3: Response | AL3: Request | AM3: Response | AN3: Request | AO3: Response
A4: Agent and Tenancy Data
A5: 1 | B5: Agent and Tenancy Data | C5: tenancyID | D5: string | E5: 50 | G5: TenancyID is a unique key value for an Agent Property with Active referencing requests linked to one or more Applicants. An Agent Property may have one or more TenancyID's with simultaneous Applicant reference requests. TenancyID is created through API methods: CreateReferenceWithAllData CreateReferenceWithInputFromApplicant CreateCompanyReferenceWithAllData CreateCompanyReferenceWithInputFromApplicant | K5: X | M5: X | AM5: X
A6: 2 | C6: applicantID | D6: integer | G6: ApplicantID is a unique identifier for a person / Company to be referenced. ApplicantID is created through API Methods: CreateReferenceWithAllData CreateReferenceWithInputFromApplicant CreateCompanyReferenceWithAllData CreateCompanyReferenceWithInputFromApplicant AddApplicantToTenancy | K6: X | M6: X | N6: M | O6: X | R6: M | T6: M | V6: M | X6: M | AM6: X
A7: 3 | C7: agentCode | D7: string | E7: 50 | G7: AgentCode is the Unique Key provided to the Agent when onboarding as a Barbon Customer. An AgentID may be linked to many Properties being managed by that Agent and Each property may be linked to 1 or more TenancyID's. | J7: M | K7: X | L7: M | P7: M | Q7: X | AL7: M | AM7: X
A8: 4 | C8: Product | D8: string | E8: 200 | G8: Product is a return value for Product description for product(s) available and enabled for the API Authenticated Agent. This includes Referencing Products (Ultimate, Express etc..) and Other services such as Insurance products (Rent on Time, Rent Guarantee etc…) and Media and Utilities. | Q8: X | AL8: M
A9: 5 | C9: rentGuarantee | D9: enum - Rent Guarantee | F9: Valid Values 1-4 (See enum definition) | G9: Rent guarantee is an indicator that determines which RG option if any the agent requires | J9: M | L9: M | AL9: M
A10: 6 | C10: tenancyTermMonths | D10: integer | G10: The term of the Tenancy in months (whole months only) | J10: M | L10: M | AL10: M
A11: 7 | C11: monthlyRental | D11: number (double) | F11: number($double) pattern: ^\d*.\d{0,2}$ | G11: The monthly rental cost | J11: M | L11: M | AL11: M
A12: 8 | C12: lettingType | D12: enum - Letting Type | F12: Valid Values 1-3 (See enum definition) | G12: The type of the letting, i.e. rent only or fully managed | J12: M | L12: M | AL12: M
A13: 9 | C13: estimatedMoveInDate | D13: string ($date-time) | F13: DD/MM/YYYY | G13: Estimated date of tenancy start (move in) | J13: M | L13: M | AL13: M
A14: 10 | C14: propertyType | D14: enum - Property Type | F14: Valid Values 1-6 (See enum definition) | G14: The Type of property | J14: M | L14: M | AL14: X
A15: 11 | C15: propertyConstructionPeriod | D15: enum - Property Construction Period | F15: Valid Values 1-9 (See enum definition) | G15: The time period in which the property was built | J15: X | L15: X | AL15: X
A16: 12 | C16: numberOfBedrooms | D16: integer | G16: The count of bedrooms in the property | J16: X | L16: X | AL16: X
A17: 13 | C17: noOfAdultOccupants | D17: integer | G17: Number of Adult occupants (18 or over) | J17: X | L17: X | AL17: X
A18: 14 | C18: noOfChildOccupants | D18: integer | G18: Number of Child Occupants (under 18) | J18: X | L18: X | AL18: X
A19: 15 | B19: Tenancy Address | C19: houseNumber | D19: string | E19: 100 | G19: The number of the property, mandatory OR pair with House name field | J19: X | L19: X | AL19: X
A20: 16 | C20: houseName | D20: string | E20: 100 | G20: The name of the property, mandatory OR pair with House number field | J20: X | L20: X | AL20: M
A21: 17 | C21: addressLine1 | D21: string | E21: 100 | G21: The first line of the property address | J21: M | L21: M | AL21: M
A22: 18 | C22: addressLine2 | D22: string | E22: 100 | G22: The second line of the property address | J22: X | L22: X | AL22: X
A23: 19 | C23: town | D23: string | E23: 50 | G23: The town in which the property exists | J23: M | L23: M | AL23: M
A24: 20 | C24: postcode | D24: string | E24: 50 | G24: the postcode of the property | J24: M | L24: M | AL24: M
A25: 21 | C25: ukCountryCode | D25: enum - UK Country List | F25: Valid Values 1-4 (See enum definition) | G25: The UK country Code | J25: M | L25: M | AL25: M
A26: Applicant Data (Tenant / Guarantor)
A27: 22 | B27: Tenant Name and Contact Data | C27: ApplicantStatus | D27: enum - Applicant Status | G27: A return value for the tenant's status (using method GetApplicantReferenceStatus) | O27: X
A28: 23 | C28: OutcomeStatus | D28: enum - outcome | G28: A return value for the reference grading status (using method GetApplicantReferenceStatus) | O28: X
A29: 24 | C29: tenantTypeId | D29: enum - Tenant Type | F29: Valid Values 1-4 (See enum definition) | G29: The Type of the Tenant, e.g. lead or Guarantor | J29: M | L29: M | AL29: M
A30: 25 | C30: referenceType | D30: enum - Reference Type | F30: Valid Values 1-2 (See enum definition) | G30: The Type of reference, e.g Full or Express | J30: M | L30: M | AL30: M
A31: 26 | C31: rightToRent | D31: boolean | G31: Use Right to rent product for this reference | J31: M | L31: M | AL31: M
A32: 27 | C32: title | D32: enum - Title | F32: Valid Values 1-7 (See enum definition) | G32: The persons title, e.g. Mr, Mrs, etc. | J32: M | L32: M
A33: 28 | C33: otherTitle | D33: string | E33: 100 | G33: If other is chosen for title, this is a text field to enter the specific title | J33: X | L33: X
A34: 29 | C34: firstName | D34: string | E34: 100 | F34: pattern: ^[a-zA-Z0-9\-' ]*$ | G34: First name, validated against the RegEx pattern | J34: M | L34: M
A35: 30 | C35: middleName | D35: string | E35: 50 | F35: pattern: ^[a-zA-Z0-9\-' ]*$ | G35: Middle name, validated against the RegEx pattern | J35: X | L35: X
A36: 31 | C36: surname | D36: string | E36: 100 | F36: pattern: ^[a-zA-Z0-9\-' ]*$ | G36: Surname name, validated against the RegEx pattern | J36: M | L36: M
A37: 32 | C37: shareOfRent | D37: number (double) | F37: pattern: ^\d*.\d{0,2}$ | G37: GBP value of the applicants share of the rent | J37: M | L37: M | AL37: M
A38: 33 | C38: dateOfBirth | D38: string ($date-time) | F38: DD/MM/YYYY | G38: The date of birth, formatted DD-MM-YYYY | J38: M
A39: 34 | C39: companyName | D39: string | E39: 100 | G39: Name of the company | J39: X | AL39: M
A40: 35 | C40: companyRegistrationNumber | D40: string | E40: 100 | G40: Registration number of the company | J40: X | AL40: M
...

Sheet Enum Short Lists
B3: Enum Field | C3: RentGuarantee
B4: Description | C4: Rent guarantee is a product option in Vision+ that provides a guaranteed payment of rent. The options for the rent guarantee are in the table
B5: Value ID | C5: Value Name | D5: Value Description
B6: 1 | C6: Yes, Annual
B7: 2 | C7: Yes, Monthly
B8: 3 | C8: Tenant Evict Only
B9: 4 | C9: No
B12: Enum Field | C12: Title
B13: Description | C13: This is the name prefix for the tenant. If Other is chosen, a free text field is required to be filled in
B14: Value ID | C14: Value Name | D14: Value Description
B15: 1 | C15: Mr
B16: 2 | C16: Mrs
B17: 3 | C17: Miss
B18: 4 | C18: Dr
B19: 5 | C19: Ms
B20: 6 | C20: Other | D20: Free text field become mandatory
B21: 7 | C21: Mx
B24: Enum Field | C24: PropertyConstructionPeriod
B25: Description | C25: This is a range of years denoting the period in which the property was built
B26: Value ID | C26: Value Name | D26: Value Description
B27: 1 | C27: Pre 1850
B28: 2 | C28: 1850 – 1899
B29: 3 | C29: 1900 – 1919
B30: 4 | C30: 1920 – 1945
B31: 5 | C31: 1946 – 1979
B32: 6 | C32: 1980 – 1990
B33: 7 | C33: 1991 – 2000
B34: 8 | C34: 2001 – 2010
B35: 9 | C35: 2011 +
B38: Enum Field | C38: Name Type
B39: Description | C39: Other name that the tenant has been known by
B40: Value ID | C40: Value Name | D40: Value Description
B41: 1 | C41: Other Name
B42: 2 | C42: Another Name
B45: Enum Field | C45: monthMovedIn
B46: Description | C46: The standard month options
B47: Value ID | C47: Value Name | D47: Value Description
B48: 1 | C48: January
B49: 2 | C49: February
B50: 3 | C50: March
...

Sheet Enum Countries
B2: Enum Field | C2: Country/Location Code
B3: Description | C3: The country or location - NB. includes legacy options Fields mapped to this enum list include: telephoneCountryID mobileCountryId country landlordContactCountryId landlordMobileCountryId countryOfEmployment employmentRefereeContactCountryID employmentRefereeMobileCountryID accountantContactNoCountryId accountantMobileNoCountryId
B4: Value ID | C4: Value Name | D4: Value Description
B5: 1 | C5: Cyprus
B6: 2 | C6: United Kingdom
B7: 3 | C7: India
B8: 4 | C8: USA
B9: 5 | C9: Andorra
B10: 6 | C10: United Arab Emirates
B11: 7 | C11: Afghanistan
B12: 8 | C12: Antigua and Barbuda
B13: 9 | C13: Anguilla
B14: 10 | C14: Albania
B15: 11 | C15: Armenia
B16: 12 | C16: Netherlands Antilles
... B239: 240 | C239: Serbia

Sheet Enum Nationalities
B2: Enum Field | C2: nationality
B3: Description | C3: The country or location - NB includes legacy options
B4: Value ID | C4: Value Name | D4: Value Description
B5: 1 | C5: Afghan
B6: 2 | C6: Albanian
B7: 3 | C7: Algerian
B8: 4 | C8: American
B9: 5 | C9: Andorran
B10: 6 | C10: Angolan
B11: 7 | C11: Anguillan
B12: 8 | C12: Citizen of Antigua and Barbuda
B13: 9 | C13: Argentine
B14: 10 | C14: Armenian
B15: 11 | C15: Australian
B16: 12 | C16: Austrian
... B235: 231 | C235: Zairian

Sheet CheckConnection
A1: GetApplicantReferenceStatus Example JSON | B1: Vision+ API Field Name | C1: Mandatory Field | D1: Field Type | E1: API Max Field Length | F1: Field Validations | G1: Field Description
A2: Request Example
A3: { | B3: =IF(OR(ISNUMBER(SEARCH("{", A3)),ISNUMBER(SEARCH("[", A3))), "", IFERROR(MID(A3, SEARCH("""", A3) +1, SEARCH("""", A3, SEARCH("""",A3) +1) - SEARCH("""", A3) -1), "")) | C3: =IF(B3="", "", VLOOKUP(B3,'API Data Dictionary'!C:N,12,FALSE)) | D3: =IF(B3="", "", VLOOKUP(B3,'API Data Dictionary'!C:D,2,FALSE)) | E3: =IF(IF(B3="", "", VLOOKUP(B3,'API Data Dictionary'!C:E,3,FALSE))=0, "", IF(B3="", "", VLOOKUP(B3,'API Data Dictionary'!C:E,3,FALSE))) | F3: =IF(IF(B3="", "", VLOOKUP(B3,'API Data Dictionary'!C:F,4,FALSE))=0, "", IF(B3="", "", VLOOKUP(B3,'API Data Dictionary'!C:F,4,FALSE))) | G3: =IF(IF(B3="", "", VLOOKUP(B3,'API Data Dictionary'!C:G,5,FALSE))=0, "", IF(B3="", "", VLOOKUP(B3,'API Data Dictionary'!C:G,5,FALSE)))
A4: N/A - No parameters | B4: N/A | C4: N/A | D4: N/A | E4: N/A | F4: N/A | G4: N/A
A5: } | B5: =IF(OR(ISNUMBER(SEARCH("{", A5)),ISNUMBER(SEARCH("[", A5))), "", IFERROR(MID(A5, SEARCH("""", A5) +1, SEARCH("""", A5, SEARCH("""",A5) +1) - SEARCH("""", A5) -1), "")) | C5: =IF(B5="", "", VLOOKUP(B5,'API Data Dictionary'!C:N,12,FALSE)) | D5: =IF(B5="", "", VLOOKUP(B5,'API Data Dictionary'!C:D,2,FALSE)) | E5: =IF(IF(B5="", "", VLOOKUP(B5,'API Data Dictionary'!C:E,3,FALSE))=0, "", IF(B5="", "", VLOOKUP(B5,'API Data Dictionary'!C:E,3,FALSE))) | F5: =IF(IF(B5="", "", VLOOKUP(B5,'API Data Dictionary'!C:F,4,FALSE))=0, "", IF(B5="", "", VLOOKUP(B5,'API Data Dictionary'!C:F,4,FALSE))) | G5: =IF(IF(B5="", "", VLOOKUP(B5,'API Data Dictionary'!C:G,5,FALSE))=0, "", IF(B5="", "", VLOOKUP(B5,'API Data Dictionary'!C:G,5,FALSE)))
A7: Response Example: Success
A8: { | B8: =IF(OR(ISNUMBER(SEARCH("{", A8)),ISNUMBER(SEARCH("[", A8))), "", IFERROR(MID(A8, SEARCH("""", A8) +1, SEARCH("""", A8, SEARCH("""",A8) +1) - SEARCH("""", A8) -1), "")) | C8: =IF(B8="", "", VLOOKUP(B8,'API Data Dictionary'!C:N,12,FALSE)) | D8: =IF(B8="", "", VLOOKUP(B8,'API Data Dictionary'!C:D,2,FALSE)) | E8: =IF(IF(B8="", "", VLOOKUP(B8,'API Data Dictionary'!C:E,3,FALSE))=0, "", IF(B8="", "", VLOOKUP(B8,'API Data Dictionary'!C:E,3,FALSE))) | F8: =IF(IF(B8="", "", VLOOKUP(B8,'API Data Dictionary'!C:F,4,FALSE))=0, "", IF(B8="", "", VLOOKUP(B8,'API Data Dictionary'!C:F,4,FALSE))) | G8: =IF(IF(B8="", "", VLOOKUP(B8,'API Data Dictionary'!C:G,5,FALSE))=0, "", IF(B8="", "", VLOOKUP(B8,'API Data Dictionary'!C:G,5,FALSE)))
A9: "success": true, | B9: =IF(OR(ISNUMBER(SEARCH("{", A9)),ISNUMBER(SEARCH("[", A9))), "", IFERROR(MID(A9, SEARCH("""", A9) +1, SEARCH("""", A9, SEARCH("""",A9) +1) - SEARCH("""", A9) -1), "")) -> success | C9: M | D9: =IF(B9="", "", VLOOKUP(B9,'API Data Dictionary'!C:D,2,FALSE)) -> string - Boolean | E9: =IF(IF(B9="", "", VLOOKUP(B9,'API Data Dictionary'!C:E,3,FALSE))=0, "", IF(B9="", "", VLOOKUP(B9,'API Data Dictionary'!C:E,3,FALSE))) -> 100 | F9: =IF(IF(B9="", "", VLOOKUP(B9,'API Data Dictionary'!C:F,4,FALSE))=0, "", IF(B9="", "", VLOOKUP(B9,'API Data Dictionary'!C:F,4,FALSE))) | G9: =IF(IF(B9="", "", VLOOKUP(B9,'API Data Dictionary'!C:G,5,FALSE))=0, "", IF(B9="", "", VLOOKUP(B9,'API Data Dictionary'!C:G,5,FALSE))) -> Returns true when successful call/connection
A10: "payload": "Healthy", | B10: =IF(OR(ISNUMBER(SEARCH("{", A10)),ISNUMBER(SEARCH("[", A10))), "", IFERROR(MID(A10, SEARCH("""", A10) +1, SEARCH("""", A10, SEARCH("""",A10) +1) - SEARCH("""", A10) -1), "")) -> payload | C10: M | D10: =IF(B10="", "", VLOOKUP(B10,'API Data Dictionary'!C:D,2,FALSE)) -> string | E10: =IF(IF(B10="", "", VLOOKUP(B10,'API Data Dictionary'!C:E,3,FALSE))=0, "", IF(B10="", "", VLOOKUP(B10,'API Data Dictionary'!C:E,3,FALSE))) -> 100 | F10: =IF(IF(B10="", "", VLOOKUP(B10,'API Data Dictionary'!C:F,4,FALSE))=0, "", IF(B10="", "", VLOOKUP(B10,'API Data Dictionary'!C:F,4,FALSE))) | G10: =IF(IF(B10="", "", VLOOKUP(B10,'API Data Dictionary'!C:G,5,FALSE))=0, "", IF(B10="", "", VLOOKUP(B10,'API Data Dictionary'!C:G,5,FALSE))) -> Returns healthy when connection has worked properly
A11: "message": null | B11: =IF(OR(ISNUMBER(SEARCH("{", A11)),ISNUMBER(SEARCH("[", A11))), "", IFERROR(MID(A11, SEARCH("""", A11) +1, SEARCH("""", A11, SEARCH("""",A11) +1) - SEARCH("""", A11) -1), "")) -> message | C11: M | D11: =IF(B11="", "", VLOOKUP(B11,'API Data Dictionary'!C:D,2,FALSE)) -> string | E11: =IF(IF(B11="", "", VLOOKUP(B11,'API Data Dictionary'!C:E,3,FALSE))=0, "", IF(B11="", "", VLOOKUP(B11,'API Data Dictionary'!C:E,3,FALSE))) -> 100 | F11: =IF(IF(B11="", "", VLOOKUP(B11,'API Data Dictionary'!C:F,4,FALSE))=0, "", IF(B11="", "", VLOOKUP(B11,'API Data Dictionary'!C:F,4,FALSE))) | G11: =IF(IF(B11="", "", VLOOKUP(B11,'API Data Dictionary'!C:G,5,FALSE))=0, "", IF(B11="", "", VLOOKUP(B11,'API Data Dictionary'!C:G,5,FALSE))) -> return value, null or success, unless there has been error
A12: }
A14: Response Example: Fail - 401 Unauthorised Error
A15: 401 Error: Unauthorized | B15: N/A | C15: N/A | D15: string | E15: 100 | G15: Returns a 401 error if not authorised
A17: Response Example: Fail - 403 Forbidden
A18: 403 Error: Forbidden | B18: N/A | C18: N/A | D18: string | E18: 100 | G18: Returns a 403 error if foribidden
A20: Response Example: Fail - 500 internal Error (post validation)
A21: { | B21: =IF(OR(ISNUMBER(SEARCH("{", A21)),ISNUMBER(SEARCH("[", A21))), "", IFERROR(MID(A21, SEARCH("""", A21) +1, SEARCH("""", A21, SEARCH("""",A21) +1) - SEARCH("""", A21) -1), "")) | C21: =IF(B21="", "", VLOOKUP(B21,'API Data Dictionary'!C:J,8,FALSE)) | D21: =IF(B21="", "", VLOOKUP(B21,'API Data Dictionary'!C:D,2,FALSE)) | E21: =IF(IF(B21="", "", VLOOKUP(B21,'API Data Dictionary'!C:E,3,FALSE))=0, "", IF(B21="", "", VLOOKUP(B21,'API Data Dictionary'!C:E,3,FALSE))) | F21: =IF(IF(B21="", "", VLOOKUP(B21,'API Data Dictionary'!C:F,4,FALSE))=0, "", IF(B21="", "", VLOOKUP(B21,'API Data Dictionary'!C:F,4,FALSE))) | G21: =IF(IF(B21="", "", VLOOKUP(B21,'API Data Dictionary'!C:G,5,FALSE))=0, "", IF(B21="", "", VLOOKUP(B21,'API Data Dictionary'!C:G,5,FALSE)))
A22: "success": false, | B22: =IF(OR(ISNUMBER(SEARCH("{", A22)),ISNUMBER(SEARCH("[", A22))), "", IFERROR(MID(A22, SEARCH("""", A22) +1, SEARCH("""", A22, SEARCH("""",A22) +1) - SEARCH("""", A22) -1), "")) -> success | C22: M | D22: =IF(B22="", "", VLOOKUP(B22,'API Data Dictionary'!C:D,2,FALSE)) -> string - Boolean | E22: =IF(IF(B22="", "", VLOOKUP(B22,'API Data Dictionary'!C:E,3,FALSE))=0, "", IF(B22="", "", VLOOKUP(B22,'API Data Dictionary'!C:E,3,FALSE))) -> 100 | F22: =IF(IF(B22="", "", VLOOKUP(B22,'API Data Dictionary'!C:F,4,FALSE))=0, "", IF(B22="", "", VLOOKUP(B22,'API Data Dictionary'!C:F,4,FALSE))) | G22: =IF(IF(B22="", "", VLOOKUP(B22,'API Data Dictionary'!C:G,5,FALSE))=0, "", IF(B22="", "", VLOOKUP(B22,'API Data Dictionary'!C:G,5,FALSE))) -> Returns true when successful call/connection
A23: "payload": null | B23: =IF(OR(ISNUMBER(SEARCH("{", A23)),ISNUMBER(SEARCH("[", A23))), "", IFERROR(MID(A23, SEARCH("""", A23) +1, SEARCH("""", A23, SEARCH("""",A23) +1) - SEARCH("""", A23) -1), "")) -> payload | C23: M | D23: =IF(B23="", "", VLOOKUP(B23,'API Data Dictionary'!C:D,2,FALSE)) -> string | E23: =IF(IF(B23="", "", VLOOKUP(B23,'API Data Dictionary'!C:E,3,FALSE))=0, "", IF(B23="", "", VLOOKUP(B23,'API Data Dictionary'!C:E,3,FALSE))) -> 100 | F23: =IF(IF(B23="", "", VLOOKUP(B23,'API Data Dictionary'!C:F,4,FALSE))=0, "", IF(B23="", "", VLOOKUP(B23,'API Data Dictionary'!C:F,4,FALSE))) | G23: =IF(IF(B23="", "", VLOOKUP(B23,'API Data Dictionary'!C:G,5,FALSE))=0, "", IF(B23="", "", VLOOKUP(B23,'API Data Dictionary'!C:G,5,FALSE))) -> Returns healthy when connection has worked properly
A24: "message": "Internal error" | B24: =IF(OR(ISNUMBER(SEARCH("{", A24)),ISNUMBER(SEARCH("[", A24))), "", IFERROR(MID(A24, SEARCH("""", A24) +1, SEARCH("""", A24, SEARCH("""",A24) +1) - SEARCH("""", A24) -1), "")) -> message | C24: M | D24: =IF(B24="", "", VLOOKUP(B24,'API Data Dictionary'!C:D,2,FALSE)) -> string | E24: =IF(IF(B24="", "", VLOOKUP(B24,'API Data Dictionary'!C:E,3,FALSE))=0, "", IF(B24="", "", VLOOKUP(B24,'API Data Dictionary'!C:E,3,FALSE))) -> 100 | F24: =IF(IF(B24="", "", VLOOKUP(B24,'API Data Dictionary'!C:F,4,FALSE))=0, "", IF(B24="", "", VLOOKUP(B24,'API Data Dictionary'!C:F,4,FALSE))) | G24: =IF(IF(B24="", "", VLOOKUP(B24,'API Data Dictionary'!C:G,5,FALSE))=0, "", IF(B24="", "", VLOOKUP(B24,'API Data Dictionary'!C:G,5,FALSE))) -> return value, null or success, unless there has been error
A25: } | B25: =IF(OR(ISNUMBER(SEARCH("{", A25)),ISNUMBER(SEARCH("[", A25))), "", IFERROR(MID(A25, SEARCH("""", A25) +1, SEARCH("""", A25, SEARCH("""",A25) +1) - SEARCH("""", A25) -1), "")) | C25: =IF(B25="", "", VLOOKUP(B25,'API Data Dictionary'!C:J,8,FALSE)) | D25: =IF(B25="", "", VLOOKUP(B25,'API Data Dictionary'!C:D,2,FALSE)) | E25: =IF(IF(B25="", "", VLOOKUP(B25,'API Data Dictionary'!C:E,3,FALSE))=0, "", IF(B25="", "", VLOOKUP(B25,'API Data Dictionary'!C:E,3,FALSE))) | F25: =IF(IF(B25="", "", VLOOKUP(B25,'API Data Dictionary'!C:F,4,FALSE))=0, "", IF(B25="", "", VLOOKUP(B25,'API Data Dictionary'!C:F,4,FALSE))) | G25: =IF(IF(B25="", "", VLOOKUP(B25,'API Data Dictionary'!C:G,5,FALSE))=0, "", IF(B25="", "", VLOOKUP(B25,'API Data Dictionary'!C:G,5,FALSE)))

Sheet GetAuthenticationToken
A1: GetApplicantReferenceStatus Example JSON | B1: Vision+ API Field Name | C1: Mandatory Field | D1: Field Type | E1: API Max Field Length | F1: Field Validations | G1: Field Description
A2: Request Example
A3: { | B3: =IF(OR(ISNUMBER(SEARCH("{", A3)),ISNUMBER(SEARCH("[", A3))), "", IFERROR(MID(A3, SEARCH("""", A3) +1, SEARCH("""", A3, SEARCH("""",A3) +1) - SEARCH("""", A3) -1), "")) | C3: =IF(B3="", "", VLOOKUP(B3,'API Data Dictionary'!C:N,12,FALSE)) | D3: =IF(B3="", "", VLOOKUP(B3,'API Data Dictionary'!C:D,2,FALSE)) | E3: =IF(IF(B3="", "", VLOOKUP(B3,'API Data Dictionary'!C:E,3,FALSE))=0, "", IF(B3="", "", VLOOKUP(B3,'API Data Dictionary'!C:E,3,FALSE))) | F3: =IF(IF(B3="", "", VLOOKUP(B3,'API Data Dictionary'!C:F,4,FALSE))=0, "", IF(B3="", "", VLOOKUP(B3,'API Data Dictionary'!C:F,4,FALSE))) | G3: =IF(IF(B3="", "", VLOOKUP(B3,'API Data Dictionary'!C:G,5,FALSE))=0, "", IF(B3="", "", VLOOKUP(B3,'API Data Dictionary'!C:G,5,FALSE)))
A4: "scope": "standardapiaccess", | B4: =IF(OR(ISNUMBER(SEARCH("{", A4)),ISNUMBER(SEARCH("[", A4))), "", IFERROR(MID(A4, SEARCH("""", A4) +1, SEARCH("""", A4, SEARCH("""",A4) +1) - SEARCH("""", A4) -1), "")) -> scope | C4: M | D4: =IF(B4="", "", VLOOKUP(B4,'API Data Dictionary'!C:D,2,FALSE)) -> string - constant | E4: =IF(IF(B4="", "", VLOOKUP(B4,'API Data Dictionary'!C:E,3,FALSE))=0, "", IF(B4="", "", VLOOKUP(B4,'API Data Dictionary'!C:E,3,FALSE))) -> 100 | F4: =IF(IF(B4="", "", VLOOKUP(B4,'API Data Dictionary'!C:F,4,FALSE))=0, "", IF(B4="", "", VLOOKUP(B4,'API Data Dictionary'!C:F,4,FALSE))) | G4: =IF(IF(B4="", "", VLOOKUP(B4,'API Data Dictionary'!C:G,5,FALSE))=0, "", IF(B4="", "", VLOOKUP(B4,'API Data Dictionary'!C:G,5,FALSE))) -> Scope of the API Authentication, must always be: "standardapiaccess"
A5: "client_id": "1234-clientID", | B5: =IF(OR(ISNUMBER(SEARCH("{", A5)),ISNUMBER(SEARCH("[", A5))), "", IFERROR(MID(A5, SEARCH("""", A5) +1, SEARCH("""", A5, SEARCH("""",A5) +1) - SEARCH("""", A5) -1), "")) -> client_id | C5: M | D5: =IF(B5="", "", VLOOKUP(B5,'API Data Dictionary'!C:D,2,FALSE)) -> string | E5: =IF(IF(B5="", "", VLOOKUP(B5,'API Data Dictionary'!C:E,3,FALSE))=0, "", IF(B5="", "", VLOOKUP(B5,'API Data Dictionary'!C:E,3,FALSE))) -> 100 | F5: =IF(IF(B5="", "", VLOOKUP(B5,'API Data Dictionary'!C:F,4,FALSE))=0, "", IF(B5="", "", VLOOKUP(B5,'API Data Dictionary'!C:F,4,FALSE))) | G5: =IF(IF(B5="", "", VLOOKUP(B5,'API Data Dictionary'!C:G,5,FALSE))=0, "", IF(B5="", "", VLOOKUP(B5,'API Data Dictionary'!C:G,5,FALSE))) -> Client ID Authentication credentials provided to you on customer setup
A6: "client_secret": "xxxxxxxxxxxxxxxxxxx" | B6: =IF(OR(ISNUMBER(SEARCH("{", A6)),ISNUMBER(SEARCH("[", A6))), "", IFERROR(MID(A6, SEARCH("""", A6) +1, SEARCH("""", A6, SEARCH("""",A6) +1) - SEARCH("""", A6) -1), "")) -> client_secret | C6: M | D6: =IF(B6="", "", VLOOKUP(B6,'API Data Dictionary'!C:D,2,FALSE)) -> string | E6: =IF(IF(B6="", "", VLOOKUP(B6,'API Data Dictionary'!C:E,3,FALSE))=0, "", IF(B6="", "", VLOOKUP(B6,'API Data Dictionary'!C:E,3,FALSE))) -> 100 | F6: =IF(IF(B6="", "", VLOOKUP(B6,'API Data Dictionary'!C:F,4,FALSE))=0, "", IF(B6="", "", VLOOKUP(B6,'API Data Dictionary'!C:F,4,FALSE))) | G6: =IF(IF(B6="", "", VLOOKUP(B6,'API Data Dictionary'!C:G,5,FALSE))=0, "", IF(B6="", "", VLOOKUP(B6,'API Data Dictionary'!C:G,5,FALSE))) -> Client Secret Authentication credentials provided to you on customer setup
A7: } | B7: =IF(OR(ISNUMBER(SEARCH("{", A7)),ISNUMBER(SEARCH("[", A7))), "", IFERROR(MID(A7, SEARCH("""", A7) +1, SEARCH("""", A7, SEARCH("""",A7) +1) - SEARCH("""", A7) -1), "")) | C7: =IF(B7="", "", VLOOKUP(B7,'API Data Dictionary'!C:N,12,FALSE)) | D7: =IF(B7="", "", VLOOKUP(B7,'API Data Dictionary'!C:D,2,FALSE)) | E7: =IF(IF(B7="", "", VLOOKUP(B7,'API Data Dictionary'!C:E,3,FALSE))=0, "", IF(B7="", "", VLOOKUP(B7,'API Data Dictionary'!C:E,3,FALSE))) | F7: =IF(IF(B7="", "", VLOOKUP(B7,'API Data Dictionary'!C:F,4,FALSE))=0, "", IF(B7="", "", VLOOKUP(B7,'API Data Dictionary'!C:F,4,FALSE))) | G7: =IF(IF(B7="", "", VLOOKUP(B7,'API Data Dictionary'!C:G,5,FALSE))=0, "", IF(B7="", "", VLOOKUP(B7,'API Data Dictionary'!C:G,5,FALSE)))
A9: Response Example: Success - 200
A10: { | B10: =IF(OR(ISNUMBER(SEARCH("{", A10)),ISNUMBER(SEARCH("[", A10))), "", IFERROR(MID(A10, SEARCH("""", A10) +1, SEARCH("""", A10, SEARCH("""",A10) +1) - SEARCH("""", A10) -1), "")) | C10: =IF(B10="", "", VLOOKUP(B10,'API Data Dictionary'!C:N,12,FALSE)) | D10: =IF(B10="", "", VLOOKUP(B10,'API Data Dictionary'!C:D,2,FALSE)) | E10: =IF(IF(B10="", "", VLOOKUP(B10,'API Data Dictionary'!C:E,3,FALSE))=0, "", IF(B10="", "", VLOOKUP(B10,'API Data Dictionary'!C:E,3,FALSE))) | F10: =IF(IF(B10="", "", VLOOKUP(B10,'API Data Dictionary'!C:F,4,FALSE))=0, "", IF(B10="", "", VLOOKUP(B10,'API Data Dictionary'!C:F,4,FALSE))) | G10: =IF(IF(B10="", "", VLOOKUP(B10,'API Data Dictionary'!C:G,5,FALSE))=0, "", IF(B10="", "", VLOOKUP(B10,'API Data Dictionary'!C:G,5,FALSE)))
A11: eyJhbGciOiJSUzI1NiIsImtpZCI6IjIzNDBFOTVDMDU1M0VGNUM1Mzc0ODNBMjUyMTU1RTkyRDFGRTM3MThSUzI1NiIsInR5cCI6ImF0K2p3dCIsIng1dCI6IkkwRHBYQVZUNzF4VGRJT2lVaFZla3RILU54ZyJ9.eyJuYmYiOjE2ODU5NjExMDcsImV4cCI6MTY4NjA0NzUwNywiaXNzIjoiaHR0cHM6Ly9wcmVwcm9kLWF1dGgtc2VydmljZS5iYXJib25kZXYuY28udWsiLCJjbGllbnRfaWQiOiI0NDQyNDFfRm94dG9ucy1XZW1ibGV5IiwianRpIjoiREIwRjhGMkQwOEUyQzEwNDBCMjA1N0Y0ODg1NkRGNDciLCJpYXQiOjE2ODU5NjExMDcsInNjb3BlIjpbInN0YW5kYXJkYXBpYWNjZXNzIl19.z9phqgSvjwsbU2LeZMFmJvnDQ5fTIdhOyPZzLxJY59uJmE8ALZNEFjIrJFpQwIeBuuw8uHY8BS8czxZpW7AZtBps-Lh0qEW4GRXANWJi0rmU-Z1eEuqbmbF1z-9MSILP-OcyZeVPac8LleTh5gfHK0ycD6ioY3f-ZlsGQu7DqE7g68xMZ3UpbN617T8X93fDT67enC67m39B1-b3XrVFcIcROvIoqYQS4o8qexqLCBSgGHM726HlNWwtfSBe7gcRBU5Seij_GjtwQB9HcZf_Jwu3loElI7joJkycc2AxxyxitBrU1FFe9ZnGBAwmxY4Hiam5PsXWhR-qO1kh3M0c2Q | B11: Bearer Token | C11: M | D11: string | E11: 1000 | G11: Returned bearer authentication Token, to be used as "bearer XYZ" where XYZ is the token. Note Microsoft .NET6 systems (or others that stringify JSON responses) are required to Trim the bearer token of double quotes, e.g. client.DefaultRequestHeaders.Authorization = new AuthenticationHeaderValue("Bearer", token.Trim('"'));
A12: } | B12: =IF(OR(ISNUMBER(SEARCH("{", A12)),ISNUMBER(SEARCH("[", A12))), "", IFERROR(MID(A12, SEARCH("""", A12) +1, SEARCH("""", A12, SEARCH("""",A12) +1) - SEARCH("""", A12) -1), "")) | C12: =IF(B12="", "", VLOOKUP(B12,'API Data Dictionary'!C:N,12,FALSE)) | D12: =IF(B12="", "", VLOOKUP(B12,'API Data Dictionary'!C:D,2,FALSE)) | E12: =IF(IF(B12="", "", VLOOKUP(B12,'API Data Dictionary'!C:E,3,FALSE))=0, "", IF(B12="", "", VLOOKUP(B12,'API Data Dictionary'!C:E,3,FALSE))) | F12: =IF(IF(B12="", "", VLOOKUP(B12,'API Data Dictionary'!C:F,4,FALSE))=0, "", IF(B12="", "", VLOOKUP(B12,'API Data Dictionary'!C:F,4,FALSE))) | G12: =IF(IF(B12="", "", VLOOKUP(B12,'API Data Dictionary'!C:G,5,FALSE))=0, "", IF(B12="", "", VLOOKUP(B12,'API Data Dictionary'!C:G,5,FALSE)))
A14: Response Example: Fail - 401 Client Credentials Error
A15: invalid_client | B15: N/A | C15: N/A | D15: string | E15: 100 | G15: Invalid client will be returned if there are any issues with the combination of client_id and client_secret.
A17: Response Example: Fail - 401 Invalid Scope Error
A18: invalid_scope | B18: N/A | C18: N/A | D18: string | E18: 100 | G18: Invalid scope will be returned if there are any issues with the scope - Should always be "standardapiaccess"
A20: Response Example: Fail - 403 Forbidden
A21: 403 Error: Forbidden | B21: N/A | C21: N/A | D21: string | E21: 100 | G21: Returns a 403 error if foribidden
A23: Response Example: Fail - 500 internal Error (post validation)
A24: { | B24: =IF(OR(ISNUMBER(SEARCH("{", A24)),ISNUMBER(SEARCH("[", A24))), "", IFERROR(MID(A24, SEARCH("""", A24) +1, SEARCH("""", A24, SEARCH("""",A24) +1) - SEARCH("""", A24) -1), "")) | C24: =IF(B24="", "", VLOOKUP(B24,'API Data Dictionary'!C:J,8,FALSE)) | D24: =IF(B24="", "", VLOOKUP(B24,'API Data Dictionary'!C:D,2,FALSE)) | E24: =IF(IF(B24="", "", VLOOKUP(B24,'API Data Dictionary'!C:E,3,FALSE))=0, "", IF(B24="", "", VLOOKUP(B24,'API Data Dictionary'!C:E,3,FALSE))) | F24: =IF(IF(B24="", "", VLOOKUP(B24,'API Data Dictionary'!C:F,4,FALSE))=0, "", IF(B24="", "", VLOOKUP(B24,'API Data Dictionary'!C:F,4,FALSE))) | G24: =IF(IF(B24="", "", VLOOKUP(B24,'API Data Dictionary'!C:G,5,FALSE))=0, "", IF(B24="", "", VLOOKUP(B24,'API Data Dictionary'!C:G,5,FALSE)))
A25: "success": false, | B25: =IF(OR(ISNUMBER(SEARCH("{", A25)),ISNUMBER(SEARCH("[", A25))), "", IFERROR(MID(A25, SEARCH("""", A25) +1, SEARCH("""", A25, SEARCH("""",A25) +1) - SEARCH("""", A25) -1), "")) -> success | C25: M | D25: =IF(B25="", "", VLOOKUP(B25,'API Data Dictionary'!C:D,2,FALSE)) -> string - Boolean | E25: =IF(IF(B25="", "", VLOOKUP(B25,'API Data Dictionary'!C:E,3,FALSE))=0, "", IF(B25="", "", VLOOKUP(B25,'API Data Dictionary'!C:E,3,FALSE))) -> 100 | F25: =IF(IF(B25="", "", VLOOKUP(B25,'API Data Dictionary'!C:F,4,FALSE))=0, "", IF(B25="", "", VLOOKUP(B25,'API Data Dictionary'!C:F,4,FALSE))) | G25: =IF(IF(B25="", "", VLOOKUP(B25,'API Data Dictionary'!C:G,5,FALSE))=0, "", IF(B25="", "", VLOOKUP(B25,'API Data Dictionary'!C:G,5,FALSE))) -> Returns true when successful call/connection
A26: "payload": null | B26: =IF(OR(ISNUMBER(SEARCH("{", A26)),ISNUMBER(SEARCH("[", A26))), "", IFERROR(MID(A26, SEARCH("""", A26) +1, SEARCH("""", A26, SEARCH("""",A26) +1) - SEARCH("""", A26) -1), "")) -> payload | C26: M | D26: =IF(B26="", "", VLOOKUP(B26,'API Data Dictionary'!C:D,2,FALSE)) -> string | E26: =IF(IF(B26="", "", VLOOKUP(B26,'API Data Dictionary'!C:E,3,FALSE))=0, "", IF(B26="", "", VLOOKUP(B26,'API Data Dictionary'!C:E,3,FALSE))) -> 100 | F26: =IF(IF(B26="", "", VLOOKUP(B26,'API Data Dictionary'!C:F,4,FALSE))=0, "", IF(B26="", "", VLOOKUP(B26,'API Data Dictionary'!C:F,4,FALSE))) | G26: =IF(IF(B26="", "", VLOOKUP(B26,'API Data Dictionary'!C:G,5,FALSE))=0, "", IF(B26="", "", VLOOKUP(B26,'API Data Dictionary'!C:G,5,FALSE))) -> Returns healthy when connection has worked properly
A27: "message": "Internal error" | B27: =IF(OR(ISNUMBER(SEARCH("{", A27)),ISNUMBER(SEARCH("[", A27))), "", IFERROR(MID(A27, SEARCH("""", A27) +1, SEARCH("""", A27, SEARCH("""",A27) +1) - SEARCH("""", A27) -1), "")) -> message | C27: M | D27: =IF(B27="", "", VLOOKUP(B27,'API Data Dictionary'!C:D,2,FALSE)) -> string | E27: =IF(IF(B27="", "", VLOOKUP(B27,'API Data Dictionary'!C:E,3,FALSE))=0, "", IF(B27="", "", VLOOKUP(B27,'API Data Dictionary'!C:E,3,FALSE))) -> 100 | F27: =IF(IF(B27="", "", VLOOKUP(B27,'API Data Dictionary'!C:F,4,FALSE))=0, "", IF(B27="", "", VLOOKUP(B27,'API Data Dictionary'!C:F,4,FALSE))) | G27: =IF(IF(B27="", "", VLOOKUP(B27,'API Data Dictionary'!C:G,5,FALSE))=0, "", IF(B27="", "", VLOOKUP(B27,'API Data Dictionary'!C:G,5,FALSE))) -> return value, null or success, unless there has been error
A28: } | B28: =IF(OR(ISNUMBER(SEARCH("{", A28)),ISNUMBER(SEARCH("[", A28))), "", IFERROR(MID(A28, SEARCH("""", A28) +1, SEARCH("""", A28, SEARCH("""",A28) +1) - SEARCH("""", A28) -1), "")) | C28: =IF(B28="", "", VLOOKUP(B28,'API Data Dictionary'!C:J,8,FALSE)) | D28: =IF(B28="", "", VLOOKUP(B28,'API Data Dictionary'!C:D,2,FALSE)) | E28: =IF(IF(B28="", "", VLOOKUP(B28,'API Data Dictionary'!C:E,3,FALSE))=0, "", IF(B28="", "", VLOOKUP(B28,'API Data Dictionary'!C:E,3,FALSE))) | F28: =IF(IF(B28="", "", VLOOKUP(B28,'API Data Dictionary'!C:F,4,FALSE))=0, "", IF(B28="", "", VLOOKUP(B28,'API Data Dictionary'!C:F,4,FALSE))) | G28: =IF(IF(B28="", "", VLOOKUP(B28,'API Data Dictionary'!C:G,5,FALSE))=0, "", IF(B28="", "", VLOOKUP(B28,'API Data Dictionary'!C:G,5,FALSE)))

Sheet CreateReferenceWithAllData
A1: CreateReferenceWithAllData Example JSON | B1: Vision+ API Field Name | C1: Mandatory Field | D1: Field Type | E1: API Max Field Length | F1: Field Validations | G1: Field Description
A2: Request Example
A3: { | B3: =IF(OR(ISNUMBER(SEARCH("{", A3)),ISNUMBER(SEARCH("[", A3))), "", IFERROR(MID(A3, SEARCH("""", A3) +1, SEARCH("""", A3, SEARCH("""",A3) +1) - SEARCH("""", A3) -1), "")) | C3: =IF(B3="", "", VLOOKUP(B3,'API Data Dictionary'!C:J,8,FALSE)) | D3: =IF(B3="", "", VLOOKUP(B3,'API Data Dictionary'!C:D,2,FALSE)) | E3: =IF(IF(B3="", "", VLOOKUP(B3,'API Data Dictionary'!C:E,3,FALSE))=0, "", IF(B3="", "", VLOOKUP(B3,'API Data Dictionary'!C:E,3,FALSE))) | F3: =IF(IF(B3="", "", VLOOKUP(B3,'API Data Dictionary'!C:F,4,FALSE))=0, "", IF(B3="", "", VLOOKUP(B3,'API Data Dictionary'!C:F,4,FALSE))) | G3: =IF(IF(B3="", "", VLOOKUP(B3,'API Data Dictionary'!C:G,5,FALSE))=0, "", IF(B3="", "", VLOOKUP(B3,'API Data Dictionary'!C:G,5,FALSE)))
A4: "agentCode": "9999", | B4: =IF(OR(ISNUMBER(SEARCH("{", A4)),ISNUMBER(SEARCH("[", A4))), "", IFERROR(MID(A4, SEARCH("""", A4) +1, SEARCH("""", A4, SEARCH("""",A4) +1) - SEARCH("""", A4) -1), "")) -> agentCode | C4: =IF(B4="", "", VLOOKUP(B4,'API Data Dictionary'!C:J,8,FALSE)) -> M | D4: =IF(B4="", "", VLOOKUP(B4,'API Data Dictionary'!C:D,2,FALSE)) -> string | E4: =IF(IF(B4="", "", VLOOKUP(B4,'API Data Dictionary'!C:E,3,FALSE))=0, "", IF(B4="", "", VLOOKUP(B4,'API Data Dictionary'!C:E,3,FALSE))) -> 50 | F4: =IF(IF(B4="", "", VLOOKUP(B4,'API Data Dictionary'!C:F,4,FALSE))=0, "", IF(B4="", "", VLOOKUP(B4,'API Data Dictionary'!C:F,4,FALSE))) | G4: =IF(IF(B4="", "", VLOOKUP(B4,'API Data Dictionary'!C:G,5,FALSE))=0, "", IF(B4="", "", VLOOKUP(B4,'API Data Dictionary'!C:G,5,FALSE))) -> AgentCode is the Unique Key provided to the Agent when onboarding as a Barbon Customer. An AgentID may be linked to many Properties being managed by that Agent and Each property may be linked to 1 or more TenancyID's.
A5: "rentGuarantee": 1, | B5: =IF(OR(ISNUMBER(SEARCH("{", A5)),ISNUMBER(SEARCH("[", A5))), "", IFERROR(MID(A5, SEARCH("""", A5) +1, SEARCH("""", A5, SEARCH("""",A5) +1) - SEARCH("""", A5) -1), "")) -> rentGuarantee | C5: =IF(B5="", "", VLOOKUP(B5,'API Data Dictionary'!C:J,8,FALSE)) -> M | D5: =IF(B5="", "", VLOOKUP(B5,'API Data Dictionary'!C:D,2,FALSE)) -> enum - Rent Guarantee | E5: =IF(IF(B5="", "", VLOOKUP(B5,'API Data Dictionary'!C:E,3,FALSE))=0, "", IF(B5="", "", VLOOKUP(B5,'API Data Dictionary'!C:E,3,FALSE))) | F5: =IF(IF(B5="", "", VLOOKUP(B5,'API Data Dictionary'!C:F,4,FALSE))=0, "", IF(B5="", "", VLOOKUP(B5,'API Data Dictionary'!C:F,4,FALSE))) -> Valid Values 1-4 (See enum definition) | G5: =IF(IF(B5="", "", VLOOKUP(B5,'API Data Dictionary'!C:G,5,FALSE))=0, "", IF(B5="", "", VLOOKUP(B5,'API Data Dictionary'!C:G,5,FALSE))) -> Rent guarantee is an indicator that determines which RG option if any the agent requires
A6: "tenancyTermMonths": 12, | B6: =IF(OR(ISNUMBER(SEARCH("{", A6)),ISNUMBER(SEARCH("[", A6))), "", IFERROR(MID(A6, SEARCH("""", A6) +1, SEARCH("""", A6, SEARCH("""",A6) +1) - SEARCH("""", A6) -1), "")) -> tenancyTermMonths | C6: =IF(B6="", "", VLOOKUP(B6,'API Data Dictionary'!C:J,8,FALSE)) -> M | D6: =IF(B6="", "", VLOOKUP(B6,'API Data Dictionary'!C:D,2,FALSE)) -> integer | E6: =IF(IF(B6="", "", VLOOKUP(B6,'API Data Dictionary'!C:E,3,FALSE))=0, "", IF(B6="", "", VLOOKUP(B6,'API Data Dictionary'!C:E,3,FALSE))) | F6: =IF(IF(B6="", "", VLOOKUP(B6,'API Data Dictionary'!C:F,4,FALSE))=0, "", IF(B6="", "", VLOOKUP(B6,'API Data Dictionary'!C:F,4,FALSE))) | G6: =IF(IF(B6="", "", VLOOKUP(B6,'API Data Dictionary'!C:G,5,FALSE))=0, "", IF(B6="", "", VLOOKUP(B6,'API Data Dictionary'!C:G,5,FALSE))) -> The term of the Tenancy in months (whole months only)
A7: "monthlyRental": 12, | B7: =IF(OR(ISNUMBER(SEARCH("{", A7)),ISNUMBER(SEARCH("[", A7))), "", IFERROR(MID(A7, SEARCH("""", A7) +1, SEARCH("""", A7, SEARCH("""",A7) +1) - SEARCH("""", A7) -1), "")) -> monthlyRental | C7: =IF(B7="", "", VLOOKUP(B7,'API Data Dictionary'!C:J,8,FALSE)) -> M | D7: =IF(B7="", "", VLOOKUP(B7,'API Data Dictionary'!C:D,2,FALSE)) -> number (double) | E7: =IF(IF(B7="", "", VLOOKUP(B7,'API Data Dictionary'!C:E,3,FALSE))=0, "", IF(B7="", "", VLOOKUP(B7,'API Data Dictionary'!C:E,3,FALSE))) | F7: =IF(IF(B7="", "", VLOOKUP(B7,'API Data Dictionary'!C:F,4,FALSE))=0, "", IF(B7="", "", VLOOKUP(B7,'API Data Dictionary'!C:F,4,FALSE))) -> number($double) pattern: ^\d*.\d{0,2}$ | G7: =IF(IF(B7="", "", VLOOKUP(B7,'API Data Dictionary'!C:G,5,FALSE))=0, "", IF(B7="", "", VLOOKUP(B7,'API Data Dictionary'!C:G,5,FALSE))) -> The monthly rental cost
A8: "lettingType": 1, | B8: =IF(OR(ISNUMBER(SEARCH("{", A8)),ISNUMBER(SEARCH("[", A8))), "", IFERROR(MID(A8, SEARCH("""", A8) +1, SEARCH("""", A8, SEARCH("""",A8) +1) - SEARCH("""", A8) -1), "")) -> lettingType | C8: =IF(B8="", "", VLOOKUP(B8,'API Data Dictionary'!C:J,8,FALSE)) -> M | D8: =IF(B8="", "", VLOOKUP(B8,'API Data Dictionary'!C:D,2,FALSE)) -> enum - Letting Type | E8: =IF(IF(B8="", "", VLOOKUP(B8,'API Data Dictionary'!C:E,3,FALSE))=0, "", IF(B8="", "", VLOOKUP(B8,'API Data Dictionary'!C:E,3,FALSE))) | F8: =IF(IF(B8="", "", VLOOKUP(B8,'API Data Dictionary'!C:F,4,FALSE))=0, "", IF(B8="", "", VLOOKUP(B8,'API Data Dictionary'!C:F,4,FALSE))) -> Valid Values 1-3 (See enum definition) | G8: =IF(IF(B8="", "", VLOOKUP(B8,'API Data Dictionary'!C:G,5,FALSE))=0, "", IF(B8="", "", VLOOKUP(B8,'API Data Dictionary'!C:G,5,FALSE))) -> The type of the letting, i.e. rent only or fully managed
A9: "estimatedMoveInDate": "2023-07-20T09:57:50.515Z", | B9: =IF(OR(ISNUMBER(SEARCH("{", A9)),ISNUMBER(SEARCH("[", A9))), "", IFERROR(MID(A9, SEARCH("""", A9) +1, SEARCH("""", A9, SEARCH("""",A9) +1) - SEARCH("""", A9) -1), "")) -> estimatedMoveInDate | C9: =IF(B9="", "", VLOOKUP(B9,'API Data Dictionary'!C:J,8,FALSE)) -> M | D9: =IF(B9="", "", VLOOKUP(B9,'API Data Dictionary'!C:D,2,FALSE)) -> string ($date-time) | E9: =IF(IF(B9="", "", VLOOKUP(B9,'API Data Dictionary'!C:E,3,FALSE))=0, "", IF(B9="", "", VLOOKUP(B9,'API Data Dictionary'!C:E,3,FALSE))) | F9: =IF(IF(B9="", "", VLOOKUP(B9,'API Data Dictionary'!C:F,4,FALSE))=0, "", IF(B9="", "", VLOOKUP(B9,'API Data Dictionary'!C:F,4,FALSE))) -> DD/MM/YYYY | G9: =IF(IF(B9="", "", VLOOKUP(B9,'API Data Dictionary'!C:G,5,FALSE))=0, "", IF(B9="", "", VLOOKUP(B9,'API Data Dictionary'!C:G,5,FALSE))) -> Estimated date of tenancy start (move in)
A10: "propertyType": 1, | B10: =IF(OR(ISNUMBER(SEARCH("{", A10)),ISNUMBER(SEARCH("[", A10))), "", IFERROR(MID(A10, SEARCH("""", A10) +1, SEARCH("""", A10, SEARCH("""",A10) +1) - SEARCH("""", A10) -1), "")) -> propertyType | C10: =IF(B10="", "", VLOOKUP(B10,'API Data Dictionary'!C:J,8,FALSE)) -> M | D10: =IF(B10="", "", VLOOKUP(B10,'API Data Dictionary'!C:D,2,FALSE)) -> enum - Property Type | E10: =IF(IF(B10="", "", VLOOKUP(B10,'API Data Dictionary'!C:E,3,FALSE))=0, "", IF(B10="", "", VLOOKUP(B10,'API Data Dictionary'!C:E,3,FALSE))) | F10: =IF(IF(B10="", "", VLOOKUP(B10,'API Data Dictionary'!C:F,4,FALSE))=0, "", IF(B10="", "", VLOOKUP(B10,'API Data Dictionary'!C:F,4,FALSE))) -> Valid Values 1-6 (See enum definition) | G10: =IF(IF(B10="", "", VLOOKUP(B10,'API Data Dictionary'!C:G,5,FALSE))=0, "", IF(B10="", "", VLOOKUP(B10,'API Data Dictionary'!C:G,5,FALSE))) -> The Type of property
A11: "propertyConstructionPeriod": 4, | B11: =IF(OR(ISNUMBER(SEARCH("{", A11)),ISNUMBER(SEARCH("[", A11))), "", IFERROR(MID(A11, SEARCH("""", A11) +1, SEARCH("""", A11, SEARCH("""",A11) +1) - SEARCH("""", A11) -1), "")) -> propertyConstructionPeriod | C11: =IF(B11="", "", VLOOKUP(B11,'API Data Dictionary'!C:J,8,FALSE)) -> X | D11: =IF(B11="", "", VLOOKUP(B11,'API Data Dictionary'!C:D,2,FALSE)) -> enum - Property Construction Period | E11: =IF(IF(B11="", "", VLOOKUP(B11,'API Data Dictionary'!C:E,3,FALSE))=0, "", IF(B11="", "", VLOOKUP(B11,'API Data Dictionary'!C:E,3,FALSE))) | F11: =IF(IF(B11="", "", VLOOKUP(B11,'API Data Dictionary'!C:F,4,FALSE))=0, "", IF(B11="", "", VLOOKUP(B11,'API Data Dictionary'!C:F,4,FALSE))) -> Valid Values 1-9 (See enum definition) | G11: =IF(IF(B11="", "", VLOOKUP(B11,'API Data Dictionary'!C:G,5,FALSE))=0, "", IF(B11="", "", VLOOKUP(B11,'API Data Dictionary'!C:G,5,FALSE))) -> The time period in which the property was built
A12: "numberOfBedrooms": 3, | B12: =IF(OR(ISNUMBER(SEARCH("{", A12)),ISNUMBER(SEARCH("[", A12))), "", IFERROR(MID(A12, SEARCH("""", A12) +1, SEARCH("""", A12, SEARCH("""",A12) +1) - SEARCH("""", A12) -1), "")) -> numberOfBedrooms | C12: =IF(B12="", "", VLOOKUP(B12,'API Data Dictionary'!C:J,8,FALSE)) -> X | D12: =IF(B12="", "", VLOOKUP(B12,'API Data Dictionary'!C:D,2,FALSE)) -> integer | E12: =IF(IF(B12="", "", VLOOKUP(B12,'API Data Dictionary'!C:E,3,FALSE))=0, "", IF(B12="", "", VLOOKUP(B12,'API Data Dictionary'!C:E,3,FALSE))) | F12: =IF(IF(B12="", "", VLOOKUP(B12,'API Data Dictionary'!C:F,4,FALSE))=0, "", IF(B12="", "", VLOOKUP(B12,'API Data Dictionary'!C:F,4,FALSE))) | G12: =IF(IF(B12="", "", VLOOKUP(B12,'API Data Dictionary'!C:G,5,FALSE))=0, "", IF(B12="", "", VLOOKUP(B12,'API Data Dictionary'!C:G,5,FALSE))) -> The count of bedrooms in the property
A13: "noOfAdultOccupants": 2, | B13: =IF(OR(ISNUMBER(SEARCH("{", A13)),ISNUMBER(SEARCH("[", A13))), "", IFERROR(MID(A13, SEARCH("""", A13) +1, SEARCH("""", A13, SEARCH("""",A13) +1) - SEARCH("""", A13) -1), "")) -> noOfAdultOccupants | C13: =IF(B13="", "", VLOOKUP(B13,'API Data Dictionary'!C:J,8,FALSE)) -> X | D13: =IF(B13="", "", VLOOKUP(B13,'API Data Dictionary'!C:D,2,FALSE)) -> integer | E13: =IF(IF(B13="", "", VLOOKUP(B13,'API Data Dictionary'!C:E,3,FALSE))=0, "", IF(B13="", "", VLOOKUP(B13,'API Data Dictionary'!C:E,3,FALSE))) | F13: =IF(IF(B13="", "", VLOOKUP(B13,'API Data Dictionary'!C:F,4,FALSE))=0, "", IF(B13="", "", VLOOKUP(B13,'API Data Dictionary'!C:F,4,FALSE))) | G13: =IF(IF(B13="", "", VLOOKUP(B13,'API Data Dictionary'!C:G,5,FALSE))=0, "", IF(B13="", "", VLOOKUP(B13,'API Data Dictionary'!C:G,5,FALSE))) -> Number of Adult occupants (18 or over)
A14: "noOfChildOccupants": 1, | B14: =IF(OR(ISNUMBER(SEARCH("{", A14)),ISNUMBER(SEARCH("[", A14))), "", IFERROR(MID(A14, SEARCH("""", A14) +1, SEARCH("""", A14, SEARCH("""",A14) +1) - SEARCH("""", A14) -1), "")) -> noOfChildOccupants | C14: =IF(B14="", "", VLOOKUP(B14,'API Data Dictionary'!C:J,8,FALSE)) -> X | D14: =IF(B14="", "", VLOOKUP(B14,'API Data Dictionary'!C:D,2,FALSE)) -> integer | E14: =IF(IF(B14="", "", VLOOKUP(B14,'API Data Dictionary'!C:E,3,FALSE))=0, "", IF(B14="", "", VLOOKUP(B14,'API Data Dictionary'!C:E,3,FALSE))) | F14: =IF(IF(B14="", "", VLOOKUP(B14,'API Data Dictionary'!C:F,4,FALSE))=0, "", IF(B14="", "", VLOOKUP(B14,'API Data Dictionary'!C:F,4,FALSE))) | G14: =IF(IF(B14="", "", VLOOKUP(B14,'API Data Dictionary'!C:G,5,FALSE))=0, "", IF(B14="", "", VLOOKUP(B14,'API Data Dictionary'!C:G,5,FALSE))) -> Number of Child Occupants (under 18)
... A32: "firstName": "Juliet", | B32: =IF(OR(ISNUMBER(SEARCH("{", A32)),ISNUMBER(SEARCH("[", A32))), "", IFERROR(MID(A32, SEARCH("""", A32) +1, SEARCH("""", A32, SEARCH("""",A32) +1) - SEARCH("""", A32) -1), "")) -> firstName | C32: =IF(B32="", "", VLOOKUP(B32,'API Data Dictionary'!C:J,8,FALSE)) -> M | D32: =IF(B32="", "", VLOOKUP(B32,'API Data Dictionary'!C:D,2,FALSE)) -> string | E32: =IF(IF(B32="", "", VLOOKUP(B32,'API Data Dictionary'!C:E,3,FALSE))=0, "", IF(B32="", "", VLOOKUP(B32,'API Data Dictionary'!C:E,3,FALSE))) -> 100 | F32: =IF(IF(B32="", "", VLOOKUP(B32,'API Data Dictionary'!C:F,4,FALSE))=0, "", IF(B32="", "", VLOOKUP(B32,'API Data Dictionary'!C:F,4,FALSE))) -> pattern: ^[a-zA-Z0-9\-' ]*$ | G32: =IF(IF(B32="", "", VLOOKUP(B32,'API Data Dictionary'!C:G,5,FALSE))=0, "", IF(B32="", "", VLOOKUP(B32,'API Data Dictionary'!C:G,5,FALSE))) -> First name, validated against the RegEx pattern
A33: "middleName": "Barney", | B33: =IF(OR(ISNUMBER(SEARCH("{", A33)),ISNUMBER(SEARCH("[", A33))), "", IFERROR(MID(A33, SEARCH("""", A33) +1, SEARCH("""", A33, SEARCH("""",A33) +1) - SEARCH("""", A33) -1), "")) -> middleName | C33: M | D33: =IF(B33="", "", VLOOKUP(B33,'API Data Dictionary'!C:D,2,FALSE)) -> string | E33: =IF(IF(B33="", "", VLOOKUP(B33,'API Data Dictionary'!C:E,3,FALSE))=0, "", IF(B33="", "", VLOOKUP(B33,'API Data Dictionary'!C:E,3,FALSE))) -> 50 | F33: =IF(IF(B33="", "", VLOOKUP(B33,'API Data Dictionary'!C:F,4,FALSE))=0, "", IF(B33="", "", VLOOKUP(B33,'API Data Dictionary'!C:F,4,FALSE))) -> pattern: ^[a-zA-Z0-9\-' ]*$ | G33: =IF(IF(B33="", "", VLOOKUP(B33,'API Data Dictionary'!C:G,5,FALSE))=0, "", IF(B33="", "", VLOOKUP(B33,'API Data Dictionary'!C:G,5,FALSE))) -> Middle name, validated against the RegEx pattern
A34: "surname": "Clarke", | B34: =IF(OR(ISNUMBER(SEARCH("{", A34)),ISNUMBER(SEARCH("[", A34))), "", IFERROR(MID(A34, SEARCH("""", A34) +1, SEARCH("""", A34, SEARCH("""",A34) +1) - SEARCH("""", A34) -1), "")) -> surname | C34: =IF(B34="", "", VLOOKUP(B34,'API Data Dictionary'!C:J,8,FALSE)) -> M | D34: =IF(B34="", "", VLOOKUP(B34,'API Data Dictionary'!C:D,2,FALSE)) -> string | E34: =IF(IF(B34="", "", VLOOKUP(B34,'API Data Dictionary'!C:E,3,FALSE))=0, "", IF(B34="", "", VLOOKUP(B34,'API Data Dictionary'!C:E,3,FALSE))) -> 100 | F34: =IF(IF(B34="", "", VLOOKUP(B34,'API Data Dictionary'!C:F,4,FALSE))=0, "", IF(B34="", "", VLOOKUP(B34,'API Data Dictionary'!C:F,4,FALSE))) -> pattern: ^[a-zA-Z0-9\-' ]*$ | G34: =IF(IF(B34="", "", VLOOKUP(B34,'API Data Dictionary'!C:G,5,FALSE))=0, "", IF(B34="", "", VLOOKUP(B34,'API Data Dictionary'!C:G,5,FALSE))) -> Surname name, validated against the RegEx pattern
A35: "shareOfRent": 525.26, | B35: =IF(OR(ISNUMBER(SEARCH("{", A35)),ISNUMBER(SEARCH("[", A35))), "", IFERROR(MID(A35, SEARCH("""", A35) +1, SEARCH("""", A35, SEARCH("""",A35) +1) - SEARCH("""", A35) -1), "")) -> shareOfRent | C35: =IF(B35="", "", VLOOKUP(B35,'API Data Dictionary'!C:J,8,FALSE)) -> M | D35: =IF(B35="", "", VLOOKUP(B35,'API Data Dictionary'!C:D,2,FALSE)) -> number (double) | E35: =IF(IF(B35="", "", VLOOKUP(B35,'API Data Dictionary'!C:E,3,FALSE))=0, "", IF(B35="", "", VLOOKUP(B35,'API Data Dictionary'!C:E,3,FALSE))) | F35: =IF(IF(B35="", "", VLOOKUP(B35,'API Data Dictionary'!C:F,4,FALSE))=0, "", IF(B35="", "", VLOOKUP(B35,'API Data Dictionary'!C:F,4,FALSE))) -> pattern: ^\d*.\d{0,2}$ | G35: =IF(IF(B35="", "", VLOOKUP(B35,'API Data Dictionary'!C:G,5,FALSE))=0, "", IF(B35="", "", VLOOKUP(B35,'API Data Dictionary'!C:G,5,FALSE))) -> GBP value of the applicants share of the rent
A36: "telephoneCountryID": 1, | B36: =IF(OR(ISNUMBER(SEARCH("{", A36)),ISNUMBER(SEARCH("[", A36))), "", IFERROR(MID(A36, SEARCH("""", A36) +1, SEARCH("""", A36, SEARCH("""",A36) +1) - SEARCH("""", A36) -1), "")) -> telephoneCountryID | C36: =IF(B36="", "", VLOOKUP(B36,'API Data Dictionary'!C:J,8,FALSE)) -> M | D36: =IF(B36="", "", VLOOKUP(B36,'API Data Dictionary'!C:D,2,FALSE)) -> enum -Country/Location Code | E36: =IF(IF(B36="", "", VLOOKUP(B36,'API Data Dictionary'!C:E,3,FALSE))=0, "", IF(B36="", "", VLOOKUP(B36,'API Data Dictionary'!C:E,3,FALSE))) | F36: =IF(IF(B36="", "", VLOOKUP(B36,'API Data Dictionary'!C:F,4,FALSE))=0, "", IF(B36="", "", VLOOKUP(B36,'API Data Dictionary'!C:F,4,FALSE))) -> Valid Values 1-239 (See enum definition) | G36: =IF(IF(B36="", "", VLOOKUP(B36,'API Data Dictionary'!C:G,5,FALSE))=0, "", IF(B36="", "", VLOOKUP(B36,'API Data Dictionary'!C:G,5,FALSE))) -> The country/location code of the phone number
A37: "contactTelephoneNo": "01234567891", | B37: =IF(OR(ISNUMBER(SEARCH("{", A37)),ISNUMBER(SEARCH("[", A37))), "", IFERROR(MID(A37, SEARCH("""", A37) +1, SEARCH("""", A37, SEARCH("""",A37) +1) - SEARCH("""", A37) -1), "")) -> contactTelephoneNo | C37: =IF(B37="", "", VLOOKUP(B37,'API Data Dictionary'!C:J,8,FALSE)) -> M | D37: =IF(B37="", "", VLOOKUP(B37,'API Data Dictionary'!C:D,2,FALSE)) -> string | E37: =IF(IF(B37="", "", VLOOKUP(B37,'API Data Dictionary'!C:E,3,FALSE))=0, "", IF(B37="", "", VLOOKUP(B37,'API Data Dictionary'!C:E,3,FALSE))) -> 15 | F37: =IF(IF(B37="", "", VLOOKUP(B37,'API Data Dictionary'!C:F,4,FALSE))=0, "", IF(B37="", "", VLOOKUP(B37,'API Data Dictionary'!C:F,4,FALSE))) -> pattern: ^(\d{11})$ | G37: =IF(IF(B37="", "", VLOOKUP(B37,'API Data Dictionary'!C:G,5,FALSE))=0, "", IF(B37="", "", VLOOKUP(B37,'API Data Dictionary'!C:G,5,FALSE))) -> The telephone number
A38: "emailAddress": "gajodal609@cnxcoin.com", | B38: =IF(OR(ISNUMBER(SEARCH("{", A38)),ISNUMBER(SEARCH("[", A38))), "", IFERROR(MID(A38, SEARCH("""", A38) +1, SEARCH("""", A38, SEARCH("""",A38) +1) - SEARCH("""", A38) -1), "")) -> emailAddress | C38: =IF(B38="", "", VLOOKUP(B38,'API Data Dictionary'!C:J,8,FALSE)) -> M | D38: =IF(B38="", "", VLOOKUP(B38,'API Data Dictionary'!C:D,2,FALSE)) -> string ($email) | E38: =IF(IF(B38="", "", VLOOKUP(B38,'API Data Dictionary'!C:E,3,FALSE))=0, "", IF(B38="", "", VLOOKUP(B38,'API Data Dictionary'!C:E,3,FALSE))) -> 200 | F38: =IF(IF(B38="", "", VLOOKUP(B38,'API Data Dictionary'!C:F,4,FALSE))=0, "", IF(B38="", "", VLOOKUP(B38,'API Data Dictionary'!C:F,4,FALSE))) -> pattern: ^(?!.*\.\.)(?!.*\\_\\_)(?!.*\-\-)[a-zA-Z0-9][-a-zA-Z0-9._]+[a-zA-Z0-9]@([-a-zA-Z0-9]+.)+[a-zA-Z]{2,5}$ | G38: =IF(IF(B38="", "", VLOOKUP(B38,'API Data Dictionary'!C:G,5,FALSE))=0, "", IF(B38="", "", VLOOKUP(B38,'API Data Dictionary'!C:G,5,FALSE))) -> The email address
A39: "dateOfBirth": "1986-10-12T00:00:00.0000000", | B39: =IF(OR(ISNUMBER(SEARCH("{", A39)),ISNUMBER(SEARCH("[", A39))), "", IFERROR(MID(A39, SEARCH("""", A39) +1, SEARCH("""", A39, SEARCH("""",A39) +1) - SEARCH("""", A39) -1), "")) -> dateOfBirth | C39: M | D39: =IF(B39="", "", VLOOKUP(B39,'API Data Dictionary'!C:D,2,FALSE)) -> string ($date-time) | E39: =IF(IF(B39="", "", VLOOKUP(B39,'API Data Dictionary'!C:E,3,FALSE))=0, "", IF(B39="", "", VLOOKUP(B39,'API Data Dictionary'!C:E,3,FALSE))) | F39: =IF(IF(B39="", "", VLOOKUP(B39,'API Data Dictionary'!C:F,4,FALSE))=0, "", IF(B39="", "", VLOOKUP(B39,'API Data Dictionary'!C:F,4,FALSE))) -> DD/MM/YYYY | G39: =IF(IF(B39="", "", VLOOKUP(B39,'API Data Dictionary'!C:G,5,FALSE))=0, "", IF(B39="", "", VLOOKUP(B39,'API Data Dictionary'!C:G,5,FALSE))) -> The date of birth, formatted DD-MM-YYYY
A40: "nationality": 1, | B40: =IF(OR(ISNUMBER(SEARCH("{", A40)),ISNUMBER(SEARCH("[", A40))), "", IFERROR(MID(A40, SEARCH("""", A40) +1, SEARCH("""", A40, SEARCH("""",A40) +1) - SEARCH("""", A40) -1), "")) -> nationality | C40: =IF(B40="", "", VLOOKUP(B40,'API Data Dictionary'!C:J,8,FALSE)) -> M | D40: =IF(B40="", "", VLOOKUP(B40,'API Data Dictionary'!C:D,2,FALSE)) -> enum - Nationality | E40: =IF(IF(B40="", "", VLOOKUP(B40,'API Data Dictionary'!C:E,3,FALSE))=0, "", IF(B40="", "", VLOOKUP(B40,'API Data Dictionary'!C:E,3,FALSE))) | F40: =IF(IF(B40="", "", VLOOKUP(B40,'API Data Dictionary'!C:F,4,FALSE))=0, "", IF(B40="", "", VLOOKUP(B40,'API Data Dictionary'!C:F,4,FALSE))) -> Valid Values 1-231 (See enum definition) | G40: =IF(IF(B40="", "", VLOOKUP(B40,'API Data Dictionary'!C:G,5,FALSE))=0, "", IF(B40="", "", VLOOKUP(B40,'API Data Dictionary'!C:G,5,FALSE))) -> The nationality, from the nationality enum list
A41: "niNumber": "AB123456D", | B41: =IF(OR(ISNUMBER(SEARCH("{", A41)),ISNUMBER(SEARCH("[", A41))), "", IFERROR(MID(A41, SEARCH("""", A41) +1, SEARCH("""", A41, SEARCH("""",A41) +1) - SEARCH("""", A41) -1), "")) -> niNumber | C41: =IF(B41="", "", VLOOKUP(B41,'API Data Dictionary'!C:J,8,FALSE)) -> X | D41: =IF(B41="", "", VLOOKUP(B41,'API Data Dictionary'!C:D,2,FALSE)) -> string | E41: =IF(IF(B41="", "", VLOOKUP(B41,'API Data Dictionary'!C:E,3,FALSE))=0, "", IF(B41="", "", VLOOKUP(B41,'API Data Dictionary'!C:E,3,FALSE))) -> 100 | F41: =IF(IF(B41="", "", VLOOKUP(B41,'API Data Dictionary'!C:F,4,FALSE))=0, "", IF(B41="", "", VLOOKUP(B41,'API Data Dictionary'!C:F,4,FALSE))) -> pattern: ^[a-zA-Z]{2}(?:\d){6}[a-zA-Z]{1}$ | G41: =IF(IF(B41="", "", VLOOKUP(B41,'API Data Dictionary'!C:G,5,FALSE))=0, "", IF(B41="", "", VLOOKUP(B41,'API Data Dictionary'!C:G,5,FALSE))) -> NI Number, matched to RegEx pattern
A42: "residentStatus": 1, | B42: =IF(OR(ISNUMBER(SEARCH("{", A42)),ISNUMBER(SEARCH("[", A42))), "", IFERROR(MID(A42, SEARCH("""", A42) +1, SEARCH("""", A42, SEARCH("""",A42) +1) - SEARCH("""", A42) -1), "")) -> residentStatus | C42: =IF(B42="", "", VLOOKUP(B42,'API Data Dictionary'!C:J,8,FALSE)) -> M | D42: =IF(B42="", "", VLOOKUP(B42,'API Data Dictionary'!C:D,2,FALSE)) -> enum - resident Status | E42: =IF(IF(B42="", "", VLOOKUP(B42,'API Data Dictionary'!C:E,3,FALSE))=0, "", IF(B42="", "", VLOOKUP(B42,'API Data Dictionary'!C:E,3,FALSE))) | F42: =IF(IF(B42="", "", VLOOKUP(B42,'API Data Dictionary'!C:F,4,FALSE))=0, "", IF(B42="", "", VLOOKUP(B42,'API Data Dictionary'!C:F,4,FALSE))) -> Valid Values 1-2 (See enum definition) | G42: =IF(IF(B42="", "", VLOOKUP(B42,'API Data Dictionary'!C:G,5,FALSE))=0, "", IF(B42="", "", VLOOKUP(B42,'API Data Dictionary'!C:G,5,FALSE))) -> Denotes the resident status e.g. UK resident
A43: "additionalInformation": "Additional information for the tenancy of tenant", | B43: =IF(OR(ISNUMBER(SEARCH("{", A43)),ISNUMBER(SEARCH("[", A43))), "", IFERROR(MID(A43, SEARCH("""", A43) +1, SEARCH("""", A43, SEARCH("""",A43) +1) - SEARCH("""", A43) -1), "")) -> additionalInformation | C43: =IF(B43="", "", VLOOKUP(B43,'API Data Dictionary'!C:J,8,FALSE)) -> X | D43: =IF(B43="", "", VLOOKUP(B43,'API Data Dictionary'!C:D,2,FALSE)) -> string | E43: =IF(IF(B43="", "", VLOOKUP(B43,'API Data Dictionary'!C:E,3,FALSE))=0, "", IF(B43="", "", VLOOKUP(B43,'API Data Dictionary'!C:E,3,FALSE))) -> 65535 | F43: =IF(IF(B43="", "", VLOOKUP(B43,'API Data Dictionary'!C:F,4,FALSE))=0, "", IF(B43="", "", VLOOKUP(B43,'API Data Dictionary'!C:F,4,FALSE))) | G43: =IF(IF(B43="", "", VLOOKUP(B43,'API Data Dictionary'!C:G,5,FALSE))=0, "", IF(B43="", "", VLOOKUP(B43,'API Data Dictionary'!C:G,5,FALSE))) -> Free text field for additional information
