Workbook

Sheet RTR
A1: Id | B1: Tenant__r.Name | C1: Related_Opportunity__c | D1: Related_Unit__c | E1: Status__c | F1: Time_Limited__c | G1: RTR_Expiry__c | H1: Date_Next_RTR_Required__c | I1: Document_Saved__c | J1: Check_Date__c | K1: CreatedDate | L1: LastModifiedDate | M1: OwnerId | N1: Criteria | P1: _LastModifiedDate_Splited | Q1: _Check_Date__c > _Is_LastModifiedDate OR Check_Date__c is NULL ?
A2: a1zNz00000095JpIAI | B2: gVcFvfyrV8jNsHt9Vf1X MxYaNpgylHRkz9GNCnmg | C2: 006Nz000002OfSMIA0 | D2: a1G8d0000004XgtEAE | E2: Completed | F2: TRUE | G2: 46656 | I2: FALSE | J2: 45203 | K2: 2023-10-03T12:20:45.000+0000 | L2: 2023-10-03T12:20:45.000+0000 | M2: 0058d00000202rVAAQ | N2: =IF(Q2=TRUE,"BASIC_CRITERIA","") -> BASIC_CRITERIA | P2: =DATEVALUE(SUBSTITUTE(LEFT(L2,10),"-","/")) -> 45202 | Q2: =IF(J2="",TRUE,IF(J2>P2,TRUE,FALSE)) -> TRUE
A3: a1zNz000000AdUjIAK | B3: Ben McCabe | C3: 006Nz000002lChMIAU | D3: a1G4J0000025wYMUAY | E3: Completed | F3: FALSE | I3: FALSE | J3: 45206 | K3: 2023-10-05T13:39:36.000+0000 | L3: 2023-10-06T08:12:09.000+0000 | M3: 0058d0000043ssPAAQ | N3: =IF(Q3=TRUE,"BASIC_CRITERIA","") -> BASIC_CRITERIA | P3: =DATEVALUE(SUBSTITUTE(LEFT(L3,10),"-","/")) -> 45205 | Q3: =IF(J3="",TRUE,IF(J3>P3,TRUE,FALSE)) -> TRUE
A4: a1zNz000000AeSPIA0 | B4: Jess Tilley | C4: 006Nz000002n7QdIAI | D4: a1G4J0000025xkKUAQ | E4: Completed | F4: FALSE | I4: FALSE | J4: 45204 | K4: 2023-10-05T13:47:43.000+0000 | L4: 2023-10-06T08:15:46.000+0000 | M4: 0058d0000043ssPAAQ | N4: =IF(Q4=TRUE,"BASIC_CRITERIA","") | P4: =DATEVALUE(SUBSTITUTE(LEFT(L4,10),"-","/")) -> 45205 | Q4: =IF(J4="",TRUE,IF(J4>P4,TRUE,FALSE)) -> FALSE
A5: a1zNz000000AeU1IAK | B5: Matthew Birkett | C5: 006Nz000002n7QdIAI | D5: a1G4J0000025xkKUAQ | E5: Completed | F5: FALSE | I5: FALSE | J5: 45204 | K5: 2023-10-05T13:48:43.000+0000 | L5: 2023-10-06T08:16:41.000+0000 | M5: 0058d0000043ssPAAQ | N5: =IF(Q5=TRUE,"BASIC_CRITERIA","") | P5: =DATEVALUE(SUBSTITUTE(LEFT(L5,10),"-","/")) -> 45205 | Q5: =IF(J5="",TRUE,IF(J5>P5,TRUE,FALSE)) -> FALSE
A6: a1zNz000000AgIvIAK | B6: Aleena Iqbal | C6: 006Nz000002p0o2IAA | D6: a1G4J0000025y3NUAQ | E6: Completed | F6: FALSE | I6: FALSE | J6: 45204 | K6: 2023-10-05T14:10:46.000+0000 | L6: 2023-10-06T08:17:59.000+0000 | M6: 0058d0000043ssPAAQ | N6: =IF(Q6=TRUE,"BASIC_CRITERIA","") | P6: =DATEVALUE(SUBSTITUTE(LEFT(L6,10),"-","/")) -> 45205 | Q6: =IF(J6="",TRUE,IF(J6>P6,TRUE,FALSE)) -> FALSE
A7: a1zNz000000AetpIAC | B7: Sam Collins | C7: 006Nz000002oZawIAE | D7: a1G4J0000025xuQUAQ | E7: Completed | F7: FALSE | I7: FALSE | J7: 45204 | K7: 2023-10-05T13:53:46.000+0000 | L7: 2023-10-09T11:21:48.000+0000 | M7: 0058d0000043ssPAAQ | N7: =IF(Q7=TRUE,"BASIC_CRITERIA","") | P7: =DATEVALUE(SUBSTITUTE(LEFT(L7,10),"-","/")) -> 45208 | Q7: =IF(J7="",TRUE,IF(J7>P7,TRUE,FALSE)) -> FALSE
A8: a1zNz000000AesDIAS | B8: Adam McCrum | C8: 006Nz000002oZawIAE | D8: a1G4J0000025xuQUAQ | E8: Completed | F8: FALSE | I8: FALSE | J8: 45204 | K8: 2023-10-05T13:53:28.000+0000 | L8: 2023-10-10T11:16:58.000+0000 | M8: 0058d0000043ssPAAQ | N8: =IF(Q8=TRUE,"BASIC_CRITERIA","") | P8: =DATEVALUE(SUBSTITUTE(LEFT(L8,10),"-","/")) -> 45209 | Q8: =IF(J8="",TRUE,IF(J8>P8,TRUE,FALSE)) -> FALSE
A9: a1zNz000000AdWLIA0 | B9: Ema Almeida | C9: 006Nz000002lChMIAU | D9: a1G4J0000025wYMUAY | E9: Completed | F9: TRUE | G9: 45944 | I9: FALSE | J9: 45204 | K9: 2023-10-05T13:40:37.000+0000 | L9: 2023-10-10T15:26:15.000+0000 | M9: 0058d0000043ssPAAQ | N9: =IF(Q9=TRUE,"BASIC_CRITERIA","") | P9: =DATEVALUE(SUBSTITUTE(LEFT(L9,10),"-","/")) -> 45209 | Q9: =IF(J9="",TRUE,IF(J9>P9,TRUE,FALSE)) -> FALSE
A10: a1zNz000000AgVpIAK | B10: Ka Po Ngai | C10: 006Nz0000023YnEIAU | D10: a1G4J0000025zIlUAI | E10: Completed | F10: TRUE | G10: 46138 | I10: FALSE | J10: 45204 | K10: 2023-10-05T14:37:50.000+0000 | L10: 2024-08-15T16:03:46.000+0000 | M10: 0058d00000202rVAAQ | N10: =IF(Q10=TRUE,"BASIC_CRITERIA","") | P10: =DATEVALUE(SUBSTITUTE(LEFT(L10,10),"-","/")) -> 45519 | Q10: =IF(J10="",TRUE,IF(J10>P10,TRUE,FALSE)) -> FALSE
A11: a1zNz000000AgM9IAK | B11: Adnan Salah | C11: 006Nz000002p0o2IAA | D11: a1G4J0000025y3NUAQ | E11: Completed | F11: TRUE | G11: 45570 | I11: FALSE | J11: 45204 | K11: 2023-10-05T14:16:27.000+0000 | L11: 2023-10-05T14:24:03.000+0000 | M11: 0058d0000043ssPAAQ | N11: =IF(Q11=TRUE,"BASIC_CRITERIA","") | P11: =DATEVALUE(SUBSTITUTE(LEFT(L11,10),"-","/")) -> 45204 | Q11: =IF(J11="",TRUE,IF(J11>P11,TRUE,FALSE)) -> FALSE
A12: a1zNz000000CAtFIAW | B12: Muskan Singh | C12: 006Nz000002EEWkIAO | D12: a1G4J0000025xj1UAA | E12: Completed | F12: FALSE | I12: FALSE | J12: 45208 | K12: 2023-10-09T16:37:47.000+0000 | L12: 2023-10-12T10:43:52.000+0000 | M12: 0058d0000043ssPAAQ | N12: =IF(Q12=TRUE,"BASIC_CRITERIA","") | P12: =DATEVALUE(SUBSTITUTE(LEFT(L12,10),"-","/")) -> 45211 | Q12: =IF(J12="",TRUE,IF(J12>P12,TRUE,FALSE)) -> FALSE
A13: a1zNz000000CPHBIA4 | B13: Letizia Olivero | C13: 006Nz000002qXMxIAM | D13: a1G8d0000004D97EAE | E13: Completed | F13: TRUE | I13: TRUE | J13: 45209 | K13: 2023-10-10T08:06:26.000+0000 | L13: 2023-10-10T13:34:47.000+0000 | M13: 0058d000006cI6JAAU | N13: =IF(Q13=TRUE,"BASIC_CRITERIA","") | P13: =DATEVALUE(SUBSTITUTE(LEFT(L13,10),"-","/")) -> 45209 | Q13: =IF(J13="",TRUE,IF(J13>P13,TRUE,FALSE)) -> FALSE
A14: a1zNz000000DpWAIA0 | B14: Alexander Karsten | C14: 006Nz000002xve1IAA | D14: a1G8d0000004DEqEAM | E14: Completed | F14: TRUE | I14: TRUE | J14: 45211 | K14: 2023-10-12T08:38:09.000+0000 | L14: 2023-10-12T08:38:09.000+0000 | M14: 0058d000006cI6JAAU | N14: =IF(Q14=TRUE,"BASIC_CRITERIA","") | P14: =DATEVALUE(SUBSTITUTE(LEFT(L14,10),"-","/")) -> 45211 | Q14: =IF(J14="",TRUE,IF(J14>P14,TRUE,FALSE)) -> FALSE
A15: a1zNz000000E2GTIA0 | B15: Afolabi Obasa | C15: 006Nz000002y7YXIAY | D15: a1G4J0000025yx2UAA | E15: Completed | F15: TRUE | G15: 46980 | I15: FALSE | J15: 45211 | K15: 2023-10-12T10:40:23.000+0000 | L15: 2023-10-12T11:34:34.000+0000 | M15: 0058d0000043ssPAAQ | N15: =IF(Q15=TRUE,"BASIC_CRITERIA","") | P15: =DATEVALUE(SUBSTITUTE(LEFT(L15,10),"-","/")) -> 45211 | Q15: =IF(J15="",TRUE,IF(J15>P15,TRUE,FALSE)) -> FALSE
A16: a1zNz000000EdG1IAK | B16: Sobomate Princewell | C16: 006Nz000002bik7IAA | D16: a1G8d0000004c7WEAQ | E16: Completed | F16: TRUE | G16: 45321 | I16: FALSE | J16: 45212 | K16: 2023-10-14T11:35:34.000+0000 | L16: 2023-10-14T11:35:34.000+0000 | M16: 0058d000004FHK0AAO | N16: =IF(Q16=TRUE,"BASIC_CRITERIA","") | P16: =DATEVALUE(SUBSTITUTE(LEFT(L16,10),"-","/")) -> 45213 | Q16: =IF(J16="",TRUE,IF(J16>P16,TRUE,FALSE)) -> FALSE
A17: a1zNz000000Edr7IAC | B17: Elba Cardoso | C17: 006Nz000000wonhIAA | D17: a1G8d0000004cBnEAI | E17: Completed | F17: TRUE | G17: 45303 | I17: FALSE | J17: 45212 | K17: 2023-10-14T12:31:33.000+0000 | L17: 2023-10-14T12:31:33.000+0000 | M17: 0058d000004FHK0AAO | N17: =IF(Q17=TRUE,"BASIC_CRITERIA","") | P17: =DATEVALUE(SUBSTITUTE(LEFT(L17,10),"-","/")) -> 45213 | Q17: =IF(J17="",TRUE,IF(J17>P17,TRUE,FALSE)) -> FALSE
A18: a1zNz000000ERZpIAO | B18: Kit Yee Kiwi Law | C18: 006Nz0000031r5PIAQ | D18: a1GNz0000000zzZMAQ | E18: Completed | F18: TRUE | G18: 46661 | I18: FALSE | J18: 45212 | K18: 2023-10-13T10:55:06.000+0000 | L18: 2023-10-13T10:56:41.000+0000 | M18: 0058d000006chw3AAA | N18: =IF(Q18=TRUE,"BASIC_CRITERIA","") | P18: =DATEVALUE(SUBSTITUTE(LEFT(L18,10),"-","/")) -> 45212 | Q18: =IF(J18="",TRUE,IF(J18>P18,TRUE,FALSE)) -> FALSE
A19: a1zNz000000FlBVIA0 | B19: laura sanchez | C19: 006Nz0000038O6lIAE | D19: a1G4J0000025xkFUAQ | E19: Completed | F19: FALSE | I19: FALSE | J19: 45215 | K19: 2023-10-16T11:44:47.000+0000 | L19: 2023-11-07T08:47:08.000+0000 | M19: 0058d0000043ssPAAQ | N19: =IF(Q19=TRUE,"BASIC_CRITERIA","") | P19: =DATEVALUE(SUBSTITUTE(LEFT(L19,10),"-","/")) -> 45237 | Q19: =IF(J19="",TRUE,IF(J19>P19,TRUE,FALSE)) -> FALSE
A20: a1zNz000000DrHsIAK | B20: Louis Rocca | C20: 006Nz000002iwjzIAA | D20: a1G4J000004jylHUAQ | E20: Completed | F20: FALSE | I20: FALSE | J20: 45216 | K20: 2023-10-12T09:02:53.000+0000 | L20: 2023-10-17T10:23:33.000+0000 | M20: 0054J000006BkQgQAK | N20: =IF(Q20=TRUE,"BASIC_CRITERIA","") | P20: =DATEVALUE(SUBSTITUTE(LEFT(L20,10),"-","/")) -> 45216 | Q20: =IF(J20="",TRUE,IF(J20>P20,TRUE,FALSE)) -> FALSE
A21: a1zNz000000IYw5IAG | B21: Benjamin Maynard | C21: 006Nz000003Bd5yIAC | D21: a1G4J0000025y4wUAA | E21: Completed | F21: FALSE | I21: FALSE | J21: 45218 | K21: 2023-10-19T15:57:09.000+0000 | L21: 2023-10-20T08:03:35.000+0000 | M21: 0058d0000043ssPAAQ | N21: =IF(Q21=TRUE,"BASIC_CRITERIA","") | P21: =DATEVALUE(SUBSTITUTE(LEFT(L21,10),"-","/")) -> 45219 | Q21: =IF(J21="",TRUE,IF(J21>P21,TRUE,FALSE)) -> FALSE
A22: a1zNz000000IYxhIAG | B22: Hazel McDowell | C22: 006Nz000003Bd5yIAC | D22: a1G4J0000025y4wUAA | E22: Completed | F22: FALSE | I22: FALSE | J22: 45218 | K22: 2023-10-19T15:57:57.000+0000 | L22: 2023-10-23T10:04:36.000+0000 | M22: 0058d0000043ssPAAQ | N22: =IF(Q22=TRUE,"BASIC_CRITERIA","") | P22: =DATEVALUE(SUBSTITUTE(LEFT(L22,10),"-","/")) -> 45222 | Q22: =IF(J22="",TRUE,IF(J22>P22,TRUE,FALSE)) -> FALSE
A23: a1zNz000000K5oMIAS | B23: Amelia Lloyd | C23: 006Nz000003I4UvIAK | D23: a1G4J0000025zDJUAY | E23: Completed | F23: FALSE | I23: FALSE | J23: 45222 | K23: 2023-10-23T09:56:42.000+0000 | L23: 2023-10-30T09:14:14.000+0000 | M23: 0058d0000043ssPAAQ | N23: =IF(Q23=TRUE,"BASIC_CRITERIA","") | P23: =DATEVALUE(SUBSTITUTE(LEFT(L23,10),"-","/")) -> 45229 | Q23: =IF(J23="",TRUE,IF(J23>P23,TRUE,FALSE)) -> FALSE
A24: a1zNz000000Jw1tIAC | B24: Ghadah Alsharif | C24: 006Nz000002b80jIAA | D24: a1GNz0000000wGyMAI | E24: Completed | F24: TRUE | G24: 45586 | I24: FALSE | J24: 45222 | K24: 2023-10-23T08:21:08.000+0000 | L24: 2023-10-23T08:21:08.000+0000 | M24: 0054J000004wSINQA2 | N24: =IF(Q24=TRUE,"BASIC_CRITERIA","") | P24: =DATEVALUE(SUBSTITUTE(LEFT(L24,10),"-","/")) -> 45222 | Q24: =IF(J24="",TRUE,IF(J24>P24,TRUE,FALSE)) -> FALSE
A25: a1zNz000000K5unIAC | B25: Rocco Tosini | C25: 006Nz000003I4UvIAK | D25: a1G4J0000025zDJUAY | E25: Completed | F25: TRUE | G25: 45863 | I25: FALSE | J25: 45222 | K25: 2023-10-23T09:56:09.000+0000 | L25: 2023-10-23T11:39:33.000+0000 | M25: 0058d0000043ssPAAQ | N25: =IF(Q25=TRUE,"BASIC_CRITERIA","") | P25: =DATEVALUE(SUBSTITUTE(LEFT(L25,10),"-","/")) -> 45222 | Q25: =IF(J25="",TRUE,IF(J25>P25,TRUE,FALSE)) -> FALSE
A26: a1zNz000000L93VIAS | B26: Kate Johnson | C26: 006Nz000002y1MjIAI | D26: a1G8d0000004XfzEAE | E26: Completed | F26: FALSE | I26: FALSE | J26: 45223 | K26: 2023-10-24T10:04:16.000+0000 | L26: 2023-10-24T10:04:16.000+0000 | M26: 0058d00000202rVAAQ | N26: =IF(Q26=TRUE,"BASIC_CRITERIA","") | P26: =DATEVALUE(SUBSTITUTE(LEFT(L26,10),"-","/")) -> 45223 | Q26: =IF(J26="",TRUE,IF(J26>P26,TRUE,FALSE)) -> FALSE
A27: a1zNz000000Q7STIA0 | B27: Princess Asante | C27: 006Nz000002jBJAIA2 | D27: a1G8d000002QBSoEAO | E27: Completed | F27: TRUE | I27: TRUE | J27: 45227 | K27: 2023-10-31T09:40:22.000+0000 | L27: 2023-10-31T09:43:00.000+0000 | M27: 0058d00000204EOAAY | N27: =IF(Q27=TRUE,"BASIC_CRITERIA","") | P27: =DATEVALUE(SUBSTITUTE(LEFT(L27,10),"-","/")) -> 45230 | Q27: =IF(J27="",TRUE,IF(J27>P27,TRUE,FALSE)) -> FALSE
A28: a1zNz000000PeIPIA0 | B28: Scott Davies | C28: 006Nz000003YWtSIAW | E28: Completed | F28: FALSE | I28: FALSE | J28: 45229 | K28: 2023-10-30T16:54:38.000+0000 | L28: 2023-10-30T16:54:38.000+0000 | M28: 0054J000004wSINQA2 | N28: =IF(Q28=TRUE,"BASIC_CRITERIA","") | P28: =DATEVALUE(SUBSTITUTE(LEFT(L28,10),"-","/")) -> 45229 | Q28: =IF(J28="",TRUE,IF(J28>P28,TRUE,FALSE)) -> FALSE
A29: a1zNz000000RUwTIAW | B29: Oladepo Oladotun | C29: 006Nz0000039RAZIA2 | D29: a1GNz00000015vKMAQ | E29: Completed | F29: TRUE | G29: 45597 | I29: FALSE | J29: 45231 | K29: 2023-11-01T12:06:19.000+0000 | L29: 2023-11-01T14:50:40.000+0000 | M29: 0058d000006chw3AAA | N29: =IF(Q29=TRUE,"BASIC_CRITERIA","") | P29: =DATEVALUE(SUBSTITUTE(LEFT(L29,10),"-","/")) -> 45231 | Q29: =IF(J29="",TRUE,IF(J29>P29,TRUE,FALSE)) -> FALSE
A30: a1zNz000000Rh8vIAC | B30: Su Yi Sarah Ng | C30: 006Nz000001MGvCIAW | D30: a1G8d000002QBa4EAG | E30: Completed | F30: TRUE | G30: 45524 | I30: FALSE | J30: 45231 | K30: 2023-11-01T14:46:35.000+0000 | L30: 2023-11-01T14:46:35.000+0000 | M30: 0058d000006chw3AAA | N30: =IF(Q30=TRUE,"BASIC_CRITERIA","") | P30: =DATEVALUE(SUBSTITUTE(LEFT(L30,10),"-","/")) -> 45231 | Q30: =IF(J30="",TRUE,IF(J30>P30,TRUE,FALSE)) -> FALSE
A31: a1zNz000000T1jtIAC | B31: Sebastien Bouchereau | E31: Completed | F31: FALSE | I31: FALSE | J31: 45234 | K31: 2023-11-04T10:30:53.000+0000 | L31: 2023-11-04T10:30:53.000+0000 | M31: 005Nz000000kC30IAE | N31: =IF(Q31=TRUE,"BASIC_CRITERIA","") | P31: =DATEVALUE(SUBSTITUTE(LEFT(L31,10),"-","/")) -> 45234 | Q31: =IF(J31="",TRUE,IF(J31>P31,TRUE,FALSE)) -> FALSE
A32: a1zNz000000UF85IAG | B32: Evaldas Rimkus | C32: 006Nz000003G6KiIAK | D32: a1G8d000002QBLSEA4 | E32: Completed | F32: FALSE | I32: FALSE | J32: 45236 | K32: 2023-11-06T09:17:48.000+0000 | L32: 2023-11-06T09:17:48.000+0000 | M32: 0058d0000043sEOAAY | N32: =IF(Q32=TRUE,"BASIC_CRITERIA","") | P32: =DATEVALUE(SUBSTITUTE(LEFT(L32,10),"-","/")) -> 45236 | Q32: =IF(J32="",TRUE,IF(J32>P32,TRUE,FALSE)) -> FALSE
A33: a1zNz000000UXzRIAW | B33: Marius Andrei Codesc | C33: 006Nz000002jGM3IAM | D33: a1G8d000002QBLDEA4 | E33: Completed | F33: FALSE | I33: FALSE | J33: 45236 | K33: 2023-11-06T14:24:39.000+0000 | L33: 2023-11-06T14:24:39.000+0000 | M33: 0058d0000043sEOAAY | N33: =IF(Q33=TRUE,"BASIC_CRITERIA","") | P33: =DATEVALUE(SUBSTITUTE(LEFT(L33,10),"-","/")) -> 45236 | Q33: =IF(J33="",TRUE,IF(J33>P33,TRUE,FALSE)) -> FALSE
A34: a1zNz000000V00XIAS | B34: Mia Lenthall | C34: 006Nz000003S54fIAC | D34: a1G4J0000025zz9UAA | E34: Completed | F34: FALSE | I34: FALSE | J34: 45237 | K34: 2023-11-07T09:29:09.000+0000 | L34: 2023-11-07T09:29:09.000+0000 | M34: 0054J000004wZgRQAU | N34: =IF(Q34=TRUE,"BASIC_CRITERIA","") | P34: =DATEVALUE(SUBSTITUTE(LEFT(L34,10),"-","/")) -> 45237 | Q34: =IF(J34="",TRUE,IF(J34>P34,TRUE,FALSE)) -> FALSE
A35: a1zNz000000VE3VIAW | B35: Sharan Sudharshan | C35: 006Nz000003vN33IAE | E35: Completed | F35: TRUE | G35: 45311 | I35: FALSE | J35: 45238 | K35: 2023-11-08T12:29:10.000+0000 | L35: 2023-11-08T12:29:10.000+0000 | M35: 0058d0000043sEOAAY | N35: =IF(Q35=TRUE,"BASIC_CRITERIA","") | P35: =DATEVALUE(SUBSTITUTE(LEFT(L35,10),"-","/")) -> 45238 | Q35: =IF(J35="",TRUE,IF(J35>P35,TRUE,FALSE)) -> FALSE
A36: a1zNz000000VN8PIAW | B36: Mohammed Munawar Munawar Khan | C36: 006Nz0000030L1AIAU | E36: Completed | F36: TRUE | G36: 45681 | I36: FALSE | J36: 45239 | K36: 2023-11-09T09:09:08.000+0000 | L36: 2023-11-09T09:09:08.000+0000 | M36: 0058d0000043sEOAAY | N36: =IF(Q36=TRUE,"BASIC_CRITERIA","") | P36: =DATEVALUE(SUBSTITUTE(LEFT(L36,10),"-","/")) -> 45239 | Q36: =IF(J36="",TRUE,IF(J36>P36,TRUE,FALSE)) -> FALSE
A37: a1zNz000000VNoLIAW | B37: Muddassir Ahmed Khan Ahmed Khan | C37: 006Nz0000030L1AIAU | D37: a1G4J0000025x1GUAQ | E37: Completed | F37: TRUE | I37: TRUE | J37: 45239 | K37: 2023-11-09T10:18:48.000+0000 | L37: 2023-11-09T10:18:48.000+0000 | M37: 0058d0000043sEOAAY | N37: =IF(Q37=TRUE,"BASIC_CRITERIA","") | P37: =DATEVALUE(SUBSTITUTE(LEFT(L37,10),"-","/")) -> 45239 | Q37: =IF(J37="",TRUE,IF(J37>P37,TRUE,FALSE)) -> FALSE
A38: a1zNz000000W3IvIAK | B38: Mark Threlfall | C38: 006Nz00000481z9IAA | D38: a1G4J0000025xsGUAQ | E38: Completed | F38: FALSE | I38: FALSE | J38: 45243 | K38: 2023-11-13T14:24:01.000+0000 | L38: 2023-11-14T08:54:38.000+0000 | M38: 0058d0000043ssPAAQ | N38: =IF(Q38=TRUE,"BASIC_CRITERIA","") | P38: =DATEVALUE(SUBSTITUTE(LEFT(L38,10),"-","/")) -> 45244 | Q38: =IF(J38="",TRUE,IF(J38>P38,TRUE,FALSE)) -> FALSE
A39: a1zNz000000WYRZIA4 | B39: Simone Simone Rodriguez | C39: 006Nz000001QZCtIAO | D39: a1G8d0000004XiPEAU | E39: Completed | F39: TRUE | G39: 45455 | I39: FALSE | J39: 45245 | K39: 2023-11-15T09:44:57.000+0000 | L39: 2023-11-15T09:44:57.000+0000 | M39: 0058d00000202rVAAQ | N39: =IF(Q39=TRUE,"BASIC_CRITERIA","") | P39: =DATEVALUE(SUBSTITUTE(LEFT(L39,10),"-","/")) -> 45245 | Q39: =IF(J39="",TRUE,IF(J39>P39,TRUE,FALSE)) -> FALSE
A40: a1zNz000000XmHBIA0 | B40: Louie Blake | C40: 006Nz000003NtBlIAK | D40: a1G4J0000025xiJUAQ | E40: Completed | F40: TRUE | I40: TRUE | J40: 45246 | K40: 2023-11-17T09:48:18.000+0000 | L40: 2023-11-17T09:48:18.000+0000 | M40: 0058d00000204EOAAY | N40: =IF(Q40=TRUE,"BASIC_CRITERIA","") | P40: =DATEVALUE(SUBSTITUTE(LEFT(L40,10),"-","/")) -> 45247 | Q40: =IF(J40="",TRUE,IF(J40>P40,TRUE,FALSE)) -> FALSE
...

Sheet RTR with No Document Upload
A1: Id | B1: Tenant__r.Name | C1: Related_Opportunity__c | D1: Related_Unit__c | E1: Status__c | F1: Time_Limited__c | G1: RTR_Expiry__c | H1: Date_Next_RTR_Required__c | I1: Document_Saved__c | J1: Check_Date__c | K1: CreatedDate | L1: LastModifiedDate | M1: OwnerId | N1: Criteria | P1: AttachedContentDocuments.totalSize | Q1: AttachedContentDocuments.done | R1: AttachedContentDocuments.records.0.Id | S1: AttachedContentDocuments.records.1.Id | T1: AttachedContentDocuments.records.2.Id | U1: AttachedContentDocuments.records.3.Id | V1: AttachedContentDocuments.records.4.Id | W1: AttachedContentDocuments.records.5.Id
A2: a1zNz00000001ddIAA | B2: Puja Aggarwal | C2: 006Nz000001QqYfIAK | D2: a1G4J000004jyoaUAA | E2: Completed | F2: FALSE | I2: TRUE | J2: 45154 | K2: 2023-08-16T14:52:09.000+0000 | L2: 2024-08-15T16:03:46.000+0000 | M2: 0058d00000202rVAAQ | N2: =IF(P2="","NO_DOCS_UPLOADED","") | P2: 2 | Q2: TRUE | R2: 06ANz000001BGUfMAO | S2: 06ANz000001BJF6MAO
A3: a1zNz00000003AnIAI | B3: 2MdM8M7dojhoxxGYABAj NwdLWsMpDGbakVQnWm7v | C3: 006Nz000001f3CfIAI | D3: a1G4J0000025z4AUAQ | E3: Completed | F3: FALSE | I3: TRUE | J3: 45159 | K3: 2023-08-21T14:40:42.000+0000 | L3: 2024-08-15T16:03:46.000+0000 | M3: 0054J000006BkQgQAK | N3: =IF(P3="","NO_DOCS_UPLOADED","") | P3: 1 | Q3: TRUE | R3: 06ANz000001FWEPMA4
A4: a1zNz00000003QvIAI | B4: Thendo Makgatho | D4: a1G4J000004jyeVUAQ | E4: Completed | F4: TRUE | G4: 45522 | I4: TRUE | J4: 45159 | K4: 2023-08-22T11:00:40.000+0000 | L4: 2024-08-15T16:03:46.000+0000 | M4: 0058d0000034Kn5AAE | N4: =IF(P4="","NO_DOCS_UPLOADED","") | P4: 1 | Q4: TRUE | R4: 06ANz000001JVpLMAW
A5: a1zNz00000004I9IAI | B5: Suliman Almazyad | C5: 006Nz000001QhFFIA0 | D5: a1G4J000004jycyUAA | E5: Completed | F5: TRUE | G5: 45687 | I5: TRUE | J5: 45161 | K5: 2023-08-23T13:27:20.000+0000 | L5: 2024-08-15T16:03:46.000+0000 | M5: 0058d00000202rVAAQ | N5: =IF(P5="","NO_DOCS_UPLOADED","") | P5: 1 | Q5: TRUE | R5: 06ANz000001IC9RMAW
A6: a1zNz00000004RpIAI | B6: Test Mohamed | D6: a1G4J000004jynNUAQ | E6: Completed | F6: TRUE | G6: 45960 | I6: TRUE | J6: 45138 | K6: 2023-08-23T14:33:15.000+0000 | L6: 2024-08-15T16:03:46.000+0000 | M6: 0058d0000034Kn5AAE | N6: =IF(P6="","NO_DOCS_UPLOADED","") | P6: 1 | Q6: TRUE | R6: 06ANz000001JXxQMAW
A7: a1zNz00000004hxIAA | B7: Ugochukwu Maduanusi | C7: 006Nz000001ThvUIAS | D7: a1G8d0000004DBDEA2 | E7: Completed | F7: FALSE | I7: TRUE | J7: 45162 | K7: 2023-08-24T09:27:14.000+0000 | L7: 2023-09-04T12:26:08.000+0000 | M7: 0058d00000202rVAAQ | N7: =IF(P7="","NO_DOCS_UPLOADED","") | P7: 1 | Q7: TRUE | R7: 06ANz000001JMIyMAO
A8: a1zNz00000004tFIAQ | B8: Chunjie Wu | C8: 006Nz0000018rmZIAQ | D8: a1G8d0000004DJvEAM | E8: Completed | F8: TRUE | G8: 45303 | I8: TRUE | J8: 45162 | K8: 2023-08-24T14:21:53.000+0000 | L8: 2023-09-04T12:27:05.000+0000 | M8: 0058d00000202rVAAQ | N8: =IF(P8="","NO_DOCS_UPLOADED","") | P8: 1 | Q8: TRUE | R8: 06ANz000001JqLkMAK
A9: a1zNz000000052vIAA | B9: Amani Alattas | C9: 006Nz000001pK2bIAE | D9: a1G4J000004jynJUAQ | E9: In Progress | F9: TRUE | G9: 45261 | I9: TRUE | J9: 45163 | K9: 2023-08-25T08:13:09.000+0000 | L9: 2023-09-04T12:10:01.000+0000 | M9: 0058d00000202rVAAQ | P9: 1 | Q9: TRUE | R9: 06ANz000001KenbMAC
A10: a1zNz00000005FpIAI | B10: Charmaine Kilonzo | C10: 006Nz000001nugPIAQ | D10: a1G4J000004jyekUAA | E10: Completed | F10: FALSE | I10: TRUE | J10: 45163 | K10: 2023-08-25T10:07:49.000+0000 | L10: 2024-08-15T16:03:46.000+0000 | M10: 0058d00000202rVAAQ | N10: =IF(P10="","NO_DOCS_UPLOADED","") | P10: 1 | Q10: TRUE | R10: 06ANz000001KrRaMAK
A11: a1zNz0000000AtpIAE | B11: Hanan Alhasan | C11: 006Nz000001lSWjIAM | D11: a1G4J000004jyj6UAA | E11: Completed | F11: TRUE | G11: 45882 | I11: TRUE | J11: 45168 | K11: 2023-08-30T15:19:11.000+0000 | L11: 2024-08-15T16:03:46.000+0000 | M11: 0054J000006BkQgQAK | N11: =IF(P11="","NO_DOCS_UPLOADED","") | P11: 1 | Q11: TRUE | R11: 06ANz000001RODsMAO
A12: a1zNz0000000CxFIAU | B12: Fajer Alalawi | C12: 006Nz000001lKAxIAM | D12: a1G4J000004jypjUAA | E12: Completed | F12: TRUE | G12: 47118 | I12: TRUE | J12: 45169 | K12: 2023-08-31T09:58:16.000+0000 | L12: 2024-08-15T16:03:46.000+0000 | M12: 0054J000006BkQgQAK | N12: =IF(P12="","NO_DOCS_UPLOADED","") | P12: 1 | Q12: TRUE | R12: 06ANz000001SIREMA4
A13: a1zNz0000000FjpIAE | B13: Afeke Hormeku | D13: a1G4J000004jyoWUAQ | E13: Completed | F13: TRUE | G13: 45519 | I13: TRUE | J13: 45169 | K13: 2023-09-01T12:11:29.000+0000 | L13: 2024-08-15T16:03:46.000+0000 | M13: 0058d0000034Kn5AAE | N13: =IF(P13="","NO_DOCS_UPLOADED","") | P13: 1 | Q13: TRUE | R13: 06ANz000001TyToMAK
A14: a1zNz0000000OdRIAU | B14: Jiaji Li | C14: 006Nz000001UfRlIAK | D14: a1G4J000004jyp9UAA | E14: Completed | F14: TRUE | G14: 45260 | I14: TRUE | J14: 45174 | K14: 2023-09-05T11:20:23.000+0000 | L14: 2023-09-05T11:21:25.000+0000 | M14: 0054J000006BkQgQAK | N14: =IF(P14="","NO_DOCS_UPLOADED","") | P14: 1 | Q14: TRUE | R14: 06ANz000001XnG6MAK
A15: a1zNz0000000OdSIAU | B15: Ruoxi Leng | C15: 006Nz000001UfRlIAK | D15: a1G4J000004jyp9UAA | E15: Completed | F15: TRUE | G15: 45676 | I15: TRUE | K15: 2023-09-05T11:21:04.000+0000 | L15: 2024-08-15T16:03:46.000+0000 | M15: 0054J000006BkQgQAK | N15: =IF(P15="","NO_DOCS_UPLOADED","") | P15: 1 | Q15: TRUE | R15: 06ANz000001XhXTMA0
A16: a1zNz0000000OjtIAE | B16: Abdulaziz Alkandari | C16: 006Nz000001vbbsIAA | D16: a1G4J000004jyvCUAQ | E16: Completed | F16: TRUE | G16: 45251 | I16: TRUE | J16: 45174 | K16: 2023-09-05T11:47:52.000+0000 | L16: 2023-09-05T11:48:13.000+0000 | M16: 0054J000006BkQgQAK | N16: =IF(P16="","NO_DOCS_UPLOADED","") | P16: 1 | Q16: TRUE | R16: 06ANz000001XqNhMAK
A17: a1zNz0000000Po1IAE | B17: Emilia Cole | C17: 006Nz000001mghBIAQ | D17: a1G4J000004jyu4UAA | E17: Completed | F17: FALSE | I17: TRUE | J17: 45175 | K17: 2023-09-06T11:14:58.000+0000 | L17: 2024-08-15T16:03:46.000+0000 | M17: 0054J000006BkQgQAK | N17: =IF(P17="","NO_DOCS_UPLOADED","") | P17: 1 | Q17: TRUE | R17: 06ANz000001ZGU2MAO
A18: a1zNz0000000PrFIAU | B18: Asina Kaya | C18: 006Nz000001f9oLIAQ | D18: a1G4J000004jyhFUAQ | E18: Completed | F18: TRUE | G18: 45253 | I18: TRUE | J18: 45175 | K18: 2023-09-06T12:37:46.000+0000 | L18: 2023-09-06T12:37:46.000+0000 | M18: 0054J000006BkQgQAK | N18: =IF(P18="","NO_DOCS_UPLOADED","") | P18: 1 | Q18: TRUE | R18: 06ANz000001ZMoIMAW
A19: a1zNz0000000PsrIAE | B19: Hakki Kaya | C19: 006Nz000001f9oLIAQ | D19: a1G4J000004jyhFUAQ | E19: Completed | F19: TRUE | G19: 45253 | I19: TRUE | J19: 45175 | K19: 2023-09-06T12:38:27.000+0000 | L19: 2023-09-06T12:38:27.000+0000 | M19: 0054J000006BkQgQAK | N19: =IF(P19="","NO_DOCS_UPLOADED","") | P19: 1 | Q19: TRUE | R19: 06ANz000001ZMl4MAG
A20: a1zNz0000000T5FIAU | B20: Luke Tibbetts | C20: 006Nz000001TeJGIA0 | D20: a1G4J000004jymPUAQ | E20: Completed | F20: FALSE | I20: TRUE | J20: 45177 | K20: 2023-09-08T12:02:06.000+0000 | L20: 2024-08-15T16:03:46.000+0000 | M20: 0058d00000202rVAAQ | N20: =IF(P20="","NO_DOCS_UPLOADED","") | P20: 1 | Q20: TRUE | R20: 06ANz000001c368MAA
A21: a1zNz0000000T6rIAE | B21: Richard Marshall | C21: 006Nz000001TeJGIA0 | D21: a1G4J000004jymPUAQ | E21: Completed | F21: FALSE | I21: TRUE | J21: 45177 | K21: 2023-09-08T12:03:20.000+0000 | L21: 2024-08-15T16:03:46.000+0000 | M21: 0058d00000202rVAAQ | N21: =IF(P21="","NO_DOCS_UPLOADED","") -> NO_DOCS_UPLOADED
A22: a1zNz0000000Ue1IAE | B22: Joseph Malik | D22: a1G4J000004jydcUAA | E22: Completed | F22: FALSE | I22: TRUE | J22: 45178 | K22: 2023-09-09T13:40:31.000+0000 | L22: 2024-08-15T16:03:46.000+0000 | M22: 0058d0000034Kn5AAE | N22: =IF(P22="","NO_DOCS_UPLOADED","") | P22: 1 | Q22: TRUE | R22: 06ANz000001d7ViMAI
A23: a1zNz0000000UirIAE | B23: Matthew Hughes | D23: a1G4J000004jydcUAA | E23: Completed | F23: FALSE | I23: TRUE | J23: 45178 | K23: 2023-09-09T13:45:34.000+0000 | L23: 2024-08-15T16:03:46.000+0000 | M23: 0058d0000034Kn5AAE | N23: =IF(P23="","NO_DOCS_UPLOADED","") | P23: 1 | Q23: TRUE | R23: 06ANz000001d4bAMAQ
A24: a1zNz0000000WEQIA2 | B24: Sophie Tolson | C24: 006Nz000001mghBIAQ | D24: a1G4J000004jyu4UAA | E24: Completed | F24: FALSE | I24: TRUE | J24: 45180 | K24: 2023-09-11T08:30:00.000+0000 | L24: 2024-08-15T16:03:46.000+0000 | M24: 0054J000006BkQgQAK | N24: =IF(P24="","NO_DOCS_UPLOADED","") | P24: 1 | Q24: TRUE | R24: 06ANz000001eGSXMA2
A25: a1zNz0000000WpVIAU | B25: Joseph Malik | C25: 006Nz000001Tcz1IAC | D25: a1G4J000004jydcUAA | E25: Completed | F25: FALSE | I25: TRUE | J25: 45178 | K25: 2023-09-11T10:25:52.000+0000 | L25: 2024-08-15T16:03:46.000+0000 | M25: 0058d0000034Ks6AAE | N25: =IF(P25="","NO_DOCS_UPLOADED","") | P25: 2 | Q25: TRUE | R25: 06ANz000001eVPaMAM | S25: 06ANz000002cJ7EMAU
A26: a1zNz0000000Wr7IAE | B26: Matthew Hughes | C26: 006Nz000001Tcz1IAC | D26: a1G4J000004jydcUAA | E26: Completed | F26: FALSE | I26: TRUE | J26: 45178 | K26: 2023-09-11T10:27:20.000+0000 | L26: 2024-08-15T16:03:46.000+0000 | M26: 0058d0000034Ks6AAE | N26: =IF(P26="","NO_DOCS_UPLOADED","") | P26: 1 | Q26: TRUE | R26: 06ANz000001eNdMMAU
A27: a1zNz0000000XATIA2 | B27: Fraser McKnespiey | C27: 006Nz000001TYFTIA4 | D27: a1G4J000004jyjwUAA | E27: Completed | F27: FALSE | I27: TRUE | J27: 45155 | K27: 2023-09-11T11:37:49.000+0000 | L27: 2024-08-15T16:03:46.000+0000 | M27: 0054J000006BkQgQAK | N27: =IF(P27="","NO_DOCS_UPLOADED","") | P27: 1 | Q27: TRUE | R27: 06ANz000001eY7oMAE
A28: a1zNz0000000XC5IAM | B28: Ellen Wright | C28: 006Nz000001TYFTIA4 | D28: a1G4J000004jyjwUAA | E28: Completed | F28: FALSE | I28: TRUE | J28: 45155 | K28: 2023-09-11T11:38:24.000+0000 | L28: 2024-08-15T16:03:46.000+0000 | M28: 0054J000006BkQgQAK | N28: =IF(P28="","NO_DOCS_UPLOADED","") | P28: 1 | Q28: TRUE | R28: 06ANz000001eTRIMA2
A29: a1zNz0000000ZsDIAU | B29: Cristina Ruiz de Loizaga Garcia | C29: 006Nz000001NHqqIAG | D29: a1G4J000004jyvRUAQ | E29: Completed | F29: TRUE | G29: 45595 | I29: TRUE | J29: 45181 | K29: 2023-09-12T12:12:29.000+0000 | L29: 2024-08-15T16:03:46.000+0000 | M29: 0054J000006BkQgQAK | N29: =IF(P29="","NO_DOCS_UPLOADED","") | P29: 1 | Q29: TRUE | R29: 06ANz000001g0TVMAY
A30: a1zNz0000003kxZIAQ | B30: Asmar Rzayeva | C30: 0064J00000FTju1QAD | D30: a1G4J0000025xSVUAY | E30: Completed | F30: TRUE | G30: 46107 | I30: TRUE | J30: 45191 | K30: 2023-09-22T12:01:22.000+0000 | L30: 2024-08-15T16:03:46.000+0000 | M30: 0058d0000034KskAAE | N30: =IF(P30="","NO_DOCS_UPLOADED","") | P30: 1 | Q30: TRUE | R30: 06ANz000001uZloMAE
A31: a1zNz0000003tkjIAA | B31: Jodi Meir | C31: 006Nz000001f3cUIAQ | D31: a1G4J0000025zLKUAY | E31: Completed | F31: FALSE | I31: TRUE | J31: 45192 | K31: 2023-09-23T16:56:37.000+0000 | L31: 2024-08-15T16:03:46.000+0000 | M31: 0054J000006BkQgQAK | N31: =IF(P31="","NO_DOCS_UPLOADED","") | P31: 1 | Q31: TRUE | R31: 06ANz000001w50MMAQ
A32: a1zNz0000003tmLIAQ | B32: Ella Wilcock | C32: 006Nz000001f3cUIAQ | D32: a1G4J0000025zLKUAY | E32: Completed | F32: FALSE | I32: TRUE | J32: 45192 | K32: 2023-09-23T16:56:57.000+0000 | L32: 2024-08-15T16:03:46.000+0000 | M32: 0054J000006BkQgQAK | N32: =IF(P32="","NO_DOCS_UPLOADED","") | P32: 1 | Q32: TRUE | R32: 06ANz000001w53aMAA
A33: a1zNz00000050SPIAY | B33: Xingyu Tian | C33: 006Nz000002O2CYIA0 | D33: a1G4J000004jyrzUAA | E33: Completed | F33: TRUE | G33: 46782 | I33: TRUE | J33: 45194 | K33: 2023-09-25T16:56:32.000+0000 | L33: 2024-08-15T16:03:46.000+0000 | M33: 0054J000006BkQgQAK | N33: =IF(P33="","NO_DOCS_UPLOADED","") | P33: 1 | Q33: TRUE | R33: 06ANz000001yLDuMAM
A34: a1zNz00000050U1IAI | B34: Ming Yue | C34: 006Nz000002O2CYIA0 | D34: a1G4J000004jyrzUAA | E34: Completed | F34: TRUE | G34: 46782 | I34: TRUE | J34: 45194 | K34: 2023-09-25T16:57:13.000+0000 | L34: 2024-08-15T16:03:46.000+0000 | M34: 0054J000006BkQgQAK | N34: =IF(P34="","NO_DOCS_UPLOADED","") | P34: 1 | Q34: TRUE | R34: 06ANz000001yHE5MAM
A35: a1zNz0000005L5RIAU | B35: Luke Bulmer | C35: 006Nz0000020IDjIAM | D35: a1G4J0000025zS4UAI | E35: Completed | F35: FALSE | I35: TRUE | J35: 45195 | K35: 2023-09-26T09:57:46.000+0000 | L35: 2024-08-15T16:03:46.000+0000 | M35: 0054J000006BkQgQAK | N35: =IF(P35="","NO_DOCS_UPLOADED","") | P35: 1 | Q35: TRUE | R35: 06ANz000001zMZfMAM
A36: a1zNz0000005L73IAE | B36: Erin Doughty | C36: 006Nz0000020IDjIAM | D36: a1G4J0000025zS4UAI | E36: Completed | F36: FALSE | I36: TRUE | J36: 45195 | K36: 2023-09-26T09:58:12.000+0000 | L36: 2024-08-15T16:03:46.000+0000 | M36: 0054J000006BkQgQAK | N36: =IF(P36="","NO_DOCS_UPLOADED","") | P36: 1 | Q36: TRUE | R36: 06ANz000001zaMAMAY
A37: a1zNz0000005YM2IAM | B37: Michail Athinaios | C37: 006Nz000002SKCMIA4 | D37: a1GNz0000000w8sMAA | E37: Completed | F37: TRUE | G37: 45519 | I37: TRUE | J37: 45195 | K37: 2023-09-26T12:39:54.000+0000 | L37: 2024-08-15T16:03:46.000+0000 | M37: 0058d00000202rVAAQ | N37: =IF(P37="","NO_DOCS_UPLOADED","") | P37: 1 | Q37: TRUE | R37: 06ANz00000200yCMAQ
A38: a1zNz0000005d3xIAA | B38: Rehekah Newey | C38: 006Nz000002SKCMIA4 | D38: a1GNz0000000w8sMAA | E38: Completed | F38: FALSE | I38: TRUE | J38: 45195 | K38: 2023-09-26T13:54:15.000+0000 | L38: 2024-08-15T16:03:46.000+0000 | M38: 0058d00000202rVAAQ | N38: =IF(P38="","NO_DOCS_UPLOADED","") | P38: 1 | Q38: TRUE | R38: 06ANz000001zuGFMAY
A39: a1zNz0000005eWHIAY | B39: Ian Kennedy | C39: 006Nz000002XVyOIAW | D39: a1GNz0000000vO5MAI | E39: Completed | F39: FALSE | I39: TRUE | J39: 45195 | K39: 2023-09-26T14:48:16.000+0000 | L39: 2024-08-15T16:03:46.000+0000 | M39: 0054J000006BkQgQAK | N39: =IF(P39="","NO_DOCS_UPLOADED","") | P39: 1 | Q39: TRUE | R39: 06ANz0000020H4oMAE
A40: a1zNz0000005rwXIAQ | B40: Elsie Appiah | C40: 006Nz0000012j3hIAA | D40: a1G4J0000025xZMUAY | E40: Completed | F40: TRUE | G40: 46728 | I40: TRUE | J40: 45196 | K40: 2023-09-27T07:49:50.000+0000 | L40: 2024-10-30T12:14:33.000+0000 | M40: 0058d0000020QoXAAU | N40: =IF(P40="","NO_DOCS_UPLOADED","") | P40: 1 | Q40: TRUE | R40: 06ANz0000021Y8YMAU
...

Sheet 1. RTR with Tenant >1 "Compltd"
A1: Id | B1: Right_to_Rents__r.totalSize | C1: Right_to_Rents__r.done | D1: Right_to_Rents__r.records.0.Status__c | E1: Right_to_Rents__r.records.1.Status__c | F1: Right_to_Rents__r.records.2.Status__c | G1: Right_to_Rents__r.records.3.Status__c | H1: Right_to_Rents__r.records.4.Status__c | I1: Right_to_Rents__r.records.5.Status__c | J1: Right_to_Rents__r.records.6.Status__c | K1: Right_to_Rents__r.records.7.Status__c | L1: Right_to_Rents__r.records.8.Status__c | M1: Right_to_Rents__r.records.9.Status__c | N1: Right_to_Rents__r.records.10.Status__c | O1: Right_to_Rents__r.records.11.Status__c | P1: Right_to_Rents__r.records.12.Status__c | Q1: Right_to_Rents__r.records.13.Status__c | R1: Right_to_Rents__r.records.14.Status__c | S1: Right_to_Rents__r.records.15.Status__c | U1: _Count of Status ="Completed" > 1
A2: 0014J00000VvTtbQAF | B2: 16 | C2: TRUE | D2: Completed | E2: Completed | F2: Completed | G2: Completed | H2: Completed | I2: Completed | J2: Completed | K2: Completed | L2: Completed | M2: Completed | N2: Completed | O2: Completed | P2: Completed | Q2: Completed | R2: Completed | S2: Not started | U2: =IF(COUNTIF(D2:S2,"Completed")>1,"TRUE","FALSE") -> TRUE
A3: 0018d00000JkBPhAAN | B3: 4 | C3: TRUE | D3: Completed | E3: Completed | F3: Completed | G3: Not started | U3: =IF(COUNTIF(D3:S3,"Completed")>1,"TRUE","FALSE") -> TRUE
A4: 0018d00000G0FPXAA3 | B4: 4 | C4: TRUE | D4: Completed | E4: Completed | F4: Not started | G4: Not started | U4: =IF(COUNTIF(D4:S4,"Completed")>1,"TRUE","FALSE") -> TRUE
A5: 001Nz000003LbAzIAK | B5: 4 | C5: TRUE | D5: Completed | E5: Completed | F5: Not started | G5: Not started | U5: =IF(COUNTIF(D5:S5,"Completed")>1,"TRUE","FALSE") -> TRUE
A6: 001Nz000002wbUIIAY | B6: 3 | C6: TRUE | D6: Completed | E6: Completed | F6: Not started | U6: =IF(COUNTIF(D6:S6,"Completed")>1,"TRUE","FALSE") -> TRUE
A7: 001Nz0000077RHBIA2 | B7: 3 | C7: TRUE | D7: Completed | E7: Completed | F7: Not started | U7: =IF(COUNTIF(D7:S7,"Completed")>1,"TRUE","FALSE") -> TRUE
A8: 001Nz000004YEPdIAO | B8: 3 | C8: TRUE | D8: Completed | E8: Completed | F8: Not started | U8: =IF(COUNTIF(D8:S8,"Completed")>1,"TRUE","FALSE") -> TRUE
A9: 0018d0000098mbAAAQ | B9: 3 | C9: TRUE | D9: Completed | E9: In Progress | F9: Completed | U9: =IF(COUNTIF(D9:S9,"Completed")>1,"TRUE","FALSE") -> TRUE
A10: 0014J00000ZtPDnQAN | B10: 3 | C10: TRUE | D10: Completed | E10: Completed | F10: Not started | U10: =IF(COUNTIF(D10:S10,"Completed")>1,"TRUE","FALSE") -> TRUE
A11: 001Nz000004OV5DIAW | B11: 3 | C11: TRUE | D11: Completed | E11: Completed | F11: Not started | U11: =IF(COUNTIF(D11:S11,"Completed")>1,"TRUE","FALSE") -> TRUE
A12: 001Nz000002XoGFIA0 | B12: 3 | C12: TRUE | D12: Completed | E12: Completed | F12: Not started | U12: =IF(COUNTIF(D12:S12,"Completed")>1,"TRUE","FALSE") -> TRUE
A13: 001Nz000006wFckIAE | B13: 3 | C13: TRUE | D13: Completed | E13: Completed | F13: Not started | U13: =IF(COUNTIF(D13:S13,"Completed")>1,"TRUE","FALSE") -> TRUE
A14: 001Nz000002spUIIAY | B14: 3 | C14: TRUE | D14: Completed | E14: Completed | F14: Not started | U14: =IF(COUNTIF(D14:S14,"Completed")>1,"TRUE","FALSE") -> TRUE
A15: 001Nz000003pVJNIA2 | B15: 3 | C15: TRUE | D15: Completed | E15: Completed | F15: Not started | U15: =IF(COUNTIF(D15:S15,"Completed")>1,"TRUE","FALSE") -> TRUE
A16: 0018d00000LMmMSAA1 | B16: 3 | C16: TRUE | D16: Completed | E16: Completed | F16: Not started | U16: =IF(COUNTIF(D16:S16,"Completed")>1,"TRUE","FALSE") -> TRUE
A17: 0018d00000EifdKAAR | B17: 3 | C17: TRUE | D17: Completed | E17: Completed | F17: Not started | U17: =IF(COUNTIF(D17:S17,"Completed")>1,"TRUE","FALSE") -> TRUE
... A30: 0018d00000PUAa4AAH | B30: 3 | C30: TRUE | D30: Completed | E30: Completed | F30: Not started | U30: =IF(COUNTIF(D30:S30,"Completed")>1,"TRUE","FALSE") -> TRUE
A31: 001Nz0000014ue9IAA | B31: 2 | C31: TRUE | D31: Completed | E31: Completed | U31: =IF(COUNTIF(D31:S31,"Completed")>1,"TRUE","FALSE") -> TRUE
A32: 001Nz000003oC2fIAE | B32: 2 | C32: TRUE | D32: Completed | E32: Completed | U32: =IF(COUNTIF(D32:S32,"Completed")>1,"TRUE","FALSE") -> TRUE
A33: 001Nz000008Nb3uIAC | B33: 2 | C33: TRUE | D33: Completed | E33: Completed | U33: =IF(COUNTIF(D33:S33,"Completed")>1,"TRUE","FALSE") -> TRUE
A34: 001Nz00000Ap54jIAB | B34: 2 | C34: TRUE | D34: Completed | E34: Completed | U34: =IF(COUNTIF(D34:S34,"Completed")>1,"TRUE","FALSE") -> TRUE
A35: 001Nz000002QXs4IAG | B35: 2 | C35: TRUE | D35: Completed | E35: Completed | U35: =IF(COUNTIF(D35:S35,"Completed")>1,"TRUE","FALSE") -> TRUE
A36: 001Nz000009qgHWIAY | B36: 2 | C36: TRUE | D36: Completed | E36: Completed | U36: =IF(COUNTIF(D36:S36,"Completed")>1,"TRUE","FALSE") -> TRUE
A37: 001Nz000008BxHuIAK | B37: 2 | C37: TRUE | D37: Completed | E37: Completed | U37: =IF(COUNTIF(D37:S37,"Completed")>1,"TRUE","FALSE") -> TRUE
A38: 0014J00000VvU1kQAF | B38: 2 | C38: TRUE | D38: Completed | E38: Completed | U38: =IF(COUNTIF(D38:S38,"Completed")>1,"TRUE","FALSE") -> TRUE
A39: 0018d00000FyzCuAAJ | B39: 2 | C39: TRUE | D39: Completed | E39: Completed | U39: =IF(COUNTIF(D39:S39,"Completed")>1,"TRUE","FALSE") -> TRUE
A40: 001Nz000004Z8LVIA0 | B40: 2 | C40: TRUE | D40: Completed | E40: Completed | U40: =IF(COUNTIF(D40:S40,"Completed")>1,"TRUE","FALSE") -> TRUE
A41: 001Nz0000027TnKIAU | B41: 2 | C41: TRUE | D41: Completed | E41: Completed | U41: =IF(COUNTIF(D41:S41,"Completed")>1,"TRUE","FALSE") -> TRUE
A42: 001Nz00000AkSejIAF | B42: 2 | C42: TRUE | D42: Completed | E42: Completed | U42: =IF(COUNTIF(D42:S42,"Completed")>1,"TRUE","FALSE") -> TRUE
... A90: 001Nz000006UNQRIA4 | B90: 2 | C90: TRUE | D90: Completed | E90: Completed | U90: =IF(COUNTIF(D90:S90,"Completed")>1,"TRUE","FALSE") -> TRUE
A91: 001Nz000001U4NNIA0 | B91: 1 | C91: TRUE | D91: Completed | U91: =IF(COUNTIF(D91:S91,"Completed")>1,"TRUE","FALSE") -> FALSE
A92: 001Nz000001iLszIAE | B92: 1 | C92: TRUE | D92: Completed | U92: =IF(COUNTIF(D92:S92,"Completed")>1,"TRUE","FALSE") -> FALSE
A93: 0018d000002sQaEAAU | B93: 1 | C93: TRUE | D93: Completed | U93: =IF(COUNTIF(D93:S93,"Completed")>1,"TRUE","FALSE") -> FALSE
A94: 001Nz000001TtoZIAS | B94: 1 | C94: TRUE | D94: Completed | U94: =IF(COUNTIF(D94:S94,"Completed")>1,"TRUE","FALSE") -> FALSE
A95: 0018d00000PSOIFAA5 | B95: 1 | C95: TRUE | D95: Completed | U95: =IF(COUNTIF(D95:S95,"Completed")>1,"TRUE","FALSE") -> FALSE
A96: 001Nz000001sfwrIAA | B96: 1 | C96: TRUE | D96: Completed | U96: =IF(COUNTIF(D96:S96,"Completed")>1,"TRUE","FALSE") -> FALSE
A97: 001Nz000001qr1FIAQ | B97: 1 | C97: TRUE | D97: Completed | U97: =IF(COUNTIF(D97:S97,"Completed")>1,"TRUE","FALSE") -> FALSE
A98: 001Nz000001oT7yIAE | B98: 1 | C98: TRUE | D98: Completed | U98: =IF(COUNTIF(D98:S98,"Completed")>1,"TRUE","FALSE") -> FALSE
A99: 001Nz000001oKXjIAM | B99: 1 | C99: TRUE | D99: Completed | U99: =IF(COUNTIF(D99:S99,"Completed")>1,"TRUE","FALSE") -> FALSE
...

Sheet 2. RTR with Tenant >1 "Compltd"
A1: Id
A2: 001Nz000002wbUIIAY
A3: 001Nz0000077RHBIA2
A4: 001Nz0000014ue9IAA
A5: 001Nz000003oC2fIAE
A6: 001Nz000008Nb3uIAC
A7: 001Nz000004YEPdIAO
A8: 001Nz00000Ap54jIAB
A9: 0018d0000098mbAAAQ
A10: 001Nz000002QXs4IAG
A11: 001Nz000009qgHWIAY
A12: 001Nz000008BxHuIAK
... A94: 001Nz000006dIBJIA2

Sheet 3. RTR with Tenant >1 "Compltd"
A1: Id | B1: Tenant__c | C1: Tenant__r.Name | D1: Related_Opportunity__c | E1: Related_Unit__c | F1: Status__c | G1: Time_Limited__c | H1: RTR_Expiry__c | I1: Document_Saved__c | J1: Check_Date__c | K1: CreatedDate | L1: LastModifiedDate | M1: OwnerId | N1: Criteria | P1: _Pass Criteria?
A2: a1zPv0000018MikIAE | B2: 0014J00000VvNS1QAN | C2: . Barber | D2: 006Pv00000CPBm9IAH | F2: Not started | G2: FALSE | I2: FALSE | K2: 2024-11-14T22:08:24.000+0000 | L2: 2024-11-14T22:08:24.000+0000 | M2: 00GPv000002kNznMAE | P2: =NOT(ISERROR(VLOOKUP(B2,'2. RTR with Tenant >1 "Compltd"'!A:A,1,FALSE))) -> FALSE
A3: a1zNz000001djEPIAY | B3: 001Nz000008jzCZIAY | C3: ?Jingyao Chen | D3: 006Nz000008VWVGIA4 | E3: a1G4J0000025ynlUAA | F3: Completed | G3: TRUE | H3: 46059 | I3: TRUE | J3: 45352 | K3: 2024-03-01T14:52:24.000+0000 | L3: 2024-08-15T16:03:49.000+0000 | M3: 0058d000006aqUrAAI | P3: =NOT(ISERROR(VLOOKUP(B3,'2. RTR with Tenant >1 "Compltd"'!A:A,1,FALSE))) -> FALSE
A4: a1zPv000000vegfIAA | C4: 006Pv00000B94ckIAB | E4: Not started | F4: FALSE | H4: FALSE | J4: 2024-09-19T09:36:23.000+0000 | K4: 2024-09-19T09:36:23.000+0000 | L4: 00GPv000002kNznMAE | P4: =NOT(ISERROR(VLOOKUP(B4,'2. RTR with Tenant >1 "Compltd"'!A:A,1,FALSE))) -> FALSE
A5: a1zPv000000vebpIAA | C5: 006Pv00000B99grIAB | E5: Not started | F5: FALSE | H5: FALSE | J5: 2024-09-19T09:22:21.000+0000 | K5: 2024-09-19T09:22:21.000+0000 | L5: 00GPv000002kNznMAE | P5: =NOT(ISERROR(VLOOKUP(B5,'2. RTR with Tenant >1 "Compltd"'!A:A,1,FALSE))) -> FALSE
A6: a1zPv00000118FuIAI | C6: 006Pv00000Bc7BpIAJ | E6: Not started | F6: FALSE | H6: FALSE | J6: 2024-10-16T16:27:10.000+0000 | K6: 2024-10-16T16:27:10.000+0000 | L6: 00GPv000002kNznMAE | P6: =NOT(ISERROR(VLOOKUP(B6,'2. RTR with Tenant >1 "Compltd"'!A:A,1,FALSE))) -> FALSE
A7: a1zNz000000UIFeIAO | B7: 001Nz0000037crdIAA | C7: 0C6qXnFQiTEyPnsIKq62 KwJRGmqaKV9wEP8KMYgG | D7: 006Nz00000347FjIAI | F7: Completed | G7: FALSE | I7: TRUE | J7: 45236 | K7: 2023-11-06T09:58:45.000+0000 | L7: 2024-08-15T16:03:47.000+0000 | M7: 0058d0000043ssPAAQ | P7: =NOT(ISERROR(VLOOKUP(B7,'2. RTR with Tenant >1 "Compltd"'!A:A,1,FALSE))) -> FALSE
A8: a1zNz000000V2rxIAC | B8: 001Nz000003ssXzIAI | C8: 0Qce73SkNtmjUBe3uDk1 9qOeWaPWHSsfIW3g4Bhg | D8: 006Nz000003TzUlIAK | E8: a1G4J0000025zKnUAI | F8: Completed | G8: TRUE | H8: 45474 | I8: TRUE | J8: 45237 | K8: 2023-11-07T11:49:29.000+0000 | L8: 2023-11-07T11:49:29.000+0000 | M8: 0054J000004wZgRQAU | P8: =NOT(ISERROR(VLOOKUP(B8,'2. RTR with Tenant >1 "Compltd"'!A:A,1,FALSE))) -> FALSE
A9: a1zNz000003OHveIAG | B9: 001Nz000000VDQoIAO | C9: 1gNhjJnB1ks3CACYmUlK teIhOuSnagmwp8f9BrXq | D9: 006Nz00000AsbRYIAZ | E9: a1G4J0000025yVWUAY | F9: Completed | G9: FALSE | I9: TRUE | J9: 45456 | K9: 2024-06-13T13:59:38.000+0000 | L9: 2024-08-15T16:03:50.000+0000 | M9: 0054J000004vXOaQAM | P9: =NOT(ISERROR(VLOOKUP(B9,'2. RTR with Tenant >1 "Compltd"'!A:A,1,FALSE))) -> FALSE
A10: a1zNz0000022USIIA2 | B10: 0018d00000JjBl0AAF | C10: 1QZtgrjblkd4nCCZbnzg 5ggn9bOUA83W9V9OqlOP | D10: 006Nz000008LS7yIAG | E10: a1G4J0000025y00UAA | F10: Completed | G10: TRUE | H10: 45894 | I10: TRUE | J10: 45379 | K10: 2024-03-28T09:03:48.000+0000 | L10: 2024-08-15T16:03:50.000+0000 | M10: 0058d00000202rVAAQ | P10: =NOT(ISERROR(VLOOKUP(B10,'2. RTR with Tenant >1 "Compltd"'!A:A,1,FALSE))) -> FALSE
A11: a1zNz000002oVvWIAU | B11: 0018d00000RGQTFAA5 | C11: 2ESBl7VxuaG8dG4Noago WzDxQ0J7KzFtyuT0Jbi1 | D11: 006Nz00000B30oNIAR | E11: a1G8d0000004cBxEAI | F11: Completed | G11: TRUE | H11: 46502 | I11: TRUE | J11: 45426 | K11: 2024-05-14T13:42:19.000+0000 | L11: 2024-08-15T16:03:50.000+0000 | M11: 005Nz000003Ka0oIAC | P11: =NOT(ISERROR(VLOOKUP(B11,'2. RTR with Tenant >1 "Compltd"'!A:A,1,FALSE))) -> FALSE
A12: a1zNz000001QUxxIAG | B12: 0018d000006X2cxAAC | C12: 2I97XkY7BvRMU9TINOyD xOiuMvFSmvWwJbK2ITRC | E12: a1G4J000002609mUAA | F12: Completed | G12: TRUE | H12: 47515 | I12: TRUE | J12: 45338 | K12: 2024-02-16T14:38:47.000+0000 | L12: 2024-08-15T16:03:49.000+0000 | M12: 0058d000001yXevAAE | P12: =NOT(ISERROR(VLOOKUP(B12,'2. RTR with Tenant >1 "Compltd"'!A:A,1,FALSE))) -> FALSE
A13: a1zNz00000003AnIAI | B13: 001Nz000001iLszIAE | C13: 2MdM8M7dojhoxxGYABAj NwdLWsMpDGbakVQnWm7v | D13: 006Nz000001f3CfIAI | E13: a1G4J0000025z4AUAQ | F13: Completed | G13: FALSE | I13: TRUE | J13: 45159 | K13: 2023-08-21T14:40:42.000+0000 | L13: 2024-08-15T16:03:46.000+0000 | M13: 0054J000006BkQgQAK | P13: =NOT(ISERROR(VLOOKUP(B13,'2. RTR with Tenant >1 "Compltd"'!A:A,1,FALSE))) -> FALSE
A14: a1zNz000001X3GHIA0 | B14: 001Nz000002rQL1IAM | C14: 8jWcYnnW7AdjgM1KUcPf SxfunkUavXYxFgSvfXt4 | D14: 006Nz000000TQn7IAG | E14: a1G8d0000004c7EEAQ | F14: Completed | G14: TRUE | H14: 46122 | I14: TRUE | J14: 45345 | K14: 2024-02-23T17:46:37.000+0000 | L14: 2024-08-15T16:03:49.000+0000 | M14: 0058d0000034KZ2AAM | P14: =NOT(ISERROR(VLOOKUP(B14,'2. RTR with Tenant >1 "Compltd"'!A:A,1,FALSE))) -> FALSE
A15: a1zPv000000z5M9IAI | B15: 001Pv00000XV1B9IAL | C15: A BC | D15: 006Pv00000BR5wXIAT | F15: Not started | G15: FALSE | I15: FALSE | K15: 2024-10-07T11:44:36.000+0000 | L15: 2024-10-07T11:44:36.000+0000 | M15: 00GPv000002kNznMAE | P15: =NOT(ISERROR(VLOOKUP(B15,'2. RTR with Tenant >1 "Compltd"'!A:A,1,FALSE))) -> FALSE
A16: a1zPv000000zx3BIAQ | B16: 001Pv00000XV1B9IAL | C16: A BC | D16: 006Pv00000BR5wXIAT | F16: Not started | G16: FALSE | I16: FALSE | K16: 2024-10-11T13:34:56.000+0000 | L16: 2024-10-11T13:34:56.000+0000 | M16: 00GPv000002kNznMAE | P16: =NOT(ISERROR(VLOOKUP(B16,'2. RTR with Tenant >1 "Compltd"'!A:A,1,FALSE))) -> FALSE
A17: a1zPv0000017GcBIAU | B17: 0018d000006WChGAAW | C17: Aakaash Sankar | D17: 006Pv00000CKGL5IAP | F17: Not started | G17: FALSE | I17: FALSE | K17: 2024-11-11T08:00:24.000+0000 | L17: 2024-11-11T08:00:24.000+0000 | M17: 00GPv000002kNzmMAE | P17: =NOT(ISERROR(VLOOKUP(B17,'2. RTR with Tenant >1 "Compltd"'!A:A,1,FALSE))) -> FALSE
A18: a1zNz000003AIMyIAO | B18: 001Nz000000vnDiIAI | C18: Aakanksha Lowlekar | D18: 006Nz000000qkd6IAA | E18: a1G4J0000025zLEUAY | F18: Completed | G18: TRUE | H18: 45883 | I18: TRUE | J18: 45446 | K18: 2024-06-03T09:22:39.000+0000 | L18: 2024-08-15T16:03:50.000+0000 | M18: 005Nz000002mlzaIAA | P18: =NOT(ISERROR(VLOOKUP(B18,'2. RTR with Tenant >1 "Compltd"'!A:A,1,FALSE))) -> FALSE
A19: a1zPv000000rXsIIAU | B19: 001Nz000004bo5JIAQ | C19: Aalaa Seidahmed | D19: 006Pv00000AqpVJIAZ | F19: Not started | G19: FALSE | I19: FALSE | K19: 2024-09-04T07:01:47.000+0000 | L19: 2024-09-04T07:01:47.000+0000 | M19: 00GPv000002kNzmMAE | P19: =NOT(ISERROR(VLOOKUP(B19,'2. RTR with Tenant >1 "Compltd"'!A:A,1,FALSE))) -> FALSE
A20: a1zNz000001whTpIAI | B20: 0018d00000V8IGwAAN | C20: Aaliyah Naseem | D20: 006Nz000009JCLHIA4 | E20: a1G4J0000025xBnUAI | F20: Completed | G20: FALSE | I20: TRUE | J20: 45029 | K20: 2024-03-21T14:44:33.000+0000 | L20: 2024-08-15T16:03:50.000+0000 | M20: 0054J000004vXOqQAM | P20: =NOT(ISERROR(VLOOKUP(B20,'2. RTR with Tenant >1 "Compltd"'!A:A,1,FALSE))) -> FALSE
A21: a1zNz000001NIOfIAO | B21: 001Nz000007ezwqIAA | C21: Aanand Natarajan Rajahsekha | D21: 006Nz000007RzwHIAS | E21: a1G4J0000025x4jUAA | F21: Completed | G21: TRUE | H21: 46058 | I21: TRUE | J21: 45335 | K21: 2024-02-13T18:59:45.000+0000 | L21: 2024-08-15T16:03:49.000+0000 | M21: 0058d0000043sEOAAY | P21: =NOT(ISERROR(VLOOKUP(B21,'2. RTR with Tenant >1 "Compltd"'!A:A,1,FALSE))) -> FALSE
A22: a1zNz000000SsqHIAS | B22: 001Nz000003U1kvIAC | C22: Aanandita Gupta | D22: 006Nz000003QsB8IAK | E22: a1G4J000004jylDUAQ | F22: Completed | G22: TRUE | H22: 46283 | I22: TRUE | J22: 45239 | K22: 2023-11-03T15:49:33.000+0000 | L22: 2024-08-15T16:03:47.000+0000 | M22: 0058d00000202rVAAQ | P22: =NOT(ISERROR(VLOOKUP(B22,'2. RTR with Tenant >1 "Compltd"'!A:A,1,FALSE))) -> FALSE
A23: a1zNz000000Me5FIAS | B23: 001Nz000003YLI1IAO | C23: Aaron Bamford | D23: 006Nz000003QxfWIAS | E23: a1G8d0000004DFkEAM | F23: Completed | G23: FALSE | I23: TRUE | J23: 45224 | K23: 2023-10-25T16:36:17.000+0000 | L23: 2024-08-15T16:03:47.000+0000 | M23: 0058d000006cI6JAAU | P23: =NOT(ISERROR(VLOOKUP(B23,'2. RTR with Tenant >1 "Compltd"'!A:A,1,FALSE))) -> FALSE
A24: a1zPv000000ziliIAA | B24: 0018d000005ja1SAAQ | C24: Aaron Cordey | D24: 006Pv00000BUJlFIAX | F24: Not started | G24: FALSE | I24: FALSE | K24: 2024-10-10T07:01:11.000+0000 | L24: 2024-10-10T07:01:11.000+0000 | M24: 00GPv000002kNzmMAE | P24: =NOT(ISERROR(VLOOKUP(B24,'2. RTR with Tenant >1 "Compltd"'!A:A,1,FALSE))) -> FALSE
A25: a1zNz000001VGhRIAW | B25: 001Nz000008QrqVIAS | C25: Aaron Doyle | D25: 006Nz000008AiftIAC | E25: a1G4J0000025yIHUAY | F25: Completed | G25: FALSE | I25: TRUE | J25: 45343 | K25: 2024-02-21T15:49:41.000+0000 | L25: 2024-08-15T16:03:49.000+0000 | M25: 0054J000004wSINQA2 | P25: =NOT(ISERROR(VLOOKUP(B25,'2. RTR with Tenant >1 "Compltd"'!A:A,1,FALSE))) -> FALSE
A26: a1zNz000002YffXIAS | B26: 001Nz00000AWzQuIAL | C26: Aaron Grew | D26: 006Nz00000AJDFEIA5 | E26: a1G4J0000025zr2UAA | F26: Completed | G26: FALSE | I26: TRUE | J26: 45407 | K26: 2024-04-29T09:43:30.000+0000 | L26: 2024-08-15T16:03:50.000+0000 | M26: 0058d00000204EOAAY | P26: =NOT(ISERROR(VLOOKUP(B26,'2. RTR with Tenant >1 "Compltd"'!A:A,1,FALSE))) -> FALSE
A27: a1zNz000003MpgTIAS | B27: 001Nz000001chctIAA | C27: Aarshika Singh | D27: 0068d00000CsUdmAAF | E27: a1G4J00000260McUAI | F27: Completed | G27: TRUE | H27: 45932 | I27: TRUE | J27: 45138 | K27: 2024-06-12T14:23:29.000+0000 | L27: 2024-08-15T16:03:50.000+0000 | M27: 0054J000004vXOnQAM | P27: =NOT(ISERROR(VLOOKUP(B27,'2. RTR with Tenant >1 "Compltd"'!A:A,1,FALSE))) -> FALSE
A28: a1zNz000002uOrJIAU | B28: 001Nz00000BMhEVIA1 | C28: Aarti Aarti | D28: 006Nz00000B2avbIAB | E28: a1GNz000000126EMAQ | F28: Completed | G28: TRUE | H28: 47164 | I28: TRUE | J28: 45432 | K28: 2024-05-20T12:13:21.000+0000 | L28: 2024-08-15T16:03:50.000+0000 | M28: 0054J000005JWtDQAW | P28: =NOT(ISERROR(VLOOKUP(B28,'2. RTR with Tenant >1 "Compltd"'!A:A,1,FALSE))) -> FALSE
A29: a1zNz000000VCOHIA4 | B29: 001Nz000003rDodIAE | C29: Aarti DCruz | D29: 006Nz000003noV3IAI | E29: a1G4J0000025yCEUAY | F29: Completed | G29: TRUE | H29: 45590 | I29: TRUE | J29: 45238 | K29: 2023-11-08T10:29:56.000+0000 | L29: 2024-08-15T16:03:47.000+0000 | M29: 0054J000004wZgRQAU | P29: =NOT(ISERROR(VLOOKUP(B29,'2. RTR with Tenant >1 "Compltd"'!A:A,1,FALSE))) -> FALSE
A30: a1zPv000000sbCPIAY | B30: 001Nz000003rDodIAE | C30: Aarti DCruz | D30: 006Pv00000AvnPkIAJ | F30: Not started | G30: FALSE | I30: FALSE | K30: 2024-09-09T07:00:33.000+0000 | L30: 2024-09-09T07:00:33.000+0000 | M30: 00GPv000002kNzmMAE | P30: =NOT(ISERROR(VLOOKUP(B30,'2. RTR with Tenant >1 "Compltd"'!A:A,1,FALSE))) -> FALSE
A31: a1zNz000003M7FdIAK | B31: 001Nz00000CikbJIAR | C31: Aarushi Dureja | D31: 006Nz00000CRNRRIA5 | E31: a1G4J0000025zaFUAQ | F31: Completed | G31: TRUE | H31: 45687 | I31: TRUE | J31: 45455 | K31: 2024-06-12T10:46:37.000+0000 | L31: 2024-08-15T16:03:50.000+0000 | M31: 0054J000004vXPBQA2 | P31: =NOT(ISERROR(VLOOKUP(B31,'2. RTR with Tenant >1 "Compltd"'!A:A,1,FALSE))) -> FALSE
A32: a1zNz000001nKkzIAE | B32: 001Nz000008nm28IAA | C32: Aarushi Gupta | D32: 006Nz000008YptCIAS | E32: a1G4J0000025zsAUAQ | F32: Completed | G32: TRUE | H32: 46055 | I32: TRUE | J32: 45363 | K32: 2024-03-12T10:43:35.000+0000 | L32: 2024-08-15T16:03:50.000+0000 | M32: 005Nz000002KcrEIAS | P32: =NOT(ISERROR(VLOOKUP(B32,'2. RTR with Tenant >1 "Compltd"'!A:A,1,FALSE))) -> FALSE
A33: a1zNz000002SGALIA4 | B33: 001Nz00000A0fn5IAB | C33: Aaryaman Gandotra | D33: 006Nz000009kndGIAQ | E33: a1G4J00000262uRUAQ | F33: Completed | G33: TRUE | H33: 46184 | I33: TRUE | J33: 45405 | K33: 2024-04-23T05:30:13.000+0000 | L33: 2024-08-15T16:03:50.000+0000 | M33: 0058d0000034c7LAAQ | P33: =NOT(ISERROR(VLOOKUP(B33,'2. RTR with Tenant >1 "Compltd"'!A:A,1,FALSE))) -> FALSE
A34: a1zNz000003OUeNIAW | B34: 001Nz00000CFtVCIA1 | C34: Aaryaman Saini | D34: 006Nz00000BzHlbIAF | E34: a1G4J0000025y1JUAQ | F34: Completed | G34: TRUE | H34: 45925 | I34: TRUE | J34: 45456 | K34: 2024-06-13T15:13:05.000+0000 | L34: 2024-08-15T16:03:50.000+0000 | M34: 0054J000004vXOaQAM | P34: =NOT(ISERROR(VLOOKUP(B34,'2. RTR with Tenant >1 "Compltd"'!A:A,1,FALSE))) -> FALSE
A35: a1zNz000000LS4XIAW | B35: 001Nz000002aYlDIAU | C35: Aashna Grewal | D35: 006Nz000002XkMIIA0 | E35: a1G8d000002QBa3EAG | F35: Completed | G35: TRUE | H35: 45514 | I35: TRUE | J35: 45223 | K35: 2023-10-24T12:17:14.000+0000 | L35: 2023-10-24T12:17:14.000+0000 | M35: 0058d000006chw3AAA | P35: =NOT(ISERROR(VLOOKUP(B35,'2. RTR with Tenant >1 "Compltd"'!A:A,1,FALSE))) -> FALSE
A36: a1zPv000000pggYIAQ | B36: 001Nz000002aYlDIAU | C36: Aashna Grewal | D36: 006Pv00000Af1vOIAR | F36: Not started | G36: FALSE | I36: FALSE | K36: 2024-08-27T07:00:45.000+0000 | L36: 2024-08-27T07:00:45.000+0000 | M36: 00GPv000002kNzmMAE | P36: =NOT(ISERROR(VLOOKUP(B36,'2. RTR with Tenant >1 "Compltd"'!A:A,1,FALSE))) -> FALSE
A37: a1zNz000002w0PtIAI | B37: 001Nz00000BV0VGIA1 | C37: Aasrit Kappagantu | D37: 006Nz00000BEaJqIAL | E37: a1G4J0000025xhdUAA | F37: Completed | G37: TRUE | H37: 46420 | I37: TRUE | J37: 45433 | K37: 2024-05-21T13:02:33.000+0000 | L37: 2024-08-15T16:03:50.000+0000 | M37: 0054J000004vXOaQAM | P37: =NOT(ISERROR(VLOOKUP(B37,'2. RTR with Tenant >1 "Compltd"'!A:A,1,FALSE))) -> FALSE
A38: a1zNz000000RhYjIAK | B38: 001Nz0000010cvxIAA | C38: Abaan Kachkar | E38: a1G8d0000004XbiEAE | F38: Completed | G38: TRUE | H38: 45611 | I38: TRUE | J38: 45231 | K38: 2023-11-01T15:08:19.000+0000 | L38: 2024-08-15T16:03:47.000+0000 | M38: 0058d0000020QoXAAU | P38: =NOT(ISERROR(VLOOKUP(B38,'2. RTR with Tenant >1 "Compltd"'!A:A,1,FALSE))) -> FALSE
A39: a1zNz000001JcyfIAC | B39: 001Nz000007uYhKIAU | C39: Abantika Saha | D39: 006Nz000007dbS3IAI | E39: a1G8d000002QBKyEAO | F39: Completed | G39: TRUE | H39: 45697 | I39: TRUE | J39: 45331 | K39: 2024-02-09T15:17:05.000+0000 | L39: 2024-08-15T16:03:49.000+0000 | M39: 0054J000004vXOnQAM | P39: =NOT(ISERROR(VLOOKUP(B39,'2. RTR with Tenant >1 "Compltd"'!A:A,1,FALSE))) -> FALSE
A40: a1zNz000002GzfxIAC | B40: 001Nz00000AK9vtIAD | C40: Abasiama Inyang | D40: 006Nz00000A3qFgIAJ | E40: a1G4J0000025xz5UAA | F40: Completed | G40: TRUE | H40: 46299 | I40: TRUE | J40: 45393 | K40: 2024-04-11T10:44:23.000+0000 | L40: 2024-08-15T16:03:50.000+0000 | M40: 0058d000006aqUrAAI | P40: =NOT(ISERROR(VLOOKUP(B40,'2. RTR with Tenant >1 "Compltd"'!A:A,1,FALSE))) -> FALSE
...

Sheet 1. RTR with Tenant >1 != Vacatd
A1: Id | B1: Right_to_Rents__r.totalSize | C1: Right_to_Rents__r.done | D1: Right_to_Rents__r.records.0.Status__c | E1: Right_to_Rents__r.records.1.Status__c | F1: Right_to_Rents__r.records.2.Status__c | G1: Right_to_Rents__r.records.3.Status__c | H1: Right_to_Rents__r.records.4.Status__c | I1: Right_to_Rents__r.records.5.Status__c | J1: Right_to_Rents__r.records.6.Status__c | K1: Right_to_Rents__r.records.7.Status__c | L1: Right_to_Rents__r.records.8.Status__c | M1: Right_to_Rents__r.records.9.Status__c | N1: Right_to_Rents__r.records.10.Status__c | O1: Right_to_Rents__r.records.11.Status__c | P1: Right_to_Rents__r.records.12.Status__c | Q1: Right_to_Rents__r.records.13.Status__c | R1: Right_to_Rents__r.records.14.Status__c | S1: Right_to_Rents__r.records.15.Status__c
A2: 001Nz000001U4NNIA0 | B2: 1 | C2: TRUE | D2: Completed
A3: 001Nz000001iLszIAE | B3: 1 | C3: TRUE | D3: Completed
A4: 0018d000002sQaEAAU | B4: 1 | C4: TRUE | D4: Completed
A5: 001Nz000001TtoZIAS | B5: 1 | C5: TRUE | D5: Completed
A6: 0014J00000biT5dQAE | B6: 3 | C6: TRUE | D6: Completed | E6: Completed | F6: Not started
A7: 0018d00000PSOIFAA5 | B7: 1 | C7: TRUE | D7: Completed
A8: 001Nz000001sfwrIAA | B8: 1 | C8: TRUE | D8: Completed
A9: 001Nz000001sCWmIAM | B9: 1 | C9: TRUE | D9: In Progress
A10: 001Nz000001qr1FIAQ | B10: 1 | C10: TRUE | D10: Completed
A11: 001Nz000001oT7yIAE | B11: 1 | C11: TRUE | D11: Completed
A12: 001Nz000001oKXjIAM | B12: 1 | C12: TRUE | D12: Completed
A13: 0018d000006WGGzAAO | B13: 1 | C13: TRUE | D13: Completed
A14: 001Nz000001XuIzIAK | B14: 1 | C14: TRUE | D14: Completed
A15: 001Nz000001jf9kIAA | B15: 1 | C15: TRUE | D15: Completed
A16: 001Nz000001yLfLIAU | B16: 1 | C16: TRUE | D16: Completed
A17: 001Nz000001pg3JIAQ | B17: 1 | C17: TRUE | D17: Completed
A18: 001Nz000001iSfxIAE | B18: 1 | C18: TRUE | D18: Completed
... A21: 001Nz000001WsmHIAS | B21: 1 | C21: TRUE | D21: Completed
A22: 001Nz000001WsJGIA0 | B22: 2 | C22: TRUE | D22: Completed | E22: Completed
A23: 001Nz000001Wz30IAC | B23: 2 | C23: TRUE | D23: Completed | E23: Completed
A24: 001Nz000001rKODIA2 | B24: 1 | C24: TRUE | D24: Completed
A25: 0018d00000EjZsSAAV | B25: 1 | C25: TRUE | D25: Completed
A26: 001Nz000001WwGRIA0 | B26: 1 | C26: TRUE | D26: Completed
A27: 001Nz000001W5FKIA0 | B27: 2 | C27: TRUE | D27: Completed | E27: Not started
A28: 0014J00000ZR2dfQAD | B28: 1 | C28: TRUE | D28: Completed
A29: 001Nz000001iO7hIAE | B29: 2 | C29: TRUE | D29: Completed | E29: Not started
A30: 001Nz000001jP9oIAE | B30: 1 | C30: TRUE | D30: Completed
A31: 001Nz000002QXs4IAG | B31: 2 | C31: TRUE | D31: Completed | E31: Completed
A32: 001Nz000002SyHqIAK | B32: 1 | C32: TRUE | D32: Completed
A33: 001Nz0000022sfwIAA | B33: 1 | C33: TRUE | D33: Completed
A34: 001Nz000002Al1JIAS | B34: 1 | C34: TRUE | D34: Completed
A35: 001Nz000002WqITIA0 | B35: 1 | C35: TRUE | D35: Completed
A36: 001Nz000002UzxpIAC | B36: 1 | C36: TRUE | D36: Completed
A37: 001Nz000002aIYPIA2 | B37: 1 | C37: TRUE | D37: Completed
A38: 0018d00000IHd34AAD | B38: 1 | C38: TRUE | D38: Completed
A39: 001Nz000002P3PpIAK | B39: 1 | C39: TRUE | D39: Completed
A40: 001Nz000002PBvBIAW | B40: 1 | C40: TRUE | D40: Completed
A41: 001Nz000002cGyfIAE | B41: 1 | C41: TRUE | D41: Completed
A42: 001Nz000002SXrCIAW | B42: 1 | C42: TRUE | D42: Completed
...

Sheet 2. RTR with Tenant >1 != Vacatd
A1: Id
A2: 0014J00000biT5dQAE
A3: 001Nz000001WsJGIA0
A4: 001Nz000001Wz30IAC
A5: 001Nz000001W5FKIA0
A6: 001Nz000001iO7hIAE
A7: 001Nz000002QXs4IAG
A8: 0018d00000Jk8SEAAZ
A9: 0018d00000JkBPhAAN
A10: 001Nz000002rHKwIAM
A11: 001Nz000002rLgQIAU
A12: 0018d00000IIGhQAAX
... A958: 001Pv00000YvlQ1IAJ

Sheet 3. RTR with Tenant >1 != Vacatd
A1: Id | B1: Tenant__c | C1: Tenant__r.Name | D1: Related_Opportunity__c | E1: Related_Unit__c | F1: Status__c | G1: Time_Limited__c | H1: RTR_Expiry__c | I1: Date_Next_RTR_Required__c | J1: Document_Saved__c | K1: Check_Date__c | L1: CreatedDate | M1: LastModifiedDate | N1: Owner.Name | P1: _Date_Next_RTR_Required__c > TODAY? | Q1: _Account_Satify_Condition? | R1: _RTR To Be Considered?
A2: a1zNz00000001ddIAA | B2: 001Nz000001U4NNIA0 | C2: Puja Aggarwal | D2: 006Nz000001QqYfIAK | E2: a1G4J000004jyoaUAA | F2: Completed | G2: FALSE | I2: 45621 | J2: TRUE | K2: 45154 | L2: 2023-08-16T14:52:09.000+0000 | M2: 2024-08-15T16:03:46.000+0000 | N2: 0058d00000202rVAAQ | P2: =IF(I2>TODAY(),TRUE,FALSE) -> FALSE | Q2: =NOT(ISERROR(VLOOKUP(B2,'2. RTR with Tenant >1 != Vacatd'!A:A,1,FALSE))) -> FALSE | R2: =AND(P2=TRUE,Q2=TRUE) -> FALSE
A3: a1zNz00000003AnIAI | B3: 001Nz000001iLszIAE | C3: 2MdM8M7dojhoxxGYABAj NwdLWsMpDGbakVQnWm7v | D3: 006Nz000001f3CfIAI | E3: a1G4J0000025z4AUAQ | F3: Completed | G3: FALSE | I3: 45973 | J3: TRUE | K3: 45159 | L3: 2023-08-21T14:40:42.000+0000 | M3: 2024-08-15T16:03:46.000+0000 | N3: 0054J000006BkQgQAK | P3: =IF(I3>TODAY(),TRUE,FALSE) -> TRUE | Q3: =NOT(ISERROR(VLOOKUP(B3,'2. RTR with Tenant >1 != Vacatd'!A:A,1,FALSE))) -> TRUE | R3: =AND(P3=TRUE,Q3=TRUE) -> TRUE
A4: a1zNz00000003QvIAI | B4: 0018d000002sQaEAAU | C4: Thendo Makgatho | E4: a1G4J000004jyeVUAQ | F4: Completed | G4: TRUE | H4: 45522 | I4: 45974 | J4: TRUE | K4: 45159 | L4: 2023-08-22T11:00:40.000+0000 | M4: 2024-08-15T16:03:46.000+0000 | N4: 0058d0000034Kn5AAE | P4: =IF(I4>TODAY(),TRUE,FALSE) -> TRUE | Q4: =NOT(ISERROR(VLOOKUP(B4,'2. RTR with Tenant >1 != Vacatd'!A:A,1,FALSE))) -> FALSE | R4: =AND(P4=TRUE,Q4=TRUE) -> FALSE
A5: a1zNz00000004I9IAI | B5: 001Nz000001TtoZIAS | C5: Suliman Almazyad | D5: 006Nz000001QhFFIA0 | E5: a1G4J000004jycyUAA | F5: Completed | G5: TRUE | H5: 45687 | I5: 45975 | J5: TRUE | K5: 45161 | L5: 2023-08-23T13:27:20.000+0000 | M5: 2024-08-15T16:03:46.000+0000 | N5: 0058d00000202rVAAQ | P5: =IF(I5>TODAY(),TRUE,FALSE) -> TRUE | Q5: =NOT(ISERROR(VLOOKUP(B5,'2. RTR with Tenant >1 != Vacatd'!A:A,1,FALSE))) -> FALSE | R5: =AND(P5=TRUE,Q5=TRUE) -> FALSE
A6: a1zNz00000004RpIAI | B6: 0014J00000biT5dQAE | C6: Test Mohamed | E6: a1G4J000004jynNUAQ | F6: Completed | G6: TRUE | H6: 45960 | I6: 45976 | J6: TRUE | K6: 45138 | L6: 2023-08-23T14:33:15.000+0000 | M6: 2024-08-15T16:03:46.000+0000 | N6: 0058d0000034Kn5AAE | P6: =IF(I6>TODAY(),TRUE,FALSE) -> TRUE | Q6: =NOT(ISERROR(VLOOKUP(B6,'2. RTR with Tenant >1 != Vacatd'!A:A,1,FALSE))) -> TRUE | R6: =AND(P6=TRUE,Q6=TRUE) -> TRUE
A7: a1zNz00000004hxIAA | B7: 0018d00000PSOIFAA5 | C7: Ugochukwu Maduanusi | D7: 006Nz000001ThvUIAS | E7: a1G8d0000004DBDEA2 | F7: Completed | G7: FALSE | I7: 45977 | J7: TRUE | K7: 45162 | L7: 2023-08-24T09:27:14.000+0000 | M7: 2023-09-04T12:26:08.000+0000 | N7: 0058d00000202rVAAQ | P7: =IF(I7>TODAY(),TRUE,FALSE) -> TRUE | Q7: =NOT(ISERROR(VLOOKUP(B7,'2. RTR with Tenant >1 != Vacatd'!A:A,1,FALSE))) -> FALSE | R7: =AND(P7=TRUE,Q7=TRUE) -> FALSE
A8: a1zNz00000004tFIAQ | B8: 001Nz000001sfwrIAA | C8: Chunjie Wu | D8: 006Nz0000018rmZIAQ | E8: a1G8d0000004DJvEAM | F8: Completed | G8: TRUE | H8: 45303 | I8: 45978 | J8: TRUE | K8: 45162 | L8: 2023-08-24T14:21:53.000+0000 | M8: 2023-09-04T12:27:05.000+0000 | N8: 0058d00000202rVAAQ | P8: =IF(I8>TODAY(),TRUE,FALSE) -> TRUE | Q8: =NOT(ISERROR(VLOOKUP(B8,'2. RTR with Tenant >1 != Vacatd'!A:A,1,FALSE))) -> FALSE | R8: =AND(P8=TRUE,Q8=TRUE) -> FALSE
A9: a1zNz000000052vIAA | B9: 001Nz000001sCWmIAM | C9: Amani Alattas | D9: 006Nz000001pK2bIAE | E9: a1G4J000004jynJUAQ | F9: In Progress | G9: TRUE | H9: 45261 | I9: 45597 | J9: TRUE | K9: 45163 | L9: 2023-08-25T08:13:09.000+0000 | M9: 2023-09-04T12:10:01.000+0000 | N9: 0058d00000202rVAAQ | P9: =IF(I9>TODAY(),TRUE,FALSE) -> FALSE | Q9: =NOT(ISERROR(VLOOKUP(B9,'2. RTR with Tenant >1 != Vacatd'!A:A,1,FALSE))) -> FALSE | R9: =AND(P9=TRUE,Q9=TRUE) -> FALSE
A10: a1zNz00000005FpIAI | B10: 001Nz000001qr1FIAQ | C10: Charmaine Kilonzo | D10: 006Nz000001nugPIAQ | E10: a1G4J000004jyekUAA | F10: Completed | G10: FALSE | I10: 45598 | J10: TRUE | K10: 45163 | L10: 2023-08-25T10:07:49.000+0000 | M10: 2024-08-15T16:03:46.000+0000 | N10: 0058d00000202rVAAQ | P10: =IF(I10>TODAY(),TRUE,FALSE) -> FALSE | Q10: =NOT(ISERROR(VLOOKUP(B10,'2. RTR with Tenant >1 != Vacatd'!A:A,1,FALSE))) -> FALSE | R10: =AND(P10=TRUE,Q10=TRUE) -> FALSE
