Workbook

Sheet Update Related Units
A1: Id | B1: Related_Opportunity__r.Primary_Offer__r.Unit__c | D1: _Update? | E1: Id | F1: Related_Unit__c | J1: Disable validation rule:
A2: a1zNz0000006zqPIAQ | B2: a1G4J0000025z5QUAQ | D2: =F2<>"" -> TRUE | E2: =A2 -> a1zNz0000006zqPIAQ | F2: =IF(NOT(ISBLANK(B2)),B2,"") -> a1G4J0000025z5QUAQ | J2: RTR_Validate_Check_Date
A3: a1zNz000000GTNpIAO | B3: a1G4J0000025y8bUAA | D3: =F3<>"" -> TRUE | E3: =A3 -> a1zNz000000GTNpIAO | F3: =IF(NOT(ISBLANK(B3)),B3,"") -> a1G4J0000025y8bUAA | J3: Document_Saved
A4: a1zNz000000GYCDIA4 | B4: a1G4J000004jyhpUAA | D4: =F4<>"" -> TRUE | E4: =A4 -> a1zNz000000GYCDIA4 | F4: =IF(NOT(ISBLANK(B4)),B4,"") -> a1G4J000004jyhpUAA | J4: RTR_Validate_Related_Opportunity
A5: a1zNz000000PdpNIAS | B5: a1GNz00000017lpMAA | D5: =F5<>"" -> TRUE | E5: =A5 -> a1zNz000000PdpNIAS | F5: =IF(NOT(ISBLANK(B5)),B5,"") -> a1GNz00000017lpMAA | J5: No_Expiry_Date_Time_Limited
A6: a1zNz000000PeIPIA0 | B6: a1GNz00000010UGMAY | D6: =F6<>"" -> TRUE | E6: =A6 -> a1zNz000000PeIPIA0 | F6: =IF(NOT(ISBLANK(B6)),B6,"") -> a1GNz00000010UGMAY | J6: RTR_Expiry_Time_Limited
A7: a1zNz000000UIFeIAO | B7: a1GNz00000012fhMAA | D7: =F7<>"" -> TRUE | E7: =A7 -> a1zNz000000UIFeIAO | F7: =IF(NOT(ISBLANK(B7)),B7,"") -> a1GNz00000012fhMAA
A8: a1zNz000000URvdIAG | B8: a1G4J0000025x92UAA | D8: =F8<>"" -> TRUE | E8: =A8 -> a1zNz000000URvdIAG | F8: =IF(NOT(ISBLANK(B8)),B8,"") -> a1G4J0000025x92UAA
A9: a1zNz000000UYfNIAW | B9: a1G8d000002QBLDEA4 | D9: =F9<>"" -> TRUE | E9: =A9 -> a1zNz000000UYfNIAW | F9: =IF(NOT(ISBLANK(B9)),B9,"") -> a1G8d000002QBLDEA4
A10: a1zNz000000UywPIAS | B10: a1G4J0000025y1kUAA | D10: =F10<>"" -> TRUE | E10: =A10 -> a1zNz000000UywPIAS | F10: =IF(NOT(ISBLANK(B10)),B10,"") -> a1G4J0000025y1kUAA
A11: a1zNz000000V6PJIA0 | B11: a1G4J0000025xyYUAQ | D11: =F11<>"" -> TRUE | E11: =A11 -> a1zNz000000V6PJIA0 | F11: =IF(NOT(ISBLANK(B11)),B11,"") -> a1G4J0000025xyYUAQ
A12: a1zNz000000VNd3IAG | B12: a1G4J0000025x1GUAQ | D12: =F12<>"" -> TRUE | E12: =A12 -> a1zNz000000VNd3IAG | F12: =IF(NOT(ISBLANK(B12)),B12,"") -> a1G4J0000025x1GUAQ
A13: a1zNz000000XDwCIAW | B13: a1G4J0000025ywGUAQ | D13: =F13<>"" -> TRUE | E13: =A13 -> a1zNz000000XDwCIAW | F13: =IF(NOT(ISBLANK(B13)),B13,"") -> a1G4J0000025ywGUAQ
A14: a1zNz000000Yww1IAC | B14: a1G4J0000025xXqUAI | D14: =F14<>"" -> TRUE | E14: =A14 -> a1zNz000000Yww1IAC | F14: =IF(NOT(ISBLANK(B14)),B14,"") -> a1G4J0000025xXqUAI
A15: a1zNz000000amu9IAA | B15: a1G4J0000025wkbUAA | D15: =F15<>"" -> TRUE | E15: =A15 -> a1zNz000000amu9IAA | F15: =IF(NOT(ISBLANK(B15)),B15,"") -> a1G4J0000025wkbUAA
A16: a1zNz000000d4jiIAA | B16: a1G4J0000025zHYUAY | D16: =F16<>"" -> TRUE | E16: =A16 -> a1zNz000000d4jiIAA | F16: =IF(NOT(ISBLANK(B16)),B16,"") -> a1G4J0000025zHYUAY
A17: a1zNz000000fNIPIA2 | B17: a1G4J00000260DRUAY | D17: =F17<>"" -> TRUE | E17: =A17 -> a1zNz000000fNIPIA2 | F17: =IF(NOT(ISBLANK(B17)),B17,"") -> a1G4J00000260DRUAY
A18: a1zNz000000kmHlIAI | B18: a1G4J0000025y09UAA | D18: =F18<>"" -> TRUE | E18: =A18 -> a1zNz000000kmHlIAI | F18: =IF(NOT(ISBLANK(B18)),B18,"") -> a1G4J0000025y09UAA
... A82: a1zNz0000030aZeIAI | B82: a1GNz0000000ynNMAQ | D82: =F82<>"" -> TRUE | E82: =A82 -> a1zNz0000030aZeIAI | F82: =IF(NOT(ISBLANK(B82)),B82,"") -> a1GNz0000000ynNMAQ
A83: a1zNz0000033rMGIAY | D83: =F83<>"" -> FALSE | E83: =A83 -> a1zNz0000033rMGIAY | F83: =IF(NOT(ISBLANK(B83)),B83,"")
A84: a1zNz0000034aUhIAI | B84: a1G8d0000004qm0EAA | D84: =F84<>"" -> TRUE | E84: =A84 -> a1zNz0000034aUhIAI | F84: =IF(NOT(ISBLANK(B84)),B84,"") -> a1G8d0000004qm0EAA
A85: a1zNz0000034cxqIAA | B85: a1G8d0000004qmoEAA | D85: =F85<>"" -> TRUE | E85: =A85 -> a1zNz0000034cxqIAA | F85: =IF(NOT(ISBLANK(B85)),B85,"") -> a1G8d0000004qmoEAA
A86: a1zNz0000034dInIAI | B86: a1G8d0000004qmoEAA | D86: =F86<>"" -> TRUE | E86: =A86 -> a1zNz0000034dInIAI | F86: =IF(NOT(ISBLANK(B86)),B86,"") -> a1G8d0000004qmoEAA
A87: a1zNz0000034wJtIAI | B87: a1G4J0000025yktUAA | D87: =F87<>"" -> TRUE | E87: =A87 -> a1zNz0000034wJtIAI | F87: =IF(NOT(ISBLANK(B87)),B87,"") -> a1G4J0000025yktUAA
A88: a1zNz0000035RlpIAE | B88: a1GNz0000019H4HMAU | D88: =F88<>"" -> TRUE | E88: =A88 -> a1zNz0000035RlpIAE | F88: =IF(NOT(ISBLANK(B88)),B88,"") -> a1GNz0000019H4HMAU
A89: a1zNz0000037xZVIAY | B89: a1G8d0000004qjaEAA | D89: =F89<>"" -> TRUE | E89: =A89 -> a1zNz0000037xZVIAY | F89: =IF(NOT(ISBLANK(B89)),B89,"") -> a1G8d0000004qjaEAA
A90: a1zNz0000038Lf3IAE | B90: a1G4J0000025yitUAA | D90: =F90<>"" -> TRUE | E90: =A90 -> a1zNz0000038Lf3IAE | F90: =IF(NOT(ISBLANK(B90)),B90,"") -> a1G4J0000025yitUAA
A91: a1zNz000003F8A1IAK | B91: a1G4J000004juuWUAQ | D91: =F91<>"" -> TRUE | E91: =A91 -> a1zNz000003F8A1IAK | F91: =IF(NOT(ISBLANK(B91)),B91,"") -> a1G4J000004juuWUAQ
A92: a1zNz000003IHK1IAO | B92: a1G8d000002QBfIEAW | D92: =F92<>"" -> TRUE | E92: =A92 -> a1zNz000003IHK1IAO | F92: =IF(NOT(ISBLANK(B92)),B92,"") -> a1G8d000002QBfIEAW
A93: a1zNz000003II4pIAG | B93: a1G4J0000025z7yUAA | D93: =F93<>"" -> TRUE | E93: =A93 -> a1zNz000003II4pIAG | F93: =IF(NOT(ISBLANK(B93)),B93,"") -> a1G4J0000025z7yUAA
A94: a1zNz000003IKWQIA4 | B94: a1G4J0000025zKeUAI | D94: =F94<>"" -> TRUE | E94: =A94 -> a1zNz000003IKWQIA4 | F94: =IF(NOT(ISBLANK(B94)),B94,"") -> a1G4J0000025zKeUAI
A95: a1zNz000003IMLKIA4 | B95: a1G4J0000025yOvUAI | D95: =F95<>"" -> TRUE | E95: =A95 -> a1zNz000003IMLKIA4 | F95: =IF(NOT(ISBLANK(B95)),B95,"") -> a1G4J0000025yOvUAI
... A129: a1zNz000003rQVhIAM | B129: a1G4J0000025ykRUAQ | D129: =F129<>"" -> TRUE | E129: =A129 -> a1zNz000003rQVhIAM | F129: =IF(NOT(ISBLANK(B129)),B129,"") -> a1G4J0000025ykRUAQ
A130: a1zNz000003sImEIAU | D130: =F130<>"" -> FALSE | E130: =A130 -> a1zNz000003sImEIAU | F130: =IF(NOT(ISBLANK(B130)),B130,"")
A131: a1zNz000003sKXuIAM | B131: a1GNz0000000zOTMAY | D131: =F131<>"" -> TRUE | E131: =A131 -> a1zNz000003sKXuIAM | F131: =IF(NOT(ISBLANK(B131)),B131,"") -> a1GNz0000000zOTMAY
A132: a1zNz000003sMQ1IAM | D132: =F132<>"" -> FALSE | E132: =A132 -> a1zNz000003sMQ1IAM | F132: =IF(NOT(ISBLANK(B132)),B132,"")
A133: a1zNz000003sMeXIAU | B133: a1G4J0000025yzMUAQ | D133: =F133<>"" -> TRUE | E133: =A133 -> a1zNz000003sMeXIAU | F133: =IF(NOT(ISBLANK(B133)),B133,"") -> a1G4J0000025yzMUAQ
A134: a1zNz000003sMufIAE | D134: =F134<>"" -> FALSE | E134: =A134 -> a1zNz000003sMufIAE | F134: =IF(NOT(ISBLANK(B134)),B134,"")
A135: a1zNz000003sMxtIAE | D135: =F135<>"" -> FALSE | E135: =A135 -> a1zNz000003sMxtIAE | F135: =IF(NOT(ISBLANK(B135)),B135,"")
A136: a1zNz000003sNNiIAM | D136: =F136<>"" -> FALSE | E136: =A136 -> a1zNz000003sNNiIAM | F136: =IF(NOT(ISBLANK(B136)),B136,"")
...

Sheet Get Queue Id
A1: Name | B1: DeveloperName | C1: Id
A2: Abbeville Apartments | B2: Abbeville_Apartments | C2: 00GNz0000028cn0MAA
A3: AM: BTR-London | B3: AM_BTR_London | C3: 00GNz0000028cmvMAA
A4: AM: BTR-Regions | B4: AM_BTR_Regions | C4: 00GNz0000028cmwMAA
A5: AM: New Launches | B5: AM_New_Launches | C5: 00GNz0000028cmxMAA
A6: AM: PRS-London | B6: AM_PRS_London | C6: 00GNz0000028cmyMAA
A7: AM: PRS-Regions | B7: AM_PRS_Regions | C7: 00GNz0000028cmzMAA
A8: Apex Gardens Team | B8: Apex_Gardens_Team | C8: 00GNz0000028cn1MAA
A9: Argo Apartments Team | B9: Argo_Apartments_Team | C9: 00GNz0000028cn2MAA
A10: Brook Place Team | B10: Brook_Place_Team | C10: 00GNz0000028cn3MAA
A11: BTR South Lead Queue | B11: Roberto_Lead_Queue | C11: 00GNz0000000AfJMAU
A12: Clippers Quay Team | B12: Clippers_Quay_Team | C12: 00GNz0000028cn4MAA
... A58: Windlass Apartments Team | B58: Windlass_Apartments_Team | C58: 00GNz0000028cnVMAQ

Sheet Update Owner Id
A1: Id | B1: OwnerId | C1: Owner.Name | D1: Related_Unit__r.Building__r.Onsite_PM_Team__c | F1: _update? | G1: Id | H1: OwnerId
A2: a1zNz00000001ddIAA | B2: 0058d00000202rVAAQ | C2: Deanne Coss | D2: The_Headline_Team | F2: =B2<>H2 -> TRUE | G2: =A2 -> a1zNz00000001ddIAA | H2: =IF(ISBLANK(D2),VLOOKUP("Renewal Team",'Get Queue Id'!A:C,3,FALSE), VLOOKUP(D2,'Get Queue Id'!B:C,2,FALSE)) -> 00GNz0000028cnRMAQ
A3: a1zNz00000003AnIAI | B3: 0054J000006BkQgQAK | C3: Jack Howe | D3: Brook_Place_Team | F3: =B3<>H3 -> TRUE | G3: =A3 -> a1zNz00000003AnIAI | H3: =IF(ISBLANK(D3),VLOOKUP("Renewal Team",'Get Queue Id'!A:C,3,FALSE), VLOOKUP(D3,'Get Queue Id'!B:C,2,FALSE)) -> 00GNz0000028cn3MAA
A4: a1zNz00000004RpIAI | B4: 0058d0000034Kn5AAE | C4: Coren Macniven | D4: The_Headline_Team | F4: =B4<>H4 -> TRUE | G4: =A4 -> a1zNz00000004RpIAI | H4: =IF(ISBLANK(D4),VLOOKUP("Renewal Team",'Get Queue Id'!A:C,3,FALSE), VLOOKUP(D4,'Get Queue Id'!B:C,2,FALSE)) -> 00GNz0000028cnRMAQ
A5: a1zNz00000004hxIAA | B5: 0058d00000202rVAAQ | C5: Deanne Coss | D5: The_Forge_Team | F5: =B5<>H5 -> TRUE | G5: =A5 -> a1zNz00000004hxIAA | H5: =IF(ISBLANK(D5),VLOOKUP("Renewal Team",'Get Queue Id'!A:C,3,FALSE), VLOOKUP(D5,'Get Queue Id'!B:C,2,FALSE)) -> 00GNz0000028cnQMAQ
A6: a1zNz00000004tFIAQ | B6: 0058d00000202rVAAQ | C6: Deanne Coss | D6: The_Forge_Team | F6: =B6<>H6 -> TRUE | G6: =A6 -> a1zNz00000004tFIAQ | H6: =IF(ISBLANK(D6),VLOOKUP("Renewal Team",'Get Queue Id'!A:C,3,FALSE), VLOOKUP(D6,'Get Queue Id'!B:C,2,FALSE)) -> 00GNz0000028cnQMAQ
A7: a1zNz00000005FpIAI | B7: 0058d00000202rVAAQ | C7: Deanne Coss | D7: The_Headline_Team | F7: =B7<>H7 -> TRUE | G7: =A7 -> a1zNz00000005FpIAI | H7: =IF(ISBLANK(D7),VLOOKUP("Renewal Team",'Get Queue Id'!A:C,3,FALSE), VLOOKUP(D7,'Get Queue Id'!B:C,2,FALSE)) -> 00GNz0000028cnRMAQ
A8: a1zNz0000000AtpIAE | B8: 0054J000006BkQgQAK | C8: Jack Howe | D8: The_Headline_Team | F8: =B8<>H8 -> TRUE | G8: =A8 -> a1zNz0000000AtpIAE | H8: =IF(ISBLANK(D8),VLOOKUP("Renewal Team",'Get Queue Id'!A:C,3,FALSE), VLOOKUP(D8,'Get Queue Id'!B:C,2,FALSE)) -> 00GNz0000028cnRMAQ
A9: a1zNz0000000CxFIAU | B9: 0054J000006BkQgQAK | C9: Jack Howe | D9: The_Headline_Team | F9: =B9<>H9 -> TRUE | G9: =A9 -> a1zNz0000000CxFIAU | H9: =IF(ISBLANK(D9),VLOOKUP("Renewal Team",'Get Queue Id'!A:C,3,FALSE), VLOOKUP(D9,'Get Queue Id'!B:C,2,FALSE)) -> 00GNz0000028cnRMAQ
A10: a1zNz0000000OdSIAU | B10: 0054J000006BkQgQAK | C10: Jack Howe | D10: The_Headline_Team | F10: =B10<>H10 -> TRUE | G10: =A10 -> a1zNz0000000OdSIAU | H10: =IF(ISBLANK(D10),VLOOKUP("Renewal Team",'Get Queue Id'!A:C,3,FALSE), VLOOKUP(D10,'Get Queue Id'!B:C,2,FALSE)) -> 00GNz0000028cnRMAQ
A11: a1zNz0000000Po1IAE | B11: 0054J000006BkQgQAK | C11: Jack Howe | D11: The_Headline_Team | F11: =B11<>H11 -> TRUE | G11: =A11 -> a1zNz0000000Po1IAE | H11: =IF(ISBLANK(D11),VLOOKUP("Renewal Team",'Get Queue Id'!A:C,3,FALSE), VLOOKUP(D11,'Get Queue Id'!B:C,2,FALSE)) -> 00GNz0000028cnRMAQ
A12: a1zNz0000000PsrIAE | B12: 0054J000006BkQgQAK | C12: Jack Howe | D12: The_Headline_Team | F12: =B12<>H12 -> TRUE | G12: =A12 -> a1zNz0000000PsrIAE | H12: =IF(ISBLANK(D12),VLOOKUP("Renewal Team",'Get Queue Id'!A:C,3,FALSE), VLOOKUP(D12,'Get Queue Id'!B:C,2,FALSE)) -> 00GNz0000028cnRMAQ
A13: a1zNz0000000T5FIAU | B13: 0058d00000202rVAAQ | C13: Deanne Coss | D13: The_Headline_Team | F13: =B13<>H13 -> TRUE | G13: =A13 -> a1zNz0000000T5FIAU | H13: =IF(ISBLANK(D13),VLOOKUP("Renewal Team",'Get Queue Id'!A:C,3,FALSE), VLOOKUP(D13,'Get Queue Id'!B:C,2,FALSE)) -> 00GNz0000028cnRMAQ
... A31: a1zNz0000005eWHIAY | B31: 0054J000006BkQgQAK | C31: Jack Howe | D31: The_Tilt_Works_Team | F31: =B31<>H31 -> TRUE | G31: =A31 -> a1zNz0000005eWHIAY | H31: =IF(ISBLANK(D31),VLOOKUP("Renewal Team",'Get Queue Id'!A:C,3,FALSE), VLOOKUP(D31,'Get Queue Id'!B:C,2,FALSE)) -> 00GNz0000028cnTMAQ
A32: a1zNz0000005rwXIAQ | B32: 0058d0000020QoXAAU | C32: Ruth Friend | F32: =B32<>H32 -> TRUE | G32: =A32 -> a1zNz0000005rwXIAQ | H32: =IF(ISBLANK(D32),VLOOKUP("Renewal Team",'Get Queue Id'!A:C,3,FALSE), VLOOKUP(D32,'Get Queue Id'!B:C,2,FALSE)) -> 00GNz0000048rhaMAA
A33: a1zNz0000006zqPIAQ | B33: 0058d00000202rVAAQ | C33: Deanne Coss | D33: Brook_Place_Team | F33: =B33<>H33 -> TRUE | G33: =A33 -> a1zNz0000006zqPIAQ | H33: =IF(ISBLANK(D33),VLOOKUP("Renewal Team",'Get Queue Id'!A:C,3,FALSE), VLOOKUP(D33,'Get Queue Id'!B:C,2,FALSE)) -> 00GNz0000028cn3MAA
A34: a1zNz0000006zvFIAQ | B34: 0054J000006BkQgQAK | C34: Jack Howe | D34: The_Tilt_Works_Team | F34: =B34<>H34 -> TRUE | G34: =A34 -> a1zNz0000006zvFIAQ | H34: =IF(ISBLANK(D34),VLOOKUP("Renewal Team",'Get Queue Id'!A:C,3,FALSE), VLOOKUP(D34,'Get Queue Id'!B:C,2,FALSE)) -> 00GNz0000028cnTMAQ
A35: a1zNz0000006zwrIAA | B35: 0054J000006BkQgQAK | C35: Jack Howe | D35: The_Tilt_Works_Team | F35: =B35<>H35 -> TRUE | G35: =A35 -> a1zNz0000006zwrIAA | H35: =IF(ISBLANK(D35),VLOOKUP("Renewal Team",'Get Queue Id'!A:C,3,FALSE), VLOOKUP(D35,'Get Queue Id'!B:C,2,FALSE)) -> 00GNz0000028cnTMAQ
A36: a1zNz00000070EbIAI | B36: 0058d00000202rVAAQ | C36: Deanne Coss | D36: The_Tilt_Works_Team | F36: =B36<>H36 -> TRUE | G36: =A36 -> a1zNz00000070EbIAI | H36: =IF(ISBLANK(D36),VLOOKUP("Renewal Team",'Get Queue Id'!A:C,3,FALSE), VLOOKUP(D36,'Get Queue Id'!B:C,2,FALSE)) -> 00GNz0000028cnTMAQ
A37: a1zNz00000070HpIAI | B37: 0058d00000202rVAAQ | C37: Deanne Coss | D37: The_Tilt_Works_Team | F37: =B37<>H37 -> TRUE | G37: =A37 -> a1zNz00000070HpIAI | H37: =IF(ISBLANK(D37),VLOOKUP("Renewal Team",'Get Queue Id'!A:C,3,FALSE), VLOOKUP(D37,'Get Queue Id'!B:C,2,FALSE)) -> 00GNz0000028cnTMAQ
A38: a1zNz00000070T7IAI | B38: 0058d0000034c7KAAQ | C38: Emma Cramer-Mitchell | D38: Brook_Place_Team | F38: =B38<>H38 -> TRUE | G38: =A38 -> a1zNz00000070T7IAI | H38: =IF(ISBLANK(D38),VLOOKUP("Renewal Team",'Get Queue Id'!A:C,3,FALSE), VLOOKUP(D38,'Get Queue Id'!B:C,2,FALSE)) -> 00GNz0000028cn3MAA
A39: a1zNz00000070WLIAY | B39: 0058d00000202rVAAQ | C39: Deanne Coss | D39: The_Tilt_Works_Team | F39: =B39<>H39 -> TRUE | G39: =A39 -> a1zNz00000070WLIAY | H39: =IF(ISBLANK(D39),VLOOKUP("Renewal Team",'Get Queue Id'!A:C,3,FALSE), VLOOKUP(D39,'Get Queue Id'!B:C,2,FALSE)) -> 00GNz0000028cnTMAQ
A40: a1zNz00000070g1IAA | B40: 0058d0000034c7KAAQ | C40: Emma Cramer-Mitchell | D40: Brook_Place_Team | F40: =B40<>H40 -> TRUE | G40: =A40 -> a1zNz00000070g1IAA | H40: =IF(ISBLANK(D40),VLOOKUP("Renewal Team",'Get Queue Id'!A:C,3,FALSE), VLOOKUP(D40,'Get Queue Id'!B:C,2,FALSE)) -> 00GNz0000028cn3MAA
A41: a1zNz00000070krIAA | B41: 0058d00000202rVAAQ | C41: Deanne Coss | D41: The_Tilt_Works_Team | F41: =B41<>H41 -> TRUE | G41: =A41 -> a1zNz00000070krIAA | H41: =IF(ISBLANK(D41),VLOOKUP("Renewal Team",'Get Queue Id'!A:C,3,FALSE), VLOOKUP(D41,'Get Queue Id'!B:C,2,FALSE)) -> 00GNz0000028cnTMAQ
A42: a1zNz00000074GbIAI | B42: 0058d00000202rVAAQ | C42: Deanne Coss | D42: The_Tilt_Works_Team | F42: =B42<>H42 -> TRUE | G42: =A42 -> a1zNz00000074GbIAI | H42: =IF(ISBLANK(D42),VLOOKUP("Renewal Team",'Get Queue Id'!A:C,3,FALSE), VLOOKUP(D42,'Get Queue Id'!B:C,2,FALSE)) -> 00GNz0000028cnTMAQ
A43: a1zNz00000074jdIAA | B43: 0058d00000202rVAAQ | C43: Deanne Coss | D43: The_Tilt_Works_Team | F43: =B43<>H43 -> TRUE | G43: =A43 -> a1zNz00000074jdIAA | H43: =IF(ISBLANK(D43),VLOOKUP("Renewal Team",'Get Queue Id'!A:C,3,FALSE), VLOOKUP(D43,'Get Queue Id'!B:C,2,FALSE)) -> 00GNz0000028cnTMAQ
A44: a1zNz00000076v7IAA | B44: 0058d00000202rVAAQ | C44: Deanne Coss | D44: The_Headline_Team | F44: =B44<>H44 -> TRUE | G44: =A44 -> a1zNz00000076v7IAA | H44: =IF(ISBLANK(D44),VLOOKUP("Renewal Team",'Get Queue Id'!A:C,3,FALSE), VLOOKUP(D44,'Get Queue Id'!B:C,2,FALSE)) -> 00GNz0000028cnRMAQ
... A4563: a1zNz000003iSzlIAE | B4563: 0058d0000020feeAAA | C4563: Corrina Gibson | D4563: Hawkins_and_George_Team | F4563: =B4563<>H4563 -> TRUE | G4563: =A4563 -> a1zNz000003iSzlIAE | H4563: =IF(ISBLANK(D4563),VLOOKUP("Renewal Team",'Get Queue Id'!A:C,3,FALSE), VLOOKUP(D4563,'Get Queue Id'!B:C,2,FALSE)) -> 00GNz0000028cnBMAQ
A4564: a1zNz000003iT6DIAU | B4564: 0058d0000020feeAAA | C4564: Corrina Gibson | F4564: =B4564<>H4564 -> TRUE | G4564: =A4564 -> a1zNz000003iT6DIAU | H4564: =IF(ISBLANK(D4564),VLOOKUP("Renewal Team",'Get Queue Id'!A:C,3,FALSE), VLOOKUP(D4564,'Get Queue Id'!B:C,2,FALSE)) -> 00GNz0000048rhaMAA
A4565: a1zNz000003iTB3IAM | B4565: 0054J000004vXPBQA2 | C4565: Clair Habgood | D4565: PRS_London | F4565: =B4565<>H4565 -> TRUE | G4565: =A4565 -> a1zNz000003iTB3IAM | H4565: =IF(ISBLANK(D4565),VLOOKUP("Renewal Team",'Get Queue Id'!A:C,3,FALSE), VLOOKUP(D4565,'Get Queue Id'!B:C,2,FALSE)) -> 00GNz0000028cnJMAQ
A4566: a1zNz000003iTFtIAM | B4566: 0058d0000034i83AAA | C4566: Honey Campbell | D4566: Clippers_Quay_Team | F4566: =B4566<>H4566 -> TRUE | G4566: =A4566 -> a1zNz000003iTFtIAM | H4566: =IF(ISBLANK(D4566),VLOOKUP("Renewal Team",'Get Queue Id'!A:C,3,FALSE), VLOOKUP(D4566,'Get Queue Id'!B:C,2,FALSE)) -> 00GNz0000028cn4MAA
A4567: a1zNz000003iTNxIAM | B4567: 0058d0000034SvqAAE | C4567: Chiara Rosati | D4567: Solstice_Apartments_Team | F4567: =B4567<>H4567 -> TRUE | G4567: =A4567 -> a1zNz000003iTNxIAM | H4567: =IF(ISBLANK(D4567),VLOOKUP("Renewal Team",'Get Queue Id'!A:C,3,FALSE), VLOOKUP(D4567,'Get Queue Id'!B:C,2,FALSE)) -> 00GNz0000028cnMMAQ
A4568: a1zNz000003iTPZIA2 | B4568: 0058d0000034SvqAAE | C4568: Chiara Rosati | D4568: Solstice_Apartments_Team | F4568: =B4568<>H4568 -> TRUE | G4568: =A4568 -> a1zNz000003iTPZIA2 | H4568: =IF(ISBLANK(D4568),VLOOKUP("Renewal Team",'Get Queue Id'!A:C,3,FALSE), VLOOKUP(D4568,'Get Queue Id'!B:C,2,FALSE)) -> 00GNz0000028cnMMAQ
A4569: a1zNz000003iTe6IAE | B4569: 0054J000004vXPBQA2 | C4569: Clair Habgood | D4569: PRS_London | F4569: =B4569<>H4569 -> TRUE | G4569: =A4569 -> a1zNz000003iTe6IAE | H4569: =IF(ISBLANK(D4569),VLOOKUP("Renewal Team",'Get Queue Id'!A:C,3,FALSE), VLOOKUP(D4569,'Get Queue Id'!B:C,2,FALSE)) -> 00GNz0000028cnJMAQ
A4570: a1zNz000003iTivIAE | B4570: 0058d0000034SvqAAE | C4570: Chiara Rosati | D4570: Hawkins_and_George_Team | F4570: =B4570<>H4570 -> TRUE | G4570: =A4570 -> a1zNz000003iTivIAE | H4570: =IF(ISBLANK(D4570),VLOOKUP("Renewal Team",'Get Queue Id'!A:C,3,FALSE), VLOOKUP(D4570,'Get Queue Id'!B:C,2,FALSE)) -> 00GNz0000028cnBMAQ
A4571: a1zNz000003iTkXIAU | B4571: 0058d0000034SvqAAE | C4571: Chiara Rosati | D4571: Hawkins_and_George_Team | F4571: =B4571<>H4571 -> TRUE | G4571: =A4571 -> a1zNz000003iTkXIAU | H4571: =IF(ISBLANK(D4571),VLOOKUP("Renewal Team",'Get Queue Id'!A:C,3,FALSE), VLOOKUP(D4571,'Get Queue Id'!B:C,2,FALSE)) -> 00GNz0000028cnBMAQ
A4572: a1zNz000003iTqzIAE | B4572: 0054J000004vXPBQA2 | C4572: Clair Habgood | D4572: PRS_London | F4572: =B4572<>H4572 -> TRUE | G4572: =A4572 -> a1zNz000003iTqzIAE | H4572: =IF(ISBLANK(D4572),VLOOKUP("Renewal Team",'Get Queue Id'!A:C,3,FALSE), VLOOKUP(D4572,'Get Queue Id'!B:C,2,FALSE)) -> 00GNz0000028cnJMAQ
A4573: a1zNz000003iTsbIAE | B4573: 0058d0000034SvqAAE | C4573: Chiara Rosati | D4573: Enigma_Square_Team | F4573: =B4573<>H4573 -> TRUE | G4573: =A4573 -> a1zNz000003iTsbIAE | H4573: =IF(ISBLANK(D4573),VLOOKUP("Renewal Team",'Get Queue Id'!A:C,3,FALSE), VLOOKUP(D4573,'Get Queue Id'!B:C,2,FALSE)) -> 00GNz0000028cn7MAA
A4574: a1zNz000003iTuDIAU | B4574: 0054J000004vXPBQA2 | C4574: Clair Habgood | D4574: PRS_London | F4574: =B4574<>H4574 -> TRUE | G4574: =A4574 -> a1zNz000003iTuDIAU | H4574: =IF(ISBLANK(D4574),VLOOKUP("Renewal Team",'Get Queue Id'!A:C,3,FALSE), VLOOKUP(D4574,'Get Queue Id'!B:C,2,FALSE)) -> 00GNz0000028cnJMAQ
A4575: a1zNz000003iU2HIAU | B4575: 0058d0000034SvqAAE | C4575: Chiara Rosati | D4575: Solstice_Apartments_Team | F4575: =B4575<>H4575 -> TRUE | G4575: =A4575 -> a1zNz000003iU2HIAU | H4575: =IF(ISBLANK(D4575),VLOOKUP("Renewal Team",'Get Queue Id'!A:C,3,FALSE), VLOOKUP(D4575,'Get Queue Id'!B:C,2,FALSE)) -> 00GNz0000028cnMMAQ
...

Sheet Extract for Grainger
A1: Id | B1: Name | C1: Tenant__r.Name | D1: Related_Opportunity__c | E1: Related_Opportunity__r | F1: Related_Unit__c | G1: Related_Unit__r | H1: Status__c | I1: Time_Limited__c | J1: RTR_Expiry__c | K1: Date_Next_RTR_Required__c | L1: Document_Saved__c | M1: Check_Date__c | N1: CreatedDate | O1: LastModifiedDate | P1: OwnerId | Q1: Owner.Name
A2: a1zNz000000G0vJIAS | B2: RTR-00000222 | C2: Gizem Salik | H2: Vacated | I2: TRUE | J2: 46156 | K2: 46156 | L2: TRUE | M2: 45215 | N2: 2023-10-16T15:40:06.000+0000 | O2: 2025-02-03T09:53:55.000+0000 | P2: 0058d00000343K8AAI | Q2: Grace Fiske
A3: a1zNz000000LKqBIAW | B3: RTR-00000327 | C3: Saumya Saumya | H3: Completed | I3: TRUE | J3: 45653 | K3: 45734 | L3: TRUE | M3: 45369 | N3: 2023-10-24T11:33:10.000+0000 | O3: 2024-08-22T23:21:53.000+0000 | P3: 0058d000001yXeuAAE | Q3: Kimberley Pope
A4: a1zNz000000LMOvIAO | B4: RTR-00000328 | C4: Rama Rama | H4: Completed | I4: TRUE | J4: 45653 | K4: 45734 | L4: TRUE | M4: 45369 | N4: 2023-10-24T11:35:22.000+0000 | O4: 2024-08-22T23:21:53.000+0000 | P4: 0058d000001yXeuAAE | Q4: Kimberley Pope
A5: a1zNz000000T3LtIAK | B5: RTR-00000462 | C5: Ali Khajah | H5: Not started | I5: TRUE | J5: 45260 | K5: 45600 | L5: TRUE | M5: 45234 | N5: 2023-11-04T11:59:42.000+0000 | O5: 2023-11-04T11:59:42.000+0000 | P5: 005Nz000000kC30IAE | Q5: Rachel Creer
A6: a1zNz000000T4OPIA0 | B6: RTR-00000466 | C6: Zoe Ling Toh | H6: Not started | I6: TRUE | J6: 45911 | K6: 45911 | L6: TRUE | M6: 45234 | N6: 2023-11-04T13:13:05.000+0000 | O6: 2023-11-04T13:13:05.000+0000 | P6: 005Nz000000kC30IAE | Q6: Rachel Creer
A7: a1zNz000000ZWQ1IAO | B7: RTR-00000702 | C7: Elizabeth Egbo | H7: Vacated | I7: TRUE | J7: 46310 | K7: 46310 | L7: TRUE | M7: 45251 | N7: 2023-11-21T16:44:09.000+0000 | O7: 2025-02-03T09:55:41.000+0000 | P7: 005Nz0000013xmCIAQ | Q7: Rachel Steventon
A8: a1zNz0000017lb7IAA | B8: RTR-00001566 | C8: Maryam Musa | H8: Completed | I8: TRUE | J8: 47275 | K8: 47275 | L8: TRUE | M8: 45316 | N8: 2024-01-25T13:51:29.000+0000 | O8: 2024-08-22T23:17:31.000+0000 | P8: 0058d000006d4S2AAI | Q8: Haginson Mtuku
A9: a1zNz00000189OvIAI | B9: RTR-00001585 | C9: Malvika Muralidhar | H9: In Progress | I9: TRUE | J9: 45791 | K9: 45791 | L9: TRUE | M9: 45308 | N9: 2024-01-26T14:19:44.000+0000 | O9: 2024-01-26T14:22:31.000+0000 | P9: 005Nz000000ImixIAC | Q9: Nyijah Bullen
A10: a1zNz00000189bpIAA | B10: RTR-00001586 | C10: Niveditha Nanjunda Kumar | H10: In Progress | I10: TRUE | J10: 45661 | K10: 45674 | L10: TRUE | M10: 45308 | N10: 2024-01-26T14:25:34.000+0000 | O10: 2024-01-26T14:25:34.000+0000 | P10: 005Nz000000ImixIAC | Q10: Nyijah Bullen
A11: a1zNz00000189yPIAQ | B11: RTR-00001589 | C11: L011I1UBXvt7no8fiz4q RHQdg4DoREqQftVDqpKP | H11: In Progress | I11: TRUE | J11: 46047 | K11: 46047 | L11: TRUE | M11: 45308 | N11: 2024-01-26T14:57:29.000+0000 | O11: 2024-01-26T14:57:29.000+0000 | P11: 005Nz000000ImixIAC | Q11: Nyijah Bullen
A12: a1zNz0000018A1dIAE | B12: RTR-00001590 | C12: Krati Doshi | H12: In Progress | I12: TRUE | J12: 46048 | K12: 46048 | L12: TRUE | M12: 45308 | N12: 2024-01-26T14:58:31.000+0000 | O12: 2024-01-26T14:58:31.000+0000 | P12: 005Nz000000ImixIAC | Q12: Nyijah Bullen
A13: a1zNz000001GhoPIAS | B13: RTR-00001769 | C13: Niksa Khemka | H13: In Progress | I13: TRUE | J13: 46431 | K13: 46431 | L13: TRUE | M13: 45348 | N13: 2024-02-06T17:07:54.000+0000 | O13: 2024-02-06T17:07:54.000+0000 | P13: 005Nz000000ImixIAC | Q13: Nyijah Bullen
... A29: a1zNz0000056JzZIAU | B29: RTR-00023213 | C29: Zaynab Ishola | H29: Completed | I29: TRUE | J29: 46587 | K29: 46587 | L29: TRUE | M29: 45685 | N29: 2025-01-28T16:19:51.000+0000 | O29: 2025-01-28T16:19:51.000+0000 | P29: 0054J000004vm9BQAQ | Q29: Louise Spooner

Sheet Result Update Related Unit
A1: Id | B1: Related_Unit__c | C1: __Status | D1: __Id | E1: __Action | F1: __Errors
A2: a1zNz0000006zqPIAQ | B2: a1G4J0000025z5QUAQ | C2: Succeeded | D2: a1zNz0000006zqPIAQ | E2: Updated
A3: a1zNz000000GTNpIAO | B3: a1G4J0000025y8bUAA | C3: Succeeded | D3: a1zNz000000GTNpIAO | E3: Updated
A4: a1zNz000000GYCDIA4 | B4: a1G4J000004jyhpUAA | C4: Succeeded | D4: a1zNz000000GYCDIA4 | E4: Updated
A5: a1zNz000000PdpNIAS | B5: a1GNz00000017lpMAA | C5: Succeeded | D5: a1zNz000000PdpNIAS | E5: Updated
A6: a1zNz000000PeIPIA0 | B6: a1GNz00000010UGMAY | C6: Succeeded | D6: a1zNz000000PeIPIA0 | E6: Updated
A7: a1zNz000000UIFeIAO | B7: a1GNz00000012fhMAA | C7: Succeeded | D7: a1zNz000000UIFeIAO | E7: Updated
A8: a1zNz000000URvdIAG | B8: a1G4J0000025x92UAA | C8: Succeeded | D8: a1zNz000000URvdIAG | E8: Updated
A9: a1zNz000000UYfNIAW | B9: a1G8d000002QBLDEA4 | C9: Succeeded | D9: a1zNz000000UYfNIAW | E9: Updated
A10: a1zNz000000UywPIAS | B10: a1G4J0000025y1kUAA | C10: Succeeded | D10: a1zNz000000UywPIAS | E10: Updated
A11: a1zNz000000V6PJIA0 | B11: a1G4J0000025xyYUAQ | C11: Succeeded | D11: a1zNz000000V6PJIA0 | E11: Updated
A12: a1zNz000000VNd3IAG | B12: a1G4J0000025x1GUAQ | C12: Succeeded | D12: a1zNz000000VNd3IAG | E12: Updated
A13: a1zNz000000XDwCIAW | B13: a1G4J0000025ywGUAQ | C13: Succeeded | D13: a1zNz000000XDwCIAW | E13: Updated
... A3720: a1zNz0000059FY1IAM | B3720: a1GNz000000163OMAQ | C3720: Succeeded | D3720: a1zNz0000059FY1IAM | E3720: Updated

Sheet Result Update Owner Id
A1: _update? | B1: Id | C1: OwnerId | D1: __Status | E1: __Id | F1: __Action | G1: __Errors
A2: TRUE | B2: a1zNz00000001ddIAA | C2: 00GNz0000028cnRMAQ | D2: Succeeded | E2: a1zNz00000001ddIAA | F2: Updated
A3: TRUE | B3: a1zNz00000003AnIAI | C3: 00GNz0000028cn3MAA | D3: Succeeded | E3: a1zNz00000003AnIAI | F3: Updated
A4: TRUE | B4: a1zNz00000004RpIAI | C4: 00GNz0000028cnRMAQ | D4: Succeeded | E4: a1zNz00000004RpIAI | F4: Updated
A5: TRUE | B5: a1zNz00000004hxIAA | C5: 00GNz0000028cnQMAQ | D5: Succeeded | E5: a1zNz00000004hxIAA | F5: Updated
A6: TRUE | B6: a1zNz00000004tFIAQ | C6: 00GNz0000028cnQMAQ | D6: Succeeded | E6: a1zNz00000004tFIAQ | F6: Updated
A7: TRUE | B7: a1zNz00000005FpIAI | C7: 00GNz0000028cnRMAQ | D7: Succeeded | E7: a1zNz00000005FpIAI | F7: Updated
A8: TRUE | B8: a1zNz0000000AtpIAE | C8: 00GNz0000028cnRMAQ | D8: Succeeded | E8: a1zNz0000000AtpIAE | F8: Updated
A9: TRUE | B9: a1zNz0000000CxFIAU | C9: 00GNz0000028cnRMAQ | D9: Succeeded | E9: a1zNz0000000CxFIAU | F9: Updated
A10: TRUE | B10: a1zNz0000000OdSIAU | C10: 00GNz0000028cnRMAQ | D10: Succeeded | E10: a1zNz0000000OdSIAU | F10: Updated
A11: TRUE | B11: a1zNz0000000Po1IAE | C11: 00GNz0000028cnRMAQ | D11: Succeeded | E11: a1zNz0000000Po1IAE | F11: Updated
A12: TRUE | B12: a1zNz0000000PsrIAE | C12: 00GNz0000028cnRMAQ | D12: Succeeded | E12: a1zNz0000000PsrIAE | F12: Updated
A13: TRUE | B13: a1zNz0000000T5FIAU | C13: 00GNz0000028cnRMAQ | D13: Succeeded | E13: a1zNz0000000T5FIAU | F13: Updated
... A14354: TRUE | B14354: a1zNz0000059FY1IAM | C14354: 00GNz0000028cnNMAQ | D14354: Succeeded | E14354: a1zNz0000059FY1IAM | F14354: Updated
