Workbook

Sheet Sheet1
A1: Unit ID
A2: 222708001
A3: 222708002
A4: 222708003
A5: 222708004
A6: 222708005
A7: 222708006
A8: 222708007
A9: 222708008
A10: 222708009
A11: 222708010
A12: 222708011
... A262: 222708261
A263: 0

Sheet Existing PBE
A1: Complex Key | B1: Id | C1: Product2.Unit__r.PMS_Reference__c | D1: Pricebook2.Name | E1: Pricebook2.Effective_Date__c | F1: UnitPrice
A2: =C2&"_"&YEAR(E2)&"_"&MONTH(E2) -> 222708001_2025_3 | B2: 01uPv0000060bPlIAI | C2: 222708001 | D2: Price Book Rent Mar 2025 | E2: 45717 | F2: 0
A3: =C3&"_"&YEAR(E3)&"_"&MONTH(E3) -> 222708001_2025_4 | B3: 01uPv0000060bPmIAI | C3: 222708001 | D3: Price Book Rent Apr 2025 | E3: 45748 | F3: 0
A4: =C4&"_"&YEAR(E4)&"_"&MONTH(E4) -> 222708001_2025_5 | B4: 01uPv0000060bPnIAI | C4: 222708001 | D4: Price Book Rent May 2025 | E4: 45778 | F4: 0
A5: =C5&"_"&YEAR(E5)&"_"&MONTH(E5) -> 222708001_2025_6 | B5: 01uPv0000060bPoIAI | C5: 222708001 | D5: Price Book Rent Jun 2025 | E5: 45809 | F5: 0
A6: =C6&"_"&YEAR(E6)&"_"&MONTH(E6) -> 222708001_2025_7 | B6: 01uPv0000060bPpIAI | C6: 222708001 | D6: Price Book Rent Jul 2025 | E6: 45839 | F6: 0
A7: =C7&"_"&YEAR(E7)&"_"&MONTH(E7) -> 222708001_2025_8 | B7: 01uPv0000060bPqIAI | C7: 222708001 | D7: Price Book Rent Aug 2025 | E7: 45870 | F7: 0
A8: =C8&"_"&YEAR(E8)&"_"&MONTH(E8) -> 222708001_2025_9 | B8: 01uPv0000060bPrIAI | C8: 222708001 | D8: Price Book Rent Sep 2025 | E8: 45901 | F8: 0
A9: =C9&"_"&YEAR(E9)&"_"&MONTH(E9) -> 222708001_2025_10 | B9: 01uPv0000060bPsIAI | C9: 222708001 | D9: Price Book Rent Oct 2025 | E9: 45931 | F9: 0
A10: =C10&"_"&YEAR(E10)&"_"&MONTH(E10) -> 222708001_2025_11 | B10: 01uPv0000060bPtIAI | C10: 222708001 | D10: Price Book Rent Nov 2025 | E10: 45962 | F10: 0
A11: =C11&"_"&YEAR(E11)&"_"&MONTH(E11) -> 222708001_2025_12 | B11: 01uPv0000060bPuIAI | C11: 222708001 | D11: Price Book Rent Dec 2025 | E11: 45992 | F11: 0
A12: =C12&"_"&YEAR(E12)&"_"&MONTH(E12) -> 222708001_2026_1 | B12: 01uPv0000060bPvIAI | C12: 222708001 | D12: Price Book Rent Jan 2026 | E12: 46023 | F12: 0
A13: =C13&"_"&YEAR(E13)&"_"&MONTH(E13) -> 222708001_2026_2 | B13: 01uPv0000060bPwIAI | C13: 222708001 | D13: Price Book Rent Feb 2026 | E13: 46054 | F13: 0
... A16966: =C16966&"_"&YEAR(E16966)&"_"&MONTH(E16966) -> 222708261_2025_2 | B16966: 01uPv000006s2PlIAI | C16966: 222708261 | D16966: Price Book Rent 2025 02 | E16966: 45689 | F16966: 1393.18

Sheet PBI
B1: Unit ID | C1: From Date | D1: To Date | E1: UnitPrice | F1: _Complex Key | G1: Id
A2: 1 | B2: 222708001 | C2: 45566 | D2: =EOMONTH(C2,0) -> 45596 | E2: 1371.7719 | F2: =B2&"_"&YEAR(C2)&"_"&MONTH(C2) -> 222708001_2024_10 | G2: =VLOOKUP(F2,'Existing PBE'!A:C,2,FALSE) -> #N/A
B3: 222708001 | C3: =D2+1 -> 45597 | D3: =EOMONTH(C3,0) -> 45626 | E3: 1378.3574 | F3: =B3&"_"&YEAR(C3)&"_"&MONTH(C3) -> 222708001_2024_11 | G3: =VLOOKUP(F3,'Existing PBE'!A:C,2,FALSE) -> #N/A
B4: 222708001 | C4: =D3+1 -> 45627 | D4: =EOMONTH(C4,0) -> 45657 | E4: 1385.1956 | F4: =B4&"_"&YEAR(C4)&"_"&MONTH(C4) -> 222708001_2024_12 | G4: =VLOOKUP(F4,'Existing PBE'!A:C,2,FALSE) -> #N/A
B5: 222708001 | C5: =D4+1 -> 45658 | D5: =EOMONTH(C5,0) -> 45688 | E5: 1392.0678 | F5: =B5&"_"&YEAR(C5)&"_"&MONTH(C5) -> 222708001_2025_1 | G5: =VLOOKUP(F5,'Existing PBE'!A:C,2,FALSE) -> #N/A
B6: 222708001 | C6: =D5+1 -> 45689 | D6: =EOMONTH(C6,0) -> 45716 | E6: 1398.3042 | F6: =B6&"_"&YEAR(C6)&"_"&MONTH(C6) -> 222708001_2025_2 | G6: =VLOOKUP(F6,'Existing PBE'!A:C,2,FALSE) -> 01uPv000006s2GWIAY
B7: 222708001 | C7: =D6+1 -> 45717 | D7: =EOMONTH(C7,0) -> 45747 | E7: 1405.2413 | F7: =B7&"_"&YEAR(C7)&"_"&MONTH(C7) -> 222708001_2025_3 | G7: =VLOOKUP(F7,'Existing PBE'!A:C,2,FALSE) -> 01uPv0000060bPlIAI
B8: 222708001 | C8: =D7+1 -> 45748 | D8: =EOMONTH(C8,0) -> 45777 | E8: 1411.9875 | F8: =B8&"_"&YEAR(C8)&"_"&MONTH(C8) -> 222708001_2025_4 | G8: =VLOOKUP(F8,'Existing PBE'!A:C,2,FALSE) -> 01uPv0000060bPmIAI
B9: 222708001 | C9: =D8+1 -> 45778 | D9: =EOMONTH(C9,0) -> 45808 | E9: 1418.9926 | F9: =B9&"_"&YEAR(C9)&"_"&MONTH(C9) -> 222708001_2025_5 | G9: =VLOOKUP(F9,'Existing PBE'!A:C,2,FALSE) -> 01uPv0000060bPnIAI
B10: 222708001 | C10: =D9+1 -> 45809 | D10: =EOMONTH(C10,0) -> 45838 | E10: 1425.8047 | F10: =B10&"_"&YEAR(C10)&"_"&MONTH(C10) -> 222708001_2025_6 | G10: =VLOOKUP(F10,'Existing PBE'!A:C,2,FALSE) -> 01uPv0000060bPoIAI
B11: 222708001 | C11: =D10+1 -> 45839 | D11: =EOMONTH(C11,0) -> 45869 | E11: 1432.8783 | F11: =B11&"_"&YEAR(C11)&"_"&MONTH(C11) -> 222708001_2025_7 | G11: =VLOOKUP(F11,'Existing PBE'!A:C,2,FALSE) -> 01uPv0000060bPpIAI
B12: 222708001 | C12: =D11+1 -> 45870 | D12: =EOMONTH(C12,0) -> 45900 | E12: 1439.987 | F12: =B12&"_"&YEAR(C12)&"_"&MONTH(C12) -> 222708001_2025_8 | G12: =VLOOKUP(F12,'Existing PBE'!A:C,2,FALSE) -> 01uPv0000060bPqIAI
B13: 222708001 | C13: =D12+1 -> 45901 | D13: =EOMONTH(C13,0) -> 45930 | E13: 1446.9 | F13: =B13&"_"&YEAR(C13)&"_"&MONTH(C13) -> 222708001_2025_9 | G13: =VLOOKUP(F13,'Existing PBE'!A:C,2,FALSE) -> 01uPv0000060bPrIAI
A14: =A2+1 -> 2 | B14: 222708002 | C14: =C2 -> 45566 | D14: =D2 -> 45596 | E14: 1200.9286 | F14: =B14&"_"&YEAR(C14)&"_"&MONTH(C14) -> 222708002_2024_10 | G14: =VLOOKUP(F14,'Existing PBE'!A:C,2,FALSE) -> #N/A
B15: 222708002 | C15: =C3 -> 45597 | D15: =D3 -> 45626 | E15: 1206.6939 | F15: =B15&"_"&YEAR(C15)&"_"&MONTH(C15) -> 222708002_2024_11 | G15: =VLOOKUP(F15,'Existing PBE'!A:C,2,FALSE) -> #N/A
B16: 222708002 | C16: =C4 -> 45627 | D16: =D4 -> 45657 | E16: 1212.6804 | F16: =B16&"_"&YEAR(C16)&"_"&MONTH(C16) -> 222708002_2024_12 | G16: =VLOOKUP(F16,'Existing PBE'!A:C,2,FALSE) -> #N/A
B17: 222708002 | C17: =C5 -> 45658 | D17: =D5 -> 45688 | E17: 1218.6967 | F17: =B17&"_"&YEAR(C17)&"_"&MONTH(C17) -> 222708002_2025_1 | G17: =VLOOKUP(F17,'Existing PBE'!A:C,2,FALSE) -> #N/A
B18: 222708002 | C18: =C6 -> 45689 | D18: =D6 -> 45716 | E18: 1224.1564 | F18: =B18&"_"&YEAR(C18)&"_"&MONTH(C18) -> 222708002_2025_2 | G18: =VLOOKUP(F18,'Existing PBE'!A:C,2,FALSE) -> 01uPv000006s2DOIAY
B19: 222708002 | C19: =C7 -> 45717 | D19: =D7 -> 45747 | E19: 1230.2296 | F19: =B19&"_"&YEAR(C19)&"_"&MONTH(C19) -> 222708002_2025_3 | G19: =VLOOKUP(F19,'Existing PBE'!A:C,2,FALSE) -> 01uPv0000060ZoaIAE
B20: 222708002 | C20: =C8 -> 45748 | D20: =D8 -> 45777 | E20: 1236.1356 | F20: =B20&"_"&YEAR(C20)&"_"&MONTH(C20) -> 222708002_2025_4 | G20: =VLOOKUP(F20,'Existing PBE'!A:C,2,FALSE) -> 01uPv0000060ZobIAE
B21: 222708002 | C21: =C9 -> 45778 | D21: =D9 -> 45808 | E21: 1242.2682 | F21: =B21&"_"&YEAR(C21)&"_"&MONTH(C21) -> 222708002_2025_5 | G21: =VLOOKUP(F21,'Existing PBE'!A:C,2,FALSE) -> 01uPv0000060ZocIAE
B22: 222708002 | C22: =C10 -> 45809 | D22: =D10 -> 45838 | E22: 1248.232 | F22: =B22&"_"&YEAR(C22)&"_"&MONTH(C22) -> 222708002_2025_6 | G22: =VLOOKUP(F22,'Existing PBE'!A:C,2,FALSE) -> 01uPv0000060ZodIAE
B23: 222708002 | C23: =C11 -> 45839 | D23: =D11 -> 45869 | E23: 1254.4246 | F23: =B23&"_"&YEAR(C23)&"_"&MONTH(C23) -> 222708002_2025_7 | G23: =VLOOKUP(F23,'Existing PBE'!A:C,2,FALSE) -> 01uPv0000060ZoeIAE
B24: 222708002 | C24: =C12 -> 45870 | D24: =D12 -> 45900 | E24: 1260.648 | F24: =B24&"_"&YEAR(C24)&"_"&MONTH(C24) -> 222708002_2025_8 | G24: =VLOOKUP(F24,'Existing PBE'!A:C,2,FALSE) -> 01uPv0000060ZofIAE
B25: 222708002 | C25: =C13 -> 45901 | D25: =D13 -> 45930 | E25: 1266.7 | F25: =B25&"_"&YEAR(C25)&"_"&MONTH(C25) -> 222708002_2025_9 | G25: =VLOOKUP(F25,'Existing PBE'!A:C,2,FALSE) -> 01uPv0000060ZogIAE
A26: =A14+1 -> 3 | B26: 222708003 | C26: =C14 -> 45566 | D26: =D14 -> 45596 | E26: 1200.9286 | F26: =B26&"_"&YEAR(C26)&"_"&MONTH(C26) -> 222708003_2024_10 | G26: =VLOOKUP(F26,'Existing PBE'!A:C,2,FALSE) -> #N/A
B27: 222708003 | C27: =C15 -> 45597 | D27: =D15 -> 45626 | E27: 1206.6939 | F27: =B27&"_"&YEAR(C27)&"_"&MONTH(C27) -> 222708003_2024_11 | G27: =VLOOKUP(F27,'Existing PBE'!A:C,2,FALSE) -> #N/A
B28: 222708003 | C28: =C16 -> 45627 | D28: =D16 -> 45657 | E28: 1212.6804 | F28: =B28&"_"&YEAR(C28)&"_"&MONTH(C28) -> 222708003_2024_12 | G28: =VLOOKUP(F28,'Existing PBE'!A:C,2,FALSE) -> #N/A
B29: 222708003 | C29: =C17 -> 45658 | D29: =D17 -> 45688 | E29: 1218.6967 | F29: =B29&"_"&YEAR(C29)&"_"&MONTH(C29) -> 222708003_2025_1 | G29: =VLOOKUP(F29,'Existing PBE'!A:C,2,FALSE) -> #N/A
B30: 222708003 | C30: =C18 -> 45689 | D30: =D18 -> 45716 | E30: 1224.1564 | F30: =B30&"_"&YEAR(C30)&"_"&MONTH(C30) -> 222708003_2025_2 | G30: =VLOOKUP(F30,'Existing PBE'!A:C,2,FALSE) -> 01uPv000006s2GOIAY
B31: 222708003 | C31: =C19 -> 45717 | D31: =D19 -> 45747 | E31: 1230.2296 | F31: =B31&"_"&YEAR(C31)&"_"&MONTH(C31) -> 222708003_2025_3 | G31: =VLOOKUP(F31,'Existing PBE'!A:C,2,FALSE) -> 01uPv0000060XaaIAE
B32: 222708003 | C32: =C20 -> 45748 | D32: =D20 -> 45777 | E32: 1236.1356 | F32: =B32&"_"&YEAR(C32)&"_"&MONTH(C32) -> 222708003_2025_4 | G32: =VLOOKUP(F32,'Existing PBE'!A:C,2,FALSE) -> 01uPv0000060XabIAE
B33: 222708003 | C33: =C21 -> 45778 | D33: =D21 -> 45808 | E33: 1242.2682 | F33: =B33&"_"&YEAR(C33)&"_"&MONTH(C33) -> 222708003_2025_5 | G33: =VLOOKUP(F33,'Existing PBE'!A:C,2,FALSE) -> 01uPv0000060XacIAE
B34: 222708003 | C34: =C22 -> 45809 | D34: =D22 -> 45838 | E34: 1248.232 | F34: =B34&"_"&YEAR(C34)&"_"&MONTH(C34) -> 222708003_2025_6 | G34: =VLOOKUP(F34,'Existing PBE'!A:C,2,FALSE) -> 01uPv0000060XadIAE
B35: 222708003 | C35: =C23 -> 45839 | D35: =D23 -> 45869 | E35: 1254.4246 | F35: =B35&"_"&YEAR(C35)&"_"&MONTH(C35) -> 222708003_2025_7 | G35: =VLOOKUP(F35,'Existing PBE'!A:C,2,FALSE) -> 01uPv0000060XaeIAE
B36: 222708003 | C36: =C24 -> 45870 | D36: =D24 -> 45900 | E36: 1260.648 | F36: =B36&"_"&YEAR(C36)&"_"&MONTH(C36) -> 222708003_2025_8 | G36: =VLOOKUP(F36,'Existing PBE'!A:C,2,FALSE) -> 01uPv0000060XafIAE
B37: 222708003 | C37: =C25 -> 45901 | D37: =D25 -> 45930 | E37: 1266.7 | F37: =B37&"_"&YEAR(C37)&"_"&MONTH(C37) -> 222708003_2025_9 | G37: =VLOOKUP(F37,'Existing PBE'!A:C,2,FALSE) -> 01uPv0000060XagIAE
A38: =A26+1 -> 4 | B38: 222708004 | C38: =C26 -> 45566 | D38: =D26 -> 45596 | E38: 1371.7719 | F38: =B38&"_"&YEAR(C38)&"_"&MONTH(C38) -> 222708004_2024_10 | G38: =VLOOKUP(F38,'Existing PBE'!A:C,2,FALSE) -> #N/A
B39: 222708004 | C39: =C27 -> 45597 | D39: =D27 -> 45626 | E39: 1378.3574 | F39: =B39&"_"&YEAR(C39)&"_"&MONTH(C39) -> 222708004_2024_11 | G39: =VLOOKUP(F39,'Existing PBE'!A:C,2,FALSE) -> #N/A
B40: 222708004 | C40: =C28 -> 45627 | D40: =D28 -> 45657 | E40: 1385.1956 | F40: =B40&"_"&YEAR(C40)&"_"&MONTH(C40) -> 222708004_2024_12 | G40: =VLOOKUP(F40,'Existing PBE'!A:C,2,FALSE) -> #N/A
...
